
# Created by Ruins mod version 17.2 Ingame Parser
# authoring Player: BARTLLOW

# TEMPLATE PARAMETER SETTINGS:
#
# criterion expression specifying mod ids required to load template
# may include plus (AND), minus (AND NOT), comma (OR), and parentheses
# all required mods listed must be present; no prohibited mods can be
requiredMods=
#
# likelihood this template will be chosen relative to all others
# e.g., a weight=6 template is chosen 3X as often as one with weight=2
weight=1
#
# list of dimensions in which this template may spawn, even if generic
# one or more dimension names, separated by commas (blank = all)
dimensionsToSpawnIn=
#
# list of other biomes in which this template may spawn
# biome corresponding to directory is always assumed, listed or not
# generic templates should leave this list empty
biomesToSpawnIn=
#
# criterion expression specifying types of biome where template spawns
# this is in addition to those explicitly listed as biomesToSpawnIn
# generic templates should leave this list empty
biomeTypesToSpawnIn=
#
# list of biomes in which this template may not spawn
# takes precedence over biomeTypesToSpawnIn, but NOT biomesToSpawnIn
# should be empty if biomeTypesToSpawnIn is empty
biomesToNotSpawnIn=
#
# depth template is pushed down into the surface when built
# offset is min/max range of random additional bury depth
embed_into_distance=0
random_height_offset=0,0
#
# whitelist/blacklist of block types on which template may be built
# specify one, not both; leave the other empty (both empty = allow all)
acceptable_target_blocks=
unacceptable_target_blocks=flowing_water,water,flowing_lava,lava
#
# size of template (#layers, #rows per layer, #blocks per row)
dimensions=11,13,9
#
# max number of missing blocks allowed in surface beneath template
allowable_overhang=0
#
# depth/height limit affected by terrain leveling
# also maximum bumpiness tolerated in surface beneath template
max_leveling=2
#
# padding applied to all sides of template horizontal footprint
# expands area affected by terrain leveling (-1 = no leveling)
leveling_buffer=0
#
# do not rotate template randomly when built (1 = no rotation)
preventRotation=0
#
# treat water/lava blocks as air and protect them from rule0 (1 = yes)
preserve_water=0
preserve_lava=0
#
# minimum distance this template must have from instances of itself
uniqueMinDistance=0
#
# min/max distances this template can be from world spawn (0 = no limit)
# only applies to overworld--i.e., dimension 0
spawnMinDistance=0
spawnMaxDistance=0
#
# other template built nearby whenever this one is
# syntax: <name>;<relativeX>;<maxYdifference>;<relativeZ>[;<chance>]
# may be used more than once to specify multiple neighbors
adjoining_template=

rule1=0,100,minecraft:vine-8
rule2=0,100,minecraft:vine-1
rule3=0,100,minecraft:log-0
rule4=0,100,minecraft:wooden_slab-0
rule5=0,100,minecraft:oak_stairs-0
rule6=0,100,minecraft:planks-0
rule7=0,100,minecraft:vine-4
rule8=0,100,minecraft:oak_stairs-6
rule9=0,100,minecraft:fence-0
rule10=0,100,minecraft:cobblestone-0
rule11=0,100,minecraft:wooden_door-4
rule12=0,100,minecraft:wooden_door-8
rule13=0,100,minecraft:glass-0
rule14=0,100,minecraft:stone_stairs-0
rule15=2,100,minecraft:torch-1
rule16=2,100,minecraft:torch-3
rule17=2,100,minecraft:torch-4
rule18=0,100,minecraft:mossy_cobblestone-0
rule19=0,100,minecraft:stone_stairs-6
rule20=0,100,minecraft:oak_stairs-1
rule21=0,100,minecraft:oak_stairs-2
rule22=0,100,minecraft:oak_stairs-3
rule23=0,100,minecraft:sandstone-2
rule24=0,100,minecraft:sandstone-0
rule25=0,100,minecraft:vine-2
rule26=0,100,minecraft:web-0
rule27=0,100,minecraft:sandstone_stairs-4
rule28=0,100,minecraft:oak_stairs-5
rule29=0,100,minecraft:oak_stairs-7
rule30=0,100,minecraft:oak_stairs-4
rule31=2,100,minecraft:torch-2
rule32=0,100,minecraft:log-4

layer
0,0,0,0,0,0,0,1,0
0,3,4,4,5,4,4,3,2
7,3,3,3,6,3,3,3,2
0,3,6,6,6,6,6,3,0
0,3,6,6,6,6,6,3,0
0,3,6,6,6,6,6,3,0
0,3,6,6,6,6,6,3,0
0,3,6,6,6,6,6,3,2
0,3,6,6,6,6,6,3,0
0,3,6,6,6,6,8,3,0
7,3,3,3,3,3,3,3,0
0,3,0,0,0,0,0,3,0
0,0,0,0,0,0,0,0,0
endlayer

layer
0,0,0,0,0,0,0,0,0
0,9,0,0,0,0,0,9,0
7,3,10,10,11,10,10,3,0
0,10,0,0,0,0,0,10,0
0,10,0,0,0,0,0,10,0
0,10,0,0,0,0,0,10,0
0,10,0,0,0,0,0,10,2
0,10,5,6,0,0,0,10,0
0,10,6,6,0,0,0,10,0
0,10,6,6,0,1,0,10,0
0,3,10,10,10,10,10,3,0
0,9,0,0,0,0,0,9,0
0,0,0,0,0,0,0,0,0
endlayer

layer
0,0,0,0,0,0,0,0,0
0,9,0,0,0,0,0,9,0
0,3,10,10,12,10,10,3,0
0,10,0,0,0,0,0,10,0
0,13,0,0,0,0,0,13,0
0,10,0,0,0,0,0,10,0
0,13,0,0,0,0,0,13,0
0,10,0,6,0,0,0,10,0
0,10,5,6,0,0,0,13,0
0,10,6,6,0,0,0,10,0
0,3,10,10,10,13,14,3,0
0,9,0,0,0,0,0,9,0
0,0,0,0,0,0,0,0,0
endlayer

layer
0,0,0,0,0,0,0,0,0
0,9,0,0,0,0,0,9,0
0,3,10,10,10,10,10,3,0
0,10,0,0,15,0,0,10,0
0,10,0,0,0,0,0,10,0
0,10,0,0,0,0,0,10,0
0,18,17,0,0,0,16,10,0
0,10,0,6,8,0,0,19,0
0,10,2,20,8,0,0,10,0
0,10,2,0,8,0,0,10,0
0,3,10,10,10,10,10,3,0
0,9,0,0,0,0,0,9,0
0,0,0,0,0,0,0,0,0
endlayer

layer
0,0,0,0,0,0,0,0,0
22,3,0,0,0,0,1,3,21
22,3,3,3,3,3,3,3,21
22,3,6,6,6,6,6,3,21
22,3,6,6,6,6,6,3,21
22,3,6,6,6,6,6,3,21
22,3,6,6,6,6,6,3,21
22,3,2,20,6,6,6,3,21
22,3,0,0,6,6,6,3,21
22,3,2,0,6,6,6,3,21
22,3,3,3,3,3,3,3,21
22,3,0,0,0,0,0,3,21
0,0,0,0,0,0,0,0,0
endlayer

layer
0,0,0,0,0,0,0,0,0
0,6,0,0,0,0,1,8,0
0,6,23,23,23,24,23,6,0
7,6,26,0,25,0,0,22,0
0,6,0,0,0,0,0,6,0
0,6,0,0,0,0,0,6,0
0,6,0,2,0,0,0,6,0
0,6,2,0,0,0,0,6,0
0,6,0,0,0,0,7,6,0
0,6,0,0,1,0,0,6,0
0,6,24,23,23,23,23,6,0
0,6,0,0,0,0,0,6,0
0,0,0,0,0,0,0,0,0
endlayer

layer
0,0,0,0,0,0,0,0,0
0,22,0,0,0,0,0,21,0
0,22,3,27,13,23,3,21,0
0,22,28,0,0,0,28,21,0
0,22,8,0,0,0,29,21,0
0,22,8,0,0,0,29,21,0
0,22,8,2,0,0,29,21,0
0,22,8,0,0,0,29,21,0
0,22,8,0,0,0,29,21,0
0,22,30,0,0,0,30,21,0
0,22,3,23,13,24,3,21,0
0,22,0,0,0,0,0,21,0
0,0,0,0,0,0,0,0,0
endlayer

layer
0,0,1,0,0,0,0,0,0
0,0,6,0,0,0,6,0,0
0,0,6,23,13,23,6,0,0
0,0,6,0,0,0,6,0,0
0,0,6,0,0,0,6,0,0
0,0,6,0,0,0,21,0,0
0,0,6,2,0,0,6,0,0
0,0,6,2,0,0,6,0,0
0,0,6,0,0,0,6,0,0
0,0,6,0,0,0,6,0,0
0,0,6,24,13,24,6,0,0
0,0,6,0,0,0,6,0,0
0,0,0,0,0,0,0,0,0
endlayer

layer
0,0,0,0,0,0,0,0,0
0,0,22,0,0,0,21,0,0
0,0,22,3,23,3,21,0,0
0,0,22,28,15,28,21,0,0
0,0,22,8,0,29,21,0,0
0,0,22,8,0,29,21,0,0
0,0,22,8,0,29,21,0,0
0,0,22,8,0,29,21,0,0
0,0,22,8,0,29,21,0,0
0,0,22,30,31,30,21,0,0
0,0,22,3,23,3,21,0,0
0,0,22,0,0,0,21,0,0
0,0,0,0,0,0,0,0,0
endlayer

layer
0,0,0,0,0,0,0,0,0
0,0,0,22,0,21,0,0,0
0,0,0,22,3,21,0,0,0
0,0,0,22,32,21,0,0,0
0,0,0,22,32,21,0,0,0
0,0,0,22,32,21,0,0,0
0,0,0,22,32,21,0,0,0
0,0,0,22,32,21,0,0,0
0,0,0,22,32,21,0,0,0
0,0,0,22,32,21,0,0,0
0,0,0,22,3,21,0,0,0
0,0,0,22,0,21,0,0,0
0,0,0,0,0,0,0,0,0
endlayer

layer
0,0,0,0,0,0,0,0,0
0,0,0,0,6,0,0,0,0
0,0,0,0,6,0,0,0,0
0,0,0,0,4,0,0,0,0
0,0,0,0,4,0,0,0,0
0,0,0,0,4,0,0,0,0
0,0,0,0,4,0,0,0,0
0,0,0,0,4,0,0,0,0
0,0,0,0,4,0,0,0,0
0,0,0,0,4,0,0,0,0
0,0,0,0,4,0,0,0,0
0,0,0,0,6,0,0,0,0
0,0,0,0,0,0,0,0,0
endlayer

