
# Created by Ruins mod version 17.2 Ingame Parser
# authoring Player: BARTLLOW

# TEMPLATE PARAMETER SETTINGS:
#
# criterion expression specifying mod ids required to load template
# may include plus (AND), minus (AND NOT), comma (OR), and parentheses
# all required mods listed must be present; no prohibited mods can be
requiredMods=
#
# likelihood this template will be chosen relative to all others
# e.g., a weight=6 template is chosen 3X as often as one with weight=2
weight=1
#
# list of dimensions in which this template may spawn, even if generic
# one or more dimension names, separated by commas (blank = all)
dimensionsToSpawnIn=
#
# list of other biomes in which this template may spawn
# biome corresponding to directory is always assumed, listed or not
# generic templates should leave this list empty
biomesToSpawnIn=
#
# criterion expression specifying types of biome where template spawns
# this is in addition to those explicitly listed as biomesToSpawnIn
# generic templates should leave this list empty
biomeTypesToSpawnIn=
#
# list of biomes in which this template may not spawn
# takes precedence over biomeTypesToSpawnIn, but NOT biomesToSpawnIn
# should be empty if biomeTypesToSpawnIn is empty
biomesToNotSpawnIn=
#
# depth template is pushed down into the surface when built
# offset is min/max range of random additional bury depth
embed_into_distance=0
random_height_offset=0,0
#
# whitelist/blacklist of block types on which template may be built
# specify one, not both; leave the other empty (both empty = allow all)
acceptable_target_blocks=
unacceptable_target_blocks=flowing_water,water,flowing_lava,lava
#
# size of template (#layers, #rows per layer, #blocks per row)
dimensions=10,13,27
#
# max number of missing blocks allowed in surface beneath template
allowable_overhang=0
#
# depth/height limit affected by terrain leveling
# also maximum bumpiness tolerated in surface beneath template
max_leveling=2
#
# padding applied to all sides of template horizontal footprint
# expands area affected by terrain leveling (-1 = no leveling)
leveling_buffer=0
#
# do not rotate template randomly when built (1 = no rotation)
preventRotation=0
#
# treat water/lava blocks as air and protect them from rule0 (1 = yes)
preserve_water=0
preserve_lava=0
#
# minimum distance this template must have from instances of itself
uniqueMinDistance=0
#
# min/max distances this template can be from world spawn (0 = no limit)
# only applies to overworld--i.e., dimension 0
spawnMinDistance=0
spawnMaxDistance=0
#
# other template built nearby whenever this one is
# syntax: <name>;<relativeX>;<maxYdifference>;<relativeZ>[;<chance>]
# may be used more than once to specify multiple neighbors
adjoining_template=

rule1=0,100,minecraft:stone-0
rule2=0,100,minecraft:vine-4
rule3=0,100,minecraft:vine-1
rule4=0,100,minecraft:dirt-0
rule5=0,100,minecraft:vine-2
rule6=0,100,minecraft:stonebrick-2
rule7=0,100,minecraft:stonebrick-0
rule8=0,100,minecraft:mob_spawner-0
rule9=0,100,minecraft:stonebrick-1
rule10=0,100,minecraft:vine-9
rule11=0,100,minecraft:stone_slab-0
rule12=0,100,minecraft:stone_brick_stairs-1
rule13=0,100,minecraft:cobblestone-0
rule14=0,100,minecraft:stone_brick_stairs-3
rule15=0,100,minecraft:carpet-14
rule16=2,100,minecraft:torch-4
rule17=0,100,minecraft:double_stone_slab-0
rule18=0,100,minecraft:vine-8
rule19=0,100,minecraft:stone_brick_stairs-0
rule20=0,100,minecraft:mossy_cobblestone-0
rule21=0,100,minecraft:stone_brick_stairs-6
rule22=0,100,minecraft:stone_brick_stairs-7
rule23=0,100,minecraft:stone_brick_stairs-5
rule24=0,100,minecraft:stone_slab-8
rule25=0,100,minecraft:wooden_slab-1
rule26=0,100,minecraft:stained_glass-4
rule27=0,100,minecraft:vine-3
rule28=0,100,minecraft:stone_brick_stairs-4
rule29=0,100,minecraft:vine-6
rule30=0,100,minecraft:stained_glass-1
rule31=0,100,minecraft:vine-12
rule32=0,100,minecraft:stonebrick-3
rule33=0,100,minecraft:stone_brick_stairs-2
rule34=0,100,minecraft:stone_slab-13
rule35=2,100,minecraft:redstone_torch-1
rule36=2,100,minecraft:redstone_torch-2
rule37=0,100,minecraft:wool-14
rule38=0,100,minecraft:stone_stairs-6

layer
0,0,0,0,0,0,0,0,1,1,1,0,0,0,0,0,1,1,1,0,0,0,0,0,0,0,0
0,0,0,0,2,1,1,1,1,1,1,1,1,1,1,1,1,1,1,1,1,1,1,1,0,0,0
0,0,0,0,0,1,1,1,1,1,1,1,1,1,1,1,1,1,1,1,1,1,1,1,1,3,0
0,0,0,2,1,1,1,1,1,1,1,1,1,1,1,1,1,1,1,1,1,1,1,1,1,1,0
0,1,1,1,1,1,1,1,1,1,1,1,1,1,1,1,1,1,1,1,1,1,1,1,1,1,1
1,1,1,1,4,1,1,1,1,1,1,1,1,1,1,1,1,1,1,1,1,1,1,1,1,1,1
1,1,1,1,1,1,1,1,1,1,1,1,1,1,1,1,1,1,1,1,1,1,1,1,1,1,1
1,1,1,1,4,1,1,1,1,1,1,1,1,1,1,1,1,1,1,1,1,1,1,1,1,1,1
2,1,1,1,1,1,1,1,1,1,1,1,1,1,1,1,1,1,1,1,1,1,1,1,1,1,1
0,5,0,2,1,1,1,1,1,1,1,1,1,1,1,1,1,1,1,1,1,1,1,1,1,1,3
0,0,0,0,5,1,1,1,1,1,1,1,1,1,1,1,1,1,1,1,1,1,1,1,1,0,0
0,0,0,0,2,1,1,1,1,1,1,1,1,1,1,1,1,1,1,1,1,1,1,1,3,0,0
0,0,0,0,0,0,0,0,1,1,1,3,5,0,5,5,1,1,1,3,0,0,0,0,0,0,0
endlayer

layer
0,0,0,0,0,0,0,0,6,7,7,0,0,0,0,0,7,6,6,0,0,0,0,0,0,0,0
0,0,0,0,2,7,7,7,7,8,6,7,9,7,7,6,7,8,7,7,7,6,6,6,0,0,0
0,0,0,0,0,9,11,11,11,7,11,11,11,6,11,11,11,6,7,7,9,7,7,7,7,10,0
0,0,0,2,7,12,0,0,0,12,0,0,2,12,3,0,13,12,6,6,7,6,6,6,2,7,0
2,7,7,6,0,0,0,0,0,0,0,0,0,0,0,0,0,0,0,0,15,0,14,7,0,0,7
7,17,17,3,7,13,0,0,0,0,0,13,13,0,0,0,0,0,0,15,0,15,0,14,7,16,6
7,13,2,13,13,0,0,0,0,0,0,0,5,0,0,0,0,0,15,15,11,11,0,0,7,16,7
7,17,17,11,9,0,0,0,0,0,0,0,0,0,0,0,0,0,13,15,0,0,0,14,6,16,7
0,7,7,9,5,0,0,0,0,0,0,0,0,0,0,0,0,0,5,0,0,15,14,7,5,18,6
0,5,0,2,7,19,20,0,0,19,0,0,0,19,0,0,0,19,7,7,7,6,7,7,0,7,3
0,0,0,0,5,7,11,11,11,7,11,11,11,9,11,0,11,7,6,6,7,7,7,6,7,0,0
0,0,0,0,2,9,7,7,9,8,7,7,7,6,7,7,6,8,6,7,6,7,7,7,3,0,0
0,0,0,0,0,5,0,0,22,21,7,3,0,0,5,5,9,7,9,3,0,0,0,0,0,0,0
endlayer

layer
0,0,0,0,0,0,0,0,6,7,21,18,0,0,0,0,6,6,7,0,18,0,0,0,0,0,0
0,0,0,0,2,6,23,7,23,6,23,7,23,9,23,7,23,7,7,7,7,6,7,7,0,0,0
0,0,0,0,2,7,24,24,24,6,24,24,24,6,24,24,24,7,7,7,6,6,7,7,6,10,0
0,0,0,2,6,23,0,0,0,23,0,0,2,23,3,0,2,23,25,0,25,25,25,7,2,7,0
2,6,9,7,0,0,0,0,0,0,0,0,0,0,0,0,0,0,0,0,0,0,0,6,3,0,6
6,17,17,0,7,0,0,0,0,0,0,0,0,0,0,0,2,0,3,0,0,0,0,0,26,2,7
7,0,0,0,0,3,0,0,0,0,0,0,0,0,0,0,0,0,0,0,0,0,0,0,26,0,19
6,11,13,0,9,0,0,0,0,0,0,0,0,0,0,0,0,0,0,0,0,0,0,0,26,2,7
0,6,12,7,5,0,0,0,0,0,0,0,2,0,0,0,2,0,0,0,0,0,0,7,0,18,7
0,5,0,0,7,28,0,0,0,28,0,0,0,28,0,0,0,28,18,0,25,25,0,7,0,7,27
0,0,0,0,5,7,24,24,24,6,24,24,24,7,24,24,24,6,7,9,7,7,6,7,9,3,0
0,0,0,0,0,7,28,6,28,7,28,6,28,7,28,7,28,7,9,6,7,9,23,7,3,0,0
0,0,0,0,0,5,0,5,7,6,7,0,0,0,5,29,7,7,6,0,5,0,0,0,0,0,0
endlayer

layer
0,0,0,0,0,0,0,0,18,0,0,0,0,0,0,0,0,0,0,18,18,0,0,0,0,0,0
0,0,0,0,2,9,12,7,12,9,12,7,12,7,12,7,12,7,7,7,9,9,7,6,0,0,0
0,0,0,0,2,7,0,25,25,9,3,25,0,7,25,25,25,7,12,0,0,13,12,9,6,0,0
0,0,0,2,7,12,0,0,0,12,0,0,2,6,3,0,2,6,0,0,0,0,0,6,2,7,0
0,7,7,6,0,0,0,0,0,0,0,0,0,23,0,0,0,23,0,0,0,0,0,14,0,0,6
7,11,13,17,7,0,0,0,0,0,0,0,0,0,0,0,2,0,3,0,0,0,0,0,26,2,7
7,0,0,0,7,3,0,0,0,0,0,0,0,0,0,0,0,0,0,0,0,0,0,0,30,2,9
7,0,0,0,7,0,0,0,0,0,0,0,0,0,0,0,0,0,0,0,0,0,0,0,26,2,7
2,6,7,6,5,0,18,0,0,0,0,0,2,28,0,0,2,28,0,0,0,0,0,9,0,31,6
0,5,0,0,6,19,0,0,0,19,0,0,0,7,0,0,2,6,0,0,0,0,0,9,3,7,0
0,0,0,0,5,6,0,0,25,7,25,25,0,22,0,0,25,7,19,0,0,0,19,7,6,3,0
0,0,0,0,0,7,19,6,19,7,19,7,19,7,19,6,19,7,7,9,7,7,9,7,3,0,0
0,0,0,0,0,5,0,0,0,0,0,0,0,0,5,0,0,0,5,0,0,0,0,0,0,0,0
endlayer

layer
0,0,0,0,0,0,0,0,18,0,0,0,0,0,0,0,0,0,0,18,0,0,0,0,0,0,0
0,0,0,0,0,23,6,7,6,6,7,6,33,7,7,6,7,7,7,6,32,32,6,6,0,0,0
0,0,0,0,2,7,23,23,23,7,23,23,23,7,23,23,23,9,0,0,0,0,5,7,7,3,0
0,0,0,0,7,23,34,34,34,23,34,34,34,7,34,34,34,6,0,0,0,0,0,7,0,7,0
0,7,7,9,0,0,0,0,0,0,0,0,0,7,0,0,0,6,0,0,0,0,0,0,26,0,7
6,0,13,11,7,0,0,0,0,0,0,0,0,6,0,0,2,7,3,0,0,0,0,0,26,0,6
6,0,0,0,7,3,0,0,0,0,0,0,0,7,0,0,0,7,0,0,0,0,0,0,30,0,6
7,0,0,0,7,0,0,0,0,0,0,0,0,6,0,0,0,6,0,0,0,0,0,0,26,2,6
5,7,6,7,0,0,18,0,0,0,0,0,2,7,0,0,2,7,0,0,0,0,0,0,26,0,9
0,0,0,0,7,28,34,34,34,28,34,34,34,9,34,34,34,7,0,0,0,0,0,6,0,23,0
0,0,0,0,5,7,28,28,28,7,28,28,28,7,28,28,28,7,0,0,0,0,0,7,9,3,0
0,0,0,0,0,6,7,7,7,7,9,6,6,7,6,7,7,9,7,32,6,6,7,6,0,0,0
0,0,0,0,0,5,0,0,0,0,0,0,0,5,0,5,0,0,0,5,0,0,0,0,0,0,0
endlayer

layer
0,0,0,0,0,0,0,0,0,0,0,0,0,0,0,0,0,0,0,18,18,0,0,0,0,0,0
0,0,0,0,0,0,0,0,0,0,0,0,0,0,0,0,0,6,7,32,6,32,28,7,0,0,0
0,0,0,0,0,0,0,0,18,0,0,0,0,0,0,0,0,7,0,0,0,0,0,7,7,3,0
0,0,0,0,6,7,7,6,6,6,6,7,6,7,6,7,19,7,0,0,0,0,0,7,3,9,0
2,7,7,7,7,0,0,0,0,35,0,0,0,6,3,0,0,7,0,0,0,0,0,0,26,0,7
7,5,0,0,6,0,0,0,0,0,0,0,0,9,0,0,2,7,28,0,0,0,0,0,30,0,7
9,0,0,0,6,0,0,0,0,0,0,0,0,6,0,0,0,7,21,0,0,0,0,0,30,0,6
7,0,0,0,6,0,0,0,0,0,0,0,0,7,0,0,0,6,23,0,0,0,0,0,30,0,6
5,6,7,7,19,0,18,0,0,36,0,0,2,7,0,0,0,6,0,0,0,0,0,0,26,0,6
0,0,5,0,7,9,6,6,7,7,7,7,7,6,7,6,6,6,0,0,0,0,0,7,0,7,0
0,0,0,0,0,0,0,0,0,0,0,0,0,0,0,0,0,7,0,0,0,0,0,7,7,3,0
0,0,0,0,0,0,0,0,0,0,0,0,0,0,0,0,0,6,7,32,32,6,7,6,0,0,0
0,0,0,0,0,0,0,0,0,0,0,0,0,0,0,0,0,0,0,5,0,0,0,0,0,0,0
endlayer

layer
0,0,0,0,0,0,0,0,0,0,0,0,0,0,0,0,0,0,0,18,0,0,0,18,0,0,0
0,0,0,0,0,0,0,0,0,0,0,0,0,0,0,0,0,7,7,9,6,6,7,7,0,0,0
0,0,0,0,0,0,0,0,0,0,0,0,0,0,0,0,0,7,23,0,0,0,23,7,6,3,0
0,0,0,0,0,0,0,0,18,18,18,0,0,18,0,0,0,7,0,0,0,0,0,6,3,6,18
2,7,7,7,7,9,7,6,7,6,7,7,19,7,28,6,7,7,28,0,0,0,0,0,26,0,7
7,0,2,13,7,7,7,6,32,7,7,7,6,23,7,6,6,6,6,3,0,0,0,0,26,0,9
7,0,0,13,7,7,9,7,7,32,6,6,7,7,6,32,7,9,37,0,0,0,0,0,30,2,7
7,13,13,13,6,7,7,7,6,6,32,32,7,7,7,6,6,7,7,0,0,0,0,0,26,2,7
5,7,6,7,19,7,7,6,7,7,7,6,7,7,9,9,21,9,23,0,0,0,0,0,26,0,9
0,0,0,0,0,0,0,5,0,0,0,0,0,0,0,0,2,7,0,0,0,0,0,9,0,6,0
0,0,0,0,0,0,0,0,0,0,0,0,0,0,0,0,0,6,28,0,0,0,28,7,6,0,0
0,0,0,0,0,0,0,0,0,0,0,0,0,0,0,0,0,7,7,7,7,6,7,7,0,0,0
0,0,0,0,0,0,0,0,0,0,0,0,0,0,0,0,0,0,0,0,0,0,0,0,0,0,0
endlayer

layer
0,0,0,0,0,0,0,0,0,0,0,0,0,0,0,0,0,18,18,18,0,0,0,0,0,0,0
0,0,0,0,0,0,0,0,0,0,0,0,0,0,0,0,0,6,6,6,7,7,9,7,0,0,0
0,0,0,0,0,0,0,0,0,0,0,0,0,0,0,0,0,7,6,9,6,7,7,7,7,10,0
0,0,0,0,0,0,0,0,0,0,0,0,0,0,0,0,0,6,7,0,0,0,0,7,3,7,18
0,7,7,0,0,0,0,0,0,0,0,0,0,0,0,0,0,7,7,0,0,0,0,9,0,2,7
7,0,13,0,0,0,0,13,13,0,0,0,0,0,0,0,2,7,37,0,0,0,0,0,26,0,7
6,0,13,0,0,0,0,0,0,0,0,0,0,0,0,0,2,9,37,0,0,0,0,0,26,2,7
6,3,13,0,0,0,0,13,13,13,0,0,0,0,0,0,0,6,37,0,0,0,0,0,26,2,7
5,6,6,0,0,0,0,0,0,0,0,0,0,0,0,0,0,7,7,0,0,0,0,7,0,0,7
0,0,0,0,0,0,0,0,0,0,0,0,0,0,0,0,2,7,7,0,0,0,0,7,0,7,0
0,0,0,0,0,0,0,0,0,0,0,0,0,0,0,0,0,9,7,7,7,7,6,6,7,0,0
0,0,0,0,0,0,0,0,0,0,0,0,0,0,0,0,0,6,6,6,6,7,14,7,0,0,0
0,0,0,0,0,0,0,0,0,0,0,0,0,0,0,0,0,0,0,0,0,0,0,0,0,0,0
endlayer

layer
0,0,0,0,0,0,0,0,0,0,0,0,0,0,0,0,0,0,18,18,0,0,0,0,0,0,0
0,0,0,0,0,0,0,0,0,0,0,0,0,0,0,0,0,7,7,6,7,7,6,7,0,0,0
0,0,0,0,0,0,0,0,0,0,0,0,0,0,0,0,0,6,7,6,6,6,6,7,6,0,0
0,0,0,0,0,0,0,0,0,0,0,0,0,0,0,0,0,7,7,6,7,7,9,6,3,6,0
0,0,0,0,0,0,0,0,0,0,0,0,0,0,0,0,0,9,6,7,7,6,7,6,0,2,6
0,13,0,0,0,0,0,0,0,0,0,0,0,0,0,0,2,7,33,7,9,32,6,7,16,0,7
13,13,13,0,0,0,0,0,0,0,0,0,0,0,0,0,2,7,7,9,6,32,32,7,3,0,7
13,13,5,0,0,0,0,0,0,0,0,0,0,0,0,0,0,7,9,9,7,9,6,7,16,0,9
0,0,38,0,0,0,0,0,0,0,0,0,0,0,0,0,0,6,6,9,6,7,6,6,0,0,7
0,0,0,0,0,0,0,0,0,0,0,0,0,0,0,0,0,7,6,6,9,9,7,7,0,7,0
0,0,0,0,0,0,0,0,0,0,0,0,0,0,0,0,0,7,6,9,7,7,7,7,6,0,0
0,0,0,0,0,0,0,0,0,0,0,0,0,0,0,0,0,0,7,7,7,7,7,7,0,0,0
0,0,0,0,0,0,0,0,0,0,0,0,0,0,0,0,0,0,0,0,5,0,0,0,0,0,0
endlayer

layer
0,0,0,0,0,0,0,0,0,0,0,0,0,0,0,0,0,0,0,0,0,0,0,0,0,0,0
0,0,0,0,0,0,0,0,0,0,0,0,0,0,0,0,0,0,0,0,0,0,0,0,0,0,0
0,0,0,0,0,0,0,0,0,0,0,0,0,0,0,0,0,0,0,0,0,0,0,0,7,0,0
0,0,0,0,0,0,0,0,0,0,0,0,0,0,0,0,0,0,0,0,0,0,0,2,7,9,0
0,0,0,0,0,0,0,0,0,0,0,0,0,0,0,0,0,0,0,0,0,0,0,0,7,7,7
0,0,0,0,0,0,0,0,0,0,0,0,0,0,0,0,0,0,0,0,0,0,0,0,6,7,7
0,0,0,0,0,0,0,0,0,0,0,0,0,0,0,0,0,0,0,0,0,0,0,0,7,9,7
0,0,0,0,0,0,0,0,0,0,0,0,0,0,0,0,0,0,0,0,0,0,0,0,7,7,6
0,0,0,0,0,0,0,0,0,0,0,0,0,0,0,0,0,0,0,0,0,0,0,0,6,7,6
0,0,0,0,0,0,0,0,0,0,0,0,0,0,0,0,0,0,0,0,0,0,0,0,6,6,0
0,0,0,0,0,0,0,0,0,0,0,0,0,0,0,0,0,0,0,0,0,0,0,0,7,0,0
0,0,0,0,0,0,0,0,0,0,0,0,0,0,0,0,0,0,0,0,0,0,0,0,0,0,0
0,0,0,0,0,0,0,0,0,0,0,0,0,0,0,0,0,0,0,0,0,0,0,0,0,0,0
endlayer

