
# Created by Ruins mod version 17.2 Ingame Parser
# authoring Player: BARTLLOW

# TEMPLATE PARAMETER SETTINGS:
#
# criterion expression specifying mod ids required to load template
# may include plus (AND), minus (AND NOT), comma (OR), and parentheses
# all required mods listed must be present; no prohibited mods can be
requiredMods=
#
# likelihood this template will be chosen relative to all others
# e.g., a weight=6 template is chosen 3X as often as one with weight=2
weight=1
#
# list of dimensions in which this template may spawn, even if generic
# one or more dimension names, separated by commas (blank = all)
dimensionsToSpawnIn=
#
# list of other biomes in which this template may spawn
# biome corresponding to directory is always assumed, listed or not
# generic templates should leave this list empty
biomesToSpawnIn=
#
# criterion expression specifying types of biome where template spawns
# this is in addition to those explicitly listed as biomesToSpawnIn
# generic templates should leave this list empty
biomeTypesToSpawnIn=
#
# list of biomes in which this template may not spawn
# takes precedence over biomeTypesToSpawnIn, but NOT biomesToSpawnIn
# should be empty if biomeTypesToSpawnIn is empty
biomesToNotSpawnIn=
#
# depth template is pushed down into the surface when built
# offset is min/max range of random additional bury depth
embed_into_distance=0
random_height_offset=0,0
#
# whitelist/blacklist of block types on which template may be built
# specify one, not both; leave the other empty (both empty = allow all)
acceptable_target_blocks=
unacceptable_target_blocks=flowing_water,water,flowing_lava,lava
#
# size of template (#layers, #rows per layer, #blocks per row)
dimensions=25,27,23
#
# max number of missing blocks allowed in surface beneath template
allowable_overhang=0
#
# depth/height limit affected by terrain leveling
# also maximum bumpiness tolerated in surface beneath template
max_leveling=2
#
# padding applied to all sides of template horizontal footprint
# expands area affected by terrain leveling (-1 = no leveling)
leveling_buffer=0
#
# do not rotate template randomly when built (1 = no rotation)
preventRotation=0
#
# treat water/lava blocks as air and protect them from rule0 (1 = yes)
preserve_water=0
preserve_lava=0
#
# minimum distance this template must have from instances of itself
uniqueMinDistance=0
#
# min/max distances this template can be from world spawn (0 = no limit)
# only applies to overworld--i.e., dimension 0
spawnMinDistance=0
spawnMaxDistance=0
#
# other template built nearby whenever this one is
# syntax: <name>;<relativeX>;<maxYdifference>;<relativeZ>[;<chance>]
# may be used more than once to specify multiple neighbors
adjoining_template=

rule1=0,100,minecraft:dirt-0
rule2=0,100,minecraft:grass-0
rule3=0,100,minecraft:water-9
rule4=0,100,minecraft:water-1
rule5=0,100,minecraft:water-2
rule6=0,100,minecraft:water-3
rule7=0,100,minecraft:water-4
rule8=0,100,minecraft:stone-0
rule9=0,100,minecraft:redstone_ore-0
rule10=0,100,minecraft:lit_redstone_ore-0
rule11=0,100,minecraft:log-8
rule12=0,100,minecraft:water-8
rule13=0,100,minecraft:leaves-4
rule14=0,100,minecraft:web-0
rule15=0,100,minecraft:log-0
rule16=0,100,minecraft:tallgrass-1
rule17=0,100,minecraft:double_plant-2
rule18=0,100,minecraft:red_mushroom_block-1
rule19=0,100,minecraft:log-4
rule20=0,100,minecraft:red_mushroom_block-14
rule21=0,100,minecraft:red_mushroom_block-2
rule22=0,100,minecraft:water-0
rule23=0,100,minecraft:mob_spawner-0
rule24=0,100,minecraft:leaves-12
rule25=0,100,minecraft:double_plant-10
rule26=0,100,minecraft:vine-9
rule27=0,100,minecraft:vine-1
rule28=0,100,minecraft:red_mushroom_block-7
rule29=0,100,minecraft:red_mushroom_block-9
rule30=0,100,minecraft:vine-2
rule31=0,100,minecraft:red_mushroom_block-3
rule32=0,100,minecraft:vine-8
rule33=0,100,minecraft:vine-4
rule34=0,100,minecraft:vine-3
rule35=0,100,minecraft:brown_mushroom_block-1
rule36=0,100,minecraft:brown_mushroom_block-7
rule37=0,100,minecraft:brown_mushroom_block-2
rule38=0,100,minecraft:brown_mushroom_block-9
rule39=0,100,minecraft:brown_mushroom_block-3
rule40=0,100,minecraft:brown_mushroom_block-4
rule41=0,100,minecraft:brown_mushroom_block-6
rule42=0,100,minecraft:vine-6
rule43=0,100,minecraft:vine-12

layer
0,0,0,0,0,0,0,0,0,0,0,0,0,0,0,0,0,0,0,0,0,0,0
0,0,0,0,0,0,0,0,0,1,1,1,1,1,1,1,1,0,0,0,0,0,0
0,0,0,0,0,0,0,0,0,1,1,1,1,1,1,1,1,0,0,0,0,0,0
0,0,0,0,0,0,0,0,0,1,1,1,1,1,1,1,1,0,0,0,0,0,0
0,0,0,0,0,0,0,1,1,1,1,1,1,1,1,1,1,0,0,0,0,0,0
0,0,0,0,0,0,0,1,1,1,1,1,1,1,1,1,1,1,1,1,1,0,0
0,0,0,0,0,0,0,0,0,1,1,1,1,1,1,1,1,1,1,1,1,0,0
0,0,0,0,0,0,0,0,0,1,1,1,1,1,1,1,1,1,1,1,1,0,0
0,0,0,0,0,0,0,0,0,1,1,1,1,1,1,1,1,1,1,1,1,0,0
0,0,0,0,0,0,0,0,0,1,1,1,1,1,1,1,1,1,1,1,1,0,0
0,0,0,0,1,1,1,1,1,1,1,1,1,1,1,1,1,1,1,1,1,0,0
0,0,0,0,1,1,1,1,1,1,1,1,1,1,1,1,1,1,1,0,0,0,0
0,0,0,0,1,1,1,1,1,1,1,1,2,1,1,1,1,1,1,0,0,0,0
0,0,0,0,1,1,1,1,1,1,1,1,1,1,1,1,1,0,0,0,0,0,0
0,0,0,1,1,1,1,1,1,1,1,1,1,1,1,1,1,0,0,0,0,0,0
0,0,0,1,1,1,1,1,1,1,1,1,1,1,1,1,1,0,0,0,0,0,0
0,0,0,1,1,1,1,1,1,1,1,1,1,1,1,1,1,0,0,0,0,0,0
0,0,1,1,1,1,1,1,1,1,1,1,1,1,1,1,1,0,0,0,0,0,0
0,0,1,1,1,1,1,1,1,1,1,1,1,1,1,1,0,0,0,0,0,0,0
0,0,0,1,1,1,1,1,1,1,1,1,1,1,1,0,0,0,0,0,0,0,0
0,0,0,0,1,1,1,1,1,1,1,1,0,0,0,0,0,0,0,0,0,0,0
0,0,0,0,1,1,1,1,1,1,1,1,0,0,0,0,0,0,0,0,0,0,0
0,0,0,0,0,0,0,0,0,0,0,0,0,0,0,0,0,0,0,0,0,0,0
0,0,0,0,0,0,0,0,0,0,0,0,0,0,0,0,0,0,0,0,0,0,0
0,0,0,0,0,0,0,0,0,0,0,0,0,0,0,0,0,0,0,0,0,0,0
0,0,0,0,0,0,0,0,0,0,0,0,0,0,0,0,0,0,0,0,0,0,0
0,0,0,0,0,0,0,0,0,0,0,0,0,0,0,0,0,0,0,0,0,0,0
endlayer

layer
0,0,0,0,0,0,0,0,0,0,0,0,1,1,1,1,0,0,0,0,0,0,0
0,0,0,0,0,0,0,0,0,2,2,1,1,1,1,1,1,0,0,0,0,0,0
0,0,0,0,0,0,0,0,1,1,1,1,2,1,2,1,1,0,0,0,0,0,0
0,0,0,0,0,0,0,1,1,1,1,1,1,1,1,1,1,1,0,0,0,0,0
0,0,0,0,0,0,0,1,2,1,2,1,2,1,1,1,1,1,0,0,0,0,0
0,0,0,0,0,0,0,1,2,2,1,1,2,2,1,1,1,1,1,2,2,0,0
0,0,0,0,0,0,0,1,1,2,2,2,2,1,1,2,2,2,1,2,2,0,0
0,0,0,0,0,0,0,1,0,1,1,1,1,1,1,1,2,2,2,1,1,0,0
0,0,0,0,0,0,0,0,1,1,1,2,1,1,1,1,1,1,1,2,1,0,0
0,0,0,0,0,0,1,1,1,1,1,1,1,1,2,2,2,1,1,1,1,0,0
0,0,0,0,1,1,1,1,1,1,1,1,1,1,2,1,1,1,2,1,1,0,0
0,0,0,1,1,1,1,1,1,2,1,2,1,2,1,2,1,1,1,1,0,0,0
0,0,0,1,2,1,1,2,1,2,2,2,1,2,2,1,1,1,1,0,0,0,0
0,0,0,1,1,1,2,2,2,1,2,1,2,1,2,1,1,1,0,0,0,0,0
0,0,1,1,1,1,2,1,1,1,1,1,1,1,1,1,1,0,0,0,0,0,0
0,1,1,2,1,1,2,1,1,1,1,2,1,1,1,1,1,0,0,0,0,0,0
0,1,1,1,2,1,1,1,1,2,1,1,1,2,2,1,1,0,0,0,0,0,0
0,1,1,1,2,1,1,1,1,2,1,1,1,2,1,1,1,0,0,0,0,0,0
0,1,1,1,2,2,1,1,2,1,1,2,1,1,1,1,0,0,0,0,0,0,0
0,1,1,2,2,2,2,1,2,1,1,1,1,1,1,0,0,0,0,0,0,0,0
0,0,1,1,1,1,2,2,1,1,1,1,1,1,1,0,0,0,0,0,0,0,0
0,0,1,1,1,2,2,1,1,1,1,1,1,1,0,0,0,0,0,0,0,0,0
0,0,0,0,1,1,1,1,1,1,1,1,0,0,0,0,0,0,0,0,0,0,0
0,0,0,0,0,0,0,1,1,1,1,1,0,0,0,0,0,0,0,0,0,0,0
0,0,0,0,0,0,0,0,1,1,1,0,0,0,0,0,0,0,0,0,0,0,0
0,0,0,0,0,0,0,0,0,0,0,0,0,0,0,0,0,0,0,0,0,0,0
0,0,0,0,0,0,0,0,0,0,0,0,0,0,0,0,0,0,0,0,0,0,0
endlayer

layer
0,0,0,0,0,0,0,0,0,0,0,0,1,1,1,1,0,0,0,0,0,0,0
0,0,0,0,0,0,0,0,0,0,0,1,2,4,3,1,1,0,0,0,0,0,0
0,0,0,0,0,0,0,0,1,1,1,1,5,4,3,3,1,0,0,0,0,0,0
0,0,0,0,0,0,0,1,1,2,2,7,6,5,4,3,1,1,0,0,0,0,0
0,0,0,0,0,0,0,1,0,2,1,2,7,6,8,8,8,1,0,0,0,0,0
0,0,0,0,0,0,0,1,0,0,2,2,8,8,1,1,1,1,1,0,0,0,0
0,0,0,0,0,0,0,1,2,8,0,0,0,2,2,0,0,0,1,0,0,0,0
0,0,0,0,0,0,0,1,2,2,8,8,2,1,2,2,8,8,0,1,1,0,0
0,0,0,0,0,0,0,0,1,2,2,8,2,1,1,8,10,9,8,0,1,0,0
0,0,0,0,0,0,1,1,2,2,2,2,2,2,0,9,10,8,8,2,1,0,0
0,0,0,0,1,1,2,8,8,1,1,1,8,2,0,8,8,8,8,1,1,0,0
0,0,0,1,2,3,4,5,2,2,1,1,1,2,8,0,8,8,1,1,0,0,0
0,0,0,1,8,8,5,2,2,1,2,2,1,2,2,8,8,1,1,1,0,0,0
0,0,0,1,8,8,2,1,1,1,1,2,1,2,2,8,2,1,0,0,0,0,0
0,0,1,2,8,2,2,1,2,1,1,1,1,1,2,8,1,1,0,0,0,0,0
0,1,1,8,8,8,2,1,1,1,1,1,1,2,2,2,1,1,0,0,0,0,0
0,1,1,8,0,8,8,2,1,2,1,1,1,2,8,1,1,1,0,0,0,0,0
0,1,1,1,0,8,8,8,2,1,1,2,2,2,8,2,0,1,0,0,0,0,0
0,1,9,8,0,0,8,2,2,2,2,2,2,1,2,1,1,1,0,0,0,0,0
0,1,1,0,0,0,0,2,8,8,8,8,1,1,1,1,1,0,0,0,0,0,0
0,0,1,2,11,11,0,8,8,8,8,8,2,1,1,1,0,0,0,0,0,0,0
0,0,1,1,2,0,0,8,8,8,2,2,1,1,0,0,0,0,0,0,0,0,0
0,0,0,0,1,1,1,1,2,2,2,1,1,1,1,0,0,0,0,0,0,0,0
0,0,0,0,0,0,0,1,1,2,2,1,0,0,0,0,0,0,0,0,0,0,0
0,0,0,0,0,0,0,0,1,1,1,0,0,0,0,0,0,0,0,0,0,0,0
0,0,0,0,0,0,0,0,0,0,0,0,0,0,0,0,0,0,0,0,0,0,0
0,0,0,0,0,0,0,0,0,0,0,0,0,0,0,0,0,0,0,0,0,0,0
endlayer

layer
0,0,0,0,0,0,0,0,0,0,0,1,1,1,1,1,0,0,0,0,0,0,0
0,0,0,0,0,0,0,0,1,0,0,2,13,0,4,12,1,0,0,0,0,0,0
0,0,0,0,0,0,0,0,0,2,2,2,0,0,4,3,1,0,0,0,0,0,0
0,0,0,0,0,0,0,1,1,14,0,0,0,0,0,4,1,1,0,0,0,0,0
0,0,0,0,0,0,1,1,0,0,15,0,0,0,0,8,0,1,1,0,0,0,0
0,0,0,0,0,0,1,2,13,0,0,0,0,0,11,11,11,1,1,1,0,0,0
0,0,0,0,0,0,1,1,13,0,0,0,0,0,0,0,0,0,2,1,0,0,0
0,0,0,0,0,0,1,2,13,0,0,0,0,2,0,0,0,0,0,2,1,0,0
0,0,0,0,0,0,1,1,2,16,0,0,0,1,2,0,0,8,0,0,1,1,0
0,0,0,0,1,1,1,2,14,0,0,16,17,0,0,9,0,0,0,0,2,1,0
0,0,0,1,1,2,0,8,0,11,19,18,0,16,0,0,0,0,0,2,1,1,0
0,0,0,1,3,4,0,0,17,0,19,21,20,17,0,0,11,11,11,2,1,1,0
0,0,1,2,8,0,0,17,15,15,15,15,15,16,17,0,0,19,2,1,1,1,0
0,0,1,2,0,0,16,15,15,15,15,15,15,14,14,0,0,2,1,1,1,0,0
0,0,1,19,0,17,14,15,15,15,15,15,15,15,0,0,2,2,1,1,1,0,0
1,1,8,0,0,0,14,15,15,15,15,15,15,17,0,0,2,2,1,0,0,0,0
1,1,9,0,0,0,0,14,15,15,15,15,15,17,0,2,2,2,1,0,0,0,0
1,1,9,9,0,0,0,0,17,15,15,15,17,16,0,0,2,2,1,0,0,0,0
1,1,8,0,0,0,0,17,0,0,14,14,0,2,0,2,2,1,1,1,0,0,0
1,1,8,0,0,0,0,16,0,0,8,0,2,1,1,2,1,1,1,1,1,0,0
0,1,2,0,0,0,0,0,0,8,8,0,0,2,2,1,1,1,1,0,0,0,0
0,1,2,2,0,0,0,0,0,0,0,0,2,2,0,1,1,0,0,0,0,0,0
0,1,1,1,2,2,2,2,0,0,0,2,1,1,1,0,0,0,0,0,0,0,0
0,0,0,0,1,1,1,1,0,0,0,1,1,0,0,0,0,0,0,0,0,0,0
0,0,0,0,0,0,0,0,1,1,1,0,0,0,0,0,0,0,0,0,0,0,0
0,0,0,0,0,0,0,0,0,0,0,0,0,0,0,0,0,0,0,0,0,0,0
0,0,0,0,0,0,0,0,0,0,0,0,0,0,0,0,0,0,0,0,0,0,0
endlayer

layer
0,0,0,0,0,0,0,0,0,0,0,1,1,1,1,1,0,0,0,0,0,0,0
0,0,0,0,0,0,0,0,1,1,1,13,0,0,8,22,1,0,0,0,0,0,0
0,0,0,0,0,0,0,0,1,14,0,13,0,0,8,4,1,0,0,0,0,0,0
0,0,0,0,0,0,0,1,1,0,0,0,0,0,0,8,1,1,0,0,0,0,0
0,0,0,0,0,0,1,9,0,0,19,0,0,0,0,8,0,1,1,0,0,0,0
0,0,0,0,0,0,1,13,0,11,19,0,0,0,0,0,0,1,0,1,0,0,0
0,0,0,0,0,0,1,15,13,0,15,0,0,0,0,0,0,1,0,1,0,0,0
0,0,0,0,0,0,1,23,13,0,0,0,0,0,0,0,0,0,0,0,1,0,0
0,0,0,0,0,0,1,1,14,0,0,0,0,1,0,0,0,0,0,0,2,1,0
0,0,0,0,1,1,8,0,0,14,19,0,25,0,0,0,0,0,0,0,24,1,0
0,0,0,1,22,0,0,0,0,0,19,0,0,0,0,0,0,0,0,24,15,2,1
0,0,0,1,4,0,0,0,25,0,15,0,0,25,0,0,0,0,0,24,2,1,0
0,0,1,0,0,0,0,25,15,15,15,15,15,0,25,0,0,0,0,2,2,1,0
0,0,1,0,0,0,0,0,15,15,15,15,15,14,0,0,0,0,2,2,1,0,0
1,1,2,0,0,25,0,14,15,15,15,15,15,0,0,0,0,0,2,2,1,0,0
1,2,14,0,0,0,0,0,15,15,15,15,15,25,0,0,0,0,2,0,0,0,0
1,9,14,0,0,0,0,0,15,15,15,15,15,25,0,0,0,0,2,0,0,0,0
1,8,9,10,0,0,0,0,25,0,14,0,25,0,0,0,0,0,2,0,0,0,0
1,8,9,0,0,0,0,25,0,0,0,0,0,0,0,0,0,2,2,1,0,0,0
1,8,0,0,0,0,0,24,24,13,13,13,0,1,2,0,2,2,2,2,1,0,0
0,1,0,0,0,0,0,24,24,15,13,13,0,0,0,1,1,2,1,1,0,0,0
0,1,0,0,0,0,0,0,24,19,13,13,0,0,1,1,1,1,1,0,0,0,0
0,1,1,1,26,0,0,0,0,19,0,0,1,1,1,0,0,0,0,0,0,0,0
0,0,0,0,1,1,1,2,2,1,1,2,2,1,0,0,0,0,0,0,0,0,0
0,0,0,0,0,0,0,1,2,2,1,1,1,1,0,0,0,0,0,0,0,0,0
0,0,0,0,0,0,0,0,1,1,1,0,0,0,0,0,0,0,0,0,0,0,0
0,0,0,0,0,0,0,0,0,0,0,0,0,0,0,0,0,0,0,0,0,0,0
endlayer

layer
0,0,0,0,0,0,0,0,0,0,0,1,1,2,2,2,0,0,0,0,0,0,0
0,0,0,0,0,0,0,0,1,1,1,13,0,0,0,1,1,0,0,0,0,0,0
0,0,0,0,0,0,0,0,1,0,0,0,0,0,0,0,2,0,0,0,0,0,0
0,0,0,0,0,0,1,1,1,0,0,0,0,0,0,1,1,1,0,0,0,0,0
0,0,0,0,0,0,1,9,9,0,0,0,0,0,0,0,14,1,1,0,0,0,0
0,0,0,0,0,0,1,27,0,0,0,0,0,0,0,0,1,2,2,2,0,0,0
0,0,0,0,0,0,1,13,13,28,19,0,0,0,0,0,14,1,0,1,0,0,0
0,0,0,0,0,0,1,13,13,29,19,0,0,0,0,0,0,0,0,0,1,0,0
0,0,0,0,0,0,1,1,0,11,19,0,0,2,0,0,0,0,0,0,14,1,0
0,0,0,0,1,1,0,0,0,0,15,0,0,0,0,0,0,0,0,0,24,1,0
0,0,0,1,0,30,0,0,0,0,0,0,0,0,0,0,0,0,0,24,24,24,1
0,0,0,1,0,0,0,0,0,15,15,0,0,0,0,0,0,0,0,0,24,2,1
0,0,1,0,0,0,0,0,0,15,15,15,0,0,0,0,0,0,0,0,0,1,0
0,0,1,0,0,0,0,0,15,15,15,23,15,0,0,0,24,0,0,14,1,0,0
1,1,0,0,0,0,0,28,15,15,15,15,15,11,0,24,24,24,0,14,1,0,0
1,0,0,0,0,0,0,28,15,15,15,15,15,11,11,24,19,24,0,1,0,0,0
1,0,0,0,0,0,0,29,31,15,15,15,0,0,19,11,11,24,0,2,0,0,0
1,0,0,0,0,0,0,0,0,19,19,0,0,0,19,11,0,0,0,2,0,0,0
1,0,0,0,0,0,0,0,0,19,0,0,0,0,0,19,11,0,0,1,0,0,0
1,0,0,0,0,0,0,0,24,19,13,0,0,1,0,19,0,0,0,0,1,0,0
0,1,0,0,0,0,0,24,11,19,11,13,24,0,0,19,11,0,2,1,1,0,0
0,1,0,0,0,0,0,0,24,13,13,0,0,0,1,1,1,1,1,0,0,0,0
0,1,1,1,26,32,0,0,0,0,0,0,1,1,1,0,0,0,0,0,0,0,0
0,0,0,0,1,1,1,0,0,2,2,0,0,1,0,0,0,0,0,0,0,0,0
0,0,0,0,0,0,0,1,32,32,2,1,1,1,0,0,0,0,0,0,0,0,0
0,0,0,0,0,0,0,0,1,1,1,0,0,0,0,0,0,0,0,0,0,0,0
0,0,0,0,0,0,0,0,0,0,0,0,0,0,0,0,0,0,0,0,0,0,0
endlayer

layer
0,0,0,0,0,0,0,0,0,0,0,1,1,0,0,0,0,0,0,0,0,0,0
0,0,0,0,0,0,0,0,1,1,1,0,2,1,1,0,2,0,0,0,0,0,0
0,0,0,0,0,0,0,0,1,0,0,0,0,2,1,1,0,0,0,0,0,0,0
0,0,0,0,0,0,1,1,1,0,0,0,0,0,1,1,2,2,0,0,0,0,0
0,0,0,0,0,0,1,9,0,0,0,0,0,0,0,0,2,2,2,0,0,0,0
0,0,0,0,0,0,1,27,0,0,0,0,0,0,33,0,1,0,0,0,0,0,0
0,0,0,0,0,0,1,13,0,0,0,0,0,0,33,0,1,1,1,1,0,0,0
0,0,0,0,0,0,1,0,0,0,0,0,0,0,0,0,0,0,0,14,1,0,0
0,0,0,0,0,0,1,1,0,0,0,0,0,0,0,0,0,0,0,0,14,1,0
0,0,0,0,1,1,0,0,0,0,0,0,0,0,0,0,0,0,0,0,0,1,0
0,0,0,1,30,30,0,0,0,0,0,0,0,0,0,0,0,0,0,0,0,24,1
0,0,0,1,0,0,0,0,0,0,32,0,0,0,0,0,0,0,0,0,0,0,1
0,0,1,14,0,0,0,0,0,0,15,0,0,0,0,0,0,0,0,0,0,1,0
0,0,1,0,0,0,0,0,0,15,15,15,32,0,0,0,24,0,0,0,1,0,0
1,1,0,0,0,0,0,0,15,15,15,15,15,27,0,0,24,24,0,0,1,0,0
1,31,18,0,0,0,0,0,0,15,15,15,0,0,0,24,15,24,0,2,1,0,0
1,31,31,0,0,0,0,0,0,15,15,15,0,0,0,24,24,24,0,0,1,0,0
1,31,31,0,0,0,0,0,0,0,0,0,0,0,0,0,0,0,0,0,1,0,0
1,0,0,0,0,0,0,0,0,0,0,0,0,0,0,0,15,0,0,1,1,0,0
1,0,0,0,0,0,0,0,24,13,13,0,0,2,0,15,11,11,0,0,1,0,0
0,1,0,0,0,0,0,0,24,13,13,0,0,0,32,0,0,0,0,1,1,0,0
0,1,1,0,0,0,0,0,0,0,0,0,0,0,1,1,1,2,1,1,1,0,0
0,1,1,1,26,0,0,0,0,0,0,0,1,1,1,0,1,1,1,1,0,0,0
0,0,0,0,1,1,0,0,0,0,0,0,0,1,0,0,0,1,1,0,0,0,0
0,0,0,0,0,0,0,1,32,32,32,1,1,1,0,0,0,0,0,0,0,0,0
0,0,0,0,0,0,0,0,1,1,1,0,0,0,0,0,0,0,0,0,0,0,0
0,0,0,0,0,0,0,0,0,0,0,0,0,0,0,0,0,0,0,0,0,0,0
endlayer

layer
0,0,0,0,0,0,0,0,0,0,0,1,1,0,0,0,0,0,0,0,0,0,0
0,0,0,0,0,0,0,0,1,1,1,0,0,1,1,1,0,0,0,0,0,0,0
0,0,0,0,0,0,0,0,1,0,0,0,0,0,0,2,0,0,0,0,0,0,0
0,0,0,0,0,0,1,1,1,0,0,0,0,0,0,1,0,0,0,0,0,0,0
0,0,0,0,0,0,1,34,0,0,0,0,0,0,0,2,0,0,0,0,0,0,0
0,0,0,0,0,0,1,27,0,0,0,0,0,0,33,1,0,0,0,0,0,0,0
0,0,0,0,0,0,1,27,0,0,0,0,0,0,33,0,1,1,1,1,0,0,0
0,0,0,0,0,0,1,0,0,0,0,0,0,0,0,0,0,29,31,31,1,0,0
0,0,0,0,0,0,1,1,0,0,0,0,0,0,0,0,0,29,31,31,31,2,0
0,0,0,0,1,1,0,0,0,0,0,0,0,0,0,0,0,29,31,31,31,1,0
0,0,0,1,0,30,0,0,0,0,0,0,0,0,0,0,0,0,29,31,31,0,1
0,0,0,1,0,0,0,0,0,0,32,0,0,0,0,0,0,0,0,0,0,0,1
0,0,1,14,24,0,0,0,36,35,15,0,0,0,0,0,0,0,0,0,0,1,1
0,0,1,24,24,24,24,0,36,15,15,15,32,0,0,0,0,0,0,0,2,1,0
1,1,0,24,24,11,11,11,15,15,15,15,15,27,0,0,0,0,0,0,1,1,0
1,0,0,0,24,24,24,0,0,0,15,15,0,0,0,0,24,0,0,0,1,1,0
1,0,0,0,0,0,24,0,0,0,15,30,0,0,0,0,0,0,0,0,1,0,0
1,0,0,0,0,0,0,0,0,0,0,0,0,0,0,0,0,0,0,0,1,0,0
1,0,0,0,0,0,0,0,0,0,0,0,0,0,0,0,0,0,0,1,2,0,0
1,0,0,0,0,0,0,0,0,0,0,0,0,0,0,0,0,15,11,1,2,0,0
0,1,0,0,0,0,0,0,0,0,0,0,0,0,32,0,0,0,19,1,2,0,0
0,1,1,0,0,0,0,0,0,0,0,0,0,0,1,1,1,0,1,2,1,0,0
0,1,1,1,26,0,0,0,0,0,0,0,1,1,1,0,1,1,1,1,1,0,0
0,0,0,0,1,1,1,0,0,0,0,0,0,1,0,0,0,1,1,0,0,0,0
0,0,0,0,0,0,0,1,0,0,32,1,1,1,0,1,1,0,0,0,0,0,0
0,0,0,0,0,0,0,0,1,1,1,0,0,0,0,0,0,0,0,0,0,0,0
0,0,0,0,0,0,0,0,0,0,0,0,0,0,0,0,0,0,0,0,0,0,0
endlayer

layer
0,0,0,0,0,0,0,0,0,0,0,1,1,1,0,0,0,0,0,0,0,0,0
0,0,0,0,0,0,0,0,1,1,1,37,0,1,1,2,0,0,0,0,0,0,0
0,0,0,0,0,0,0,0,1,38,38,37,0,0,1,0,0,0,0,0,0,0,0
0,0,0,0,0,0,1,1,1,38,38,39,0,0,1,0,0,0,0,0,0,0,0
0,0,0,0,0,0,1,38,38,38,39,0,0,0,1,0,0,0,0,0,0,0,0
0,0,0,0,0,0,1,0,0,0,0,0,0,0,33,1,1,0,0,0,0,0,0
0,0,0,0,0,0,1,0,0,0,0,0,0,0,33,1,1,1,1,1,0,0,0
0,0,0,0,0,0,1,0,0,0,0,0,0,0,0,0,0,0,0,0,1,0,0
0,0,0,0,0,0,1,1,0,0,0,27,0,0,24,24,24,0,0,0,1,0,0
0,0,0,0,1,1,27,0,0,0,0,0,0,24,24,19,24,0,0,0,1,1,0
0,0,0,1,0,30,0,0,0,0,0,0,24,24,19,11,24,0,0,0,0,0,1
0,0,0,1,0,0,0,0,0,0,32,0,0,19,11,24,24,0,0,0,0,0,1
0,0,1,0,0,0,0,0,0,33,15,0,0,15,0,0,0,0,0,0,0,2,1
0,0,1,0,24,24,24,0,0,15,15,15,0,0,0,0,0,0,0,0,0,1,0
1,1,0,0,24,15,24,0,15,15,15,15,15,0,0,0,0,0,0,0,2,1,0
1,0,0,0,0,24,24,0,0,0,15,15,31,0,0,0,0,0,0,0,2,1,0
1,13,0,0,0,0,0,0,0,0,0,30,0,0,0,0,0,0,0,0,1,0,0
1,13,13,0,0,0,0,0,0,0,0,0,0,0,0,0,0,0,0,0,1,0,0
1,1,0,0,0,0,0,0,0,0,0,0,0,0,0,0,0,0,0,1,0,0,0
1,1,1,0,0,0,0,0,0,0,0,0,0,0,0,0,0,0,0,1,0,0,0
0,1,1,1,0,0,0,0,0,0,0,0,0,0,32,0,0,0,1,1,0,0,0
0,1,1,1,0,0,0,0,0,0,0,0,0,0,1,2,2,0,9,8,1,0,0
0,1,1,1,26,32,0,0,0,0,0,0,1,1,1,2,2,9,8,1,1,0,0
0,0,0,0,1,1,1,1,0,0,0,0,0,1,1,2,1,1,1,0,0,0,0
0,0,0,0,0,0,0,1,1,0,32,1,1,1,0,1,1,0,0,0,0,0,0
0,0,0,0,0,0,0,0,1,1,1,0,0,0,0,0,0,0,0,0,0,0,0
0,0,0,0,0,0,0,0,0,0,0,0,0,0,0,0,0,0,0,0,0,0,0
endlayer

layer
0,0,0,0,0,0,0,0,0,0,0,1,1,1,0,0,0,0,0,0,0,0,0
0,0,0,0,0,0,0,0,2,2,1,1,0,1,2,0,0,0,0,0,0,0,0
0,0,0,0,0,0,0,0,2,0,0,0,33,1,1,1,0,0,0,0,0,0,0
0,0,0,0,0,0,1,1,1,0,0,0,0,30,1,1,1,0,0,0,0,0,0
0,0,0,0,0,1,1,0,0,0,0,0,0,0,1,1,2,0,0,0,0,0,0
0,0,0,0,0,1,2,0,0,0,0,0,0,0,33,1,1,0,0,1,0,0,0
0,0,0,0,0,1,2,0,0,0,0,0,0,0,0,2,1,1,1,1,0,0,0
0,0,0,0,0,1,2,0,0,0,0,0,0,0,0,0,0,0,0,0,1,0,0
0,0,0,0,0,1,2,2,0,0,0,27,0,0,0,0,0,0,0,0,1,0,0
0,0,0,0,1,1,27,0,0,0,0,0,0,0,24,24,24,0,0,0,1,1,0
0,0,0,1,1,0,0,0,0,0,0,0,0,0,24,15,24,0,0,0,0,0,1
0,0,0,1,0,0,0,0,0,0,19,0,0,19,0,24,24,0,0,0,0,0,1
0,0,1,0,0,0,0,0,0,0,15,0,19,11,0,0,0,0,0,0,0,0,1
0,0,1,0,0,24,0,0,0,15,15,15,15,0,0,0,0,0,0,0,0,1,0
1,1,0,0,24,24,0,0,15,15,15,15,15,0,0,0,0,0,0,0,0,1,0
1,13,0,0,0,0,0,0,0,15,15,15,0,0,0,0,0,0,0,32,0,1,0
1,24,24,24,0,0,0,0,0,0,0,30,0,0,0,0,0,0,33,2,1,0,0
1,11,24,24,30,0,0,0,0,0,0,0,0,0,0,0,0,0,0,2,1,0,0
1,2,2,0,0,0,0,0,0,0,0,0,0,0,0,0,0,0,0,2,0,0,0
1,1,2,0,0,0,0,0,0,0,0,0,0,0,0,0,0,0,0,1,0,0,0
0,1,1,2,40,40,40,0,0,0,0,0,0,0,32,0,0,0,2,1,0,0,0
0,1,1,1,39,39,39,0,0,0,0,0,0,0,2,0,0,0,0,9,1,0,0
0,1,1,1,39,39,39,0,0,0,0,0,1,1,2,14,14,14,8,1,1,0,0
0,0,0,0,2,1,1,1,14,0,0,0,0,1,1,14,2,1,1,1,0,0,0
0,0,0,0,0,0,0,1,1,1,1,1,1,1,0,1,0,1,1,1,0,0,0
0,0,0,0,0,0,0,0,1,1,1,1,1,0,1,1,1,1,1,0,0,0,0
0,0,0,0,0,0,0,0,0,0,0,0,0,0,0,0,0,1,0,0,0,0,0
endlayer

layer
0,0,0,0,0,0,0,0,0,0,0,1,1,2,0,0,0,0,0,0,0,0,0
0,0,0,0,0,0,0,0,0,0,2,1,0,1,0,0,0,0,0,0,0,0,0
0,0,0,0,0,0,0,0,0,2,1,0,0,1,1,1,0,0,0,0,0,0,0
0,0,0,0,0,0,2,1,1,1,0,0,0,0,1,1,1,0,0,0,0,0,0
0,0,0,0,1,1,0,0,0,0,0,0,0,0,2,1,0,0,0,0,0,0,0
0,0,0,0,1,2,0,0,24,24,24,24,0,0,0,1,1,1,0,2,0,0,0
0,0,0,1,1,2,0,13,13,19,19,13,0,0,0,0,1,1,1,1,0,0,0
0,0,0,0,1,2,0,24,24,11,19,24,0,0,0,0,0,1,0,0,1,0,0
0,0,0,0,0,1,0,0,24,24,19,27,0,0,0,0,0,0,0,0,1,0,0
0,0,0,0,1,2,0,0,0,33,19,27,0,0,0,0,0,0,0,0,1,1,0
0,0,0,1,1,2,0,0,0,0,19,0,0,0,24,24,0,0,0,0,0,0,1
0,0,0,1,2,2,0,0,0,19,19,0,0,0,0,0,0,0,0,0,0,0,1
0,0,1,0,0,0,0,0,0,15,15,15,0,0,0,0,0,0,0,0,0,0,1
0,0,1,0,0,0,0,0,0,15,15,15,15,0,0,0,0,0,0,0,0,1,1
1,1,0,0,0,0,0,11,15,15,15,15,15,0,0,0,0,0,0,0,0,1,0
1,0,0,0,0,30,0,0,0,15,15,15,15,0,0,0,0,0,0,0,0,1,0
1,13,0,0,0,0,0,0,0,15,15,30,0,0,0,0,0,0,0,0,1,1,0
1,24,13,0,30,0,0,0,0,19,0,0,0,0,0,0,0,0,0,0,1,1,0
1,13,13,13,0,0,0,0,0,19,0,0,0,0,33,0,0,0,0,0,1,1,0
1,1,0,0,0,0,0,0,0,19,27,0,0,0,0,0,0,0,0,1,1,1,1
0,1,2,0,0,0,0,0,11,19,0,0,0,0,0,0,0,0,0,1,1,1,1
0,1,1,2,0,0,0,0,19,11,11,13,0,0,0,0,0,0,0,9,1,1,0
0,1,1,1,1,0,0,0,19,13,19,13,2,2,0,0,0,0,9,8,1,0,0
0,0,0,0,0,1,1,2,14,14,13,13,0,2,2,0,0,2,1,1,0,0,0
0,0,0,0,0,0,1,0,1,1,2,2,2,1,2,2,2,2,2,1,0,0,0
0,0,0,0,0,0,0,0,0,1,1,1,1,0,1,1,1,2,1,0,0,0,0
0,0,0,0,0,0,0,0,0,1,0,0,0,0,0,0,0,1,0,0,0,0,0
endlayer

layer
0,0,0,0,0,0,0,0,0,0,0,1,2,0,0,0,0,0,0,0,0,0,0
0,0,0,0,0,0,0,0,0,0,0,1,0,1,0,0,0,0,0,0,0,0,0
0,0,0,0,0,0,0,0,0,0,1,0,0,1,1,1,1,0,0,0,0,0,0
0,0,0,0,0,0,0,1,1,1,0,0,0,0,1,1,1,0,0,0,0,0,0
0,0,0,0,2,1,1,1,19,0,0,0,0,0,0,1,1,1,0,0,0,0,0
0,0,0,0,1,0,0,0,11,19,0,0,0,0,0,2,1,1,0,0,0,0,0
0,0,0,2,1,0,0,13,13,15,13,0,0,0,0,0,1,2,2,2,0,0,0
0,0,0,0,1,0,0,24,24,15,24,0,0,0,0,0,0,1,1,1,2,0,0
0,0,0,0,0,1,0,0,24,24,0,0,0,0,0,0,1,1,1,1,1,0,0
0,0,0,0,1,0,0,0,0,0,0,0,0,0,0,0,0,0,0,13,1,1,0
0,0,0,1,1,0,0,0,0,0,0,0,0,0,0,0,0,0,13,13,0,0,1
0,1,1,1,0,0,0,0,0,32,32,0,0,0,0,0,0,13,13,19,11,11,1
0,1,1,0,0,0,0,0,0,15,15,15,15,0,0,0,0,13,19,11,0,30,1
1,0,1,0,0,0,0,0,15,15,15,15,15,0,0,0,0,15,11,13,0,1,1
1,1,0,0,0,0,11,11,15,15,15,15,15,11,11,11,0,13,13,13,0,1,0
1,0,0,0,0,30,0,0,15,15,15,15,15,11,11,11,0,0,0,0,0,1,0
1,0,0,33,0,0,0,0,0,15,15,15,0,0,30,19,11,11,0,0,1,1,0
1,0,0,0,30,0,0,0,0,19,19,0,0,0,0,0,0,0,0,0,1,1,0
1,0,0,0,0,0,0,0,0,19,0,0,0,0,33,0,0,0,0,0,2,1,0
1,2,0,0,0,0,0,0,0,19,0,0,0,0,0,0,0,0,0,2,1,1,1
0,1,0,0,0,0,0,0,0,0,0,0,0,0,0,0,0,0,0,2,1,1,1
0,1,1,0,0,0,0,0,24,24,24,24,0,0,0,0,0,0,0,0,1,1,0
0,1,1,1,1,0,0,0,15,24,15,24,24,0,0,0,0,0,0,1,1,0,0
0,0,0,0,0,1,1,0,19,24,24,24,24,0,0,0,0,0,1,0,0,0,0
0,0,0,0,0,0,1,1,1,2,0,0,0,1,0,0,0,0,0,1,1,0,0
0,0,0,0,0,0,0,0,1,2,1,1,1,0,1,1,1,0,1,1,0,0,0
0,0,0,0,0,0,0,0,0,1,0,0,0,0,0,0,0,1,0,0,0,0,0
endlayer

layer
0,0,0,0,0,0,0,0,0,0,0,2,0,0,0,0,0,0,0,0,0,0,0
0,0,0,0,0,0,0,0,0,0,0,1,2,2,0,0,0,0,0,0,0,0,0
0,0,0,0,0,0,0,0,0,0,1,0,0,2,2,2,2,0,0,0,0,0,0
0,0,0,0,0,0,0,1,1,1,0,0,0,0,2,2,2,0,0,0,0,0,0
0,0,0,0,0,1,1,1,0,0,0,0,0,0,1,1,1,2,0,0,0,0,0
0,0,0,0,1,0,0,0,0,0,0,0,0,0,1,0,1,2,0,0,0,0,0
0,0,0,0,1,0,0,0,0,13,0,0,0,0,0,0,1,0,0,0,0,0,0
0,0,0,0,1,0,0,0,24,24,0,0,0,0,0,0,0,2,2,2,0,0,0
0,0,0,0,1,1,0,0,0,0,0,0,0,0,0,0,1,2,2,2,2,0,0
0,0,0,0,1,0,0,0,0,0,0,0,0,0,0,0,0,1,1,1,1,1,1
1,1,0,1,2,0,0,0,0,0,0,0,24,0,0,0,0,0,0,13,0,0,2
1,1,2,1,0,0,0,0,0,32,32,24,19,24,0,0,0,13,13,15,13,0,1
1,1,2,0,0,0,24,0,0,15,15,15,15,0,0,0,0,13,13,15,13,0,1
1,0,1,0,0,24,19,24,15,23,15,15,15,11,11,11,11,11,13,13,13,1,1
1,1,0,0,11,15,15,14,15,15,15,15,15,11,11,11,0,0,0,13,0,1,0
1,0,0,0,19,30,0,0,15,23,15,15,15,11,11,0,0,0,0,0,0,1,0
1,0,0,33,19,0,0,0,15,15,15,15,15,0,0,0,15,15,0,0,1,0,0
1,0,0,0,30,0,0,0,0,0,41,41,39,0,0,0,19,11,0,0,1,1,0
1,0,0,0,0,0,0,0,0,0,0,0,0,0,33,11,19,0,0,0,14,1,0
1,0,0,0,0,0,0,0,0,0,0,0,0,1,13,19,19,0,0,14,0,0,1
0,1,1,0,0,0,0,0,0,0,0,0,0,24,13,19,24,0,0,42,0,2,2
0,1,1,0,0,0,0,0,0,24,24,0,0,0,24,24,24,24,0,0,0,2,0
0,1,1,1,1,1,0,0,24,24,24,0,0,0,24,24,13,13,0,1,1,0,0
0,0,0,0,1,1,1,11,15,0,24,0,0,0,0,24,13,0,2,1,0,0,0
0,0,0,0,0,0,1,1,2,0,0,0,0,1,0,0,0,0,0,2,1,0,0
0,0,0,0,0,0,0,0,1,0,2,1,1,1,2,2,2,0,1,1,0,0,0
0,0,0,0,0,0,0,0,0,1,1,1,1,0,1,1,1,1,0,0,0,0,0
endlayer

layer
0,0,0,0,0,0,0,0,0,0,0,0,0,0,0,0,0,0,0,0,0,0,0
0,0,0,0,0,0,0,0,0,0,0,2,0,0,0,0,0,0,0,0,0,0,0
0,0,0,0,0,0,0,0,0,0,2,2,2,0,0,0,0,0,0,0,0,0,0
0,0,0,0,0,0,0,2,2,1,0,0,0,2,0,0,0,0,0,0,0,0,0
0,0,0,0,0,1,1,1,1,0,0,0,0,2,2,2,2,0,0,0,0,0,0
0,0,0,0,1,0,0,0,0,0,0,0,0,0,1,1,1,0,0,0,0,0,0
0,0,0,0,1,0,0,0,0,0,0,0,0,0,0,0,1,0,0,0,0,0,0
0,0,0,0,1,0,0,9,0,0,0,0,0,0,0,0,1,0,0,0,0,0,0
0,0,0,0,1,2,0,0,0,0,0,0,0,1,0,0,1,0,0,0,0,0,0
0,0,0,1,2,0,0,0,0,0,0,0,0,0,0,0,1,1,1,1,1,2,2
1,1,0,1,0,0,0,0,0,0,0,0,0,0,0,0,0,0,0,0,0,1,0
1,2,0,1,0,0,0,0,33,32,32,0,24,0,0,0,0,0,0,13,0,0,1
1,2,0,0,0,0,0,0,0,15,15,15,15,11,0,0,0,0,0,13,0,0,1
1,1,2,0,0,0,24,0,15,15,15,15,15,11,11,11,0,0,0,13,0,0,2
1,1,0,11,11,15,0,14,15,15,15,15,15,11,11,0,0,0,0,0,0,1,2
1,1,0,0,19,0,0,0,15,15,15,15,15,0,0,0,0,0,0,0,0,1,0
1,0,0,24,19,0,0,0,15,15,15,15,15,0,0,0,0,0,0,0,9,2,0
1,0,24,11,19,24,0,0,0,0,0,0,0,0,0,0,0,15,0,0,9,1,0
1,0,0,24,24,0,0,0,0,0,0,0,0,0,0,0,0,19,11,0,14,1,1
1,0,0,0,0,0,0,0,0,0,0,0,0,1,13,13,24,19,19,11,1,1,2
0,1,1,1,0,0,0,0,0,0,0,0,0,0,13,15,24,0,30,42,1,0,0
0,2,1,1,0,0,0,0,0,0,0,0,0,0,24,24,24,0,0,0,1,0,0
0,1,1,1,0,1,0,0,0,0,0,0,0,0,0,0,0,0,0,2,1,0,0
0,0,0,0,2,1,1,2,0,0,0,0,0,0,0,0,0,0,0,1,0,0,0
0,0,0,0,0,1,0,1,0,0,0,0,0,2,0,0,0,0,0,0,1,0,0
0,0,0,0,0,0,0,1,1,0,0,2,2,1,0,0,0,0,1,1,0,0,0
0,0,0,0,0,0,0,1,1,1,1,1,1,0,1,1,1,1,0,0,0,0,0
endlayer

layer
0,0,0,0,0,0,0,0,0,0,0,0,0,0,0,0,0,0,0,0,0,0,0
0,0,0,0,0,0,0,0,0,0,0,0,0,0,0,0,0,0,0,0,0,0,0
0,0,0,0,0,0,0,0,0,0,0,0,0,0,0,0,0,0,0,0,0,0,0
0,0,0,0,0,0,0,0,0,2,1,2,2,0,0,0,0,0,0,0,0,0,0
0,0,0,0,0,2,1,1,2,2,0,0,1,0,0,0,0,0,0,0,0,0,0
0,0,0,0,2,0,0,0,1,1,0,0,1,1,1,1,1,0,0,0,0,0,0
0,0,0,0,2,1,0,0,0,0,0,0,0,0,0,0,1,0,0,0,0,0,0
0,0,0,0,1,0,0,9,0,0,0,0,0,0,0,0,1,0,0,0,0,0,0
0,0,0,0,1,0,0,0,0,0,0,0,0,1,0,0,1,0,0,0,0,0,0
0,0,0,1,0,0,0,0,0,0,0,0,0,0,0,0,1,1,1,2,1,0,0
1,1,1,1,0,0,0,0,0,32,0,0,0,0,0,0,0,0,0,0,0,1,0
1,0,0,1,0,0,0,0,43,15,15,14,14,0,0,0,0,0,0,0,0,0,1
1,0,0,0,0,0,0,33,15,15,15,15,15,15,0,0,0,0,0,0,0,0,1
1,19,0,0,0,0,0,15,15,15,15,15,15,15,0,0,0,0,0,0,0,2,0
1,11,11,15,0,0,0,15,15,15,15,15,15,15,0,0,0,0,0,0,0,2,0
2,1,0,0,0,0,0,15,15,15,15,15,15,15,0,0,0,0,0,0,1,1,0
1,0,0,0,24,0,0,14,15,15,15,15,15,15,0,0,0,0,0,0,9,8,1
1,0,0,24,24,0,0,0,0,15,15,15,15,0,0,0,0,0,0,9,9,9,1
1,1,0,24,0,0,0,0,0,0,0,0,0,0,0,0,0,0,0,1,9,9,1
2,1,1,0,0,0,0,0,0,0,0,0,0,1,0,13,0,0,0,1,1,1,0
0,2,1,1,0,0,0,0,0,0,0,0,0,0,0,13,24,0,0,0,1,0,0
0,0,2,1,1,14,14,0,0,0,0,0,0,0,0,24,24,0,0,0,1,0,0
0,2,2,2,2,1,14,0,0,0,0,0,0,0,0,0,0,0,0,0,1,0,0
0,0,0,0,0,1,1,0,0,0,0,0,0,0,0,0,0,0,0,1,0,0,0
0,0,0,0,0,2,1,1,0,0,13,0,0,0,0,0,0,0,0,0,1,0,0
0,0,0,0,0,0,0,1,2,13,13,13,13,1,0,0,0,0,1,1,0,0,0
0,0,0,0,0,0,0,1,1,1,1,1,1,0,2,1,2,1,0,0,0,0,0
endlayer

layer
0,0,0,0,0,0,0,0,0,0,0,0,0,0,0,0,0,0,0,0,0,0,0
0,0,0,0,0,0,0,0,0,0,0,0,0,0,0,0,0,0,0,0,0,0,0
0,0,0,0,0,0,0,0,0,0,0,0,0,0,0,0,0,0,0,0,0,0,0
0,0,0,0,0,0,0,0,0,0,2,0,0,0,0,0,0,0,0,0,0,0,0
0,0,0,0,0,0,2,2,0,0,2,0,2,0,0,0,0,0,0,0,0,0,0
0,0,0,0,0,2,9,2,2,2,0,0,1,1,1,1,1,0,0,0,0,0,0
0,0,0,0,0,2,9,9,0,0,0,0,0,1,0,9,2,0,0,0,0,0,0
0,0,0,0,2,2,9,9,0,0,0,0,0,1,0,0,1,0,0,0,0,0,0
0,0,0,0,2,1,0,9,0,0,0,0,1,1,0,0,1,0,0,0,0,0,0
0,0,0,2,1,0,0,0,0,0,0,0,0,0,0,0,1,2,2,0,2,0,0
2,1,2,1,0,0,0,0,0,0,0,0,0,0,0,0,1,2,2,2,1,2,2
1,0,0,1,0,0,0,0,15,15,15,15,15,15,0,0,1,1,1,1,2,1,2
1,0,0,0,0,0,0,15,15,15,15,15,15,15,0,0,0,0,0,1,2,2,2
2,0,0,0,0,0,0,15,15,15,15,15,15,15,0,0,0,0,0,0,2,0,0
1,1,0,0,0,0,0,15,15,15,15,15,15,15,0,0,0,0,0,0,2,0,0
0,1,0,0,0,0,0,15,15,15,15,15,15,15,0,0,0,0,0,0,2,2,0
1,0,0,0,0,0,0,15,15,15,15,15,15,15,0,0,0,0,0,9,9,8,2
2,0,0,0,0,0,0,15,15,15,15,15,15,15,0,0,0,0,0,9,9,8,2
2,1,0,0,0,0,0,0,0,0,0,0,1,1,0,0,0,0,0,1,1,0,2
0,2,1,1,0,9,0,0,0,0,0,0,1,1,1,0,0,0,0,1,1,2,0
0,0,2,1,0,0,0,0,0,0,0,0,0,0,0,0,0,0,0,0,1,0,0
0,0,0,2,1,1,14,0,0,0,0,0,0,0,0,0,0,0,0,0,1,0,0
0,0,0,0,0,2,1,1,0,0,0,0,0,0,0,0,0,0,0,0,1,0,0
0,0,0,0,0,2,0,0,0,0,0,0,0,0,0,0,0,0,0,1,0,0,0
0,0,0,0,0,0,1,1,0,0,13,13,0,0,0,0,0,0,0,0,2,0,0
0,0,0,0,0,0,0,1,0,0,13,24,13,1,2,2,1,0,1,2,0,0,0
0,0,0,0,0,0,0,1,1,1,1,1,1,0,0,2,0,2,0,0,0,0,0
endlayer

layer
0,0,0,0,0,0,0,0,0,0,0,0,0,0,0,0,0,0,0,0,0,0,0
0,0,0,0,0,0,0,0,0,0,0,0,0,0,0,0,0,0,0,0,0,0,0
0,0,0,0,0,0,0,0,0,0,0,0,0,0,0,0,0,0,0,0,0,0,0
0,0,0,0,0,0,0,0,0,0,0,0,0,0,0,0,0,0,0,0,0,0,0
0,0,0,0,0,0,0,0,0,0,0,2,0,0,0,0,0,0,0,0,0,0,0
0,0,0,0,0,0,2,0,0,0,2,1,1,1,1,1,1,0,0,0,0,0,0
0,0,0,0,0,0,2,2,2,2,2,1,1,1,9,9,9,1,0,0,0,0,0
0,0,0,0,0,0,2,1,1,2,1,1,1,1,1,0,1,0,0,0,0,0,0
0,0,0,0,0,2,1,9,1,1,1,1,1,1,1,0,1,0,0,0,0,0,0
0,0,0,0,2,1,1,1,1,1,1,1,1,1,1,1,2,0,0,0,0,0,0
0,2,0,2,2,1,1,1,1,1,1,1,1,1,1,1,1,0,0,0,2,0,0
2,2,2,2,1,1,1,1,1,1,1,1,1,1,1,1,2,2,2,2,0,2,0
2,1,1,1,1,1,1,1,1,1,1,1,1,1,1,1,1,1,1,2,0,0,0
0,1,1,1,1,1,1,1,1,1,1,1,1,1,1,1,1,1,1,2,0,0,0
2,1,1,0,1,1,1,1,1,1,1,1,1,1,1,1,1,1,1,2,0,0,0
0,1,0,0,1,1,1,1,1,1,1,1,1,1,1,1,1,1,1,2,0,0,0
2,1,0,0,1,1,1,1,1,1,1,1,1,1,1,1,1,1,1,2,2,2,0
0,1,1,1,1,1,1,1,1,1,1,1,1,1,1,1,1,1,2,2,2,2,0
0,2,1,1,1,1,1,1,1,1,1,1,1,1,1,1,1,1,1,1,2,2,0
0,0,2,1,9,9,9,1,1,1,1,1,1,1,1,0,0,0,0,1,1,0,0
0,0,0,2,2,9,1,1,1,1,1,1,1,1,1,0,0,0,0,1,1,0,0
0,0,0,0,2,2,0,1,1,1,1,1,1,1,1,1,0,0,0,0,1,0,0
0,0,0,0,0,0,2,2,1,2,1,1,1,1,1,1,1,0,0,0,1,0,0
0,0,0,0,0,0,2,1,1,2,2,2,2,2,2,2,1,1,1,1,2,0,0
0,0,0,0,0,0,2,2,1,1,2,2,2,2,2,2,2,1,2,2,0,0,0
0,0,0,0,0,0,0,2,1,2,1,19,1,2,0,0,2,2,2,0,0,0,0
0,0,0,0,0,0,0,2,2,2,2,2,2,0,0,0,0,0,0,0,0,0,0
endlayer

layer
0,0,0,0,0,0,0,0,0,0,0,0,0,0,0,0,0,0,0,0,0,0,0
0,0,0,0,0,0,0,0,0,0,0,0,0,0,0,0,0,0,0,0,0,0,0
0,0,0,0,0,0,0,0,0,0,0,0,0,0,0,0,0,0,0,0,0,0,0
0,0,0,0,0,0,0,0,0,0,0,0,0,0,0,0,0,0,0,0,0,0,0
0,0,0,0,0,0,0,0,0,0,0,0,0,0,0,0,0,0,0,0,0,0,0
0,0,0,0,0,0,0,0,0,0,0,2,1,1,2,1,1,0,0,0,0,0,0
0,0,0,0,0,0,0,0,0,0,0,2,2,1,9,9,9,1,0,0,0,0,0
0,0,0,0,0,0,0,2,2,0,2,2,2,1,8,9,1,0,0,0,0,0,0
0,0,0,0,0,0,2,2,2,2,1,2,2,1,8,8,1,1,0,0,0,0,0
0,0,0,0,0,2,2,1,1,1,1,1,1,1,1,2,0,0,0,0,0,0,0
0,0,0,0,0,2,1,1,1,1,1,1,1,1,1,2,2,0,0,0,0,0,0
0,0,0,0,2,2,1,1,1,1,1,1,1,1,1,1,0,0,0,0,0,0,0
0,2,2,2,2,2,1,1,1,1,1,1,1,1,1,1,2,2,2,0,0,0,0
0,2,2,2,2,1,1,1,2,2,1,1,1,1,1,1,2,2,2,0,0,0,0
0,2,1,1,2,1,1,1,1,1,1,1,1,1,1,1,1,2,2,0,0,0,0
0,2,1,1,1,1,1,1,2,2,2,1,1,1,1,1,2,2,2,0,0,0,0
0,2,1,1,1,1,1,1,1,2,2,1,1,1,1,1,1,2,2,0,0,0,0
0,2,2,2,2,1,1,1,1,2,2,2,1,1,1,2,2,2,0,0,0,0,0
0,0,2,2,1,1,1,1,1,1,1,1,1,2,2,1,1,2,2,2,0,0,0
0,0,0,2,2,2,1,1,1,1,1,1,2,2,2,1,1,1,1,1,2,0,0
0,0,0,0,0,2,2,1,1,2,2,2,2,2,2,1,1,1,1,2,2,0,0
0,0,0,0,0,0,2,2,2,2,2,2,2,2,2,2,2,1,1,1,2,0,0
0,0,0,0,0,0,0,0,2,0,2,2,2,2,2,2,2,1,1,1,2,0,0
0,0,0,0,0,0,0,2,2,0,0,0,0,0,0,0,2,2,2,2,0,0,0
0,0,0,0,0,0,0,0,2,2,0,0,0,0,0,0,0,2,0,0,0,0,0
0,0,0,0,0,0,0,0,2,0,2,2,2,0,0,0,0,0,0,0,0,0,0
0,0,0,0,0,0,0,0,0,0,0,0,0,0,0,0,0,0,0,0,0,0,0
endlayer

layer
0,0,0,0,0,0,0,0,0,0,0,0,0,0,0,0,0,0,0,0,0,0,0
0,0,0,0,0,0,0,0,0,0,0,0,0,0,0,0,0,0,0,0,0,0,0
0,0,0,0,0,0,0,0,0,0,0,0,0,0,0,0,0,0,0,0,0,0,0
0,0,0,0,0,0,0,0,0,0,0,0,0,0,0,0,0,0,0,0,0,0,0
0,0,0,0,0,0,0,0,0,0,0,0,0,0,0,0,0,0,0,0,0,0,0
0,0,0,0,0,0,0,0,0,0,0,0,2,2,0,2,1,0,0,0,0,0,0
0,0,0,0,0,0,0,0,0,0,0,0,0,2,1,9,9,1,0,0,0,0,0
0,0,0,0,0,0,0,0,0,0,0,0,0,2,2,2,2,0,0,0,0,0,0
0,0,0,0,0,0,0,0,0,0,2,0,0,2,2,2,2,2,0,0,0,0,0
0,0,0,0,0,0,0,2,2,2,2,2,2,2,2,0,0,0,0,0,0,0,0
0,0,0,0,0,0,2,2,2,2,2,2,2,2,2,0,0,0,0,0,0,0,0
0,0,0,0,0,0,2,2,1,2,2,1,1,1,2,2,0,0,0,0,0,0,0
0,0,0,0,0,0,2,2,1,1,2,2,1,1,2,2,0,0,0,0,0,0,0
0,0,0,0,0,2,2,2,0,0,2,2,1,1,2,2,0,0,0,0,0,0,0
0,0,2,2,0,2,2,1,2,2,2,1,2,2,2,2,2,0,0,0,0,0,0
0,0,2,2,2,2,2,2,0,0,0,1,2,2,2,2,0,0,0,0,0,0,0
0,0,2,1,2,2,2,2,1,0,0,1,2,2,2,2,2,0,0,0,0,0,0
0,0,0,0,0,2,2,2,1,0,0,0,2,2,2,0,0,0,0,0,0,0,0
0,0,0,0,2,2,2,2,2,2,1,1,1,0,0,2,2,0,0,0,0,0,0
0,0,0,0,0,0,2,2,2,2,2,1,0,0,0,2,2,2,2,2,0,0,0
0,0,0,0,0,0,0,2,2,0,0,0,0,0,0,2,2,2,2,0,0,0,0
0,0,0,0,0,0,0,0,0,0,0,0,0,0,0,0,0,2,2,2,0,0,0
0,0,0,0,0,0,0,0,0,0,0,0,0,0,0,0,0,2,2,2,0,0,0
0,0,0,0,0,0,0,0,0,0,0,0,0,0,0,0,0,0,0,0,0,0,0
0,0,0,0,0,0,0,0,0,0,0,0,0,0,0,0,0,0,0,0,0,0,0
0,0,0,0,0,0,0,0,0,0,0,0,0,0,0,0,0,0,0,0,0,0,0
0,0,0,0,0,0,0,0,0,0,0,0,0,0,0,0,0,0,0,0,0,0,0
endlayer

layer
0,0,0,0,0,0,0,0,0,0,0,0,0,0,0,0,0,0,0,0,0,0,0
0,0,0,0,0,0,0,0,0,0,0,0,0,0,0,0,0,0,0,0,0,0,0
0,0,0,0,0,0,0,0,0,0,0,0,0,0,0,0,0,0,0,0,0,0,0
0,0,0,0,0,0,0,0,0,0,0,0,0,0,0,0,0,0,0,0,0,0,0
0,0,0,0,0,0,0,0,0,0,0,0,0,0,0,0,0,0,0,0,0,0,0
0,0,0,0,0,0,0,0,0,0,0,0,0,0,0,0,2,0,0,0,0,0,0
0,0,0,0,0,0,0,0,0,0,0,0,0,0,2,2,2,2,0,0,0,0,0
0,0,0,0,0,0,0,0,0,0,0,0,0,0,0,0,0,0,0,0,0,0,0
0,0,0,0,0,0,0,0,0,0,0,0,0,0,0,0,0,0,0,0,0,0,0
0,0,0,0,0,0,0,0,0,0,0,0,0,0,0,0,0,0,0,0,0,0,0
0,0,0,0,0,0,0,0,0,0,0,0,0,0,0,0,0,0,0,0,0,0,0
0,0,0,0,0,0,0,0,1,0,0,2,1,2,0,0,0,0,0,0,0,0,0
0,0,0,0,0,0,0,0,2,1,0,0,1,1,0,0,0,0,0,0,0,0,0
0,0,0,0,0,0,0,0,0,0,0,0,2,2,0,0,0,0,0,0,0,0,0
0,0,0,0,0,0,0,2,0,0,0,2,0,0,0,0,0,0,0,0,0,0,0
0,0,0,0,0,0,0,0,0,0,0,1,0,0,0,0,0,0,0,0,0,0,0
0,0,0,2,0,0,0,0,2,0,0,1,0,0,0,0,0,0,0,0,0,0,0
0,0,0,0,0,0,0,0,1,0,0,0,0,0,0,0,0,0,0,0,0,0,0
0,0,0,0,0,0,0,0,0,0,2,1,2,0,0,0,0,0,0,0,0,0,0
0,0,0,0,0,0,0,0,0,0,0,1,0,0,0,0,0,0,0,0,0,0,0
0,0,0,0,0,0,0,0,0,0,0,0,0,0,0,0,0,0,0,0,0,0,0
0,0,0,0,0,0,0,0,0,0,0,0,0,0,0,0,0,0,0,0,0,0,0
0,0,0,0,0,0,0,0,0,0,0,0,0,0,0,0,0,0,0,0,0,0,0
0,0,0,0,0,0,0,0,0,0,0,0,0,0,0,0,0,0,0,0,0,0,0
0,0,0,0,0,0,0,0,0,0,0,0,0,0,0,0,0,0,0,0,0,0,0
0,0,0,0,0,0,0,0,0,0,0,0,0,0,0,0,0,0,0,0,0,0,0
0,0,0,0,0,0,0,0,0,0,0,0,0,0,0,0,0,0,0,0,0,0,0
endlayer

layer
0,0,0,0,0,0,0,0,0,0,0,0,0,0,0,0,0,0,0,0,0,0,0
0,0,0,0,0,0,0,0,0,0,0,0,0,0,0,0,0,0,0,0,0,0,0
0,0,0,0,0,0,0,0,0,0,0,0,0,0,0,0,0,0,0,0,0,0,0
0,0,0,0,0,0,0,0,0,0,0,0,0,0,0,0,0,0,0,0,0,0,0
0,0,0,0,0,0,0,0,0,0,0,0,0,0,0,0,0,0,0,0,0,0,0
0,0,0,0,0,0,0,0,0,0,0,0,0,0,0,0,0,0,0,0,0,0,0
0,0,0,0,0,0,0,0,0,0,0,0,0,0,0,0,0,0,0,0,0,0,0
0,0,0,0,0,0,0,0,0,0,0,0,0,0,0,0,0,0,0,0,0,0,0
0,0,0,0,0,0,0,0,0,0,0,0,0,0,0,0,0,0,0,0,0,0,0
0,0,0,0,0,0,0,0,0,0,0,0,0,0,0,0,0,0,0,0,0,0,0
0,0,0,0,0,0,0,0,0,0,0,0,0,0,0,0,0,0,0,0,0,0,0
0,0,0,0,0,0,0,0,2,0,0,0,2,0,0,0,0,0,0,0,0,0,0
0,0,0,0,0,0,0,0,0,1,0,0,1,1,0,0,0,0,0,0,0,0,0
0,0,0,0,0,0,0,0,0,0,0,0,0,0,0,0,0,0,0,0,0,0,0
0,0,0,0,0,0,0,0,0,0,0,0,0,0,0,0,0,0,0,0,0,0,0
0,0,0,0,0,0,0,0,0,0,0,2,0,0,0,0,0,0,0,0,0,0,0
0,0,0,0,0,0,0,0,0,0,0,1,0,0,0,0,0,0,0,0,0,0,0
0,0,0,0,0,0,0,0,2,0,0,0,0,0,0,0,0,0,0,0,0,0,0
0,0,0,0,0,0,0,0,0,0,0,2,0,0,0,0,0,0,0,0,0,0,0
0,0,0,0,0,0,0,0,0,0,0,1,0,0,0,0,0,0,0,0,0,0,0
0,0,0,0,0,0,0,0,0,0,0,0,0,0,0,0,0,0,0,0,0,0,0
0,0,0,0,0,0,0,0,0,0,0,0,0,0,0,0,0,0,0,0,0,0,0
0,0,0,0,0,0,0,0,0,0,0,0,0,0,0,0,0,0,0,0,0,0,0
0,0,0,0,0,0,0,0,0,0,0,0,0,0,0,0,0,0,0,0,0,0,0
0,0,0,0,0,0,0,0,0,0,0,0,0,0,0,0,0,0,0,0,0,0,0
0,0,0,0,0,0,0,0,0,0,0,0,0,0,0,0,0,0,0,0,0,0,0
0,0,0,0,0,0,0,0,0,0,0,0,0,0,0,0,0,0,0,0,0,0,0
endlayer

layer
0,0,0,0,0,0,0,0,0,0,0,0,0,0,0,0,0,0,0,0,0,0,0
0,0,0,0,0,0,0,0,0,0,0,0,0,0,0,0,0,0,0,0,0,0,0
0,0,0,0,0,0,0,0,0,0,0,0,0,0,0,0,0,0,0,0,0,0,0
0,0,0,0,0,0,0,0,0,0,0,0,0,0,0,0,0,0,0,0,0,0,0
0,0,0,0,0,0,0,0,0,0,0,0,0,0,0,0,0,0,0,0,0,0,0
0,0,0,0,0,0,0,0,0,0,0,0,0,0,0,0,0,0,0,0,0,0,0
0,0,0,0,0,0,0,0,0,0,0,0,0,0,0,0,0,0,0,0,0,0,0
0,0,0,0,0,0,0,0,0,0,0,0,0,0,0,0,0,0,0,0,0,0,0
0,0,0,0,0,0,0,0,0,0,0,0,0,0,0,0,0,0,0,0,0,0,0
0,0,0,0,0,0,0,0,0,0,0,0,0,0,0,0,0,0,0,0,0,0,0
0,0,0,0,0,0,0,0,0,0,0,0,0,0,0,0,0,0,0,0,0,0,0
0,0,0,0,0,0,0,0,0,0,0,0,0,0,0,0,0,0,0,0,0,0,0
0,0,0,0,0,0,0,0,0,1,0,0,1,1,0,0,0,0,0,0,0,0,0
0,0,0,0,0,0,0,0,0,0,0,0,0,0,0,0,0,0,0,0,0,0,0
0,0,0,0,0,0,0,0,0,0,0,0,0,0,0,0,0,0,0,0,0,0,0
0,0,0,0,0,0,0,0,0,0,0,0,0,0,0,0,0,0,0,0,0,0,0
0,0,0,0,0,0,0,0,0,0,0,2,0,0,0,0,0,0,0,0,0,0,0
0,0,0,0,0,0,0,0,0,0,0,0,0,0,0,0,0,0,0,0,0,0,0
0,0,0,0,0,0,0,0,0,0,0,0,0,0,0,0,0,0,0,0,0,0,0
0,0,0,0,0,0,0,0,0,0,0,1,0,0,0,0,0,0,0,0,0,0,0
0,0,0,0,0,0,0,0,0,0,0,0,0,0,0,0,0,0,0,0,0,0,0
0,0,0,0,0,0,0,0,0,0,0,0,0,0,0,0,0,0,0,0,0,0,0
0,0,0,0,0,0,0,0,0,0,0,0,0,0,0,0,0,0,0,0,0,0,0
0,0,0,0,0,0,0,0,0,0,0,0,0,0,0,0,0,0,0,0,0,0,0
0,0,0,0,0,0,0,0,0,0,0,0,0,0,0,0,0,0,0,0,0,0,0
0,0,0,0,0,0,0,0,0,0,0,0,0,0,0,0,0,0,0,0,0,0,0
0,0,0,0,0,0,0,0,0,0,0,0,0,0,0,0,0,0,0,0,0,0,0
endlayer

layer
0,0,0,0,0,0,0,0,0,0,0,0,0,0,0,0,0,0,0,0,0,0,0
0,0,0,0,0,0,0,0,0,0,0,0,0,0,0,0,0,0,0,0,0,0,0
0,0,0,0,0,0,0,0,0,0,0,0,0,0,0,0,0,0,0,0,0,0,0
0,0,0,0,0,0,0,0,0,0,0,0,0,0,0,0,0,0,0,0,0,0,0
0,0,0,0,0,0,0,0,0,0,0,0,0,0,0,0,0,0,0,0,0,0,0
0,0,0,0,0,0,0,0,0,0,0,0,0,0,0,0,0,0,0,0,0,0,0
0,0,0,0,0,0,0,0,0,0,0,0,0,0,0,0,0,0,0,0,0,0,0
0,0,0,0,0,0,0,0,0,0,0,0,0,0,0,0,0,0,0,0,0,0,0
0,0,0,0,0,0,0,0,0,0,0,0,0,0,0,0,0,0,0,0,0,0,0
0,0,0,0,0,0,0,0,0,0,0,0,0,0,0,0,0,0,0,0,0,0,0
0,0,0,0,0,0,0,0,0,0,0,0,0,0,0,0,0,0,0,0,0,0,0
0,0,0,0,0,0,0,0,0,0,0,0,0,0,0,0,0,0,0,0,0,0,0
0,0,0,0,0,0,0,0,0,1,0,0,1,2,0,0,0,0,0,0,0,0,0
0,0,0,0,0,0,0,0,0,0,0,0,0,0,0,0,0,0,0,0,0,0,0
0,0,0,0,0,0,0,0,0,0,0,0,0,0,0,0,0,0,0,0,0,0,0
0,0,0,0,0,0,0,0,0,0,0,0,0,0,0,0,0,0,0,0,0,0,0
0,0,0,0,0,0,0,0,0,0,0,0,0,0,0,0,0,0,0,0,0,0,0
0,0,0,0,0,0,0,0,0,0,0,0,0,0,0,0,0,0,0,0,0,0,0
0,0,0,0,0,0,0,0,0,0,0,0,0,0,0,0,0,0,0,0,0,0,0
0,0,0,0,0,0,0,0,0,0,0,2,0,0,0,0,0,0,0,0,0,0,0
0,0,0,0,0,0,0,0,0,0,0,0,0,0,0,0,0,0,0,0,0,0,0
0,0,0,0,0,0,0,0,0,0,0,0,0,0,0,0,0,0,0,0,0,0,0
0,0,0,0,0,0,0,0,0,0,0,0,0,0,0,0,0,0,0,0,0,0,0
0,0,0,0,0,0,0,0,0,0,0,0,0,0,0,0,0,0,0,0,0,0,0
0,0,0,0,0,0,0,0,0,0,0,0,0,0,0,0,0,0,0,0,0,0,0
0,0,0,0,0,0,0,0,0,0,0,0,0,0,0,0,0,0,0,0,0,0,0
0,0,0,0,0,0,0,0,0,0,0,0,0,0,0,0,0,0,0,0,0,0,0
endlayer

layer
0,0,0,0,0,0,0,0,0,0,0,0,0,0,0,0,0,0,0,0,0,0,0
0,0,0,0,0,0,0,0,0,0,0,0,0,0,0,0,0,0,0,0,0,0,0
0,0,0,0,0,0,0,0,0,0,0,0,0,0,0,0,0,0,0,0,0,0,0
0,0,0,0,0,0,0,0,0,0,0,0,0,0,0,0,0,0,0,0,0,0,0
0,0,0,0,0,0,0,0,0,0,0,0,0,0,0,0,0,0,0,0,0,0,0
0,0,0,0,0,0,0,0,0,0,0,0,0,0,0,0,0,0,0,0,0,0,0
0,0,0,0,0,0,0,0,0,0,0,0,0,0,0,0,0,0,0,0,0,0,0
0,0,0,0,0,0,0,0,0,0,0,0,0,0,0,0,0,0,0,0,0,0,0
0,0,0,0,0,0,0,0,0,0,0,0,0,0,0,0,0,0,0,0,0,0,0
0,0,0,0,0,0,0,0,0,0,0,0,0,0,0,0,0,0,0,0,0,0,0
0,0,0,0,0,0,0,0,0,0,0,0,0,0,0,0,0,0,0,0,0,0,0
0,0,0,0,0,0,0,0,0,0,0,0,0,0,0,0,0,0,0,0,0,0,0
0,0,0,0,0,0,0,0,0,2,0,0,1,0,0,0,0,0,0,0,0,0,0
0,0,0,0,0,0,0,0,0,0,0,0,0,0,0,0,0,0,0,0,0,0,0
0,0,0,0,0,0,0,0,0,0,0,0,0,0,0,0,0,0,0,0,0,0,0
0,0,0,0,0,0,0,0,0,0,0,0,0,0,0,0,0,0,0,0,0,0,0
0,0,0,0,0,0,0,0,0,0,0,0,0,0,0,0,0,0,0,0,0,0,0
0,0,0,0,0,0,0,0,0,0,0,0,0,0,0,0,0,0,0,0,0,0,0
0,0,0,0,0,0,0,0,0,0,0,0,0,0,0,0,0,0,0,0,0,0,0
0,0,0,0,0,0,0,0,0,0,0,0,0,0,0,0,0,0,0,0,0,0,0
0,0,0,0,0,0,0,0,0,0,0,0,0,0,0,0,0,0,0,0,0,0,0
0,0,0,0,0,0,0,0,0,0,0,0,0,0,0,0,0,0,0,0,0,0,0
0,0,0,0,0,0,0,0,0,0,0,0,0,0,0,0,0,0,0,0,0,0,0
0,0,0,0,0,0,0,0,0,0,0,0,0,0,0,0,0,0,0,0,0,0,0
0,0,0,0,0,0,0,0,0,0,0,0,0,0,0,0,0,0,0,0,0,0,0
0,0,0,0,0,0,0,0,0,0,0,0,0,0,0,0,0,0,0,0,0,0,0
0,0,0,0,0,0,0,0,0,0,0,0,0,0,0,0,0,0,0,0,0,0,0
endlayer

layer
0,0,0,0,0,0,0,0,0,0,0,0,0,0,0,0,0,0,0,0,0,0,0
0,0,0,0,0,0,0,0,0,0,0,0,0,0,0,0,0,0,0,0,0,0,0
0,0,0,0,0,0,0,0,0,0,0,0,0,0,0,0,0,0,0,0,0,0,0
0,0,0,0,0,0,0,0,0,0,0,0,0,0,0,0,0,0,0,0,0,0,0
0,0,0,0,0,0,0,0,0,0,0,0,0,0,0,0,0,0,0,0,0,0,0
0,0,0,0,0,0,0,0,0,0,0,0,0,0,0,0,0,0,0,0,0,0,0
0,0,0,0,0,0,0,0,0,0,0,0,0,0,0,0,0,0,0,0,0,0,0
0,0,0,0,0,0,0,0,0,0,0,0,0,0,0,0,0,0,0,0,0,0,0
0,0,0,0,0,0,0,0,0,0,0,0,0,0,0,0,0,0,0,0,0,0,0
0,0,0,0,0,0,0,0,0,0,0,0,0,0,0,0,0,0,0,0,0,0,0
0,0,0,0,0,0,0,0,0,0,0,0,0,0,0,0,0,0,0,0,0,0,0
0,0,0,0,0,0,0,0,0,0,0,0,0,0,0,0,0,0,0,0,0,0,0
0,0,0,0,0,0,0,0,0,0,0,0,2,0,0,0,0,0,0,0,0,0,0
0,0,0,0,0,0,0,0,0,0,0,0,0,0,0,0,0,0,0,0,0,0,0
0,0,0,0,0,0,0,0,0,0,0,0,0,0,0,0,0,0,0,0,0,0,0
0,0,0,0,0,0,0,0,0,0,0,0,0,0,0,0,0,0,0,0,0,0,0
0,0,0,0,0,0,0,0,0,0,0,0,0,0,0,0,0,0,0,0,0,0,0
0,0,0,0,0,0,0,0,0,0,0,0,0,0,0,0,0,0,0,0,0,0,0
0,0,0,0,0,0,0,0,0,0,0,0,0,0,0,0,0,0,0,0,0,0,0
0,0,0,0,0,0,0,0,0,0,0,0,0,0,0,0,0,0,0,0,0,0,0
0,0,0,0,0,0,0,0,0,0,0,0,0,0,0,0,0,0,0,0,0,0,0
0,0,0,0,0,0,0,0,0,0,0,0,0,0,0,0,0,0,0,0,0,0,0
0,0,0,0,0,0,0,0,0,0,0,0,0,0,0,0,0,0,0,0,0,0,0
0,0,0,0,0,0,0,0,0,0,0,0,0,0,0,0,0,0,0,0,0,0,0
0,0,0,0,0,0,0,0,0,0,0,0,0,0,0,0,0,0,0,0,0,0,0
0,0,0,0,0,0,0,0,0,0,0,0,0,0,0,0,0,0,0,0,0,0,0
0,0,0,0,0,0,0,0,0,0,0,0,0,0,0,0,0,0,0,0,0,0,0
endlayer

