
# Created by Ruins mod version 17.2 Ingame Parser
# authoring Player: BARTLLOW

# TEMPLATE PARAMETER SETTINGS:
#
# criterion expression specifying mod ids required to load template
# may include plus (AND), minus (AND NOT), comma (OR), and parentheses
# all required mods listed must be present; no prohibited mods can be
requiredMods=
#
# likelihood this template will be chosen relative to all others
# e.g., a weight=6 template is chosen 3X as often as one with weight=2
weight=1
#
# list of dimensions in which this template may spawn, even if generic
# one or more dimension names, separated by commas (blank = all)
dimensionsToSpawnIn=
#
# list of other biomes in which this template may spawn
# biome corresponding to directory is always assumed, listed or not
# generic templates should leave this list empty
biomesToSpawnIn=
#
# criterion expression specifying types of biome where template spawns
# this is in addition to those explicitly listed as biomesToSpawnIn
# generic templates should leave this list empty
biomeTypesToSpawnIn=
#
# list of biomes in which this template may not spawn
# takes precedence over biomeTypesToSpawnIn, but NOT biomesToSpawnIn
# should be empty if biomeTypesToSpawnIn is empty
biomesToNotSpawnIn=
#
# depth template is pushed down into the surface when built
# offset is min/max range of random additional bury depth
embed_into_distance=0
random_height_offset=0,0
#
# whitelist/blacklist of block types on which template may be built
# specify one, not both; leave the other empty (both empty = allow all)
acceptable_target_blocks=
unacceptable_target_blocks=flowing_water,water,flowing_lava,lava
#
# size of template (#layers, #rows per layer, #blocks per row)
dimensions=18,33,37
#
# max number of missing blocks allowed in surface beneath template
allowable_overhang=0
#
# depth/height limit affected by terrain leveling
# also maximum bumpiness tolerated in surface beneath template
max_leveling=2
#
# padding applied to all sides of template horizontal footprint
# expands area affected by terrain leveling (-1 = no leveling)
leveling_buffer=0
#
# do not rotate template randomly when built (1 = no rotation)
preventRotation=0
#
# treat water/lava blocks as air and protect them from rule0 (1 = yes)
preserve_water=0
preserve_lava=0
#
# minimum distance this template must have from instances of itself
uniqueMinDistance=0
#
# min/max distances this template can be from world spawn (0 = no limit)
# only applies to overworld--i.e., dimension 0
spawnMinDistance=0
spawnMaxDistance=0
#
# other template built nearby whenever this one is
# syntax: <name>;<relativeX>;<maxYdifference>;<relativeZ>[;<chance>]
# may be used more than once to specify multiple neighbors
adjoining_template=

rule1=0,100,minecraft:sponge-0
rule2=0,100,minecraft:dirt-0
rule3=0,100,minecraft:sandstone-2
rule4=0,100,minecraft:sandstone-0
rule5=0,100,minecraft:sandstone_stairs-3
rule6=0,100,minecraft:sandstone_stairs-0
rule7=0,100,minecraft:sandstone_stairs-1
rule8=0,100,minecraft:sandstone_stairs-5
rule9=0,100,minecraft:sandstone_stairs-7
rule10=0,100,minecraft:sandstone_stairs-2
rule11=0,100,minecraft:web-0
rule12=0,100,minecraft:mob_spawner-0
rule13=0,100,minecraft:stone_slab-1
rule14=0,100,IInventory;minecraft:chest;minecraft:leather_helmet#1#0#1+minecraft:leather_boots#1#0#9+minecraft:written_book#{pages:["\"Count the blizzards, call the light.\\nEva! Oh, Eva!\\n2000 cheeks endure swiftly\\nIs lethargy really quick like dawn?\\nSo relaxed\\nYet there\\u0027s dawn under the desires and the hearts.\\n\"","\"What is the comfortable penumb ra to gamely make the water?\\nAlthough it\\u0027s now more empty and less vigorous.\\n\\nCount the smiles, befriend the desire.\\nHow does the snow \"","\"not endure?\\nThey see to see.\\nSo veiled\\nYet there\\u0027s fear under the transformations an d the texts.\\nAs the beds are, the mosquitoes found otherwhile.\\n\""],author:"Joonas Emiliasson",title:"50 embraces"}#0#13+minecraft:leather#5#0#16+minecraft:web#1#0#26-5
rule15=0,100,IInventory;minecraft:chest;minecraft:web#1#0#1+minecraft:web#1#0#2+minecraft:web#1#0#6+minecraft:leather_helmet#1#0#12+minecraft:leather_helmet#1#0#19-4
rule16=0,100,minecraft:sandstone_stairs-4
rule17=2,100,minecraft:torch-4
rule18=0,100,IInventory;minecraft:chest;minecraft:coal#5#0#3+minecraft:web#1#0#12+minecraft:emerald#1#0#22+minecraft:web#1#0#24-3
rule19=0,100,minecraft:stone_slab-9
rule20=0,100,IInventory;minecraft:chest;minecraft:bone#1#0#7+minecraft:web#1#0#16+minecraft:coal#29#0#17+minecraft:written_book#{pages:["\"Where is the  byssopelagic miasm a, the abyssopelagic betr ayal now?\\nNow the betrayal is abyssopelagic\\n\\nWhere is the  byssopelagic miasm \"","\"a, the abyssopelagic betr ayal now?\\nWhere is the  byssopelagic miasm a, the abyssopelagic betr ayal now?\\n\""],author:"Lars Rebekkasson",title:"Jon"}#0#24-5
rule21=0,100,minecraft:sandstone_stairs-6

layer
1,1,1,1,1,1,1,1,1,1,1,1,1,1,1,1,1,1,1,1,1,1,1,1,1,1,1,1,1,1,1,1,1,1,1,1,1
1,1,2,1,1,1,1,1,1,1,1,2,1,1,2,2,1,1,1,1,2,2,1,2,1,2,1,1,2,1,2,2,1,1,1,1,1
1,1,2,2,2,2,1,2,1,2,1,1,1,1,2,2,2,2,1,1,1,1,1,2,1,1,2,2,2,2,1,1,1,1,1,1,1
1,1,1,1,1,2,1,2,2,1,1,2,1,2,1,1,2,1,1,1,2,1,1,2,1,2,1,2,1,1,1,1,1,1,1,1,1
1,1,1,2,1,1,1,1,1,1,1,2,1,1,1,1,2,1,2,1,1,2,1,2,2,1,1,2,2,1,1,1,1,1,1,1,1
1,2,2,1,2,1,2,1,2,1,2,2,2,1,1,1,1,1,1,1,1,2,2,1,1,2,2,1,1,1,1,1,1,1,1,1,1
1,1,1,2,1,2,1,1,1,1,1,1,1,1,2,2,1,2,2,1,1,1,1,2,2,1,2,1,2,2,1,2,1,1,1,1,1
1,1,2,2,2,1,1,2,2,2,1,1,2,2,1,1,2,2,1,1,2,1,2,2,1,2,1,1,2,1,2,2,1,1,1,1,1
1,1,1,2,1,1,1,2,1,2,1,2,1,1,1,1,1,1,2,1,1,1,1,1,1,1,1,2,2,2,1,1,1,1,1,1,1
1,2,1,1,1,1,2,2,2,2,1,2,1,1,1,1,2,1,1,2,1,1,2,1,2,1,1,2,1,1,1,1,1,1,1,1,1
1,2,1,1,1,2,2,2,1,2,2,2,2,1,1,1,1,1,1,1,1,2,2,1,1,1,1,1,1,1,1,1,1,1,1,1,1
1,2,2,2,1,2,1,1,2,1,2,2,1,2,1,2,2,1,2,1,2,1,1,2,1,2,2,1,1,1,1,1,1,1,1,1,1
1,1,1,2,2,2,1,2,2,2,1,1,1,1,2,2,1,1,1,2,1,1,1,1,1,1,1,2,1,1,1,2,1,1,1,1,1
1,1,1,2,1,1,2,1,2,1,1,2,1,2,1,2,1,1,1,1,1,1,1,2,1,2,2,2,1,2,2,2,1,1,1,1,1
1,2,1,1,1,1,2,2,2,1,1,2,1,2,1,2,1,2,1,1,2,2,1,2,1,1,2,1,2,2,1,2,2,1,1,1,1
1,2,1,1,1,2,1,2,2,1,2,1,2,1,1,1,1,1,2,1,2,1,1,1,1,2,1,1,1,2,1,2,1,1,1,1,1
1,2,2,1,1,1,1,2,1,2,1,1,1,1,2,1,1,2,2,1,1,2,1,1,1,2,2,2,1,1,2,2,1,1,2,1,1
1,1,2,2,1,1,2,2,1,1,1,2,2,1,2,2,1,1,1,1,2,2,1,2,1,1,2,2,2,2,2,2,1,1,1,1,1
1,2,2,1,1,2,1,1,1,2,1,1,2,1,2,2,1,1,1,1,2,1,1,2,1,2,1,1,1,1,1,2,2,1,1,1,1
1,1,1,1,2,2,2,1,1,1,1,2,1,2,1,1,1,2,1,2,1,1,1,1,1,2,1,2,2,2,2,1,1,1,1,1,1
1,1,2,2,2,1,1,1,1,1,2,1,2,1,2,1,1,1,1,1,2,2,1,2,1,1,2,2,2,1,2,2,1,1,1,1,1
1,1,2,1,1,2,2,1,1,1,2,2,1,2,1,1,1,2,2,1,1,1,1,2,2,1,1,1,2,1,1,1,1,1,1,1,1
1,1,1,1,1,1,1,1,1,1,1,2,2,1,2,1,2,1,2,1,1,2,1,1,2,2,2,1,2,1,2,2,1,1,1,1,1
1,1,1,2,1,1,1,2,1,2,1,1,2,1,1,1,1,1,2,1,1,1,2,2,1,1,1,1,1,1,1,2,1,1,1,1,1
1,2,2,1,1,1,1,1,1,2,1,1,2,2,2,2,1,1,1,1,1,2,1,1,2,1,1,1,1,1,1,1,1,1,1,1,1
1,2,1,1,2,2,1,1,2,1,1,2,1,2,1,2,1,1,2,2,2,1,1,2,1,1,2,1,1,1,1,2,1,1,1,1,1
1,1,1,1,2,1,1,2,2,1,1,1,2,2,1,1,1,2,1,2,2,1,2,1,2,1,1,1,1,1,1,2,1,1,1,1,1
1,2,1,1,1,1,1,1,1,1,2,2,1,1,2,2,1,1,2,2,2,1,1,1,1,2,2,2,2,1,1,1,1,1,1,1,1
1,2,2,2,1,1,1,2,1,1,1,2,2,2,1,1,2,2,1,2,1,2,1,1,2,1,2,1,1,1,1,1,1,1,1,1,1
1,2,1,1,1,1,2,2,1,1,2,2,1,2,2,1,1,1,1,2,1,2,1,2,1,1,1,1,2,2,1,1,1,1,1,1,1
1,1,2,2,2,2,2,2,1,1,2,1,1,2,1,1,1,1,1,2,2,1,2,1,2,2,2,2,1,1,1,1,1,1,1,1,1
1,2,1,2,2,1,1,1,2,1,1,1,2,1,1,1,1,1,1,1,1,1,1,2,2,2,1,1,1,1,2,2,1,1,1,1,1
1,1,1,1,1,1,1,1,1,1,1,1,1,1,1,1,1,1,1,1,1,1,1,1,1,1,1,1,1,1,1,1,1,1,1,1,1
endlayer

layer
1,1,1,1,1,1,1,1,1,1,1,1,1,1,1,1,1,1,1,1,1,1,1,1,1,1,1,1,1,1,1,1,1,1,1,1,1
1,3,3,3,3,3,3,3,3,3,3,3,3,3,3,3,3,3,3,3,3,3,3,3,3,3,3,3,3,3,3,3,1,1,1,1,1
1,3,3,3,3,3,3,3,3,3,3,3,3,3,3,3,3,3,3,3,3,3,3,3,3,3,3,3,3,3,3,3,1,1,1,1,1
1,3,3,3,3,3,3,3,3,3,3,3,3,3,3,3,3,3,3,3,3,3,3,3,3,3,3,3,3,3,3,3,1,1,1,1,1
1,3,3,3,3,3,3,3,3,3,3,3,3,3,3,3,3,3,3,3,3,3,3,3,3,3,3,3,3,3,3,3,1,1,1,1,1
1,3,3,3,3,3,3,3,3,3,3,3,3,3,3,3,3,3,3,3,3,3,3,3,3,3,3,3,3,3,3,3,1,1,1,1,1
1,3,3,3,3,3,4,4,3,3,3,3,3,3,3,3,3,3,3,3,3,3,3,4,3,3,3,3,3,3,3,3,1,1,1,1,1
1,3,3,3,3,3,3,5,4,3,3,3,3,3,3,3,3,3,3,3,3,3,3,4,3,3,4,3,3,3,3,3,1,1,1,1,1
1,3,3,3,3,3,3,3,3,3,3,3,3,3,3,3,3,3,3,3,3,4,4,3,3,3,4,3,3,3,3,3,1,1,1,1,1
1,3,3,3,3,3,4,3,3,3,3,3,3,3,3,3,3,3,3,3,3,7,4,3,3,3,6,3,3,3,3,3,1,1,1,1,1
1,3,3,3,3,3,3,3,3,3,3,3,3,3,3,3,3,3,3,3,3,8,4,4,3,4,3,3,3,3,3,3,1,1,1,1,1
1,3,3,3,3,3,3,3,3,3,3,3,3,3,3,3,3,3,3,3,3,4,3,3,4,3,3,3,3,3,3,3,1,1,1,1,1
1,3,3,3,3,3,3,4,4,3,3,4,4,4,3,3,4,4,3,3,3,3,3,3,3,3,3,3,3,3,3,3,1,1,1,1,1
1,3,3,3,3,3,4,3,3,3,4,3,3,4,3,4,3,4,3,3,3,3,3,3,3,4,3,3,3,3,3,3,1,1,1,1,1
1,3,3,3,3,3,9,3,4,3,4,4,4,3,3,3,4,3,3,3,3,3,3,3,4,8,3,3,3,3,3,3,3,1,1,1,1
1,3,3,3,3,3,4,3,4,3,3,3,3,3,3,3,3,3,3,3,3,3,3,3,3,3,3,3,3,3,3,3,3,3,3,1,1
1,3,3,3,3,3,4,3,4,3,3,3,3,3,3,3,3,3,3,3,3,3,3,3,3,3,3,3,3,3,3,3,3,3,3,3,1
1,3,3,3,3,3,4,3,4,3,3,3,3,3,3,3,3,3,3,3,3,3,3,3,3,3,3,3,3,3,3,3,3,3,3,1,1
1,3,3,3,3,3,3,4,3,3,3,3,3,3,3,4,4,4,3,3,3,3,3,3,3,3,3,3,3,3,3,3,3,1,1,1,1
1,3,3,3,3,3,3,3,3,3,3,3,3,3,3,3,3,3,3,3,3,3,3,3,4,3,3,3,3,3,3,3,1,1,1,1,1
1,3,3,3,3,3,3,3,3,3,3,3,3,3,3,3,3,3,3,3,3,3,3,3,4,3,3,3,3,3,3,3,1,1,1,1,1
1,3,3,3,3,3,3,3,3,3,3,3,4,4,3,3,3,3,3,3,3,3,3,3,3,4,4,3,3,3,3,3,1,1,1,1,1
1,3,3,3,3,3,3,3,3,3,3,3,3,3,3,3,3,3,3,3,3,3,3,3,3,3,3,3,3,3,3,3,1,1,1,1,1
1,3,3,3,3,3,3,3,3,3,3,3,3,3,3,4,4,4,3,3,3,3,3,3,3,4,3,3,3,3,3,3,1,1,1,1,1
1,3,3,3,3,3,3,3,3,3,3,3,3,3,3,3,3,4,3,4,4,4,3,3,4,3,3,3,3,3,3,3,1,1,1,1,1
1,3,3,3,3,3,3,3,3,3,3,3,3,4,3,4,3,3,3,3,4,3,3,4,3,4,3,3,3,3,3,3,1,1,1,1,1
1,3,3,3,3,3,3,3,3,3,3,3,4,3,3,4,3,3,3,3,3,3,4,3,4,4,3,3,3,3,3,3,1,1,1,1,1
1,3,3,3,3,3,3,3,3,3,3,3,3,3,3,3,3,3,3,3,3,3,3,3,3,3,3,3,3,3,3,3,1,1,1,1,1
1,3,3,3,3,3,3,3,3,3,3,3,3,3,3,3,3,3,3,3,3,3,3,3,3,3,3,3,3,3,3,3,1,1,1,1,1
1,3,3,3,3,3,3,3,3,3,3,3,3,3,3,3,3,3,3,3,3,3,3,3,3,3,3,3,3,3,3,3,1,1,1,1,1
1,3,3,3,3,3,3,3,3,3,3,3,3,3,3,3,3,3,3,3,3,3,3,3,3,3,3,3,3,3,3,3,1,1,1,1,1
1,3,3,3,3,3,3,3,3,3,3,3,3,3,3,3,3,3,3,3,3,3,3,3,3,3,3,3,3,3,3,3,1,1,1,1,1
1,1,1,1,1,1,1,1,1,1,1,1,1,1,1,1,1,1,1,1,1,1,1,1,1,1,1,1,1,1,1,1,1,1,1,1,1
endlayer

layer
0,0,0,0,0,0,0,0,0,0,0,0,0,0,0,0,0,0,0,0,0,0,0,0,0,0,0,0,0,0,0,0,0,0,0,0,0
0,5,6,6,6,6,6,6,6,6,6,6,6,6,6,6,6,6,6,6,6,6,6,6,6,6,6,6,6,6,6,6,0,0,0,0,0
0,5,3,3,3,3,3,3,3,3,3,3,3,3,3,3,3,3,3,3,3,3,3,3,3,3,3,3,3,3,3,10,0,0,0,0,0
0,5,3,3,3,3,3,3,3,3,3,3,3,3,3,3,3,3,3,3,3,3,3,3,3,3,3,3,3,3,3,10,0,0,0,0,0
0,5,3,3,3,3,3,3,3,3,3,3,3,3,3,3,3,3,3,3,3,3,3,3,3,3,3,3,3,3,3,10,0,0,0,0,0
0,5,3,3,3,3,3,3,3,3,3,3,3,3,3,3,3,3,3,3,3,3,3,3,3,3,3,3,3,3,3,10,0,0,0,0,0
0,5,3,3,3,3,3,4,3,3,3,3,3,3,3,3,3,3,3,3,3,3,9,4,3,7,3,3,3,3,3,10,0,0,0,0,0
0,5,3,3,3,3,7,0,0,0,0,0,13,12,3,3,12,0,11,0,0,3,0,0,3,0,3,3,3,3,3,10,0,0,0,0,0
0,5,3,3,3,3,4,3,3,3,13,11,0,0,3,3,13,0,13,0,3,3,4,4,3,0,3,3,3,3,3,10,0,0,0,0,0
0,5,3,3,3,3,4,3,3,3,3,0,13,11,3,3,0,11,0,3,3,3,3,4,4,4,3,3,3,3,3,10,0,0,0,0,0
0,5,3,3,3,3,4,0,0,0,0,3,0,0,3,3,0,13,3,0,0,0,0,4,0,0,4,3,3,3,3,10,0,0,0,0,0
0,5,3,3,3,3,3,3,4,3,0,3,3,0,3,3,0,3,3,0,3,3,3,4,3,3,3,3,3,3,3,10,0,0,0,0,0
0,5,3,3,3,3,3,0,9,3,0,3,3,0,4,4,3,3,3,0,3,3,3,3,4,0,4,3,3,3,3,10,0,0,0,0,0
0,5,3,3,3,3,4,0,3,3,11,3,3,0,3,0,0,3,3,0,5,3,3,3,3,0,3,3,3,3,3,3,0,0,0,0,0
0,5,3,3,3,3,4,3,3,3,3,3,3,4,4,3,3,3,3,0,3,3,3,3,4,4,4,3,3,3,0,0,0,0,0,0,0
0,5,3,3,3,3,3,3,3,3,3,3,3,3,3,0,0,14,3,0,0,0,0,3,3,0,0,0,0,0,3,0,0,0,0,0,0
0,5,3,3,3,3,4,0,3,3,12,0,11,0,0,0,13,13,3,3,3,3,0,0,0,0,0,0,0,0,0,0,0,0,0,0,0
0,5,3,3,3,3,3,0,4,3,13,0,13,0,3,0,0,15,3,3,3,3,3,3,3,0,0,0,0,0,3,0,0,0,0,0,0
0,5,3,3,3,3,3,3,3,3,0,11,0,3,3,3,3,4,3,3,3,3,3,3,4,3,3,3,3,3,0,0,0,0,0,0,0
0,5,3,3,3,3,3,0,3,3,0,13,3,0,0,4,0,3,0,0,0,13,12,3,3,0,3,3,3,3,3,3,0,0,0,0,0
0,5,3,3,3,3,3,0,4,3,0,3,3,0,3,4,0,3,3,13,11,0,0,3,3,0,3,3,3,3,3,10,0,0,0,0,0
0,5,3,3,3,3,3,0,3,3,0,3,4,3,16,3,0,4,3,3,0,13,11,3,3,0,3,3,3,3,3,10,0,0,0,0,0
0,5,3,3,3,3,3,0,9,3,0,0,0,0,3,3,0,3,0,0,3,0,0,3,4,0,3,3,3,3,3,10,0,0,0,0,0
0,5,3,3,3,3,3,0,8,9,3,3,3,3,3,4,4,3,3,0,3,3,0,3,3,4,3,3,3,3,3,10,0,0,0,0,0
0,5,3,3,3,3,3,0,0,9,8,3,3,4,3,3,3,4,3,4,4,4,0,4,3,4,10,3,3,3,3,10,0,0,0,0,0
0,5,3,3,3,3,3,3,0,0,0,0,11,0,3,3,0,0,0,0,4,4,0,3,0,0,3,3,3,3,3,10,0,0,0,0,0
0,5,3,3,3,3,3,3,3,3,3,3,4,3,4,4,3,3,3,4,3,3,4,4,3,4,3,3,3,3,3,10,0,0,0,0,0
0,5,3,3,3,3,3,3,3,3,3,3,3,3,3,3,3,3,3,3,3,3,3,3,3,3,3,3,3,3,3,10,0,0,0,0,0
0,5,3,3,3,3,3,3,3,3,3,3,3,3,3,3,3,3,3,3,3,3,3,3,3,3,3,3,3,3,3,10,0,0,0,0,0
0,5,3,3,3,3,3,3,3,3,3,3,3,3,3,3,3,3,3,3,3,3,3,3,3,3,3,3,3,3,3,10,0,0,0,0,0
0,5,3,3,3,3,3,3,3,3,3,3,3,3,3,3,3,3,3,3,3,3,3,3,3,3,3,3,3,3,3,10,0,0,0,0,0
0,7,7,7,7,7,7,7,7,7,7,7,7,7,7,7,7,7,7,7,7,7,7,7,7,7,7,7,7,7,7,7,0,0,0,0,0
0,0,0,0,0,0,0,0,0,0,0,0,0,0,0,0,0,0,0,0,0,0,0,0,0,0,0,0,0,0,0,0,0,0,0,0,0
endlayer

layer
0,0,0,0,0,0,0,0,0,0,0,0,0,0,0,0,0,0,0,0,0,0,0,0,0,0,0,0,0,0,0,0,0,0,0,0,0
0,0,0,0,0,0,0,0,0,0,0,0,0,0,0,0,0,0,0,0,0,0,0,0,0,0,0,0,0,0,0,0,0,0,0,0,0
0,0,6,6,6,6,6,6,6,6,6,6,6,6,6,6,6,6,6,6,6,6,6,6,6,6,6,6,6,6,6,0,0,0,0,0,0
0,0,5,3,3,3,3,3,3,3,3,3,3,3,3,3,3,3,3,3,3,3,3,3,3,3,3,3,3,3,10,0,0,0,0,0,0
0,0,5,3,3,3,3,3,3,3,3,3,3,3,3,3,3,3,3,3,3,3,3,3,3,3,3,3,3,3,10,0,0,0,0,0,0
0,0,5,3,3,3,3,3,3,3,3,3,3,3,3,3,3,3,3,3,3,3,3,3,3,3,3,3,3,3,10,0,0,0,0,0,0
0,0,5,3,3,3,3,4,4,3,3,3,3,3,3,3,3,3,3,3,3,3,4,4,4,4,3,3,3,3,10,0,0,0,0,0,0
0,0,5,3,3,3,4,0,0,11,0,0,0,11,3,3,11,0,0,0,11,11,11,0,0,0,4,3,3,3,10,0,0,0,0,0,0
0,0,5,3,3,3,4,0,3,3,0,0,0,0,3,3,0,0,0,11,3,3,3,4,3,11,3,3,3,3,10,0,0,0,0,0,0
0,0,5,3,3,3,4,0,4,3,3,0,0,0,3,3,0,0,0,3,3,4,4,3,4,0,3,3,3,3,10,0,0,0,0,0,0
0,0,5,3,3,3,3,0,0,0,0,3,11,0,3,3,0,0,3,0,0,0,0,0,0,0,3,3,3,3,10,0,0,0,0,0,0
0,0,5,3,3,3,3,0,3,3,0,3,3,11,3,3,11,3,3,0,3,3,4,10,3,0,16,3,3,3,10,0,0,0,0,0,0
0,0,5,3,3,3,3,0,3,4,0,4,4,0,3,3,0,3,3,0,3,3,3,3,5,0,3,3,3,3,10,0,0,0,0,0,0
0,0,5,3,3,3,4,0,3,3,0,4,4,0,0,0,0,3,3,0,0,0,0,3,10,0,4,3,3,3,3,3,0,0,0,0,0
0,0,5,3,3,3,3,0,3,3,4,3,3,4,3,3,3,4,3,0,3,3,6,3,4,0,4,3,3,3,0,0,0,0,0,0,0
0,0,5,3,3,3,3,0,3,3,3,3,3,3,3,17,0,0,3,0,0,0,0,3,3,0,0,0,0,0,3,0,0,0,0,0,0
0,0,5,3,3,3,4,0,4,3,11,0,0,0,11,0,0,0,3,3,3,3,0,0,0,0,0,0,0,0,0,0,0,0,0,0,0
0,0,5,3,3,3,4,0,4,3,0,0,0,11,3,17,0,0,3,3,3,3,3,3,3,0,0,0,0,0,3,0,0,0,0,0,0
0,0,5,3,3,3,3,0,3,3,0,0,0,3,3,3,3,3,3,3,3,3,3,3,3,0,3,3,3,3,0,0,0,0,0,0,0
0,0,5,3,3,3,3,0,4,3,0,0,3,0,0,0,0,0,11,0,0,0,11,3,3,0,4,3,3,3,3,3,0,0,0,0,0
0,0,5,3,3,3,4,0,3,3,11,3,3,0,3,4,0,3,3,0,0,0,0,3,3,0,4,3,3,3,10,0,0,0,0,0,0
0,0,5,3,3,3,3,0,3,3,0,3,3,0,3,3,0,4,3,3,0,0,0,3,4,0,4,3,3,3,10,0,0,0,0,0,0
0,0,5,3,3,3,3,0,18,3,0,0,0,0,4,3,0,0,0,0,3,11,0,3,4,0,4,3,3,3,10,0,0,0,0,0,0
0,0,5,3,3,3,3,0,0,19,3,3,3,0,4,3,3,4,3,0,3,3,11,3,3,0,3,3,3,3,10,0,0,0,0,0,0
0,0,5,3,3,3,3,0,0,0,20,3,4,0,3,4,3,3,3,0,3,3,0,4,4,0,3,3,3,3,10,0,0,0,0,0,0
0,0,5,3,3,3,3,3,0,0,0,0,0,0,3,3,0,0,0,0,3,21,0,0,0,0,3,3,3,3,10,0,0,0,0,0,0
0,0,5,3,3,3,3,3,3,3,3,3,3,3,3,3,3,3,3,3,4,3,3,3,3,3,3,3,3,3,10,0,0,0,0,0,0
0,0,5,3,3,3,3,3,3,3,3,3,3,3,3,3,3,3,3,3,3,3,3,3,3,3,3,3,3,3,10,0,0,0,0,0,0
0,0,5,3,3,3,3,3,3,3,3,3,3,3,3,3,3,3,3,3,3,3,3,3,3,3,3,3,3,3,10,0,0,0,0,0,0
0,0,5,3,3,3,3,3,3,3,3,3,3,3,3,3,3,3,3,3,3,3,3,3,3,3,3,3,3,3,10,0,0,0,0,0,0
0,0,7,7,7,7,7,7,7,7,7,7,7,7,7,7,7,7,7,7,7,7,7,7,7,7,7,7,7,7,10,0,0,0,0,0,0
0,0,0,0,0,0,0,0,0,0,0,0,0,0,0,0,0,0,0,0,0,0,0,0,0,0,0,0,0,0,0,0,0,0,0,0,0
0,0,0,0,0,0,0,0,0,0,0,0,0,0,0,0,0,0,0,0,0,0,0,0,0,0,0,0,0,0,0,0,0,0,0,0,0
endlayer

layer
0,0,0,0,0,0,0,0,0,0,0,0,0,0,0,0,0,0,0,0,0,0,0,0,0,0,0,0,0,0,0,0,0,0,0,0,0
0,0,0,0,0,0,0,0,0,0,0,0,0,0,0,0,0,0,0,0,0,0,0,0,0,0,0,0,0,0,0,0,0,0,0,0,0
0,0,0,0,0,0,0,0,0,0,0,0,0,0,0,0,0,0,0,0,0,0,0,0,0,0,0,0,0,0,0,0,0,0,0,0,0
0,0,0,6,6,6,6,6,6,6,6,6,6,6,6,6,6,6,6,6,6,6,6,6,6,6,6,6,6,6,0,0,0,0,0,0,0
0,0,0,5,3,3,3,3,3,3,3,3,3,3,3,3,3,3,3,3,3,3,3,3,3,3,3,3,3,10,0,0,0,0,0,0,0
0,0,0,5,3,3,3,3,3,3,3,3,3,3,3,3,3,3,3,3,3,3,3,3,3,3,3,3,3,10,0,0,0,0,0,0,0
0,0,0,5,3,3,21,3,4,3,3,3,3,3,3,3,3,3,3,3,3,4,4,4,3,4,4,3,3,10,0,0,0,0,0,0,0
0,0,0,5,3,3,3,3,3,3,3,0,0,3,3,3,3,0,0,3,3,3,3,3,3,3,4,3,3,10,0,0,0,0,0,0,0
0,0,0,5,3,3,4,3,4,3,3,0,0,0,3,3,0,0,0,3,3,4,3,3,4,3,3,3,3,10,0,0,0,0,0,0,0
0,0,0,5,3,3,4,3,3,3,3,3,0,0,3,3,0,0,3,3,3,3,3,4,4,3,4,3,3,10,0,0,0,0,0,0,0
0,0,0,5,3,3,3,3,4,3,3,3,3,3,3,3,3,3,3,3,3,3,3,3,3,3,3,3,3,10,0,0,0,0,0,0,0
0,0,0,5,3,3,4,4,3,3,3,3,3,3,3,3,3,3,3,3,3,4,3,3,8,4,4,3,3,10,0,0,0,0,0,0,0
0,0,0,5,3,3,3,4,3,4,3,3,3,3,4,3,3,3,3,3,3,3,3,3,4,3,4,3,3,10,0,0,0,0,0,0,0
0,0,0,5,3,3,3,3,4,4,3,3,3,3,3,4,3,3,3,0,0,0,0,3,4,4,4,3,3,10,0,0,0,0,0,0,0
0,0,0,5,3,3,4,4,4,3,3,3,3,3,3,7,3,4,3,3,3,3,0,3,4,4,3,3,3,10,0,0,0,0,0,0,0
0,0,0,5,3,3,4,3,3,3,3,3,3,3,3,0,0,0,3,3,3,3,6,3,3,3,3,0,3,10,6,0,0,0,0,0,0
0,0,0,5,3,3,3,4,3,3,3,0,0,3,3,0,0,0,3,3,3,3,3,3,0,0,0,0,3,4,4,0,0,0,0,0,0
0,0,0,5,3,3,3,8,4,3,0,0,0,3,3,0,0,0,3,3,3,3,3,3,3,3,3,0,3,7,7,0,0,0,0,0,0
0,0,0,5,3,3,3,4,3,3,0,0,3,3,3,3,21,3,3,3,3,3,3,3,3,4,3,3,3,10,0,0,0,0,0,0,0
0,0,0,5,3,3,3,4,3,3,3,3,3,3,3,3,3,3,3,3,0,0,3,3,3,3,3,3,3,10,0,0,0,0,0,0,0
0,0,0,5,3,3,3,3,3,3,3,3,3,3,3,4,3,3,3,3,0,0,0,3,4,3,3,3,3,10,0,0,0,0,0,0,0
0,0,0,5,3,3,3,3,3,3,3,3,3,3,3,4,4,16,3,3,3,0,0,3,4,3,4,3,3,10,0,0,0,0,0,0,0
0,0,0,5,3,3,3,0,0,3,3,3,4,3,4,3,4,4,3,3,3,3,3,3,6,3,3,3,3,10,0,0,0,0,0,0,0
0,0,0,5,3,3,3,0,0,3,3,3,3,4,3,4,3,3,3,3,3,3,3,3,4,3,3,3,3,10,0,0,0,0,0,0,0
0,0,0,5,3,3,3,0,0,0,0,3,6,4,3,3,3,4,3,3,3,4,4,3,3,3,3,3,3,10,0,0,0,0,0,0,0
0,0,0,5,3,3,3,3,0,0,0,3,3,3,3,3,3,4,4,4,3,3,3,4,16,4,3,3,3,10,0,0,0,0,0,0,0
0,0,0,5,3,3,3,3,3,3,3,3,3,6,3,3,4,3,3,3,4,4,3,3,4,3,3,3,3,10,0,0,0,0,0,0,0
0,0,0,5,3,3,3,3,3,3,3,3,3,3,3,3,3,3,3,3,3,3,3,3,3,3,3,3,3,10,0,0,0,0,0,0,0
0,0,0,5,3,3,3,3,3,3,3,3,3,3,3,3,3,3,3,3,3,3,3,3,3,3,3,3,3,10,0,0,0,0,0,0,0
0,0,0,7,7,7,7,7,7,7,7,7,7,7,7,7,7,7,7,7,7,7,7,7,7,7,7,7,7,7,0,0,0,0,0,0,0
0,0,0,0,0,0,0,0,0,0,0,0,0,0,0,0,0,0,0,0,0,0,0,0,0,0,0,0,0,0,0,0,0,0,0,0,0
0,0,0,0,0,0,0,0,0,0,0,0,0,0,0,0,0,0,0,0,0,0,0,0,0,0,0,0,0,0,0,0,0,0,0,0,0
0,0,0,0,0,0,0,0,0,0,0,0,0,0,0,0,0,0,0,0,0,0,0,0,0,0,0,0,0,0,0,0,0,0,0,0,0
endlayer

layer
0,0,0,0,0,0,0,0,0,0,0,0,0,0,0,0,0,0,0,0,0,0,0,0,0,0,0,0,0,0,0,0,0,0,0,0,0
0,0,0,0,0,0,0,0,0,0,0,0,0,0,0,0,0,0,0,0,0,0,0,0,0,0,0,0,0,0,0,0,0,0,0,0,0
0,0,0,0,0,0,0,0,0,0,0,0,0,0,0,0,0,0,0,0,0,0,0,0,0,0,0,0,0,0,0,0,0,0,0,0,0
0,0,0,0,0,0,0,0,0,0,0,0,0,0,0,0,0,0,0,0,0,0,0,0,0,0,0,0,0,0,0,0,0,0,0,0,0
0,0,0,0,5,6,6,6,6,6,6,6,6,6,6,6,6,6,6,6,6,6,6,6,6,6,6,6,6,0,0,0,0,0,0,0,0
0,0,0,0,5,3,3,3,3,3,3,3,3,3,3,3,3,3,3,3,3,3,3,3,3,3,3,3,10,0,0,0,0,0,0,0,0
0,0,0,0,5,3,3,3,3,3,3,3,3,3,3,3,3,3,3,3,3,3,3,3,3,3,3,3,10,0,0,0,0,0,0,0,0
0,0,0,0,5,3,3,3,3,3,3,3,3,3,3,3,3,3,3,3,3,3,3,3,3,3,3,3,10,0,0,0,0,0,0,0,0
0,0,0,0,5,3,3,3,3,3,3,3,3,3,3,3,3,3,3,3,3,3,3,3,3,3,3,3,10,0,0,0,0,0,0,0,0
0,0,0,0,5,3,3,3,3,3,3,4,3,3,3,3,4,3,3,4,3,3,4,4,3,3,3,3,10,0,0,0,0,0,0,0,0
0,0,0,0,5,3,3,3,3,4,3,4,3,3,3,3,3,3,3,3,4,4,4,3,3,3,3,3,10,0,0,0,0,0,0,0,0
0,0,0,0,5,3,3,3,3,4,3,3,3,3,3,3,3,3,10,3,3,3,4,3,3,3,3,3,10,0,0,0,0,0,0,0,0
0,0,0,0,5,3,3,3,3,4,4,3,3,4,3,3,3,4,3,3,3,3,3,3,3,3,3,3,10,0,0,0,0,0,0,0,0
0,0,0,0,5,3,3,3,3,3,3,3,4,3,3,3,4,7,3,3,3,3,0,3,3,3,3,3,10,0,0,0,0,0,0,0,0
0,0,0,0,5,3,3,3,3,3,6,4,4,3,16,3,4,4,3,3,3,3,0,3,3,3,3,3,10,0,0,0,0,0,0,0,0
0,0,0,0,5,3,3,3,3,3,3,3,3,3,3,3,3,3,3,3,3,3,0,3,3,3,3,3,10,0,0,0,0,0,0,0,0
0,0,0,0,5,3,3,3,3,3,3,3,3,3,3,3,3,3,3,3,3,10,0,3,3,3,3,3,10,0,0,0,0,0,0,0,0
0,0,0,0,5,3,3,3,3,3,3,3,3,3,3,3,3,3,3,3,3,3,3,3,3,3,3,3,10,0,0,0,0,0,0,0,0
0,0,0,0,5,3,3,3,3,3,3,3,3,3,3,3,3,3,3,3,3,3,3,3,3,3,3,3,10,0,0,0,0,0,0,0,0
0,0,0,0,5,3,3,3,3,3,3,3,3,3,3,3,3,3,3,3,3,3,3,3,3,3,3,3,10,0,0,0,0,0,0,0,0
0,0,0,0,5,3,3,3,3,3,3,3,3,3,3,3,3,3,3,3,3,3,3,3,3,3,3,3,10,0,0,0,0,0,0,0,0
0,0,0,0,5,3,3,3,3,3,3,3,3,3,3,3,3,3,3,3,3,3,3,3,3,3,3,3,10,0,0,0,0,0,0,0,0
0,0,0,0,5,3,3,3,3,3,3,3,3,3,3,3,3,3,3,3,3,3,3,3,3,3,3,3,10,0,0,0,0,0,0,0,0
0,0,0,0,5,3,3,3,3,3,3,3,3,3,3,3,3,3,3,3,3,3,3,3,3,3,3,3,10,0,0,0,0,0,0,0,0
0,0,0,0,5,3,3,3,3,3,3,3,3,3,3,3,3,3,3,3,3,3,3,3,3,3,3,3,10,0,0,0,0,0,0,0,0
0,0,0,0,5,3,3,3,3,3,3,3,3,3,3,3,3,3,3,3,3,3,3,3,3,3,3,3,10,0,0,0,0,0,0,0,0
0,0,0,0,5,3,3,3,3,3,3,3,3,3,3,3,3,3,3,3,3,3,3,3,3,3,3,3,10,0,0,0,0,0,0,0,0
0,0,0,0,5,3,3,3,3,3,3,3,3,3,3,3,3,3,3,3,3,3,3,3,3,3,3,3,10,0,0,0,0,0,0,0,0
0,0,0,0,7,7,7,7,7,7,7,7,7,7,7,7,7,7,7,7,7,7,7,7,7,7,7,7,7,0,0,0,0,0,0,0,0
0,0,0,0,0,0,0,0,0,0,0,0,0,0,0,0,0,0,0,0,0,0,0,0,0,0,0,0,0,0,0,0,0,0,0,0,0
0,0,0,0,0,0,0,0,0,0,0,0,0,0,0,0,0,0,0,0,0,0,0,0,0,0,0,0,0,0,0,0,0,0,0,0,0
0,0,0,0,0,0,0,0,0,0,0,0,0,0,0,0,0,0,0,0,0,0,0,0,0,0,0,0,0,0,0,0,0,0,0,0,0
0,0,0,0,0,0,0,0,0,0,0,0,0,0,0,0,0,0,0,0,0,0,0,0,0,0,0,0,0,0,0,0,0,0,0,0,0
endlayer

layer
0,0,0,0,0,0,0,0,0,0,0,0,0,0,0,0,0,0,0,0,0,0,0,0,0,0,0,0,0,0,0,0,0,0,0,0,0
0,0,0,0,0,0,0,0,0,0,0,0,0,0,0,0,0,0,0,0,0,0,0,0,0,0,0,0,0,0,0,0,0,0,0,0,0
0,0,0,0,0,0,0,0,0,0,0,0,0,0,0,0,0,0,0,0,0,0,0,0,0,0,0,0,0,0,0,0,0,0,0,0,0
0,0,0,0,0,0,0,0,0,0,0,0,0,0,0,0,0,0,0,0,0,0,0,0,0,0,0,0,0,0,0,0,0,0,0,0,0
0,0,0,0,0,0,0,0,0,0,0,0,0,0,0,0,0,0,0,0,0,0,0,0,0,0,0,0,0,0,0,0,0,0,0,0,0
0,0,0,0,0,6,6,6,6,6,6,6,6,6,6,6,6,6,6,6,6,6,6,6,6,6,6,6,0,0,0,0,0,0,0,0,0
0,0,0,0,0,5,3,3,3,3,3,3,3,3,3,3,3,3,3,3,3,3,3,3,3,3,3,10,0,0,0,0,0,0,0,0,0
0,0,0,0,0,5,3,3,3,3,3,3,3,3,3,3,3,3,3,3,3,3,3,3,3,3,3,10,0,0,0,0,0,0,0,0,0
0,0,0,0,0,5,3,3,3,3,3,3,3,3,3,3,3,3,3,3,3,3,3,3,3,3,3,10,0,0,0,0,0,0,0,0,0
0,0,0,0,0,5,3,3,3,3,9,6,3,3,3,3,4,10,4,3,3,3,4,3,3,3,3,10,0,0,0,0,0,0,0,0,0
0,0,0,0,0,5,3,3,3,8,0,3,3,3,3,3,0,0,3,0,0,0,0,3,3,3,3,10,0,0,0,0,0,0,0,0,0
0,0,0,0,0,5,3,3,3,3,11,3,3,3,3,3,10,4,4,4,3,4,3,4,3,3,3,10,0,0,0,0,0,0,0,0,0
0,0,0,0,0,5,3,3,3,3,4,4,3,3,4,3,0,3,3,3,3,3,3,3,3,3,3,10,0,0,0,0,0,0,0,0,0
0,0,0,0,0,5,3,3,3,4,0,0,3,0,3,3,0,3,0,0,0,3,0,3,3,3,3,10,0,0,0,0,0,0,0,0,0
0,0,0,0,0,5,3,3,3,3,9,3,3,0,3,3,3,4,3,0,0,3,0,3,3,3,3,10,0,0,0,0,0,0,0,0,0
0,0,0,0,0,5,3,3,3,3,0,3,3,0,3,3,3,3,3,0,0,3,0,3,3,3,3,10,0,0,0,0,0,0,0,0,0
0,0,0,0,0,5,3,3,3,3,0,0,0,0,3,3,3,3,3,0,0,0,0,3,3,3,3,10,0,0,0,0,0,0,0,0,0
0,0,0,0,0,5,3,3,3,3,0,0,0,0,3,3,3,3,3,3,3,3,3,3,3,3,3,10,0,0,0,0,0,0,0,0,0
0,0,0,0,0,5,3,3,3,3,0,16,16,0,3,3,3,3,3,3,3,3,3,3,3,3,3,10,0,0,0,0,0,0,0,0,0
0,0,0,0,0,5,3,3,3,3,16,9,21,16,3,3,3,3,3,3,3,3,3,3,3,3,3,10,0,0,0,0,0,0,0,0,0
0,0,0,0,0,5,3,3,3,3,3,3,3,3,3,3,3,3,3,3,3,3,3,3,3,3,3,10,0,0,0,0,0,0,0,0,0
0,0,0,0,0,5,3,3,3,3,3,3,3,3,3,3,3,3,3,3,3,3,3,3,3,3,3,10,0,0,0,0,0,0,0,0,0
0,0,0,0,0,5,3,3,3,3,3,3,3,3,3,3,3,3,3,3,3,3,3,3,3,3,3,10,0,0,0,0,0,0,0,0,0
0,0,0,0,0,5,3,3,3,3,3,3,3,3,3,3,3,3,3,3,3,3,3,3,3,3,3,10,0,0,0,0,0,0,0,0,0
0,0,0,0,0,5,3,3,3,3,3,3,3,3,3,3,3,3,3,3,3,3,3,3,3,3,3,10,0,0,0,0,0,0,0,0,0
0,0,0,0,0,5,3,3,3,3,3,3,3,3,3,3,3,3,3,3,3,3,3,3,3,3,3,10,0,0,0,0,0,0,0,0,0
0,0,0,0,0,5,3,3,3,3,3,3,3,3,3,3,3,3,3,3,3,3,3,3,3,3,3,10,0,0,0,0,0,0,0,0,0
0,0,0,0,0,5,7,7,7,7,7,7,7,7,7,7,7,7,7,7,7,7,7,7,7,7,7,7,0,0,0,0,0,0,0,0,0
0,0,0,0,0,0,0,0,0,0,0,0,0,0,0,0,0,0,0,0,0,0,0,0,0,0,0,0,0,0,0,0,0,0,0,0,0
0,0,0,0,0,0,0,0,0,0,0,0,0,0,0,0,0,0,0,0,0,0,0,0,0,0,0,0,0,0,0,0,0,0,0,0,0
0,0,0,0,0,0,0,0,0,0,0,0,0,0,0,0,0,0,0,0,0,0,0,0,0,0,0,0,0,0,0,0,0,0,0,0,0
0,0,0,0,0,0,0,0,0,0,0,0,0,0,0,0,0,0,0,0,0,0,0,0,0,0,0,0,0,0,0,0,0,0,0,0,0
0,0,0,0,0,0,0,0,0,0,0,0,0,0,0,0,0,0,0,0,0,0,0,0,0,0,0,0,0,0,0,0,0,0,0,0,0
endlayer

layer
0,0,0,0,0,0,0,0,0,0,0,0,0,0,0,0,0,0,0,0,0,0,0,0,0,0,0,0,0,0,0,0,0,0,0,0,0
0,0,0,0,0,0,0,0,0,0,0,0,0,0,0,0,0,0,0,0,0,0,0,0,0,0,0,0,0,0,0,0,0,0,0,0,0
0,0,0,0,0,0,0,0,0,0,0,0,0,0,0,0,0,0,0,0,0,0,0,0,0,0,0,0,0,0,0,0,0,0,0,0,0
0,0,0,0,0,0,0,0,0,0,0,0,0,0,0,0,0,0,0,0,0,0,0,0,0,0,0,0,0,0,0,0,0,0,0,0,0
0,0,0,0,0,0,0,0,0,0,0,0,0,0,0,0,0,0,0,0,0,0,0,0,0,0,0,0,0,0,0,0,0,0,0,0,0
0,0,0,0,0,0,0,0,0,0,0,0,0,0,0,0,0,0,0,0,0,0,0,0,0,0,0,0,0,0,0,0,0,0,0,0,0
0,0,0,0,0,0,6,6,6,6,6,6,6,6,6,6,6,6,6,6,6,6,6,6,6,6,6,0,0,0,0,0,0,0,0,0,0
0,0,0,0,0,0,5,3,3,3,3,3,3,3,3,3,3,3,3,3,3,3,3,3,3,3,10,0,0,0,0,0,0,0,0,0,0
0,0,0,0,0,0,5,3,3,3,3,3,3,3,3,3,3,3,3,3,3,3,3,3,3,3,10,0,0,0,0,0,0,0,0,0,0
0,0,0,0,0,0,5,3,3,3,4,4,3,3,3,8,4,3,3,4,4,3,4,4,3,3,10,0,0,0,0,0,0,0,0,0,0
0,0,0,0,0,0,5,3,3,3,0,3,3,3,3,3,0,0,0,0,0,0,0,4,3,3,10,0,0,0,0,0,0,0,0,0,0
0,0,0,0,0,0,5,3,3,3,0,4,3,3,3,3,0,4,4,3,3,4,4,3,3,3,10,0,0,0,0,0,0,0,0,0,0
0,0,0,0,0,0,5,3,3,3,0,3,4,4,3,3,0,3,3,3,3,3,3,3,3,3,10,0,0,0,0,0,0,0,0,0,0
0,0,0,0,0,0,5,3,3,4,0,0,0,0,0,0,0,0,0,0,0,3,0,3,3,3,10,0,0,0,0,0,0,0,0,0,0
0,0,0,0,0,0,5,3,3,3,0,3,3,11,3,4,3,4,3,0,0,3,0,3,3,3,10,0,0,0,0,0,0,0,0,0,0
0,0,0,0,0,0,5,3,3,3,0,3,3,0,3,3,3,3,3,0,0,3,0,3,3,3,10,0,0,0,0,0,0,0,0,0,0
0,0,0,0,0,0,5,3,3,3,0,0,0,0,3,3,3,3,3,0,0,0,0,3,3,3,10,0,0,0,0,0,0,0,0,0,0
0,0,0,0,0,0,5,3,3,3,0,0,0,0,3,3,3,3,3,3,3,3,3,3,3,3,10,0,0,0,0,0,0,0,0,0,0
0,0,0,0,0,0,5,3,3,3,0,0,0,0,3,3,3,3,3,3,3,3,3,3,3,3,10,0,0,0,0,0,0,0,0,0,0
0,0,0,0,0,0,5,3,3,3,0,12,12,0,3,3,3,3,3,3,3,3,3,3,3,3,10,0,0,0,0,0,0,0,0,0,0
0,0,0,0,0,0,5,3,3,3,3,3,3,3,3,3,3,3,3,3,3,3,3,3,3,3,10,0,0,0,0,0,0,0,0,0,0
0,0,0,0,0,0,5,3,3,3,3,3,3,3,3,3,3,3,3,3,3,3,3,3,3,3,10,0,0,0,0,0,0,0,0,0,0
0,0,0,0,0,0,5,3,3,3,3,3,3,3,3,3,3,3,3,3,3,3,3,3,3,3,10,0,0,0,0,0,0,0,0,0,0
0,0,0,0,0,0,5,3,3,3,3,3,3,3,3,3,3,3,3,3,3,3,3,3,3,3,10,0,0,0,0,0,0,0,0,0,0
0,0,0,0,0,0,5,3,3,3,3,3,3,3,3,3,3,3,3,3,3,3,3,3,3,3,10,0,0,0,0,0,0,0,0,0,0
0,0,0,0,0,0,5,3,3,3,3,3,3,3,3,3,3,3,3,3,3,3,3,3,3,3,10,0,0,0,0,0,0,0,0,0,0
0,0,0,0,0,0,5,7,7,7,7,7,7,7,7,7,7,7,7,7,7,7,7,7,7,7,7,0,0,0,0,0,0,0,0,0,0
0,0,0,0,0,0,0,0,0,0,0,0,0,0,0,0,0,0,0,0,0,0,0,0,0,0,0,0,0,0,0,0,0,0,0,0,0
0,0,0,0,0,0,0,0,0,0,0,0,0,0,0,0,0,0,0,0,0,0,0,0,0,0,0,0,0,0,0,0,0,0,0,0,0
0,0,0,0,0,0,0,0,0,0,0,0,0,0,0,0,0,0,0,0,0,0,0,0,0,0,0,0,0,0,0,0,0,0,0,0,0
0,0,0,0,0,0,0,0,0,0,0,0,0,0,0,0,0,0,0,0,0,0,0,0,0,0,0,0,0,0,0,0,0,0,0,0,0
0,0,0,0,0,0,0,0,0,0,0,0,0,0,0,0,0,0,0,0,0,0,0,0,0,0,0,0,0,0,0,0,0,0,0,0,0
0,0,0,0,0,0,0,0,0,0,0,0,0,0,0,0,0,0,0,0,0,0,0,0,0,0,0,0,0,0,0,0,0,0,0,0,0
endlayer

layer
0,0,0,0,0,0,0,0,0,0,0,0,0,0,0,0,0,0,0,0,0,0,0,0,0,0,0,0,0,0,0,0,0,0,0,0,0
0,0,0,0,0,0,0,0,0,0,0,0,0,0,0,0,0,0,0,0,0,0,0,0,0,0,0,0,0,0,0,0,0,0,0,0,0
0,0,0,0,0,0,0,0,0,0,0,0,0,0,0,0,0,0,0,0,0,0,0,0,0,0,0,0,0,0,0,0,0,0,0,0,0
0,0,0,0,0,0,0,0,0,0,0,0,0,0,0,0,0,0,0,0,0,0,0,0,0,0,0,0,0,0,0,0,0,0,0,0,0
0,0,0,0,0,0,0,0,0,0,0,0,0,0,0,0,0,0,0,0,0,0,0,0,0,0,0,0,0,0,0,0,0,0,0,0,0
0,0,0,0,0,0,0,0,0,0,0,0,0,0,0,0,0,0,0,0,0,0,0,0,0,0,0,0,0,0,0,0,0,0,0,0,0
0,0,0,0,0,0,0,0,0,0,0,0,0,0,0,0,0,0,0,0,0,0,0,0,0,0,0,0,0,0,0,0,0,0,0,0,0
0,0,0,0,0,0,0,6,6,6,6,6,6,6,6,6,6,6,6,6,6,6,6,6,6,10,0,0,0,0,0,0,0,0,0,0,0
0,0,0,0,0,0,0,5,3,3,3,3,3,3,3,3,3,3,3,3,3,3,3,3,3,10,0,0,0,0,0,0,0,0,0,0,0
0,0,0,0,0,0,0,5,3,4,4,3,3,3,3,3,3,4,7,3,4,3,4,3,3,10,0,0,0,0,0,0,0,0,0,0,0
0,0,0,0,0,0,0,5,3,3,3,4,3,3,3,3,3,3,3,3,3,3,4,4,3,10,0,0,0,0,0,0,0,0,0,0,0
0,0,0,0,0,0,0,5,3,4,3,3,3,3,3,3,4,3,3,3,3,3,3,3,3,10,0,0,0,0,0,0,0,0,0,0,0
0,0,0,0,0,0,0,5,3,3,3,3,3,3,3,3,3,3,3,3,3,3,3,3,3,10,0,0,0,0,0,0,0,0,0,0,0
0,0,0,0,0,0,0,5,3,3,3,4,3,3,3,4,6,4,3,3,3,3,3,3,3,10,0,0,0,0,0,0,0,0,0,0,0
0,0,0,0,0,0,0,5,3,3,3,3,4,3,3,5,3,4,3,3,3,3,3,3,3,10,0,0,0,0,0,0,0,0,0,0,0
0,0,0,0,0,0,0,5,3,3,3,3,3,3,3,3,3,3,3,3,3,3,3,3,3,10,0,0,0,0,0,0,0,0,0,0,0
0,0,0,0,0,0,0,5,3,3,3,0,0,3,3,3,3,3,3,3,3,3,3,3,3,10,0,0,0,0,0,0,0,0,0,0,0
0,0,0,0,0,0,0,5,3,3,0,0,0,0,3,3,3,3,3,3,3,3,3,3,3,10,0,0,0,0,0,0,0,0,0,0,0
0,0,0,0,0,0,0,5,3,3,0,0,0,0,3,3,3,3,3,3,3,3,3,3,3,10,0,0,0,0,0,0,0,0,0,0,0
0,0,0,0,0,0,0,5,3,3,0,0,0,0,3,3,3,3,3,3,3,3,3,3,3,10,0,0,0,0,0,0,0,0,0,0,0
0,0,0,0,0,0,0,5,3,3,3,3,3,3,3,3,3,3,3,3,3,3,3,3,3,10,0,0,0,0,0,0,0,0,0,0,0
0,0,0,0,0,0,0,5,3,3,3,3,3,3,3,3,3,3,3,3,3,3,3,3,3,10,0,0,0,0,0,0,0,0,0,0,0
0,0,0,0,0,0,0,5,3,3,3,3,3,3,3,3,3,3,3,3,3,3,3,3,3,10,0,0,0,0,0,0,0,0,0,0,0
0,0,0,0,0,0,0,5,3,3,3,3,3,3,3,3,3,3,3,3,3,3,3,3,3,10,0,0,0,0,0,0,0,0,0,0,0
0,0,0,0,0,0,0,5,3,3,3,3,3,3,3,3,3,3,3,3,3,3,3,3,3,10,0,0,0,0,0,0,0,0,0,0,0
0,0,0,0,0,0,0,7,7,7,7,7,7,7,7,7,7,7,7,7,7,7,7,7,7,7,0,0,0,0,0,0,0,0,0,0,0
0,0,0,0,0,0,0,0,0,0,0,0,0,0,0,0,0,0,0,0,0,0,0,0,0,0,0,0,0,0,0,0,0,0,0,0,0
0,0,0,0,0,0,0,0,0,0,0,0,0,0,0,0,0,0,0,0,0,0,0,0,0,0,0,0,0,0,0,0,0,0,0,0,0
0,0,0,0,0,0,0,0,0,0,0,0,0,0,0,0,0,0,0,0,0,0,0,0,0,0,0,0,0,0,0,0,0,0,0,0,0
0,0,0,0,0,0,0,0,0,0,0,0,0,0,0,0,0,0,0,0,0,0,0,0,0,0,0,0,0,0,0,0,0,0,0,0,0
0,0,0,0,0,0,0,0,0,0,0,0,0,0,0,0,0,0,0,0,0,0,0,0,0,0,0,0,0,0,0,0,0,0,0,0,0
0,0,0,0,0,0,0,0,0,0,0,0,0,0,0,0,0,0,0,0,0,0,0,0,0,0,0,0,0,0,0,0,0,0,0,0,0
0,0,0,0,0,0,0,0,0,0,0,0,0,0,0,0,0,0,0,0,0,0,0,0,0,0,0,0,0,0,0,0,0,0,0,0,0
endlayer

layer
0,0,0,0,0,0,0,0,0,0,0,0,0,0,0,0,0,0,0,0,0,0,0,0,0,0,0,0,0,0,0,0,0,0,0,0,0
0,0,0,0,0,0,0,0,0,0,0,0,0,0,0,0,0,0,0,0,0,0,0,0,0,0,0,0,0,0,0,0,0,0,0,0,0
0,0,0,0,0,0,0,0,0,0,0,0,0,0,0,0,0,0,0,0,0,0,0,0,0,0,0,0,0,0,0,0,0,0,0,0,0
0,0,0,0,0,0,0,0,0,0,0,0,0,0,0,0,0,0,0,0,0,0,0,0,0,0,0,0,0,0,0,0,0,0,0,0,0
0,0,0,0,0,0,0,0,0,0,0,0,0,0,0,0,0,0,0,0,0,0,0,0,0,0,0,0,0,0,0,0,0,0,0,0,0
0,0,0,0,0,0,0,0,0,0,0,0,0,0,0,0,0,0,0,0,0,0,0,0,0,0,0,0,0,0,0,0,0,0,0,0,0
0,0,0,0,0,0,0,0,0,0,0,0,0,0,0,0,0,0,0,0,0,0,0,0,0,0,0,0,0,0,0,0,0,0,0,0,0
0,0,0,0,0,0,0,0,0,0,0,0,0,0,0,0,0,0,0,0,0,0,0,0,0,0,0,0,0,0,0,0,0,0,0,0,0
0,0,0,0,0,0,0,0,6,6,6,6,6,6,6,6,6,6,6,6,6,6,6,6,10,0,0,0,0,0,0,0,0,0,0,0,0
0,0,0,0,0,0,0,0,5,3,3,3,3,3,3,3,3,3,3,3,3,3,3,3,10,0,0,0,0,0,0,0,0,0,0,0,0
0,0,0,0,0,0,0,0,5,3,3,3,3,3,3,3,3,3,3,3,3,3,3,3,10,0,0,0,0,0,0,0,0,0,0,0,0
0,0,0,0,0,0,0,0,5,3,3,3,3,3,3,3,3,3,3,3,3,3,3,3,10,0,0,0,0,0,0,0,0,0,0,0,0
0,0,0,0,0,0,0,0,5,3,3,3,3,3,3,3,3,3,3,3,3,3,3,3,10,0,0,0,0,0,0,0,0,0,0,0,0
0,0,0,0,0,0,0,0,5,3,3,3,3,3,3,3,3,3,3,3,3,3,3,3,10,0,0,0,0,0,0,0,0,0,0,0,0
0,0,0,0,0,0,0,0,5,3,3,3,3,3,3,3,3,3,3,3,3,3,3,3,10,0,0,0,0,0,0,0,0,0,0,0,0
0,0,0,0,0,0,0,0,5,3,3,3,3,3,3,3,3,3,3,3,3,3,3,3,10,0,0,0,0,0,0,0,0,0,0,0,0
0,0,0,0,0,0,0,0,5,3,3,3,3,3,3,3,3,3,3,3,3,3,3,3,10,0,0,0,0,0,0,0,0,0,0,0,0
0,0,0,0,0,0,0,0,5,3,3,3,3,3,3,3,3,3,3,3,3,3,3,3,10,0,0,0,0,0,0,0,0,0,0,0,0
0,0,0,0,0,0,0,0,5,3,3,3,3,3,3,3,3,3,3,3,3,3,3,3,10,0,0,0,0,0,0,0,0,0,0,0,0
0,0,0,0,0,0,0,0,5,3,3,3,3,3,3,3,3,3,3,3,3,3,3,3,10,0,0,0,0,0,0,0,0,0,0,0,0
0,0,0,0,0,0,0,0,5,3,3,3,3,3,3,3,3,3,3,3,3,3,3,3,10,0,0,0,0,0,0,0,0,0,0,0,0
0,0,0,0,0,0,0,0,5,3,3,3,3,3,3,3,3,3,3,3,3,3,3,3,10,0,0,0,0,0,0,0,0,0,0,0,0
0,0,0,0,0,0,0,0,5,3,3,3,3,3,3,3,3,3,3,3,3,3,3,3,10,0,0,0,0,0,0,0,0,0,0,0,0
0,0,0,0,0,0,0,0,5,3,3,3,3,3,3,3,3,3,3,3,3,3,3,3,10,0,0,0,0,0,0,0,0,0,0,0,0
0,0,0,0,0,0,0,0,7,7,7,7,7,7,7,7,7,7,7,7,7,7,7,7,7,0,0,0,0,0,0,0,0,0,0,0,0
0,0,0,0,0,0,0,0,0,0,0,0,0,0,0,0,0,0,0,0,0,0,0,0,0,0,0,0,0,0,0,0,0,0,0,0,0
0,0,0,0,0,0,0,0,0,0,0,0,0,0,0,0,0,0,0,0,0,0,0,0,0,0,0,0,0,0,0,0,0,0,0,0,0
0,0,0,0,0,0,0,0,0,0,0,0,0,0,0,0,0,0,0,0,0,0,0,0,0,0,0,0,0,0,0,0,0,0,0,0,0
0,0,0,0,0,0,0,0,0,0,0,0,0,0,0,0,0,0,0,0,0,0,0,0,0,0,0,0,0,0,0,0,0,0,0,0,0
0,0,0,0,0,0,0,0,0,0,0,0,0,0,0,0,0,0,0,0,0,0,0,0,0,0,0,0,0,0,0,0,0,0,0,0,0
0,0,0,0,0,0,0,0,0,0,0,0,0,0,0,0,0,0,0,0,0,0,0,0,0,0,0,0,0,0,0,0,0,0,0,0,0
0,0,0,0,0,0,0,0,0,0,0,0,0,0,0,0,0,0,0,0,0,0,0,0,0,0,0,0,0,0,0,0,0,0,0,0,0
0,0,0,0,0,0,0,0,0,0,0,0,0,0,0,0,0,0,0,0,0,0,0,0,0,0,0,0,0,0,0,0,0,0,0,0,0
endlayer

layer
0,0,0,0,0,0,0,0,0,0,0,0,0,0,0,0,0,0,0,0,0,0,0,0,0,0,0,0,0,0,0,0,0,0,0,0,0
0,0,0,0,0,0,0,0,0,0,0,0,0,0,0,0,0,0,0,0,0,0,0,0,0,0,0,0,0,0,0,0,0,0,0,0,0
0,0,0,0,0,0,0,0,0,0,0,0,0,0,0,0,0,0,0,0,0,0,0,0,0,0,0,0,0,0,0,0,0,0,0,0,0
0,0,0,0,0,0,0,0,0,0,0,0,0,0,0,0,0,0,0,0,0,0,0,0,0,0,0,0,0,0,0,0,0,0,0,0,0
0,0,0,0,0,0,0,0,0,0,0,0,0,0,0,0,0,0,0,0,0,0,0,0,0,0,0,0,0,0,0,0,0,0,0,0,0
0,0,0,0,0,0,0,0,0,0,0,0,0,0,0,0,0,0,0,0,0,0,0,0,0,0,0,0,0,0,0,0,0,0,0,0,0
0,0,0,0,0,0,0,0,0,0,0,0,0,0,0,0,0,0,0,0,0,0,0,0,0,0,0,0,0,0,0,0,0,0,0,0,0
0,0,0,0,0,0,0,0,0,0,0,0,0,0,0,0,0,0,0,0,0,0,0,0,0,0,0,0,0,0,0,0,0,0,0,0,0
0,0,0,0,0,0,0,0,0,0,0,0,0,0,0,0,0,0,0,0,0,0,0,0,0,0,0,0,0,0,0,0,0,0,0,0,0
0,0,0,0,0,0,0,0,0,6,6,6,6,6,6,6,6,6,6,6,6,6,6,6,0,0,0,0,0,0,0,0,0,0,0,0,0
0,0,0,0,0,0,0,0,0,5,3,3,3,3,3,3,3,3,3,3,3,3,3,10,0,0,0,0,0,0,0,0,0,0,0,0,0
0,0,0,0,0,0,0,0,0,5,3,3,3,3,3,3,3,3,3,3,3,3,3,10,0,0,0,0,0,0,0,0,0,0,0,0,0
0,0,0,0,0,0,0,0,0,5,3,3,3,3,3,3,3,3,3,3,3,3,3,10,0,0,0,0,0,0,0,0,0,0,0,0,0
0,0,0,0,0,0,0,0,0,5,3,3,3,3,3,3,3,3,3,3,3,3,3,10,0,0,0,0,0,0,0,0,0,0,0,0,0
0,0,0,0,0,0,0,0,0,5,3,3,3,3,3,3,3,3,3,3,3,3,3,10,0,0,0,0,0,0,0,0,0,0,0,0,0
0,0,0,0,0,0,0,0,0,5,3,3,3,3,3,3,3,3,3,3,3,3,3,10,0,0,0,0,0,0,0,0,0,0,0,0,0
0,0,0,0,0,0,0,0,0,5,3,3,3,3,3,3,3,3,3,3,3,3,3,10,0,0,0,0,0,0,0,0,0,0,0,0,0
0,0,0,0,0,0,0,0,0,5,3,3,3,3,3,3,3,3,3,3,3,3,3,10,0,0,0,0,0,0,0,0,0,0,0,0,0
0,0,0,0,0,0,0,0,0,5,3,3,3,3,3,3,3,3,3,3,3,3,3,10,0,0,0,0,0,0,0,0,0,0,0,0,0
0,0,0,0,0,0,0,0,0,5,3,3,3,3,3,3,3,3,3,3,3,3,3,10,0,0,0,0,0,0,0,0,0,0,0,0,0
0,0,0,0,0,0,0,0,0,5,3,3,3,3,3,3,3,3,3,3,3,3,3,10,0,0,0,0,0,0,0,0,0,0,0,0,0
0,0,0,0,0,0,0,0,0,5,3,3,3,3,3,3,3,3,3,3,3,3,3,10,0,0,0,0,0,0,0,0,0,0,0,0,0
0,0,0,0,0,0,0,0,0,5,3,3,3,3,3,3,3,3,3,3,3,3,3,10,0,0,0,0,0,0,0,0,0,0,0,0,0
0,0,0,0,0,0,0,0,0,5,7,7,7,7,7,7,7,7,7,7,7,7,7,7,0,0,0,0,0,0,0,0,0,0,0,0,0
0,0,0,0,0,0,0,0,0,0,0,0,0,0,0,0,0,0,0,0,0,0,0,0,0,0,0,0,0,0,0,0,0,0,0,0,0
0,0,0,0,0,0,0,0,0,0,0,0,0,0,0,0,0,0,0,0,0,0,0,0,0,0,0,0,0,0,0,0,0,0,0,0,0
0,0,0,0,0,0,0,0,0,0,0,0,0,0,0,0,0,0,0,0,0,0,0,0,0,0,0,0,0,0,0,0,0,0,0,0,0
0,0,0,0,0,0,0,0,0,0,0,0,0,0,0,0,0,0,0,0,0,0,0,0,0,0,0,0,0,0,0,0,0,0,0,0,0
0,0,0,0,0,0,0,0,0,0,0,0,0,0,0,0,0,0,0,0,0,0,0,0,0,0,0,0,0,0,0,0,0,0,0,0,0
0,0,0,0,0,0,0,0,0,0,0,0,0,0,0,0,0,0,0,0,0,0,0,0,0,0,0,0,0,0,0,0,0,0,0,0,0
0,0,0,0,0,0,0,0,0,0,0,0,0,0,0,0,0,0,0,0,0,0,0,0,0,0,0,0,0,0,0,0,0,0,0,0,0
0,0,0,0,0,0,0,0,0,0,0,0,0,0,0,0,0,0,0,0,0,0,0,0,0,0,0,0,0,0,0,0,0,0,0,0,0
0,0,0,0,0,0,0,0,0,0,0,0,0,0,0,0,0,0,0,0,0,0,0,0,0,0,0,0,0,0,0,0,0,0,0,0,0
endlayer

layer
0,0,0,0,0,0,0,0,0,0,0,0,0,0,0,0,0,0,0,0,0,0,0,0,0,0,0,0,0,0,0,0,0,0,0,0,0
0,0,0,0,0,0,0,0,0,0,0,0,0,0,0,0,0,0,0,0,0,0,0,0,0,0,0,0,0,0,0,0,0,0,0,0,0
0,0,0,0,0,0,0,0,0,0,0,0,0,0,0,0,0,0,0,0,0,0,0,0,0,0,0,0,0,0,0,0,0,0,0,0,0
0,0,0,0,0,0,0,0,0,0,0,0,0,0,0,0,0,0,0,0,0,0,0,0,0,0,0,0,0,0,0,0,0,0,0,0,0
0,0,0,0,0,0,0,0,0,0,0,0,0,0,0,0,0,0,0,0,0,0,0,0,0,0,0,0,0,0,0,0,0,0,0,0,0
0,0,0,0,0,0,0,0,0,0,0,0,0,0,0,0,0,0,0,0,0,0,0,0,0,0,0,0,0,0,0,0,0,0,0,0,0
0,0,0,0,0,0,0,0,0,0,0,0,0,0,0,0,0,0,0,0,0,0,0,0,0,0,0,0,0,0,0,0,0,0,0,0,0
0,0,0,0,0,0,0,0,0,0,0,0,0,0,0,0,0,0,0,0,0,0,0,0,0,0,0,0,0,0,0,0,0,0,0,0,0
0,0,0,0,0,0,0,0,0,0,0,0,0,0,0,0,0,0,0,0,0,0,0,0,0,0,0,0,0,0,0,0,0,0,0,0,0
0,0,0,0,0,0,0,0,0,0,0,0,0,0,0,0,0,0,0,0,0,0,0,0,0,0,0,0,0,0,0,0,0,0,0,0,0
0,0,0,0,0,0,0,0,0,0,6,6,6,6,6,6,6,6,6,6,6,6,6,0,0,0,0,0,0,0,0,0,0,0,0,0,0
0,0,0,0,0,0,0,0,0,0,5,3,3,3,3,3,3,3,3,3,3,3,10,0,0,0,0,0,0,0,0,0,0,0,0,0,0
0,0,0,0,0,0,0,0,0,0,5,3,3,3,3,3,3,3,3,3,3,3,10,0,0,0,0,0,0,0,0,0,0,0,0,0,0
0,0,0,0,0,0,0,0,0,0,5,3,3,3,3,3,3,3,3,3,3,3,10,0,0,0,0,0,0,0,0,0,0,0,0,0,0
0,0,0,0,0,0,0,0,0,0,5,3,3,3,3,3,3,3,3,3,3,3,10,0,0,0,0,0,0,0,0,0,0,0,0,0,0
0,0,0,0,0,0,0,0,0,0,5,3,3,3,3,3,3,3,3,3,3,3,10,0,0,0,0,0,0,0,0,0,0,0,0,0,0
0,0,0,0,0,0,0,0,0,0,5,3,3,3,3,3,3,3,3,3,3,3,10,0,0,0,0,0,0,0,0,0,0,0,0,0,0
0,0,0,0,0,0,0,0,0,0,5,3,3,3,3,3,3,3,3,3,3,3,10,0,0,0,0,0,0,0,0,0,0,0,0,0,0
0,0,0,0,0,0,0,0,0,0,5,3,3,3,3,3,3,3,3,3,3,3,10,0,0,0,0,0,0,0,0,0,0,0,0,0,0
0,0,0,0,0,0,0,0,0,0,5,3,3,3,3,3,3,3,3,3,3,3,10,0,0,0,0,0,0,0,0,0,0,0,0,0,0
0,0,0,0,0,0,0,0,0,0,5,3,3,3,3,3,3,3,3,3,3,3,10,0,0,0,0,0,0,0,0,0,0,0,0,0,0
0,0,0,0,0,0,0,0,0,0,5,3,3,3,3,3,3,3,3,3,3,3,10,0,0,0,0,0,0,0,0,0,0,0,0,0,0
0,0,0,0,0,0,0,0,0,0,5,7,7,7,7,7,7,7,7,7,7,7,7,0,0,0,0,0,0,0,0,0,0,0,0,0,0
0,0,0,0,0,0,0,0,0,0,0,0,0,0,0,0,0,0,0,0,0,0,0,0,0,0,0,0,0,0,0,0,0,0,0,0,0
0,0,0,0,0,0,0,0,0,0,0,0,0,0,0,0,0,0,0,0,0,0,0,0,0,0,0,0,0,0,0,0,0,0,0,0,0
0,0,0,0,0,0,0,0,0,0,0,0,0,0,0,0,0,0,0,0,0,0,0,0,0,0,0,0,0,0,0,0,0,0,0,0,0
0,0,0,0,0,0,0,0,0,0,0,0,0,0,0,0,0,0,0,0,0,0,0,0,0,0,0,0,0,0,0,0,0,0,0,0,0
0,0,0,0,0,0,0,0,0,0,0,0,0,0,0,0,0,0,0,0,0,0,0,0,0,0,0,0,0,0,0,0,0,0,0,0,0
0,0,0,0,0,0,0,0,0,0,0,0,0,0,0,0,0,0,0,0,0,0,0,0,0,0,0,0,0,0,0,0,0,0,0,0,0
0,0,0,0,0,0,0,0,0,0,0,0,0,0,0,0,0,0,0,0,0,0,0,0,0,0,0,0,0,0,0,0,0,0,0,0,0
0,0,0,0,0,0,0,0,0,0,0,0,0,0,0,0,0,0,0,0,0,0,0,0,0,0,0,0,0,0,0,0,0,0,0,0,0
0,0,0,0,0,0,0,0,0,0,0,0,0,0,0,0,0,0,0,0,0,0,0,0,0,0,0,0,0,0,0,0,0,0,0,0,0
0,0,0,0,0,0,0,0,0,0,0,0,0,0,0,0,0,0,0,0,0,0,0,0,0,0,0,0,0,0,0,0,0,0,0,0,0
endlayer

layer
0,0,0,0,0,0,0,0,0,0,0,0,0,0,0,0,0,0,0,0,0,0,0,0,0,0,0,0,0,0,0,0,0,0,0,0,0
0,0,0,0,0,0,0,0,0,0,0,0,0,0,0,0,0,0,0,0,0,0,0,0,0,0,0,0,0,0,0,0,0,0,0,0,0
0,0,0,0,0,0,0,0,0,0,0,0,0,0,0,0,0,0,0,0,0,0,0,0,0,0,0,0,0,0,0,0,0,0,0,0,0
0,0,0,0,0,0,0,0,0,0,0,0,0,0,0,0,0,0,0,0,0,0,0,0,0,0,0,0,0,0,0,0,0,0,0,0,0
0,0,0,0,0,0,0,0,0,0,0,0,0,0,0,0,0,0,0,0,0,0,0,0,0,0,0,0,0,0,0,0,0,0,0,0,0
0,0,0,0,0,0,0,0,0,0,0,0,0,0,0,0,0,0,0,0,0,0,0,0,0,0,0,0,0,0,0,0,0,0,0,0,0
0,0,0,0,0,0,0,0,0,0,0,0,0,0,0,0,0,0,0,0,0,0,0,0,0,0,0,0,0,0,0,0,0,0,0,0,0
0,0,0,0,0,0,0,0,0,0,0,0,0,0,0,0,0,0,0,0,0,0,0,0,0,0,0,0,0,0,0,0,0,0,0,0,0
0,0,0,0,0,0,0,0,0,0,0,0,0,0,0,0,0,0,0,0,0,0,0,0,0,0,0,0,0,0,0,0,0,0,0,0,0
0,0,0,0,0,0,0,0,0,0,0,0,0,0,0,0,0,0,0,0,0,0,0,0,0,0,0,0,0,0,0,0,0,0,0,0,0
0,0,0,0,0,0,0,0,0,0,0,0,0,0,0,0,0,0,0,0,0,0,0,0,0,0,0,0,0,0,0,0,0,0,0,0,0
0,0,0,0,0,0,0,0,0,0,0,5,6,6,6,6,6,6,6,6,6,10,0,0,0,0,0,0,0,0,0,0,0,0,0,0,0
0,0,0,0,0,0,0,0,0,0,0,5,3,3,3,3,3,3,3,3,3,10,0,0,0,0,0,0,0,0,0,0,0,0,0,0,0
0,0,0,0,0,0,0,0,0,0,0,5,3,3,3,3,3,3,3,3,3,10,0,0,0,0,0,0,0,0,0,0,0,0,0,0,0
0,0,0,0,0,0,0,0,0,0,0,5,3,3,3,3,3,3,3,3,3,10,0,0,0,0,0,0,0,0,0,0,0,0,0,0,0
0,0,0,0,0,0,0,0,0,0,0,5,3,3,3,3,3,3,3,3,3,10,0,0,0,0,0,0,0,0,0,0,0,0,0,0,0
0,0,0,0,0,0,0,0,0,0,0,5,3,3,3,3,3,3,3,3,3,10,0,0,0,0,0,0,0,0,0,0,0,0,0,0,0
0,0,0,0,0,0,0,0,0,0,0,5,3,3,3,3,3,3,3,3,3,10,0,0,0,0,0,0,0,0,0,0,0,0,0,0,0
0,0,0,0,0,0,0,0,0,0,0,5,3,3,3,3,3,3,3,3,3,10,0,0,0,0,0,0,0,0,0,0,0,0,0,0,0
0,0,0,0,0,0,0,0,0,0,0,5,3,3,3,3,3,3,3,3,3,10,0,0,0,0,0,0,0,0,0,0,0,0,0,0,0
0,0,0,0,0,0,0,0,0,0,0,5,3,3,3,3,3,3,3,3,3,10,0,0,0,0,0,0,0,0,0,0,0,0,0,0,0
0,0,0,0,0,0,0,0,0,0,0,7,7,7,7,7,7,7,7,7,7,7,0,0,0,0,0,0,0,0,0,0,0,0,0,0,0
0,0,0,0,0,0,0,0,0,0,0,0,0,0,0,0,0,0,0,0,0,0,0,0,0,0,0,0,0,0,0,0,0,0,0,0,0
0,0,0,0,0,0,0,0,0,0,0,0,0,0,0,0,0,0,0,0,0,0,0,0,0,0,0,0,0,0,0,0,0,0,0,0,0
0,0,0,0,0,0,0,0,0,0,0,0,0,0,0,0,0,0,0,0,0,0,0,0,0,0,0,0,0,0,0,0,0,0,0,0,0
0,0,0,0,0,0,0,0,0,0,0,0,0,0,0,0,0,0,0,0,0,0,0,0,0,0,0,0,0,0,0,0,0,0,0,0,0
0,0,0,0,0,0,0,0,0,0,0,0,0,0,0,0,0,0,0,0,0,0,0,0,0,0,0,0,0,0,0,0,0,0,0,0,0
0,0,0,0,0,0,0,0,0,0,0,0,0,0,0,0,0,0,0,0,0,0,0,0,0,0,0,0,0,0,0,0,0,0,0,0,0
0,0,0,0,0,0,0,0,0,0,0,0,0,0,0,0,0,0,0,0,0,0,0,0,0,0,0,0,0,0,0,0,0,0,0,0,0
0,0,0,0,0,0,0,0,0,0,0,0,0,0,0,0,0,0,0,0,0,0,0,0,0,0,0,0,0,0,0,0,0,0,0,0,0
0,0,0,0,0,0,0,0,0,0,0,0,0,0,0,0,0,0,0,0,0,0,0,0,0,0,0,0,0,0,0,0,0,0,0,0,0
0,0,0,0,0,0,0,0,0,0,0,0,0,0,0,0,0,0,0,0,0,0,0,0,0,0,0,0,0,0,0,0,0,0,0,0,0
0,0,0,0,0,0,0,0,0,0,0,0,0,0,0,0,0,0,0,0,0,0,0,0,0,0,0,0,0,0,0,0,0,0,0,0,0
endlayer

layer
0,0,0,0,0,0,0,0,0,0,0,0,0,0,0,0,0,0,0,0,0,0,0,0,0,0,0,0,0,0,0,0,0,0,0,0,0
0,0,0,0,0,0,0,0,0,0,0,0,0,0,0,0,0,0,0,0,0,0,0,0,0,0,0,0,0,0,0,0,0,0,0,0,0
0,0,0,0,0,0,0,0,0,0,0,0,0,0,0,0,0,0,0,0,0,0,0,0,0,0,0,0,0,0,0,0,0,0,0,0,0
0,0,0,0,0,0,0,0,0,0,0,0,0,0,0,0,0,0,0,0,0,0,0,0,0,0,0,0,0,0,0,0,0,0,0,0,0
0,0,0,0,0,0,0,0,0,0,0,0,0,0,0,0,0,0,0,0,0,0,0,0,0,0,0,0,0,0,0,0,0,0,0,0,0
0,0,0,0,0,0,0,0,0,0,0,0,0,0,0,0,0,0,0,0,0,0,0,0,0,0,0,0,0,0,0,0,0,0,0,0,0
0,0,0,0,0,0,0,0,0,0,0,0,0,0,0,0,0,0,0,0,0,0,0,0,0,0,0,0,0,0,0,0,0,0,0,0,0
0,0,0,0,0,0,0,0,0,0,0,0,0,0,0,0,0,0,0,0,0,0,0,0,0,0,0,0,0,0,0,0,0,0,0,0,0
0,0,0,0,0,0,0,0,0,0,0,0,0,0,0,0,0,0,0,0,0,0,0,0,0,0,0,0,0,0,0,0,0,0,0,0,0
0,0,0,0,0,0,0,0,0,0,0,0,0,0,0,0,0,0,0,0,0,0,0,0,0,0,0,0,0,0,0,0,0,0,0,0,0
0,0,0,0,0,0,0,0,0,0,0,0,0,0,0,0,0,0,0,0,0,0,0,0,0,0,0,0,0,0,0,0,0,0,0,0,0
0,0,0,0,0,0,0,0,0,0,0,0,0,0,0,0,0,0,0,0,0,0,0,0,0,0,0,0,0,0,0,0,0,0,0,0,0
0,0,0,0,0,0,0,0,0,0,0,0,6,6,6,6,6,6,6,6,6,0,0,0,0,0,0,0,0,0,0,0,0,0,0,0,0
0,0,0,0,0,0,0,0,0,0,0,0,5,3,3,3,3,3,3,3,10,0,0,0,0,0,0,0,0,0,0,0,0,0,0,0,0
0,0,0,0,0,0,0,0,0,0,0,0,5,3,3,3,3,3,3,3,10,0,0,0,0,0,0,0,0,0,0,0,0,0,0,0,0
0,0,0,0,0,0,0,0,0,0,0,0,5,3,3,3,3,3,3,3,10,0,0,0,0,0,0,0,0,0,0,0,0,0,0,0,0
0,0,0,0,0,0,0,0,0,0,0,0,5,3,3,3,3,3,3,3,10,0,0,0,0,0,0,0,0,0,0,0,0,0,0,0,0
0,0,0,0,0,0,0,0,0,0,0,0,5,3,3,3,3,3,3,3,10,0,0,0,0,0,0,0,0,0,0,0,0,0,0,0,0
0,0,0,0,0,0,0,0,0,0,0,0,5,3,3,3,3,3,3,3,10,0,0,0,0,0,0,0,0,0,0,0,0,0,0,0,0
0,0,0,0,0,0,0,0,0,0,0,0,5,3,3,3,3,3,3,3,10,0,0,0,0,0,0,0,0,0,0,0,0,0,0,0,0
0,0,0,0,0,0,0,0,0,0,0,0,5,7,7,7,7,7,7,7,10,0,0,0,0,0,0,0,0,0,0,0,0,0,0,0,0
0,0,0,0,0,0,0,0,0,0,0,0,0,0,0,0,0,0,0,0,0,0,0,0,0,0,0,0,0,0,0,0,0,0,0,0,0
0,0,0,0,0,0,0,0,0,0,0,0,0,0,0,0,0,0,0,0,0,0,0,0,0,0,0,0,0,0,0,0,0,0,0,0,0
0,0,0,0,0,0,0,0,0,0,0,0,0,0,0,0,0,0,0,0,0,0,0,0,0,0,0,0,0,0,0,0,0,0,0,0,0
0,0,0,0,0,0,0,0,0,0,0,0,0,0,0,0,0,0,0,0,0,0,0,0,0,0,0,0,0,0,0,0,0,0,0,0,0
0,0,0,0,0,0,0,0,0,0,0,0,0,0,0,0,0,0,0,0,0,0,0,0,0,0,0,0,0,0,0,0,0,0,0,0,0
0,0,0,0,0,0,0,0,0,0,0,0,0,0,0,0,0,0,0,0,0,0,0,0,0,0,0,0,0,0,0,0,0,0,0,0,0
0,0,0,0,0,0,0,0,0,0,0,0,0,0,0,0,0,0,0,0,0,0,0,0,0,0,0,0,0,0,0,0,0,0,0,0,0
0,0,0,0,0,0,0,0,0,0,0,0,0,0,0,0,0,0,0,0,0,0,0,0,0,0,0,0,0,0,0,0,0,0,0,0,0
0,0,0,0,0,0,0,0,0,0,0,0,0,0,0,0,0,0,0,0,0,0,0,0,0,0,0,0,0,0,0,0,0,0,0,0,0
0,0,0,0,0,0,0,0,0,0,0,0,0,0,0,0,0,0,0,0,0,0,0,0,0,0,0,0,0,0,0,0,0,0,0,0,0
0,0,0,0,0,0,0,0,0,0,0,0,0,0,0,0,0,0,0,0,0,0,0,0,0,0,0,0,0,0,0,0,0,0,0,0,0
0,0,0,0,0,0,0,0,0,0,0,0,0,0,0,0,0,0,0,0,0,0,0,0,0,0,0,0,0,0,0,0,0,0,0,0,0
endlayer

layer
0,0,0,0,0,0,0,0,0,0,0,0,0,0,0,0,0,0,0,0,0,0,0,0,0,0,0,0,0,0,0,0,0,0,0,0,0
0,0,0,0,0,0,0,0,0,0,0,0,0,0,0,0,0,0,0,0,0,0,0,0,0,0,0,0,0,0,0,0,0,0,0,0,0
0,0,0,0,0,0,0,0,0,0,0,0,0,0,0,0,0,0,0,0,0,0,0,0,0,0,0,0,0,0,0,0,0,0,0,0,0
0,0,0,0,0,0,0,0,0,0,0,0,0,0,0,0,0,0,0,0,0,0,0,0,0,0,0,0,0,0,0,0,0,0,0,0,0
0,0,0,0,0,0,0,0,0,0,0,0,0,0,0,0,0,0,0,0,0,0,0,0,0,0,0,0,0,0,0,0,0,0,0,0,0
0,0,0,0,0,0,0,0,0,0,0,0,0,0,0,0,0,0,0,0,0,0,0,0,0,0,0,0,0,0,0,0,0,0,0,0,0
0,0,0,0,0,0,0,0,0,0,0,0,0,0,0,0,0,0,0,0,0,0,0,0,0,0,0,0,0,0,0,0,0,0,0,0,0
0,0,0,0,0,0,0,0,0,0,0,0,0,0,0,0,0,0,0,0,0,0,0,0,0,0,0,0,0,0,0,0,0,0,0,0,0
0,0,0,0,0,0,0,0,0,0,0,0,0,0,0,0,0,0,0,0,0,0,0,0,0,0,0,0,0,0,0,0,0,0,0,0,0
0,0,0,0,0,0,0,0,0,0,0,0,0,0,0,0,0,0,0,0,0,0,0,0,0,0,0,0,0,0,0,0,0,0,0,0,0
0,0,0,0,0,0,0,0,0,0,0,0,0,0,0,0,0,0,0,0,0,0,0,0,0,0,0,0,0,0,0,0,0,0,0,0,0
0,0,0,0,0,0,0,0,0,0,0,0,0,0,0,0,0,0,0,0,0,0,0,0,0,0,0,0,0,0,0,0,0,0,0,0,0
0,0,0,0,0,0,0,0,0,0,0,0,0,0,0,0,0,0,0,0,0,0,0,0,0,0,0,0,0,0,0,0,0,0,0,0,0
0,0,0,0,0,0,0,0,0,0,0,0,0,6,6,6,6,6,6,10,0,0,0,0,0,0,0,0,0,0,0,0,0,0,0,0,0
0,0,0,0,0,0,0,0,0,0,0,0,0,5,3,3,3,3,3,10,0,0,0,0,0,0,0,0,0,0,0,0,0,0,0,0,0
0,0,0,0,0,0,0,0,0,0,0,0,0,5,3,3,3,3,3,10,0,0,0,0,0,0,0,0,0,0,0,0,0,0,0,0,0
0,0,0,0,0,0,0,0,0,0,0,0,0,5,3,3,3,3,3,10,0,0,0,0,0,0,0,0,0,0,0,0,0,0,0,0,0
0,0,0,0,0,0,0,0,0,0,0,0,0,5,3,3,3,3,3,10,0,0,0,0,0,0,0,0,0,0,0,0,0,0,0,0,0
0,0,0,0,0,0,0,0,0,0,0,0,0,5,3,3,3,3,3,10,0,0,0,0,0,0,0,0,0,0,0,0,0,0,0,0,0
0,0,0,0,0,0,0,0,0,0,0,0,0,7,7,7,7,7,7,7,0,0,0,0,0,0,0,0,0,0,0,0,0,0,0,0,0
0,0,0,0,0,0,0,0,0,0,0,0,0,0,0,0,0,0,0,0,0,0,0,0,0,0,0,0,0,0,0,0,0,0,0,0,0
0,0,0,0,0,0,0,0,0,0,0,0,0,0,0,0,0,0,0,0,0,0,0,0,0,0,0,0,0,0,0,0,0,0,0,0,0
0,0,0,0,0,0,0,0,0,0,0,0,0,0,0,0,0,0,0,0,0,0,0,0,0,0,0,0,0,0,0,0,0,0,0,0,0
0,0,0,0,0,0,0,0,0,0,0,0,0,0,0,0,0,0,0,0,0,0,0,0,0,0,0,0,0,0,0,0,0,0,0,0,0
0,0,0,0,0,0,0,0,0,0,0,0,0,0,0,0,0,0,0,0,0,0,0,0,0,0,0,0,0,0,0,0,0,0,0,0,0
0,0,0,0,0,0,0,0,0,0,0,0,0,0,0,0,0,0,0,0,0,0,0,0,0,0,0,0,0,0,0,0,0,0,0,0,0
0,0,0,0,0,0,0,0,0,0,0,0,0,0,0,0,0,0,0,0,0,0,0,0,0,0,0,0,0,0,0,0,0,0,0,0,0
0,0,0,0,0,0,0,0,0,0,0,0,0,0,0,0,0,0,0,0,0,0,0,0,0,0,0,0,0,0,0,0,0,0,0,0,0
0,0,0,0,0,0,0,0,0,0,0,0,0,0,0,0,0,0,0,0,0,0,0,0,0,0,0,0,0,0,0,0,0,0,0,0,0
0,0,0,0,0,0,0,0,0,0,0,0,0,0,0,0,0,0,0,0,0,0,0,0,0,0,0,0,0,0,0,0,0,0,0,0,0
0,0,0,0,0,0,0,0,0,0,0,0,0,0,0,0,0,0,0,0,0,0,0,0,0,0,0,0,0,0,0,0,0,0,0,0,0
0,0,0,0,0,0,0,0,0,0,0,0,0,0,0,0,0,0,0,0,0,0,0,0,0,0,0,0,0,0,0,0,0,0,0,0,0
0,0,0,0,0,0,0,0,0,0,0,0,0,0,0,0,0,0,0,0,0,0,0,0,0,0,0,0,0,0,0,0,0,0,0,0,0
endlayer

layer
0,0,0,0,0,0,0,0,0,0,0,0,0,0,0,0,0,0,0,0,0,0,0,0,0,0,0,0,0,0,0,0,0,0,0,0,0
0,0,0,0,0,0,0,0,0,0,0,0,0,0,0,0,0,0,0,0,0,0,0,0,0,0,0,0,0,0,0,0,0,0,0,0,0
0,0,0,0,0,0,0,0,0,0,0,0,0,0,0,0,0,0,0,0,0,0,0,0,0,0,0,0,0,0,0,0,0,0,0,0,0
0,0,0,0,0,0,0,0,0,0,0,0,0,0,0,0,0,0,0,0,0,0,0,0,0,0,0,0,0,0,0,0,0,0,0,0,0
0,0,0,0,0,0,0,0,0,0,0,0,0,0,0,0,0,0,0,0,0,0,0,0,0,0,0,0,0,0,0,0,0,0,0,0,0
0,0,0,0,0,0,0,0,0,0,0,0,0,0,0,0,0,0,0,0,0,0,0,0,0,0,0,0,0,0,0,0,0,0,0,0,0
0,0,0,0,0,0,0,0,0,0,0,0,0,0,0,0,0,0,0,0,0,0,0,0,0,0,0,0,0,0,0,0,0,0,0,0,0
0,0,0,0,0,0,0,0,0,0,0,0,0,0,0,0,0,0,0,0,0,0,0,0,0,0,0,0,0,0,0,0,0,0,0,0,0
0,0,0,0,0,0,0,0,0,0,0,0,0,0,0,0,0,0,0,0,0,0,0,0,0,0,0,0,0,0,0,0,0,0,0,0,0
0,0,0,0,0,0,0,0,0,0,0,0,0,0,0,0,0,0,0,0,0,0,0,0,0,0,0,0,0,0,0,0,0,0,0,0,0
0,0,0,0,0,0,0,0,0,0,0,0,0,0,0,0,0,0,0,0,0,0,0,0,0,0,0,0,0,0,0,0,0,0,0,0,0
0,0,0,0,0,0,0,0,0,0,0,0,0,0,0,0,0,0,0,0,0,0,0,0,0,0,0,0,0,0,0,0,0,0,0,0,0
0,0,0,0,0,0,0,0,0,0,0,0,0,0,0,0,0,0,0,0,0,0,0,0,0,0,0,0,0,0,0,0,0,0,0,0,0
0,0,0,0,0,0,0,0,0,0,0,0,0,0,0,0,0,0,0,0,0,0,0,0,0,0,0,0,0,0,0,0,0,0,0,0,0
0,0,0,0,0,0,0,0,0,0,0,0,0,0,6,6,6,6,6,0,0,0,0,0,0,0,0,0,0,0,0,0,0,0,0,0,0
0,0,0,0,0,0,0,0,0,0,0,0,0,0,5,3,3,3,10,0,0,0,0,0,0,0,0,0,0,0,0,0,0,0,0,0,0
0,0,0,0,0,0,0,0,0,0,0,0,0,0,5,3,3,3,10,0,0,0,0,0,0,0,0,0,0,0,0,0,0,0,0,0,0
0,0,0,0,0,0,0,0,0,0,0,0,0,0,5,3,3,3,10,0,0,0,0,0,0,0,0,0,0,0,0,0,0,0,0,0,0
0,0,0,0,0,0,0,0,0,0,0,0,0,0,5,7,7,7,7,0,0,0,0,0,0,0,0,0,0,0,0,0,0,0,0,0,0
0,0,0,0,0,0,0,0,0,0,0,0,0,0,0,0,0,0,0,0,0,0,0,0,0,0,0,0,0,0,0,0,0,0,0,0,0
0,0,0,0,0,0,0,0,0,0,0,0,0,0,0,0,0,0,0,0,0,0,0,0,0,0,0,0,0,0,0,0,0,0,0,0,0
0,0,0,0,0,0,0,0,0,0,0,0,0,0,0,0,0,0,0,0,0,0,0,0,0,0,0,0,0,0,0,0,0,0,0,0,0
0,0,0,0,0,0,0,0,0,0,0,0,0,0,0,0,0,0,0,0,0,0,0,0,0,0,0,0,0,0,0,0,0,0,0,0,0
0,0,0,0,0,0,0,0,0,0,0,0,0,0,0,0,0,0,0,0,0,0,0,0,0,0,0,0,0,0,0,0,0,0,0,0,0
0,0,0,0,0,0,0,0,0,0,0,0,0,0,0,0,0,0,0,0,0,0,0,0,0,0,0,0,0,0,0,0,0,0,0,0,0
0,0,0,0,0,0,0,0,0,0,0,0,0,0,0,0,0,0,0,0,0,0,0,0,0,0,0,0,0,0,0,0,0,0,0,0,0
0,0,0,0,0,0,0,0,0,0,0,0,0,0,0,0,0,0,0,0,0,0,0,0,0,0,0,0,0,0,0,0,0,0,0,0,0
0,0,0,0,0,0,0,0,0,0,0,0,0,0,0,0,0,0,0,0,0,0,0,0,0,0,0,0,0,0,0,0,0,0,0,0,0
0,0,0,0,0,0,0,0,0,0,0,0,0,0,0,0,0,0,0,0,0,0,0,0,0,0,0,0,0,0,0,0,0,0,0,0,0
0,0,0,0,0,0,0,0,0,0,0,0,0,0,0,0,0,0,0,0,0,0,0,0,0,0,0,0,0,0,0,0,0,0,0,0,0
0,0,0,0,0,0,0,0,0,0,0,0,0,0,0,0,0,0,0,0,0,0,0,0,0,0,0,0,0,0,0,0,0,0,0,0,0
0,0,0,0,0,0,0,0,0,0,0,0,0,0,0,0,0,0,0,0,0,0,0,0,0,0,0,0,0,0,0,0,0,0,0,0,0
0,0,0,0,0,0,0,0,0,0,0,0,0,0,0,0,0,0,0,0,0,0,0,0,0,0,0,0,0,0,0,0,0,0,0,0,0
endlayer

layer
0,0,0,0,0,0,0,0,0,0,0,0,0,0,0,0,0,0,0,0,0,0,0,0,0,0,0,0,0,0,0,0,0,0,0,0,0
0,0,0,0,0,0,0,0,0,0,0,0,0,0,0,0,0,0,0,0,0,0,0,0,0,0,0,0,0,0,0,0,0,0,0,0,0
0,0,0,0,0,0,0,0,0,0,0,0,0,0,0,0,0,0,0,0,0,0,0,0,0,0,0,0,0,0,0,0,0,0,0,0,0
0,0,0,0,0,0,0,0,0,0,0,0,0,0,0,0,0,0,0,0,0,0,0,0,0,0,0,0,0,0,0,0,0,0,0,0,0
0,0,0,0,0,0,0,0,0,0,0,0,0,0,0,0,0,0,0,0,0,0,0,0,0,0,0,0,0,0,0,0,0,0,0,0,0
0,0,0,0,0,0,0,0,0,0,0,0,0,0,0,0,0,0,0,0,0,0,0,0,0,0,0,0,0,0,0,0,0,0,0,0,0
0,0,0,0,0,0,0,0,0,0,0,0,0,0,0,0,0,0,0,0,0,0,0,0,0,0,0,0,0,0,0,0,0,0,0,0,0
0,0,0,0,0,0,0,0,0,0,0,0,0,0,0,0,0,0,0,0,0,0,0,0,0,0,0,0,0,0,0,0,0,0,0,0,0
0,0,0,0,0,0,0,0,0,0,0,0,0,0,0,0,0,0,0,0,0,0,0,0,0,0,0,0,0,0,0,0,0,0,0,0,0
0,0,0,0,0,0,0,0,0,0,0,0,0,0,0,0,0,0,0,0,0,0,0,0,0,0,0,0,0,0,0,0,0,0,0,0,0
0,0,0,0,0,0,0,0,0,0,0,0,0,0,0,0,0,0,0,0,0,0,0,0,0,0,0,0,0,0,0,0,0,0,0,0,0
0,0,0,0,0,0,0,0,0,0,0,0,0,0,0,0,0,0,0,0,0,0,0,0,0,0,0,0,0,0,0,0,0,0,0,0,0
0,0,0,0,0,0,0,0,0,0,0,0,0,0,0,0,0,0,0,0,0,0,0,0,0,0,0,0,0,0,0,0,0,0,0,0,0
0,0,0,0,0,0,0,0,0,0,0,0,0,0,0,0,0,0,0,0,0,0,0,0,0,0,0,0,0,0,0,0,0,0,0,0,0
0,0,0,0,0,0,0,0,0,0,0,0,0,0,0,0,0,0,0,0,0,0,0,0,0,0,0,0,0,0,0,0,0,0,0,0,0
0,0,0,0,0,0,0,0,0,0,0,0,0,0,0,6,6,6,0,0,0,0,0,0,0,0,0,0,0,0,0,0,0,0,0,0,0
0,0,0,0,0,0,0,0,0,0,0,0,0,0,0,5,4,10,0,0,0,0,0,0,0,0,0,0,0,0,0,0,0,0,0,0,0
0,0,0,0,0,0,0,0,0,0,0,0,0,0,0,7,7,7,0,0,0,0,0,0,0,0,0,0,0,0,0,0,0,0,0,0,0
0,0,0,0,0,0,0,0,0,0,0,0,0,0,0,0,0,0,0,0,0,0,0,0,0,0,0,0,0,0,0,0,0,0,0,0,0
0,0,0,0,0,0,0,0,0,0,0,0,0,0,0,0,0,0,0,0,0,0,0,0,0,0,0,0,0,0,0,0,0,0,0,0,0
0,0,0,0,0,0,0,0,0,0,0,0,0,0,0,0,0,0,0,0,0,0,0,0,0,0,0,0,0,0,0,0,0,0,0,0,0
0,0,0,0,0,0,0,0,0,0,0,0,0,0,0,0,0,0,0,0,0,0,0,0,0,0,0,0,0,0,0,0,0,0,0,0,0
0,0,0,0,0,0,0,0,0,0,0,0,0,0,0,0,0,0,0,0,0,0,0,0,0,0,0,0,0,0,0,0,0,0,0,0,0
0,0,0,0,0,0,0,0,0,0,0,0,0,0,0,0,0,0,0,0,0,0,0,0,0,0,0,0,0,0,0,0,0,0,0,0,0
0,0,0,0,0,0,0,0,0,0,0,0,0,0,0,0,0,0,0,0,0,0,0,0,0,0,0,0,0,0,0,0,0,0,0,0,0
0,0,0,0,0,0,0,0,0,0,0,0,0,0,0,0,0,0,0,0,0,0,0,0,0,0,0,0,0,0,0,0,0,0,0,0,0
0,0,0,0,0,0,0,0,0,0,0,0,0,0,0,0,0,0,0,0,0,0,0,0,0,0,0,0,0,0,0,0,0,0,0,0,0
0,0,0,0,0,0,0,0,0,0,0,0,0,0,0,0,0,0,0,0,0,0,0,0,0,0,0,0,0,0,0,0,0,0,0,0,0
0,0,0,0,0,0,0,0,0,0,0,0,0,0,0,0,0,0,0,0,0,0,0,0,0,0,0,0,0,0,0,0,0,0,0,0,0
0,0,0,0,0,0,0,0,0,0,0,0,0,0,0,0,0,0,0,0,0,0,0,0,0,0,0,0,0,0,0,0,0,0,0,0,0
0,0,0,0,0,0,0,0,0,0,0,0,0,0,0,0,0,0,0,0,0,0,0,0,0,0,0,0,0,0,0,0,0,0,0,0,0
0,0,0,0,0,0,0,0,0,0,0,0,0,0,0,0,0,0,0,0,0,0,0,0,0,0,0,0,0,0,0,0,0,0,0,0,0
0,0,0,0,0,0,0,0,0,0,0,0,0,0,0,0,0,0,0,0,0,0,0,0,0,0,0,0,0,0,0,0,0,0,0,0,0
endlayer

layer
0,0,0,0,0,0,0,0,0,0,0,0,0,0,0,0,0,0,0,0,0,0,0,0,0,0,0,0,0,0,0,0,0,0,0,0,0
0,0,0,0,0,0,0,0,0,0,0,0,0,0,0,0,0,0,0,0,0,0,0,0,0,0,0,0,0,0,0,0,0,0,0,0,0
0,0,0,0,0,0,0,0,0,0,0,0,0,0,0,0,0,0,0,0,0,0,0,0,0,0,0,0,0,0,0,0,0,0,0,0,0
0,0,0,0,0,0,0,0,0,0,0,0,0,0,0,0,0,0,0,0,0,0,0,0,0,0,0,0,0,0,0,0,0,0,0,0,0
0,0,0,0,0,0,0,0,0,0,0,0,0,0,0,0,0,0,0,0,0,0,0,0,0,0,0,0,0,0,0,0,0,0,0,0,0
0,0,0,0,0,0,0,0,0,0,0,0,0,0,0,0,0,0,0,0,0,0,0,0,0,0,0,0,0,0,0,0,0,0,0,0,0
0,0,0,0,0,0,0,0,0,0,0,0,0,0,0,0,0,0,0,0,0,0,0,0,0,0,0,0,0,0,0,0,0,0,0,0,0
0,0,0,0,0,0,0,0,0,0,0,0,0,0,0,0,0,0,0,0,0,0,0,0,0,0,0,0,0,0,0,0,0,0,0,0,0
0,0,0,0,0,0,0,0,0,0,0,0,0,0,0,0,0,0,0,0,0,0,0,0,0,0,0,0,0,0,0,0,0,0,0,0,0
0,0,0,0,0,0,0,0,0,0,0,0,0,0,0,0,0,0,0,0,0,0,0,0,0,0,0,0,0,0,0,0,0,0,0,0,0
0,0,0,0,0,0,0,0,0,0,0,0,0,0,0,0,0,0,0,0,0,0,0,0,0,0,0,0,0,0,0,0,0,0,0,0,0
0,0,0,0,0,0,0,0,0,0,0,0,0,0,0,0,0,0,0,0,0,0,0,0,0,0,0,0,0,0,0,0,0,0,0,0,0
0,0,0,0,0,0,0,0,0,0,0,0,0,0,0,0,0,0,0,0,0,0,0,0,0,0,0,0,0,0,0,0,0,0,0,0,0
0,0,0,0,0,0,0,0,0,0,0,0,0,0,0,0,0,0,0,0,0,0,0,0,0,0,0,0,0,0,0,0,0,0,0,0,0
0,0,0,0,0,0,0,0,0,0,0,0,0,0,0,0,0,0,0,0,0,0,0,0,0,0,0,0,0,0,0,0,0,0,0,0,0
0,0,0,0,0,0,0,0,0,0,0,0,0,0,0,0,0,0,0,0,0,0,0,0,0,0,0,0,0,0,0,0,0,0,0,0,0
0,0,0,0,0,0,0,0,0,0,0,0,0,0,0,0,13,0,0,0,0,0,0,0,0,0,0,0,0,0,0,0,0,0,0,0,0
0,0,0,0,0,0,0,0,0,0,0,0,0,0,0,0,0,0,0,0,0,0,0,0,0,0,0,0,0,0,0,0,0,0,0,0,0
0,0,0,0,0,0,0,0,0,0,0,0,0,0,0,0,0,0,0,0,0,0,0,0,0,0,0,0,0,0,0,0,0,0,0,0,0
0,0,0,0,0,0,0,0,0,0,0,0,0,0,0,0,0,0,0,0,0,0,0,0,0,0,0,0,0,0,0,0,0,0,0,0,0
0,0,0,0,0,0,0,0,0,0,0,0,0,0,0,0,0,0,0,0,0,0,0,0,0,0,0,0,0,0,0,0,0,0,0,0,0
0,0,0,0,0,0,0,0,0,0,0,0,0,0,0,0,0,0,0,0,0,0,0,0,0,0,0,0,0,0,0,0,0,0,0,0,0
0,0,0,0,0,0,0,0,0,0,0,0,0,0,0,0,0,0,0,0,0,0,0,0,0,0,0,0,0,0,0,0,0,0,0,0,0
0,0,0,0,0,0,0,0,0,0,0,0,0,0,0,0,0,0,0,0,0,0,0,0,0,0,0,0,0,0,0,0,0,0,0,0,0
0,0,0,0,0,0,0,0,0,0,0,0,0,0,0,0,0,0,0,0,0,0,0,0,0,0,0,0,0,0,0,0,0,0,0,0,0
0,0,0,0,0,0,0,0,0,0,0,0,0,0,0,0,0,0,0,0,0,0,0,0,0,0,0,0,0,0,0,0,0,0,0,0,0
0,0,0,0,0,0,0,0,0,0,0,0,0,0,0,0,0,0,0,0,0,0,0,0,0,0,0,0,0,0,0,0,0,0,0,0,0
0,0,0,0,0,0,0,0,0,0,0,0,0,0,0,0,0,0,0,0,0,0,0,0,0,0,0,0,0,0,0,0,0,0,0,0,0
0,0,0,0,0,0,0,0,0,0,0,0,0,0,0,0,0,0,0,0,0,0,0,0,0,0,0,0,0,0,0,0,0,0,0,0,0
0,0,0,0,0,0,0,0,0,0,0,0,0,0,0,0,0,0,0,0,0,0,0,0,0,0,0,0,0,0,0,0,0,0,0,0,0
0,0,0,0,0,0,0,0,0,0,0,0,0,0,0,0,0,0,0,0,0,0,0,0,0,0,0,0,0,0,0,0,0,0,0,0,0
0,0,0,0,0,0,0,0,0,0,0,0,0,0,0,0,0,0,0,0,0,0,0,0,0,0,0,0,0,0,0,0,0,0,0,0,0
0,0,0,0,0,0,0,0,0,0,0,0,0,0,0,0,0,0,0,0,0,0,0,0,0,0,0,0,0,0,0,0,0,0,0,0,0
endlayer

