
# Created by Ruins mod version 17.2 Ingame Parser
# authoring Player: BARTLLOW

# TEMPLATE PARAMETER SETTINGS:
#
# criterion expression specifying mod ids required to load template
# may include plus (AND), minus (AND NOT), comma (OR), and parentheses
# all required mods listed must be present; no prohibited mods can be
requiredMods=
#
# likelihood this template will be chosen relative to all others
# e.g., a weight=6 template is chosen 3X as often as one with weight=2
weight=1
#
# list of dimensions in which this template may spawn, even if generic
# one or more dimension names, separated by commas (blank = all)
dimensionsToSpawnIn=
#
# list of other biomes in which this template may spawn
# biome corresponding to directory is always assumed, listed or not
# generic templates should leave this list empty
biomesToSpawnIn=
#
# criterion expression specifying types of biome where template spawns
# this is in addition to those explicitly listed as biomesToSpawnIn
# generic templates should leave this list empty
biomeTypesToSpawnIn=
#
# list of biomes in which this template may not spawn
# takes precedence over biomeTypesToSpawnIn, but NOT biomesToSpawnIn
# should be empty if biomeTypesToSpawnIn is empty
biomesToNotSpawnIn=
#
# depth template is pushed down into the surface when built
# offset is min/max range of random additional bury depth
embed_into_distance=0
random_height_offset=0,0
#
# whitelist/blacklist of block types on which template may be built
# specify one, not both; leave the other empty (both empty = allow all)
acceptable_target_blocks=
unacceptable_target_blocks=flowing_water,water,flowing_lava,lava
#
# size of template (#layers, #rows per layer, #blocks per row)
dimensions=5,24,24
#
# max number of missing blocks allowed in surface beneath template
allowable_overhang=0
#
# depth/height limit affected by terrain leveling
# also maximum bumpiness tolerated in surface beneath template
max_leveling=2
#
# padding applied to all sides of template horizontal footprint
# expands area affected by terrain leveling (-1 = no leveling)
leveling_buffer=0
#
# do not rotate template randomly when built (1 = no rotation)
preventRotation=0
#
# treat water/lava blocks as air and protect them from rule0 (1 = yes)
preserve_water=0
preserve_lava=0
#
# minimum distance this template must have from instances of itself
uniqueMinDistance=0
#
# min/max distances this template can be from world spawn (0 = no limit)
# only applies to overworld--i.e., dimension 0
spawnMinDistance=0
spawnMaxDistance=0
#
# other template built nearby whenever this one is
# syntax: <name>;<relativeX>;<maxYdifference>;<relativeZ>[;<chance>]
# may be used more than once to specify multiple neighbors
adjoining_template=

rule1=0,100,minecraft:stone-0
rule2=0,100,minecraft:stonebrick-2
rule3=0,100,minecraft:mossy_cobblestone-0
rule4=0,100,minecraft:vine-4
rule5=0,100,minecraft:cobblestone-0
rule6=0,100,minecraft:stone_stairs-1
rule7=0,100,minecraft:stone_stairs-4
rule8=0,100,minecraft:stone_stairs-0
rule9=0,100,minecraft:vine-1
rule10=0,100,minecraft:web-0
rule11=0,100,minecraft:stone_stairs-5
rule12=0,100,minecraft:lava-10
rule13=0,100,minecraft:stonebrick-0
rule14=0,100,minecraft:vine-2
rule15=0,100,IInventory;minecraft:chest;minecraft:saddle#1#0#4+minecraft:saddle#1#0#5+minecraft:name_tag#1#0#22-5
rule16=0,100,IInventory;minecraft:chest;minecraft:record_cat#1#0#22+minecraft:record_13#1#0#25-4
rule17=0,100,minecraft:vine-8
rule18=0,100,minecraft:stone_brick_stairs-0
rule19=0,100,minecraft:stone_brick_stairs-2
rule20=0,100,minecraft:stone_brick_stairs-3
rule21=0,100,minecraft:stone_brick_stairs-1
rule22=0,100,minecraft:vine-9
rule23=0,100,minecraft:lava-2
rule24=0,100,minecraft:stone_brick_stairs-4
rule25=0,100,minecraft:stone_brick_stairs-6
rule26=0,100,minecraft:stone_brick_stairs-7
rule27=0,100,minecraft:stone_brick_stairs-5
rule28=0,100,minecraft:stone_stairs-2
rule29=0,100,minecraft:stone_stairs-6
rule30=0,100,minecraft:lava-0

layer
1,1,3,1,1,1,3,1,1,0,4,1,1,3,2,1,0,0,0,0,0,0,0,0
1,1,1,5,1,1,1,1,1,0,0,5,1,1,1,3,0,0,0,0,0,0,0,0
1,1,1,1,1,1,1,1,1,1,1,1,1,1,1,1,1,1,0,0,0,0,0,0
1,3,1,1,3,1,1,1,1,1,1,1,1,1,1,1,1,1,0,0,0,0,0,0
1,1,1,1,1,1,1,1,3,1,1,1,1,1,1,1,1,1,0,0,0,0,0,0
1,1,1,1,1,1,3,7,1,3,1,5,1,1,1,6,1,1,0,0,0,0,0,0
1,1,1,1,1,1,1,1,1,1,1,1,5,1,1,1,1,1,0,0,0,0,0,0
1,1,1,1,5,1,1,1,1,0,0,1,1,1,3,1,0,0,0,0,0,0,0,0
1,1,1,5,5,1,1,1,1,0,0,1,1,1,1,1,0,0,0,0,0,0,0,0
0,0,0,1,1,1,1,1,1,1,1,1,1,1,1,1,1,1,1,1,1,0,0,0
0,0,0,5,1,1,1,1,1,1,1,1,1,1,5,1,1,1,1,1,1,0,0,0
0,0,0,1,1,5,1,1,1,1,1,1,1,1,1,1,1,1,1,1,1,0,0,0
0,0,0,0,0,0,1,5,1,1,1,1,1,1,3,1,1,5,1,1,1,1,1,1
0,0,0,0,0,0,1,3,1,1,1,1,1,1,1,1,1,1,1,8,1,1,1,1
0,0,0,0,0,0,1,1,1,1,1,1,5,2,3,1,1,1,1,1,1,1,1,5
0,0,0,0,0,0,1,1,1,1,1,1,1,1,1,0,0,5,1,1,1,1,0,0
0,0,0,0,0,0,1,1,1,1,1,1,1,1,1,10,0,5,1,1,5,1,9,0
0,0,0,0,0,0,1,1,1,1,1,1,1,1,1,1,1,1,1,1,1,1,1,11
0,0,0,0,0,0,1,1,1,12,13,12,1,1,1,5,5,1,1,1,1,1,1,1
0,0,0,0,0,0,1,1,1,13,1,13,1,1,1,1,1,1,1,1,1,1,1,1
0,0,0,0,0,0,1,1,1,12,1,12,1,1,1,1,1,1,1,1,1,1,5,1
0,0,0,0,0,0,1,1,1,1,1,1,1,1,1,1,1,1,1,1,1,1,1,1
0,0,0,0,0,0,1,1,1,1,1,1,1,1,1,0,0,1,1,1,1,1,9,0
0,0,0,0,0,0,1,1,1,1,1,1,1,1,1,0,0,1,1,3,1,5,0,0
endlayer

layer
1,1,1,5,1,1,1,1,1,0,0,5,0,0,0,3,0,0,0,0,0,0,0,0
1,14,0,0,0,0,0,4,1,0,0,1,9,0,0,1,0,0,0,0,0,0,0,0
1,1,1,1,0,5,1,10,1,1,1,1,0,0,4,1,1,5,0,0,0,0,0,0
1,1,1,1,4,1,1,0,1,1,3,1,0,0,0,1,1,1,0,0,0,0,0,0
1,10,0,0,0,0,0,4,1,1,1,1,0,0,0,1,1,1,0,0,0,0,0,0
1,0,1,1,0,1,1,1,1,5,1,1,9,0,0,1,1,1,0,0,0,0,0,0
1,0,1,1,4,1,1,1,1,1,1,5,0,0,0,5,1,5,0,0,0,0,0,0
1,16,1,1,9,1,1,15,1,0,14,1,0,0,4,1,0,0,0,0,0,0,0,0
1,1,1,1,0,1,1,0,1,0,0,1,0,0,0,1,0,0,0,0,0,0,0,0
0,0,0,3,0,1,1,0,1,1,1,1,5,9,1,1,1,1,1,1,1,0,0,0
0,0,0,1,0,10,0,0,1,1,10,0,17,0,0,0,0,0,0,0,1,0,0,0
0,0,0,1,1,1,1,4,5,1,1,1,1,1,1,1,0,1,1,1,1,0,0,0
0,0,0,0,0,0,1,0,1,1,1,1,1,1,1,1,0,5,1,1,1,1,1,1
0,0,0,0,0,0,1,0,0,17,0,0,0,0,14,0,10,1,1,0,0,10,0,1
0,0,0,0,0,0,1,1,1,1,0,1,1,1,1,1,1,3,1,0,3,1,1,1
0,0,0,0,0,0,1,1,1,1,0,1,1,1,1,0,0,1,0,0,4,2,0,0
0,0,0,0,0,0,1,0,0,0,0,0,0,0,1,17,0,1,0,0,0,1,9,0
0,0,0,0,0,0,1,0,0,0,0,0,0,0,1,1,1,1,9,0,0,5,1,5
0,0,0,0,0,0,1,1,18,12,18,12,18,0,1,0,14,0,0,0,0,1,1,1
0,0,0,0,0,0,1,1,20,13,13,13,19,0,0,0,0,0,0,0,4,1,1,1
0,0,0,0,0,0,1,1,21,12,21,12,21,0,1,0,0,0,0,0,17,1,1,5
0,0,0,0,0,0,1,0,0,0,0,0,0,0,1,5,5,1,1,1,1,1,1,1
0,0,0,0,0,0,1,0,0,0,0,0,0,0,1,0,0,5,1,1,1,1,9,0
0,0,0,0,0,0,1,1,1,1,0,1,1,1,1,0,0,1,1,1,1,1,9,0
endlayer

layer
1,1,1,1,1,1,1,1,1,0,0,1,0,0,0,1,0,0,0,0,0,0,0,0
1,0,0,0,0,0,0,4,1,0,17,1,0,0,0,1,0,0,0,0,0,0,0,0
1,1,1,1,0,1,1,10,1,1,1,1,0,0,0,1,5,1,0,0,0,0,0,0
5,1,1,1,0,1,1,0,1,1,1,1,0,0,0,1,1,1,0,0,0,0,0,0
1,10,0,0,0,10,0,0,5,1,1,1,0,0,0,1,5,1,0,0,0,0,0,0
1,0,1,1,0,1,1,2,1,1,1,1,9,0,0,1,1,1,0,0,0,0,0,0
1,0,1,1,4,1,1,1,1,1,1,1,0,0,0,3,1,1,0,0,0,0,0,0
1,0,1,1,9,1,1,0,1,0,14,1,0,0,4,1,0,0,0,0,0,0,0,0
1,1,1,1,0,1,1,0,1,0,0,1,0,0,0,1,0,0,0,0,0,0,0,0
0,0,0,1,0,1,1,10,1,1,1,5,1,9,3,1,1,5,1,1,1,0,0,0
0,0,0,1,0,0,0,0,1,1,0,0,17,0,0,0,0,17,0,0,5,0,0,0
0,0,0,1,1,5,1,0,1,1,1,1,5,1,1,1,0,1,1,1,1,0,0,0
0,0,0,0,0,0,1,10,1,1,5,1,1,1,1,1,0,1,1,1,1,1,1,1
0,0,0,0,0,0,1,0,10,0,0,0,0,17,0,10,0,1,1,0,0,0,0,1
0,0,0,0,0,0,1,1,1,1,0,1,1,1,1,1,1,3,1,0,1,1,1,1
0,0,0,0,0,0,1,1,1,1,0,1,1,1,1,0,0,1,0,0,4,1,0,0
0,0,0,0,0,0,1,0,0,0,0,0,0,0,1,0,4,1,0,0,0,1,22,0
0,0,0,0,0,0,1,0,0,0,0,0,0,0,1,5,5,1,0,0,0,11,1,1
0,0,0,0,0,0,1,0,0,23,24,23,0,0,1,0,0,0,0,0,0,1,1,1
0,0,0,0,0,0,1,1,26,12,13,12,25,0,0,0,0,0,0,0,4,1,3,1
0,0,0,0,0,0,1,0,0,23,27,23,0,0,1,0,0,0,0,0,0,1,1,1
0,0,0,0,0,0,1,0,0,0,0,0,0,0,1,1,1,5,1,1,5,1,1,5
0,0,0,0,0,0,1,0,0,0,0,0,0,0,1,0,0,5,1,3,1,5,9,0
0,0,0,0,0,0,1,1,1,1,0,1,1,1,1,0,0,1,1,1,1,1,9,0
endlayer

layer
1,1,5,1,5,1,1,1,1,0,0,1,0,0,0,1,0,0,0,0,0,0,0,0
1,1,1,1,1,1,1,1,1,17,17,1,0,0,0,1,0,0,0,0,0,0,0,0
1,1,1,3,1,1,3,1,1,1,1,1,0,0,0,1,1,1,0,0,0,0,0,0
1,1,1,1,5,1,1,1,1,1,1,1,0,0,0,1,1,1,0,0,0,0,0,0
3,1,1,1,5,3,1,1,1,1,1,1,0,0,0,1,1,1,0,0,0,0,0,0
1,1,3,1,1,1,1,1,1,1,1,1,0,0,0,1,1,1,0,0,0,0,0,0
1,1,1,1,3,1,1,1,1,28,1,1,0,0,0,1,1,1,0,0,0,0,0,0
1,1,1,1,1,1,1,1,1,0,4,29,0,0,0,1,0,0,0,0,0,0,0,0
1,1,1,1,1,1,1,1,1,0,0,1,0,0,0,1,0,0,0,0,0,0,0,0
0,0,0,1,1,3,1,1,1,5,3,5,1,1,1,1,1,1,1,1,1,0,0,0
0,0,0,1,3,1,1,1,1,1,1,1,1,1,1,1,1,1,1,1,1,0,0,0
0,0,0,1,1,1,1,1,1,1,1,1,1,1,1,1,1,1,1,1,5,0,0,0
0,0,0,0,0,0,1,1,1,1,1,1,1,1,1,3,1,1,1,3,1,1,1,1
0,0,0,0,0,0,1,1,1,1,1,1,1,1,1,5,1,1,1,1,1,1,1,1
0,0,0,0,0,0,1,1,1,1,1,1,1,1,1,1,1,1,1,3,6,1,1,1
0,0,0,0,0,0,1,1,1,1,1,1,1,1,1,0,0,5,0,0,0,5,0,0
0,0,0,0,0,0,1,0,0,0,0,0,0,0,1,0,4,1,0,0,0,5,22,17
0,0,0,0,0,0,1,0,0,0,0,0,0,0,1,1,1,5,0,0,0,1,5,1
0,0,0,0,0,0,1,0,0,0,18,0,0,0,1,0,0,0,0,0,0,1,3,1
0,0,0,0,0,0,1,0,13,23,30,23,13,0,1,0,0,0,0,0,4,1,1,1
0,0,0,0,0,0,1,0,0,0,21,0,0,0,1,0,0,0,0,0,0,1,1,1
0,0,0,0,0,0,1,0,0,0,0,0,0,0,1,5,5,1,1,5,1,1,1,1
0,0,0,0,0,0,1,0,0,0,0,0,0,0,1,0,0,1,1,1,1,1,0,0
0,0,0,0,0,0,1,1,1,1,1,1,1,1,1,0,0,1,1,1,1,1,9,0
endlayer

layer
0,0,0,0,0,0,0,0,0,0,0,1,5,1,1,1,0,0,0,0,0,0,0,0
0,0,0,0,0,0,0,0,0,0,0,1,1,1,1,5,0,0,0,0,0,0,0,0
0,0,0,0,0,0,0,0,0,1,1,1,1,1,1,1,1,1,0,0,0,0,0,0
0,0,0,0,0,0,0,0,0,1,1,1,1,1,1,1,1,1,0,0,0,0,0,0
0,0,0,0,0,0,0,0,0,1,1,1,1,1,1,3,5,1,0,0,0,0,0,0
0,0,0,0,0,0,0,0,0,1,1,5,1,1,1,1,1,5,0,0,0,0,0,0
0,0,0,0,0,0,0,0,0,1,1,1,1,1,6,1,1,5,0,0,0,0,0,0
0,0,0,0,0,0,0,0,0,0,4,1,1,3,1,1,0,0,0,0,0,0,0,0
0,0,0,0,0,0,0,0,0,0,4,1,1,5,5,1,0,0,0,0,0,0,0,0
0,0,0,0,0,0,0,0,0,0,0,0,0,0,0,0,0,0,0,0,0,0,0,0
0,0,0,0,0,0,0,0,0,0,0,0,0,0,0,0,0,0,0,0,0,0,0,0
0,0,0,0,0,0,0,0,0,0,0,0,0,0,0,0,0,0,0,0,0,0,0,0
0,0,0,0,0,0,0,0,0,0,0,0,0,0,0,0,0,0,0,0,0,0,0,0
0,0,0,0,0,0,0,0,0,0,0,0,0,0,0,0,0,0,0,0,0,0,0,0
0,0,0,0,0,0,0,0,0,0,0,0,0,0,0,0,0,0,0,0,0,0,0,0
0,0,0,0,0,0,1,1,1,1,1,1,1,1,1,0,0,1,1,1,1,1,0,0
0,0,0,0,0,0,1,1,1,1,1,1,1,1,1,0,0,1,1,1,1,1,0,0
0,0,0,0,0,0,1,1,1,1,1,1,1,1,1,1,1,5,1,1,1,1,1,5
0,0,0,0,0,0,1,1,1,1,1,1,1,1,1,3,3,1,1,1,1,1,5,1
0,0,0,0,0,0,1,1,1,1,1,1,1,1,1,1,1,1,1,1,1,1,1,1
0,0,0,0,0,0,1,1,1,1,1,1,1,1,1,1,1,1,1,1,1,1,1,1
0,0,0,0,0,0,1,1,1,1,1,1,1,1,1,1,1,3,1,1,1,1,1,1
0,0,0,0,0,0,1,1,1,1,1,1,1,1,1,0,0,5,1,1,5,1,0,0
0,0,0,0,0,0,1,1,1,1,1,1,1,1,1,0,0,5,1,1,1,1,9,0
endlayer

