
# Created by Ruins mod version 17.2 Ingame Parser
# authoring Player: BARTLLOW

# TEMPLATE PARAMETER SETTINGS:
#
# criterion expression specifying mod ids required to load template
# may include plus (AND), minus (AND NOT), comma (OR), and parentheses
# all required mods listed must be present; no prohibited mods can be
requiredMods=
#
# likelihood this template will be chosen relative to all others
# e.g., a weight=6 template is chosen 3X as often as one with weight=2
weight=1
#
# list of dimensions in which this template may spawn, even if generic
# one or more dimension names, separated by commas (blank = all)
dimensionsToSpawnIn=
#
# list of other biomes in which this template may spawn
# biome corresponding to directory is always assumed, listed or not
# generic templates should leave this list empty
biomesToSpawnIn=
#
# criterion expression specifying types of biome where template spawns
# this is in addition to those explicitly listed as biomesToSpawnIn
# generic templates should leave this list empty
biomeTypesToSpawnIn=
#
# list of biomes in which this template may not spawn
# takes precedence over biomeTypesToSpawnIn, but NOT biomesToSpawnIn
# should be empty if biomeTypesToSpawnIn is empty
biomesToNotSpawnIn=
#
# depth template is pushed down into the surface when built
# offset is min/max range of random additional bury depth
embed_into_distance=0
random_height_offset=0,0
#
# whitelist/blacklist of block types on which template may be built
# specify one, not both; leave the other empty (both empty = allow all)
acceptable_target_blocks=
unacceptable_target_blocks=flowing_water,water,flowing_lava,lava
#
# size of template (#layers, #rows per layer, #blocks per row)
dimensions=18,11,9
#
# max number of missing blocks allowed in surface beneath template
allowable_overhang=0
#
# depth/height limit affected by terrain leveling
# also maximum bumpiness tolerated in surface beneath template
max_leveling=2
#
# padding applied to all sides of template horizontal footprint
# expands area affected by terrain leveling (-1 = no leveling)
leveling_buffer=0
#
# do not rotate template randomly when built (1 = no rotation)
preventRotation=0
#
# treat water/lava blocks as air and protect them from rule0 (1 = yes)
preserve_water=0
preserve_lava=0
#
# minimum distance this template must have from instances of itself
uniqueMinDistance=0
#
# min/max distances this template can be from world spawn (0 = no limit)
# only applies to overworld--i.e., dimension 0
spawnMinDistance=0
spawnMaxDistance=0
#
# other template built nearby whenever this one is
# syntax: <name>;<relativeX>;<maxYdifference>;<relativeZ>[;<chance>]
# may be used more than once to specify multiple neighbors
adjoining_template=

rule1=0,100,minecraft:stone_brick_stairs-2
rule2=0,100,minecraft:stone_brick_stairs-0
rule3=0,100,minecraft:stone_brick_stairs-3
rule4=0,100,minecraft:stonebrick-0
rule5=0,100,minecraft:planks-0
rule6=0,100,minecraft:stone_brick_stairs-1
rule7=0,100,minecraft:stonebrick-2
rule8=0,100,minecraft:vine-4
rule9=0,100,minecraft:stonebrick-1
rule10=0,100,minecraft:vine-2
rule11=0,100,minecraft:vine-8
rule12=0,100,minecraft:nether_brick_fence-0
rule13=0,100,minecraft:vine-1
rule14=0,100,minecraft:wooden_door-0
rule15=0,100,minecraft:ladder-4
rule16=0,100,minecraft:mob_spawner-0
rule17=0,100,minecraft:wooden_door-8
rule18=0,100,minecraft:iron_bars-0
rule19=0,100,minecraft:nether_brick_stairs-2
rule20=0,100,minecraft:nether_brick_stairs-0
rule21=0,100,minecraft:nether_brick_stairs-3
rule22=0,100,minecraft:stone_brick_stairs-6
rule23=0,100,minecraft:stone_brick_stairs-7
rule24=0,100,minecraft:stone_brick_stairs-4
rule25=0,100,minecraft:stone_brick_stairs-5
rule26=0,100,IInventory;minecraft:chest;minecraft:saddle#1#0#0+minecraft:golden_horse_armor#1#0#1+minecraft:name_tag#1#0#5+minecraft:record_cat#1#0#8+minecraft:diamond_horse_armor#1#0#11+minecraft:name_tag#1#0#12+minecraft:record_cat#1#0#13+minecraft:saddle#1#0#14+minecraft:enchanted_book#{StoredEnchantments:[{lvl:3s,id:48s}]}#0#17+minecraft:saddle#1#0#18+minecraft:golden_apple#1#0#22+minecraft:record_13#1#0#24-2
rule27=0,100,minecraft:nether_brick_stairs-1
rule28=0,100,minecraft:nether_brick-0

layer
0,0,3,2,2,2,1,0,0
3,2,3,4,4,4,1,2,2
3,4,4,4,5,4,4,4,1
6,4,5,5,5,5,5,4,6
8,7,5,5,5,5,5,7,0
8,7,5,5,5,5,5,7,0
0,4,5,5,5,5,5,9,0
2,4,5,5,5,5,5,4,2
3,4,4,4,4,4,4,4,1
6,6,1,10,10,10,3,6,1
0,0,0,0,0,0,0,0,0
endlayer

layer
0,0,0,0,0,0,0,0,0
0,11,11,12,0,12,0,11,0
8,7,4,4,14,4,7,7,13
8,4,0,0,0,0,0,4,13
8,4,0,0,0,0,0,4,0
0,3,0,0,0,0,0,1,0
0,4,0,0,0,0,0,4,0
0,4,16,0,15,0,0,9,0
8,9,4,7,4,7,4,4,0
0,10,10,10,10,10,10,0,0
0,0,0,0,0,0,0,0,0
endlayer

layer
0,0,0,0,0,0,0,0,0
0,11,11,12,0,12,0,11,0
8,9,4,4,17,4,4,4,13
8,4,0,0,0,0,0,9,13
12,4,0,0,0,0,0,4,12
0,18,0,0,0,0,0,18,0
12,4,0,0,0,0,0,4,12
0,4,0,0,15,0,0,4,0
8,4,7,4,4,9,4,4,0
0,10,10,10,10,10,10,0,0
0,0,0,0,0,0,0,0,0
endlayer

layer
0,0,0,0,0,0,0,0,0
0,11,11,21,20,19,0,11,0
8,4,9,4,4,4,4,4,13
8,7,0,0,0,0,0,4,13
12,4,0,0,0,0,0,4,12
0,18,0,0,0,0,0,18,0
12,4,0,0,0,0,0,4,12
0,9,0,0,15,0,0,4,0
8,4,4,9,4,4,4,9,0
0,10,10,10,10,10,10,0,0
0,0,0,0,0,0,0,0,0
endlayer

layer
0,0,0,0,0,0,0,0,0
0,11,11,0,0,0,0,11,0
8,4,4,7,9,4,4,9,13
8,9,0,0,0,0,0,7,13
8,9,0,0,0,0,0,4,0
0,23,0,0,0,0,0,22,0
0,4,0,0,0,0,0,4,0
0,7,0,0,15,0,0,4,0
8,4,4,9,4,4,7,4,0
0,10,10,0,10,10,10,0,0
0,0,0,0,0,0,0,0,0
endlayer

layer
0,0,0,0,0,0,0,0,0
0,11,11,0,0,0,0,11,0
0,2,2,2,2,2,2,2,13
8,3,5,5,5,5,5,1,13
0,3,5,5,5,5,5,1,0
0,3,5,5,5,5,5,1,0
0,3,5,5,5,5,5,1,0
0,3,5,5,15,5,5,1,0
8,6,6,6,4,6,6,6,0
0,10,0,0,10,10,10,0,0
0,0,0,0,0,0,0,0,0
endlayer

layer
0,0,0,0,0,0,0,0,0
0,11,11,0,0,0,0,11,0
8,4,24,4,2,4,24,4,13
8,23,0,0,0,0,0,22,13
0,4,0,0,0,0,0,4,0
0,3,0,0,0,0,0,1,0
0,4,0,0,0,0,0,4,0
0,23,0,0,15,0,0,22,0
8,4,25,4,4,4,25,4,0
0,10,10,0,10,10,10,0,0
0,0,0,0,0,0,0,0,0
endlayer

layer
0,0,0,0,0,0,0,0,0
0,11,11,12,0,12,0,11,0
8,9,4,4,18,4,4,4,13
8,4,0,0,0,0,0,4,13
12,4,0,0,0,0,0,4,12
0,18,0,0,0,0,0,18,0
12,4,0,0,0,0,0,4,12
0,7,0,0,15,0,0,9,0
8,7,9,4,4,9,4,7,0
0,10,10,0,10,10,10,0,0
0,0,0,0,0,0,0,0,0
endlayer

layer
0,0,0,0,0,0,0,0,0
0,11,11,12,0,12,0,11,0
8,4,9,4,18,4,4,4,13
8,7,0,0,0,0,0,4,13
12,4,0,0,0,0,0,4,12
0,18,0,0,0,0,0,18,0
12,4,0,0,0,0,0,4,12
0,4,0,0,15,0,0,4,0
8,7,4,9,4,4,9,9,0
0,10,10,0,10,10,10,0,0
0,0,0,0,0,0,0,0,0
endlayer

layer
0,0,0,0,0,0,0,0,0
0,11,24,0,24,0,24,11,0
8,4,4,4,4,4,4,4,13
23,4,0,0,0,0,0,4,22
0,4,0,0,0,0,0,4,0
23,4,0,0,0,0,0,4,22
0,4,0,0,0,0,0,4,0
23,4,0,0,15,0,0,4,22
8,4,4,9,4,4,4,4,0
0,10,25,0,25,10,25,0,0
0,0,0,0,0,0,0,0,0
endlayer

layer
0,0,0,0,0,0,0,0,0
23,24,4,24,4,24,4,24,24
23,5,5,5,5,5,5,5,22
4,5,5,5,5,5,5,5,4
23,5,5,5,5,5,5,5,22
4,5,5,5,5,5,5,5,4
23,5,5,5,5,5,5,5,22
4,5,5,5,15,5,5,5,4
23,5,5,5,5,5,5,5,22
25,25,4,25,4,25,4,25,22
0,0,0,0,0,0,0,0,0
endlayer

layer
0,0,0,0,0,0,0,0,0
4,4,2,4,2,4,2,4,4
4,0,0,0,0,0,0,0,4
3,0,4,0,0,0,4,0,1
4,0,0,0,16,0,0,0,4
3,0,0,0,26,0,0,0,1
4,0,0,0,0,0,0,0,4
3,0,4,0,0,0,4,0,1
4,0,0,0,0,0,0,0,4
4,4,6,4,6,4,6,4,4
0,0,0,0,0,0,0,0,0
endlayer

layer
0,0,0,0,0,0,0,0,0
3,2,0,2,0,2,0,2,1
3,0,0,0,0,0,0,0,1
0,0,4,22,0,23,4,0,0
3,0,25,0,0,0,25,0,1
0,0,0,0,0,0,0,0,0
3,0,24,0,0,0,24,0,1
0,0,4,22,0,23,4,0,0
3,0,0,0,0,0,0,0,1
3,6,0,6,0,6,0,6,1
0,0,0,0,0,0,0,0,0
endlayer

layer
0,0,0,0,0,0,0,0,0
0,0,0,0,0,0,0,0,0
0,0,24,0,0,0,24,0,0
0,23,4,4,4,4,4,22,0
0,0,4,0,0,0,4,0,0
0,0,4,0,0,0,4,0,0
0,0,4,0,0,0,4,0,0
0,23,4,4,4,4,4,22,0
0,0,25,0,0,0,25,0,0
0,0,0,0,0,0,0,0,0
0,0,0,0,0,0,0,0,0
endlayer

layer
0,0,0,0,0,0,0,0,0
0,0,0,0,0,0,0,0,0
0,20,20,20,20,20,20,19,0
0,21,4,4,4,4,4,19,0
0,21,4,4,4,4,4,19,0
0,21,4,4,4,4,4,19,0
0,21,4,4,4,4,4,19,0
0,21,4,4,4,4,4,19,0
0,27,27,27,27,27,27,19,0
0,0,0,0,0,0,0,0,0
0,0,0,0,0,0,0,0,0
endlayer

layer
0,0,0,0,0,0,0,0,0
0,0,0,0,0,0,0,0,0
0,0,0,0,0,0,0,0,0
0,0,20,20,20,20,19,0,0
0,0,21,4,4,4,19,0,0
0,0,21,4,4,4,19,0,0
0,0,21,4,4,4,19,0,0
0,0,27,27,27,27,27,0,0
0,0,0,0,0,0,0,0,0
0,0,0,0,0,0,0,0,0
0,0,0,0,0,0,0,0,0
endlayer

layer
0,0,0,0,0,0,0,0,0
0,0,0,0,0,0,0,0,0
0,0,0,0,0,0,0,0,0
0,0,0,0,0,0,0,0,0
0,0,0,21,20,20,0,0,0
0,0,0,21,4,19,0,0,0
0,0,0,27,27,19,0,0,0
0,0,0,0,0,0,0,0,0
0,0,0,0,0,0,0,0,0
0,0,0,0,0,0,0,0,0
0,0,0,0,0,0,0,0,0
endlayer

layer
0,0,0,0,0,0,0,0,0
0,0,0,0,0,0,0,0,0
0,0,0,0,0,0,0,0,0
0,0,0,0,0,0,0,0,0
0,0,0,0,0,0,0,0,0
0,0,0,0,28,0,0,0,0
0,0,0,0,0,0,0,0,0
0,0,0,0,0,0,0,0,0
0,0,0,0,0,0,0,0,0
0,0,0,0,0,0,0,0,0
0,0,0,0,0,0,0,0,0
endlayer

