
# Created by Ruins mod version 17.2 Ingame Parser
# authoring Player: BARTLLOW

# TEMPLATE PARAMETER SETTINGS:
#
# criterion expression specifying mod ids required to load template
# may include plus (AND), minus (AND NOT), comma (OR), and parentheses
# all required mods listed must be present; no prohibited mods can be
requiredMods=
#
# likelihood this template will be chosen relative to all others
# e.g., a weight=6 template is chosen 3X as often as one with weight=2
weight=1
#
# list of dimensions in which this template may spawn, even if generic
# one or more dimension names, separated by commas (blank = all)
dimensionsToSpawnIn=
#
# list of other biomes in which this template may spawn
# biome corresponding to directory is always assumed, listed or not
# generic templates should leave this list empty
biomesToSpawnIn=
#
# criterion expression specifying types of biome where template spawns
# this is in addition to those explicitly listed as biomesToSpawnIn
# generic templates should leave this list empty
biomeTypesToSpawnIn=
#
# list of biomes in which this template may not spawn
# takes precedence over biomeTypesToSpawnIn, but NOT biomesToSpawnIn
# should be empty if biomeTypesToSpawnIn is empty
biomesToNotSpawnIn=
#
# depth template is pushed down into the surface when built
# offset is min/max range of random additional bury depth
embed_into_distance=0
random_height_offset=0,0
#
# whitelist/blacklist of block types on which template may be built
# specify one, not both; leave the other empty (both empty = allow all)
acceptable_target_blocks=
unacceptable_target_blocks=flowing_water,water,flowing_lava,lava
#
# size of template (#layers, #rows per layer, #blocks per row)
dimensions=27,15,14
#
# max number of missing blocks allowed in surface beneath template
allowable_overhang=0
#
# depth/height limit affected by terrain leveling
# also maximum bumpiness tolerated in surface beneath template
max_leveling=2
#
# padding applied to all sides of template horizontal footprint
# expands area affected by terrain leveling (-1 = no leveling)
leveling_buffer=0
#
# do not rotate template randomly when built (1 = no rotation)
preventRotation=0
#
# treat water/lava blocks as air and protect them from rule0 (1 = yes)
preserve_water=0
preserve_lava=0
#
# minimum distance this template must have from instances of itself
uniqueMinDistance=0
#
# min/max distances this template can be from world spawn (0 = no limit)
# only applies to overworld--i.e., dimension 0
spawnMinDistance=0
spawnMaxDistance=0
#
# other template built nearby whenever this one is
# syntax: <name>;<relativeX>;<maxYdifference>;<relativeZ>[;<chance>]
# may be used more than once to specify multiple neighbors
adjoining_template=

rule1=0,100,minecraft:stone_slab-14
rule2=0,100,minecraft:nether_brick-0
rule3=0,100,minecraft:mob_spawner-0
rule4=0,100,minecraft:obsidian-0
rule5=0,100,minecraft:glowstone-0
rule6=0,100,minecraft:nether_brick_stairs-4
rule7=0,100,minecraft:nether_brick_stairs-6
rule8=0,100,minecraft:nether_brick_stairs-7
rule9=0,100,minecraft:nether_brick_stairs-0
rule10=0,100,minecraft:nether_brick_stairs-2
rule11=0,100,minecraft:nether_brick_stairs-3
rule12=0,100,minecraft:nether_brick_stairs-5
rule13=0,100,minecraft:nether_brick_stairs-1
rule14=0,100,minecraft:netherrack-0
rule15=0,100,minecraft:stone_slab-6
rule16=0,100,minecraft:fire-15
rule17=0,100,minecraft:stained_glass-15
rule18=0,100,IInventory;minecraft:dropper;minecraft:potion#{Potion:"minecraft:strong_strength"}#0#0+minecraft:leather_chestplate#1#0#2+minecraft:potion#{Potion:"minecraft:strong_strength"}#0#6+minecraft:enchanted_book#{StoredEnchantments:[{lvl:2,id:7}]}#0#7+minecraft:splash_potion#{Potion:"minecraft:long_weakness"}#0#8-0

layer
0,0,0,0,0,0,0,0,0,0,0,0,0,0
0,0,0,0,0,0,0,0,0,0,0,0,0,0
0,0,0,0,0,0,0,0,0,0,0,0,0,0
0,0,0,0,0,0,0,0,0,0,0,0,0,0
0,0,0,0,0,0,0,0,0,0,0,0,0,0
0,0,0,0,0,0,0,0,0,0,0,0,0,0
0,0,0,0,0,0,0,0,0,0,0,0,0,0
0,0,0,0,0,0,0,0,0,0,0,0,0,0
0,0,0,0,0,0,0,0,0,0,0,0,0,0
0,0,0,0,0,0,0,0,0,0,0,0,0,0
0,0,0,0,0,0,0,0,0,0,0,0,0,0
0,0,0,0,0,0,0,0,0,0,0,0,0,0
0,0,0,0,0,0,0,0,0,0,0,0,0,0
0,0,0,0,0,0,0,0,0,0,0,0,0,0
0,0,0,0,0,0,0,0,0,0,0,0,0,0
endlayer

layer
0,0,0,0,0,0,0,0,0,0,0,0,0,0
0,0,0,0,0,0,0,0,0,0,0,0,0,0
0,0,0,0,0,0,0,0,0,0,0,0,0,0
0,0,0,0,0,0,0,0,0,0,0,0,0,0
0,0,0,0,0,0,2,2,2,1,0,0,0,0
0,0,0,0,0,2,0,2,0,2,1,0,0,0
0,0,0,0,2,0,0,1,0,0,2,0,0,0
0,0,0,0,2,2,1,1,1,2,2,0,0,0
0,0,0,0,2,0,0,1,0,0,2,0,0,0
0,0,0,0,1,2,0,2,0,2,1,0,0,0
0,0,0,0,0,1,2,2,2,1,0,0,0,0
0,0,0,0,0,0,0,0,0,0,0,0,0,0
0,0,0,0,0,0,0,0,0,0,0,0,0,0
0,0,0,0,0,0,0,0,0,0,0,0,0,0
0,0,0,0,0,0,0,0,0,0,0,0,0,0
endlayer

layer
0,0,0,0,0,0,0,0,0,0,0,0,0,0
0,0,0,0,0,0,0,0,0,0,0,0,0,0
0,0,0,0,0,0,0,0,0,0,0,0,0,0
0,0,0,0,0,0,0,0,0,0,0,0,0,0
0,0,0,0,0,2,2,2,2,2,0,0,0,0
0,0,0,0,2,2,2,2,2,2,2,0,0,0
0,0,0,0,2,2,2,2,2,2,2,0,0,0
0,0,0,0,2,2,2,3,2,2,2,0,0,0
0,0,0,0,2,2,2,2,2,2,2,0,0,0
0,0,0,0,2,2,2,2,2,2,2,0,0,0
0,0,0,0,0,2,2,2,2,2,0,0,0,0
0,0,0,0,0,0,0,0,0,0,0,0,0,0
0,0,0,0,0,0,0,0,0,0,0,0,0,0
0,0,0,0,0,0,0,0,0,0,0,0,0,0
0,0,0,0,0,0,0,0,0,0,0,0,0,0
endlayer

layer
0,0,0,0,0,0,0,0,0,0,0,0,0,0
0,0,0,0,0,0,0,0,0,0,0,0,0,0
0,0,0,0,0,0,0,0,0,0,0,0,0,0
0,0,0,0,0,0,0,0,0,0,0,0,0,0
0,0,0,0,0,2,2,2,2,2,0,0,0,0
0,0,0,0,2,2,2,2,2,2,2,0,0,0
0,0,0,0,2,2,2,2,2,2,2,0,0,0
0,0,0,0,2,2,2,0,2,2,2,0,0,0
0,0,0,0,2,2,2,2,2,2,2,0,0,0
0,0,0,0,2,2,2,2,2,2,2,0,0,0
0,0,0,0,0,2,2,2,2,2,0,0,0,0
0,0,0,0,0,0,0,0,0,0,0,0,0,0
0,0,0,0,0,0,0,0,0,0,0,0,0,0
0,0,0,0,0,0,0,0,0,0,0,0,0,0
0,0,0,0,0,0,0,0,0,0,0,0,0,0
endlayer

layer
0,0,0,0,0,0,0,0,0,0,0,0,0,0
0,0,0,0,0,0,0,0,0,0,0,0,0,0
0,0,0,0,0,0,0,0,0,0,0,0,0,0
0,0,0,0,0,0,0,0,0,0,0,0,0,0
0,0,0,0,0,2,4,4,4,2,0,0,0,0
0,0,0,0,2,2,2,2,2,2,2,0,0,0
0,0,0,0,4,2,2,2,2,2,4,0,0,0
0,0,0,0,4,2,2,2,2,2,4,0,0,0
0,0,0,0,4,2,2,2,2,2,4,0,0,0
0,0,0,0,2,2,2,2,2,2,2,0,0,0
0,0,0,0,0,2,4,4,4,2,0,0,0,0
0,0,0,0,0,0,0,0,0,0,0,0,0,0
0,0,0,0,0,0,0,0,0,0,0,0,0,0
0,0,0,0,0,0,0,0,0,0,0,0,0,0
0,0,0,0,0,0,0,0,0,0,0,0,0,0
endlayer

layer
0,0,0,0,0,0,0,0,0,0,0,0,0,0
0,0,0,0,0,0,0,0,0,0,0,0,0,0
0,0,0,0,0,0,0,0,0,0,0,0,0,0
0,0,0,0,0,0,0,0,0,0,0,0,0,0
0,0,0,0,0,4,4,2,4,4,0,0,0,0
0,0,0,0,4,2,2,2,2,2,4,0,0,0
0,0,0,0,4,2,2,2,2,2,4,0,0,0
0,0,0,0,2,2,2,2,2,2,2,0,0,0
0,0,0,0,4,2,2,2,2,2,4,0,0,0
0,0,0,0,4,2,2,2,2,2,4,0,0,0
0,0,0,0,0,4,4,2,4,4,0,0,0,0
0,0,0,0,0,0,0,0,0,0,0,0,0,0
0,0,0,0,0,0,0,0,0,0,0,0,0,0
0,0,0,0,0,0,0,0,0,0,0,0,0,0
0,0,0,0,0,0,0,0,0,0,0,0,0,0
endlayer

layer
0,0,0,0,0,0,0,0,0,0,0,0,0,0
0,0,0,0,0,0,0,0,0,0,0,0,0,0
0,0,0,0,0,0,0,0,0,0,0,0,0,0
0,0,0,0,0,0,0,1,0,0,0,0,0,0
0,0,0,0,0,2,2,2,2,2,0,0,0,0
0,0,0,0,2,2,0,0,0,2,2,0,0,0
0,0,0,0,2,0,2,0,2,0,2,0,0,0
0,0,0,1,2,0,0,5,0,0,2,1,0,0
0,0,0,0,2,0,2,0,2,0,2,0,0,0
0,0,0,0,2,2,0,0,0,2,2,0,0,0
0,0,0,0,0,2,2,2,2,2,0,0,0,0
0,0,0,0,0,0,0,1,0,0,0,0,0,0
0,0,0,0,0,0,0,0,0,0,0,0,0,0
0,0,0,0,0,0,0,0,0,0,0,0,0,0
0,0,0,0,0,0,0,0,0,0,0,0,0,0
endlayer

layer
0,0,0,0,0,0,0,0,0,0,0,0,0,0
0,0,0,0,0,1,0,6,0,1,0,0,0,0
0,0,0,0,0,0,6,2,6,0,0,0,0,0
0,0,0,0,0,0,8,5,7,0,0,0,0,0
0,0,0,0,0,2,2,2,2,2,0,0,0,0
0,1,0,0,2,2,0,0,0,2,2,0,0,1
0,0,8,6,2,0,0,9,0,0,2,6,7,0
0,8,2,5,2,0,11,2,10,0,2,5,2,7
0,0,8,12,2,0,0,13,0,0,2,12,7,0
0,1,0,0,2,2,0,0,0,2,2,0,0,1
0,0,0,0,0,2,2,2,2,2,0,0,0,0
0,0,0,0,0,0,8,5,7,0,0,0,0,0
0,0,0,0,0,0,12,2,12,0,0,0,0,0
0,0,0,0,0,1,0,12,0,1,0,0,0,0
0,0,0,0,0,0,0,0,0,0,0,0,0,0
endlayer

layer
0,0,0,0,1,2,4,4,4,2,1,0,0,0
0,0,1,2,2,14,2,4,2,14,2,2,1,0
0,1,14,2,2,2,2,2,2,2,2,2,14,1
0,2,2,2,2,2,2,2,2,2,2,2,2,2
1,2,2,2,2,2,2,2,2,2,2,2,2,2
2,14,2,2,2,2,0,0,0,2,2,2,2,14
4,2,2,2,2,0,0,0,0,0,2,2,2,2
4,4,2,2,2,0,0,15,0,0,2,2,2,4
4,2,2,2,2,0,0,0,0,0,2,2,2,2
2,14,2,2,2,2,0,0,0,2,2,2,2,14
1,2,2,2,2,2,2,2,2,2,2,2,2,2
0,2,2,2,2,2,2,2,2,2,2,2,2,2
0,1,14,2,2,2,2,2,2,2,2,2,14,1
0,0,1,2,2,14,2,4,2,14,2,2,1,0
0,0,0,0,1,2,4,4,4,2,1,0,0,0
endlayer

layer
0,0,0,0,0,0,0,0,0,0,0,0,0,0
0,0,0,0,0,16,0,0,0,16,0,0,0,0
0,0,16,0,0,0,0,0,0,0,0,0,16,0
0,0,0,0,0,0,0,0,0,0,0,0,0,0
0,0,0,0,0,2,14,9,14,2,0,0,0,0
0,16,0,0,2,3,2,2,2,3,2,0,0,16
0,0,0,0,14,2,17,17,17,2,14,0,0,0
0,0,0,0,11,2,17,17,17,2,10,0,0,0
0,0,0,0,14,2,17,17,17,2,14,0,0,0
0,16,0,0,2,3,2,2,2,3,2,0,0,16
0,0,0,0,0,2,14,13,14,2,0,0,0,0
0,0,0,0,0,0,0,0,0,0,0,0,0,0
0,0,16,0,0,0,0,0,0,0,0,0,16,0
0,0,0,0,0,16,0,0,0,16,0,0,0,0
0,0,0,0,0,0,0,0,0,0,0,0,0,0
endlayer

layer
0,0,0,0,0,0,0,0,0,0,0,0,0,0
0,0,0,0,0,0,0,0,0,0,0,0,0,0
0,0,0,0,0,0,0,0,0,0,0,0,0,0
0,0,0,0,0,0,0,0,0,0,0,0,0,0
0,0,0,0,0,2,14,0,14,2,0,0,0,0
0,0,0,0,2,2,13,0,13,2,2,0,0,0
0,0,0,0,14,10,0,0,0,11,14,0,0,0
0,0,0,0,0,0,0,0,0,0,0,0,0,0
0,0,0,0,14,10,0,0,0,11,14,0,0,0
0,0,0,0,2,2,9,0,9,2,2,0,0,0
0,0,0,0,0,2,14,0,14,2,0,0,0,0
0,0,0,0,0,0,0,0,0,0,0,0,0,0
0,0,0,0,0,0,0,0,0,0,0,0,0,0
0,0,0,0,0,0,0,0,0,0,0,0,0,0
0,0,0,0,0,0,0,0,0,0,0,0,0,0
endlayer

layer
0,0,0,0,0,0,0,0,0,0,0,0,0,0
0,0,0,0,0,0,0,0,0,0,0,0,0,0
0,0,0,0,0,0,0,0,0,0,0,0,0,0
0,0,0,0,0,0,0,0,0,0,0,0,0,0
0,0,0,0,0,2,10,0,11,2,0,0,0,0
0,0,0,0,2,2,12,0,12,2,2,0,0,0
0,0,0,0,13,7,0,0,0,8,13,0,0,0
0,0,0,0,0,0,0,0,0,0,0,0,0,0
0,0,0,0,9,7,0,0,0,8,9,0,0,0
0,0,0,0,2,2,6,0,6,2,2,0,0,0
0,0,0,0,0,2,10,0,11,2,0,0,0,0
0,0,0,0,0,0,0,0,0,0,0,0,0,0
0,0,0,0,0,0,0,0,0,0,0,0,0,0
0,0,0,0,0,0,0,0,0,0,0,0,0,0
0,0,0,0,0,0,0,0,0,0,0,0,0,0
endlayer

layer
0,0,0,0,0,0,0,0,0,0,0,0,0,0
0,0,0,0,0,0,0,0,0,0,0,0,0,0
0,0,0,0,0,0,0,0,0,0,0,0,0,0
0,0,0,0,0,0,0,0,0,0,0,0,0,0
0,0,0,0,0,2,7,0,8,2,0,0,0,0
0,0,0,0,2,2,7,0,8,2,2,0,0,0
0,0,0,0,12,12,0,0,0,12,12,0,0,0
0,0,0,0,0,0,0,0,0,0,0,0,0,0
0,0,0,0,6,6,0,0,0,6,6,0,0,0
0,0,0,0,2,2,7,0,8,2,2,0,0,0
0,0,0,0,0,2,7,0,8,2,0,0,0,0
0,0,0,0,0,0,0,0,0,0,0,0,0,0
0,0,0,0,0,0,0,0,0,0,0,0,0,0
0,0,0,0,0,0,0,0,0,0,0,0,0,0
0,0,0,0,0,0,0,0,0,0,0,0,0,0
endlayer

layer
0,0,0,0,0,0,0,0,0,0,0,0,0,0
0,0,0,0,0,0,0,0,0,0,0,0,0,0
0,0,0,0,0,0,0,0,0,0,0,0,0,0
0,0,0,0,0,0,0,0,0,0,0,0,0,0
0,0,0,0,0,4,4,0,4,4,0,0,0,0
0,0,0,0,4,2,2,2,2,2,4,0,0,0
0,0,0,0,4,2,0,0,0,2,4,0,0,0
0,0,0,0,0,2,0,0,0,2,0,0,0,0
0,0,0,0,4,2,0,0,0,2,4,0,0,0
0,0,0,0,4,2,2,2,2,2,4,0,0,0
0,0,0,0,0,4,4,0,4,4,0,0,0,0
0,0,0,0,0,0,0,0,0,0,0,0,0,0
0,0,0,0,0,0,0,0,0,0,0,0,0,0
0,0,0,0,0,0,0,0,0,0,0,0,0,0
0,0,0,0,0,0,0,0,0,0,0,0,0,0
endlayer

layer
0,0,0,0,0,0,0,0,0,0,0,0,0,0
0,0,0,0,0,0,0,0,0,0,0,0,0,0
0,0,0,0,0,0,0,0,0,0,0,0,0,0
0,0,0,0,0,0,0,0,0,0,0,0,0,0
0,0,0,0,0,2,10,0,11,2,0,0,0,0
0,0,0,0,2,2,2,2,2,2,2,0,0,0
0,0,0,0,13,2,1,0,1,2,13,0,0,0
0,0,0,0,0,2,0,0,0,2,0,0,0,0
0,0,0,0,9,2,1,0,1,2,9,0,0,0
0,0,0,0,2,2,2,2,2,2,2,0,0,0
0,0,0,0,0,2,10,0,11,2,0,0,0,0
0,0,0,0,0,0,0,0,0,0,0,0,0,0
0,0,0,0,0,0,0,0,0,0,0,0,0,0
0,0,0,0,0,0,0,0,0,0,0,0,0,0
0,0,0,0,0,0,0,0,0,0,0,0,0,0
endlayer

layer
0,0,0,0,0,0,0,0,0,0,0,0,0,0
0,0,0,0,0,0,0,0,0,0,0,0,0,0
0,0,0,0,0,0,0,0,0,0,0,0,0,0
0,0,0,0,0,0,0,0,0,0,0,0,0,0
0,0,0,0,0,2,7,0,8,2,0,0,0,0
0,0,0,0,2,2,2,2,2,2,2,0,0,0
0,0,0,0,12,2,2,12,2,2,12,0,0,0
0,0,0,0,0,2,7,0,8,2,0,0,0,0
0,0,0,0,6,2,2,6,2,2,6,0,0,0
0,0,0,0,2,2,2,2,2,2,2,0,0,0
0,0,0,0,0,2,7,0,8,2,0,0,0,0
0,0,0,0,0,0,0,0,0,0,0,0,0,0
0,0,0,0,0,0,0,0,0,0,0,0,0,0
0,0,0,0,0,0,0,0,0,0,0,0,0,0
0,0,0,0,0,0,0,0,0,0,0,0,0,0
endlayer

layer
0,0,0,0,0,0,0,0,0,0,0,0,0,0
0,0,0,0,0,0,0,0,0,0,0,0,0,0
0,0,0,0,0,0,0,0,0,0,0,0,0,0
0,0,0,0,0,0,0,0,0,0,0,0,0,0
0,0,0,0,0,2,2,0,2,2,0,0,0,0
0,0,0,0,2,2,2,2,2,2,2,0,0,0
0,0,0,0,2,2,2,2,2,2,2,0,0,0
0,0,0,0,0,2,2,18,2,2,0,0,0,0
0,0,0,0,2,2,2,2,2,2,2,0,0,0
0,0,0,0,2,2,2,2,2,2,2,0,0,0
0,0,0,0,0,2,2,0,2,2,0,0,0,0
0,0,0,0,0,0,0,0,0,0,0,0,0,0
0,0,0,0,0,0,0,0,0,0,0,0,0,0
0,0,0,0,0,0,0,0,0,0,0,0,0,0
0,0,0,0,0,0,0,0,0,0,0,0,0,0
endlayer

layer
0,0,0,0,0,0,0,0,0,0,0,0,0,0
0,0,0,0,0,0,0,0,0,0,0,0,0,0
0,0,0,0,0,0,0,0,0,0,0,0,0,0
0,0,0,0,0,0,0,0,0,0,0,0,0,0
0,0,0,0,0,2,10,0,11,2,0,0,0,0
0,0,0,0,2,2,2,2,2,2,2,0,0,0
0,0,0,0,13,2,2,2,2,2,13,0,0,0
0,0,0,0,0,2,2,2,2,2,0,0,0,0
0,0,0,0,9,2,2,2,2,2,9,0,0,0
0,0,0,0,2,2,2,2,2,2,2,0,0,0
0,0,0,0,0,2,10,0,11,2,0,0,0,0
0,0,0,0,0,0,0,0,0,0,0,0,0,0
0,0,0,0,0,0,0,0,0,0,0,0,0,0
0,0,0,0,0,0,0,0,0,0,0,0,0,0
0,0,0,0,0,0,0,0,0,0,0,0,0,0
endlayer

layer
0,0,0,0,0,0,0,0,0,0,0,0,0,0
0,0,0,0,0,0,0,0,0,0,0,0,0,0
0,0,0,0,0,0,0,0,0,0,0,0,0,0
0,0,0,0,0,0,0,0,0,0,0,0,0,0
0,0,0,0,0,2,7,0,8,2,0,0,0,0
0,0,0,0,2,2,2,2,2,2,2,0,0,0
0,0,0,0,12,2,2,2,2,2,12,0,0,0
0,0,0,0,0,2,2,2,2,2,0,0,0,0
0,0,0,0,6,2,2,2,2,2,6,0,0,0
0,0,0,0,2,2,2,2,2,2,2,0,0,0
0,0,0,0,0,2,7,0,8,2,0,0,0,0
0,0,0,0,0,0,0,0,0,0,0,0,0,0
0,0,0,0,0,0,0,0,0,0,0,0,0,0
0,0,0,0,0,0,0,0,0,0,0,0,0,0
0,0,0,0,0,0,0,0,0,0,0,0,0,0
endlayer

layer
0,0,0,0,0,0,0,0,0,0,0,0,0,0
0,0,0,0,0,0,0,0,0,0,0,0,0,0
0,0,0,0,0,0,0,0,0,0,0,0,0,0
0,0,0,0,0,8,6,0,6,7,0,0,0,0
0,0,0,0,0,4,14,2,14,4,0,0,0,0
0,0,0,6,4,2,2,2,2,2,4,6,0,0
0,0,0,8,14,2,2,2,2,2,14,7,0,0
0,0,0,0,2,2,2,2,2,2,2,0,0,0
0,0,0,8,14,2,2,2,2,2,14,7,0,0
0,0,0,12,4,2,2,2,2,2,4,12,0,0
0,0,0,0,0,4,14,2,14,4,0,0,0,0
0,0,0,0,0,8,12,0,12,7,0,0,0,0
0,0,0,0,0,0,0,0,0,0,0,0,0,0
0,0,0,0,0,0,0,0,0,0,0,0,0,0
0,0,0,0,0,0,0,0,0,0,0,0,0,0
endlayer

layer
0,0,0,0,0,0,0,0,0,0,0,0,0,0
0,0,0,0,0,0,0,0,0,0,0,0,0,0
0,0,0,0,0,0,0,0,0,0,0,0,0,0
0,0,0,0,0,0,0,0,0,0,0,0,0,0
0,0,0,0,0,2,16,0,16,2,0,0,0,0
0,0,0,0,2,2,2,2,2,2,2,0,0,0
0,0,0,0,16,2,2,2,2,2,16,0,0,0
0,0,0,0,0,2,2,2,2,2,0,0,0,0
0,0,0,0,16,2,2,2,2,2,16,0,0,0
0,0,0,0,2,2,2,2,2,2,2,0,0,0
0,0,0,0,0,2,16,0,16,2,0,0,0,0
0,0,0,0,0,0,0,0,0,0,0,0,0,0
0,0,0,0,0,0,0,0,0,0,0,0,0,0
0,0,0,0,0,0,0,0,0,0,0,0,0,0
0,0,0,0,0,0,0,0,0,0,0,0,0,0
endlayer

layer
0,0,0,0,0,0,0,0,0,0,0,0,0,0
0,0,0,0,0,0,0,0,0,0,0,0,0,0
0,0,0,0,0,0,0,0,0,0,0,0,0,0
0,0,0,0,0,0,0,0,0,0,0,0,0,0
0,0,0,0,0,2,0,0,0,2,0,0,0,0
0,0,0,0,2,2,2,2,2,2,2,0,0,0
0,0,0,0,0,2,2,2,2,2,0,0,0,0
0,0,0,0,0,2,2,2,2,2,0,0,0,0
0,0,0,0,0,2,2,2,2,2,0,0,0,0
0,0,0,0,2,2,2,2,2,2,2,0,0,0
0,0,0,0,0,2,0,0,0,2,0,0,0,0
0,0,0,0,0,0,0,0,0,0,0,0,0,0
0,0,0,0,0,0,0,0,0,0,0,0,0,0
0,0,0,0,0,0,0,0,0,0,0,0,0,0
0,0,0,0,0,0,0,0,0,0,0,0,0,0
endlayer

layer
0,0,0,0,0,0,0,0,0,0,0,0,0,0
0,0,0,0,0,0,0,0,0,0,0,0,0,0
0,0,0,0,0,0,0,0,0,0,0,0,0,0
0,0,0,0,0,0,0,0,0,0,0,0,0,0
0,0,0,0,0,2,2,0,2,2,0,0,0,0
0,0,0,0,2,2,2,2,2,2,2,0,0,0
0,0,0,0,2,2,2,2,2,2,2,0,0,0
0,0,0,0,0,2,2,2,2,2,0,0,0,0
0,0,0,0,2,2,2,2,2,2,2,0,0,0
0,0,0,0,2,2,2,2,2,2,2,0,0,0
0,0,0,0,0,2,2,0,2,2,0,0,0,0
0,0,0,0,0,0,0,0,0,0,0,0,0,0
0,0,0,0,0,0,0,0,0,0,0,0,0,0
0,0,0,0,0,0,0,0,0,0,0,0,0,0
0,0,0,0,0,0,0,0,0,0,0,0,0,0
endlayer

layer
0,0,0,0,0,0,0,0,0,0,0,0,0,0
0,0,0,0,0,0,0,0,0,0,0,0,0,0
0,0,0,0,0,0,0,0,0,0,0,0,0,0
0,0,0,0,0,0,0,0,0,0,0,0,0,0
0,0,0,0,0,2,10,0,11,2,0,0,0,0
0,0,0,0,2,2,2,2,2,2,2,0,0,0
0,0,0,0,13,2,2,2,2,2,13,0,0,0
0,0,0,0,0,2,2,2,2,2,0,0,0,0
0,0,0,0,9,2,2,2,2,2,9,0,0,0
0,0,0,0,2,2,2,2,2,2,2,0,0,0
0,0,0,0,0,2,10,0,11,2,0,0,0,0
0,0,0,0,0,0,0,0,0,0,0,0,0,0
0,0,0,0,0,0,0,0,0,0,0,0,0,0
0,0,0,0,0,0,0,0,0,0,0,0,0,0
0,0,0,0,0,0,0,0,0,0,0,0,0,0
endlayer

layer
0,0,0,0,0,0,0,0,0,0,0,0,0,0
0,0,0,0,0,0,0,0,0,0,0,0,0,0
0,0,0,0,0,0,0,0,0,0,0,0,0,0
0,0,0,0,0,0,0,0,0,0,0,0,0,0
0,0,0,0,0,2,7,0,8,2,0,0,0,0
0,0,0,0,2,2,2,2,2,2,2,0,0,0
0,0,0,0,12,2,2,2,2,2,12,0,0,0
0,0,0,0,0,2,2,2,2,2,0,0,0,0
0,0,0,0,6,2,2,2,2,2,6,0,0,0
0,0,0,0,2,2,2,2,2,2,2,0,0,0
0,0,0,0,0,2,7,0,8,2,0,0,0,0
0,0,0,0,0,0,0,0,0,0,0,0,0,0
0,0,0,0,0,0,0,0,0,0,0,0,0,0
0,0,0,0,0,0,0,0,0,0,0,0,0,0
0,0,0,0,0,0,0,0,0,0,0,0,0,0
endlayer

layer
0,0,0,0,0,0,0,0,0,0,0,0,0,0
0,0,0,0,0,0,0,0,0,0,0,0,0,0
0,0,0,0,0,0,0,0,0,0,0,0,0,0
0,0,0,0,0,0,0,0,0,0,0,0,0,0
0,0,0,0,0,15,14,6,14,15,0,0,0,0
0,0,0,0,15,2,15,2,15,2,15,0,0,0
0,0,0,0,14,15,15,0,15,15,14,0,0,0
0,0,0,0,8,2,0,0,0,2,7,0,0,0
0,0,0,0,14,15,15,0,15,15,14,0,0,0
0,0,0,0,15,2,15,2,15,2,15,0,0,0
0,0,0,0,0,15,14,12,14,15,0,0,0,0
0,0,0,0,0,0,0,0,0,0,0,0,0,0
0,0,0,0,0,0,0,0,0,0,0,0,0,0
0,0,0,0,0,0,0,0,0,0,0,0,0,0
0,0,0,0,0,0,0,0,0,0,0,0,0,0
endlayer

layer
0,0,0,0,0,0,0,0,0,0,0,0,0,0
0,0,0,0,0,0,0,0,0,0,0,0,0,0
0,0,0,0,0,0,0,0,0,0,0,0,0,0
0,0,0,0,0,0,0,0,0,0,0,0,0,0
0,0,0,0,0,0,16,0,16,0,0,0,0,0
0,0,0,0,0,0,0,0,0,0,0,0,0,0
0,0,0,0,16,0,0,0,0,0,16,0,0,0
0,0,0,0,0,0,0,0,0,0,0,0,0,0
0,0,0,0,16,0,0,0,0,0,16,0,0,0
0,0,0,0,0,0,0,0,0,0,0,0,0,0
0,0,0,0,0,0,16,0,16,0,0,0,0,0
0,0,0,0,0,0,0,0,0,0,0,0,0,0
0,0,0,0,0,0,0,0,0,0,0,0,0,0
0,0,0,0,0,0,0,0,0,0,0,0,0,0
0,0,0,0,0,0,0,0,0,0,0,0,0,0
endlayer

