
# Created by Ruins mod version 17.2 Ingame Parser
# authoring Player: BARTLLOW

# TEMPLATE PARAMETER SETTINGS:
#
# criterion expression specifying mod ids required to load template
# may include plus (AND), minus (AND NOT), comma (OR), and parentheses
# all required mods listed must be present; no prohibited mods can be
requiredMods=
#
# likelihood this template will be chosen relative to all others
# e.g., a weight=6 template is chosen 3X as often as one with weight=2
weight=1
#
# list of dimensions in which this template may spawn, even if generic
# one or more dimension names, separated by commas (blank = all)
dimensionsToSpawnIn=
#
# list of other biomes in which this template may spawn
# biome corresponding to directory is always assumed, listed or not
# generic templates should leave this list empty
biomesToSpawnIn=
#
# criterion expression specifying types of biome where template spawns
# this is in addition to those explicitly listed as biomesToSpawnIn
# generic templates should leave this list empty
biomeTypesToSpawnIn=
#
# list of biomes in which this template may not spawn
# takes precedence over biomeTypesToSpawnIn, but NOT biomesToSpawnIn
# should be empty if biomeTypesToSpawnIn is empty
biomesToNotSpawnIn=
#
# depth template is pushed down into the surface when built
# offset is min/max range of random additional bury depth
embed_into_distance=0
random_height_offset=0,0
#
# whitelist/blacklist of block types on which template may be built
# specify one, not both; leave the other empty (both empty = allow all)
acceptable_target_blocks=
unacceptable_target_blocks=flowing_water,water,flowing_lava,lava
#
# size of template (#layers, #rows per layer, #blocks per row)
dimensions=28,13,13
#
# max number of missing blocks allowed in surface beneath template
allowable_overhang=0
#
# depth/height limit affected by terrain leveling
# also maximum bumpiness tolerated in surface beneath template
max_leveling=2
#
# padding applied to all sides of template horizontal footprint
# expands area affected by terrain leveling (-1 = no leveling)
leveling_buffer=0
#
# do not rotate template randomly when built (1 = no rotation)
preventRotation=0
#
# treat water/lava blocks as air and protect them from rule0 (1 = yes)
preserve_water=0
preserve_lava=0
#
# minimum distance this template must have from instances of itself
uniqueMinDistance=0
#
# min/max distances this template can be from world spawn (0 = no limit)
# only applies to overworld--i.e., dimension 0
spawnMinDistance=0
spawnMaxDistance=0
#
# other template built nearby whenever this one is
# syntax: <name>;<relativeX>;<maxYdifference>;<relativeZ>[;<chance>]
# may be used more than once to specify multiple neighbors
adjoining_template=

rule1=0,100,minecraft:grass-0
rule2=0,100,minecraft:dirt-0
rule3=0,100,minecraft:piston-1
rule4=0,100,minecraft:cobblestone-0
rule5=0,100,minecraft:planks-0
rule6=0,100,minecraft:furnace-5
rule7=2,100,WallSign:null:null:null:null-4
rule8=0,100,minecraft:oak_stairs-3
rule9=0,100,minecraft:oak_stairs-2
rule10=0,100,minecraft:crafting_table-0
rule11=0,100,minecraft:wooden_door-1
rule12=2,100,WallSign:null:null:null:null-5
rule13=0,100,minecraft:ladder-2
rule14=0,100,minecraft:furnace-4
rule15=0,100,minecraft:stonebrick-1
rule16=0,100,minecraft:stonebrick-2
rule17=0,100,minecraft:wooden_door-9
rule18=0,100,minecraft:wooden_slab-0
rule19=0,100,minecraft:stonebrick-0
rule20=0,100,minecraft:oak_stairs-1
rule21=0,100,minecraft:oak_stairs-0
rule22=2,100,minecraft:torch-3
rule23=2,100,minecraft:torch-4
rule24=2,100,minecraft:torch-1
rule25=2,100,minecraft:torch-2
rule26=0,100,minecraft:stone_stairs-0
rule27=0,100,minecraft:stone_stairs-2
rule28=0,100,minecraft:stone_stairs-3
rule29=0,100,minecraft:stone_stairs-1
rule30=0,100,minecraft:stone_slab-3
rule31=0,100,minecraft:fence-0
rule32=0,100,minecraft:log-1
rule33=0,100,minecraft:log-0
rule34=0,100,minecraft:bookshelf-0
rule35=2,100,WallSign:null:null:null:null-2
rule36=2,100,WallSign:null:null:null:null-3
rule37=0,100,minecraft:bed-10
rule38=0,100,minecraft:bed-2
rule39=0,100,IInventory;minecraft:chest;minecraft:bow#1#0#0+minecraft:wooden_sword#1#0#1+minecraft:arrow#40#0#2+minecraft:wooden_sword#1#0#5+minecraft:arrow#27#0#8+minecraft:clock#1#0#14+minecraft:iron_axe#1#0#18+minecraft:bow#1#0#19+minecraft:bow#1#0#22+minecraft:arrow#7#0#25+minecraft:leather_helmet#1#0#26-3
rule40=0,100,IInventory;minecraft:chest;minecraft:bow#1#0#2+minecraft:leather_boots#1#0#21-3
rule41=0,100,minecraft:redstone_lamp-0
rule42=0,100,minecraft:redstone_block-0

layer
1,1,1,1,2,1,1,1,2,1,1,1,1
1,1,1,2,2,2,1,2,1,2,1,1,1
1,1,1,2,1,2,2,2,2,2,1,1,1
1,2,2,2,1,1,1,1,1,2,2,2,1
2,2,2,1,1,1,1,3,3,1,2,2,2
1,2,2,1,1,1,1,3,3,1,1,2,1
1,2,2,1,2,1,1,1,1,1,1,1,1
1,2,2,1,1,1,1,1,1,1,1,2,1
2,1,2,1,1,1,1,1,1,1,2,1,1
1,2,2,2,1,1,1,1,1,2,1,1,1
1,1,1,1,2,2,2,2,2,2,1,1,1
1,1,1,2,2,2,2,1,2,2,1,1,1
1,1,1,1,2,1,1,1,2,1,1,1,1
endlayer

layer
0,0,0,0,4,0,0,0,4,0,0,0,0
0,0,0,4,4,4,4,4,4,4,0,0,0
0,0,0,4,5,6,6,6,5,4,0,0,0
0,4,4,5,0,0,7,0,0,5,4,4,0
4,4,5,0,0,0,9,0,0,8,5,4,4
0,4,10,0,0,0,9,0,0,8,0,4,0
0,4,10,0,4,13,12,0,0,12,0,11,0
0,4,10,0,0,0,0,0,0,0,0,4,0
4,4,5,0,0,0,0,0,0,0,5,4,4
0,4,4,5,0,0,0,0,0,5,4,4,0
0,0,0,4,5,14,14,14,5,4,0,0,0
0,0,0,4,4,4,4,4,4,4,0,0,0
0,0,0,0,4,0,0,0,4,0,0,0,0
endlayer

layer
0,0,0,0,4,0,0,0,4,0,0,0,0
0,0,0,4,16,15,16,15,15,4,0,0,0
0,0,0,15,5,0,0,0,5,15,0,0,0
0,4,15,5,0,0,0,0,0,5,15,4,0
4,16,5,0,0,0,0,0,0,0,5,4,4
0,15,0,0,0,0,0,0,0,0,0,4,0
0,16,0,0,4,13,0,0,0,0,0,17,0
0,15,0,0,0,0,0,0,0,0,0,16,0
4,15,5,0,0,0,0,0,0,0,5,16,4
0,4,16,5,0,0,0,0,0,5,16,4,0
0,0,0,15,5,0,0,0,5,16,0,0,0
0,0,0,4,16,16,15,15,15,4,0,0,0
0,0,0,0,4,0,0,0,4,0,0,0,0
endlayer

layer
0,0,0,0,4,0,0,0,4,0,0,0,0
0,0,0,4,19,9,18,8,16,4,0,0,0
0,0,0,18,5,0,0,0,5,18,0,0,0
0,4,18,5,0,0,0,0,0,5,18,4,0
4,16,5,0,0,0,0,0,0,0,5,16,4
0,20,0,0,0,0,0,0,0,0,0,20,0
0,18,0,0,4,13,0,0,0,0,0,18,0
0,21,0,0,0,0,0,0,0,0,0,21,0
4,16,5,0,0,0,0,0,0,0,5,16,4
0,4,18,5,0,0,0,0,0,5,18,4,0
0,0,0,18,5,0,0,0,5,18,0,0,0
0,0,0,4,16,9,18,8,16,4,0,0,0
0,0,0,0,4,0,0,0,4,0,0,0,0
endlayer

layer
0,0,0,0,4,0,0,0,4,0,0,0,0
0,0,0,4,16,9,18,8,16,4,0,0,0
0,0,0,18,5,0,0,0,5,18,0,0,0
0,4,18,5,0,0,0,0,0,5,18,4,0
4,16,5,0,0,0,0,0,0,0,5,16,4
0,20,0,0,0,0,0,0,0,0,0,20,0
0,18,0,0,4,13,0,0,0,0,0,18,0
0,21,0,0,0,0,0,0,0,0,0,21,0
4,16,5,0,0,0,0,0,0,0,5,16,4
0,4,18,5,0,0,0,0,0,5,18,4,0
0,0,0,18,5,0,0,0,5,18,0,0,0
0,0,0,4,16,9,18,8,16,4,0,0,0
0,0,0,0,4,0,0,0,4,0,0,0,0
endlayer

layer
0,0,0,0,4,0,0,0,4,0,0,0,0
0,0,0,4,16,9,18,8,16,4,0,0,0
0,0,0,18,5,0,0,0,5,18,0,0,0
0,4,18,5,0,0,0,0,0,5,18,4,0
4,16,5,0,0,0,0,0,0,0,5,16,4
0,20,0,0,0,0,0,0,0,0,0,20,0
0,18,0,0,4,13,0,0,0,0,0,18,0
0,21,0,0,0,0,0,0,0,0,0,21,0
4,16,5,0,0,0,0,0,0,0,5,16,4
0,4,18,5,0,0,0,0,0,5,18,4,0
0,0,0,18,5,0,0,0,5,18,0,0,0
0,0,0,4,16,9,18,8,16,4,0,0,0
0,0,0,0,4,0,0,0,4,0,0,0,0
endlayer

layer
0,0,0,0,4,0,0,0,4,0,0,0,0
0,0,0,4,16,9,18,8,16,4,0,0,0
0,0,0,18,5,23,0,22,5,18,0,0,0
0,4,18,5,0,0,0,0,0,5,18,4,0
4,16,5,0,0,0,0,0,0,0,5,16,4
0,20,24,0,0,0,0,0,0,0,24,20,0
0,18,0,0,4,13,0,0,0,0,0,18,0
0,21,25,0,0,0,0,0,0,0,25,21,0
4,16,5,0,0,0,0,0,0,0,5,16,4
0,4,18,5,0,0,0,0,0,5,18,4,0
0,0,0,18,5,23,0,22,5,18,0,0,0
0,0,0,4,16,9,18,8,16,4,0,0,0
0,0,0,0,4,0,0,0,4,0,0,0,0
endlayer

layer
0,0,0,0,26,0,0,0,26,0,0,0,0
0,0,0,28,16,9,18,8,16,27,0,0,0
0,0,0,18,5,5,5,5,5,18,0,0,0
0,26,18,5,5,5,5,5,5,5,18,26,0
28,16,5,5,5,5,5,5,5,5,5,16,27
0,20,5,5,5,5,5,5,5,5,5,20,0
0,18,5,5,4,13,5,5,5,5,5,18,0
0,21,5,5,5,5,5,5,5,5,5,21,0
28,16,5,5,5,5,5,5,5,5,5,16,27
0,29,18,5,5,5,5,5,5,5,18,29,0
0,0,0,18,5,5,5,5,5,18,0,0,0
0,0,0,28,16,9,18,8,16,27,0,0,0
0,0,0,0,29,0,0,0,29,0,0,0,0
endlayer

layer
0,0,0,0,0,0,0,0,0,0,0,0,0
0,0,0,0,30,0,0,0,30,0,0,0,0
0,0,0,0,31,31,31,31,31,0,0,0,0
0,0,0,31,31,32,4,32,31,31,0,0,0
0,30,31,31,33,34,34,34,33,31,31,30,0
0,0,31,32,0,0,0,0,10,32,31,0,0
0,0,31,4,4,13,0,0,10,4,31,0,0
0,0,31,32,0,0,0,0,10,32,31,0,0
0,30,31,31,33,36,21,35,33,31,31,30,0
0,0,0,31,31,32,4,32,31,31,0,0,0
0,0,0,0,31,31,31,31,31,0,0,0,0
0,0,0,0,30,0,0,0,30,0,0,0,0
0,0,0,0,0,0,0,0,0,0,0,0,0
endlayer

layer
0,0,0,0,0,0,0,0,0,0,0,0,0
0,0,0,0,0,0,0,0,0,0,0,0,0
0,0,0,0,0,0,0,0,0,0,0,0,0
0,0,0,0,31,32,4,32,31,0,0,0,0
0,0,0,31,33,0,0,0,33,31,0,0,0
0,0,0,32,0,0,0,0,0,32,0,0,0
0,0,0,4,4,13,0,0,0,4,0,0,0
0,0,0,32,0,0,0,0,0,32,0,0,0
0,0,0,31,33,0,0,0,33,31,0,0,0
0,0,0,0,31,32,4,32,31,0,0,0,0
0,0,0,0,0,0,0,0,0,0,0,0,0
0,0,0,0,0,0,0,0,0,0,0,0,0
0,0,0,0,0,0,0,0,0,0,0,0,0
endlayer

layer
0,0,0,0,0,0,0,0,0,0,0,0,0
0,0,0,0,0,0,0,0,0,0,0,0,0
0,0,0,0,0,0,0,0,0,0,0,0,0
0,0,0,0,31,32,31,32,31,0,0,0,0
0,0,0,31,33,0,0,0,33,31,0,0,0
0,0,0,32,0,0,0,0,0,32,0,0,0
0,0,0,31,4,13,0,0,0,31,0,0,0
0,0,0,32,0,0,0,0,0,32,0,0,0
0,0,0,31,33,0,0,0,33,31,0,0,0
0,0,0,0,31,32,31,32,31,0,0,0,0
0,0,0,0,0,0,0,0,0,0,0,0,0
0,0,0,0,0,0,0,0,0,0,0,0,0
0,0,0,0,0,0,0,0,0,0,0,0,0
endlayer

layer
0,0,0,0,0,0,0,0,0,0,0,0,0
0,0,0,0,0,0,0,0,0,0,0,0,0
0,0,0,0,0,0,0,0,0,0,0,0,0
0,0,0,0,31,32,4,32,31,0,0,0,0
0,0,0,31,33,0,24,0,33,31,0,0,0
0,0,0,32,0,0,0,0,0,32,0,0,0
0,0,0,4,4,13,0,0,22,4,0,0,0
0,0,0,32,0,0,0,0,0,32,0,0,0
0,0,0,31,33,0,25,0,33,31,0,0,0
0,0,0,0,31,32,4,32,31,0,0,0,0
0,0,0,0,0,0,0,0,0,0,0,0,0
0,0,0,0,0,0,0,0,0,0,0,0,0
0,0,0,0,0,0,0,0,0,0,0,0,0
endlayer

layer
0,0,0,0,0,0,0,0,0,0,0,0,0
0,0,0,0,0,0,0,0,0,0,0,0,0
0,0,0,0,0,0,0,0,0,0,0,0,0
0,0,0,0,31,32,4,32,31,0,0,0,0
0,0,0,31,33,0,0,0,33,31,0,0,0
0,0,0,32,0,0,0,0,0,32,0,0,0
0,0,0,4,4,13,0,0,0,4,0,0,0
0,0,0,32,0,0,0,0,0,32,0,0,0
0,0,0,31,33,0,0,0,33,31,0,0,0
0,0,0,0,31,32,4,32,31,0,0,0,0
0,0,0,0,0,0,0,0,0,0,0,0,0
0,0,0,0,0,0,0,0,0,0,0,0,0
0,0,0,0,0,0,0,0,0,0,0,0,0
endlayer

layer
0,0,0,0,0,0,0,0,0,0,0,0,0
0,0,0,0,0,0,0,0,0,0,0,0,0
0,0,0,0,0,0,0,0,0,0,0,0,0
0,0,0,0,31,21,21,21,31,0,0,0,0
0,0,0,31,5,33,32,33,5,31,0,0,0
0,0,0,8,33,5,5,5,33,9,0,0,0
0,0,0,8,32,13,5,5,32,9,0,0,0
0,0,0,8,33,5,5,5,33,9,0,0,0
0,0,0,31,5,33,32,33,5,31,0,0,0
0,0,0,0,31,20,20,20,31,0,0,0,0
0,0,0,0,0,0,0,0,0,0,0,0,0
0,0,0,0,0,0,0,0,0,0,0,0,0
0,0,0,0,0,0,0,0,0,0,0,0,0
endlayer

layer
0,0,0,0,0,0,0,0,0,0,0,0,0
0,0,0,0,0,0,0,0,0,0,0,0,0
0,0,0,0,0,0,0,0,0,0,0,0,0
0,0,0,0,31,0,0,0,31,0,0,0,0
0,0,0,31,31,33,32,33,31,31,0,0,0
0,0,0,0,33,0,38,37,33,0,0,0,0
0,0,0,0,32,13,0,0,32,0,0,0,0
0,0,0,0,33,0,38,37,33,0,0,0,0
0,0,0,31,31,33,32,33,31,31,0,0,0
0,0,0,0,31,0,0,0,31,0,0,0,0
0,0,0,0,0,0,0,0,0,0,0,0,0
0,0,0,0,0,0,0,0,0,0,0,0,0
0,0,0,0,0,0,0,0,0,0,0,0,0
endlayer

layer
0,0,0,0,0,0,0,0,0,0,0,0,0
0,0,0,0,0,0,0,0,0,0,0,0,0
0,0,0,0,0,0,0,0,0,0,0,0,0
0,0,0,0,31,0,0,0,31,0,0,0,0
0,0,0,31,31,33,31,33,31,31,0,0,0
0,0,0,0,33,0,0,0,33,0,0,0,0
0,0,0,0,32,13,0,0,31,0,0,0,0
0,0,0,0,33,0,0,0,33,0,0,0,0
0,0,0,31,31,33,31,33,31,31,0,0,0
0,0,0,0,31,0,0,0,31,0,0,0,0
0,0,0,0,0,0,0,0,0,0,0,0,0
0,0,0,0,0,0,0,0,0,0,0,0,0
0,0,0,0,0,0,0,0,0,0,0,0,0
endlayer

layer
0,0,0,0,0,0,0,0,0,0,0,0,0
0,0,0,0,0,0,0,0,0,0,0,0,0
0,0,0,0,0,0,0,0,0,0,0,0,0
0,0,0,0,31,0,0,0,31,0,0,0,0
0,0,0,31,31,33,32,33,31,31,0,0,0
0,0,0,0,33,0,0,0,33,0,0,0,0
0,0,0,0,32,13,0,22,32,0,0,0,0
0,0,0,0,33,0,0,0,33,0,0,0,0
0,0,0,31,31,33,32,33,31,31,0,0,0
0,0,0,0,31,0,0,0,31,0,0,0,0
0,0,0,0,0,0,0,0,0,0,0,0,0
0,0,0,0,0,0,0,0,0,0,0,0,0
0,0,0,0,0,0,0,0,0,0,0,0,0
endlayer

layer
0,0,0,0,0,0,0,0,0,0,0,0,0
0,0,0,0,0,0,0,0,0,0,0,0,0
0,0,0,0,0,0,0,0,0,0,0,0,0
0,0,0,0,31,0,0,0,31,0,0,0,0
0,0,0,31,31,33,31,33,31,31,0,0,0
0,0,0,0,33,0,0,0,33,0,0,0,0
0,0,0,0,32,13,0,0,31,0,0,0,0
0,0,0,0,33,0,0,0,33,0,0,0,0
0,0,0,31,31,33,31,33,31,31,0,0,0
0,0,0,0,31,0,0,0,31,0,0,0,0
0,0,0,0,0,0,0,0,0,0,0,0,0
0,0,0,0,0,0,0,0,0,0,0,0,0
0,0,0,0,0,0,0,0,0,0,0,0,0
endlayer

layer
0,0,0,0,0,0,0,0,0,0,0,0,0
0,0,0,0,0,0,0,0,0,0,0,0,0
0,0,0,0,0,0,0,0,0,0,0,0,0
0,0,0,0,31,0,0,0,31,0,0,0,0
0,0,0,31,31,33,32,33,31,31,0,0,0
0,0,0,0,33,0,0,0,33,0,0,0,0
0,0,0,0,32,13,0,22,32,0,0,0,0
0,0,0,0,33,0,0,0,33,0,0,0,0
0,0,0,31,31,33,32,33,31,31,0,0,0
0,0,0,0,31,0,0,0,31,0,0,0,0
0,0,0,0,0,0,0,0,0,0,0,0,0
0,0,0,0,0,0,0,0,0,0,0,0,0
0,0,0,0,0,0,0,0,0,0,0,0,0
endlayer

layer
0,0,0,0,0,0,0,0,0,0,0,0,0
0,0,0,0,0,0,0,0,0,0,0,0,0
0,0,0,0,0,5,5,5,0,0,0,0,0
0,0,0,0,5,5,5,5,5,0,0,0,0
0,0,0,5,5,5,5,5,5,5,0,0,0
0,0,5,5,5,5,5,5,5,5,5,0,0
0,0,5,5,5,13,5,5,5,5,5,0,0
0,0,5,5,5,5,5,5,5,5,5,0,0
0,0,0,5,5,5,5,5,5,5,0,0,0
0,0,0,0,5,5,5,5,5,0,0,0,0
0,0,0,0,0,5,5,5,0,0,0,0,0
0,0,0,0,0,0,0,0,0,0,0,0,0
0,0,0,0,0,0,0,0,0,0,0,0,0
endlayer

layer
0,0,0,0,0,0,0,0,0,0,0,0,0
0,0,0,0,0,0,0,0,0,0,0,0,0
0,0,0,0,0,4,30,4,0,0,0,0,0
0,0,0,0,30,0,0,0,30,0,0,0,0
0,0,0,30,0,0,0,0,0,30,0,0,0
0,0,4,0,0,0,0,0,0,39,4,0,0
0,0,30,0,0,0,0,0,0,40,30,0,0
0,0,4,0,0,0,0,0,0,0,4,0,0
0,0,0,30,0,0,0,0,0,30,0,0,0
0,0,0,0,30,0,0,0,30,0,0,0,0
0,0,0,0,0,4,30,4,0,0,0,0,0
0,0,0,0,0,0,0,0,0,0,0,0,0
0,0,0,0,0,0,0,0,0,0,0,0,0
endlayer

layer
0,0,0,0,0,0,0,0,0,0,0,0,0
0,0,0,0,0,0,0,0,0,0,0,0,0
0,0,0,0,0,31,0,31,0,0,0,0,0
0,0,0,0,0,0,0,0,0,0,0,0,0
0,0,0,0,0,0,0,0,0,0,0,0,0
0,0,31,0,0,0,0,0,0,0,31,0,0
0,0,0,0,0,0,0,0,0,0,0,0,0
0,0,31,0,0,0,0,0,0,0,31,0,0
0,0,0,0,0,0,0,0,0,0,0,0,0
0,0,0,0,0,0,0,0,0,0,0,0,0
0,0,0,0,0,31,0,31,0,0,0,0,0
0,0,0,0,0,0,0,0,0,0,0,0,0
0,0,0,0,0,0,0,0,0,0,0,0,0
endlayer

layer
0,0,0,0,0,0,0,0,0,0,0,0,0
0,0,0,0,0,0,0,0,0,0,0,0,0
0,0,0,0,0,26,26,26,0,0,0,0,0
0,0,0,0,4,4,0,4,4,0,0,0,0
0,0,0,4,4,0,0,0,4,4,0,0,0
0,0,28,4,0,0,0,0,0,4,27,0,0
0,0,28,0,0,0,0,0,0,0,27,0,0
0,0,28,4,0,0,0,0,0,4,27,0,0
0,0,0,4,4,0,0,0,4,4,0,0,0
0,0,0,0,4,4,0,4,4,0,0,0,0
0,0,0,0,0,29,29,29,0,0,0,0,0
0,0,0,0,0,0,0,0,0,0,0,0,0
0,0,0,0,0,0,0,0,0,0,0,0,0
endlayer

layer
0,0,0,0,0,0,0,0,0,0,0,0,0
0,0,0,0,0,0,0,0,0,0,0,0,0
0,0,0,0,0,0,0,0,0,0,0,0,0
0,0,0,0,30,26,26,26,30,0,0,0,0
0,0,0,30,4,23,0,22,4,30,0,0,0
0,0,0,28,24,0,0,0,24,27,0,0,0
0,0,0,28,0,0,0,0,0,27,0,0,0
0,0,0,28,25,0,0,0,25,27,0,0,0
0,0,0,30,4,23,0,22,4,30,0,0,0
0,0,0,0,30,29,29,29,30,0,0,0,0
0,0,0,0,0,0,0,0,0,0,0,0,0
0,0,0,0,0,0,0,0,0,0,0,0,0
0,0,0,0,0,0,0,0,0,0,0,0,0
endlayer

layer
0,0,0,0,0,0,0,0,0,0,0,0,0
0,0,0,0,0,0,0,0,0,0,0,0,0
0,0,0,0,0,0,0,0,0,0,0,0,0
0,0,0,0,0,0,0,0,0,0,0,0,0
0,0,0,0,30,26,26,26,30,0,0,0,0
0,0,0,0,28,0,0,0,27,0,0,0,0
0,0,0,0,28,0,0,0,27,0,0,0,0
0,0,0,0,28,0,0,0,27,0,0,0,0
0,0,0,0,30,29,29,29,30,0,0,0,0
0,0,0,0,0,0,0,0,0,0,0,0,0
0,0,0,0,0,0,0,0,0,0,0,0,0
0,0,0,0,0,0,0,0,0,0,0,0,0
0,0,0,0,0,0,0,0,0,0,0,0,0
endlayer

layer
0,0,0,0,0,0,0,0,0,0,0,0,0
0,0,0,0,0,0,0,0,0,0,0,0,0
0,0,0,0,0,0,0,0,0,0,0,0,0
0,0,0,0,0,0,0,0,0,0,0,0,0
0,0,0,0,0,0,0,0,0,0,0,0,0
0,0,0,0,0,4,4,4,0,0,0,0,0
0,0,0,0,0,4,41,4,0,0,0,0,0
0,0,0,0,0,4,4,4,0,0,0,0,0
0,0,0,0,0,0,0,0,0,0,0,0,0
0,0,0,0,0,0,0,0,0,0,0,0,0
0,0,0,0,0,0,0,0,0,0,0,0,0
0,0,0,0,0,0,0,0,0,0,0,0,0
0,0,0,0,0,0,0,0,0,0,0,0,0
endlayer

layer
0,0,0,0,0,0,0,0,0,0,0,0,0
0,0,0,0,0,0,0,0,0,0,0,0,0
0,0,0,0,0,0,0,0,0,0,0,0,0
0,0,0,0,0,0,0,0,0,0,0,0,0
0,0,0,0,0,0,0,0,0,0,0,0,0
0,0,0,0,0,0,26,0,0,0,0,0,0
0,0,0,0,0,28,42,27,0,0,0,0,0
0,0,0,0,0,0,29,0,0,0,0,0,0
0,0,0,0,0,0,0,0,0,0,0,0,0
0,0,0,0,0,0,0,0,0,0,0,0,0
0,0,0,0,0,0,0,0,0,0,0,0,0
0,0,0,0,0,0,0,0,0,0,0,0,0
0,0,0,0,0,0,0,0,0,0,0,0,0
endlayer

layer
0,0,0,0,0,0,0,0,0,0,0,0,0
0,0,0,0,0,0,0,0,0,0,0,0,0
0,0,0,0,0,0,0,0,0,0,0,0,0
0,0,0,0,0,0,0,0,0,0,0,0,0
0,0,0,0,0,0,0,0,0,0,0,0,0
0,0,0,0,0,0,0,0,0,0,0,0,0
0,0,0,0,0,0,30,0,0,0,0,0,0
0,0,0,0,0,0,0,0,0,0,0,0,0
0,0,0,0,0,0,0,0,0,0,0,0,0
0,0,0,0,0,0,0,0,0,0,0,0,0
0,0,0,0,0,0,0,0,0,0,0,0,0
0,0,0,0,0,0,0,0,0,0,0,0,0
0,0,0,0,0,0,0,0,0,0,0,0,0
endlayer

