
# Created by Ruins mod version 17.2 Ingame Parser
# authoring Player: BARTLLOW

# TEMPLATE PARAMETER SETTINGS:
#
# criterion expression specifying mod ids required to load template
# may include plus (AND), minus (AND NOT), comma (OR), and parentheses
# all required mods listed must be present; no prohibited mods can be
requiredMods=
#
# likelihood this template will be chosen relative to all others
# e.g., a weight=6 template is chosen 3X as often as one with weight=2
weight=1
#
# list of dimensions in which this template may spawn, even if generic
# one or more dimension names, separated by commas (blank = all)
dimensionsToSpawnIn=
#
# list of other biomes in which this template may spawn
# biome corresponding to directory is always assumed, listed or not
# generic templates should leave this list empty
biomesToSpawnIn=
#
# criterion expression specifying types of biome where template spawns
# this is in addition to those explicitly listed as biomesToSpawnIn
# generic templates should leave this list empty
biomeTypesToSpawnIn=
#
# list of biomes in which this template may not spawn
# takes precedence over biomeTypesToSpawnIn, but NOT biomesToSpawnIn
# should be empty if biomeTypesToSpawnIn is empty
biomesToNotSpawnIn=
#
# depth template is pushed down into the surface when built
# offset is min/max range of random additional bury depth
embed_into_distance=0
random_height_offset=0,0
#
# whitelist/blacklist of block types on which template may be built
# specify one, not both; leave the other empty (both empty = allow all)
acceptable_target_blocks=
unacceptable_target_blocks=flowing_water,water,flowing_lava,lava
#
# size of template (#layers, #rows per layer, #blocks per row)
dimensions=20,43,33
#
# max number of missing blocks allowed in surface beneath template
allowable_overhang=0
#
# depth/height limit affected by terrain leveling
# also maximum bumpiness tolerated in surface beneath template
max_leveling=2
#
# padding applied to all sides of template horizontal footprint
# expands area affected by terrain leveling (-1 = no leveling)
leveling_buffer=0
#
# do not rotate template randomly when built (1 = no rotation)
preventRotation=0
#
# treat water/lava blocks as air and protect them from rule0 (1 = yes)
preserve_water=0
preserve_lava=0
#
# minimum distance this template must have from instances of itself
uniqueMinDistance=0
#
# min/max distances this template can be from world spawn (0 = no limit)
# only applies to overworld--i.e., dimension 0
spawnMinDistance=0
spawnMaxDistance=0
#
# other template built nearby whenever this one is
# syntax: <name>;<relativeX>;<maxYdifference>;<relativeZ>[;<chance>]
# may be used more than once to specify multiple neighbors
adjoining_template=

rule1=0,100,minecraft:dirt-0
rule2=0,100,minecraft:web-0
rule3=0,100,minecraft:lava-0
rule4=0,100,minecraft:grass-0
rule5=0,100,minecraft:iron_bars-0
rule6=0,100,minecraft:vine-1
rule7=0,100,minecraft:wool-14
rule8=0,100,minecraft:vine-4
rule9=0,100,minecraft:vine-2
rule10=0,100,minecraft:stonebrick-2
rule11=0,100,minecraft:wool-0
rule12=0,100,minecraft:stonebrick-0
rule13=0,100,minecraft:leaves-7
rule14=0,100,minecraft:water-0
rule15=0,100,minecraft:stone_brick_stairs-0
rule16=0,100,minecraft:water-1
rule17=0,100,minecraft:stone_brick_stairs-4
rule18=0,100,minecraft:stone-6
rule19=0,100,minecraft:cobblestone-0
rule20=0,100,minecraft:stone_stairs-0
rule21=0,100,minecraft:stone_stairs-6
rule22=0,100,minecraft:stone_brick_stairs-3
rule23=0,100,minecraft:stone_brick_stairs-1
rule24=0,100,minecraft:stone_brick_stairs-2
rule25=0,100,minecraft:stonebrick-1
rule26=0,100,minecraft:wool-4
rule27=0,100,minecraft:stone_slab-11
rule28=0,100,minecraft:stone_stairs-2
rule29=0,100,minecraft:cauldron-0
rule30=0,100,minecraft:leaves-15
rule31=0,100,IInventory;minecraft:chest;minecraft:iron_sword#1#0#3+minecraft:wooden_button#2#0#5+minecraft:wooden_button#2#0#7+minecraft:sea_lantern#2#0#8+minecraft:iron_sword#1#0#26-2
rule32=0,100,IInventory;minecraft:chest;minecraft:iron_helmet#1#0#14-2
rule33=0,100,minecraft:vine-12
rule34=0,100,minecraft:vine-8
rule35=0,100,minecraft:spruce_fence-0
rule36=0,100,IInventory;minecraft:chest;minecraft:diamond#2#0#3+minecraft:wool#1#0#5+minecraft:obsidian#2#0#7+minecraft:diamond#2#0#8+minecraft:diamond#2#0#26-4
rule37=0,100,IInventory;minecraft:chest;minecraft:fence#2#0#14-4
rule38=0,100,minecraft:double_stone_slab-3
rule39=0,100,IInventory;minecraft:dispenser;minecraft:redstone#1#0#2+minecraft:string#1#0#4+minecraft:tripwire_hook#1#0#6-2
rule40=0,100,minecraft:obsidian-0
rule41=0,100,minecraft:tallgrass-1
rule42=0,100,minecraft:redstone_wire-0
rule43=0,100,minecraft:quartz_block-0
rule44=0,100,minecraft:spruce_door-1
rule45=0,100,minecraft:spruce_door-3
rule46=0,100,minecraft:wooden_slab-13
rule47=0,100,minecraft:double_stone_slab-0
rule48=0,100,Skull:0:4-1
rule49=0,100,minecraft:wooden_slab-9
rule50=0,100,minecraft:log-0
rule51=0,100,minecraft:fence-0
rule52=0,100,minecraft:stone_slab-8
rule53=0,100,minecraft:spruce_door-5
rule54=0,100,IInventory;minecraft:chest;minecraft:written_book#{pages:["\"The rebirth of 3 rivers\\n20 storms whisper dissemblingly\\nrun, Sofia!\\n\\nlovers undulated the water under the clear desire, mindlessly but mindlessly.\\nstorms made lovers \"","\"like abyssopelagic lovers run.\\nalas! taint, the abyssopelagic host ility.\\n\""],author:"Alexander Roosasson",title:"God!"}#0#0+minecraft:web#1#0#3+minecraft:emerald#3#0#5+minecraft:bone#1#0#8+minecraft:paper#12#0#26-2
rule55=0,100,minecraft:spruce_door-7
rule56=0,100,Skull:0:5-1
rule57=0,100,minecraft:brown_mushroom-0
rule58=0,100,minecraft:stone_brick_stairs-5
rule59=0,100,minecraft:double_wooden_slab-5
rule60=0,100,minecraft:wooden_slab-5
rule61=0,100,Skull:0:9-1
rule62=0,100,minecraft:double_wooden_slab-1
rule63=0,100,minecraft:stone_slab-13
rule64=0,100,minecraft:spruce_door-6
rule65=0,100,IInventory;minecraft:chest;minecraft:iron_sword#1#0#3+minecraft:leather_helmet#1#0#5+minecraft:leather_chestplate#1#0#8-3
rule66=0,100,IInventory;minecraft:dispenser;minecraft:tipped_arrow#{Potion:"minecraft:strong_strength"}#0#4-2
rule67=0,100,minecraft:portal-2
rule68=0,100,minecraft:tripwire_hook-0
rule69=0,100,minecraft:lever-3
rule70=0,100,minecraft:lever-4
rule71=0,100,minecraft:spruce_door-9
rule72=0,100,Skull:0:15-1
rule73=0,100,minecraft:stone_slab-5
rule74=0,100,minecraft:spruce_door-8
rule75=0,100,minecraft:lever-5
rule76=2,100,minecraft:redstone_torch-2
rule77=0,100,minecraft:tripwire_hook-1
rule78=2,100,minecraft:torch-1
rule79=2,100,minecraft:torch-2
rule80=0,100,minecraft:tripwire_hook-2
rule81=2,100,minecraft:redstone_torch-3
rule82=0,100,minecraft:stone_brick_stairs-7
rule83=0,100,minecraft:cauldron-3
rule84=0,100,minecraft:lever-10
rule85=0,100,minecraft:stone_brick_stairs-6
rule86=2,100,minecraft:redstone_torch-4
rule87=0,100,minecraft:trapdoor-9
rule88=0,100,minecraft:trapdoor-13
rule89=0,100,minecraft:wool-15
rule90=0,100,minecraft:wall_banner-5
rule91=0,100,IInventory;minecraft:chest;minecraft:flint_and_steel#1#0#0+minecraft:iron_trapdoor#1#0#1+minecraft:iron_bars#1#0#15+minecraft:water_bucket#1#0#20-3
rule92=0,100,minecraft:cobblestone_wall-0
rule93=0,100,minecraft:lever-6
rule94=0,100,minecraft:stone_slab-0
rule95=0,100,minecraft:quartz_stairs-2
rule96=0,100,minecraft:quartz_stairs-7
rule97=0,100,minecraft:quartz_stairs-3
rule98=0,100,minecraft:log-8
rule99=0,100,minecraft:vine-9
rule100=0,100,minecraft:vine-3
rule101=0,100,minecraft:quartz_stairs-1
rule102=0,100,minecraft:quartz_stairs-6
rule103=0,100,minecraft:vine-10
rule104=0,100,minecraft:sea_lantern-0
rule105=0,100,minecraft:vine-6
rule106=0,100,minecraft:quartz_stairs-4

layer
1,1,1,1,1,1,1,1,1,1,1,1,1,1,1,1,1,1,1,1,1,1,1,1,1,1,1,1,1,1,1,1,1
1,1,1,1,1,1,1,1,1,1,1,1,1,1,1,1,1,1,1,1,1,1,1,1,1,1,1,1,1,1,1,1,1
1,1,1,1,1,1,1,1,1,1,1,1,1,1,1,1,1,1,1,1,1,1,1,1,1,1,1,1,1,1,1,1,1
1,1,1,1,1,1,1,1,1,1,1,1,1,1,1,1,1,1,1,1,1,1,1,1,1,1,1,1,1,1,1,1,1
1,1,1,1,1,1,1,1,1,1,1,1,1,1,1,1,1,1,1,1,1,1,1,1,1,1,1,1,1,1,1,1,1
1,1,1,1,1,1,1,1,1,1,1,1,1,1,1,1,1,1,1,1,1,1,1,1,1,1,1,1,1,1,1,1,1
1,0,0,1,0,0,1,1,1,1,1,1,1,1,1,1,1,1,1,1,1,1,1,1,1,1,1,0,0,0,0,0,1
1,1,1,1,1,1,1,1,1,1,1,1,1,1,1,1,1,1,1,1,1,1,1,1,1,1,1,1,1,1,1,1,1
1,1,1,1,1,1,1,1,1,1,1,1,1,1,1,1,1,1,1,1,1,1,1,1,1,1,1,1,1,1,1,1,1
1,1,1,1,1,1,1,1,1,1,1,1,1,1,1,1,1,1,1,1,1,1,1,1,1,1,1,1,1,1,1,1,1
1,1,1,1,1,1,1,1,1,1,1,1,1,1,1,1,1,1,1,1,1,1,1,1,1,1,1,1,1,1,1,1,1
1,1,1,1,1,1,1,1,1,1,1,1,1,1,1,1,1,1,1,1,1,1,1,1,1,1,1,1,1,1,1,1,1
1,1,1,1,1,1,1,1,1,1,1,1,1,1,1,1,1,1,1,1,1,1,1,1,1,1,1,1,1,1,1,1,1
1,1,1,0,0,0,1,1,1,1,1,1,1,1,1,1,1,1,1,1,1,1,1,1,1,1,1,1,1,1,1,1,1
1,1,1,1,1,1,1,1,1,1,1,1,1,1,1,1,1,1,1,1,1,1,1,1,1,1,1,1,1,1,1,1,1
1,1,1,1,1,1,1,1,1,1,1,1,1,1,1,1,1,1,1,1,1,1,1,1,1,1,1,1,1,1,1,1,1
1,1,1,1,1,1,1,1,1,1,1,1,1,1,1,1,1,1,1,1,1,1,1,1,1,1,1,1,1,1,1,1,1
1,1,1,1,1,1,1,1,1,1,1,1,1,1,1,1,1,1,1,1,1,1,1,1,1,1,1,1,1,1,1,1,1
1,1,1,1,1,1,1,1,1,1,1,1,1,1,1,1,1,1,1,1,1,1,1,1,1,1,1,1,1,1,1,1,1
1,1,1,1,1,1,1,1,1,1,1,1,1,1,1,1,1,1,1,1,1,1,1,1,1,1,1,1,1,1,1,1,1
1,1,1,1,1,1,1,1,1,1,1,1,1,1,1,1,1,1,1,1,1,1,1,1,1,1,1,1,1,1,1,1,1
1,1,1,1,1,1,1,1,1,1,1,1,1,1,1,1,1,1,1,1,1,1,1,1,1,1,1,1,1,1,2,0,1
1,1,1,1,1,1,1,1,1,1,1,1,1,1,1,1,1,1,1,1,1,1,1,1,1,1,1,1,1,1,1,1,1
1,1,1,1,1,1,1,1,1,1,1,1,1,1,1,1,1,1,1,1,1,1,1,1,1,1,1,1,1,1,1,1,1
1,1,1,1,1,1,1,1,1,1,1,1,1,1,1,1,1,1,1,1,1,1,1,1,1,1,1,1,1,1,1,1,1
1,1,1,1,1,1,1,1,1,1,1,1,1,1,1,1,1,1,1,1,1,1,1,1,1,1,1,1,1,1,1,1,1
1,1,1,1,1,1,1,1,1,1,1,1,1,1,1,1,1,1,1,1,1,1,1,1,1,1,1,1,1,1,1,1,1
1,1,1,1,1,1,1,1,1,1,1,1,1,1,1,1,3,1,1,1,1,1,1,1,1,1,1,1,1,1,1,1,1
1,1,1,1,1,1,1,1,1,1,1,1,1,0,0,1,1,1,1,1,1,1,1,1,1,1,1,1,1,1,1,1,1
1,0,0,0,0,0,1,1,1,1,1,1,1,1,0,0,1,1,1,1,1,1,1,1,1,1,1,0,0,0,0,0,1
1,1,1,1,1,1,1,1,1,1,1,1,3,1,4,1,1,1,1,1,1,1,1,1,1,1,1,1,1,1,1,1,1
1,1,1,1,1,1,1,1,1,1,1,1,1,4,1,1,1,1,1,1,1,1,1,1,1,1,1,1,1,1,1,1,1
1,1,1,1,1,1,1,1,1,1,1,1,1,1,1,1,1,1,1,1,1,1,1,1,1,1,1,1,1,1,1,1,1
1,1,1,1,1,1,1,1,1,1,1,1,1,1,1,1,1,1,1,1,1,1,1,1,1,1,1,1,1,1,1,1,1
1,1,1,1,1,1,1,1,1,1,1,1,1,1,1,1,1,1,1,1,1,1,1,1,1,1,1,1,1,1,1,1,1
1,1,1,1,1,1,1,1,1,1,1,1,1,1,1,1,1,1,1,1,1,1,1,1,1,1,1,1,1,1,1,1,1
1,0,0,1,1,1,1,1,1,1,1,1,1,1,1,1,1,1,1,1,1,1,1,1,1,1,1,1,1,1,1,1,1
1,1,1,1,1,1,1,1,1,1,1,1,1,1,1,1,1,1,0,1,1,1,1,1,1,1,1,1,1,1,1,1,1
1,1,1,1,1,1,1,1,1,1,1,1,1,1,1,1,1,1,0,1,1,1,1,1,1,1,1,1,1,1,1,1,1
1,1,1,1,1,1,1,1,1,1,1,1,1,1,1,1,1,1,0,1,1,1,1,1,1,1,1,1,1,1,1,1,1
1,1,1,1,1,1,1,1,1,1,1,1,1,1,1,1,1,1,1,1,1,1,1,1,1,1,1,1,1,1,1,1,1
1,1,1,1,1,1,1,1,1,1,1,1,1,1,1,1,1,1,1,1,1,1,1,1,1,1,1,1,1,1,1,1,1
1,1,1,1,1,1,1,1,1,1,1,1,1,1,1,1,1,1,1,1,1,1,1,1,1,1,1,1,1,1,1,1,1
endlayer

layer
1,1,1,1,1,1,1,1,1,1,1,1,1,1,1,1,1,1,1,1,1,1,1,1,1,1,1,1,1,1,1,1,1
1,1,1,1,1,1,1,1,1,1,1,1,1,1,1,1,1,1,1,1,1,1,1,1,1,1,1,1,1,1,1,1,1
1,1,1,1,1,1,1,1,1,1,1,1,1,1,1,1,1,1,1,1,1,1,1,1,1,1,1,1,1,1,1,1,1
1,1,1,1,1,1,1,1,1,1,1,1,1,1,1,1,1,1,1,1,1,1,1,1,1,1,1,1,1,1,1,1,1
1,1,1,1,1,1,1,1,1,1,1,1,1,1,1,1,1,1,1,1,1,1,1,1,1,1,1,1,1,1,1,1,1
1,1,1,1,1,1,1,1,1,1,1,1,1,1,1,1,1,1,1,1,1,1,1,1,1,1,1,1,1,1,1,1,1
1,1,1,1,1,1,1,1,1,1,1,1,1,1,1,1,1,1,1,1,1,1,1,1,1,1,1,1,1,1,1,1,1
1,1,1,1,1,1,1,1,1,1,1,1,1,1,1,1,1,1,1,1,1,1,1,1,1,1,1,1,1,1,1,1,1
1,1,1,1,1,1,1,1,1,1,1,1,1,1,1,1,1,1,1,1,1,1,1,1,1,1,1,1,1,1,1,1,1
1,1,1,1,1,1,1,1,1,1,1,1,1,1,1,1,1,1,1,1,1,1,1,1,1,1,1,1,1,1,1,1,1
1,1,1,1,1,1,1,1,1,1,1,1,1,1,1,1,1,1,1,1,1,1,1,1,1,1,1,1,1,1,1,1,1
1,1,1,1,1,1,1,1,1,1,1,1,1,1,1,1,1,1,1,1,1,1,1,1,1,1,1,1,1,1,1,1,1
1,1,1,1,1,1,1,1,1,1,1,1,1,1,1,1,1,1,1,1,1,1,1,1,1,1,1,1,1,1,1,1,1
1,1,1,1,1,1,1,1,1,1,1,1,1,1,1,1,1,1,1,1,1,1,1,1,1,1,1,1,1,1,1,1,1
1,1,1,1,1,1,1,1,1,1,1,1,1,1,1,1,1,1,1,1,1,1,1,1,1,1,1,1,1,1,1,1,1
1,1,1,1,1,1,1,1,1,1,1,1,1,1,1,1,1,1,1,1,1,1,1,1,1,1,1,1,1,1,1,1,1
1,1,1,1,1,1,1,1,1,1,1,1,1,1,1,1,1,1,1,1,1,1,1,1,1,1,1,1,1,1,1,1,1
1,1,1,1,1,1,1,1,1,1,1,1,1,1,1,1,1,1,1,1,1,1,1,1,1,1,1,1,1,1,1,1,1
1,1,1,1,1,1,1,1,1,1,1,1,1,1,1,1,1,1,1,1,1,1,1,1,1,1,1,1,1,1,1,1,1
1,1,1,1,1,1,1,1,1,1,1,1,1,1,1,1,1,1,1,1,1,1,1,1,1,1,1,1,1,1,1,1,1
1,1,1,1,1,1,1,1,1,1,1,1,1,1,1,1,1,1,1,1,1,1,1,1,1,1,1,1,1,1,1,1,1
1,1,1,1,1,1,1,1,1,1,1,1,1,1,1,1,1,1,1,1,1,1,1,1,1,1,1,1,1,1,1,1,1
1,1,1,1,1,1,1,1,1,1,1,1,1,1,1,1,1,1,1,1,1,1,1,1,1,1,1,1,1,1,1,1,1
1,1,1,1,1,1,1,1,1,1,1,1,1,1,1,1,1,1,1,1,1,1,1,1,1,1,1,1,1,1,1,1,1
1,1,1,1,1,1,1,1,1,1,1,1,1,1,1,1,1,1,1,1,1,1,1,1,1,1,1,1,1,1,1,1,1
1,1,1,1,1,1,1,1,1,1,1,1,1,1,1,1,0,1,1,1,1,1,1,1,1,1,1,1,1,1,1,1,1
1,1,1,1,1,1,1,1,1,1,1,1,1,1,1,0,1,0,1,1,1,1,1,1,1,1,1,1,1,1,1,1,1
1,1,1,1,1,1,1,1,1,1,1,1,1,1,0,1,5,1,0,1,1,1,1,1,1,1,1,1,1,1,1,1,1
1,1,1,1,1,1,1,1,1,1,1,1,0,0,0,0,1,0,1,1,1,1,1,1,1,1,1,1,1,1,1,1,1
1,1,1,1,1,1,1,1,1,1,1,0,1,0,0,0,0,1,1,1,1,1,1,1,1,1,1,1,1,1,1,1,1
1,1,1,1,1,1,1,1,1,1,0,1,5,1,0,1,1,1,1,1,1,1,1,1,1,1,1,1,1,1,1,1,1
1,1,1,1,1,1,1,1,1,1,0,0,1,0,1,1,1,1,1,1,1,1,1,1,1,1,1,1,1,1,1,1,1
1,1,1,1,1,1,1,1,1,1,1,0,0,1,1,1,1,1,1,1,1,1,1,1,1,1,1,1,1,1,1,1,1
1,1,1,1,1,1,1,1,1,1,1,1,1,1,1,1,1,1,1,1,1,1,1,1,1,1,1,1,1,1,1,1,1
1,1,1,1,1,1,1,1,1,1,1,1,1,1,1,1,1,1,1,1,1,1,1,1,1,1,1,1,1,1,1,1,1
1,1,1,1,1,1,1,1,1,1,1,1,1,1,1,1,1,1,1,1,1,1,1,1,1,1,1,1,1,1,1,1,1
1,1,1,1,1,1,1,1,1,1,1,1,1,1,1,1,1,1,1,1,1,1,1,1,1,1,1,1,1,1,1,1,1
1,1,1,1,1,1,1,1,1,1,1,1,1,1,1,1,1,1,1,1,1,1,1,1,1,1,1,1,1,1,1,1,1
1,1,1,1,1,1,1,1,1,1,1,1,1,1,1,1,1,1,1,1,1,1,1,1,1,1,1,1,1,1,1,1,1
1,1,1,1,1,1,1,1,1,1,1,1,1,1,1,1,1,1,1,1,1,1,1,1,1,1,1,1,1,1,1,1,1
1,1,1,1,1,1,1,1,1,1,1,1,1,1,1,1,1,1,1,1,1,1,1,1,1,1,1,1,1,1,1,1,1
1,1,1,1,1,1,1,1,1,1,1,1,1,1,1,1,1,1,1,1,1,1,1,1,1,1,1,1,1,1,1,1,1
1,1,1,1,1,1,1,1,1,1,1,1,1,1,1,1,1,1,1,1,1,1,1,1,1,1,1,1,1,1,1,1,1
endlayer

layer
1,1,1,1,1,1,1,1,1,1,1,1,1,1,1,1,1,1,1,1,1,1,1,1,1,1,1,1,1,1,1,1,1
1,1,1,1,1,1,1,1,1,1,1,1,1,1,1,1,1,1,1,1,1,1,1,1,1,1,1,1,1,1,1,1,1
1,1,1,1,1,1,1,1,1,1,1,1,1,1,1,1,1,1,1,1,1,1,1,1,1,1,1,1,1,1,1,1,1
1,1,1,1,1,1,1,1,1,1,1,1,1,1,1,1,1,1,1,1,1,1,1,1,1,1,1,1,1,1,1,1,1
1,1,1,1,1,1,1,1,1,1,1,1,1,1,1,1,1,1,1,1,1,1,1,1,1,1,1,1,1,1,1,1,1
1,1,1,1,1,1,1,1,1,1,1,1,1,1,1,1,1,1,1,1,1,1,1,1,1,1,1,1,1,1,1,1,1
1,1,1,1,1,1,1,1,1,1,1,1,1,1,1,1,1,1,1,1,1,1,1,1,1,1,1,1,1,1,1,1,1
1,1,1,1,1,1,1,1,1,1,1,1,1,1,1,1,1,1,1,1,1,1,1,1,1,1,1,1,1,1,1,1,1
1,1,1,1,1,1,1,1,1,1,1,1,1,1,1,1,1,1,1,1,1,1,1,1,1,1,1,1,1,1,1,1,1
1,1,1,1,1,1,1,1,1,1,1,1,1,1,1,1,1,1,1,1,1,1,1,1,1,1,1,1,1,1,1,1,1
1,1,1,1,1,1,1,1,1,1,1,1,1,1,1,1,1,1,1,1,1,1,1,1,1,1,1,1,1,1,1,1,1
1,1,1,1,1,1,1,1,1,1,1,1,1,1,1,1,1,1,1,1,1,1,1,1,1,1,1,1,1,1,1,1,1
1,1,1,1,1,1,1,1,1,1,1,1,1,1,1,1,1,1,1,1,1,1,1,1,1,1,1,1,1,1,1,1,1
1,1,1,1,1,1,1,1,1,1,1,1,1,1,1,1,1,1,1,1,1,1,1,1,1,1,1,1,1,1,1,1,1
1,1,1,1,1,1,1,1,1,1,1,1,1,1,1,1,1,1,1,1,1,1,1,1,1,1,1,1,1,1,1,1,1
1,1,1,1,1,1,1,1,1,1,1,1,1,1,1,1,1,1,1,1,1,1,1,1,1,1,1,1,1,1,1,1,1
1,1,1,1,1,1,1,1,1,1,1,1,1,1,1,1,1,1,1,1,1,1,1,1,1,1,1,1,1,1,1,1,1
1,1,1,1,1,1,1,1,1,1,1,0,1,0,1,1,1,1,1,1,1,1,1,1,1,1,1,1,1,1,1,1,1
1,1,1,1,1,1,1,1,1,1,1,1,1,1,1,1,1,1,1,1,1,1,1,1,1,1,1,1,1,1,1,1,1
1,1,1,1,1,1,1,1,1,1,1,1,1,1,1,1,1,1,1,1,1,1,1,1,1,1,1,1,1,1,1,1,1
1,1,1,1,1,1,1,1,1,1,1,1,1,1,1,1,1,1,1,1,1,1,1,1,1,1,1,1,1,1,1,1,1
1,1,1,1,1,1,1,1,1,1,1,0,1,2,1,1,1,1,1,1,1,1,1,1,1,1,1,1,1,1,1,1,1
1,1,1,1,1,1,1,1,1,1,1,1,1,1,1,1,1,1,1,1,1,1,1,1,1,1,1,1,1,1,1,1,1
1,1,1,1,1,1,1,1,1,1,1,1,1,1,1,1,1,1,1,1,1,1,1,1,1,1,1,1,1,1,1,1,1
1,1,1,1,1,1,1,1,1,1,1,1,1,1,1,1,1,1,1,1,1,1,1,1,1,1,1,1,1,1,1,1,1
1,1,1,1,1,1,1,1,1,1,1,1,0,0,1,1,0,1,1,1,1,1,1,1,1,1,1,1,1,1,1,1,1
1,1,1,1,1,1,1,1,1,1,1,0,0,0,1,0,1,2,1,1,1,1,1,1,1,1,1,1,1,1,1,1,1
1,1,1,1,1,1,1,1,1,1,1,0,0,0,0,1,5,1,6,1,1,1,1,1,1,1,1,1,1,1,1,1,1
1,1,1,1,1,1,1,1,1,1,1,0,0,0,0,0,1,0,1,1,1,1,1,1,1,1,1,1,1,1,1,1,1
1,1,1,1,1,1,1,1,1,1,1,0,1,0,0,0,0,1,1,1,1,1,1,1,1,1,1,1,1,1,1,1,1
1,1,1,1,1,1,1,1,1,1,0,1,5,1,0,1,1,1,1,1,1,1,1,1,1,1,1,1,1,1,1,1,1
1,1,1,1,1,1,1,1,1,1,0,0,1,0,1,1,1,1,1,1,1,1,1,1,1,1,1,1,1,1,1,1,1
1,1,1,1,1,1,1,1,1,1,1,0,0,1,1,1,1,1,1,1,1,1,1,1,1,1,1,1,1,1,1,1,1
1,1,1,1,1,1,1,1,1,1,1,1,1,1,1,1,1,1,1,1,1,1,1,1,1,1,1,1,1,1,1,1,1
1,1,1,1,1,1,1,1,1,1,1,1,1,1,1,1,1,1,1,1,1,1,1,1,1,1,1,1,1,1,1,1,1
1,1,1,1,1,1,1,1,1,1,1,1,1,1,1,1,1,1,1,1,1,1,1,1,1,1,1,1,1,1,1,1,1
1,1,1,1,1,1,1,1,1,1,1,1,1,1,1,1,1,1,1,1,1,1,1,1,1,1,1,1,1,1,1,1,1
1,1,1,1,1,1,1,1,1,1,1,1,1,1,1,1,1,1,1,1,1,1,1,1,1,1,1,1,1,1,1,1,1
1,1,1,1,1,1,1,1,1,1,1,1,1,1,1,1,1,1,1,1,1,1,1,1,1,1,1,1,1,1,1,1,1
1,1,1,1,1,1,1,1,1,1,1,1,1,1,1,1,1,1,1,1,1,1,1,1,1,1,1,1,1,1,1,1,1
1,1,1,1,1,1,1,1,1,1,1,1,1,1,1,1,1,1,1,1,1,1,1,1,1,1,1,1,1,1,1,1,1
1,1,1,1,1,1,1,1,1,1,1,1,1,1,1,1,1,1,1,1,1,1,1,1,1,1,1,1,1,1,1,1,1
1,1,1,1,1,1,1,1,1,1,1,1,1,1,1,1,1,1,1,1,1,1,1,1,1,1,1,1,1,1,1,1,1
endlayer

layer
1,1,1,1,1,1,1,1,4,1,1,1,1,1,1,1,1,1,1,1,1,1,1,4,1,1,1,1,1,1,1,1,1
1,4,4,1,1,1,1,1,1,1,1,1,1,4,1,1,1,1,1,1,1,1,4,1,1,4,4,4,4,4,4,4,1
1,1,1,1,1,1,1,1,1,1,1,1,4,4,1,1,4,4,4,1,1,1,4,4,4,4,4,4,4,4,4,4,1
1,1,1,1,1,4,1,1,4,1,1,4,1,1,1,1,4,4,4,4,1,1,4,4,4,4,4,1,4,1,1,1,1
1,1,1,1,1,1,1,1,1,1,1,1,1,1,4,1,4,1,4,4,4,4,4,1,1,1,1,1,1,1,1,1,4
1,1,1,1,1,1,1,1,4,1,1,1,4,4,1,1,1,4,1,4,4,4,1,1,1,1,1,1,1,1,1,1,1
1,0,0,0,0,0,1,1,1,1,1,1,1,1,1,1,1,1,1,1,1,1,1,1,1,1,1,0,0,0,0,0,1
1,1,1,1,1,1,1,1,1,1,1,1,1,1,4,1,1,1,1,1,1,1,1,1,1,1,1,1,1,1,1,1,1
1,1,1,1,1,1,1,1,1,1,1,1,1,1,1,1,4,1,1,1,1,1,1,1,1,1,4,1,1,1,1,1,1
1,1,1,1,1,1,1,4,1,1,1,1,4,4,4,1,1,4,1,1,1,1,1,1,1,1,1,4,1,1,1,1,1
1,1,1,1,1,1,1,1,1,1,1,1,1,1,1,1,1,1,1,4,1,1,1,1,1,1,1,1,4,1,1,1,1
1,1,1,1,1,1,1,1,4,1,1,1,1,1,1,1,1,1,1,1,1,1,4,1,1,1,1,4,1,1,1,1,1
1,1,1,1,1,1,1,1,1,1,1,1,1,1,1,1,1,1,1,1,1,1,1,1,1,1,1,1,1,1,1,1,1
1,0,0,0,0,0,1,1,1,1,1,1,1,1,1,1,1,1,1,1,1,1,1,1,1,1,1,2,0,0,0,0,1
1,1,1,1,1,1,1,1,1,1,1,1,1,4,1,1,1,1,1,1,1,1,1,1,1,1,1,1,1,1,1,1,1
1,1,1,1,1,1,1,4,1,4,4,4,4,1,4,4,1,1,1,1,1,1,1,1,1,1,1,1,1,1,1,1,1
1,1,1,1,1,1,1,1,1,4,7,7,7,7,7,4,4,1,1,1,1,1,1,1,1,1,1,1,1,1,1,1,4
1,4,1,1,1,1,4,4,1,4,7,1,7,1,7,4,1,1,1,1,1,1,1,1,1,1,1,1,1,1,1,1,1
1,1,1,1,1,1,1,1,1,4,7,7,7,7,7,4,1,1,1,1,1,1,1,1,1,1,1,1,1,1,1,1,4
1,1,1,1,1,1,1,1,1,4,7,7,7,7,7,1,1,1,4,1,1,1,1,1,1,1,4,1,1,1,1,1,1
4,1,1,1,1,1,1,1,1,4,7,7,7,7,7,4,1,1,1,1,1,1,1,1,1,4,1,1,1,1,1,1,1
4,1,1,1,1,1,1,1,1,1,7,1,7,1,7,4,1,1,1,1,1,1,1,1,1,1,1,0,0,0,0,0,1
1,1,1,1,1,1,1,1,1,4,7,7,7,7,7,4,1,1,1,1,1,1,1,4,1,1,1,1,1,1,1,1,1
1,1,1,1,1,1,1,1,1,4,4,1,4,4,4,4,1,1,1,1,1,1,1,1,1,1,1,1,1,1,1,1,1
4,1,1,1,1,4,1,1,1,1,4,1,1,1,1,1,1,1,1,1,1,1,4,1,1,1,1,1,1,4,1,4,1
1,1,4,1,1,1,1,1,1,1,1,4,1,1,1,1,8,1,1,1,1,1,1,1,1,1,1,1,1,1,1,1,1
1,1,1,1,1,1,1,1,1,1,1,1,1,1,1,0,1,0,1,1,1,1,1,1,1,1,1,1,4,1,1,1,1
1,1,1,1,4,1,1,1,4,1,1,1,1,1,0,1,5,1,6,1,1,1,1,4,1,1,1,1,1,1,1,1,1
1,1,1,1,1,1,1,1,1,1,1,1,0,1,1,0,1,0,1,1,1,1,1,1,1,1,1,1,1,1,1,1,1
1,0,0,0,0,0,1,1,1,1,4,0,1,0,1,1,0,1,1,1,4,1,1,1,1,1,1,0,0,0,0,0,1
1,1,1,1,1,1,1,4,4,1,0,1,5,1,0,1,1,1,1,1,1,1,1,1,1,1,1,1,1,1,1,1,1
1,1,1,1,1,1,1,1,1,1,0,0,1,0,1,1,1,1,1,1,1,1,4,1,1,1,1,1,1,1,1,1,1
1,1,1,1,1,1,1,1,1,1,1,1,0,1,1,1,1,4,1,1,4,1,1,1,1,4,1,1,1,1,1,1,1
1,1,1,4,1,1,1,1,1,4,1,4,1,1,1,1,1,1,1,1,1,1,1,1,1,1,1,1,1,1,1,1,1
1,1,1,1,4,4,1,1,1,1,1,1,1,1,4,1,1,1,1,1,1,1,1,1,1,4,1,1,1,1,1,1,1
1,1,1,1,1,1,1,1,1,1,1,1,1,1,1,1,1,1,1,1,1,1,1,1,1,1,4,1,1,1,1,1,1
1,0,0,0,0,0,1,1,1,1,1,1,1,1,1,1,1,1,1,1,4,1,1,1,1,1,4,1,1,1,1,1,1
1,1,1,1,1,1,1,1,1,1,4,1,1,1,1,1,1,1,9,1,1,1,1,1,1,1,1,1,1,1,1,1,1
1,1,1,1,1,1,1,1,4,4,1,1,1,1,0,1,1,1,0,1,1,1,4,1,1,1,1,1,1,1,1,1,1
1,1,1,4,1,1,1,4,1,1,1,1,1,1,0,1,1,1,0,1,1,1,1,1,1,1,1,1,1,1,1,1,1
1,1,1,1,4,1,1,1,1,1,1,1,1,1,1,1,1,1,0,1,1,1,1,1,1,1,1,1,4,1,1,1,1
1,1,1,1,1,1,1,1,1,1,1,1,1,1,0,1,1,1,2,1,1,1,1,1,1,1,1,1,1,1,1,4,4
1,1,1,1,1,1,1,1,1,1,1,1,1,1,1,1,1,1,1,1,1,1,1,1,1,1,1,1,1,1,1,1,1
endlayer

layer
11,11,11,11,11,11,11,11,11,11,11,11,11,11,11,11,11,11,11,11,11,11,11,11,11,11,11,11,11,11,11,11,10
11,12,10,12,12,14,12,12,10,10,12,10,12,12,12,12,12,12,12,10,12,12,12,12,12,14,14,14,14,13,13,13,12
11,10,10,12,14,14,14,12,12,10,12,10,13,13,14,14,14,14,14,12,12,10,14,14,14,14,14,14,13,13,13,13,12
11,12,10,12,12,14,14,14,14,14,10,14,14,14,14,12,14,14,14,14,12,12,14,14,14,14,14,14,14,14,14,14,10
11,10,12,10,12,12,10,14,14,14,14,14,12,12,15,12,10,12,14,14,14,14,14,12,12,12,12,12,14,14,14,12,10
11,12,12,10,12,12,12,12,14,12,14,12,17,12,10,12,12,10,10,14,14,14,12,12,12,12,10,12,12,10,16,10,12
11,4,1,1,1,1,11,11,16,11,11,11,11,11,11,11,11,11,11,11,11,11,11,11,11,11,11,1,1,1,1,1,10
11,4,18,18,18,18,18,18,4,18,18,18,18,18,18,18,18,18,18,18,12,12,12,4,18,18,18,18,18,18,18,18,10
11,18,4,4,18,18,18,18,19,4,18,18,18,18,18,18,18,18,18,18,18,4,4,4,4,4,18,18,18,18,4,18,12
11,18,18,18,18,18,18,18,18,18,19,4,20,4,18,18,18,18,18,18,18,18,18,4,18,18,18,18,18,18,18,18,10
11,18,18,18,18,18,18,18,19,4,19,19,19,19,19,18,18,18,18,21,19,19,19,18,18,18,18,18,18,18,18,18,10
11,18,18,18,18,18,18,18,18,18,19,18,18,19,4,19,19,19,18,19,19,19,19,19,18,18,18,18,18,4,18,18,12
11,18,18,18,4,4,11,18,18,18,18,18,18,18,19,19,19,19,19,19,18,18,18,18,18,18,11,4,18,18,18,18,12
11,1,1,1,1,1,11,18,18,18,18,18,18,18,19,19,4,18,18,18,18,18,18,18,18,18,11,1,1,1,1,1,10
11,18,12,18,18,18,11,18,18,18,18,18,18,18,18,18,19,4,18,18,18,19,18,18,18,18,11,4,4,4,18,18,10
11,4,4,12,18,4,18,18,18,23,23,12,23,12,23,22,19,19,4,18,18,18,18,18,18,18,18,4,4,18,18,18,12
11,18,18,25,18,18,18,18,18,24,5,5,5,5,5,22,19,19,19,18,18,18,18,19,18,18,18,18,18,18,18,18,12
11,18,18,18,18,18,18,18,18,24,5,25,5,12,5,22,19,19,18,18,18,18,19,18,18,18,18,18,10,12,4,18,12
11,18,18,18,4,18,18,18,18,24,5,5,5,5,5,22,18,19,18,18,18,18,19,19,19,18,18,18,18,18,18,18,22
11,18,18,18,18,18,18,18,18,24,5,5,5,5,5,10,4,19,18,18,18,18,18,18,18,18,18,18,18,10,18,4,12
11,18,18,18,4,4,11,18,18,24,5,5,5,5,5,22,19,4,18,18,18,18,18,18,18,18,11,18,18,18,18,18,10
11,26,26,26,26,26,11,18,18,18,5,10,5,12,5,22,19,19,18,18,18,18,18,18,18,18,11,1,1,1,1,1,10
11,18,10,18,18,18,11,18,18,24,5,5,5,5,5,22,18,19,18,18,18,18,18,18,18,18,11,18,4,18,18,18,12
11,18,4,18,18,18,18,18,18,24,15,10,15,15,15,22,19,19,4,4,4,18,18,18,18,18,18,18,4,18,18,4,12
11,18,18,4,18,27,18,18,18,18,10,18,18,12,12,19,19,18,19,19,19,19,18,18,18,18,18,18,18,18,18,4,12
11,18,27,18,18,18,18,18,18,18,12,0,4,4,10,19,18,18,18,18,18,18,18,18,18,18,18,18,18,4,18,18,12
11,18,18,18,18,18,18,12,12,10,18,18,19,4,10,23,23,22,18,18,18,18,18,18,18,18,18,18,18,18,18,18,12
11,18,18,18,27,4,18,10,18,18,18,18,19,4,19,24,0,22,18,18,18,18,18,18,18,18,18,18,4,18,18,18,10
11,18,18,18,4,4,11,18,18,18,18,18,18,18,12,24,15,22,18,18,18,18,18,18,18,18,11,18,18,18,18,18,12
11,1,1,1,1,1,11,18,18,18,18,23,23,22,12,18,18,18,18,18,18,18,18,18,18,18,11,1,1,1,1,1,12
11,18,18,4,18,18,11,18,18,4,4,24,5,22,12,18,18,4,18,18,18,18,19,19,18,18,18,4,18,18,18,18,12
11,18,18,18,18,18,18,18,18,18,18,24,15,22,19,4,4,10,19,19,19,4,18,19,18,18,18,4,18,18,18,4,11
11,18,18,18,18,18,18,18,18,18,18,18,4,18,12,19,19,18,18,18,28,18,18,18,18,18,18,18,4,18,18,18,11
11,18,18,15,18,12,18,18,18,18,18,0,4,18,19,19,19,18,18,4,18,18,18,4,18,18,18,18,18,18,4,18,11
11,18,18,18,18,12,18,18,18,18,4,4,18,18,18,19,18,18,19,18,18,18,18,18,18,18,18,18,18,18,18,18,11
11,18,4,4,18,18,18,18,18,18,18,18,18,18,18,19,19,19,4,19,18,18,18,18,18,18,18,18,18,18,18,18,11
11,1,1,1,4,4,11,18,18,18,18,18,18,18,11,18,18,19,11,18,18,18,18,18,18,18,18,18,18,18,18,18,11
11,18,18,18,18,18,18,18,18,18,18,18,18,18,26,18,18,18,1,18,18,18,4,18,18,18,4,4,18,18,18,18,11
11,18,18,18,4,18,18,18,29,29,18,18,4,18,1,18,18,18,1,18,4,4,4,18,18,4,18,12,12,18,4,4,11
11,18,18,18,18,4,18,18,18,18,18,18,18,18,1,18,18,18,1,18,4,18,18,18,18,18,18,18,4,18,18,18,11
11,18,18,18,18,18,18,18,4,18,4,18,18,18,26,18,18,18,1,18,18,4,18,18,10,18,18,18,10,12,18,18,11
11,18,18,18,18,18,4,4,4,18,18,18,18,18,1,18,18,18,1,18,18,18,18,18,18,18,18,18,18,18,18,18,11
11,11,11,11,11,11,11,11,11,11,11,11,11,11,11,18,18,18,11,11,11,11,11,11,11,11,11,11,11,11,11,11,11
endlayer

layer
15,12,12,12,12,12,10,12,12,12,10,12,10,15,12,10,12,12,12,12,12,12,10,10,12,12,10,12,12,12,12,12,12
10,31,9,9,9,0,9,9,9,0,0,30,30,30,13,0,0,9,0,9,9,0,29,29,9,0,9,0,0,0,13,13,22
10,32,0,0,0,0,0,0,0,0,0,9,0,0,0,0,0,0,0,0,0,0,0,0,0,0,0,0,0,0,13,13,12
12,13,13,0,0,0,0,0,0,0,0,0,0,0,0,0,0,0,0,0,0,0,0,0,0,0,0,0,0,0,0,0,10
12,13,13,13,0,0,0,0,0,0,0,0,0,0,0,0,0,0,0,0,0,0,0,0,0,0,0,0,0,0,0,8,10
12,13,13,13,13,34,0,34,0,35,34,34,0,37,36,34,34,35,0,34,34,34,0,0,0,0,0,34,34,0,0,33,12
12,25,12,12,12,10,12,12,12,12,10,10,12,10,10,12,25,12,12,12,12,12,12,38,0,38,12,10,10,12,12,12,12
10,41,0,0,29,29,5,0,41,0,0,8,12,40,40,40,40,40,40,10,39,0,0,0,0,9,5,29,29,0,0,5,12
10,0,41,42,0,0,5,0,0,41,0,0,12,10,12,43,43,43,12,12,12,0,0,0,0,0,5,42,0,0,41,0,12
10,5,42,0,0,0,5,0,0,0,0,41,0,0,0,43,43,43,0,0,0,0,0,0,0,0,5,0,0,0,0,5,12
12,5,0,42,0,0,12,0,0,0,0,0,0,0,0,0,0,0,0,0,0,0,0,0,0,0,12,0,0,42,0,5,10
12,0,0,0,0,0,45,0,0,0,0,0,0,0,41,0,0,0,0,0,0,0,0,0,0,0,44,0,0,0,0,0,12
10,46,46,46,41,41,12,12,47,35,0,49,49,49,0,48,0,0,0,0,0,0,0,0,47,10,10,41,0,46,46,46,10
12,12,12,12,12,12,12,12,12,47,0,49,49,49,0,0,0,0,0,50,0,0,50,47,12,12,12,12,12,12,10,12,10
12,5,0,0,29,29,12,12,47,0,0,49,49,49,0,0,0,0,0,0,0,0,0,0,47,12,10,41,41,0,29,29,12
12,41,41,42,0,41,5,0,0,0,0,51,0,51,0,0,0,0,41,0,42,0,0,0,0,0,5,0,0,0,0,0,12
10,5,0,0,0,0,5,0,0,0,52,52,52,52,52,0,0,0,0,42,0,0,0,0,0,0,5,0,42,0,0,0,25
12,5,0,0,0,42,5,0,42,0,52,10,0,12,52,0,0,0,0,0,42,0,0,0,0,0,5,0,0,0,41,5,12
12,0,42,0,41,0,12,0,0,0,52,52,52,52,52,5,0,0,0,0,0,0,0,0,0,0,12,0,0,0,0,5,12
12,0,42,0,0,0,55,0,0,0,52,52,54,52,10,52,41,0,0,0,42,0,0,0,0,42,53,0,0,42,0,0,10
12,46,46,46,41,41,12,25,47,0,52,52,52,52,52,5,0,0,0,35,0,0,0,0,47,10,12,0,0,46,46,46,12
12,10,10,12,12,10,25,12,10,47,52,12,0,10,52,0,0,0,0,50,0,0,50,47,12,12,12,12,10,12,10,12,12
12,5,0,57,29,29,12,12,47,9,52,52,52,52,52,0,0,56,0,0,0,0,0,0,47,10,10,5,41,46,46,46,12
10,0,41,0,0,0,5,0,0,0,0,51,0,51,0,0,0,0,41,0,0,0,0,0,0,0,5,0,0,42,0,41,12
10,5,0,42,0,0,5,0,0,0,0,0,0,0,0,0,0,0,0,0,0,0,0,0,0,0,5,0,0,0,0,41,12
10,5,0,0,42,0,5,0,0,0,56,0,0,0,0,0,0,0,0,0,0,0,0,0,0,0,5,0,0,41,42,5,12
12,0,0,0,0,0,12,0,0,0,0,0,0,41,0,0,0,0,0,0,0,46,6,0,0,0,10,42,0,0,42,5,12
10,0,42,0,0,0,55,0,0,0,0,0,0,0,0,0,0,0,0,46,46,59,0,0,0,0,44,0,41,0,0,0,58
12,46,46,46,0,41,10,10,47,0,0,0,0,0,0,0,0,0,42,59,60,59,0,0,47,12,10,0,0,0,29,29,12
12,12,12,10,12,12,12,12,12,47,35,0,0,0,61,0,0,0,0,60,60,60,0,47,10,12,10,12,10,12,12,12,12
12,5,2,41,0,2,12,12,47,0,41,0,0,0,0,0,0,48,0,42,0,0,0,0,47,12,10,41,0,46,46,46,10
12,0,0,0,0,0,5,9,0,0,0,0,0,0,0,0,0,0,0,0,0,0,0,0,0,0,5,41,0,0,42,41,10
12,29,42,0,60,42,5,0,0,42,0,0,0,0,0,0,0,0,0,0,0,0,0,0,42,0,5,0,41,0,0,5,12
12,29,42,0,60,42,5,42,42,42,0,0,0,0,0,0,0,0,0,41,0,42,0,41,0,0,5,0,0,0,41,5,12
12,29,0,0,60,42,12,42,0,0,0,57,0,0,0,0,0,0,0,0,0,0,42,62,0,0,10,0,0,42,0,0,12
25,0,41,5,0,42,55,42,0,12,0,0,10,0,0,0,0,0,0,0,10,0,0,10,0,42,53,0,0,0,29,29,10
10,12,12,10,12,12,12,63,63,12,64,64,10,63,12,63,0,63,10,63,12,64,0,12,63,63,10,12,10,12,12,10,10
12,12,12,0,0,0,0,0,0,0,0,0,0,0,12,38,0,38,12,0,0,0,0,0,0,0,0,0,0,0,0,0,12
12,10,12,0,41,0,42,0,0,0,42,0,41,0,10,0,0,0,12,5,41,0,42,0,0,42,0,0,0,0,41,41,12
12,10,12,0,0,41,0,0,0,0,0,0,0,29,12,0,0,65,12,5,42,0,42,42,0,0,0,0,42,0,0,42,12
10,12,10,0,0,0,0,0,42,0,0,0,0,5,10,12,0,12,12,0,0,41,0,42,0,0,0,0,0,0,0,0,12
10,12,12,0,0,5,41,41,41,0,0,0,5,5,12,0,0,0,10,5,0,0,46,46,46,0,0,0,0,0,29,29,10
12,12,12,12,12,10,10,12,12,12,12,12,10,10,12,0,0,0,24,10,12,10,12,12,12,10,12,12,12,12,10,12,12
endlayer

layer
12,12,10,12,10,12,12,12,12,10,12,12,10,12,12,12,10,12,12,10,12,10,12,12,12,12,10,10,12,12,12,10,12
12,0,0,9,9,0,9,9,9,0,0,9,30,9,9,0,0,0,0,0,0,0,9,0,9,0,9,0,0,0,13,13,12
12,0,0,0,0,0,0,0,0,0,0,0,0,0,0,0,0,0,0,0,0,0,0,0,0,0,0,0,0,0,0,13,25
12,0,0,0,0,0,0,0,0,0,0,0,0,0,0,0,0,0,0,0,0,0,0,0,0,0,0,0,0,0,0,13,12
12,13,13,0,0,0,0,0,0,0,0,0,0,0,0,0,0,0,0,0,0,0,0,0,0,0,0,0,0,0,0,8,12
12,6,13,13,13,34,0,34,0,35,34,34,0,34,0,34,34,35,0,34,34,34,0,0,34,34,0,34,34,0,0,33,10
12,12,5,25,10,10,12,12,12,12,12,10,10,12,10,12,10,12,12,12,10,12,5,38,0,12,10,5,12,10,10,12,12
12,0,0,0,0,0,5,0,0,0,0,0,12,40,67,67,67,67,67,40,66,0,0,0,0,9,5,0,0,0,0,5,12
12,0,0,0,0,0,5,0,0,0,0,0,10,12,43,0,0,0,43,12,38,0,0,0,0,0,5,0,0,0,0,0,12
12,5,0,0,0,0,5,0,0,0,0,0,0,0,43,0,0,0,43,0,0,0,0,0,0,0,5,0,0,0,0,68,12
10,5,0,0,0,0,10,70,0,0,0,0,0,0,0,0,0,0,0,0,0,0,0,0,0,69,12,0,0,0,0,68,12
12,0,0,0,0,0,71,0,0,0,0,0,0,0,0,0,0,0,0,0,0,0,0,0,0,0,71,0,0,0,0,0,12
12,0,72,0,0,0,10,12,24,0,0,5,5,5,0,0,0,0,0,0,0,0,0,0,22,10,12,0,0,0,0,0,12
10,12,73,12,12,12,12,12,12,24,0,5,5,5,0,0,0,0,0,50,0,0,50,22,12,12,12,10,12,12,10,10,12
12,5,0,0,0,0,10,12,24,0,0,5,5,5,0,0,0,0,0,0,0,0,0,0,22,12,22,0,0,0,0,0,25
12,0,0,0,0,0,5,0,0,0,0,51,0,51,0,0,0,0,0,0,0,0,0,0,0,0,5,0,0,0,0,8,12
12,5,0,0,0,0,5,0,0,0,0,51,0,51,0,0,0,0,0,0,0,0,0,0,0,0,5,0,0,0,0,0,12
12,5,0,0,0,0,5,0,0,0,0,0,0,0,0,0,0,0,0,0,0,0,0,0,0,0,5,0,0,0,0,5,12
12,0,0,0,0,0,10,70,0,0,0,0,0,0,5,5,0,0,0,0,0,0,0,0,0,69,12,0,0,0,0,5,12
12,0,0,0,0,0,71,0,0,0,0,0,0,0,5,75,0,0,0,0,0,0,0,0,0,0,74,0,0,0,0,0,10
12,0,0,0,0,0,12,10,24,0,0,0,0,0,5,5,0,0,0,35,0,0,0,0,22,12,12,0,0,0,0,0,10
12,10,12,12,10,12,10,12,12,24,0,0,0,0,0,0,0,0,0,50,0,0,50,22,12,12,12,10,12,12,12,10,25
12,5,0,0,0,0,12,10,24,0,0,51,0,51,0,0,0,0,0,0,0,0,0,0,22,12,10,5,0,0,0,0,12
12,0,0,0,0,0,5,0,0,0,0,51,0,51,0,0,0,0,0,0,0,0,0,0,0,0,5,0,0,0,0,0,12
10,5,0,0,0,0,5,0,0,0,0,0,0,0,0,0,0,0,0,0,0,46,0,0,0,0,5,0,0,0,0,0,12
12,5,0,0,0,0,5,0,0,0,0,0,0,0,0,0,0,0,0,46,46,59,0,0,0,0,5,0,0,0,0,5,12
12,0,0,0,0,0,12,70,0,0,0,0,0,0,0,0,0,0,0,59,60,59,6,0,0,69,25,0,0,0,0,5,12
12,0,0,0,0,0,74,0,0,0,0,0,0,0,0,0,0,0,0,60,0,60,0,0,0,0,71,0,0,0,0,0,12
12,0,0,0,0,0,12,12,24,0,0,0,0,0,0,0,0,0,0,0,0,0,0,0,22,10,12,0,0,0,0,5,12
10,12,12,12,73,12,10,12,10,24,35,0,0,0,0,0,0,0,0,0,0,0,0,22,12,12,12,12,10,12,12,12,12
12,5,0,0,0,0,10,12,24,0,0,0,0,0,0,0,0,0,0,0,0,0,0,0,22,12,10,0,0,0,0,0,10
25,0,0,0,0,0,5,9,0,0,0,0,0,0,0,0,0,0,0,0,0,0,0,0,0,0,5,0,0,0,0,0,10
10,0,0,0,0,0,5,0,0,0,0,0,0,0,0,0,0,0,0,0,0,0,0,0,0,0,5,0,0,0,0,5,12
10,0,0,0,0,0,5,0,0,0,0,0,0,0,0,0,0,0,0,0,0,0,0,0,0,0,5,0,0,0,0,5,10
12,0,0,0,0,0,10,70,0,0,0,0,0,0,0,0,0,0,0,0,0,0,0,0,0,69,10,0,0,0,0,0,10
10,0,0,5,0,0,71,0,0,12,0,0,12,0,76,0,0,0,76,0,12,0,0,10,6,0,74,0,0,0,34,0,12
12,10,10,12,10,10,10,5,5,12,74,71,12,5,12,63,0,63,12,5,12,74,0,10,5,5,12,12,12,12,12,12,10
12,60,60,0,0,0,0,0,0,0,0,0,0,0,10,38,0,38,10,0,0,0,0,0,0,0,0,0,0,0,0,0,10
12,60,60,0,0,0,0,0,0,0,0,0,0,0,12,0,0,0,10,5,0,0,46,0,0,0,0,0,0,0,0,0,12
10,60,60,0,0,0,0,0,0,0,0,0,0,0,12,0,0,0,12,5,0,0,46,0,0,0,0,0,0,0,0,68,12
10,60,60,0,0,0,0,0,0,0,0,0,0,5,12,12,0,10,12,0,0,0,46,0,0,0,0,0,0,0,0,0,12
10,60,60,0,0,5,0,0,77,77,77,0,5,5,12,0,0,0,10,5,0,0,0,0,0,0,0,0,0,0,0,0,22
12,12,12,12,12,12,12,10,12,12,10,10,12,10,12,0,0,0,12,12,12,12,12,12,12,12,10,12,10,10,12,12,12
endlayer

layer
10,12,10,12,12,10,12,12,12,10,12,12,12,12,12,12,10,12,12,12,25,12,10,12,12,12,12,12,12,12,12,12,58
10,0,0,9,9,0,9,9,0,0,0,9,0,9,9,0,0,0,0,0,0,0,9,78,9,0,9,0,0,0,0,13,12
12,0,0,0,0,0,0,0,0,0,0,0,0,0,0,0,0,0,0,0,0,0,0,0,0,0,0,0,0,0,0,13,12
10,0,0,0,0,0,0,0,0,0,0,0,0,0,0,0,0,0,0,0,0,0,0,0,0,0,0,0,0,0,0,8,25
12,13,0,0,0,0,0,0,0,0,0,0,0,0,0,0,0,0,0,0,0,0,0,0,0,0,0,0,0,0,0,8,12
10,13,13,13,0,0,0,0,0,35,34,34,34,34,0,0,0,35,79,34,34,34,34,0,34,34,0,34,34,0,0,34,12
12,12,12,12,12,12,12,10,12,12,12,10,10,12,10,12,22,10,12,12,22,12,12,5,12,12,12,12,12,5,12,12,12
10,0,0,0,0,0,5,0,0,0,0,0,10,40,67,67,67,67,67,40,12,0,0,0,0,0,5,0,0,0,0,5,12
10,0,0,0,0,0,5,0,0,0,0,0,12,43,0,0,0,0,0,43,38,0,0,0,0,0,5,0,0,0,0,0,10
12,80,0,0,0,0,5,0,0,0,0,0,0,43,0,0,0,0,0,43,0,0,0,0,0,0,5,0,0,0,0,5,10
12,80,0,0,0,0,12,0,0,0,0,0,0,0,0,0,0,0,0,0,0,0,0,0,0,81,10,0,0,0,0,5,25
10,0,0,0,0,0,5,0,0,0,0,0,0,0,0,0,0,0,0,0,0,0,0,0,0,0,5,0,0,0,0,0,12
12,0,0,0,0,0,10,12,0,0,0,5,5,5,0,0,0,0,0,0,0,0,0,0,0,12,82,0,0,0,0,0,12
12,10,12,12,10,12,12,12,10,0,0,5,5,5,0,0,0,0,0,50,0,2,50,0,12,12,12,12,12,12,12,12,10
12,5,0,0,0,0,12,12,0,0,0,5,5,5,0,0,0,0,0,0,0,0,0,0,0,10,12,0,0,0,0,0,10
12,0,0,0,0,0,5,0,0,0,0,51,51,51,0,0,0,0,0,0,0,0,0,0,0,0,5,0,0,0,0,8,12
12,80,0,0,0,0,5,0,0,0,0,0,0,0,0,0,0,0,0,0,0,0,0,0,0,0,5,0,0,0,0,0,12
10,80,0,0,0,0,5,0,0,0,0,0,0,0,0,0,0,0,0,0,0,0,0,0,0,0,5,0,0,0,0,68,10
12,0,0,0,0,0,12,0,0,0,0,0,0,0,0,0,0,0,0,0,0,0,0,0,0,81,10,0,0,0,0,68,12
10,0,0,0,0,0,5,0,0,0,0,0,0,0,0,0,0,0,0,0,0,0,0,0,0,0,5,0,0,0,0,0,12
12,0,0,0,0,0,12,10,0,0,0,0,0,0,0,0,0,0,0,35,0,0,0,0,2,12,12,0,0,0,0,0,12
12,12,12,10,63,10,12,12,10,0,0,0,0,0,0,83,0,0,0,50,0,0,50,0,10,12,12,12,12,12,12,12,12
12,5,0,0,0,0,12,10,0,0,0,51,51,51,0,0,0,0,0,0,46,46,0,0,0,12,12,5,0,0,0,0,12
10,0,0,0,0,0,5,0,0,0,0,0,0,0,0,0,0,0,0,46,46,59,0,0,0,0,5,0,0,0,0,0,10
12,80,0,0,0,0,5,0,0,0,0,0,0,0,0,0,0,0,0,59,60,59,0,0,0,0,5,0,0,0,0,0,12
12,80,0,0,0,0,5,0,0,0,0,0,0,0,0,0,0,0,0,60,0,60,0,0,0,0,5,0,0,0,0,68,12
63,0,0,0,0,0,12,0,0,0,0,0,0,0,0,0,0,0,0,0,0,0,0,0,0,0,17,0,0,0,0,68,12
25,0,0,0,0,0,5,0,0,0,0,0,0,0,0,0,0,0,0,0,0,0,0,0,0,0,5,0,0,0,0,0,12
12,0,0,0,0,0,12,12,0,0,0,0,0,0,0,0,0,0,0,0,0,0,0,0,0,12,12,0,0,0,0,5,12
12,12,12,12,10,25,12,10,12,0,35,0,0,0,0,0,0,0,0,0,0,0,0,0,12,10,10,12,12,12,12,12,10
12,5,0,0,0,0,10,10,0,0,0,0,0,0,0,0,0,0,0,0,0,0,0,0,0,12,10,0,0,0,0,0,10
12,0,0,0,0,0,5,9,0,0,0,0,0,0,0,0,0,0,0,0,0,0,0,0,0,0,5,0,0,0,0,0,12
12,80,0,0,0,0,5,0,0,0,0,0,0,0,0,0,0,0,0,0,0,0,0,0,0,0,5,0,0,0,0,68,12
12,80,0,0,0,0,5,0,0,0,0,0,0,0,0,0,0,0,0,0,0,0,0,0,0,0,5,0,0,0,0,68,12
10,80,0,0,0,0,12,0,0,0,0,0,0,0,0,0,0,0,0,0,0,0,0,84,0,0,12,0,0,0,0,81,12
12,0,0,5,77,0,5,0,0,12,0,0,12,0,0,0,0,0,0,0,10,0,0,12,6,0,5,0,0,0,34,0,12
12,12,12,12,12,12,10,5,5,12,5,5,12,5,12,63,0,63,10,5,10,5,5,12,5,5,12,25,10,12,12,12,10
10,0,0,0,0,0,0,0,0,0,0,0,0,0,12,38,0,38,10,0,0,0,0,0,0,0,0,0,0,9,0,0,12
12,0,0,0,0,0,0,0,0,0,0,0,0,0,10,0,0,0,12,80,0,0,5,0,0,0,0,0,0,0,0,0,10
5,0,0,0,0,0,0,0,0,0,0,0,0,0,12,2,0,0,12,80,0,0,0,0,0,0,0,0,0,0,0,0,5
12,0,0,0,0,0,0,0,0,0,0,0,0,5,12,12,2,12,12,0,0,0,5,0,0,0,0,0,0,0,0,0,12
12,0,0,0,0,77,0,0,0,0,0,34,5,5,12,0,0,0,10,5,0,0,60,60,60,0,0,0,0,0,0,0,10
12,10,10,12,12,10,12,10,12,10,10,12,12,10,10,0,0,0,10,10,10,12,10,12,12,12,12,12,10,12,12,12,15
endlayer

layer
10,12,12,12,12,12,25,12,12,10,10,12,12,12,10,12,12,12,12,12,10,12,12,12,12,12,12,10,12,12,12,12,12
12,0,0,9,9,0,9,9,0,0,0,0,0,0,0,0,0,0,0,0,0,0,9,9,9,0,9,0,0,0,0,0,12
10,6,0,0,0,0,0,0,0,0,0,0,0,0,0,0,0,0,0,0,0,0,0,0,0,0,0,0,0,0,0,8,12
12,0,0,0,0,0,0,0,0,0,0,0,0,0,0,0,0,0,0,0,0,0,0,0,0,0,0,0,0,0,0,8,12
12,0,0,0,0,0,0,0,0,0,0,0,0,0,0,0,0,0,0,0,0,0,0,0,0,0,0,0,0,0,0,8,12
10,13,13,0,0,0,0,0,0,35,34,34,34,0,0,0,0,35,34,34,34,34,34,0,0,34,0,0,0,0,0,0,10
12,12,10,12,5,12,12,10,12,12,12,12,12,12,10,23,12,12,12,12,12,12,12,5,12,10,12,10,12,5,12,10,10
25,0,0,0,0,0,5,0,0,0,0,0,10,40,67,67,67,67,67,40,12,0,0,0,0,0,5,0,0,0,0,5,12
12,0,0,0,0,0,5,0,0,0,0,0,10,43,0,0,0,0,0,43,10,0,0,0,0,0,5,0,0,0,0,0,12
12,0,0,0,0,0,5,0,0,0,0,0,0,43,0,0,0,0,0,43,0,0,0,0,0,0,5,0,0,0,0,5,10
10,0,0,0,0,0,12,0,0,0,0,0,0,0,0,0,0,0,0,0,0,0,0,0,0,0,12,0,0,0,0,5,12
85,0,0,0,0,0,5,0,0,0,0,0,0,0,0,0,0,0,0,0,0,0,0,0,0,0,5,0,0,0,0,0,12
10,0,0,0,0,0,10,10,0,0,0,5,5,5,0,0,0,0,46,46,46,46,46,46,46,12,12,0,0,0,0,0,12
10,12,10,12,12,12,12,12,5,0,0,5,5,5,0,0,0,0,46,50,46,46,50,46,10,10,12,12,12,15,12,10,10
10,5,0,0,0,0,12,10,86,0,0,5,5,5,0,0,0,0,46,46,46,46,12,46,46,10,12,0,0,0,0,0,12
12,0,0,0,0,0,5,0,0,0,0,0,0,0,0,0,0,0,46,46,87,46,46,46,46,46,5,0,0,0,0,0,12
12,0,0,0,0,0,5,0,0,0,0,0,0,0,0,0,0,0,46,46,46,46,46,46,46,46,5,0,0,0,0,0,12
12,0,0,0,0,0,5,0,0,0,0,0,0,0,0,0,0,0,46,46,88,46,46,46,46,46,5,0,0,0,0,0,12
63,0,0,0,0,0,12,0,0,0,0,0,0,0,0,0,0,0,46,46,46,46,46,46,46,46,12,0,0,0,0,0,12
12,0,0,0,0,0,5,0,0,0,0,0,0,0,0,0,0,0,46,46,88,46,46,46,46,46,5,0,0,0,0,0,12
25,0,0,0,0,0,12,12,0,0,0,0,0,0,0,0,0,0,46,46,46,46,46,46,46,12,12,0,0,0,0,0,12
12,12,10,12,10,12,12,5,10,0,0,0,0,0,0,5,0,0,46,50,46,46,50,46,10,23,10,10,12,25,10,12,12
12,5,0,0,0,0,12,5,0,0,0,0,0,0,0,0,0,0,46,59,60,60,59,46,46,25,12,5,0,0,0,0,12
12,0,0,0,0,0,5,0,0,0,0,0,0,0,0,0,0,0,0,60,0,60,0,0,0,0,5,0,0,0,0,8,10
10,0,0,0,0,0,5,0,0,0,0,0,0,0,0,0,0,0,0,0,0,0,0,0,0,0,5,0,0,0,0,0,12
10,0,0,0,0,0,5,0,0,0,0,0,0,0,0,0,0,0,0,0,0,0,0,0,0,0,5,0,0,0,0,0,23
12,0,0,0,0,0,12,0,0,0,0,0,0,0,0,0,0,0,0,0,0,0,0,0,0,0,12,0,0,0,0,8,12
12,0,0,0,0,0,5,0,0,0,0,0,0,0,0,0,0,0,0,0,0,0,0,0,0,0,5,0,0,0,0,0,12
10,0,0,0,0,0,12,12,0,0,35,0,0,0,0,0,0,0,0,0,0,0,0,0,0,12,12,0,0,0,0,5,12
12,10,12,12,12,10,12,10,12,86,35,35,0,0,0,0,0,0,0,0,0,0,0,81,12,12,12,12,12,12,12,10,12
10,5,0,0,0,0,12,12,0,0,0,0,0,0,0,0,0,0,0,0,0,0,0,0,0,10,12,0,0,0,0,0,10
12,0,0,0,0,0,5,0,0,0,0,0,0,0,0,0,0,0,0,0,0,0,0,0,0,0,5,0,0,0,0,0,12
12,0,0,0,0,0,5,0,0,0,0,0,0,0,0,0,0,0,0,0,0,0,0,0,0,0,5,0,0,0,0,0,12
12,0,0,0,0,0,5,0,0,0,0,0,0,0,0,0,0,0,0,0,0,0,0,0,0,0,5,0,0,0,0,0,12
12,0,0,0,0,0,12,0,0,0,0,0,0,0,0,0,0,0,0,0,0,0,0,0,0,0,12,0,0,0,0,0,12
12,0,0,5,0,0,5,0,0,12,0,0,10,0,73,73,73,73,73,2,12,0,0,12,0,0,5,0,0,0,34,0,12
10,10,10,12,10,12,10,5,5,12,5,5,12,5,12,12,12,10,12,5,12,5,5,12,5,5,10,10,10,12,12,12,12
10,0,0,0,0,0,0,0,0,0,0,0,0,0,12,12,10,10,12,0,0,0,0,0,0,0,0,0,0,9,0,0,12
12,0,0,0,0,0,0,0,0,0,0,0,0,0,12,12,12,10,12,0,0,0,5,0,0,0,0,0,0,0,0,0,58
5,0,0,0,0,0,0,0,0,0,0,0,0,8,12,12,12,12,12,0,0,0,0,0,0,0,0,0,0,0,0,0,5
12,0,0,0,0,0,0,0,0,0,0,0,0,5,12,12,10,10,12,0,0,0,5,0,0,0,0,0,0,0,0,0,12
12,0,0,0,0,0,0,0,0,0,0,34,5,5,12,12,12,10,10,5,0,0,0,0,0,0,0,0,0,0,0,0,10
25,12,12,12,12,10,10,12,12,12,10,12,10,12,17,12,12,12,12,12,12,12,12,12,12,10,12,12,12,12,10,12,10
endlayer

layer
12,12,10,12,12,10,12,10,12,12,10,82,12,12,12,12,12,12,12,10,10,10,12,12,12,12,12,12,12,12,10,12,12
10,2,0,0,9,0,0,0,0,35,0,0,0,0,0,0,0,35,0,0,0,0,0,2,9,0,0,0,0,0,0,0,12
12,0,0,0,0,0,0,0,0,35,0,0,0,0,0,0,0,35,0,0,0,0,0,0,0,0,0,0,0,0,0,8,10
12,0,0,0,0,0,0,0,0,35,0,0,0,0,0,0,0,35,0,0,0,0,0,0,0,0,0,0,0,0,0,8,12
12,0,0,0,0,0,0,0,0,35,0,0,0,0,0,0,0,35,0,0,0,0,0,0,0,0,0,0,0,0,0,8,12
10,0,0,0,0,0,0,0,0,35,2,0,0,0,0,0,0,35,0,0,0,0,34,0,0,0,0,0,0,0,0,0,12
12,10,10,12,12,10,12,10,12,10,12,10,12,12,10,12,12,12,10,12,10,10,10,10,12,12,12,12,12,12,12,12,12
10,0,0,0,0,0,73,0,0,0,0,0,10,40,67,67,67,67,67,40,10,2,0,0,0,2,73,0,0,0,0,5,12
12,0,0,0,0,0,73,0,0,0,0,0,10,43,89,0,0,0,89,43,10,0,0,0,0,0,73,0,0,0,0,0,10
10,0,0,0,0,0,73,0,0,0,0,0,2,43,90,0,0,0,90,43,2,0,0,0,0,0,73,0,0,0,0,5,12
12,0,0,0,0,0,73,0,0,0,0,0,0,0,0,0,0,0,0,0,0,0,0,0,0,0,73,0,0,0,0,5,12
12,0,0,0,0,0,73,0,0,0,0,0,0,0,0,0,0,0,0,0,0,0,0,0,0,0,73,0,0,0,0,0,12
10,0,0,0,0,0,12,10,0,0,0,0,0,0,0,0,0,0,0,0,0,0,0,0,0,12,12,0,0,0,0,2,12
10,12,12,12,12,10,12,12,5,0,0,0,51,0,0,0,0,0,0,50,51,51,50,0,10,12,10,12,15,12,10,12,10
10,5,0,0,0,0,10,12,0,0,0,0,0,0,0,0,0,0,0,0,0,0,10,0,9,25,12,2,0,0,0,2,10
12,0,0,0,0,0,73,0,0,0,0,0,0,0,0,0,0,0,0,42,0,0,47,50,0,0,73,0,0,0,0,0,12
12,0,0,0,0,0,73,0,0,0,0,0,0,0,0,0,0,0,0,0,0,0,0,0,0,0,73,0,0,0,0,0,12
12,0,0,0,0,0,73,0,0,0,0,0,0,0,0,0,0,0,0,0,0,0,0,50,0,0,73,0,0,0,0,0,12
12,0,0,0,0,0,73,0,0,0,0,0,0,0,0,0,0,0,0,42,0,42,0,0,91,0,73,0,0,0,0,0,12
10,0,0,0,0,0,73,0,0,0,0,0,0,0,0,0,0,0,0,0,0,0,0,50,0,0,73,0,0,0,0,0,12
12,2,0,0,0,0,12,12,2,0,0,0,0,0,0,0,0,0,0,0,0,0,0,0,0,12,12,0,0,0,0,0,12
12,12,12,12,12,12,12,12,12,0,0,6,0,0,0,5,0,0,0,50,0,0,50,0,12,10,12,10,12,12,12,12,12
10,5,0,0,0,0,10,12,0,0,0,0,0,0,0,0,0,0,0,0,0,0,0,0,0,82,12,5,0,0,0,8,12
63,0,0,0,0,0,73,0,0,0,0,0,0,0,0,0,0,0,0,0,0,0,0,0,0,0,73,0,0,0,0,8,12
12,0,0,0,0,0,73,0,0,0,0,0,0,0,0,0,0,0,0,0,0,0,0,0,0,0,73,0,0,0,0,8,25
12,0,0,0,0,0,73,0,0,0,0,0,0,0,0,0,0,0,0,0,0,0,0,0,0,0,73,0,0,0,0,0,12
12,0,0,0,0,0,73,0,0,0,0,0,0,0,0,0,0,0,0,0,0,0,0,0,0,0,73,0,0,0,0,0,10
10,0,0,0,0,0,73,0,0,0,0,0,0,0,0,0,0,0,0,0,0,0,0,0,0,0,73,0,0,0,0,0,10
12,2,0,0,0,0,12,10,2,0,0,0,0,0,0,0,0,0,0,0,0,0,0,0,0,12,10,0,0,0,0,5,12
12,12,10,10,12,12,25,12,12,0,0,0,0,0,0,0,0,0,0,0,0,0,0,0,10,12,12,12,12,12,12,12,12
12,5,0,0,0,0,10,12,0,0,0,0,0,0,0,0,0,0,0,0,0,0,0,0,0,12,12,0,0,0,0,2,10
12,0,0,0,0,0,73,0,0,0,0,0,0,0,0,0,0,0,0,0,0,0,0,0,0,0,73,0,0,0,0,0,12
12,0,0,0,0,0,73,0,0,0,0,0,0,0,0,0,0,0,0,0,0,0,0,0,0,0,73,0,0,0,0,0,12
12,0,0,0,0,0,73,0,0,0,0,0,0,0,0,0,0,0,0,0,0,0,0,0,0,0,73,0,0,0,0,0,10
12,0,0,0,0,0,73,0,0,0,0,0,0,0,0,0,0,0,0,0,0,0,0,0,0,0,73,0,0,0,0,0,10
12,2,0,5,0,0,73,0,0,12,0,0,10,73,73,73,73,73,73,73,12,0,0,10,0,0,73,0,0,0,0,0,25
12,12,12,12,12,10,12,73,73,10,73,73,12,73,12,12,12,10,82,73,12,73,73,12,73,73,10,12,10,12,12,12,12
10,0,0,0,0,0,0,0,0,0,0,0,0,0,25,0,0,0,12,2,0,0,0,0,0,0,0,0,0,0,0,2,12
12,0,0,0,0,0,0,0,0,0,0,0,0,0,12,0,0,0,10,0,0,0,5,0,0,0,0,0,0,0,0,0,12
12,0,0,0,0,0,0,0,0,0,0,0,0,8,12,0,0,0,12,0,0,0,0,0,0,0,0,0,0,0,0,0,12
12,0,0,0,0,0,0,0,0,0,0,0,0,5,12,2,0,0,23,0,0,0,5,0,0,0,0,0,0,0,0,0,12
12,0,0,0,0,0,0,0,0,0,34,34,5,5,12,0,0,0,12,5,0,0,0,0,0,2,0,0,0,0,0,0,12
10,12,10,10,12,12,10,10,12,10,10,12,12,12,12,12,12,12,10,10,10,12,12,12,12,12,15,12,12,12,10,10,12
endlayer

layer
12,10,12,12,12,12,10,12,10,12,12,12,12,12,10,12,12,12,10,12,10,10,12,12,12,12,12,12,12,12,82,12,12
10,10,12,12,12,12,12,12,25,12,12,12,12,12,12,10,10,12,10,12,12,12,12,12,10,12,12,12,12,10,12,12,12
12,12,12,10,12,12,12,12,12,12,10,12,10,10,12,10,12,12,12,12,12,10,12,12,10,10,12,10,12,12,12,12,12
12,12,12,12,10,12,12,12,12,12,10,12,12,12,12,12,10,12,12,10,12,12,10,12,12,10,12,12,10,12,10,12,12
12,10,10,12,12,10,10,10,12,12,12,12,10,10,12,12,10,12,10,12,12,12,12,12,12,12,12,10,12,10,12,10,12
10,12,12,17,12,12,25,12,24,12,12,12,10,12,12,10,12,12,12,12,12,12,12,12,12,12,10,10,12,12,10,10,10
12,12,10,12,12,12,10,10,24,12,15,25,10,58,12,10,10,10,22,12,10,10,12,10,12,10,12,12,12,12,12,12,12
12,12,12,10,12,12,12,12,10,12,12,10,12,40,67,67,67,67,67,40,12,10,12,12,10,10,10,12,12,12,10,10,23
10,12,12,12,10,10,12,10,52,52,52,52,43,43,43,89,89,89,43,43,43,52,52,52,52,10,12,12,12,12,12,10,12
12,85,12,5,5,12,12,10,52,0,0,0,43,0,43,90,90,90,43,0,43,0,0,0,52,12,10,10,12,12,12,12,12
12,12,12,5,5,12,10,12,52,0,0,0,0,0,0,0,0,0,0,0,0,0,0,0,52,12,12,10,12,12,12,12,12
12,10,12,25,12,12,10,10,52,0,0,0,0,0,0,0,0,0,0,0,0,0,0,0,52,12,10,10,12,12,12,12,10
12,10,12,85,10,12,12,12,52,52,0,0,0,0,0,0,0,0,0,0,0,0,0,52,52,12,12,10,12,12,12,12,10
10,12,25,12,10,10,12,24,12,52,0,0,92,0,0,0,0,0,0,0,0,0,0,52,12,12,85,12,10,12,12,12,12
24,12,12,12,10,12,10,12,52,52,0,0,0,0,0,0,0,0,0,0,0,0,12,52,52,12,10,12,12,12,12,12,12
12,12,10,12,10,12,10,12,52,0,0,0,0,0,0,0,0,0,0,0,51,0,93,50,52,10,12,17,12,10,12,10,10
12,12,10,12,12,12,12,12,52,0,0,0,0,0,0,0,0,0,0,0,0,0,0,0,52,12,12,82,12,10,12,10,10
10,12,12,5,12,12,12,12,52,0,0,0,0,0,0,0,0,0,0,0,51,0,0,50,52,12,12,10,12,12,12,10,25
12,10,12,12,12,12,10,10,52,0,0,0,0,0,0,0,0,0,0,0,0,0,0,0,52,12,12,12,5,12,12,10,82
12,10,12,12,10,10,12,12,52,0,0,0,0,0,0,0,0,0,0,0,51,0,0,50,52,12,12,12,12,10,12,10,12
12,10,12,10,10,12,12,10,52,52,0,0,0,0,0,0,0,0,0,0,0,0,0,52,52,12,12,12,12,12,12,12,12
12,12,10,12,12,12,10,82,12,52,0,6,0,0,0,35,0,0,0,0,0,0,0,52,10,12,10,10,10,15,12,12,12
12,12,12,12,12,12,12,12,52,52,0,0,0,0,0,0,0,0,0,0,0,0,0,52,52,10,12,12,12,12,12,10,10
12,12,12,12,12,12,12,12,52,0,0,0,0,0,0,0,0,0,0,0,0,0,0,0,52,12,12,10,12,12,12,12,10
12,12,10,12,12,12,12,10,52,0,0,0,0,0,0,0,0,0,0,0,0,0,0,0,52,12,12,12,10,12,12,12,12
12,12,12,5,10,10,10,12,52,0,0,0,0,0,0,0,83,0,0,0,0,0,0,0,52,10,10,10,10,5,12,12,12
10,12,12,12,10,12,12,12,52,0,0,0,0,0,0,0,0,0,0,0,0,0,0,0,52,12,10,12,10,5,10,12,10
12,10,12,12,10,12,12,12,52,0,0,0,0,0,0,0,0,0,0,0,0,0,0,0,52,10,10,10,10,12,12,10,12
12,12,12,12,10,12,12,12,52,52,0,0,0,0,0,0,0,0,0,0,0,0,0,52,52,10,12,10,10,10,12,10,12
12,12,10,12,12,12,12,15,12,52,0,0,0,0,0,0,0,0,0,0,0,0,0,52,10,12,12,10,10,10,12,12,10
12,12,12,10,10,10,10,12,52,52,0,0,0,0,0,0,0,0,0,0,0,0,0,52,52,12,12,12,10,10,12,10,10
10,12,12,12,12,12,12,12,52,0,0,0,0,0,0,0,0,0,0,0,0,0,0,0,52,15,12,12,10,12,10,12,12
12,12,12,5,12,12,12,12,52,0,0,0,0,0,0,0,0,0,0,0,0,0,0,0,52,10,10,10,10,10,10,12,12
12,25,12,5,12,12,12,10,52,0,0,0,0,0,0,0,0,0,0,0,0,0,0,0,52,12,10,12,12,12,10,12,10
12,10,10,12,12,25,12,12,52,0,0,0,0,0,0,0,0,0,0,0,0,0,0,0,52,25,10,12,10,12,12,12,12
22,10,12,12,10,10,12,10,10,10,94,94,10,0,0,0,0,0,0,0,10,94,94,12,12,10,12,12,10,12,12,12,12
12,12,12,12,15,10,12,12,12,12,10,10,12,12,12,12,0,12,12,12,10,12,12,12,12,12,12,12,12,12,12,25,12
12,10,12,12,12,25,12,12,12,10,12,12,12,12,10,12,12,12,25,12,10,12,12,12,12,12,10,12,10,10,12,10,12
12,12,12,10,12,12,12,15,10,10,12,10,12,10,12,10,10,12,25,10,12,10,12,10,12,12,12,25,5,12,12,10,12
10,10,12,12,12,85,10,12,10,12,10,10,12,12,12,12,12,12,12,12,12,12,12,12,12,12,12,12,12,12,12,12,10
12,12,12,12,12,12,12,12,10,12,12,12,10,12,12,10,12,25,10,12,24,12,12,5,12,12,12,12,10,12,12,15,12
12,12,15,25,25,12,12,10,12,10,12,12,12,10,10,12,12,12,12,12,25,17,12,12,12,17,12,12,10,12,85,25,12
10,10,12,12,10,12,10,12,12,10,12,10,12,12,12,12,12,12,15,12,10,12,10,12,12,12,82,10,12,22,12,12,12
endlayer

layer
0,0,0,0,0,0,0,0,0,0,0,0,0,0,0,0,0,0,0,0,0,0,0,0,0,0,0,0,0,0,0,0,0
0,0,0,0,0,0,0,0,0,0,0,0,0,0,0,0,0,0,0,0,0,0,0,0,0,0,0,0,0,0,0,0,0
0,0,0,0,0,0,0,0,0,0,0,0,0,0,0,0,0,0,0,0,0,0,0,0,0,0,0,0,0,0,0,0,0
0,0,0,0,0,0,0,0,0,0,0,0,0,0,0,0,0,0,0,0,0,0,0,0,0,0,0,0,0,0,0,0,0
0,0,0,0,0,0,0,0,0,0,0,0,0,0,0,0,0,0,0,0,0,0,0,0,0,0,0,0,0,0,0,0,0
0,0,0,0,0,0,0,0,34,0,0,0,0,0,0,0,0,0,34,0,0,0,0,0,0,0,0,0,0,0,0,0,0
0,0,0,0,0,0,10,12,10,10,12,12,12,17,12,12,10,12,12,12,12,12,10,12,12,12,10,0,0,0,0,0,0
0,0,0,0,0,0,25,5,0,0,9,12,10,40,40,40,40,40,40,40,12,12,0,0,0,0,12,0,0,0,0,0,0
0,0,0,0,0,0,12,0,0,0,0,43,43,43,43,43,43,43,43,43,43,43,0,0,0,0,12,0,0,0,0,0,0
0,0,0,0,0,0,12,0,0,0,0,0,0,43,97,43,43,96,95,43,2,0,0,0,0,0,12,0,0,0,0,0,0
0,0,0,0,0,0,12,6,0,0,0,0,0,0,0,0,0,0,0,0,0,0,0,0,0,0,10,0,0,0,0,0,0
0,0,0,0,0,0,12,0,0,0,0,0,0,0,0,0,0,0,0,0,0,0,0,0,0,0,12,0,0,0,0,0,0
0,0,0,0,0,0,12,0,0,0,0,0,0,0,0,0,0,0,0,0,0,0,0,0,0,0,10,0,0,0,0,0,0
0,0,0,0,0,0,12,98,98,98,98,98,98,0,0,0,0,0,0,0,0,0,0,0,12,12,10,0,0,0,0,0,0
0,0,0,0,0,0,12,0,0,0,0,0,0,0,0,0,0,0,0,0,0,0,10,99,0,0,10,6,0,0,0,0,0
0,0,0,0,0,0,12,49,49,49,49,0,0,0,0,0,0,0,0,0,51,0,0,50,0,0,10,0,0,0,0,0,0
0,0,0,0,0,0,12,49,49,49,49,0,0,0,0,0,0,0,0,0,0,0,0,0,0,0,10,0,0,0,0,0,0
0,0,0,0,0,0,12,49,49,49,49,0,0,0,0,0,0,0,0,0,51,0,0,50,0,0,12,0,0,0,0,0,0
0,0,0,0,0,0,12,49,49,49,49,0,0,0,0,0,0,0,0,0,0,0,0,0,0,0,12,0,0,0,0,0,0
0,0,0,0,0,0,10,49,49,49,49,0,0,0,0,0,0,0,0,0,51,0,0,50,0,0,12,0,0,0,0,0,0
0,0,0,0,0,0,10,0,0,0,0,0,0,0,0,0,0,0,0,0,0,0,0,0,34,0,12,0,0,0,0,0,0
0,0,0,0,0,0,10,12,12,0,0,6,0,0,0,35,0,0,0,0,0,0,0,2,12,12,12,0,0,0,0,0,0
0,0,0,0,0,0,12,34,0,0,0,0,0,0,0,0,0,0,0,0,0,0,0,0,0,2,12,0,0,0,0,0,0
0,0,0,0,0,0,12,12,0,0,0,0,0,0,0,0,0,0,0,0,0,0,0,0,0,12,10,0,0,0,0,0,0
0,0,0,0,0,0,12,52,0,0,0,0,0,0,0,0,0,0,0,0,0,0,0,0,0,52,12,0,0,0,0,0,0
0,0,0,0,0,0,12,52,0,0,0,0,0,0,0,0,5,6,0,0,0,0,0,0,0,52,12,0,0,0,0,0,0
0,0,0,0,0,0,12,52,0,0,0,0,0,0,0,0,0,0,9,0,0,0,0,0,0,52,10,0,0,0,0,0,0
0,0,0,0,0,0,12,25,0,0,0,0,0,0,0,0,0,0,0,0,0,0,0,0,0,12,12,0,0,0,0,0,0
0,0,0,0,0,0,12,0,0,0,0,0,0,0,0,0,0,0,0,0,0,0,0,0,0,0,10,0,0,0,0,0,0
0,0,0,0,0,0,10,12,12,0,0,0,0,0,0,0,0,0,0,0,0,0,0,0,12,12,10,0,0,0,0,0,0
0,0,0,0,0,0,12,100,0,0,0,0,0,0,0,0,0,0,0,0,0,0,0,0,0,0,12,0,0,0,0,0,0
0,0,0,0,0,0,12,0,0,0,0,0,0,0,0,0,0,0,0,0,0,0,0,0,0,0,12,0,0,0,0,0,0
0,0,0,0,0,0,12,0,0,0,0,0,0,0,0,0,0,0,0,0,0,0,0,0,0,0,12,0,0,0,0,0,0
0,0,0,0,0,0,12,0,0,0,0,0,0,0,0,0,0,0,0,0,0,0,0,0,0,0,10,0,0,0,0,0,0
0,0,0,0,0,0,12,0,0,0,0,0,0,0,0,0,0,0,0,0,0,0,0,0,0,0,12,0,0,0,0,0,0
0,0,0,0,0,0,12,94,94,12,94,94,12,0,0,0,12,0,0,0,25,94,94,10,94,94,10,6,0,0,0,0,0
0,0,0,0,0,0,12,89,89,89,89,89,10,12,12,0,12,0,12,12,10,89,89,89,89,89,12,6,0,0,0,0,0
0,0,0,0,0,0,12,9,0,34,0,0,0,9,0,89,2,89,0,0,0,0,0,0,0,0,10,6,0,0,0,0,0
0,0,0,0,0,0,12,12,12,12,12,12,10,12,10,10,10,12,12,12,10,12,12,12,12,12,12,0,0,0,0,0,0
0,0,0,0,0,0,0,0,0,0,0,0,0,0,0,0,0,0,0,0,0,0,0,0,0,0,0,0,0,0,0,0,0
0,0,0,0,0,0,0,0,0,0,0,0,0,0,0,0,0,0,0,0,0,0,0,0,0,0,0,0,0,0,0,0,0
0,0,0,0,0,0,0,0,0,0,0,0,0,0,0,0,0,0,0,0,0,0,0,0,0,0,0,0,0,0,0,0,0
0,0,0,0,0,0,0,0,0,0,0,0,0,0,0,0,0,0,0,0,0,0,0,0,0,0,0,0,0,0,0,0,0
endlayer

layer
0,0,0,0,0,0,0,0,0,0,0,0,0,0,0,0,0,0,0,0,0,0,0,0,0,0,0,0,0,0,0,0,0
0,0,0,0,0,0,0,0,0,0,0,0,0,0,0,0,0,0,0,0,0,0,0,0,0,0,0,0,0,0,0,0,0
0,0,0,0,0,0,0,0,0,0,0,0,0,0,0,0,0,0,0,0,0,0,0,0,0,0,0,0,0,0,0,0,0
0,0,0,0,0,0,0,0,0,0,0,0,0,0,0,0,0,0,0,0,0,0,0,0,0,0,0,0,0,0,0,0,0
0,0,0,0,0,0,0,0,0,0,0,0,0,0,0,0,0,0,0,0,0,0,0,0,0,0,0,0,0,0,0,0,0
0,0,0,0,0,0,0,0,0,0,0,0,0,0,0,0,0,0,34,0,0,0,0,0,0,0,0,0,0,0,0,0,0
0,0,0,0,0,0,12,25,12,10,12,12,10,12,25,10,10,10,10,12,12,10,12,12,12,10,12,0,0,0,0,0,0
0,0,0,0,0,0,12,5,0,0,9,12,12,0,0,0,0,0,0,0,12,10,0,0,0,0,12,0,0,0,0,0,0
0,0,0,0,0,0,10,0,0,0,0,43,0,0,43,0,0,0,101,0,0,43,0,0,0,0,5,0,0,0,0,0,0
0,0,0,0,0,0,5,0,0,0,0,9,43,43,102,43,43,43,96,43,43,0,6,0,0,0,5,0,0,0,0,0,0
0,0,0,0,0,0,12,0,0,0,0,0,0,0,0,0,0,0,0,0,0,0,0,0,0,0,10,0,0,0,0,0,0
0,0,0,0,0,0,12,0,0,0,0,0,0,0,0,0,0,0,0,0,0,0,0,0,0,0,10,0,0,0,0,0,0
0,0,0,0,0,0,12,0,0,0,0,0,0,0,0,0,0,0,0,0,0,0,0,0,0,0,12,0,0,0,0,0,0
0,0,0,0,0,0,85,12,10,0,0,0,92,0,0,0,0,0,0,0,0,0,0,0,10,12,12,0,0,0,0,0,0
0,0,0,0,0,0,12,0,0,0,0,0,0,0,0,0,0,0,0,0,0,0,10,0,0,0,10,0,0,0,0,0,0
0,0,0,0,0,0,12,0,0,0,35,0,0,0,0,0,0,0,0,0,51,0,0,50,0,0,12,0,0,0,0,0,0
0,0,0,0,0,0,12,0,0,0,0,0,0,0,0,0,0,0,0,0,0,0,0,0,0,0,12,0,0,0,0,0,0
0,0,0,0,0,0,25,0,0,0,0,0,0,0,0,0,0,0,0,0,51,0,0,50,0,0,12,0,0,0,0,0,0
0,0,0,0,0,0,12,0,0,0,0,0,0,0,0,0,0,0,0,0,0,0,0,0,0,8,12,0,0,0,0,0,0
0,0,0,0,0,0,12,0,0,0,35,0,0,0,0,0,0,0,0,0,51,0,0,50,0,0,12,0,0,0,0,0,0
0,0,0,0,0,0,12,0,0,0,0,0,0,0,0,0,0,0,0,0,0,0,0,0,0,0,10,0,0,0,0,0,0
0,0,0,0,0,0,12,0,0,12,12,6,0,0,0,35,0,0,0,0,0,0,12,10,0,0,12,0,0,0,0,0,0
0,0,0,0,0,0,12,0,0,0,0,0,0,0,0,0,0,0,0,0,0,0,0,0,0,0,10,0,0,0,0,0,0
0,0,0,0,0,0,12,12,0,0,0,0,0,0,0,0,0,0,0,0,0,0,0,0,0,10,10,0,0,0,0,0,0
0,0,0,0,0,0,12,52,0,0,0,0,0,0,0,0,0,0,0,0,0,0,0,0,0,52,12,0,0,0,0,0,0
0,0,0,0,0,0,12,52,0,0,0,0,0,0,0,0,5,6,0,0,0,0,0,0,0,52,12,0,0,0,0,0,0
0,0,0,0,0,0,12,52,0,0,0,0,0,0,0,0,0,0,9,0,0,0,0,0,0,52,12,0,0,0,0,0,0
0,0,0,0,0,0,12,58,0,0,0,0,0,0,0,0,0,0,0,0,0,0,0,0,0,10,12,0,0,0,0,0,0
0,0,0,0,0,0,10,0,0,0,0,0,0,0,0,0,0,0,0,0,0,0,0,0,0,0,10,0,0,0,0,0,0
0,0,0,0,0,0,12,0,0,12,12,0,0,0,0,0,0,0,0,0,0,0,10,12,0,0,10,0,0,0,0,0,0
0,0,0,0,0,0,10,0,0,0,0,0,0,0,0,0,0,0,0,0,0,0,0,0,0,0,12,0,0,0,0,0,0
0,0,0,0,0,0,12,0,0,0,0,0,0,0,0,0,0,0,0,0,0,0,0,0,0,0,12,0,0,0,0,0,0
0,0,0,0,0,0,10,0,0,0,0,0,0,0,0,0,0,0,0,0,0,0,0,0,0,0,5,0,0,0,0,0,0
0,0,0,0,0,0,12,0,0,0,0,0,0,0,0,0,0,0,0,0,0,0,0,0,0,0,12,0,0,0,0,0,0
0,0,0,0,0,0,12,0,0,0,0,0,0,0,0,0,0,0,0,0,0,0,0,0,0,0,25,0,0,0,0,0,0
0,0,0,0,0,0,12,94,94,10,94,94,10,0,0,12,10,12,0,0,10,94,94,10,94,94,12,6,0,0,0,0,0
0,0,0,0,0,0,10,89,89,89,89,89,12,12,0,10,12,12,2,10,12,89,89,89,89,89,12,6,0,0,0,0,0
0,0,0,0,0,0,10,9,0,103,34,0,0,9,89,0,0,2,89,0,0,0,0,0,0,0,12,0,0,0,0,0,0
0,0,0,0,0,0,10,10,12,12,12,12,12,12,22,12,12,10,12,82,10,12,10,10,12,12,10,0,0,0,0,0,0
0,0,0,0,0,0,0,0,0,0,0,9,0,0,0,0,0,0,0,0,0,0,0,0,0,0,0,0,0,0,0,0,0
0,0,0,0,0,0,0,0,0,0,0,0,0,0,0,0,0,0,0,0,0,0,0,0,0,0,0,0,0,0,0,0,0
0,0,0,0,0,0,0,0,0,0,0,0,0,0,0,0,0,0,0,0,0,0,0,0,0,0,0,0,0,0,0,0,0
0,0,0,0,0,0,0,0,0,0,0,0,0,0,0,0,0,0,0,0,0,0,0,0,0,0,0,0,0,0,0,0,0
endlayer

layer
0,0,0,0,0,0,0,0,0,0,0,0,0,0,0,0,0,0,0,0,0,0,0,0,0,0,0,0,0,0,0,0,0
0,0,0,0,0,0,0,0,0,0,0,0,0,0,0,0,0,0,0,0,0,0,0,0,0,0,0,0,0,0,0,0,0
0,0,0,0,0,0,0,0,0,0,0,0,0,0,0,0,0,0,0,0,0,0,0,0,0,0,0,0,0,0,0,0,0
0,0,0,0,0,0,0,0,0,0,0,0,0,0,0,0,0,0,0,0,0,0,0,0,0,0,0,0,0,0,0,0,0
0,0,0,0,0,0,0,0,0,0,0,0,0,0,0,0,0,0,0,0,0,0,0,0,0,0,0,0,0,0,0,0,0
0,0,0,0,0,0,0,0,0,0,0,0,0,0,0,34,0,0,0,0,0,0,0,0,0,0,0,0,0,0,0,0,0
0,0,0,0,0,0,10,12,12,5,10,12,12,12,12,10,10,10,10,12,12,10,12,12,10,10,10,0,0,0,0,0,0
0,0,0,0,0,0,12,5,0,0,9,12,12,0,0,0,0,0,0,0,12,12,0,0,0,0,10,0,0,0,0,0,0
0,0,0,0,0,0,12,0,0,0,0,43,89,89,89,89,89,89,89,89,89,43,6,0,0,0,5,0,0,0,0,0,0
0,0,0,0,0,0,5,0,0,0,0,43,0,0,97,95,0,97,95,0,0,43,6,0,0,0,12,0,0,0,0,0,0
0,0,0,0,0,0,12,0,0,0,0,0,0,0,0,0,0,0,0,0,0,0,0,0,0,0,12,0,0,0,0,0,0
0,0,0,0,0,0,12,0,0,0,0,0,0,0,0,0,0,0,0,0,0,0,0,0,0,0,12,0,0,0,0,0,0
0,0,0,0,0,0,12,0,0,0,0,0,0,0,0,0,0,0,0,0,0,0,0,0,0,0,10,0,0,0,0,0,0
0,0,0,0,0,0,12,12,12,0,0,0,12,0,0,0,0,0,0,0,0,0,0,0,5,5,10,0,0,0,0,0,0
0,0,0,0,0,0,12,0,0,0,0,0,0,0,0,0,0,0,0,0,0,0,10,0,0,0,12,0,0,0,0,0,0
0,0,0,0,0,0,10,12,0,0,35,0,0,0,0,0,0,0,0,0,12,10,51,50,0,0,10,0,0,0,0,0,0
0,0,0,0,0,0,5,0,0,0,0,0,0,0,0,0,0,0,0,0,0,0,0,0,0,0,10,0,0,0,0,0,0
0,0,0,0,0,0,12,0,0,0,0,0,0,0,0,0,0,0,0,0,12,12,51,50,0,0,12,0,0,0,0,0,0
0,0,0,0,0,0,10,0,0,0,0,0,0,0,0,0,0,0,0,0,0,0,0,2,0,0,12,0,0,0,0,0,0
0,0,0,0,0,0,10,12,0,0,35,0,0,0,0,0,0,0,0,0,15,12,51,50,0,0,12,0,0,0,0,0,0
0,0,0,0,0,0,10,0,0,0,0,0,0,0,34,0,0,0,0,0,0,0,0,0,0,0,12,0,0,0,0,0,0
0,0,0,0,0,0,10,0,0,0,0,12,10,12,35,35,35,35,35,10,10,10,0,0,0,0,10,0,0,0,0,0,0
0,0,0,0,0,0,12,34,0,0,0,0,0,0,0,0,0,0,0,0,0,0,0,0,0,0,10,0,0,0,0,0,0
0,0,0,0,0,0,12,12,0,0,0,0,0,0,0,0,0,0,0,0,0,0,0,0,0,12,12,0,0,0,0,0,0
0,0,0,0,0,0,22,52,0,0,0,0,0,0,0,0,0,0,0,0,0,0,0,0,0,52,10,0,0,0,0,0,0
0,0,0,0,0,0,10,52,0,0,0,0,0,0,0,0,50,6,0,0,0,0,0,0,0,52,12,0,0,0,0,0,0
0,0,0,0,0,0,12,52,0,0,0,0,0,0,0,0,0,0,9,0,0,0,0,0,0,52,12,0,0,0,0,0,0
0,0,0,0,0,0,12,12,0,0,0,0,0,0,0,0,0,0,0,0,0,0,0,0,0,12,12,0,0,0,0,0,0
0,0,0,0,0,0,12,0,0,0,0,0,0,0,0,0,0,0,0,0,0,0,0,0,0,0,12,0,0,0,0,0,0
0,0,0,0,0,0,10,0,0,0,0,12,10,12,0,0,0,0,0,12,10,10,0,0,0,0,12,0,0,0,0,0,0
0,0,0,0,0,0,12,0,0,0,0,0,0,0,0,0,0,0,0,0,0,0,0,0,0,0,12,0,0,0,0,0,0
0,0,0,0,0,0,12,0,0,0,0,0,0,0,0,0,0,0,0,0,0,0,0,0,0,0,10,0,0,0,0,0,0
0,0,0,0,0,0,12,0,0,0,0,0,0,0,0,0,0,0,0,0,0,0,0,0,0,0,5,0,0,0,0,0,0
0,0,0,0,0,0,10,0,0,0,0,0,0,0,0,0,0,0,0,0,0,0,0,0,0,0,12,0,0,0,0,0,0
0,0,0,0,0,0,10,0,0,0,0,0,0,0,0,0,0,0,0,0,0,0,0,0,0,0,12,0,0,0,0,0,0
0,0,0,0,0,0,12,94,94,10,94,94,12,0,0,12,0,12,0,0,12,94,94,10,94,94,12,6,0,0,0,0,0
0,0,0,0,0,0,82,89,89,89,89,89,12,12,0,10,104,12,34,12,12,89,89,89,89,89,12,6,0,0,0,0,0
0,0,0,0,0,0,12,0,0,0,0,0,0,0,89,0,89,0,89,2,0,0,0,0,0,34,12,0,0,0,0,0,0
0,0,0,0,0,0,12,10,10,12,10,12,12,12,12,12,12,10,12,12,58,10,10,12,12,10,10,0,0,0,0,0,0
0,0,0,0,0,0,0,0,0,0,0,9,0,0,0,0,0,0,0,0,0,0,0,0,0,0,0,0,0,0,0,0,0
0,0,0,0,0,0,0,0,0,0,0,0,0,0,0,0,0,0,0,0,0,0,0,0,0,0,0,0,0,0,0,0,0
0,0,0,0,0,0,0,0,0,0,0,0,0,0,0,0,0,0,0,0,0,0,0,0,0,0,0,0,0,0,0,0,0
0,0,0,0,0,0,0,0,0,0,0,0,0,0,0,0,0,0,0,0,0,0,0,0,0,0,0,0,0,0,0,0,0
endlayer

layer
0,0,0,0,0,0,0,0,0,0,0,0,0,0,0,0,0,0,0,0,0,0,0,0,0,0,0,0,0,0,0,0,0
0,0,0,0,0,0,0,0,0,0,0,0,0,0,0,0,0,0,0,0,0,0,0,0,0,0,0,0,0,0,0,0,0
0,0,0,0,0,0,0,0,0,0,0,0,0,0,0,0,0,0,0,0,0,0,0,0,0,0,0,0,0,0,0,0,0
0,0,0,0,0,0,0,0,0,0,0,0,0,0,0,0,0,0,0,0,0,0,0,0,0,0,0,0,0,0,0,0,0
0,0,0,0,0,0,0,0,0,0,0,0,0,0,0,0,0,0,0,0,0,0,0,0,0,0,0,0,0,0,0,0,0
0,0,0,0,0,0,0,0,0,0,0,0,0,0,0,34,0,0,0,0,0,0,0,34,0,0,0,0,0,0,0,0,0
0,0,0,0,0,0,12,12,5,12,12,12,10,12,10,10,12,12,12,12,12,22,12,5,12,12,12,0,0,0,0,0,0
0,0,0,0,0,0,12,5,0,0,0,12,12,0,0,0,0,0,0,0,10,10,0,0,0,0,12,0,0,0,0,0,0
0,0,0,0,0,0,12,0,0,0,0,43,89,89,89,0,89,0,89,89,89,43,6,0,0,0,12,0,0,0,0,0,0
0,0,0,0,0,0,12,0,0,0,0,43,0,0,0,43,2,43,2,0,0,43,0,0,0,0,12,0,0,0,0,0,0
0,0,0,0,0,0,5,0,0,0,0,0,0,0,0,0,0,0,0,0,0,0,0,0,0,0,10,0,0,0,0,0,0
0,0,0,0,0,0,10,0,0,0,0,0,0,0,0,0,0,0,0,0,0,0,0,0,0,0,10,0,0,0,0,0,0
0,0,0,0,0,0,10,0,0,0,0,0,0,0,0,0,0,0,0,0,0,0,0,0,0,0,12,0,0,0,0,0,0
0,0,0,0,0,0,10,5,5,0,0,0,0,0,0,0,0,0,0,0,0,0,0,0,5,5,12,0,0,0,0,0,0
0,0,0,0,0,0,10,0,0,0,0,0,0,0,0,0,0,0,0,0,0,0,12,0,0,0,12,0,0,0,0,0,0
0,0,0,0,0,0,12,58,12,58,35,0,0,0,0,0,0,0,0,0,94,0,12,0,0,0,10,0,0,0,0,0,0
0,0,0,0,0,0,5,0,0,0,0,0,0,0,0,0,0,0,0,0,0,0,10,0,0,0,10,0,0,0,0,0,0
0,0,0,0,0,0,12,0,0,0,0,0,0,0,0,0,0,0,0,0,94,0,12,0,0,0,10,0,0,0,0,0,0
0,0,0,0,0,0,12,0,0,0,0,0,0,0,0,0,0,0,0,0,0,0,12,0,0,0,12,0,0,0,0,0,0
0,0,0,0,0,0,5,12,10,12,35,0,0,0,0,0,0,0,0,0,94,0,10,0,0,0,12,0,0,0,0,0,0
0,0,0,0,0,0,12,0,0,0,0,0,0,0,34,0,0,0,0,0,0,0,0,0,0,0,10,0,0,0,0,0,0
0,0,0,0,0,0,12,0,0,0,0,0,0,0,12,10,12,12,12,0,0,0,0,0,0,0,12,0,0,0,0,0,0
0,0,0,0,0,0,10,34,0,0,0,0,0,0,0,0,12,0,0,0,0,0,0,0,0,0,12,0,0,0,0,0,0
0,0,0,0,0,0,10,12,0,0,0,0,0,0,0,0,10,0,0,0,0,0,0,0,0,10,12,0,0,0,0,0,0
0,0,0,0,0,0,12,52,0,0,0,0,0,0,0,0,10,0,0,0,0,0,0,0,0,52,12,0,0,0,0,0,0
0,0,0,0,0,0,10,52,98,98,98,98,98,98,98,98,12,98,98,98,98,98,98,98,98,98,12,0,0,0,0,0,0
0,0,0,0,0,0,12,52,0,0,0,0,0,0,0,0,10,0,9,0,0,0,0,0,0,52,12,0,0,0,0,0,0
0,0,0,0,0,0,12,12,0,0,0,0,0,0,0,0,10,0,0,0,0,0,0,0,0,10,12,0,0,0,0,0,0
0,0,0,0,0,0,12,0,0,0,0,0,0,0,0,0,10,0,0,0,0,0,0,0,0,0,12,0,0,0,0,0,0
0,0,0,0,0,0,10,0,0,0,0,0,0,0,10,12,12,12,12,0,0,0,0,0,0,0,10,0,0,0,0,0,0
0,0,0,0,0,0,5,0,0,0,0,0,0,0,0,0,0,0,0,0,0,0,0,0,0,0,12,0,0,0,0,0,0
0,0,0,0,0,0,12,0,0,0,0,0,0,0,0,0,0,0,0,0,0,0,0,0,0,0,5,0,0,0,0,0,0
0,0,0,0,0,0,5,0,0,0,0,0,0,0,0,0,0,0,0,0,0,0,0,0,0,0,12,0,0,0,0,0,0
0,0,0,0,0,0,12,0,0,0,0,0,0,0,0,0,0,0,0,0,0,0,0,0,0,0,12,0,0,0,0,0,0
0,0,0,0,0,0,12,0,0,0,0,0,0,0,0,0,0,0,0,0,0,0,0,0,0,0,12,0,0,0,0,0,0
0,0,0,0,0,0,12,94,94,12,94,94,10,0,0,10,12,12,0,0,12,94,94,12,94,94,12,6,0,0,0,0,0
0,0,0,0,0,0,12,89,89,89,89,89,12,12,0,12,12,10,0,12,12,89,89,89,89,89,12,0,0,0,0,0,0
0,0,0,0,0,0,12,34,0,0,0,0,0,105,89,0,34,0,89,0,0,9,9,0,0,34,12,0,0,0,0,0,0
0,0,0,0,0,0,10,12,12,12,12,12,12,10,12,12,10,10,12,10,12,12,12,12,12,12,10,0,0,0,0,0,0
0,0,0,0,0,0,0,0,0,0,0,9,0,0,0,0,0,0,0,0,0,0,0,0,0,0,0,0,0,0,0,0,0
0,0,0,0,0,0,0,0,0,0,0,0,0,0,0,0,0,0,0,0,0,0,0,0,0,0,0,0,0,0,0,0,0
0,0,0,0,0,0,0,0,0,0,0,0,0,0,0,0,0,0,0,0,0,0,0,0,0,0,0,0,0,0,0,0,0
0,0,0,0,0,0,0,0,0,0,0,0,0,0,0,0,0,0,0,0,0,0,0,0,0,0,0,0,0,0,0,0,0
endlayer

layer
0,0,0,0,0,0,0,0,0,0,0,0,0,0,0,0,0,0,0,0,0,0,0,0,0,0,0,0,0,0,0,0,0
0,0,0,0,0,0,0,0,0,0,0,0,0,0,0,0,0,0,0,0,0,0,0,0,0,0,0,0,0,0,0,0,0
0,0,0,0,0,0,0,0,0,0,0,0,0,0,0,0,0,0,0,0,0,0,0,0,0,0,0,0,0,0,0,0,0
0,0,0,0,0,0,0,0,0,0,0,0,0,0,0,0,0,0,0,0,0,0,0,0,0,0,0,0,0,0,0,0,0
0,0,0,0,0,0,0,0,0,0,0,0,0,0,0,0,0,0,0,0,0,0,0,0,0,0,0,0,0,0,0,0,0
0,0,0,0,0,0,0,0,0,0,0,0,0,0,0,0,0,0,0,0,0,0,0,34,0,0,0,0,0,0,0,0,0
0,0,0,0,0,0,10,10,0,5,10,12,12,12,10,12,12,10,12,12,10,12,10,10,82,12,10,0,0,0,0,0,0
0,0,0,0,0,0,10,5,0,0,0,12,10,0,0,0,0,0,0,9,10,12,0,0,0,0,10,0,0,0,0,0,0
0,0,0,0,0,0,38,0,0,0,0,43,0,0,43,43,0,43,43,0,0,43,6,0,0,0,12,0,0,0,0,0,0
0,0,0,0,0,0,12,0,0,0,0,0,43,43,43,0,101,0,43,43,43,0,0,0,0,8,10,0,0,0,0,0,0
0,0,0,0,0,0,5,0,0,0,0,0,0,0,0,0,0,0,0,0,0,0,0,0,0,0,5,0,0,0,0,0,0
0,0,0,0,0,0,10,0,0,0,0,0,0,0,0,0,0,0,0,0,0,0,0,0,0,0,12,0,0,0,0,0,0
0,0,0,0,0,0,10,0,0,0,0,0,0,0,0,0,0,0,0,0,0,0,0,0,0,0,10,0,0,0,0,0,0
0,0,0,0,0,0,12,5,5,0,0,0,0,0,0,0,0,0,0,0,0,0,0,0,5,12,12,0,0,0,0,0,0
0,0,0,0,0,0,25,0,0,0,0,0,0,0,0,0,0,0,0,0,0,0,51,0,0,9,12,0,0,0,0,0,0
0,0,0,0,0,0,12,12,12,12,10,0,0,0,0,0,0,0,0,0,0,0,51,0,0,0,10,0,0,0,0,0,0
0,0,0,0,0,0,10,12,12,10,12,0,0,0,0,0,0,0,0,0,0,0,51,0,0,0,12,0,0,0,0,0,0
0,0,0,0,0,0,10,12,12,12,12,0,0,0,0,0,0,0,0,0,0,0,51,0,0,0,12,0,0,0,0,0,0
0,0,0,0,0,0,12,10,12,12,12,0,0,0,0,0,0,0,0,0,0,0,51,0,0,0,10,0,0,0,0,0,0
0,0,0,0,0,0,12,12,10,12,12,0,0,0,0,0,0,0,0,0,0,0,51,0,0,0,10,0,0,0,0,0,0
0,0,0,0,0,0,5,0,0,0,0,0,0,0,0,0,0,0,0,0,0,0,0,0,0,0,12,0,0,0,0,0,0
0,0,0,0,0,0,10,0,0,0,0,0,0,0,0,0,0,0,0,0,0,0,0,0,0,0,10,0,0,0,0,0,0
0,0,0,0,0,0,10,99,0,0,0,0,0,0,0,0,0,0,0,0,0,0,0,0,0,0,12,0,0,0,0,0,0
0,0,0,0,0,0,12,10,0,0,0,0,0,0,0,0,0,0,0,0,0,0,0,0,0,12,10,0,0,0,0,0,0
0,0,0,0,0,0,12,52,0,0,0,0,0,0,0,0,0,0,0,0,0,0,0,0,0,52,12,0,0,0,0,0,0
0,0,0,0,0,0,12,52,35,35,35,35,35,35,35,35,50,35,35,35,35,35,35,35,35,52,10,0,0,0,0,0,0
0,0,0,0,0,0,10,52,0,0,0,0,0,0,0,0,0,0,0,0,0,0,0,0,0,52,10,0,0,0,0,0,0
0,0,0,0,0,0,12,12,0,0,0,0,0,0,0,0,0,0,0,0,0,0,0,0,0,12,12,0,0,0,0,0,0
0,0,0,0,0,0,10,0,0,0,0,0,0,0,0,0,0,0,0,0,0,0,0,0,10,10,12,0,0,0,0,0,0
0,0,0,0,0,0,5,0,0,0,0,0,0,0,0,0,0,0,0,0,0,10,25,10,10,12,12,0,0,0,0,0,0
0,0,0,0,0,0,12,0,0,0,0,0,0,0,0,0,0,0,0,0,0,0,0,12,10,12,12,0,0,0,0,0,0
0,0,0,0,0,0,12,0,0,0,0,0,0,0,0,0,0,0,0,0,0,0,12,10,12,10,10,0,0,0,0,0,0
0,0,0,0,0,0,5,0,0,0,0,0,0,0,0,0,0,0,0,0,0,0,0,12,12,12,10,0,0,0,0,0,0
0,0,0,0,0,0,12,0,0,0,0,0,0,0,0,0,0,0,0,0,0,0,0,10,12,12,12,0,0,0,0,0,0
0,0,0,0,0,0,12,0,0,0,0,0,0,0,0,0,0,0,0,0,0,0,0,0,25,12,12,0,0,0,0,0,0
0,0,0,0,0,0,12,94,94,12,94,94,12,0,0,0,10,0,0,0,12,94,94,12,94,94,10,6,0,0,0,0,0
0,0,0,0,0,0,12,89,89,89,89,89,12,12,12,0,12,0,12,25,10,89,89,89,89,89,10,0,0,0,0,0,0
0,0,0,0,0,0,10,99,0,0,0,0,0,0,0,89,0,89,0,0,0,9,0,0,0,34,12,0,0,0,0,0,0
0,0,0,0,0,0,10,10,12,12,12,10,12,10,12,12,10,12,12,12,12,12,12,10,12,12,12,0,0,0,0,0,0
0,0,0,0,0,0,0,0,0,0,0,0,0,0,0,0,0,0,0,0,0,0,0,0,0,0,0,0,0,0,0,0,0
0,0,0,0,0,0,0,0,0,0,0,0,0,0,0,0,0,0,0,0,0,0,0,0,0,0,0,0,0,0,0,0,0
0,0,0,0,0,0,0,0,0,0,0,0,0,0,0,0,0,0,0,0,0,0,0,0,0,0,0,0,0,0,0,0,0
0,0,0,0,0,0,0,0,0,0,0,0,0,0,0,0,0,0,0,0,0,0,0,0,0,0,0,0,0,0,0,0,0
endlayer

layer
0,0,0,0,0,0,0,0,0,0,0,0,0,0,0,0,0,0,0,0,0,0,0,0,0,0,0,0,0,0,0,0,0
0,0,0,0,0,0,0,0,0,0,0,0,0,0,0,0,0,0,0,0,0,0,0,0,0,0,0,0,0,0,0,0,0
0,0,0,0,0,0,0,0,0,0,0,0,0,0,0,0,0,0,0,0,0,0,0,0,0,0,0,0,0,0,0,0,0
0,0,0,0,0,0,0,0,0,0,0,0,0,0,0,0,0,0,0,0,0,0,0,0,0,0,0,0,0,0,0,0,0
0,0,0,0,0,0,0,0,0,0,0,0,0,0,0,0,0,0,0,0,0,0,0,0,0,0,0,0,0,0,0,0,0
0,0,0,0,0,0,0,0,0,0,34,0,34,0,0,0,0,0,0,0,0,0,0,34,0,0,0,0,0,0,0,0,0
0,0,0,0,0,0,12,12,12,5,12,12,58,12,12,12,12,12,12,12,12,12,12,12,5,10,12,0,0,0,0,0,0
0,0,0,0,0,0,12,5,0,0,0,0,82,0,0,0,0,0,0,9,10,0,0,0,0,0,10,0,0,0,0,0,0
0,0,0,0,0,0,25,0,0,0,0,0,43,43,43,43,43,43,43,43,43,0,0,0,0,0,10,0,0,0,0,0,0
0,0,0,0,0,0,12,0,0,0,0,0,0,0,0,0,0,0,0,0,0,0,0,0,0,0,12,0,0,0,0,0,0
0,0,0,0,0,0,10,0,0,0,0,0,0,0,0,0,0,0,0,0,0,0,0,0,0,0,12,0,0,0,0,0,0
0,0,0,0,0,0,10,0,0,0,0,0,0,0,0,0,0,0,0,0,0,0,0,0,0,0,12,0,0,0,0,0,0
0,0,0,0,0,0,5,0,0,0,0,0,0,0,0,0,0,0,0,0,0,0,0,0,0,0,12,0,0,0,0,0,0
0,0,0,0,0,0,12,12,5,0,0,0,0,0,0,0,0,0,0,0,0,0,0,0,12,10,10,0,0,0,0,0,0
0,0,0,0,0,0,10,0,0,0,0,0,0,0,0,0,0,0,0,0,0,0,0,0,9,9,12,0,0,0,0,0,0
0,0,0,0,0,0,5,0,0,0,0,0,0,0,0,0,0,0,0,0,0,0,0,0,0,0,10,0,0,0,0,0,0
0,0,0,0,0,0,10,0,0,0,0,0,0,0,0,0,0,0,0,0,0,0,0,0,0,0,12,0,0,0,0,0,0
0,0,0,0,0,0,12,0,0,0,0,0,0,0,0,0,0,0,0,0,0,0,0,0,0,0,10,0,0,0,0,0,0
0,0,0,0,0,0,17,0,0,0,0,0,0,0,0,0,0,0,0,0,0,0,0,0,0,0,12,0,0,0,0,0,0
0,0,0,0,0,0,5,0,0,0,0,0,0,0,0,0,0,0,0,0,0,0,0,0,0,0,12,0,0,0,0,0,0
0,0,0,0,0,0,10,0,0,0,0,0,0,0,0,0,0,0,0,0,0,0,0,0,0,0,10,0,0,0,0,0,0
0,0,0,0,0,0,10,0,0,0,0,0,0,0,0,0,0,0,0,0,0,0,0,0,0,0,12,0,0,0,0,0,0
0,0,0,0,0,0,12,0,0,0,0,0,0,0,0,0,0,0,0,0,0,0,0,0,0,0,25,0,0,0,0,0,0
0,0,0,0,0,0,12,10,0,0,0,0,0,0,0,0,0,0,0,0,0,0,0,0,0,12,12,0,0,0,0,0,0
0,0,0,0,0,0,12,52,0,0,0,0,0,0,0,0,0,0,0,0,0,0,0,0,0,52,12,0,0,0,0,0,0
0,0,0,0,0,0,10,52,0,0,0,0,0,0,0,0,50,0,0,0,0,0,0,0,0,52,10,0,0,0,0,0,0
0,0,0,0,0,0,10,52,0,0,0,0,0,0,0,0,0,0,0,0,0,0,0,0,0,52,85,0,0,0,0,0,0
0,0,0,0,0,0,12,10,0,0,0,0,0,0,0,0,0,0,0,0,0,0,0,0,0,12,10,0,0,0,0,0,0
0,0,0,0,0,0,12,0,0,0,0,0,0,0,0,0,0,0,0,0,0,0,0,0,5,5,12,0,0,0,0,0,0
0,0,0,0,0,0,5,0,0,0,0,0,0,0,0,0,0,0,0,0,0,5,5,5,5,0,12,0,0,0,0,0,0
0,0,0,0,0,0,12,0,0,0,0,0,0,0,0,0,0,0,0,0,0,0,0,5,0,0,12,0,0,0,0,0,0
0,0,0,0,0,0,12,0,0,0,0,0,0,0,0,0,0,0,0,0,0,0,5,5,0,0,10,0,0,0,0,0,0
0,0,0,0,0,0,12,0,0,0,0,0,0,0,0,0,0,0,0,0,0,0,0,0,0,0,10,0,0,0,0,0,0
0,0,0,0,0,0,12,0,0,0,0,0,0,0,0,0,0,0,0,0,0,0,0,0,0,0,12,0,0,0,0,0,0
0,0,0,0,0,0,10,0,0,0,0,0,0,0,0,0,0,0,0,0,0,0,0,0,0,8,12,0,0,0,0,0,0
0,0,0,0,0,0,10,94,94,24,94,94,10,0,0,0,0,0,0,0,10,94,94,12,94,94,12,0,0,0,0,0,0
0,0,0,0,0,0,10,89,89,89,89,89,10,10,12,12,0,12,12,12,10,89,89,89,89,89,12,0,0,0,0,0,0
0,0,0,0,0,0,12,99,0,0,0,0,0,0,0,0,89,0,0,0,0,0,0,0,0,0,12,0,0,0,0,0,0
0,0,0,0,0,0,12,12,10,12,12,12,10,12,12,12,12,10,10,12,10,12,12,12,12,12,10,0,0,0,0,0,0
0,0,0,0,0,0,0,0,0,0,0,0,0,0,0,0,0,0,0,0,0,0,0,0,0,0,0,0,0,0,0,0,0
0,0,0,0,0,0,0,0,0,0,0,0,0,0,0,0,0,0,0,0,0,0,0,0,0,0,0,0,0,0,0,0,0
0,0,0,0,0,0,0,0,0,0,0,0,0,0,0,0,0,0,0,0,0,0,0,0,0,0,0,0,0,0,0,0,0
0,0,0,0,0,0,0,0,0,0,0,0,0,0,0,0,0,0,0,0,0,0,0,0,0,0,0,0,0,0,0,0,0
endlayer

layer
0,0,0,0,0,0,0,0,0,0,0,0,0,0,0,0,0,0,0,0,0,0,0,0,0,0,0,0,0,0,0,0,0
0,0,0,0,0,0,0,0,0,0,0,0,0,0,0,0,0,0,0,0,0,0,0,0,0,0,0,0,0,0,0,0,0
0,0,0,0,0,0,0,0,0,0,0,0,0,0,0,0,0,0,0,0,0,0,0,0,0,0,0,0,0,0,0,0,0
0,0,0,0,0,0,0,0,0,0,0,0,0,0,0,0,0,0,0,0,0,0,0,0,0,0,0,0,0,0,0,0,0
0,0,0,0,0,0,0,0,0,0,0,0,0,0,0,0,0,0,0,0,0,0,0,0,0,0,0,0,0,0,0,0,0
0,0,0,0,0,0,0,0,0,0,0,0,34,0,0,0,0,0,0,0,0,0,0,34,0,0,0,0,0,0,0,0,0
0,0,0,0,0,0,10,12,12,12,10,10,12,12,12,12,10,10,12,10,10,10,10,12,10,10,12,0,0,0,0,0,0
0,0,0,0,0,0,12,5,0,0,0,0,0,12,12,12,12,12,12,12,0,0,0,0,0,0,10,0,0,0,0,0,0
0,0,0,0,0,0,12,0,0,0,0,0,0,43,43,106,43,43,43,43,0,0,0,0,0,0,10,0,0,0,0,0,0
0,0,0,0,0,0,12,0,0,0,0,0,0,0,0,0,0,0,0,0,0,0,0,0,0,0,5,0,0,0,0,0,0
0,0,0,0,0,0,38,0,0,0,0,0,0,0,0,0,0,0,0,0,0,0,0,0,0,0,5,0,0,0,0,0,0
0,0,0,0,0,0,12,0,0,0,0,0,0,0,0,0,0,0,0,0,0,0,0,0,0,0,12,0,0,0,0,0,0
0,0,0,0,0,0,12,0,0,0,0,0,0,0,0,0,0,0,0,0,0,0,0,0,0,0,12,0,0,0,0,0,0
0,0,0,0,0,0,12,10,5,0,0,0,0,0,0,0,0,0,0,0,0,0,0,0,12,10,10,0,0,0,0,0,0
0,0,0,0,0,0,12,0,0,0,0,0,0,0,0,0,0,0,0,0,0,0,0,0,0,0,12,0,0,0,0,0,0
0,0,0,0,0,0,12,0,0,0,0,0,0,0,0,0,0,0,0,0,0,0,0,0,0,0,12,0,0,0,0,0,0
0,0,0,0,0,0,10,0,0,0,0,0,0,0,0,0,0,0,0,0,0,0,0,0,0,0,12,0,0,0,0,0,0
0,0,0,0,0,0,12,0,0,0,0,0,0,0,6,0,0,0,0,0,0,0,0,0,0,0,10,0,0,0,0,0,0
0,0,0,0,0,0,12,0,0,0,0,0,0,0,0,0,0,0,0,0,0,0,0,0,0,0,12,0,0,0,0,0,0
0,0,0,0,0,0,10,0,0,0,0,0,0,0,0,0,0,0,0,0,0,0,0,0,0,0,10,0,0,0,0,0,0
0,0,0,0,0,0,5,0,0,0,0,0,0,0,0,0,0,0,0,0,0,0,0,0,0,0,12,0,0,0,0,0,0
0,0,0,0,0,0,12,0,0,0,0,0,0,0,0,0,0,0,0,0,0,0,0,0,0,0,10,0,0,0,0,0,0
0,0,0,0,0,0,12,0,0,0,0,0,0,0,0,0,0,0,0,0,0,0,0,0,0,0,12,0,0,0,0,0,0
0,0,0,0,0,0,12,12,0,0,0,0,0,0,0,0,0,0,0,0,0,0,0,0,0,12,12,0,0,0,0,0,0
0,0,0,0,0,0,10,52,0,0,0,0,0,0,0,0,0,0,0,0,0,0,0,0,0,52,10,0,0,0,0,0,0
0,0,0,0,0,0,12,52,0,0,0,0,0,0,0,0,50,0,0,0,0,0,0,0,0,52,12,0,0,0,0,0,0
0,0,0,0,0,0,10,52,0,0,0,0,0,0,0,0,0,0,0,9,0,0,0,0,0,52,10,0,0,0,0,0,0
0,0,0,0,0,0,12,10,0,0,0,0,0,0,0,0,0,0,0,0,0,0,0,0,0,10,12,0,0,0,0,0,0
0,0,0,0,0,0,12,0,0,0,0,0,0,0,0,0,0,0,0,0,0,0,0,0,0,10,12,0,0,0,0,0,0
0,0,0,0,0,0,12,0,0,0,0,0,0,0,0,0,0,0,0,0,0,0,0,0,0,12,10,0,0,0,0,0,0
0,0,0,0,0,0,12,0,0,0,0,0,0,0,0,0,0,0,0,0,0,0,0,0,0,10,10,0,0,0,0,0,0
0,0,0,0,0,0,5,0,0,0,0,0,0,0,0,0,0,0,0,0,0,0,0,0,0,10,12,0,0,0,0,0,0
0,0,0,0,0,0,12,0,0,0,0,0,0,0,0,0,0,0,0,0,0,0,0,0,0,12,12,0,0,0,0,0,0
0,0,0,0,0,0,5,0,0,0,0,0,0,0,0,0,0,0,0,0,0,0,0,0,0,12,12,0,0,0,0,0,0
0,0,0,0,0,0,10,0,0,0,0,0,0,0,0,0,0,0,0,0,0,0,0,0,0,12,12,0,0,0,0,0,0
0,0,0,0,0,0,12,94,94,10,94,94,10,0,0,0,0,0,0,0,12,94,94,12,94,94,82,0,0,0,0,0,0
0,0,0,0,0,0,12,89,89,89,89,89,10,12,12,12,2,10,12,23,10,89,89,89,89,89,12,0,0,0,0,0,0
0,0,0,0,0,0,10,6,0,0,0,0,0,0,0,0,89,0,0,0,0,0,0,0,0,0,12,0,0,0,0,0,0
0,0,0,0,0,0,12,12,12,12,12,12,12,12,10,12,12,10,10,17,10,15,12,10,12,12,12,0,0,0,0,0,0
0,0,0,0,0,0,0,0,0,0,0,0,0,0,0,0,0,0,0,0,0,0,0,0,0,0,0,0,0,0,0,0,0
0,0,0,0,0,0,0,0,0,0,0,0,0,0,0,0,0,0,0,0,0,0,0,0,0,0,0,0,0,0,0,0,0
0,0,0,0,0,0,0,0,0,0,0,0,0,0,0,0,0,0,0,0,0,0,0,0,0,0,0,0,0,0,0,0,0
0,0,0,0,0,0,0,0,0,0,0,0,0,0,0,0,0,0,0,0,0,0,0,0,0,0,0,0,0,0,0,0,0
endlayer

layer
0,0,0,0,0,0,0,0,0,0,0,0,0,0,0,0,0,0,0,0,0,0,0,0,0,0,0,0,0,0,0,0,0
0,0,0,0,0,0,0,0,0,0,0,0,0,0,0,0,0,0,0,0,0,0,0,0,0,0,0,0,0,0,0,0,0
0,0,0,0,0,0,0,0,0,0,0,0,0,0,0,0,0,0,0,0,0,0,0,0,0,0,0,0,0,0,0,0,0
0,0,0,0,0,0,0,0,0,0,0,0,0,0,0,0,0,0,0,0,0,0,0,0,0,0,0,0,0,0,0,0,0
0,0,0,0,0,0,0,0,0,0,0,0,0,0,0,0,0,0,0,0,0,0,0,0,0,0,0,0,0,0,0,0,0
0,0,0,0,0,0,0,0,0,0,0,0,0,0,0,0,0,0,0,0,0,34,0,34,0,0,0,0,0,0,0,0,0
0,0,0,0,0,0,10,12,10,12,12,38,12,12,12,10,10,10,12,10,12,5,12,12,12,82,12,0,0,0,0,0,0
0,0,0,0,0,0,12,5,12,0,12,0,0,2,0,0,0,0,0,0,0,0,0,12,10,0,12,0,0,0,0,0,0
0,0,0,0,0,0,12,0,12,0,0,10,0,0,0,0,0,0,0,0,0,0,0,0,0,0,12,0,0,0,0,0,0
0,0,0,0,0,0,10,12,12,0,12,12,0,0,0,0,0,0,0,0,0,0,0,0,12,12,12,0,0,0,0,0,0
0,0,0,0,0,0,12,0,0,0,0,10,0,0,0,0,0,0,0,0,0,0,0,10,12,0,12,0,0,0,0,0,0
0,0,0,0,0,0,23,0,0,0,0,12,0,0,0,0,0,0,0,2,10,10,12,12,10,0,10,0,0,0,0,0,0
0,0,0,0,0,0,12,0,0,0,12,12,12,0,0,0,0,0,0,10,0,0,0,0,0,0,10,0,0,0,0,0,0
0,0,0,0,0,0,12,10,12,0,0,0,0,10,0,0,0,0,0,0,0,0,0,0,12,12,12,0,0,0,0,0,0
0,0,0,0,0,8,10,0,0,0,0,0,0,12,0,0,0,12,12,0,0,0,0,0,0,0,10,0,0,0,0,0,0
0,0,0,0,0,0,12,0,0,0,0,0,0,0,0,0,0,0,10,12,12,0,0,0,0,0,12,0,0,0,0,0,0
0,0,0,0,0,0,12,0,0,0,0,0,10,10,12,0,12,10,0,0,0,10,0,0,0,2,12,0,0,0,0,0,0
0,0,0,0,0,0,12,0,0,0,0,10,0,12,6,0,0,0,0,0,10,12,10,10,12,12,10,0,0,0,0,0,0
0,0,0,0,0,0,10,0,0,0,0,12,0,0,0,0,0,0,0,12,10,12,12,12,12,10,12,0,0,0,0,0,0
0,0,0,0,0,0,12,0,0,0,0,12,0,12,0,12,0,0,0,0,0,0,0,0,12,10,12,0,0,0,0,0,0
0,0,0,0,0,0,12,0,0,0,0,10,10,0,0,0,0,0,0,0,0,0,0,0,0,0,12,0,0,0,0,0,0
0,0,0,0,0,0,12,0,0,0,0,0,0,0,12,10,12,10,12,0,0,0,0,0,10,10,12,0,0,0,0,0,0
0,0,0,0,0,0,12,0,0,0,0,0,0,12,0,0,12,0,0,12,0,0,0,0,0,12,12,0,0,0,0,0,0
0,0,0,0,0,0,10,58,0,0,0,0,23,0,0,0,12,0,0,0,58,0,0,0,0,12,10,0,0,0,0,0,0
0,0,0,0,0,0,12,52,0,0,0,0,12,0,0,0,12,0,0,0,12,0,0,0,0,52,12,0,0,0,0,0,0
0,0,0,0,0,0,12,52,0,0,0,0,12,12,12,12,50,12,12,12,12,0,0,0,0,52,12,0,0,0,0,0,0
0,0,0,0,0,0,10,52,0,0,0,0,10,0,0,0,12,0,0,9,10,0,0,0,0,52,12,0,0,0,0,0,0
0,0,0,0,0,8,12,12,0,0,0,0,10,0,0,0,12,0,0,0,12,0,0,0,0,10,10,0,0,0,0,0,0
0,0,0,0,0,0,23,0,0,0,0,0,9,10,0,0,12,0,0,12,0,0,0,0,0,0,10,0,0,0,0,0,0
0,0,0,0,0,0,10,0,0,0,0,0,0,0,12,10,12,12,10,0,0,0,0,0,0,0,12,0,0,0,0,0,0
0,0,0,0,0,0,10,0,0,0,0,0,0,0,0,0,0,0,0,0,0,0,0,0,0,0,10,0,0,0,0,0,0
0,0,0,0,0,0,5,0,0,0,0,0,0,0,0,0,0,0,0,0,0,0,0,0,0,0,12,0,0,0,0,0,0
0,0,0,0,0,0,10,0,0,0,0,0,0,0,0,0,0,0,0,0,0,0,0,0,0,0,12,0,0,0,0,0,0
0,0,0,0,0,0,12,0,0,0,0,0,0,0,0,0,0,0,0,0,0,0,0,0,0,0,12,0,0,0,0,0,0
0,0,0,0,0,0,12,0,0,0,0,0,0,0,0,0,0,0,0,0,0,0,0,0,0,0,12,0,0,0,0,0,0
0,0,0,0,0,0,12,94,94,12,94,94,10,73,73,73,73,73,73,73,12,94,94,12,94,94,10,0,0,0,0,0,0
0,0,0,0,0,0,12,89,89,89,89,89,10,12,12,12,12,12,10,12,12,89,89,89,89,89,12,0,0,0,0,0,0
0,0,0,0,0,0,12,0,0,0,0,0,0,0,0,0,0,0,0,0,0,0,0,0,0,0,12,0,0,0,0,0,0
0,0,0,0,0,0,10,10,12,12,10,12,12,12,10,10,12,12,12,12,12,12,12,12,12,10,10,0,0,0,0,0,0
0,0,0,0,0,0,0,0,0,0,0,0,0,0,0,0,0,0,0,0,0,0,0,0,0,0,0,0,0,0,0,0,0
0,0,0,0,0,0,0,0,0,0,0,0,0,0,0,0,0,0,0,0,0,0,0,0,0,0,0,0,0,0,0,0,0
0,0,0,0,0,0,0,0,0,0,0,0,0,0,0,0,0,0,0,0,0,0,0,0,0,0,0,0,0,0,0,0,0
0,0,0,0,0,0,0,0,0,0,0,0,0,0,0,0,0,0,0,0,0,0,0,0,0,0,0,0,0,0,0,0,0
endlayer

layer
0,0,0,0,0,0,0,0,0,0,0,0,0,0,0,0,0,0,0,0,0,0,0,0,0,0,0,0,0,0,0,0,0
0,0,0,0,0,0,0,0,0,0,0,0,0,0,0,0,0,0,0,0,0,0,0,0,0,0,0,0,0,0,0,0,0
0,0,0,0,0,0,0,0,0,0,0,0,0,0,0,0,0,0,0,0,0,0,0,0,0,0,0,0,0,0,0,0,0
0,0,0,0,0,0,0,0,0,0,0,0,0,0,0,0,0,0,0,0,0,0,0,0,0,0,0,0,0,0,0,0,0
0,0,0,0,0,0,0,0,0,0,0,0,0,0,0,0,0,0,0,0,0,0,0,0,0,0,0,0,0,0,0,0,0
0,0,0,0,0,0,0,0,0,0,0,0,0,0,0,0,0,0,0,0,0,34,0,0,0,0,0,0,0,0,0,0,0
0,0,0,0,0,0,12,12,10,10,10,12,12,12,82,12,12,12,12,10,10,12,12,12,12,12,10,0,0,0,0,0,0
0,0,0,0,0,0,12,10,12,10,12,12,12,12,12,10,12,12,12,12,12,12,12,12,12,10,12,0,0,0,0,0,0
0,0,0,0,0,0,10,12,17,10,12,12,12,12,10,12,12,10,12,12,12,12,12,12,24,12,12,0,0,0,0,0,0
0,0,0,0,0,0,12,12,12,10,12,12,12,12,12,10,10,10,12,12,12,12,12,10,12,12,10,0,0,0,0,0,0
0,0,0,0,0,0,12,12,12,12,12,10,12,12,12,10,12,25,12,10,82,12,12,12,12,12,10,0,0,0,0,0,0
0,0,0,0,0,0,85,12,12,10,12,12,10,12,12,12,12,12,24,12,12,12,12,12,12,12,12,0,0,0,0,0,0
0,0,0,0,0,0,12,10,10,12,12,10,10,10,12,10,10,12,12,12,12,12,12,12,12,10,10,0,0,0,0,0,0
0,0,0,0,0,0,12,12,10,12,12,12,12,10,12,10,12,12,15,12,12,12,12,12,12,12,12,0,0,0,0,0,0
0,0,0,0,0,8,10,12,10,10,12,12,12,12,17,10,12,12,10,12,12,12,12,12,12,12,10,0,0,0,0,0,0
0,0,0,0,0,0,12,12,10,12,12,12,12,10,12,10,12,12,85,10,12,12,10,12,12,12,12,0,0,0,0,0,0
0,0,0,0,0,0,12,12,10,12,12,10,12,12,12,10,12,12,12,10,10,12,12,12,12,12,22,0,0,0,0,0,0
0,0,0,0,0,0,10,12,12,12,12,10,12,10,10,12,10,12,10,12,12,12,10,12,12,10,10,0,0,0,0,0,0
0,0,0,0,0,0,10,12,10,25,10,10,12,12,12,12,10,12,12,12,10,12,10,12,10,12,12,6,0,0,0,0,0
0,0,0,0,0,0,10,12,10,12,10,12,10,10,10,12,12,12,22,12,12,10,12,12,12,12,12,0,0,0,0,0,0
0,0,0,0,0,0,12,10,12,10,12,12,12,24,12,12,12,10,12,10,12,12,10,10,12,12,12,0,0,0,0,0,0
0,0,0,0,0,0,12,10,10,12,12,10,12,12,12,12,10,10,12,12,12,12,12,10,10,10,10,0,0,0,0,0,0
0,0,0,0,0,0,17,12,12,12,12,22,10,12,5,5,12,5,5,12,10,10,12,10,10,12,12,0,0,0,0,0,0
0,0,0,0,0,0,23,12,12,10,12,12,12,5,5,5,25,5,5,5,12,12,12,12,12,10,12,0,0,0,0,0,0
0,0,0,0,0,0,12,12,10,10,12,12,10,5,5,5,12,5,5,5,12,12,10,12,10,12,12,0,0,0,0,0,0
0,0,0,0,0,0,10,12,10,12,10,12,12,12,12,12,12,12,12,10,10,10,22,12,12,12,12,0,0,0,0,0,0
0,0,0,0,0,0,12,12,10,10,12,12,12,5,5,5,10,5,5,12,12,12,10,12,10,12,12,0,0,0,0,0,0
0,0,0,0,0,8,10,12,12,10,12,12,12,5,5,5,12,5,5,10,12,12,10,12,12,10,12,0,0,0,0,0,0
0,0,0,0,0,0,10,10,10,10,10,10,12,12,5,5,12,5,5,12,10,12,10,12,12,10,12,0,0,0,0,0,0
0,0,0,0,0,0,12,12,12,10,12,12,12,12,12,12,12,12,12,12,12,12,10,12,10,12,12,0,0,0,0,0,0
0,0,0,0,0,0,12,12,10,12,12,12,12,12,12,10,10,12,10,25,12,12,10,12,12,10,10,0,0,0,0,0,0
0,0,0,0,0,0,12,12,10,10,12,10,10,12,12,12,12,10,10,12,82,82,10,12,12,12,12,0,0,0,0,0,0
0,0,0,0,0,0,10,85,10,12,12,12,10,12,12,12,10,12,10,12,12,10,12,12,25,12,12,0,0,0,0,0,0
0,0,0,0,0,0,12,10,10,10,10,10,10,12,10,24,12,22,12,12,12,10,12,12,12,12,10,0,0,0,0,0,0
0,0,0,0,0,0,10,12,12,10,12,12,12,12,12,10,12,10,10,10,10,12,12,12,12,10,10,0,0,0,0,0,0
0,0,0,0,0,0,10,10,10,12,12,25,10,10,10,12,12,12,10,10,12,10,12,12,12,12,10,0,0,0,0,0,0
0,0,0,0,0,0,12,12,12,12,10,10,12,10,12,12,12,12,10,12,12,12,10,12,10,10,12,0,0,0,0,0,0
0,0,0,0,0,0,12,12,12,12,12,12,12,12,12,12,10,12,12,10,12,12,12,12,12,12,12,0,0,0,0,0,0
0,0,0,0,0,0,10,12,25,12,12,12,12,10,12,25,10,12,25,10,10,10,12,10,25,10,12,0,0,0,0,0,0
0,0,0,0,0,0,0,0,0,0,0,0,0,0,0,0,0,0,0,0,0,0,0,0,0,0,0,0,0,0,0,0,0
0,0,0,0,0,0,0,0,0,0,0,0,0,0,0,0,0,0,0,0,0,0,0,0,0,0,0,0,0,0,0,0,0
0,0,0,0,0,0,0,0,0,0,0,0,0,0,0,0,0,0,0,0,0,0,0,0,0,0,0,0,0,0,0,0,0
0,0,0,0,0,0,0,0,0,0,0,0,0,0,0,0,0,0,0,0,0,0,0,0,0,0,0,0,0,0,0,0,0
endlayer

