
# Created by Ruins mod version 17.2 Ingame Parser
# authoring Player: BARTLLOW

# TEMPLATE PARAMETER SETTINGS:
#
# criterion expression specifying mod ids required to load template
# may include plus (AND), minus (AND NOT), comma (OR), and parentheses
# all required mods listed must be present; no prohibited mods can be
requiredMods=
#
# likelihood this template will be chosen relative to all others
# e.g., a weight=6 template is chosen 3X as often as one with weight=2
weight=1
#
# list of dimensions in which this template may spawn, even if generic
# one or more dimension names, separated by commas (blank = all)
dimensionsToSpawnIn=
#
# list of other biomes in which this template may spawn
# biome corresponding to directory is always assumed, listed or not
# generic templates should leave this list empty
biomesToSpawnIn=
#
# criterion expression specifying types of biome where template spawns
# this is in addition to those explicitly listed as biomesToSpawnIn
# generic templates should leave this list empty
biomeTypesToSpawnIn=
#
# list of biomes in which this template may not spawn
# takes precedence over biomeTypesToSpawnIn, but NOT biomesToSpawnIn
# should be empty if biomeTypesToSpawnIn is empty
biomesToNotSpawnIn=
#
# depth template is pushed down into the surface when built
# offset is min/max range of random additional bury depth
embed_into_distance=0
random_height_offset=0,0
#
# whitelist/blacklist of block types on which template may be built
# specify one, not both; leave the other empty (both empty = allow all)
acceptable_target_blocks=
unacceptable_target_blocks=flowing_water,water,flowing_lava,lava
#
# size of template (#layers, #rows per layer, #blocks per row)
dimensions=35,47,31
#
# max number of missing blocks allowed in surface beneath template
allowable_overhang=0
#
# depth/height limit affected by terrain leveling
# also maximum bumpiness tolerated in surface beneath template
max_leveling=2
#
# padding applied to all sides of template horizontal footprint
# expands area affected by terrain leveling (-1 = no leveling)
leveling_buffer=0
#
# do not rotate template randomly when built (1 = no rotation)
preventRotation=0
#
# treat water/lava blocks as air and protect them from rule0 (1 = yes)
preserve_water=0
preserve_lava=0
#
# minimum distance this template must have from instances of itself
uniqueMinDistance=0
#
# min/max distances this template can be from world spawn (0 = no limit)
# only applies to overworld--i.e., dimension 0
spawnMinDistance=0
spawnMaxDistance=0
#
# other template built nearby whenever this one is
# syntax: <name>;<relativeX>;<maxYdifference>;<relativeZ>[;<chance>]
# may be used more than once to specify multiple neighbors
adjoining_template=

rule1=0,100,minecraft:sponge-0
rule2=0,100,minecraft:dirt-0
rule3=0,100,minecraft:mossy_cobblestone-0
rule4=0,100,minecraft:stone-0
rule5=0,100,minecraft:vine-1
rule6=0,100,minecraft:leaves-0
rule7=0,100,minecraft:stone_brick_stairs-2
rule8=0,100,minecraft:stone_brick_stairs-0
rule9=0,100,minecraft:leaves-3
rule10=0,100,minecraft:stone_brick_stairs-3
rule11=0,100,minecraft:stonebrick-0
rule12=0,100,minecraft:stonebrick-2
rule13=0,100,minecraft:vine-4
rule14=0,100,minecraft:stonebrick-1
rule15=0,100,minecraft:cobblestone-0
rule16=0,100,minecraft:stone_brick_stairs-7
rule17=0,100,minecraft:stone_brick_stairs-1
rule18=0,100,minecraft:stone_brick_stairs-6
rule19=0,100,minecraft:stone_stairs-0
rule20=0,100,minecraft:stone_slab-5
rule21=0,100,minecraft:stone_brick_stairs-4
rule22=0,100,minecraft:stone_stairs-3
rule23=0,100,minecraft:vine-2
rule24=0,100,minecraft:vine-8
rule25=0,100,minecraft:stone_brick_stairs-5
rule26=0,100,minecraft:stone_stairs-7
rule27=0,100,minecraft:vine-6
rule28=0,100,minecraft:stone_stairs-2
rule29=0,100,minecraft:vine-3
rule30=0,100,minecraft:stone_stairs-1
rule31=0,100,minecraft:stained_hardened_clay-9
rule32=0,100,minecraft:cobblestone_wall-1
rule33=0,100,minecraft:cobblestone_wall-0
rule34=0,100,minecraft:web-0
rule35=0,100,minecraft:double_stone_slab-5
rule36=0,100,minecraft:vine-9
rule37=0,100,minecraft:mob_spawner-0
rule38=0,100,minecraft:vine-10
rule39=0,100,minecraft:vine-12
rule40=0,100,minecraft:stone_slab-11
rule41=0,100,minecraft:stone_stairs-6
rule42=0,100,minecraft:stone_stairs-4
rule43=0,100,minecraft:stone_stairs-5
rule44=0,100,minecraft:stone_slab-13
rule45=0,100,minecraft:stone_slab-3
rule46=0,100,minecraft:grass-0
rule47=0,100,minecraft:tallgrass-1
rule48=0,100,minecraft:double_plant-3
rule49=0,100,minecraft:redstone_block-0
rule50=0,100,IInventory;minecraft:chest;minecraft:name_tag#1#0#1+minecraft:record_13#1#0#9+minecraft:name_tag#1#0#15+minecraft:record_13#1#0#17+minecraft:golden_apple#1#0#22+minecraft:saddle#1#0#26-3
rule51=0,100,IInventory;minecraft:chest;minecraft:golden_apple#1#1#5+minecraft:iron_horse_armor#1#0#12+minecraft:record_cat#1#0#14+minecraft:record_13#1#0#19-3
rule52=0,100,IInventory;minecraft:chest;minecraft:enchanted_book#{StoredEnchantments:[{lvl:1s,id:6s}]}#0#0+minecraft:record_13#1#0#6+minecraft:iron_horse_armor#1#0#7+minecraft:name_tag#1#0#8+minecraft:name_tag#1#0#10+minecraft:saddle#1#0#24+minecraft:name_tag#1#0#26-3
rule53=0,100,IInventory;minecraft:chest;minecraft:record_cat#1#0#12+minecraft:golden_horse_armor#1#0#13+minecraft:iron_horse_armor#1#0#14+minecraft:name_tag#1#0#20+minecraft:diamond_horse_armor#1#0#21-3
rule54=0,100,minecraft:double_plant-10
rule55=0,100,minecraft:vine-5
rule56=0,100,minecraft:redstone_lamp-0
rule57=0,100,minecraft:lit_redstone_lamp-0
rule58=0,100,minecraft:stone-4
rule59=0,100,minecraft:log-15
rule60=0,100,minecraft:double_stone_slab-3
rule61=0,100,minecraft:stained_hardened_clay-14

layer
1,1,1,1,1,1,1,1,1,1,1,1,1,1,1,1,1,1,1,1,1,1,1,1,1,1,1,1,1,1,1
1,1,1,1,1,1,1,1,1,1,1,1,1,1,1,1,1,1,1,1,1,1,1,1,1,1,1,1,1,1,1
1,1,1,2,1,1,1,1,1,2,1,1,1,1,2,2,1,1,1,1,1,2,1,1,1,1,1,1,1,1,1
1,1,1,2,1,1,2,2,2,1,1,2,1,1,1,1,2,1,1,2,1,2,1,1,1,1,1,2,1,1,1
1,1,2,1,2,1,1,1,1,2,1,1,1,1,1,1,2,1,2,1,1,2,2,2,1,1,1,2,1,1,1
1,1,1,2,2,2,2,2,1,2,1,1,2,2,1,1,2,2,1,1,2,2,2,1,1,2,2,2,1,1,1
1,1,1,1,2,1,2,2,2,2,1,2,2,2,1,2,2,1,1,1,1,1,1,1,1,1,1,2,1,1,1
1,1,1,2,2,1,1,1,1,1,1,1,1,2,2,1,1,2,1,1,1,2,2,2,2,1,2,2,1,1,1
1,1,1,2,2,1,1,1,1,1,1,1,1,1,1,2,1,2,2,1,1,2,1,2,1,1,1,2,1,1,1
1,1,1,1,1,1,2,1,2,1,2,1,1,2,1,1,1,1,1,2,1,1,2,2,1,2,1,1,2,1,1
1,1,1,2,2,1,1,1,1,2,2,2,1,1,2,2,2,1,2,2,2,1,1,2,2,2,1,1,1,1,1
1,1,1,1,2,2,1,1,1,2,2,2,1,1,1,2,2,2,1,1,1,1,1,2,1,1,1,1,1,1,1
1,1,1,1,1,1,2,2,2,2,1,2,2,2,2,2,2,2,1,1,2,2,1,2,1,2,2,2,1,1,1
1,1,1,1,2,1,2,1,1,2,2,2,2,2,1,1,2,1,1,1,1,2,2,1,1,1,2,1,1,1,1
1,1,1,2,1,1,2,2,2,1,2,2,1,2,1,2,1,1,2,1,1,2,1,2,1,2,1,1,2,1,1
1,1,1,1,2,1,2,1,2,2,2,1,2,1,1,1,2,1,1,1,1,1,1,1,2,1,1,2,1,1,1
1,1,2,2,1,1,2,2,1,2,2,2,1,2,1,1,2,1,1,1,1,1,1,1,2,1,1,1,2,1,1
1,1,1,2,1,1,1,2,2,1,2,1,1,2,2,2,2,2,1,1,1,1,2,1,2,1,2,2,1,1,1
1,1,1,1,1,2,2,1,1,2,1,1,1,2,1,2,2,2,1,1,1,2,2,2,1,1,1,2,1,1,1
1,1,2,1,2,2,1,1,2,2,2,1,1,2,1,2,2,1,2,1,2,2,2,2,1,1,1,1,1,1,1
1,1,1,2,1,2,2,2,2,2,1,1,2,1,2,1,1,1,2,2,1,2,1,1,1,1,1,1,1,1,1
1,1,1,2,1,2,1,1,2,1,1,1,1,2,2,1,1,2,2,1,1,1,2,2,2,1,1,1,1,1,1
1,1,1,1,2,1,1,2,1,1,2,1,2,1,1,1,1,1,2,2,2,2,1,1,1,1,1,2,1,1,1
1,1,1,1,1,1,1,1,1,2,1,2,1,1,1,2,1,2,2,1,1,1,2,2,2,1,1,1,1,1,1
1,1,1,2,1,1,2,1,1,1,1,1,2,1,1,2,1,2,1,1,1,1,1,1,2,2,2,1,2,1,1
1,1,2,1,2,2,1,1,1,2,1,2,1,1,1,2,2,1,1,2,2,2,1,1,2,1,1,2,1,1,1
1,1,2,1,1,1,1,2,2,1,2,1,2,1,1,2,2,2,2,2,1,1,2,2,2,1,1,1,1,1,1
1,1,2,2,2,2,2,1,2,1,1,2,1,1,2,2,1,2,1,2,1,2,2,1,1,1,1,1,1,1,1
1,1,1,2,2,2,2,2,2,2,1,2,1,2,2,2,2,2,1,1,1,1,2,2,2,1,1,1,1,1,1
1,1,1,1,1,2,2,1,1,1,1,2,1,1,1,2,1,1,1,1,1,2,1,1,1,2,1,1,1,1,1
1,1,1,2,1,1,1,1,2,2,1,1,1,1,2,1,1,2,2,1,1,1,1,2,2,2,1,1,2,1,1
1,1,1,1,2,1,1,2,1,2,2,2,2,1,1,1,1,1,1,2,1,1,2,2,2,1,2,2,2,1,1
1,1,2,2,2,2,2,2,2,1,2,2,2,1,1,1,1,1,1,1,2,1,1,1,1,1,2,2,2,1,1
1,1,1,1,2,1,2,1,1,2,2,1,2,2,1,1,2,2,2,2,2,1,1,2,1,1,2,1,1,1,1
1,1,1,1,2,1,1,1,1,2,2,1,1,2,1,1,2,1,2,2,1,2,1,1,1,1,2,1,1,1,1
1,1,1,2,3,2,1,1,2,2,1,1,1,2,1,2,1,1,2,2,2,1,1,1,1,2,1,2,1,1,1
1,1,1,1,2,2,1,1,1,1,2,1,1,1,1,1,2,1,2,2,1,2,2,1,2,1,2,1,1,1,1
1,1,2,2,2,1,2,2,2,2,2,1,1,2,1,1,2,1,1,1,1,1,1,1,2,1,1,1,2,1,1
1,1,1,2,2,1,1,1,1,1,1,1,1,1,1,2,2,1,1,1,2,2,1,1,1,2,1,2,1,1,1
1,1,1,2,2,2,1,1,1,2,1,1,2,2,2,2,2,2,1,1,2,2,1,2,2,2,1,1,1,1,1
1,1,1,1,1,2,1,1,1,2,1,2,2,2,1,1,1,2,1,2,1,1,1,1,1,2,1,2,1,1,1
1,1,1,2,2,1,1,1,2,1,1,1,1,1,1,1,2,1,2,2,1,1,1,1,2,1,2,2,1,1,1
1,1,1,2,2,1,1,1,2,1,2,1,1,2,1,1,1,2,2,1,2,2,1,2,1,1,2,1,2,1,1
1,1,1,2,2,2,1,1,2,2,2,1,1,1,2,1,1,2,1,2,1,2,2,1,2,1,1,1,2,1,1
1,1,1,1,2,1,1,1,1,1,1,1,1,1,1,2,2,1,1,1,1,2,1,1,1,1,2,2,1,1,1
1,1,1,1,4,4,1,1,1,1,1,1,1,1,1,1,1,1,1,1,1,1,1,1,1,1,1,1,1,1,1
1,1,1,1,1,1,1,1,1,1,1,1,1,1,1,1,1,1,1,1,1,1,1,1,1,1,1,1,1,1,1
endlayer

layer
0,0,6,0,0,0,0,0,0,0,0,0,0,0,0,0,6,5,0,0,0,0,0,0,0,0,0,0,0,0,0
0,10,8,8,8,8,6,0,0,0,0,0,0,8,8,8,8,8,9,0,0,0,0,0,0,8,8,8,8,7,0
9,10,11,15,14,7,9,6,8,11,8,0,9,10,11,12,11,7,9,6,8,12,8,0,13,10,11,12,11,7,0
0,10,11,11,11,11,11,11,12,11,11,11,11,11,12,14,11,16,7,11,11,11,11,11,11,12,11,12,12,7,0
0,10,11,11,11,15,11,14,15,15,11,12,11,11,11,11,15,12,11,11,11,11,12,12,12,11,15,12,11,7,0
0,10,17,15,11,11,15,11,14,12,11,11,12,12,11,11,12,15,11,11,11,15,12,11,14,11,11,14,17,7,0
0,0,0,12,11,12,11,11,11,11,11,11,12,11,11,11,11,11,12,12,15,12,12,12,11,12,14,11,0,0,0
0,0,0,12,11,11,12,11,11,12,14,12,11,11,15,11,11,12,11,15,15,11,11,11,11,14,12,11,0,0,0
0,0,10,15,11,11,11,14,11,12,12,11,11,11,15,12,11,11,12,11,11,11,11,14,11,16,11,11,8,0,0
0,6,11,12,11,18,15,11,12,11,11,12,12,11,12,11,12,11,11,11,11,11,15,11,11,12,11,15,12,0,0
0,6,10,12,11,11,11,11,15,11,15,11,12,15,15,11,11,10,12,11,11,15,12,11,11,12,11,11,7,9,0
0,0,6,11,11,12,11,15,11,12,15,11,12,12,11,12,11,11,11,11,12,11,11,12,11,11,14,11,0,0,0
0,9,0,12,11,15,11,15,11,11,11,11,11,11,11,11,15,11,11,12,15,11,12,11,11,11,12,11,0,0,0
9,10,8,19,12,11,11,11,11,15,11,11,11,11,11,12,11,11,14,12,12,11,15,12,11,12,11,12,8,7,0
0,10,12,12,12,11,11,11,11,14,15,11,12,12,11,11,11,11,11,11,11,11,11,11,15,11,15,12,12,7,0
0,10,11,11,12,11,11,11,15,11,11,7,11,12,12,11,8,11,12,11,11,12,11,14,12,11,11,11,11,7,0
0,10,15,11,12,11,15,11,12,11,11,11,11,11,11,11,11,12,11,11,11,11,11,15,12,11,12,11,11,7,0
0,17,17,11,12,11,11,11,14,7,11,12,11,11,12,15,11,11,11,12,11,15,12,11,11,12,11,15,17,17,0
0,8,6,9,11,11,12,14,11,15,11,11,11,12,11,11,11,15,12,11,11,14,11,11,15,11,17,11,0,0,0
0,10,15,12,15,12,12,11,12,12,11,11,12,12,12,12,12,11,12,11,12,11,11,11,11,11,15,11,9,0,0
0,10,11,11,11,11,11,15,11,11,11,11,11,11,15,11,11,12,11,14,12,11,12,11,11,12,11,11,6,0,0
0,20,15,11,11,12,11,12,12,12,11,11,12,12,11,11,11,12,14,12,11,11,15,12,15,12,11,12,7,6,5
0,10,21,11,11,11,11,11,12,15,11,11,11,12,11,12,12,12,14,12,12,11,11,10,11,11,11,11,11,6,0
0,20,11,11,14,11,16,11,15,11,11,12,15,12,7,11,12,11,11,11,11,15,11,11,11,11,12,11,7,0,0
0,10,15,12,12,8,12,12,11,11,11,12,11,11,11,11,11,12,12,11,11,11,12,11,11,15,12,12,12,0,0
0,22,11,12,21,14,11,11,15,17,11,15,11,11,11,11,11,11,11,11,11,11,12,12,11,12,11,12,7,0,0
0,10,15,12,11,11,11,12,12,12,11,12,11,11,11,11,15,12,14,12,11,11,11,11,11,11,12,11,0,0,0
0,10,11,11,12,11,11,12,11,11,12,12,15,12,12,11,12,11,11,12,11,11,11,11,11,12,11,11,0,0,0
0,22,17,12,12,11,12,12,21,12,11,12,12,11,12,12,11,11,14,11,15,11,12,11,11,10,11,15,9,0,0
0,20,19,11,12,12,11,11,12,11,11,11,11,11,11,12,11,11,11,10,14,12,11,11,12,11,11,11,8,7,0
0,10,11,11,12,11,11,11,11,11,11,11,15,12,14,11,14,11,12,11,12,11,11,11,11,3,11,12,11,6,0
0,10,11,15,12,11,12,11,11,12,11,11,12,11,15,14,11,11,12,12,11,11,11,12,11,12,11,11,11,7,0
0,10,11,11,12,11,12,14,12,11,11,11,11,11,11,12,11,15,15,11,11,11,11,12,11,11,11,11,11,7,0
0,0,10,12,15,12,11,11,12,15,11,12,12,11,12,12,11,11,11,11,12,11,11,11,11,12,15,11,17,7,0
0,0,0,3,11,11,11,11,14,14,11,12,11,11,11,11,11,15,15,11,11,11,11,12,12,15,15,11,5,0,0
0,6,6,11,12,11,11,11,12,11,12,12,12,11,11,11,11,12,11,11,11,12,15,11,11,11,11,11,5,0,0
9,6,10,11,11,12,12,12,14,11,15,11,11,14,11,11,12,12,14,15,11,11,12,12,11,11,11,11,7,0,0
0,6,11,11,12,11,11,12,12,12,15,11,11,15,11,11,11,11,11,11,15,14,11,11,11,11,11,11,11,0,0
0,0,10,11,12,11,11,11,12,14,11,11,14,11,11,11,14,12,12,14,11,11,11,11,12,11,12,11,7,0,0
0,0,0,12,14,11,11,12,12,11,11,11,11,8,12,11,11,11,11,12,11,12,11,11,15,12,12,12,9,9,0
0,0,0,18,11,12,11,11,11,12,11,12,12,11,15,12,11,11,11,11,11,12,11,12,12,11,11,11,0,6,0
0,10,8,12,15,11,11,11,12,14,11,15,11,11,15,15,11,11,11,12,12,12,11,11,12,11,11,11,8,7,9
0,10,14,11,11,11,12,11,11,11,11,15,11,11,11,11,15,11,11,12,11,12,11,11,11,12,12,11,11,18,0
9,10,3,11,11,11,11,11,12,12,15,11,11,11,12,12,11,12,3,11,11,11,11,11,11,11,11,11,12,7,0
13,10,11,11,11,7,23,6,17,12,17,0,9,10,11,12,11,7,0,0,17,11,17,0,9,10,12,11,11,7,0
6,10,17,17,17,17,0,0,9,6,0,0,0,17,17,17,17,17,0,0,0,23,0,0,9,17,17,17,17,7,0
0,9,6,0,0,0,0,0,0,0,0,0,0,0,9,5,0,0,0,0,0,0,0,0,0,6,6,0,0,0,0
endlayer

layer
0,0,6,0,0,0,0,0,0,0,0,0,0,0,0,0,0,0,0,0,0,0,0,0,0,0,0,0,0,0,0
0,9,9,9,0,0,24,0,0,0,0,0,0,0,0,24,6,6,0,0,0,0,0,0,0,0,0,0,24,0,0
0,9,11,12,15,6,6,0,0,15,5,0,0,9,11,15,11,6,6,0,0,15,0,0,13,0,11,12,14,0,0
0,9,12,11,11,18,21,21,16,11,18,21,21,16,12,11,11,18,21,21,16,11,18,21,21,16,11,11,11,0,0
0,0,3,11,11,11,11,12,12,11,11,12,12,12,11,11,11,12,15,11,11,12,11,11,12,11,11,11,12,0,0
0,0,0,25,11,12,12,15,11,12,14,15,12,15,15,12,11,12,11,12,17,15,11,11,12,11,11,25,0,0,0
0,0,0,16,11,11,12,12,12,12,11,11,11,11,11,12,15,12,10,12,11,11,11,12,11,11,11,18,0,0,0
0,0,0,16,11,11,3,11,11,11,12,11,11,12,11,12,15,11,11,11,14,11,11,15,11,11,11,18,0,0,0
0,0,0,21,11,11,12,11,11,11,11,11,15,12,11,12,11,11,11,11,11,11,12,11,11,11,11,21,0,0,0
0,0,11,11,11,15,11,12,11,15,11,11,15,11,11,18,11,11,11,11,11,15,11,11,11,15,10,12,11,0,0
0,0,23,25,12,11,11,12,12,12,11,14,11,11,11,11,12,11,12,11,11,12,12,11,12,11,12,25,23,0,0
0,0,0,16,11,12,7,11,15,15,11,11,11,11,15,11,11,11,11,11,12,11,11,7,11,12,11,18,5,0,0
0,0,0,16,12,11,11,15,11,11,12,11,12,12,11,11,11,12,11,12,11,11,11,11,12,11,11,18,0,0,0
0,9,0,21,11,15,11,11,11,12,11,12,12,11,11,12,11,12,12,11,14,11,11,11,14,11,25,21,0,0,0
0,0,12,11,12,12,11,12,15,11,12,14,11,12,12,11,11,11,15,12,11,12,12,12,12,14,11,7,14,0,0
0,0,12,11,11,12,12,12,11,11,11,11,11,11,11,11,11,15,11,11,12,15,11,11,11,12,11,15,12,0,0
0,0,11,11,11,11,11,12,15,12,15,11,15,14,11,11,11,12,11,14,16,11,11,15,11,11,11,14,11,0,0
0,0,6,12,11,11,12,11,12,11,11,11,7,11,11,12,11,12,11,11,15,11,11,11,12,11,11,12,23,0,0
0,0,0,11,12,12,11,11,12,15,19,12,25,11,15,12,11,11,14,11,11,15,14,11,11,15,11,11,0,0,0
0,0,8,11,11,11,11,15,16,11,12,11,11,11,17,15,11,11,15,12,11,11,11,11,12,12,15,11,0,0,0
0,0,20,12,11,12,12,11,12,12,11,11,12,12,11,11,12,11,12,11,12,12,11,11,12,11,11,11,6,0,0
0,0,10,11,11,11,11,12,11,14,12,12,15,14,14,12,15,15,12,11,12,12,11,15,11,12,11,11,6,0,0
0,0,20,12,12,11,11,15,11,14,12,11,12,12,12,12,10,11,11,11,12,11,15,12,11,11,15,15,9,0,0
0,0,22,11,11,12,12,11,12,11,11,11,11,11,11,14,12,15,12,12,3,8,11,12,22,11,11,11,0,0,0
0,0,10,11,12,12,12,11,11,15,14,11,11,12,11,12,11,12,12,11,12,11,12,12,11,11,11,12,7,0,0
0,0,20,11,11,15,12,11,11,11,12,12,11,11,12,11,15,11,11,11,12,14,11,14,12,11,11,26,0,0,0
0,0,10,11,11,12,11,11,15,8,11,11,11,11,11,11,11,12,15,11,11,11,12,11,12,11,15,11,0,0,0
0,0,17,12,11,14,11,11,11,12,11,11,11,11,11,11,12,11,11,11,12,14,12,11,11,12,11,12,0,0,0
0,0,13,12,14,11,11,11,11,11,11,14,12,11,12,11,15,11,11,11,11,15,11,15,12,11,14,12,0,0,0
0,0,0,11,11,12,11,11,12,11,11,11,11,11,11,12,11,12,12,14,14,11,12,12,11,12,11,12,6,0,0
0,13,15,14,11,11,11,11,11,12,11,12,11,11,11,11,11,11,11,15,15,12,11,11,11,11,12,11,11,0,0
0,0,11,12,12,11,11,12,11,11,11,11,12,12,12,11,14,11,11,11,12,11,12,14,15,15,11,11,11,9,0
0,0,10,11,12,12,21,3,12,11,11,12,11,12,18,12,11,11,11,12,11,16,12,11,11,11,11,14,11,0,0
0,0,0,25,11,15,15,11,11,11,11,12,11,11,11,15,11,11,11,12,11,11,12,11,12,11,15,25,5,0,0
0,0,0,16,12,11,11,11,12,11,11,12,11,11,12,12,15,11,11,11,11,11,11,11,12,11,11,18,0,0,0
0,0,24,16,15,11,11,12,11,12,11,11,11,11,12,11,11,11,11,11,12,12,12,12,11,11,11,18,0,0,0
0,6,6,21,12,11,11,11,12,11,12,15,12,11,11,12,11,11,12,11,11,11,12,12,11,15,15,21,5,0,0
0,0,11,12,11,11,12,11,11,12,11,11,14,11,11,12,11,12,12,11,11,12,12,12,11,12,12,11,11,0,0
0,0,0,25,11,11,11,11,12,15,11,11,11,11,11,11,12,12,12,11,11,14,15,11,12,14,11,25,0,0,0
0,0,0,16,11,14,11,11,11,11,14,11,11,17,12,15,11,11,12,11,11,12,11,12,11,11,11,18,9,0,0
0,0,0,16,25,11,12,11,11,18,12,11,11,11,11,11,11,14,12,12,12,11,11,11,11,12,11,18,0,9,0
0,0,0,21,11,11,11,14,11,11,11,11,14,11,11,15,11,11,11,11,11,11,11,11,11,11,11,21,9,0,0
0,0,11,15,11,15,11,3,12,11,11,12,15,11,15,14,11,12,11,11,12,11,11,11,12,12,11,15,12,0,0
0,0,11,11,11,18,25,25,16,11,18,25,25,16,12,11,11,18,25,25,16,11,18,25,25,16,11,15,11,0,0
13,6,11,12,12,0,0,0,6,11,0,0,0,0,12,12,12,0,0,0,27,16,0,0,0,6,11,11,11,0,0
0,9,9,0,23,0,0,0,0,6,0,0,0,6,9,5,0,0,0,0,0,0,0,0,0,9,6,6,0,0,0
0,0,0,0,0,0,0,0,0,0,0,0,0,0,0,0,0,0,0,0,0,0,0,0,0,0,0,0,0,0,0
endlayer

layer
0,0,0,0,0,0,0,0,0,0,0,0,0,0,0,0,0,0,0,0,0,0,0,0,0,0,0,0,0,0,0
0,0,9,0,0,0,0,0,0,0,0,0,0,0,0,24,0,0,0,0,0,0,0,0,0,0,0,0,24,0,0
0,9,11,12,11,0,6,0,0,8,0,0,0,0,14,11,14,9,0,0,0,8,0,0,13,0,11,11,11,5,0
0,0,11,11,12,11,14,12,16,11,11,12,15,11,12,11,11,11,11,11,15,14,11,12,12,12,11,12,12,0,0
0,0,25,12,11,11,15,11,12,12,11,11,11,11,11,15,15,14,15,11,11,11,11,11,14,15,11,11,3,0,0
0,0,0,15,15,12,11,12,11,7,12,11,15,15,11,12,11,11,14,11,11,15,12,11,11,11,12,11,0,0,0
0,0,0,11,11,12,11,11,11,11,15,11,12,12,11,12,12,11,15,14,14,11,15,12,12,11,11,11,0,0,0
0,0,0,11,12,17,11,12,11,12,11,28,11,12,12,15,11,14,11,12,11,12,11,11,12,11,12,11,0,0,0
0,0,0,11,11,12,11,12,11,15,12,15,12,12,11,11,11,12,12,11,11,11,15,12,11,15,12,12,0,0,0
0,0,10,12,11,12,11,12,11,12,11,11,17,11,11,15,11,15,11,11,14,12,12,14,11,12,11,11,7,0,0
0,0,0,11,11,12,14,11,12,12,15,11,11,11,11,12,11,12,12,11,12,12,11,11,12,11,11,15,0,0,0
0,0,13,11,12,11,11,12,12,11,11,12,11,15,15,14,11,11,12,18,12,12,11,11,11,11,11,11,5,0,0
0,0,0,14,11,15,11,11,12,12,11,11,11,11,11,12,11,11,11,11,15,11,11,12,11,12,11,17,0,0,0
13,9,0,15,11,11,11,11,12,12,11,12,12,12,11,11,11,15,11,12,11,15,11,11,11,11,11,7,0,0,0
0,0,11,12,12,14,11,11,11,11,15,12,11,11,11,11,11,11,11,11,11,11,11,11,12,11,11,11,14,0,0
0,0,11,14,12,15,12,14,12,11,11,11,11,15,11,11,11,12,12,12,15,11,15,11,12,11,14,21,11,0,0
0,23,11,12,11,11,12,11,14,11,11,11,28,11,11,11,12,12,17,15,11,11,11,11,15,16,11,3,11,0,0
0,13,9,11,11,11,12,11,11,17,11,11,11,15,11,12,12,12,12,11,12,3,11,12,14,11,11,12,29,0,0
0,0,0,11,11,11,15,11,11,14,12,15,11,14,15,11,11,11,15,12,11,11,11,11,7,11,11,11,0,0,0
0,0,0,11,11,11,11,11,15,11,15,11,11,11,15,12,12,11,21,11,11,14,11,12,12,14,11,12,0,0,0
0,0,0,10,11,12,11,11,11,11,15,14,11,11,15,11,12,11,11,15,11,15,11,11,11,11,12,11,0,0,0
0,0,0,10,11,14,15,12,11,11,11,11,11,11,14,11,11,12,12,15,15,11,11,12,11,11,12,11,6,0,0
0,0,0,10,11,11,11,12,15,11,12,11,15,11,11,12,12,11,11,12,11,12,11,11,12,11,11,15,9,0,0
0,0,0,20,14,11,11,11,11,15,11,11,12,15,12,11,12,11,12,12,15,11,14,12,11,11,12,11,0,0,0
0,0,0,10,11,15,15,7,14,12,12,12,11,11,12,11,11,11,11,11,11,11,18,14,11,11,11,11,0,0,0
0,0,0,22,12,12,11,12,14,11,11,11,12,11,11,11,11,11,11,11,11,11,17,11,11,15,11,11,0,0,0
0,0,0,10,11,11,14,11,12,12,12,11,14,11,12,12,12,11,14,11,22,11,14,11,15,11,12,11,0,0,0
0,0,13,10,11,12,15,12,12,11,11,12,11,12,12,11,11,11,12,12,11,11,12,11,11,11,11,11,0,0,0
0,0,13,12,11,12,11,15,11,12,11,11,11,11,12,11,21,11,11,11,16,11,11,11,11,12,12,15,0,0,0
0,0,0,11,11,11,11,11,15,12,11,11,11,11,12,12,11,11,11,11,11,12,11,12,11,15,11,11,0,0,0
0,0,11,12,11,11,11,15,11,11,11,12,11,11,11,11,11,12,11,15,11,11,12,12,11,11,12,11,15,0,0
0,0,11,12,15,11,11,12,15,12,11,12,11,14,12,14,11,14,12,11,11,11,15,11,11,11,11,11,11,0,5
0,0,12,12,11,14,12,11,15,12,15,11,11,12,11,15,11,11,11,14,11,11,11,11,11,15,12,15,25,6,0
0,0,0,11,11,11,11,11,11,11,11,12,11,12,11,15,11,11,11,15,12,11,11,11,15,11,12,15,5,23,0
0,0,0,11,11,12,25,11,12,15,12,14,11,12,12,14,12,11,11,11,12,11,12,11,11,12,11,14,0,0,0
0,0,0,11,11,15,11,11,12,11,15,11,11,11,11,11,15,15,11,11,12,15,11,11,11,15,11,11,0,0,0
0,0,9,12,12,12,11,12,11,11,12,11,15,12,11,11,12,15,11,3,11,11,18,11,11,11,12,12,5,0,0
0,0,10,11,11,12,11,11,12,12,11,11,11,11,11,12,12,11,11,15,11,11,11,12,14,14,11,11,7,0,0
0,0,0,11,12,11,12,11,11,11,11,11,12,15,11,11,12,11,11,11,12,11,11,11,11,11,11,11,0,0,0
0,0,0,11,11,11,11,12,11,14,12,11,12,11,15,11,15,11,15,14,11,11,11,11,11,11,11,11,5,0,0
0,0,0,11,3,11,11,12,11,11,12,11,12,11,12,12,11,15,14,11,11,12,11,30,12,11,12,11,6,0,0
0,0,0,10,11,11,11,11,12,11,11,11,11,11,11,11,12,11,11,12,11,11,11,15,16,15,11,12,0,0,0
0,0,11,11,12,15,12,11,11,10,11,11,11,8,15,12,15,11,12,14,11,15,11,11,11,11,12,12,11,0,0
0,0,11,14,3,12,11,11,11,15,11,17,11,12,11,11,12,12,12,11,12,12,14,17,12,18,11,11,12,0,0
0,0,14,11,11,0,0,0,9,17,0,0,0,9,11,11,12,0,0,0,23,17,0,0,0,13,11,11,14,0,0
0,6,0,0,0,0,0,0,0,6,0,0,0,0,6,29,0,0,0,0,0,0,0,0,0,0,23,6,5,0,0
0,0,0,0,0,0,0,0,0,0,0,0,0,0,0,0,0,0,0,0,0,0,0,0,0,0,0,0,0,0,0
endlayer

layer
0,0,0,0,0,0,0,0,0,0,0,0,0,0,0,0,0,0,0,0,0,0,0,0,0,0,0,0,0,0,0
0,0,0,21,0,0,0,0,0,0,0,0,0,0,0,21,0,0,0,0,0,0,0,0,0,0,0,21,24,0,0
0,9,12,11,11,0,0,9,5,0,0,0,0,0,15,12,11,0,9,0,0,0,0,0,13,9,15,15,11,5,0
0,16,11,12,15,12,8,11,8,11,8,11,8,11,12,12,11,11,8,11,8,11,8,11,8,11,12,11,11,18,0
0,0,11,11,11,11,12,11,11,11,12,11,11,11,11,11,11,14,11,11,12,11,12,11,18,11,11,11,11,0,0
0,0,0,11,12,14,11,11,14,12,12,12,11,12,12,14,11,11,11,11,14,11,12,12,11,12,11,14,0,0,0
0,0,9,10,11,12,12,12,12,11,11,25,11,11,11,14,14,14,11,12,11,11,11,12,11,12,11,7,0,0,0
0,0,23,12,12,11,12,11,11,12,14,11,11,11,11,14,12,11,14,11,11,11,11,11,11,11,11,12,0,0,0
0,0,0,10,11,11,12,12,12,12,12,14,12,12,12,12,12,12,11,11,14,11,11,11,11,11,11,7,0,0,0
0,0,0,11,11,18,14,11,11,11,12,12,12,14,12,12,16,12,11,11,12,11,12,11,11,11,11,12,0,0,0
0,0,0,10,10,11,12,12,12,12,11,12,14,12,11,12,11,11,11,12,11,14,12,12,11,11,11,7,0,0,0
0,0,0,11,12,11,12,10,14,11,11,14,14,11,12,14,11,14,12,11,11,11,11,12,11,11,11,11,5,0,0
0,0,0,10,11,11,11,12,12,11,14,14,11,12,11,11,12,12,12,11,12,14,14,11,11,11,11,7,0,0,0
0,0,9,12,11,12,11,14,12,12,12,14,14,11,11,11,12,14,12,12,12,12,12,11,11,11,14,12,0,0,0
0,0,12,15,12,11,11,12,12,11,14,12,14,14,12,11,11,11,21,12,12,12,11,11,12,12,15,15,11,0,0
0,16,11,12,11,14,14,11,12,12,11,11,11,12,12,12,12,12,11,11,12,12,14,12,11,11,12,12,14,18,0
0,23,12,12,14,11,11,11,14,14,11,18,14,12,12,11,11,14,11,11,12,11,11,12,11,11,11,11,12,0,0
0,0,0,12,12,11,11,11,11,11,10,11,11,12,12,11,11,11,12,12,11,11,11,11,14,11,12,12,0,0,0
0,0,6,10,31,12,11,11,12,11,11,12,12,11,12,11,12,11,11,12,11,17,11,11,11,11,11,7,0,0,0
0,0,0,15,33,11,33,12,33,12,33,12,33,12,33,11,33,11,33,11,33,0,33,11,32,11,11,11,5,0,0
0,0,0,0,0,0,0,0,0,0,0,0,0,0,0,0,0,0,0,0,0,0,0,0,0,0,11,7,0,0,0
0,0,0,0,0,0,0,0,0,0,0,0,0,0,0,0,0,0,0,0,0,0,0,0,0,0,23,11,9,0,0
0,0,0,0,0,0,0,0,0,0,0,0,0,0,0,0,0,0,0,0,0,0,0,0,0,0,0,7,0,0,0
0,0,0,0,0,0,0,0,0,0,0,0,0,0,0,0,0,0,0,0,0,0,0,0,0,0,0,11,0,0,0
0,0,0,0,0,0,0,0,0,0,0,0,0,0,0,0,0,0,0,0,0,0,0,0,0,0,0,7,0,0,0
0,0,0,0,0,0,0,0,0,0,0,0,0,0,0,0,0,0,0,0,0,0,0,0,0,0,34,11,0,0,0
0,0,0,0,0,0,0,24,0,0,0,0,0,0,0,0,0,0,0,0,0,0,0,0,0,0,12,7,0,0,0
0,0,13,11,33,11,33,12,33,11,33,11,33,11,33,11,33,12,33,11,33,0,33,12,33,11,11,25,0,0,0
0,0,0,10,31,11,31,11,31,11,31,11,31,12,31,11,31,11,31,12,31,8,31,12,31,12,11,7,0,0,0
0,0,0,11,11,12,11,11,11,11,11,11,11,11,11,12,11,12,11,11,11,12,11,11,11,12,11,11,24,0,0
0,0,11,11,11,12,11,11,12,11,11,12,12,11,11,12,12,14,11,14,11,11,12,12,12,14,11,11,11,0,0
0,16,11,11,11,12,17,12,11,12,12,11,11,11,11,11,12,11,14,12,12,11,12,14,11,11,11,11,12,18,5
0,0,15,14,12,11,11,11,11,11,12,12,11,11,14,12,11,12,11,11,11,12,12,11,11,14,12,12,11,9,0
0,0,0,11,11,11,11,11,11,11,11,11,14,11,12,11,11,11,12,12,14,11,12,11,11,14,11,12,5,23,0
0,0,0,10,11,11,11,12,11,11,12,11,11,11,12,12,11,14,11,11,11,12,11,12,11,14,12,7,0,0,0
0,0,0,11,11,11,11,12,11,11,11,11,11,11,12,12,11,14,14,12,14,11,14,11,11,12,11,11,0,0,0
0,0,6,10,11,11,11,12,16,11,12,11,11,11,11,12,12,14,11,14,11,11,17,14,11,12,11,7,0,0,0
0,0,0,11,11,12,11,11,11,11,14,11,11,11,11,11,11,11,12,14,11,11,12,12,12,12,12,12,0,0,0
0,0,0,10,12,11,11,11,11,11,11,12,12,11,11,11,11,12,14,14,12,11,11,12,11,11,12,7,0,0,0
0,0,0,12,11,11,12,11,11,12,11,12,11,12,11,12,11,14,11,12,11,11,12,14,12,12,11,11,0,0,0
0,0,0,10,12,11,11,12,10,14,12,12,12,11,11,11,11,8,12,12,12,12,14,14,11,11,12,7,6,0,0
0,0,0,11,11,11,11,12,14,12,12,11,12,11,11,11,21,14,12,12,11,11,11,11,12,12,11,15,24,0,0
0,0,12,11,11,11,11,11,11,14,11,11,12,11,12,11,11,12,11,8,11,12,14,11,11,11,11,12,11,0,0
0,16,15,15,11,12,17,8,17,11,17,14,17,11,12,11,12,11,17,12,17,11,17,11,17,14,12,12,11,18,0
0,0,15,12,11,0,0,0,0,9,0,0,0,9,11,11,11,23,0,0,0,23,0,0,0,23,11,11,11,5,0
0,0,0,25,0,0,0,0,0,0,0,0,0,0,23,25,0,0,0,0,0,0,0,0,0,0,23,25,9,0,0
0,0,0,0,0,0,0,0,0,0,0,0,0,0,0,0,0,0,0,0,0,0,0,0,0,0,0,0,0,0,0
endlayer

layer
0,0,0,0,24,0,0,0,0,0,0,0,0,0,0,0,0,0,0,0,0,0,0,0,0,0,0,0,0,0,0
0,0,9,11,0,0,0,0,0,0,0,0,0,0,0,11,0,0,0,0,0,0,0,0,0,0,6,14,24,0,0
0,0,11,11,12,0,0,9,0,0,0,0,0,0,11,12,11,0,0,0,0,0,0,0,0,0,11,11,15,0,0
13,35,11,12,11,12,0,11,6,11,34,11,0,14,11,12,11,11,9,11,0,12,0,11,0,11,11,12,12,35,0
0,0,11,12,11,12,31,11,31,14,31,12,31,12,12,11,11,12,31,11,31,11,31,11,31,21,11,11,11,0,0
0,0,9,11,12,34,11,11,11,14,11,11,11,11,12,11,11,11,12,12,11,12,11,11,12,7,11,11,0,0,0
0,0,0,0,31,11,14,11,11,34,12,11,12,12,11,0,11,11,11,12,12,11,12,11,11,11,31,0,0,0,0
0,0,0,11,11,11,12,11,25,0,12,11,17,11,14,34,12,12,12,12,11,11,12,12,11,11,11,15,0,0,0
0,0,0,0,31,11,17,11,14,12,11,12,11,11,12,5,14,12,12,11,12,14,14,11,11,11,31,36,0,0,0
0,0,0,15,11,11,0,11,11,34,12,12,0,11,12,0,12,0,0,0,34,11,12,12,11,11,12,15,0,0,0
0,0,0,0,31,12,0,11,11,34,11,11,0,11,12,17,12,14,8,11,5,14,11,11,11,11,31,0,0,0,0
0,0,0,12,11,12,11,11,12,0,12,14,0,14,11,11,11,12,12,12,0,11,12,11,11,11,12,11,0,0,0
0,0,0,0,31,11,5,0,0,0,14,0,0,12,12,11,11,11,14,12,0,0,11,12,11,7,31,0,0,0,0
0,0,9,14,11,11,12,12,11,11,34,20,34,11,11,14,11,12,11,12,12,0,12,11,12,11,11,11,0,0,0
0,0,11,11,12,11,12,12,12,20,34,0,0,12,11,11,12,12,11,11,11,12,11,11,11,12,12,15,11,0,0
0,11,11,11,11,14,23,0,0,0,0,20,37,11,11,11,12,11,11,11,11,13,12,11,11,11,11,11,11,14,0
0,23,11,11,11,11,11,12,11,11,12,12,14,12,11,11,12,12,18,11,12,13,11,12,12,12,15,15,12,0,0
0,0,0,15,11,11,11,11,11,11,11,11,11,11,11,11,11,11,11,11,33,0,33,11,11,12,11,11,0,0,0
0,0,0,6,31,11,31,11,31,14,31,12,31,12,31,11,31,11,31,11,31,0,31,11,31,11,31,0,0,0,0
0,0,0,11,33,11,33,12,32,11,33,11,33,11,33,12,33,11,32,12,33,0,33,11,33,11,0,14,5,0,0
0,0,0,0,0,0,0,0,0,0,0,0,0,0,0,0,0,0,0,0,0,0,0,0,0,0,31,0,0,0,0
0,0,0,0,0,0,0,0,0,0,0,0,0,0,0,0,0,0,0,0,0,0,0,0,0,0,23,11,0,0,0
0,0,0,0,0,0,0,0,0,0,0,0,0,0,0,0,0,0,0,0,0,0,0,0,0,0,31,5,0,0,0
0,0,0,0,0,0,0,0,0,0,0,0,0,0,0,0,0,0,0,0,0,0,0,0,0,0,34,21,0,0,0
0,0,0,0,0,0,0,0,0,0,0,0,0,0,0,0,0,0,0,0,0,0,0,0,0,0,31,24,0,0,0
0,0,0,0,0,0,0,0,0,0,0,0,0,0,0,0,0,0,0,0,0,0,0,0,0,0,0,11,0,0,0
0,0,0,0,0,0,0,24,0,0,0,0,0,0,0,0,0,0,0,0,0,0,0,0,0,0,31,0,0,0,0
0,0,0,8,33,12,33,12,33,11,33,12,33,11,33,12,33,11,33,11,33,0,33,11,33,11,13,11,0,0,0
0,0,0,0,31,11,31,11,31,11,31,11,31,12,31,12,31,12,31,12,31,5,31,12,31,12,31,24,0,0,0
0,0,0,11,11,11,11,14,10,11,12,11,11,11,12,11,11,11,11,12,33,0,33,11,12,12,11,12,0,0,0
0,0,11,11,12,11,12,11,12,11,11,12,11,11,11,11,11,12,12,12,12,11,11,11,11,12,12,11,11,0,0
0,15,11,12,15,12,11,11,12,11,11,21,11,12,12,12,11,12,0,0,11,34,23,0,23,11,12,12,11,12,5
0,0,11,11,11,11,11,12,11,11,12,12,11,12,12,11,11,25,11,11,14,11,14,11,12,14,11,11,12,0,0
0,0,23,11,11,11,11,12,12,25,11,12,11,12,12,14,12,11,11,12,11,14,12,12,12,11,11,11,9,0,0
0,0,0,38,31,11,11,11,12,12,11,11,12,18,11,12,11,11,14,11,12,5,0,0,34,12,31,0,0,0,0
0,0,0,11,11,11,12,12,12,11,11,12,11,11,12,12,11,12,11,11,12,11,12,12,11,12,11,11,5,0,0
0,0,0,9,31,11,11,11,11,14,11,11,11,12,12,11,11,14,12,12,11,18,12,12,0,11,31,34,0,0,0
0,0,0,11,12,11,12,11,11,12,12,11,11,12,11,11,11,12,17,14,11,14,12,11,34,11,11,12,0,0,0
0,0,0,0,31,11,11,11,11,11,11,11,11,14,11,12,11,11,24,14,11,11,11,12,12,11,31,0,0,0,0
0,0,0,11,12,11,11,11,11,14,11,12,11,11,12,14,11,12,12,12,11,14,12,11,13,11,11,11,0,0,0
0,0,0,0,31,12,11,11,12,11,12,11,11,11,11,7,12,12,24,24,0,0,12,11,34,12,31,6,0,0,0
0,0,0,11,12,0,12,11,11,12,14,11,11,17,11,12,11,11,11,12,12,12,11,12,11,12,11,12,24,0,0
0,0,11,11,11,11,31,12,31,11,31,11,31,11,14,12,11,11,31,12,31,12,31,12,31,12,11,11,11,0,0
0,35,14,12,11,11,0,12,9,11,0,15,13,11,14,11,11,11,0,11,5,12,0,11,0,12,15,11,12,7,0
0,0,11,11,11,0,0,0,0,6,0,0,0,6,11,12,12,23,0,0,0,0,6,5,0,23,12,11,12,0,0
0,0,0,11,0,0,0,0,0,0,0,0,0,0,0,14,0,0,0,0,0,0,0,0,0,0,0,11,9,0,0
0,0,0,0,0,0,0,0,0,0,0,0,0,0,0,0,0,0,0,0,0,0,0,0,0,0,0,0,0,0,0
endlayer

layer
0,0,0,0,24,0,0,0,0,0,0,0,0,0,0,0,0,0,0,0,0,0,0,0,0,0,0,0,0,0,0
0,0,6,15,0,0,0,0,0,0,0,0,0,0,0,12,0,0,0,0,0,0,0,0,0,0,6,12,24,0,0
0,0,10,12,12,0,0,24,0,0,0,0,0,0,18,14,15,0,0,24,0,0,0,0,0,0,11,12,11,0,0
0,35,12,11,8,11,0,15,6,12,0,11,24,11,15,11,15,10,13,12,0,11,0,16,0,11,12,11,12,35,0
0,0,3,12,11,11,31,11,31,12,31,11,31,11,11,11,11,12,31,11,31,12,31,11,31,11,11,11,15,0,0
0,0,6,12,11,11,11,14,14,14,11,11,14,12,12,14,12,11,11,11,12,11,11,14,11,11,11,7,0,0,0
0,0,0,0,31,11,11,11,11,0,14,11,12,12,12,0,12,11,11,11,11,11,12,11,11,12,31,0,0,0,0
0,0,0,11,10,11,11,11,11,0,12,12,11,11,12,0,11,11,11,17,11,12,11,12,11,12,11,11,0,0,0
0,0,0,0,31,12,11,11,14,5,18,11,12,12,11,0,11,14,12,11,10,12,11,12,11,11,31,36,0,0,0
0,0,0,12,11,12,0,34,24,0,0,0,0,34,23,0,0,0,0,0,0,11,14,12,12,11,12,11,0,0,0
0,0,0,0,31,11,0,12,12,0,12,12,0,12,11,14,16,17,0,14,5,12,11,14,12,11,31,0,0,0,0
0,0,0,11,12,12,0,12,21,0,12,11,34,12,11,11,12,14,34,12,34,12,11,12,12,12,11,11,0,0,0
0,0,0,0,31,14,5,0,0,0,11,34,0,12,12,11,11,12,0,10,0,0,14,12,11,11,31,0,0,0,0
0,0,0,15,12,14,5,11,12,12,0,0,0,11,12,11,11,12,14,12,12,0,11,12,11,11,11,12,0,0,0
0,6,11,15,11,11,0,11,11,0,0,0,0,11,12,11,11,11,11,14,14,0,25,11,12,11,15,11,12,0,0
0,15,12,11,11,11,0,34,34,0,0,0,34,12,12,11,12,11,11,11,14,0,12,12,11,11,11,11,15,14,0
0,0,12,12,12,11,11,11,14,12,14,12,14,12,12,12,12,12,11,11,14,13,11,11,11,12,12,11,12,0,0
0,0,9,11,11,11,12,11,12,12,11,11,12,12,12,11,11,11,11,12,33,0,33,11,12,12,11,11,0,0,0
0,0,0,0,31,12,31,12,31,11,31,11,31,11,31,11,31,12,31,12,31,0,31,12,31,11,31,0,0,0,0
0,0,0,11,33,11,33,12,33,11,33,11,33,11,33,11,33,11,32,11,33,0,33,11,33,11,0,12,0,0,0
0,0,0,0,0,0,0,0,0,0,0,0,0,0,0,0,0,23,0,0,0,0,0,0,0,0,31,0,0,0,0
0,0,0,0,0,0,0,0,0,0,0,0,0,0,0,0,0,0,0,0,0,0,0,0,0,0,23,12,0,0,0
0,0,0,0,0,0,0,0,0,0,0,0,0,0,0,0,0,0,0,0,0,0,0,0,0,0,31,36,0,0,0
0,0,0,0,0,0,0,0,0,0,0,0,0,0,0,0,0,0,0,0,0,0,0,0,0,0,0,11,0,0,0
0,0,0,0,0,0,0,0,0,0,0,0,0,0,0,0,0,0,0,0,0,0,0,0,0,0,31,24,0,0,0
0,0,0,0,0,0,0,0,0,0,0,0,0,0,0,0,0,0,0,0,0,0,0,0,0,0,0,12,0,0,0
0,0,0,0,0,0,0,0,0,0,0,0,0,0,0,0,0,0,0,0,0,0,0,0,0,0,31,0,0,0,0
0,0,0,11,33,11,33,12,33,14,33,12,33,12,33,14,33,12,33,11,33,0,33,12,33,11,0,11,0,0,0
0,0,0,0,31,12,31,11,31,11,31,12,31,11,31,14,31,12,31,11,31,5,31,11,31,14,31,24,0,0,0
0,0,0,12,11,11,11,12,11,11,11,14,12,12,11,12,12,11,11,11,33,0,33,11,11,11,11,11,0,0,0
0,0,11,11,11,12,14,12,12,11,11,11,11,11,11,11,11,11,12,11,12,13,14,14,12,12,12,18,12,0,0
0,12,11,11,11,12,12,12,11,11,11,12,11,12,11,12,12,12,5,0,0,0,0,0,0,12,11,15,11,11,0
0,0,11,11,17,11,11,11,12,11,11,12,11,11,12,11,11,11,12,11,14,0,14,12,14,11,11,11,11,0,0
0,0,0,11,11,11,12,11,11,11,12,11,11,11,11,11,11,12,14,11,11,0,11,12,11,11,11,12,9,0,0
0,0,0,0,31,12,11,12,8,11,11,12,12,11,12,17,11,12,11,11,12,0,0,23,0,12,31,0,0,0,0
0,0,9,21,31,11,11,14,11,11,11,12,11,11,11,14,10,14,12,11,11,14,12,12,0,14,14,15,5,0,0
0,0,0,0,31,11,11,11,12,11,14,11,12,11,21,11,11,12,17,11,11,11,11,12,0,11,31,0,0,0,0
0,0,0,12,11,11,11,11,11,11,11,11,11,10,12,11,11,12,0,12,12,11,12,14,0,12,11,11,0,0,0
0,0,0,0,31,12,11,12,11,11,14,12,11,11,11,11,11,12,36,12,11,11,11,11,0,12,31,34,0,0,0
0,0,0,11,12,11,11,12,11,12,12,11,11,11,12,12,12,12,13,12,11,14,11,12,13,14,12,11,0,0,0
0,0,0,0,31,16,11,11,11,11,12,11,11,11,25,11,11,12,0,0,0,0,0,0,0,12,31,34,0,0,0
0,0,0,12,12,11,12,11,11,12,11,11,12,11,11,11,11,14,11,11,12,12,12,11,11,12,11,11,24,0,0
0,13,11,11,11,11,31,11,31,12,31,11,31,11,11,11,12,11,31,11,31,11,31,11,31,11,11,11,12,0,0
0,35,11,14,12,12,34,12,9,12,0,12,0,12,11,11,14,12,0,17,0,15,0,12,23,11,11,15,11,35,0
0,27,11,11,11,0,0,0,0,0,0,0,0,0,14,10,11,0,0,0,0,0,6,0,0,23,11,12,11,0,0
0,0,0,15,0,0,0,0,0,0,0,0,0,0,0,12,0,0,0,0,0,0,0,0,0,0,0,17,23,0,0
0,0,0,0,0,0,0,0,0,0,0,0,0,0,0,0,0,0,0,0,0,0,0,0,0,0,0,0,0,0,0
endlayer

layer
0,0,0,0,24,0,0,0,0,0,0,0,0,0,0,0,0,0,0,0,0,0,0,0,0,0,0,0,0,0,0
0,0,0,8,6,0,0,0,0,0,0,0,0,0,0,8,0,0,0,0,0,0,0,0,0,0,0,8,24,0,0
0,9,11,11,12,0,0,0,0,0,0,0,0,0,11,11,12,0,0,0,0,0,0,0,0,9,12,12,12,0,0
0,10,12,15,11,12,0,11,5,12,0,11,24,12,11,11,11,12,13,11,0,11,0,11,0,11,15,11,11,7,0
0,9,15,11,11,12,31,12,31,14,31,11,31,11,12,12,12,11,31,11,31,12,31,11,31,11,12,12,11,0,0
0,0,0,11,12,11,11,11,14,12,11,11,11,11,12,12,11,12,12,11,12,12,18,11,11,11,11,12,0,0,0
0,0,0,0,31,11,14,12,12,12,11,11,11,12,12,14,21,11,12,11,12,12,12,11,11,11,31,5,0,0,0
0,0,0,11,11,14,12,11,14,12,14,11,7,11,12,12,11,11,11,12,11,11,11,12,11,11,11,15,0,0,0
0,0,0,0,31,11,11,11,12,12,14,11,12,12,11,11,11,12,12,11,12,12,14,11,12,12,31,24,0,0,0
0,0,0,11,11,12,11,12,11,14,12,12,12,11,11,12,11,11,34,12,12,11,14,14,12,11,12,11,0,0,0
0,0,0,0,31,12,14,14,12,14,14,11,11,11,14,12,11,12,0,14,12,14,11,11,11,11,31,34,0,0,0
0,0,0,16,11,11,12,25,11,14,12,14,12,12,12,11,12,11,0,12,12,12,11,11,11,11,11,3,0,0,0
0,0,0,0,31,12,14,12,14,11,11,11,11,12,12,11,12,14,0,39,10,12,12,11,12,11,31,0,0,0,0
0,0,0,12,11,12,12,11,11,12,12,0,0,11,11,11,12,14,14,12,14,12,11,11,16,14,11,11,0,0,0
0,6,14,11,15,12,11,12,12,11,0,0,0,12,11,14,11,11,11,7,12,14,14,14,14,11,11,11,12,0,0
0,10,11,11,11,11,12,11,11,12,0,0,14,14,17,11,11,12,11,11,11,14,11,12,11,11,11,11,11,7,0
0,0,11,11,12,12,11,12,11,11,12,11,12,12,11,11,11,14,12,11,11,12,11,12,12,11,11,11,11,0,0
0,0,9,7,12,12,11,11,11,11,12,14,11,12,11,11,11,12,11,11,11,12,14,11,11,11,12,11,0,0,0
0,0,0,0,31,10,31,12,31,12,31,11,31,11,31,11,31,12,31,12,31,11,31,12,31,11,31,34,0,0,0
0,0,0,11,25,11,25,11,25,11,25,11,25,11,25,12,25,12,25,11,25,12,25,11,25,11,0,11,0,0,0
0,0,0,25,0,25,0,25,0,25,0,25,0,25,0,25,0,25,0,25,0,25,0,25,0,25,31,34,0,0,0
0,0,0,0,0,0,0,0,0,0,0,0,0,0,0,0,0,0,0,0,0,0,0,0,0,0,0,11,0,0,0
0,6,0,0,0,0,0,0,0,0,0,0,0,0,0,0,0,0,0,0,0,0,0,0,0,0,31,24,0,0,0
0,0,0,0,0,0,0,0,0,0,0,0,0,0,0,0,0,0,0,0,0,0,0,0,0,0,0,11,5,0,0
0,0,0,0,0,0,0,0,0,0,0,0,0,0,0,0,0,0,0,0,0,0,0,0,0,0,31,0,0,0,0
0,0,0,0,0,0,0,0,0,0,0,0,0,0,0,0,0,0,0,0,0,0,0,0,0,0,0,11,0,0,0
0,0,0,21,0,21,0,21,0,21,0,21,0,21,0,21,0,21,0,21,0,21,0,21,0,21,31,0,0,0,0
0,0,0,15,21,11,21,11,21,12,21,12,21,12,21,12,21,12,21,11,21,11,21,11,21,12,0,11,0,0,0
0,0,0,0,31,11,31,11,31,11,31,14,31,11,31,12,31,12,31,11,31,11,31,12,31,11,31,24,0,0,0
0,0,0,12,12,12,12,11,12,12,11,21,11,12,12,12,12,11,18,12,11,11,12,11,11,14,12,12,0,0,0
0,0,10,11,11,11,12,11,11,11,11,11,11,11,11,11,11,14,12,11,12,11,11,14,12,14,15,11,11,0,0
0,10,11,11,12,12,11,11,12,14,14,12,11,12,11,12,11,12,12,12,12,11,11,11,14,14,30,11,11,7,0
0,0,12,11,12,12,17,11,14,11,12,10,11,11,11,11,11,12,14,12,12,11,12,12,12,12,11,11,11,0,0
0,0,0,11,11,11,11,11,11,11,12,14,12,12,11,12,11,12,14,12,12,12,14,12,8,14,11,11,0,0,0
0,0,0,0,31,11,11,11,11,11,11,11,11,11,11,11,11,12,11,11,11,12,12,14,12,12,31,6,0,0,0
0,0,6,11,11,11,11,11,14,11,12,11,11,12,12,11,11,14,17,11,11,11,12,11,14,12,11,11,5,0,0
0,0,0,34,31,11,12,12,12,11,11,11,11,12,11,14,11,11,0,11,14,12,11,18,12,11,31,0,0,0,0
0,0,0,14,12,11,11,11,11,11,12,11,14,12,11,11,11,12,0,11,11,12,11,14,17,12,11,11,0,0,0
0,0,0,34,31,12,12,11,11,11,11,11,11,11,11,12,11,12,0,12,11,11,11,11,12,14,31,0,0,0,0
0,0,0,15,12,11,12,11,12,11,12,11,11,11,11,11,11,12,21,11,12,11,12,12,12,11,11,15,0,0,0
0,0,0,0,31,12,11,11,11,11,11,11,11,11,14,12,12,11,11,11,14,11,12,25,14,14,31,34,0,0,0
0,0,0,11,11,11,12,11,11,11,12,11,12,12,12,12,12,11,12,11,12,12,12,12,12,11,12,11,0,0,0
0,0,11,11,14,12,31,11,31,11,31,11,31,12,12,12,18,12,31,12,31,11,31,11,31,12,11,12,11,0,0
0,10,11,12,11,12,0,12,0,12,0,11,0,11,11,11,11,11,13,12,0,11,0,11,0,12,11,11,3,7,0
0,0,11,11,12,0,0,6,0,0,0,0,0,0,11,15,11,0,0,0,0,0,13,9,0,0,12,11,11,0,0
0,0,0,17,0,0,0,0,0,0,0,0,0,0,0,17,0,0,0,0,0,0,0,0,0,0,0,17,23,0,0
0,0,0,0,0,0,0,0,0,0,0,0,0,0,0,0,0,0,0,0,0,0,0,0,0,0,0,0,0,0,0
endlayer

layer
0,0,0,0,0,0,0,0,0,0,0,0,0,0,0,0,0,0,0,0,0,0,0,0,0,0,0,0,0,0,0
0,0,0,0,0,0,0,0,0,0,0,0,0,0,24,0,0,0,0,0,0,0,0,0,0,0,0,0,0,0,0
0,6,11,15,15,6,0,0,0,33,0,0,0,0,11,12,11,0,0,0,0,33,0,0,0,6,15,12,11,0,0
0,9,12,12,15,14,21,11,21,12,21,11,21,11,11,11,12,11,21,11,21,15,21,12,21,11,11,11,11,0,0
0,0,14,11,11,12,12,11,11,11,11,11,12,12,12,14,11,11,11,11,12,12,11,11,12,11,11,12,15,0,0
0,0,0,11,16,11,11,12,12,12,14,11,11,12,12,11,11,11,12,12,12,11,11,14,11,12,11,11,0,0,0
0,0,0,16,11,11,12,12,11,12,11,11,11,11,11,12,11,11,12,12,11,11,12,11,16,14,11,18,0,0,0
0,0,0,12,11,11,11,12,11,11,12,11,12,12,12,11,12,12,11,12,14,8,14,12,14,14,11,11,0,0,0
0,0,0,16,11,18,11,11,11,12,12,11,11,11,11,12,11,14,14,12,14,14,11,14,11,12,11,18,0,0,0
0,0,33,15,11,12,11,14,11,11,11,12,11,11,11,11,7,11,14,14,18,14,12,11,12,14,12,11,33,0,0
0,0,0,16,11,12,11,11,12,11,11,11,11,11,11,11,11,12,14,14,14,11,12,12,12,14,12,18,0,0,0
0,0,0,12,11,11,12,12,11,12,12,11,11,25,12,11,14,11,14,12,12,17,11,14,11,11,11,12,0,0,0
0,0,0,16,11,12,11,11,12,11,12,11,11,12,11,14,12,12,0,0,0,0,12,11,12,12,12,18,0,0,0
0,0,6,11,11,11,11,11,11,11,14,12,12,11,21,8,11,14,11,11,11,12,11,12,12,12,11,11,0,0,0
0,0,12,15,15,12,12,11,12,11,11,11,11,11,14,14,12,11,12,11,11,12,11,11,11,11,12,11,11,0,0
0,0,11,11,11,14,12,12,17,12,11,11,12,12,11,14,11,11,11,12,12,12,11,12,12,11,11,12,12,0,0
0,0,15,11,15,11,11,11,11,11,25,11,11,11,12,11,11,11,14,11,12,12,14,11,12,11,11,11,12,0,0
0,0,0,12,12,11,12,11,12,11,12,11,11,11,12,11,11,12,12,11,12,12,12,12,14,11,12,11,0,0,0
0,0,0,16,11,12,11,12,12,11,11,12,11,12,11,11,11,11,12,12,11,11,11,11,12,12,11,18,0,0,0
0,0,0,11,11,11,11,11,12,11,12,11,12,11,11,12,11,11,11,11,11,12,11,11,11,12,11,11,0,0,0
0,0,0,14,25,15,25,15,25,15,25,15,25,15,25,15,25,15,25,15,25,15,25,22,25,15,11,18,0,0,0
0,0,0,25,0,25,0,25,0,25,0,25,0,25,0,25,0,25,0,25,0,25,0,25,0,25,11,12,0,0,0
0,9,0,0,0,0,0,0,0,0,0,0,0,0,0,0,0,0,0,0,0,0,0,0,0,0,11,18,0,0,0
0,0,0,0,0,0,0,0,0,0,0,0,0,0,0,0,0,0,0,0,0,0,0,0,0,0,11,11,0,0,0
0,0,0,0,0,0,0,0,0,0,0,0,0,0,0,0,0,0,0,0,0,0,0,0,0,0,11,18,0,0,0
0,0,0,21,0,21,0,21,0,21,0,21,0,21,0,21,0,21,0,21,0,21,0,21,0,21,12,25,0,0,0
0,0,0,11,21,11,21,11,21,11,21,11,21,12,21,12,21,11,21,11,21,11,21,11,21,11,12,17,0,0,0
0,0,0,12,11,11,14,11,11,14,12,12,12,12,12,11,12,11,14,12,11,11,11,11,11,11,11,11,0,0,0
0,0,0,16,25,11,11,11,11,11,11,12,12,11,12,11,11,11,11,7,11,12,11,14,11,11,11,18,0,0,0
0,0,0,12,11,11,11,14,12,11,11,14,12,11,11,11,11,11,11,11,12,12,11,12,7,11,11,11,0,0,0
0,0,11,12,15,12,12,11,12,11,12,12,11,11,14,12,12,8,11,12,12,12,12,11,12,14,12,11,11,0,0
0,0,11,11,11,11,11,12,12,12,11,11,12,11,12,12,12,12,12,11,11,11,11,11,8,11,11,11,11,0,0
0,0,12,12,15,11,11,12,11,12,11,11,12,11,11,12,12,11,14,11,11,12,14,12,12,11,12,11,11,0,0
0,0,0,11,11,11,11,11,11,11,14,11,11,11,12,11,10,11,12,12,12,14,12,11,14,12,11,11,0,0,0
0,0,0,16,11,12,11,11,11,12,11,11,12,14,12,12,12,11,17,14,11,11,14,12,14,14,12,18,0,0,0
0,0,0,12,11,12,11,11,11,11,11,14,12,11,11,12,14,14,0,14,12,16,11,12,11,11,11,11,9,0,0
0,0,0,16,11,11,11,11,11,11,11,11,11,11,11,12,11,12,0,14,11,11,11,14,12,12,11,18,0,0,0
0,0,33,11,12,12,12,11,14,12,11,12,11,12,11,14,11,12,0,11,12,14,12,12,12,12,11,11,33,0,0
0,0,0,16,11,11,11,11,11,11,11,14,11,12,11,12,14,14,11,11,14,14,12,14,12,11,14,18,0,0,0
0,0,0,11,11,12,11,11,11,11,12,14,11,11,12,11,12,11,12,11,12,11,12,12,11,11,14,12,0,0,0
0,0,0,16,11,11,12,12,11,11,11,11,12,11,11,12,14,12,11,11,12,11,11,11,12,11,12,18,0,0,0
0,0,0,12,11,11,11,12,11,11,11,16,11,11,11,11,14,11,11,12,11,11,11,12,11,11,11,11,0,0,0
0,0,11,14,12,7,12,11,11,12,12,11,11,11,11,11,11,12,11,11,12,11,12,12,11,11,11,12,11,0,0
0,0,11,14,11,12,25,11,25,11,25,11,25,3,12,11,15,8,25,15,25,11,25,11,25,11,15,10,11,0,0
0,0,11,25,11,0,0,9,0,33,0,0,0,23,11,25,11,5,0,0,0,33,0,6,0,0,11,12,15,0,0
0,0,0,0,0,0,0,0,0,0,0,0,0,0,0,0,0,0,0,0,0,0,0,0,0,0,0,0,0,0,0
0,0,0,0,0,0,0,0,0,0,0,0,0,0,0,0,0,0,0,0,0,0,0,0,0,0,0,0,0,0,0
endlayer

layer
0,0,0,0,0,0,0,0,0,0,0,0,0,0,0,0,0,0,0,0,0,0,0,0,0,0,0,0,0,0,0
0,0,0,0,0,0,0,0,0,0,0,0,0,0,0,0,0,0,0,0,0,0,0,0,0,0,0,0,0,0,0
0,0,12,11,11,6,0,40,26,19,41,40,0,0,11,11,12,0,0,40,26,19,41,40,9,0,11,15,11,0,0
0,9,11,3,12,11,11,12,12,11,11,12,11,12,11,11,11,11,11,11,11,11,11,11,11,11,11,11,11,0,0
0,0,12,12,11,12,11,12,11,11,14,11,11,11,11,11,12,11,12,11,11,12,12,11,11,11,11,11,12,0,0
0,0,0,12,11,11,11,17,17,17,17,17,17,11,11,11,11,11,11,12,12,12,12,14,12,11,11,12,0,0,0
0,0,0,11,11,14,7,0,0,0,0,0,0,10,12,11,8,7,0,12,12,24,23,0,23,12,11,15,0,0,0
0,0,40,11,11,12,11,0,0,0,0,0,0,10,11,11,11,11,5,12,12,11,11,12,12,12,11,12,40,0,0
0,0,42,11,11,12,12,0,0,0,0,0,0,10,11,11,11,11,34,12,11,14,11,12,0,11,12,11,42,0,0
0,0,22,11,11,14,12,0,0,0,10,8,8,11,11,12,12,11,0,23,0,0,12,12,5,11,11,11,28,0,0
0,0,43,12,14,11,12,0,0,0,10,17,17,11,11,11,11,11,5,0,0,0,12,11,21,11,12,11,43,0,0
0,0,40,11,11,12,11,0,0,0,0,0,0,17,11,12,11,12,12,11,14,13,14,11,11,11,12,12,40,0,0
0,9,0,11,11,12,11,0,0,0,0,0,0,0,24,13,12,11,0,0,0,0,14,14,0,11,11,11,0,0,0
0,0,0,12,7,11,11,0,0,0,0,0,0,8,12,12,11,12,14,11,12,14,12,14,0,12,11,11,0,0,0
0,0,12,11,11,11,7,0,0,0,0,0,0,11,11,11,11,11,14,11,12,11,12,11,12,12,11,11,11,0,0
0,0,11,12,11,11,11,8,11,12,11,11,8,16,11,0,23,11,34,0,12,23,0,34,0,12,11,11,12,0,0
0,0,11,17,11,11,11,11,12,12,11,11,11,11,11,12,12,12,11,11,14,11,11,12,11,11,12,11,11,0,0
0,0,0,12,11,11,11,11,12,11,11,11,11,14,11,11,11,11,11,12,11,11,11,34,0,0,14,11,0,0,0
0,0,0,11,11,11,11,14,14,11,14,12,11,12,11,11,18,11,11,11,14,11,11,0,0,0,11,8,0,0,0
0,0,0,11,11,11,14,11,11,11,14,12,11,12,11,11,12,11,11,12,12,11,11,8,8,8,11,12,0,0,0
0,0,0,11,12,11,11,12,12,11,17,12,14,11,11,11,11,11,11,11,11,11,11,12,11,11,11,12,0,0,0
0,0,0,11,25,15,25,15,25,15,25,15,25,15,25,15,25,15,25,15,25,15,25,15,11,15,11,12,0,0,0
0,0,0,25,0,25,0,25,0,25,0,25,0,25,0,25,0,25,0,25,0,25,12,25,14,25,12,21,0,0,0
0,9,0,0,0,0,0,0,0,0,0,0,0,0,0,0,0,0,0,0,0,0,11,11,11,11,12,11,0,0,0
0,0,0,21,0,21,0,21,0,21,0,21,0,21,0,21,0,21,0,21,0,21,11,21,12,21,12,11,0,0,0
0,0,0,12,21,28,21,15,21,15,21,15,21,15,21,15,21,15,21,15,21,15,21,15,21,3,12,11,0,0,0
0,0,0,16,11,12,11,11,12,11,11,11,12,12,11,11,11,11,12,11,12,12,11,11,12,12,11,11,0,0,0
0,0,0,12,12,11,11,11,11,11,11,11,11,11,11,11,11,12,11,11,11,11,11,17,17,17,11,11,0,0,0
0,0,0,15,11,12,11,11,12,14,11,11,11,11,14,11,11,12,11,11,11,12,11,0,0,0,11,11,0,0,0
0,0,0,11,11,11,11,11,11,12,11,11,11,11,11,18,12,11,11,11,11,11,11,0,0,24,12,11,0,0,0
0,0,14,11,12,11,11,11,12,11,12,12,12,11,11,12,12,11,12,11,11,12,11,11,0,14,8,11,12,0,0
0,0,11,11,12,12,11,17,11,11,12,11,17,11,11,0,12,14,23,12,23,0,11,11,0,12,11,15,11,0,0
0,0,12,12,12,11,7,0,0,0,0,0,0,14,11,34,12,7,5,12,12,10,11,12,12,14,11,11,11,0,0
0,0,0,11,11,11,11,0,0,0,0,0,0,17,11,12,11,12,0,12,14,0,12,14,0,11,11,15,0,0,0
0,0,0,15,12,11,11,0,0,0,0,0,0,0,23,0,12,14,0,14,11,0,0,0,0,11,11,12,9,0,0
0,0,40,11,12,11,14,0,0,0,0,0,0,8,12,11,11,14,13,12,11,0,0,0,0,12,11,11,40,0,0
0,0,42,15,11,12,11,0,0,0,10,8,8,11,16,34,11,11,0,12,11,0,21,21,0,10,12,10,42,0,0
0,0,22,15,12,12,11,0,0,0,10,17,17,11,12,34,11,12,11,11,11,21,16,18,21,11,18,12,28,0,0
0,0,43,11,11,11,11,0,0,0,0,0,0,10,14,11,12,12,12,12,12,17,11,12,7,12,12,14,43,0,0
0,0,40,11,11,11,11,0,0,0,0,0,0,10,12,0,14,11,11,12,11,12,11,11,12,11,14,15,40,0,0
0,0,0,11,12,11,7,0,0,0,0,0,0,10,11,0,11,12,11,12,11,12,12,11,11,11,21,11,0,0,0
0,0,0,11,11,12,12,8,8,8,8,8,8,11,11,11,12,11,11,12,11,11,12,12,12,11,11,11,0,0,0
0,0,11,15,11,11,12,11,12,12,11,11,11,11,14,11,11,11,12,11,12,11,11,11,11,11,11,11,11,0,0
0,0,12,11,11,11,11,11,11,11,11,12,14,11,12,15,11,11,12,11,12,11,12,12,12,11,11,12,11,0,0
0,0,16,15,14,0,0,40,26,30,41,40,0,0,25,12,12,0,0,40,26,30,41,40,0,0,11,11,11,0,0
0,0,0,0,0,0,0,0,6,0,0,0,0,0,0,0,0,0,0,0,0,0,0,6,0,0,0,0,0,0,0
0,0,0,0,0,0,0,0,0,0,0,0,0,0,0,0,0,0,0,0,0,0,0,0,0,0,0,0,0,0,0
endlayer

layer
0,0,0,0,0,0,0,0,0,0,0,0,0,0,0,0,0,0,0,0,0,0,0,0,0,0,0,0,0,0,0
0,19,19,19,19,19,0,0,0,0,0,0,0,22,19,19,19,28,0,0,0,0,0,9,0,19,19,19,19,19,0
0,22,15,11,11,28,19,19,19,19,19,19,19,19,11,15,12,19,19,19,19,19,19,19,19,22,11,12,14,28,0
0,22,11,11,11,14,11,12,12,11,12,12,15,11,11,12,11,14,11,12,12,12,14,15,12,12,12,11,11,28,0
0,22,12,11,11,12,11,14,11,11,11,11,12,11,11,11,11,11,11,14,12,11,11,11,11,11,11,11,11,28,0
0,22,30,11,11,11,12,25,25,25,25,25,25,11,11,11,12,8,12,11,12,12,11,12,12,14,10,11,30,28,0
0,0,22,12,11,31,0,0,0,0,0,0,0,16,11,12,12,12,5,23,0,38,38,0,23,11,11,11,28,0,0
0,0,22,12,12,31,17,0,0,0,0,0,0,16,11,11,11,11,0,12,11,14,12,12,0,14,12,11,28,0,0
0,0,22,11,11,31,0,0,0,0,0,0,0,16,11,11,11,12,0,14,12,12,14,12,0,11,11,12,28,0,0
0,0,22,12,12,31,0,0,0,0,21,0,0,12,11,12,14,14,0,0,0,0,11,11,0,12,11,11,28,0,0
0,0,22,14,12,31,7,0,0,0,16,8,8,12,12,11,11,14,0,0,0,0,12,12,0,11,11,12,28,0,0
0,24,22,11,12,31,0,0,0,0,0,0,0,25,11,14,12,11,14,12,12,0,14,12,0,12,14,11,28,0,0
0,9,22,12,12,31,34,0,0,0,0,0,0,0,0,13,11,14,0,0,0,0,11,12,0,12,11,15,28,0,0
0,19,22,11,11,31,8,0,0,0,0,0,0,21,11,0,14,14,12,14,14,12,12,12,0,14,11,11,28,19,0
0,22,11,11,12,31,36,0,0,0,0,0,0,31,11,34,11,14,11,12,11,14,11,21,0,11,11,12,11,28,0
0,22,12,15,12,12,11,0,7,0,0,10,0,31,14,0,23,0,0,0,0,0,0,0,0,11,25,11,12,28,0
0,22,12,11,12,12,11,31,31,31,31,31,31,12,11,12,25,12,12,12,11,12,11,14,13,12,11,11,11,28,0
0,30,30,11,11,11,11,12,12,14,11,11,12,11,11,11,11,11,14,11,11,12,11,23,0,0,12,14,30,30,0
0,0,22,11,11,11,12,11,11,12,12,11,12,11,12,11,11,12,11,11,10,11,11,0,0,0,11,12,28,0,0
0,0,22,11,12,11,11,11,12,12,11,12,12,11,11,11,11,12,11,12,12,12,11,0,0,0,11,11,28,0,0
0,0,22,11,11,11,11,12,11,11,12,11,11,12,11,12,11,12,11,11,11,11,11,0,0,0,12,12,28,0,0
0,0,22,25,11,11,11,11,12,11,11,11,11,12,11,11,11,7,11,11,11,14,0,0,0,0,0,11,28,0,0
0,0,22,15,25,11,25,11,25,12,25,12,25,11,25,11,25,14,25,11,25,11,5,0,0,0,13,11,28,0,0
0,6,22,11,44,12,44,11,44,12,44,11,44,12,44,11,44,11,11,11,44,14,12,0,0,0,11,15,28,0,0
0,0,22,11,21,12,21,12,21,12,21,14,21,12,21,11,21,11,21,11,21,11,34,0,0,0,0,12,28,0,0
0,0,22,11,15,11,15,12,15,12,15,11,3,11,3,11,15,12,15,11,15,11,5,0,0,0,0,12,28,0,0
0,0,22,12,11,14,11,11,11,11,11,11,11,11,11,11,12,11,11,11,11,11,11,0,0,0,12,12,28,0,0
0,0,22,11,12,21,12,11,17,11,11,11,11,12,11,11,11,11,11,11,11,12,11,0,0,0,11,11,28,0,0
0,0,22,12,11,12,12,11,11,11,11,11,12,11,11,12,11,11,11,11,12,14,11,0,0,0,12,15,28,0,0
0,19,19,11,12,11,11,11,11,11,11,12,11,12,12,11,12,16,11,11,12,11,11,0,0,0,12,11,19,19,0
0,22,11,11,11,11,12,31,31,31,31,31,31,7,12,12,12,11,12,16,11,12,11,21,0,7,26,12,11,28,0
0,22,11,11,11,11,12,0,7,0,34,10,0,31,14,0,0,0,0,0,0,0,14,11,34,12,15,11,11,28,0
0,22,12,11,12,31,0,0,0,0,0,0,0,31,11,0,12,14,5,12,11,0,14,16,0,11,11,11,12,28,0
0,30,22,11,11,31,17,0,0,0,0,0,0,25,11,34,12,11,0,12,12,34,11,11,0,12,11,12,28,30,0
0,0,22,12,12,31,0,0,0,0,0,0,0,0,0,0,14,14,0,11,14,0,0,0,0,14,11,11,28,0,0
0,0,22,12,11,31,34,0,0,0,0,0,0,21,11,0,12,11,13,12,14,23,0,0,0,12,11,12,28,0,0
0,0,22,11,12,31,7,5,0,0,16,17,17,11,11,0,11,12,12,14,12,0,0,0,0,11,12,12,28,0,0
0,0,22,12,14,31,0,5,0,0,25,0,0,11,11,0,14,11,11,12,12,0,37,37,0,14,11,12,28,0,0
0,0,22,11,11,31,0,0,0,0,0,0,0,16,12,0,11,14,11,11,12,14,11,11,12,12,12,11,28,0,0
0,0,22,11,11,31,8,0,0,0,0,0,0,16,12,34,14,11,14,12,14,11,11,11,11,12,12,11,28,0,0
0,0,22,11,11,31,34,0,0,0,0,24,0,16,14,34,12,12,7,14,12,11,11,12,12,11,11,11,28,0,0
0,22,19,11,11,12,11,21,21,21,21,21,21,12,12,12,12,11,11,11,11,11,11,11,12,12,11,12,19,28,0
0,22,11,11,11,11,11,11,12,11,12,11,14,11,11,12,11,11,11,11,11,11,11,11,11,11,11,12,11,28,0
0,22,11,15,11,11,11,11,11,25,12,12,14,15,15,12,11,11,15,12,11,11,11,15,12,11,11,11,11,28,0
0,22,11,11,12,28,30,30,30,30,30,30,30,30,11,11,11,30,30,30,30,30,30,30,30,22,11,11,11,28,0
0,30,30,30,30,30,0,6,6,0,0,0,0,22,30,30,30,28,0,0,0,0,6,0,0,30,30,30,30,30,0
0,0,0,0,0,0,0,0,0,0,0,0,0,0,0,0,0,0,0,0,0,0,0,0,0,0,0,0,0,0,0
endlayer

layer
0,0,6,0,0,0,0,0,0,0,0,0,0,0,0,0,0,0,0,0,0,0,0,0,0,0,0,0,0,0,0
0,45,45,45,45,45,0,0,0,0,0,0,0,45,45,45,45,45,0,0,0,0,0,6,0,45,45,45,45,45,0
0,45,31,31,31,45,45,45,45,45,45,45,45,45,31,31,31,45,45,45,45,45,45,45,45,45,31,31,31,45,0
0,45,31,11,15,31,31,31,31,31,31,31,31,31,11,12,11,31,31,31,31,31,31,31,31,31,12,11,31,45,0
0,45,31,11,11,12,14,11,12,12,11,11,11,11,12,11,11,25,11,11,11,11,11,11,12,11,12,11,31,45,0
0,45,45,31,12,11,11,11,11,14,12,11,11,11,11,11,11,11,12,11,12,11,11,12,12,14,12,31,45,45,0
0,0,45,31,12,12,11,0,0,0,0,0,0,12,12,11,12,12,12,12,11,11,11,14,14,12,12,31,45,0,0
0,0,45,31,11,11,11,0,0,0,0,0,0,11,12,11,11,12,12,11,14,11,12,11,12,11,11,31,45,0,0
0,0,45,31,14,12,12,0,0,0,0,0,23,11,11,11,11,12,11,12,14,14,11,11,12,14,7,31,45,0,0
0,0,45,31,11,11,11,0,0,0,11,0,0,12,11,11,10,11,11,12,11,11,12,11,11,11,11,31,45,0,0
0,0,45,31,11,11,11,0,0,0,11,0,0,11,11,11,14,12,12,12,11,14,12,12,11,10,21,31,45,0,0
0,0,45,31,11,12,12,21,21,21,11,8,8,11,12,12,11,11,11,12,11,12,11,11,11,12,12,31,45,0,0
0,0,45,31,12,11,11,14,12,12,8,11,11,11,8,11,12,11,8,14,14,12,11,14,11,11,11,31,45,0,0
6,45,45,31,14,11,11,12,11,12,11,11,11,11,11,12,11,12,12,11,11,12,14,14,11,11,11,31,45,45,0
0,45,31,11,14,12,11,14,12,11,11,11,11,11,12,14,12,12,11,12,11,12,12,11,12,12,11,11,31,45,0
0,45,31,11,11,11,11,12,12,11,11,11,12,12,12,12,16,11,12,25,12,11,12,14,11,11,12,11,31,45,0
0,45,31,31,14,12,11,11,11,11,11,11,14,11,12,11,12,11,11,11,12,11,11,14,12,12,11,31,31,45,0
0,45,45,31,11,12,12,11,11,12,11,11,11,12,12,11,12,12,11,11,11,11,31,0,0,0,31,31,45,45,0
0,0,45,31,12,12,11,11,11,11,11,11,14,11,11,11,11,11,12,14,11,12,31,0,0,0,31,31,45,0,0
0,0,45,31,11,12,12,11,11,11,12,11,11,12,12,11,11,12,11,11,11,11,31,0,0,0,31,31,45,0,0
0,0,45,31,11,12,21,14,11,11,12,11,11,11,12,11,12,11,11,11,11,31,31,0,0,0,31,31,45,0,0
0,0,45,31,11,11,12,11,11,14,11,11,11,12,12,11,11,11,11,12,11,31,0,0,0,0,0,31,45,0,0
0,9,19,31,11,11,11,11,11,14,12,8,11,11,11,12,11,11,11,12,12,31,0,0,0,0,13,31,19,0,0
0,9,33,31,12,11,12,11,11,11,11,12,11,12,11,11,12,12,11,11,11,31,11,0,0,0,12,31,33,0,0
0,0,30,31,11,11,12,11,12,11,12,8,12,12,12,11,11,12,11,11,11,31,0,0,0,0,0,31,30,0,0
0,0,45,31,12,12,21,12,11,14,11,12,11,11,12,21,12,12,11,11,11,31,5,0,0,0,0,31,45,0,0
0,0,45,31,11,11,11,14,12,11,12,12,11,17,12,11,12,12,12,11,11,31,31,0,0,0,31,31,45,0,0
0,0,45,31,11,11,11,12,11,11,11,11,11,12,11,12,11,14,12,12,14,12,31,0,0,0,31,31,45,0,0
0,0,45,31,11,12,11,12,12,12,11,11,11,11,11,11,11,11,14,12,11,14,31,0,0,0,31,31,45,0,0
0,45,45,31,25,12,11,11,11,11,11,12,12,12,11,11,12,12,12,12,11,12,31,0,0,0,31,31,45,45,0
0,45,31,31,11,11,11,11,12,11,12,12,11,11,11,12,11,12,11,11,11,12,16,11,21,12,31,31,31,45,0
0,45,31,11,12,11,12,14,11,11,12,11,11,12,12,7,11,11,11,11,11,12,11,12,11,14,14,14,31,45,0
0,45,31,15,12,11,11,11,11,12,11,11,12,12,12,12,11,12,11,12,11,12,12,11,11,12,11,11,31,45,0
0,45,45,31,11,11,11,11,11,11,14,11,11,12,14,11,12,14,12,14,11,12,14,11,11,11,11,31,45,45,0
0,0,45,31,11,11,12,11,12,11,11,12,11,11,11,12,25,8,12,12,11,12,0,0,11,12,11,31,45,0,0
0,0,45,31,11,11,11,25,25,25,11,17,17,11,14,12,14,14,14,12,12,23,0,0,34,12,11,31,45,0,0
0,0,45,31,12,12,11,0,0,0,11,0,0,12,11,11,14,12,11,11,12,0,0,0,0,11,11,31,45,0,0
0,0,45,31,12,12,11,5,0,0,11,0,0,11,11,12,12,11,11,12,14,0,0,0,0,11,11,31,45,0,0
0,0,45,31,11,12,10,0,0,0,0,0,0,11,12,14,12,14,12,11,12,14,11,14,12,11,11,31,45,0,0
0,0,45,31,12,11,12,0,0,0,0,0,0,11,11,12,14,12,11,11,11,12,11,11,11,11,11,31,45,0,0
0,0,45,31,11,11,11,0,0,0,0,24,0,12,12,11,14,11,12,11,12,11,11,11,14,11,12,31,45,0,0
0,45,45,31,11,11,12,11,11,11,11,12,11,12,11,12,11,12,21,12,11,12,11,11,11,12,11,31,45,45,0
0,45,31,11,11,11,11,12,12,12,11,12,12,11,11,11,12,11,11,12,12,11,11,11,11,12,11,14,31,45,0
0,45,31,11,12,31,31,31,31,31,31,31,31,31,11,12,11,31,31,31,31,31,31,31,31,31,12,12,31,45,0
0,45,31,31,31,45,45,45,45,45,45,45,45,45,31,31,31,45,45,45,45,45,45,45,45,45,31,31,31,45,0
0,45,45,45,45,45,0,0,0,6,0,0,0,45,45,45,45,45,0,0,0,0,9,0,0,45,45,45,45,45,0
0,0,0,0,0,0,0,0,0,0,0,0,0,0,0,0,0,0,0,0,0,0,0,0,0,0,0,0,0,0,0
endlayer

layer
0,0,6,0,0,0,0,0,0,0,0,0,0,0,0,0,0,0,0,0,0,0,0,0,0,0,0,0,0,0,0
0,40,40,40,40,40,0,0,0,0,0,0,0,40,40,40,40,40,0,0,0,0,0,0,9,40,40,40,40,40,0
0,40,31,31,31,40,40,40,40,40,40,40,40,40,31,31,31,40,40,40,40,40,40,40,40,40,31,31,31,40,0
0,40,31,11,12,31,31,31,31,31,31,31,31,31,11,11,11,31,31,31,31,31,31,31,31,31,11,11,31,40,0
0,40,31,15,12,11,11,12,11,11,11,11,11,11,12,11,11,12,11,11,11,11,11,11,11,12,14,11,31,40,0
0,40,40,31,11,11,12,11,11,11,12,12,11,14,12,12,11,11,12,12,11,11,11,12,12,11,11,31,40,40,0
0,0,40,31,11,11,11,11,11,12,11,11,11,12,12,11,11,14,11,11,14,11,11,12,11,11,11,31,40,0,0
0,0,40,31,11,12,11,11,12,11,11,12,11,11,11,12,11,11,12,12,11,14,11,11,11,11,11,31,40,0,0
0,0,40,31,12,11,12,11,11,12,11,0,23,11,11,11,11,11,11,11,11,12,12,11,11,11,12,31,40,0,0
0,0,40,31,11,12,11,11,12,16,11,0,0,11,11,11,11,11,12,11,12,14,12,11,11,12,11,31,40,0,0
0,0,40,31,11,11,14,12,12,11,11,0,0,12,12,11,8,11,11,11,12,12,11,11,12,11,12,31,40,0,0
0,0,40,31,12,11,11,11,12,11,12,0,0,11,11,12,12,11,11,11,11,11,11,11,12,8,12,31,40,0,0
0,0,40,31,12,12,11,12,12,21,7,0,0,11,11,11,11,12,11,11,12,12,25,11,11,12,11,31,40,0,0
6,40,40,31,14,12,11,12,11,12,7,0,0,11,12,11,12,12,12,11,11,11,11,12,12,11,11,31,40,40,0
0,40,31,15,12,11,12,11,11,12,11,11,11,11,12,11,12,12,11,11,11,12,12,11,12,12,11,11,31,40,0
0,40,31,12,11,11,12,11,11,11,11,12,11,12,11,11,14,11,11,11,11,11,12,12,11,11,12,12,31,40,0
0,40,31,31,11,11,11,12,12,12,11,12,12,12,11,11,11,11,11,14,12,11,11,12,11,11,12,31,31,40,0
0,40,40,31,11,11,11,11,11,11,11,12,11,11,11,12,11,12,12,11,11,14,12,18,44,16,11,31,40,40,0
0,0,40,31,11,11,14,11,14,11,12,11,11,12,12,11,11,21,11,12,12,11,11,18,44,16,11,31,40,0,0
0,0,40,31,12,14,12,11,12,11,12,11,11,14,12,11,12,11,11,12,11,12,11,44,44,44,11,31,40,0,0
0,0,40,31,11,12,12,12,11,11,11,11,11,11,11,11,12,11,12,11,11,14,12,44,0,44,12,31,40,0,0
0,0,9,31,11,11,12,11,11,12,11,11,11,11,11,11,11,11,12,11,11,11,18,0,0,0,16,31,40,0,0
0,6,42,31,11,12,12,11,14,11,12,11,12,11,11,12,11,11,12,14,11,11,18,0,0,0,16,31,42,0,0
0,0,33,31,11,11,11,12,11,11,12,11,12,11,12,12,12,11,12,12,11,12,11,0,0,0,11,31,33,0,0
0,9,43,31,11,11,11,11,12,12,11,11,11,14,11,12,16,12,11,14,12,11,18,0,0,0,16,31,43,0,0
0,0,40,31,11,11,14,11,11,11,11,11,11,11,11,11,11,12,12,12,11,8,18,0,0,0,16,31,40,0,0
0,0,40,31,12,11,11,12,12,11,11,11,11,12,12,11,11,11,11,11,12,11,12,44,0,44,11,31,40,0,0
0,0,40,31,11,11,11,12,12,21,12,12,11,11,11,11,11,11,11,11,16,11,12,44,44,44,18,31,40,0,0
0,0,40,31,11,11,11,11,12,11,11,12,11,11,11,11,12,11,12,11,12,11,11,18,44,16,11,31,40,0,0
0,40,40,31,11,12,11,10,12,11,11,11,11,12,14,11,11,11,14,11,11,11,11,18,44,16,11,31,40,40,0
0,40,31,31,12,11,11,12,11,14,12,11,12,11,12,11,11,11,11,11,11,11,11,11,12,12,11,31,31,40,0
0,40,31,11,11,11,12,11,14,11,11,12,11,14,11,12,11,11,12,11,11,11,11,11,11,12,11,15,31,40,0
0,40,31,11,11,12,11,12,11,11,12,11,11,12,11,12,12,14,11,12,11,11,12,12,11,11,11,15,31,40,0
0,40,40,31,11,11,11,12,11,11,7,0,13,11,11,11,12,12,11,11,11,11,11,11,11,11,11,31,40,40,0
0,0,40,31,11,7,11,11,12,11,7,0,0,11,12,11,11,12,11,12,12,11,12,14,12,11,11,31,40,0,0
0,0,40,31,12,11,12,11,12,11,11,0,0,11,12,11,11,12,12,25,12,11,11,11,11,11,11,31,40,0,0
0,0,40,31,12,11,12,12,11,12,12,0,0,11,12,11,12,11,12,11,11,11,11,11,14,11,11,31,40,0,0
0,0,40,31,12,12,11,12,11,11,11,0,0,11,14,16,11,11,11,12,11,12,14,11,12,11,11,31,40,0,0
0,0,40,31,12,12,11,14,11,11,11,0,0,14,11,11,11,11,12,11,11,12,11,11,12,14,12,31,40,0,0
0,0,40,31,12,11,11,12,11,11,11,11,11,11,11,11,12,11,11,11,12,14,12,11,12,11,12,31,40,0,0
0,0,40,31,11,12,11,11,11,7,12,12,11,11,11,11,11,11,11,11,11,12,11,12,11,11,11,31,40,0,0
0,40,40,31,12,14,11,11,12,11,11,25,11,11,12,11,11,11,11,11,25,11,12,11,11,11,12,31,40,40,0
0,40,31,15,12,21,11,11,11,11,11,11,12,11,11,11,12,11,11,11,12,12,11,11,11,12,12,11,31,40,0
0,40,31,11,15,31,31,31,31,31,31,31,31,31,12,11,12,31,31,31,31,31,31,31,31,31,11,11,31,40,0
0,40,31,31,31,40,40,40,40,40,40,40,40,40,31,31,31,40,40,40,40,40,40,40,40,40,31,31,31,40,0
0,40,40,40,40,40,0,0,0,6,0,0,0,40,40,40,40,40,0,0,0,0,0,9,0,40,40,40,40,40,0
0,0,0,0,0,0,0,0,0,0,0,0,0,0,0,0,0,0,0,0,0,0,0,0,0,0,0,0,0,0,0
endlayer

layer
0,9,24,0,0,0,0,0,0,0,0,0,0,0,0,0,0,0,0,0,0,0,0,0,0,0,0,0,0,0,0
0,26,42,42,42,41,0,0,0,0,0,0,0,42,42,42,42,42,0,0,0,0,0,0,9,26,42,42,42,41,0
0,26,46,46,46,42,42,42,42,42,42,42,42,26,46,46,46,41,42,42,42,42,42,42,42,42,46,46,46,41,0
0,26,46,46,46,46,46,46,46,46,46,46,46,46,46,46,46,46,46,46,46,46,46,46,46,46,46,46,46,41,0
0,26,46,46,11,12,11,11,46,46,46,46,46,12,11,11,11,11,46,46,46,46,46,11,11,11,11,46,46,41,0
0,43,26,46,11,12,12,11,11,11,14,11,12,11,11,12,11,12,11,12,11,11,11,12,11,11,12,46,41,43,0
0,0,26,46,11,11,7,8,11,12,12,14,11,12,11,11,11,11,12,11,12,11,11,11,11,11,11,46,41,0,0
0,0,26,46,46,12,12,11,11,11,12,11,12,14,11,11,11,16,12,12,12,11,11,17,11,11,11,46,41,0,0
0,0,26,46,46,11,11,11,11,12,11,11,11,18,11,14,11,12,11,12,11,11,11,12,12,12,46,46,41,0,0
0,0,26,46,46,12,12,14,11,11,11,14,11,12,11,11,11,16,11,11,11,12,12,12,11,11,46,46,41,0,0
0,0,26,46,46,11,12,12,11,12,12,0,0,12,11,11,12,11,11,11,11,12,11,11,11,14,46,46,41,0,0
0,0,26,46,46,12,11,11,11,11,11,0,13,11,11,12,11,12,11,11,12,12,12,12,12,11,46,46,41,0,0
0,0,26,46,46,11,11,12,11,7,0,0,0,12,14,11,11,11,14,11,12,11,11,11,11,11,46,46,41,0,0
0,26,42,46,11,12,12,12,11,7,0,0,0,12,11,11,12,12,12,11,11,11,11,11,11,14,11,46,42,41,0
9,26,46,46,14,11,11,12,12,11,12,12,11,11,11,11,11,11,12,11,8,11,11,11,11,11,11,46,46,41,0
0,26,46,46,12,12,12,11,11,11,11,12,11,12,11,11,11,12,11,11,11,12,11,11,11,11,11,46,46,41,0
0,26,46,46,2,2,2,46,46,46,46,46,46,12,11,14,11,11,46,46,46,46,46,46,2,2,2,46,46,41,0
0,43,43,46,46,46,46,46,46,46,46,46,46,46,46,46,46,46,46,46,46,46,46,46,46,46,46,46,43,43,0
0,0,26,46,46,46,46,46,46,46,46,46,46,46,46,46,46,46,46,46,46,46,46,46,46,46,46,46,41,0,0
0,0,26,46,46,11,12,14,11,11,11,11,11,11,11,11,11,11,11,14,12,12,11,11,12,14,46,46,41,0,0
0,0,26,46,46,12,12,11,11,11,11,11,12,11,11,11,11,11,11,11,12,11,11,11,11,12,46,46,41,0,0
0,0,26,46,46,11,12,12,11,11,11,11,11,11,11,11,11,14,11,11,11,12,11,18,0,16,46,46,41,0,0
0,0,26,46,46,11,14,11,11,11,11,11,11,11,11,12,12,11,11,11,11,11,12,18,0,16,46,46,41,0,0
0,0,26,46,11,11,11,12,11,11,11,12,11,14,12,12,11,12,12,11,11,11,11,18,0,16,46,46,41,0,0
0,6,26,46,46,11,11,12,11,12,11,11,12,11,11,11,11,12,12,12,12,11,11,18,0,16,46,46,41,0,0
0,0,26,46,46,12,12,12,14,11,12,11,11,12,11,11,12,12,11,11,11,12,11,18,0,16,46,46,41,0,0
0,0,26,46,46,11,11,11,11,11,11,11,11,14,12,12,14,11,11,11,11,11,12,11,11,11,46,46,41,0,0
0,0,26,46,46,11,12,12,11,11,11,12,12,11,12,11,11,12,11,11,12,11,11,11,11,11,46,46,41,0,0
0,0,26,46,46,46,46,46,46,46,46,46,46,46,46,46,46,46,46,46,46,46,46,46,46,46,46,46,41,0,0
0,42,42,46,46,46,46,46,46,46,46,46,46,46,46,46,46,46,46,46,46,46,46,46,46,46,46,46,42,42,0
0,26,46,46,12,11,11,11,46,46,46,46,46,12,11,21,11,11,46,46,46,46,46,11,11,12,11,46,46,41,0
0,26,46,46,11,12,11,12,11,12,11,11,11,12,12,11,11,11,11,11,11,12,12,11,11,12,11,46,46,41,0
0,26,46,46,11,12,11,14,11,11,11,12,11,12,11,14,11,11,12,11,11,11,11,11,11,11,11,46,46,41,0
0,26,43,46,11,12,11,12,12,7,0,0,0,12,12,11,11,12,8,11,11,12,14,11,12,21,11,46,43,41,0
0,0,26,46,46,11,11,11,11,7,0,0,0,11,11,11,11,11,11,11,11,11,12,11,11,11,46,46,41,0,0
0,0,26,46,46,11,12,11,17,11,11,0,0,11,12,11,14,11,12,11,11,11,11,11,11,11,46,46,41,0,0
0,0,26,46,46,11,11,11,11,11,12,0,0,11,11,11,14,11,14,11,11,12,12,12,11,11,46,46,41,0,0
0,0,26,46,46,11,11,12,11,12,11,11,11,11,11,11,11,14,11,11,11,11,11,12,12,11,46,46,41,0,0
0,0,26,46,46,11,11,11,12,11,12,11,11,11,12,11,11,11,12,12,12,11,11,11,12,11,46,46,41,0,0
0,0,26,46,12,11,11,11,11,11,11,11,12,21,12,11,11,12,11,14,11,11,11,12,11,11,14,46,41,0,0
0,0,26,46,11,11,11,11,12,8,11,14,12,11,11,11,11,11,11,11,11,12,11,11,11,12,11,46,41,0,0
0,42,26,46,12,11,11,11,11,11,11,11,11,12,11,12,11,11,12,11,11,11,11,12,12,12,11,46,41,42,0
0,26,46,46,11,11,11,11,46,46,46,46,46,12,11,11,12,11,46,46,46,46,46,11,11,14,11,46,46,41,0
0,26,46,46,46,46,46,46,46,46,46,46,46,46,46,46,46,46,46,46,46,46,46,46,46,46,46,46,46,41,0
0,26,46,46,46,43,43,43,43,43,43,43,43,26,46,46,46,41,43,43,43,43,43,43,43,43,46,46,46,41,0
0,26,43,43,43,41,0,0,6,0,0,0,0,43,43,43,43,43,0,0,0,0,0,9,0,26,43,43,43,41,0
0,0,0,0,0,0,0,0,0,0,0,0,0,0,0,0,0,0,0,0,0,0,0,0,0,0,0,0,0,0,0
endlayer

layer
0,0,24,0,0,0,0,0,0,0,0,0,0,0,0,0,0,0,0,0,0,0,0,0,0,0,0,0,0,0,0
0,45,6,45,0,45,0,0,0,0,0,0,0,45,0,45,0,45,0,0,0,0,0,0,0,45,0,45,0,45,0
0,13,9,6,47,0,45,0,45,0,45,0,45,0,0,0,47,0,45,0,45,0,45,6,45,0,47,0,0,0,0
0,45,0,9,47,47,0,9,0,47,47,0,0,0,48,24,0,6,0,6,47,0,0,0,6,0,0,0,47,45,0
0,0,47,0,11,14,11,7,6,47,0,47,47,10,11,11,15,7,6,0,0,47,9,10,11,12,11,48,0,0,0
0,45,0,47,12,11,12,12,12,12,11,11,8,12,12,11,11,11,12,12,12,11,12,11,12,11,15,0,5,45,0
0,0,45,6,12,11,11,0,0,0,31,0,0,0,11,11,11,0,0,27,31,34,0,0,11,11,15,0,45,0,0
0,0,0,0,6,12,5,0,0,0,0,0,0,0,0,0,0,0,0,0,0,0,0,0,0,11,17,0,0,0,0
0,0,45,47,48,12,0,0,0,0,0,0,0,0,0,0,0,0,0,0,0,17,10,11,11,11,0,0,45,0,0
0,0,0,0,0,12,0,0,0,0,0,0,0,0,0,0,0,0,0,0,0,50,10,49,14,12,0,47,0,0,0
0,0,45,47,0,11,31,0,0,0,0,0,0,0,0,0,0,0,0,0,0,0,10,12,0,11,48,0,45,0,0
0,0,0,6,48,14,0,0,0,0,0,0,0,0,0,0,0,0,0,0,0,51,10,49,11,11,47,0,0,0,0
0,0,45,9,6,11,0,0,0,0,0,0,0,0,0,0,0,0,0,0,0,8,8,12,11,12,5,47,45,0,0
0,45,0,0,8,11,0,0,0,0,0,0,0,0,0,24,0,0,0,0,0,0,0,0,0,11,8,47,0,45,0
9,9,9,9,14,11,11,34,0,0,31,0,0,0,12,12,11,0,0,0,31,0,0,0,15,15,11,0,0,0,0
0,45,9,9,12,11,11,11,15,11,12,11,11,11,11,14,11,11,14,12,11,11,11,12,12,11,11,0,48,45,0
0,0,47,13,11,14,11,7,0,9,0,9,6,10,11,11,11,7,48,48,0,0,0,10,11,11,12,47,47,0,0
0,45,0,47,47,0,0,0,0,0,0,0,6,0,9,0,0,0,0,0,6,48,0,0,13,6,6,47,0,45,0
0,0,45,47,0,0,0,47,0,48,0,9,6,6,0,0,0,0,24,9,9,9,6,0,0,0,9,9,45,0,0
0,0,0,47,48,11,11,11,11,11,11,11,11,11,11,11,11,11,11,11,11,11,14,14,12,11,0,47,0,0,0
0,0,45,0,47,15,11,12,11,15,15,11,12,11,12,14,11,11,11,11,12,11,11,12,11,12,0,0,45,0,0
0,0,0,0,0,11,11,11,12,11,11,11,15,11,11,14,14,11,15,11,11,15,11,14,11,11,9,0,0,0,0
0,0,45,47,0,14,11,11,12,11,11,15,11,11,11,11,11,11,11,11,12,14,12,12,15,11,0,47,45,0,0
0,0,9,6,0,12,12,11,11,12,3,15,11,11,11,12,12,11,12,11,11,11,11,11,12,11,6,47,0,0,0
0,0,45,0,6,8,11,11,12,11,12,12,11,14,11,12,11,11,11,11,11,11,11,15,15,12,0,48,45,0,0
0,0,0,9,6,12,11,12,11,12,7,12,15,12,11,12,11,12,12,11,11,12,11,12,12,14,47,0,0,0,0
0,0,45,0,6,11,12,11,11,11,11,11,12,11,11,11,12,11,12,12,11,11,11,12,11,12,0,0,45,0,0
0,0,0,47,0,11,12,12,15,11,11,11,11,11,11,11,12,14,11,15,3,11,14,11,25,15,48,0,0,0,0
0,0,45,0,6,6,47,0,9,0,0,47,0,47,0,0,0,47,13,6,0,47,0,47,9,47,47,0,45,0,0
0,45,0,9,6,6,0,0,9,6,0,47,0,0,0,0,0,9,48,0,0,0,0,9,9,0,0,47,0,45,0
0,0,48,0,12,11,12,7,0,6,0,0,48,10,11,12,11,7,6,0,0,47,47,10,12,11,11,47,0,0,0
0,45,0,0,11,14,11,11,12,11,11,11,11,11,12,14,11,14,11,11,11,12,14,11,12,15,11,0,0,45,0
0,0,47,47,12,12,11,0,0,0,31,0,0,0,12,11,11,0,0,0,31,0,0,34,15,11,11,0,48,0,0
0,45,0,47,17,11,0,0,0,0,0,0,0,0,0,0,0,0,0,0,0,0,0,0,0,14,17,47,0,45,0
0,0,45,6,0,11,0,0,0,0,0,0,0,0,0,0,0,0,0,0,0,17,17,11,11,12,9,0,45,0,0
0,0,0,6,9,12,0,0,0,0,0,0,0,0,0,0,0,0,0,0,0,52,10,49,12,11,0,6,0,0,0
0,0,45,9,47,11,31,0,0,0,0,0,0,0,0,0,0,0,0,0,0,0,10,11,0,12,9,9,45,0,0
0,0,0,6,6,11,0,0,0,0,0,0,0,0,0,0,0,0,0,0,0,53,10,49,12,11,6,0,0,0,0
0,0,45,0,6,15,0,0,0,0,0,0,0,0,0,0,0,0,0,0,0,8,10,16,11,11,0,47,45,0,0
0,0,0,0,8,11,34,0,0,0,0,0,0,0,0,0,0,0,0,24,0,0,0,0,0,19,8,47,0,0,0
0,0,45,0,11,12,11,0,0,0,31,34,0,0,12,11,11,24,0,34,31,0,34,0,12,11,11,47,45,0,0
0,45,0,47,11,12,11,11,11,12,11,11,14,15,15,11,11,12,12,15,11,12,11,12,11,11,12,24,0,45,0
0,0,47,0,12,12,11,7,6,0,9,0,0,10,12,11,11,7,23,23,9,0,9,10,15,11,12,6,47,0,0
0,45,48,0,47,0,47,6,9,6,47,47,0,0,47,0,48,0,47,47,48,9,6,0,0,47,0,9,0,45,0
0,0,0,47,48,0,45,9,45,0,45,0,45,0,0,47,47,0,45,0,45,0,45,9,45,0,6,47,48,0,0
0,45,0,45,0,45,0,0,0,0,0,0,0,45,0,45,0,45,0,0,0,0,0,0,0,45,0,45,0,45,0
0,0,0,0,0,0,0,0,0,0,0,0,0,0,0,0,0,0,0,0,0,0,0,0,0,0,0,0,0,0,0
endlayer

layer
0,0,0,0,0,0,0,0,0,0,0,0,0,0,0,0,0,0,0,0,0,0,0,0,0,0,0,0,0,0,0
0,0,0,0,0,0,0,0,0,0,0,0,0,0,0,0,0,0,0,0,0,0,0,0,0,0,0,0,0,0,0
0,0,0,9,0,0,0,0,0,0,0,0,0,0,0,0,0,0,0,0,0,0,0,0,0,0,0,0,0,0,0
0,0,0,0,0,21,0,0,0,0,0,0,0,0,54,21,0,0,0,0,0,0,0,9,6,21,24,0,0,0,0
0,0,0,0,11,11,11,6,9,0,0,0,0,0,11,12,11,55,0,6,9,0,0,6,11,11,11,54,0,0,0
0,0,0,16,11,11,11,11,12,35,20,35,12,11,11,11,12,11,11,35,20,35,15,11,12,11,11,18,5,0,0
0,0,0,13,12,11,12,0,31,31,33,31,31,0,12,15,11,0,31,31,33,31,31,0,11,11,11,0,0,0,0
0,0,0,0,6,12,5,0,0,0,0,0,0,0,0,0,0,0,0,0,0,0,0,0,0,14,0,0,0,0,0
0,0,0,0,54,11,31,0,0,0,0,0,0,0,0,0,0,0,0,0,0,0,0,0,31,11,0,0,0,0,0
0,0,0,0,0,35,31,0,0,0,0,0,0,0,0,0,0,0,0,0,0,0,0,56,31,35,0,0,0,0,0
0,0,0,0,0,20,33,0,0,0,0,0,0,0,0,0,0,0,0,0,0,0,0,11,33,20,54,0,0,0,0
0,0,0,0,54,35,31,0,0,0,0,0,0,0,0,0,0,0,0,0,0,0,0,56,31,35,0,0,0,0,0
0,0,0,0,0,11,31,0,0,0,0,0,0,0,0,0,0,0,0,0,0,0,0,0,31,11,0,0,0,0,0
0,0,0,0,9,11,0,0,0,0,0,0,0,0,0,24,0,0,0,0,0,0,0,0,34,11,0,0,0,0,0
0,0,0,0,11,12,11,0,31,31,33,31,31,0,12,11,11,0,31,31,33,31,31,34,14,12,11,0,0,0,0
0,0,0,16,11,11,12,15,12,35,20,35,11,11,11,11,11,11,11,35,20,35,12,11,12,12,11,18,54,0,0
0,0,0,0,14,12,12,0,23,0,0,0,0,9,15,11,11,23,54,54,0,0,0,0,12,11,11,0,0,0,0
0,0,0,0,0,25,0,0,0,0,0,0,0,0,0,25,0,0,0,0,0,54,0,0,0,25,0,0,0,0,0
0,0,0,0,0,0,0,0,0,54,6,9,0,9,0,0,0,0,0,0,6,9,0,0,0,0,0,0,0,0,0
0,0,0,0,54,16,21,21,21,21,21,21,21,21,21,21,21,21,21,21,21,21,21,21,21,18,0,0,0,0,0
0,0,0,0,0,16,46,46,46,46,46,46,46,46,46,46,46,46,46,46,46,46,46,46,46,18,0,0,0,0,0
0,0,0,0,0,16,46,46,46,46,46,46,46,46,46,46,46,46,46,46,46,46,46,46,46,18,0,0,0,0,0
0,0,0,0,0,16,46,46,46,46,46,2,2,2,2,11,11,12,14,12,46,46,46,46,46,18,0,0,0,0,0
0,0,0,0,0,16,46,46,46,46,2,2,2,2,12,11,12,11,12,11,2,46,46,46,46,18,9,0,0,0,0
0,0,0,0,6,16,46,46,46,46,46,2,2,2,2,11,11,11,11,11,46,46,46,46,46,18,0,54,0,0,0
0,0,0,0,0,16,46,46,46,46,46,46,46,46,46,46,46,46,46,46,46,46,46,46,46,18,0,0,0,0,0
0,0,0,0,0,16,46,46,46,46,46,46,46,46,46,46,46,46,46,46,46,46,46,46,46,18,0,0,0,0,0
0,0,0,0,0,16,25,25,25,25,25,25,25,25,25,25,25,25,25,25,25,25,25,25,25,18,54,0,0,0,0
0,0,0,0,0,0,0,0,0,0,0,0,0,0,0,0,0,0,0,9,0,0,0,0,6,6,0,0,0,0,0
0,0,0,0,6,21,0,0,9,5,0,0,0,0,24,21,0,0,54,0,0,0,0,0,0,21,0,5,0,0,0
0,0,54,24,15,12,11,5,0,9,0,0,54,0,12,11,11,9,6,24,0,0,0,0,11,12,11,0,0,0,0
0,0,0,16,12,11,11,11,11,35,20,35,12,12,11,11,12,15,16,35,20,35,11,11,11,11,11,18,0,0,0
0,0,0,0,11,11,12,0,31,31,33,31,31,0,11,12,12,13,31,31,33,31,31,0,11,11,11,0,54,0,0
0,0,0,0,0,12,0,0,0,0,0,0,0,0,0,0,0,0,0,0,0,0,0,0,0,11,0,0,0,0,0
0,0,0,0,0,11,31,0,0,0,0,0,0,0,0,0,0,0,0,0,0,0,0,0,31,12,0,0,0,0,0
0,0,0,0,9,35,31,0,0,0,0,0,0,0,0,0,0,0,0,0,0,0,0,57,31,35,9,0,0,0,0
0,0,0,9,0,20,33,0,0,0,0,0,0,0,0,0,0,0,0,0,0,0,0,12,33,20,9,5,0,0,0
0,0,0,0,0,35,31,0,0,0,0,0,0,0,0,0,0,0,0,0,0,0,13,57,31,35,9,0,0,0,0
0,0,0,6,9,11,31,0,0,0,0,0,0,0,0,0,0,0,0,0,0,0,0,0,31,8,0,0,0,0,0
0,0,0,0,0,12,0,0,0,0,0,0,0,0,0,0,0,0,0,24,0,0,0,0,0,11,0,0,0,0,0
0,0,0,0,11,11,11,0,31,31,32,31,31,0,11,15,11,24,31,31,32,31,31,0,12,11,11,0,0,0,0
0,0,0,16,16,12,11,12,12,35,20,35,11,11,11,11,12,11,11,35,20,35,12,11,11,12,11,18,0,0,0
0,0,0,0,11,11,11,6,0,0,0,0,0,0,11,12,11,0,23,0,0,0,0,0,11,11,11,0,0,0,0
0,0,54,0,0,25,0,9,0,6,0,0,0,0,0,25,54,0,0,0,54,0,0,0,0,25,6,6,0,0,0
0,0,0,0,54,0,0,0,0,0,0,0,0,0,0,0,0,0,0,0,0,0,0,0,0,0,0,0,54,0,0
0,0,0,0,0,0,0,0,0,0,0,0,0,0,0,0,0,0,0,0,0,0,0,0,0,0,0,0,0,0,0
0,0,0,0,0,0,0,0,0,0,0,0,0,0,0,0,0,0,0,0,0,0,0,0,0,0,0,0,0,0,0
endlayer

layer
0,0,0,0,0,0,0,0,0,0,0,0,0,0,0,0,0,0,0,0,0,0,0,0,0,0,0,0,0,0,0
0,0,0,0,0,0,0,0,0,0,0,0,0,0,0,0,0,0,0,0,0,0,0,0,0,0,0,0,0,0,0
0,0,0,0,0,0,0,0,0,0,0,0,0,0,0,0,0,0,0,0,0,0,0,0,0,0,0,0,0,0,0
0,0,0,0,0,12,0,0,0,0,0,0,0,0,0,11,0,0,0,0,0,0,0,0,9,12,24,0,0,0,0
0,0,0,0,11,11,11,6,0,0,0,0,0,0,15,11,15,13,9,0,0,0,0,24,11,11,11,0,0,0,0
0,0,0,11,12,12,11,15,7,0,0,0,10,11,11,14,12,14,7,6,0,0,10,11,12,12,12,11,5,0,0
0,0,0,0,15,15,11,31,33,31,33,31,33,31,11,11,11,31,33,31,33,31,33,31,15,11,11,0,0,0,0
0,0,0,0,0,11,31,0,0,0,0,0,0,0,0,0,0,0,0,0,0,0,0,23,31,11,0,0,0,0,0
0,0,0,0,0,17,33,0,0,0,0,0,0,0,0,0,0,0,0,0,0,0,0,0,33,17,0,0,0,0,0
0,0,0,0,0,0,31,0,0,0,0,0,0,0,0,0,0,0,0,0,0,0,0,0,31,0,0,0,0,0,0
0,0,0,0,0,0,33,0,0,0,0,0,0,0,0,0,0,0,0,0,0,0,0,11,33,0,0,0,0,0,0
0,0,0,0,0,0,31,0,0,0,0,0,0,0,0,0,0,0,0,0,0,0,0,0,31,0,0,0,0,0,0
0,0,0,0,0,8,33,0,0,0,0,0,0,0,0,0,0,0,0,0,0,0,0,0,33,8,0,0,0,0,0
0,0,0,0,6,11,31,0,0,0,0,0,0,0,0,24,0,0,0,0,0,0,0,0,31,11,0,0,0,0,0
0,0,0,13,11,11,11,31,33,31,33,31,33,31,12,11,11,31,33,31,32,31,33,31,19,11,11,0,0,0,0
0,0,0,15,15,12,12,12,7,0,0,23,10,12,11,11,12,11,7,0,0,0,10,11,14,3,12,14,0,0,0
0,0,0,0,11,14,12,0,0,0,0,0,0,0,11,11,11,0,0,0,0,0,0,23,12,15,11,0,0,0,0
0,0,0,0,0,11,0,0,0,0,0,0,0,0,0,15,0,0,0,0,0,0,0,0,0,15,5,0,0,0,0
0,0,0,0,0,0,0,0,0,0,0,0,0,0,0,0,0,0,0,0,0,6,0,0,0,0,0,0,0,0,0
0,0,0,0,0,20,0,20,0,20,9,20,0,20,0,20,0,20,0,20,0,20,0,20,0,20,0,0,0,0,0
0,0,0,0,0,0,47,47,47,47,0,6,6,47,48,0,0,47,0,47,0,0,47,0,47,0,0,0,0,0,0
0,0,0,0,0,20,0,48,0,47,0,0,9,47,0,9,9,0,24,0,24,47,0,0,9,20,0,0,0,0,0
0,0,0,0,0,0,9,0,0,0,0,58,58,12,11,11,11,11,58,58,0,0,0,9,0,6,0,0,0,0,0
0,0,0,0,0,20,6,9,6,5,58,11,11,11,12,12,11,11,11,11,58,0,47,0,9,20,0,0,0,0,0
0,0,0,0,0,6,6,6,9,0,13,58,58,12,12,11,11,12,58,58,0,0,0,9,0,0,0,0,0,0,0
0,0,0,0,0,20,0,6,0,0,47,0,47,47,0,9,0,6,5,0,47,6,6,0,0,20,0,0,0,0,0
0,0,0,0,0,0,47,0,0,47,0,0,0,48,0,47,47,6,6,0,9,0,6,0,47,0,0,0,0,0,0
0,0,0,0,0,20,0,20,0,20,0,20,0,20,0,20,0,20,0,20,9,20,0,20,0,20,0,0,0,0,0
0,0,0,0,0,0,0,0,0,0,0,0,0,0,0,0,0,0,0,0,0,0,0,0,0,6,0,0,0,0,0
0,0,0,0,0,3,0,0,0,0,0,0,0,0,24,11,0,0,0,0,0,0,0,0,0,12,6,5,0,0,0
0,0,0,24,11,11,15,5,6,0,0,0,0,0,12,12,11,9,0,0,0,0,0,0,15,11,11,0,0,0,0
0,0,0,11,11,11,11,11,7,9,0,0,10,12,11,11,11,11,7,0,0,0,10,11,3,12,11,8,0,0,0
0,0,0,0,12,11,11,31,33,31,33,31,33,31,11,11,12,31,33,31,33,31,33,31,15,12,12,0,0,0,0
0,0,0,0,0,11,31,23,0,0,0,0,0,0,0,0,0,0,0,0,0,0,0,0,31,12,0,0,0,0,0
0,0,0,0,0,17,33,0,0,0,0,0,0,0,0,0,0,0,0,0,0,0,0,0,33,17,0,0,0,0,0
0,0,0,0,0,0,31,0,0,0,0,0,0,0,0,0,0,0,0,0,0,0,0,34,31,0,0,0,0,0,0
0,0,0,6,0,0,33,0,0,0,0,0,0,0,0,0,0,0,0,0,0,0,0,12,33,0,6,0,0,0,0
0,0,0,0,0,0,31,0,0,0,0,0,0,0,0,0,0,0,0,0,0,0,0,0,31,0,0,0,0,0,0
0,0,0,0,0,8,33,0,0,0,0,0,0,0,0,0,0,0,0,0,0,0,0,0,33,8,0,0,0,0,0
0,0,0,0,0,11,31,0,0,0,0,0,0,0,0,0,0,0,0,24,0,0,0,0,31,12,0,0,0,0,0
0,0,0,0,11,12,11,31,33,31,33,31,33,31,12,12,16,31,33,31,33,31,33,31,15,11,11,0,0,0,0
0,0,0,11,15,12,12,11,7,0,0,0,10,11,15,11,12,11,7,0,0,0,10,12,11,11,11,12,0,0,0
0,0,0,0,21,11,10,5,0,0,0,0,0,0,11,11,11,0,0,0,0,0,0,0,11,11,11,0,0,0,0
0,0,0,0,0,15,0,9,0,0,0,0,0,0,0,12,0,0,0,0,0,0,0,0,0,11,9,0,0,0,0
0,0,0,0,0,0,0,0,0,0,0,0,0,0,0,0,0,0,0,0,0,0,0,0,0,0,0,0,0,0,0
0,0,0,0,0,0,0,0,0,0,0,0,0,0,0,0,0,0,0,0,0,0,0,0,0,0,0,0,0,0,0
0,0,0,0,0,0,0,0,0,0,0,0,0,0,0,0,0,0,0,0,0,0,0,0,0,0,0,0,0,0,0
endlayer

layer
0,0,0,0,0,0,0,0,0,0,0,0,0,0,0,0,0,0,0,0,0,0,0,0,0,0,0,0,0,0,0
0,0,0,0,0,0,0,0,0,0,0,0,0,0,0,0,0,0,0,0,0,0,0,0,0,0,0,0,0,0,0
0,0,0,0,0,0,0,0,0,0,0,0,0,0,0,0,0,0,0,0,0,0,0,0,0,0,0,0,0,0,0
0,0,0,0,0,8,0,0,0,0,0,0,0,0,0,8,0,6,0,0,0,0,0,0,0,8,0,0,0,0,0
0,0,0,0,12,11,11,6,0,0,0,0,0,0,11,11,15,9,0,0,0,0,0,9,11,12,7,0,0,0,0
0,0,0,10,11,15,12,11,0,0,0,0,0,12,14,11,15,11,0,0,0,6,0,11,11,12,11,7,0,0,0
0,0,0,0,12,11,15,31,33,31,33,31,33,31,11,11,12,31,33,31,33,31,33,31,12,11,11,0,0,0,0
0,0,0,0,23,11,31,0,0,0,0,0,0,0,0,0,0,0,0,0,0,0,0,23,31,11,0,0,0,0,0
0,0,0,0,0,0,33,0,0,0,0,0,0,0,0,0,0,0,0,0,0,0,0,0,33,0,0,0,0,0,0
0,0,0,0,0,13,31,0,0,0,0,0,0,0,0,0,0,0,0,0,0,0,0,0,31,0,0,0,0,0,0
0,0,0,0,0,0,33,0,0,0,0,0,0,0,0,0,0,0,0,0,0,0,0,0,33,0,0,0,0,0,0
0,0,0,0,0,0,31,0,0,0,0,0,0,0,0,0,0,0,0,0,0,0,0,0,31,0,0,0,0,0,0
0,0,0,0,6,0,33,0,0,0,0,0,0,0,0,0,0,0,0,0,0,0,0,0,33,0,0,0,0,0,0
0,0,0,0,0,12,31,0,0,0,0,0,0,0,0,0,0,24,0,0,0,0,0,0,31,15,0,0,0,0,0
0,0,0,0,11,12,25,31,33,31,33,31,33,31,11,15,15,31,33,31,33,31,33,31,11,11,11,0,0,0,0
0,0,0,10,15,11,11,3,0,0,0,0,0,11,11,11,12,11,0,0,0,0,0,11,11,12,11,7,0,0,0
0,0,0,0,12,11,15,0,0,0,0,0,0,9,11,12,15,0,0,0,0,0,0,0,12,14,11,0,0,0,0
0,0,0,0,0,17,0,0,0,0,0,0,0,0,0,17,0,0,0,0,0,0,0,0,0,17,0,0,0,0,0
0,0,0,0,0,0,0,0,0,0,0,0,0,0,0,0,0,0,0,0,0,0,0,0,0,0,0,0,0,0,0
0,0,0,0,0,0,0,0,0,0,0,0,0,0,0,0,0,0,0,0,0,0,0,0,0,0,0,0,0,0,0
0,0,0,0,0,0,0,0,0,0,0,0,0,0,54,0,0,0,0,0,0,0,0,0,0,0,0,0,0,0,0
0,0,0,0,0,0,0,54,0,0,0,0,6,0,0,0,6,0,24,0,24,0,0,0,0,0,0,0,0,0,0
0,0,0,0,0,0,24,0,0,0,58,11,12,12,12,11,12,12,11,11,58,0,0,0,0,0,0,0,0,0,0
0,0,0,0,0,0,6,0,0,58,11,11,14,11,11,12,10,11,12,17,11,58,0,0,0,0,0,0,0,0,0
0,0,0,0,0,0,0,6,0,0,58,11,11,11,12,12,12,11,11,11,58,34,0,0,0,0,0,0,0,0,0
0,0,0,0,0,0,0,0,0,0,0,0,0,0,9,9,0,6,5,0,0,0,0,0,0,0,0,0,0,0,0
0,0,0,0,0,0,0,0,0,0,0,0,0,54,0,0,0,0,0,0,0,0,0,0,0,0,0,0,0,0,0
0,0,0,0,0,0,0,0,0,0,0,0,0,0,0,0,0,0,0,0,0,0,0,0,0,0,0,0,0,0,0
0,0,0,0,0,0,0,0,0,0,0,0,0,0,0,0,0,0,0,0,0,0,0,0,0,0,0,0,0,0,0
0,0,0,0,0,8,0,0,0,0,0,0,0,0,24,8,0,0,0,0,0,0,0,0,0,8,6,0,0,0,0
0,0,0,0,11,15,11,0,6,0,0,0,0,0,11,11,14,0,0,0,0,0,0,0,12,11,11,0,0,0,0
0,0,0,10,12,11,15,11,0,0,0,0,0,11,12,11,11,12,0,0,0,0,13,11,11,12,11,7,0,0,0
0,0,0,0,12,12,11,31,33,31,32,31,33,31,12,15,15,31,33,31,33,31,33,31,11,11,11,0,0,0,0
0,0,0,0,0,12,31,23,0,0,0,0,0,0,0,0,23,0,0,0,0,0,0,0,31,15,0,0,0,0,0
0,0,0,0,0,0,33,0,0,0,0,0,0,0,0,0,0,0,0,0,0,0,0,0,33,0,0,0,0,0,0
0,0,0,0,0,0,31,0,0,0,0,0,0,0,0,0,0,0,0,0,0,0,0,0,31,0,0,0,0,0,0
0,0,0,0,0,0,33,0,0,0,0,0,0,0,0,0,0,0,0,0,0,0,0,0,33,0,0,0,0,0,0
0,0,0,0,0,0,31,0,0,0,0,0,0,0,0,0,0,0,0,0,0,0,0,0,31,9,0,0,0,0,0
0,0,0,0,0,6,33,0,0,0,0,0,0,0,0,0,0,0,0,0,0,0,0,0,33,0,0,0,0,0,0
0,0,0,0,0,12,31,0,0,0,0,0,0,0,0,0,0,0,0,0,0,0,0,0,31,15,0,0,0,0,0
0,0,0,0,11,11,15,31,33,31,33,31,33,31,12,12,11,31,33,31,33,31,32,31,11,12,11,0,0,0,0
0,0,0,10,11,14,12,12,0,0,0,0,0,14,11,11,15,12,0,0,0,0,0,15,12,12,11,7,0,0,0
0,0,0,0,11,12,15,29,0,0,0,0,0,0,11,11,11,23,0,0,0,0,0,0,11,11,11,0,0,0,0
0,0,0,0,0,17,23,0,0,0,0,0,0,0,0,17,0,0,0,0,0,0,0,0,0,17,0,0,0,0,0
0,0,0,0,0,0,0,0,0,0,0,0,0,0,0,0,0,0,0,0,0,0,0,0,0,0,0,0,0,0,0
0,0,0,0,0,0,0,0,0,0,0,0,0,0,0,0,0,0,0,0,0,0,0,0,0,0,0,0,0,0,0
0,0,0,0,0,0,0,0,0,0,0,0,0,0,0,0,0,0,0,0,0,0,0,0,0,0,0,0,0,0,0
endlayer

layer
0,0,0,0,0,0,0,0,0,0,0,0,0,0,0,0,0,0,0,0,0,0,0,0,0,0,0,0,0,0,0
0,0,0,0,0,0,0,0,0,0,0,0,0,0,0,0,0,0,0,0,0,0,0,0,0,0,0,0,0,0,0
0,0,0,0,0,0,0,0,0,0,0,0,0,0,0,0,0,0,0,0,0,0,0,0,0,0,0,0,0,0,0
0,0,0,0,0,0,0,0,0,0,0,0,0,0,0,9,6,0,0,0,0,0,0,0,6,9,0,0,0,0,0
0,0,0,0,15,11,12,0,0,0,0,0,0,0,11,11,14,9,0,0,0,0,0,0,14,11,12,0,0,0,0
0,0,0,0,11,15,11,20,0,0,0,0,0,20,16,11,11,20,0,0,0,6,0,20,12,11,15,0,0,0,0
0,0,0,0,12,3,11,31,33,31,33,31,33,31,12,11,18,31,33,31,33,31,33,31,15,12,11,0,0,0,0
0,0,0,0,0,20,31,0,0,0,0,0,0,0,0,0,0,0,0,0,0,0,0,0,31,20,0,0,0,0,0
0,0,0,0,0,0,33,0,0,0,0,0,0,0,0,0,0,0,0,0,0,0,0,0,33,0,0,0,0,0,0
0,0,0,0,0,0,31,0,0,0,0,0,0,0,0,0,0,0,0,0,0,0,0,0,31,0,0,0,0,0,0
0,0,0,0,0,0,33,0,0,0,0,0,0,0,0,0,0,0,0,0,0,0,0,0,33,0,0,0,0,0,0
0,0,0,0,9,0,31,0,0,0,0,0,0,0,0,0,0,0,0,0,0,0,0,0,31,0,0,0,0,0,0
0,0,0,0,0,0,33,0,0,0,0,0,0,0,0,0,0,0,0,0,0,0,0,0,33,0,0,0,0,0,0
0,0,0,0,0,20,31,5,0,0,0,0,0,0,0,0,0,0,0,0,0,0,0,0,31,20,0,0,0,0,0
0,0,0,0,11,12,12,31,33,31,33,31,33,31,12,11,12,31,33,31,33,31,33,31,12,12,11,0,0,0,0
0,0,0,0,15,11,11,20,0,0,0,0,0,20,11,11,11,20,0,0,0,0,0,20,11,11,11,0,0,0,0
0,0,0,0,11,15,11,0,0,0,0,0,0,6,15,11,11,0,0,0,0,0,0,0,12,11,11,0,0,0,0
0,0,0,0,0,0,0,0,0,0,0,0,0,0,0,0,0,0,0,0,0,0,0,0,0,0,0,0,0,0,0
0,0,0,0,0,0,0,0,0,0,0,0,0,0,0,0,0,0,0,0,0,0,0,0,0,0,0,0,0,0,0
0,0,0,0,0,0,0,0,0,0,0,0,0,0,0,0,0,0,0,0,0,0,0,0,0,0,0,0,0,0,0
0,0,0,0,0,0,0,0,0,0,0,0,0,0,0,0,0,0,0,0,0,0,0,0,0,0,0,0,0,0,0
0,0,0,0,0,0,0,0,0,0,0,0,0,0,0,0,0,0,24,0,24,0,0,0,0,0,0,0,0,0,0
0,0,0,0,0,0,0,0,0,58,11,12,11,9,0,0,9,13,12,11,11,58,34,0,0,0,0,0,0,0,0
0,0,0,0,0,0,9,0,58,11,11,11,12,12,9,6,9,12,12,12,11,11,58,0,0,0,0,0,0,0,0
0,0,0,0,0,0,0,0,0,58,11,12,12,9,6,0,9,34,11,11,12,58,0,0,0,0,0,0,0,0,0
0,0,0,0,0,0,0,0,0,0,0,0,0,0,0,0,9,0,0,0,23,0,0,0,0,0,0,0,0,0,0
0,0,0,0,0,0,0,0,0,0,0,0,0,0,0,0,0,0,0,0,0,0,0,0,0,0,0,0,0,0,0
0,0,0,0,0,0,0,0,0,0,0,0,0,0,0,0,0,0,0,0,0,0,0,0,0,0,0,0,0,0,0
0,0,0,0,0,0,0,0,0,0,0,0,0,0,0,0,0,0,0,0,0,0,0,0,0,0,0,0,0,0,0
0,0,0,0,0,0,0,0,0,0,0,0,0,0,0,0,0,0,0,0,0,0,0,0,0,0,0,0,0,0,0
0,0,0,0,11,11,11,0,0,0,0,0,0,0,12,14,11,0,0,0,0,0,0,0,11,14,11,9,0,0,0
0,0,0,0,12,12,11,20,0,0,0,0,0,20,12,11,11,20,0,0,0,0,0,20,11,12,12,0,0,0,0
0,0,0,0,12,12,11,31,33,31,33,31,33,31,11,11,18,31,33,31,33,31,33,31,12,15,11,0,0,0,0
0,0,0,0,0,20,31,0,0,0,0,0,0,0,0,0,0,0,0,0,0,0,0,0,31,20,0,0,0,0,0
0,0,0,0,0,0,33,0,0,0,0,0,0,0,0,0,0,0,0,0,0,0,0,0,33,0,0,0,0,0,0
0,0,0,0,0,0,31,5,0,0,0,0,0,0,0,0,0,0,0,0,0,0,0,0,31,0,0,0,0,0,0
0,0,0,0,0,0,33,0,0,0,0,0,0,0,0,0,0,0,0,0,0,0,0,0,33,0,0,0,0,0,0
0,0,0,0,0,6,31,0,0,0,0,0,0,0,0,0,0,0,0,0,0,0,0,0,31,0,0,0,0,0,0
0,0,0,0,0,0,33,0,0,0,0,0,0,0,0,0,0,0,0,0,0,0,0,0,33,0,0,0,0,0,0
0,0,0,0,0,20,31,5,0,0,0,0,0,0,0,0,0,0,0,0,0,0,0,0,31,20,0,0,0,0,0
0,0,0,0,11,11,11,31,33,31,33,31,33,31,14,12,11,31,33,31,33,31,33,31,15,11,11,0,0,0,0
0,0,0,0,11,12,11,20,0,0,0,0,0,20,11,11,12,20,0,0,0,0,0,20,14,11,12,0,0,0,0
0,0,0,0,11,11,11,0,0,0,0,0,0,0,15,12,11,0,0,0,0,0,0,0,11,11,12,0,0,0,0
0,0,0,0,0,0,0,0,0,0,0,0,0,0,0,0,0,0,0,0,0,0,0,0,0,0,0,0,0,0,0
0,0,0,0,0,0,0,0,0,0,0,0,0,0,0,0,0,0,0,0,0,0,0,0,0,0,0,0,0,0,0
0,0,0,0,0,0,0,0,0,0,0,0,0,0,0,0,0,0,0,0,0,0,0,0,0,0,0,0,0,0,0
0,0,0,0,0,0,0,0,0,0,0,0,0,0,0,0,0,0,0,0,0,0,0,0,0,0,0,0,0,0,0
endlayer

layer
0,0,0,0,0,0,0,0,0,0,0,0,0,0,0,0,0,0,0,0,0,0,0,0,0,0,0,0,0,0,0
0,0,0,0,0,0,0,0,0,0,0,0,0,0,0,0,0,0,0,0,0,0,0,0,0,0,0,0,0,0,0
0,0,0,0,0,0,0,0,0,0,0,0,0,0,0,0,0,0,0,0,0,0,0,0,0,0,0,0,0,0,0
0,0,0,0,19,19,19,28,0,0,0,0,0,19,19,19,19,19,0,0,0,0,0,22,19,19,19,0,0,0,0
0,0,0,22,11,11,14,28,0,0,0,0,0,22,11,12,12,28,0,0,0,0,9,22,11,8,11,28,0,0,0
0,0,0,22,12,11,11,28,19,19,19,19,19,19,11,15,12,19,19,19,19,19,19,22,15,15,11,28,0,0,0
0,0,0,22,15,11,11,31,33,31,33,31,33,31,11,14,14,31,33,31,33,31,33,31,11,11,25,28,0,0,0
0,0,0,22,30,22,31,23,0,0,0,0,0,0,25,25,25,0,0,0,0,0,0,0,31,28,30,28,0,0,0
0,0,0,0,0,22,33,0,0,0,0,0,0,0,0,0,0,0,0,0,0,0,0,0,33,28,0,0,0,0,0
0,0,0,0,0,22,31,0,0,0,0,0,0,0,0,0,0,0,0,0,0,0,0,0,31,28,0,0,0,0,0
0,0,0,0,0,22,33,0,0,0,0,0,0,0,0,0,0,0,0,0,0,0,0,0,33,28,0,0,0,0,0
0,0,0,0,9,22,31,0,0,0,0,0,0,0,0,0,0,0,0,0,0,0,0,0,31,28,0,0,0,0,0
0,0,0,0,0,22,33,0,0,0,0,0,0,0,0,0,0,0,0,0,0,0,0,0,33,28,0,0,0,0,0
0,0,0,22,19,22,31,5,0,0,0,0,0,0,21,21,21,0,0,0,0,0,0,0,31,28,19,28,0,0,0
0,0,0,22,12,11,12,31,33,31,33,31,33,31,11,12,11,31,33,31,33,31,33,31,11,11,11,28,0,0,0
0,0,0,22,11,11,11,28,30,30,30,30,30,30,14,15,30,30,30,30,30,30,30,22,12,14,12,28,0,0,0
0,0,0,22,12,11,11,28,0,0,0,0,6,22,12,11,12,28,0,0,0,0,0,22,11,11,11,28,0,0,0
0,0,0,0,30,30,30,28,0,0,0,0,0,30,30,30,30,30,0,0,0,0,0,22,30,30,30,0,0,0,0
0,0,0,0,0,0,0,0,0,0,0,0,0,0,0,0,0,0,0,0,0,0,0,0,0,0,0,0,0,0,0
0,0,0,0,0,0,0,0,0,0,0,0,0,0,0,0,0,0,0,0,0,0,0,0,0,0,0,0,0,0,0
0,0,0,0,0,0,0,0,0,0,0,0,0,0,0,0,0,0,0,0,0,0,0,0,0,0,0,0,0,0,0
0,0,0,0,0,0,0,0,0,0,0,0,0,0,0,0,0,0,24,0,0,0,0,0,0,0,0,0,0,0,0
0,0,0,0,0,0,0,24,58,11,11,0,0,0,0,0,0,0,9,9,10,11,58,0,0,0,0,0,0,0,0
0,0,0,0,0,0,0,0,58,16,11,12,6,6,0,0,0,6,0,11,11,12,58,0,0,0,0,0,0,0,0
0,0,0,0,0,0,0,0,58,11,12,9,0,0,0,0,0,0,0,0,11,11,58,0,0,0,0,0,0,0,0
0,0,0,0,0,0,0,0,0,0,0,0,0,0,0,0,0,0,0,0,23,0,0,0,0,0,0,0,0,0,0
0,0,0,0,0,0,0,0,0,0,0,0,0,0,0,0,0,0,0,0,0,0,0,0,0,0,0,0,0,0,0
0,0,0,0,0,0,0,0,0,0,0,0,0,0,0,0,0,0,0,0,0,0,0,0,0,0,0,0,0,0,0
0,0,0,0,0,0,0,0,0,0,0,0,0,0,0,0,0,0,0,0,0,0,0,0,0,0,0,0,0,0,0
0,0,0,0,19,19,19,28,0,24,0,0,0,19,19,19,19,19,0,0,0,0,0,22,19,19,19,9,0,0,0
0,0,0,22,11,11,12,28,6,0,0,0,0,22,11,11,11,28,0,0,0,0,0,22,11,11,11,28,0,0,0
0,0,0,22,11,11,12,28,19,19,19,19,19,19,11,11,11,19,19,19,19,19,19,22,11,11,11,28,0,0,0
0,0,0,22,11,12,11,31,33,31,33,31,33,31,11,11,11,31,33,31,33,31,33,31,11,12,11,28,0,0,0
0,0,0,22,30,22,31,0,0,0,0,0,0,0,25,25,25,0,0,0,0,0,0,0,31,28,30,28,0,0,0
0,0,0,0,0,22,33,0,0,0,0,0,0,0,0,0,0,0,0,0,0,0,0,0,33,28,0,0,0,0,0
0,0,0,0,0,22,31,5,0,0,0,0,0,0,0,0,0,0,0,0,0,0,0,0,31,28,0,0,0,0,0
0,0,0,0,0,22,33,0,0,0,0,0,0,0,0,0,0,0,0,0,0,0,0,0,33,28,0,0,0,0,0
0,0,0,0,0,6,31,0,0,0,0,0,0,0,0,0,0,0,0,0,0,0,0,0,31,28,0,0,0,0,0
0,0,0,0,0,22,33,0,0,0,0,0,0,0,0,0,0,0,0,0,0,0,0,0,33,28,0,0,0,0,0
0,0,0,22,19,22,31,5,0,0,0,0,0,0,21,21,21,0,0,0,0,0,0,0,31,28,19,28,0,0,0
0,0,0,22,11,11,11,31,33,31,33,31,33,31,11,11,11,31,33,31,33,31,33,31,11,14,11,28,0,0,0
0,0,0,22,11,11,11,28,30,30,30,30,30,30,11,12,12,30,30,30,30,30,30,22,14,11,12,28,0,0,0
0,0,0,22,15,12,11,28,0,0,0,0,0,22,12,12,11,28,0,0,0,0,0,22,11,11,11,28,0,0,0
0,0,0,0,30,30,30,28,0,0,0,0,0,30,30,30,30,30,0,0,0,0,0,22,30,30,30,0,0,0,0
0,0,0,0,0,0,0,0,0,0,0,0,0,0,0,0,0,0,0,0,0,0,0,0,0,0,0,0,0,0,0
0,0,0,0,0,0,0,0,0,0,0,0,0,0,0,0,0,0,0,0,0,0,0,0,0,0,0,0,0,0,0
0,0,0,0,0,0,0,0,0,0,0,0,0,0,0,0,0,0,0,0,0,0,0,0,0,0,0,0,0,0,0
endlayer

layer
0,0,0,0,0,0,0,0,0,0,0,0,0,0,0,0,0,0,0,0,0,0,0,0,0,0,0,0,0,0,0
0,0,0,0,0,0,0,0,0,0,0,0,0,0,0,0,0,0,0,0,0,0,0,0,0,0,0,0,0,0,0
0,0,0,0,0,0,0,0,0,0,0,0,0,0,0,0,0,0,0,0,0,0,0,0,0,0,0,0,0,0,0
0,0,0,0,45,45,45,45,0,0,0,0,0,45,45,45,45,45,0,0,0,0,0,45,45,45,45,0,0,0,0
0,0,0,45,11,11,11,45,0,0,0,0,0,45,11,11,11,45,0,0,0,0,9,45,11,11,12,45,0,0,0
0,0,0,45,11,11,11,45,45,45,45,45,45,45,15,11,11,45,45,45,45,45,45,45,12,11,12,45,0,0,0
0,0,0,45,11,11,11,15,11,11,12,11,11,11,12,12,11,11,12,11,11,11,11,11,8,11,15,45,0,0,0
0,0,0,45,45,45,11,11,11,11,12,11,12,16,12,11,11,12,12,11,11,11,11,12,11,45,45,45,0,0,0
0,0,0,0,0,45,14,12,14,12,11,11,11,11,11,14,11,11,11,11,11,11,12,12,11,45,0,0,0,0,0
0,0,0,0,0,45,11,11,12,11,11,11,18,11,14,12,12,12,11,11,11,11,11,11,12,45,0,0,0,0,0
0,0,0,0,13,9,12,11,12,11,12,12,11,11,11,12,14,11,12,25,12,11,11,12,15,45,0,0,0,0,0
0,0,0,0,0,45,12,11,11,14,11,12,11,11,11,11,11,11,14,21,11,11,11,11,11,45,0,0,0,0,0
0,0,0,0,0,45,12,11,11,11,11,12,11,11,21,14,11,11,11,12,11,11,11,11,15,45,0,0,0,0,0
0,0,0,45,45,45,11,11,11,11,11,12,11,12,11,11,12,11,11,11,12,11,11,11,11,45,45,45,0,0,0
0,0,0,45,11,11,11,11,11,11,15,11,12,11,12,11,16,11,11,11,11,11,12,11,14,14,11,45,0,0,0
0,0,0,45,11,11,11,45,45,45,45,45,9,45,12,12,11,45,45,45,45,45,45,45,11,11,11,45,0,0,0
0,0,0,45,3,12,11,45,0,0,0,0,0,45,11,11,11,45,0,0,0,0,0,45,12,11,12,45,0,0,0
0,0,0,0,45,45,45,45,0,0,0,0,0,45,45,45,45,45,0,0,0,0,0,45,45,45,45,0,0,0,0
0,0,0,0,0,0,0,0,0,0,0,0,0,0,0,0,0,0,0,0,0,0,0,0,0,0,0,0,0,0,0
0,0,0,0,0,0,0,0,0,0,0,0,0,0,0,0,0,0,0,0,0,0,0,0,0,0,0,0,0,0,0
0,0,0,0,0,0,0,0,0,0,0,0,0,0,0,0,0,0,0,0,0,0,0,0,0,0,0,0,0,0,0
0,0,0,0,0,0,0,0,0,0,0,0,0,0,0,0,0,0,0,0,0,0,0,0,0,0,0,0,0,0,0
0,0,0,0,0,0,0,24,58,11,11,0,0,0,0,0,0,0,0,24,12,11,58,0,0,0,0,0,0,0,0
0,0,0,0,0,0,0,58,11,11,12,6,0,0,0,0,0,0,0,6,11,11,12,58,0,0,0,0,0,0,0
0,0,0,0,0,0,0,34,58,11,11,0,0,0,0,0,0,0,0,0,12,12,58,0,0,0,0,0,0,0,0
0,0,0,0,0,0,0,0,0,0,0,0,0,0,0,0,0,0,0,0,23,0,0,0,0,0,0,0,0,0,0
0,0,0,0,0,0,0,0,0,0,0,0,0,0,0,0,0,0,0,0,0,0,0,0,0,0,0,0,0,0,0
0,0,0,0,0,0,0,0,0,0,0,0,0,0,0,0,0,0,0,0,0,0,0,0,0,0,0,0,0,0,0
0,0,0,0,0,0,0,0,0,0,0,0,0,0,0,0,0,0,0,0,0,0,0,0,0,0,0,0,0,0,0
0,0,0,0,45,45,45,45,0,24,0,0,0,45,45,45,45,45,0,0,0,0,0,45,45,45,45,0,0,0,0
0,0,0,45,11,17,11,45,0,9,0,0,0,45,12,12,12,45,0,0,0,0,0,45,11,11,12,45,0,0,0
0,0,0,45,12,11,17,45,45,45,45,45,45,45,11,15,12,45,45,45,45,45,45,45,11,11,12,45,0,0,0
0,0,0,45,10,11,12,12,11,11,15,11,11,11,11,12,12,11,12,12,11,11,11,11,12,11,14,45,0,0,0
0,0,0,45,45,45,12,11,11,12,12,11,12,11,11,11,12,11,12,11,11,12,11,11,11,45,45,45,0,0,0
0,0,0,0,0,45,11,12,12,11,11,12,11,12,11,11,11,11,12,11,12,12,11,11,15,45,0,0,0,0,0
0,0,0,0,0,45,11,11,12,11,11,11,11,11,11,11,12,11,11,12,11,11,14,11,11,45,0,0,0,0,0
0,0,0,0,0,6,11,11,12,12,12,11,12,12,11,11,11,11,12,12,18,11,11,11,15,45,0,0,0,0,0
0,0,0,0,0,45,11,11,11,11,14,11,11,11,11,11,12,11,11,12,12,11,11,12,11,45,0,0,0,0,0
0,0,0,0,0,45,12,11,11,11,11,11,11,11,11,11,14,12,11,11,11,14,12,12,11,45,0,0,0,0,0
0,0,0,45,45,45,11,12,11,11,11,11,11,11,11,11,12,11,11,12,12,12,11,12,14,45,45,45,0,0,0
0,0,0,45,11,11,12,15,11,11,12,11,12,11,12,14,12,12,11,12,11,8,11,11,11,15,12,45,0,0,0
0,0,0,45,11,15,12,45,45,45,45,45,45,6,12,11,12,45,45,45,45,45,45,45,11,12,12,45,0,0,0
0,0,0,45,12,11,11,45,0,0,0,0,0,45,11,11,11,45,0,0,0,0,0,45,11,15,11,45,0,0,0
0,0,0,0,45,45,45,45,0,0,0,0,0,45,45,45,45,45,0,0,0,0,0,45,45,45,45,0,0,0,0
0,0,0,0,0,0,0,0,0,0,0,0,0,0,0,0,0,0,0,0,0,0,0,0,0,0,0,0,0,0,0
0,0,0,0,0,0,0,0,0,0,0,0,0,0,0,0,0,0,0,0,0,0,0,0,0,0,0,0,0,0,0
0,0,0,0,0,0,0,0,0,0,0,0,0,0,0,0,0,0,0,0,0,0,0,0,0,0,0,0,0,0,0
endlayer

layer
0,0,0,0,0,0,0,0,0,0,0,0,0,0,0,0,0,0,0,0,0,0,0,0,0,0,0,0,0,0,0
0,0,0,0,0,0,0,0,0,0,0,0,0,0,0,0,0,0,0,0,0,0,0,0,0,0,0,0,0,0,0
0,0,0,0,0,0,0,0,0,0,0,0,0,0,0,0,0,0,0,0,0,0,0,0,0,0,0,0,0,0,0
0,0,0,0,0,0,0,0,0,0,0,0,0,0,0,0,0,0,0,0,0,0,0,0,0,0,0,0,0,0,0
0,0,0,0,12,21,11,0,0,0,0,0,0,0,11,21,11,0,0,0,0,0,0,0,11,21,11,0,0,0,0
0,0,0,0,16,46,18,0,0,0,0,0,0,0,16,46,18,0,9,0,24,0,0,9,16,46,18,0,0,0,0
0,0,0,13,11,11,12,21,12,21,12,21,11,21,11,46,12,21,12,21,11,21,11,21,11,12,11,0,0,0,0
0,0,0,0,0,6,16,46,46,46,46,46,46,46,46,46,46,46,46,46,46,46,46,46,18,0,0,0,0,0,0
0,0,0,0,0,0,12,46,46,46,46,46,46,46,46,46,46,46,46,46,2,46,2,46,18,0,0,0,0,0,0
0,0,0,0,0,0,16,46,46,46,46,46,46,46,46,46,46,46,46,46,2,2,46,46,18,0,0,0,0,0,0
0,0,0,0,13,9,11,46,46,46,2,46,46,46,46,46,46,46,46,46,46,2,2,46,11,0,0,0,0,0,0
0,0,0,0,0,0,16,46,46,2,2,46,46,46,46,46,46,46,46,46,2,2,46,46,18,0,0,0,0,0,0
0,0,0,0,0,0,11,46,46,46,46,46,46,46,46,46,46,46,46,46,2,46,46,46,12,0,0,0,0,0,0
0,0,0,0,0,0,16,46,46,46,46,46,46,46,46,46,46,46,46,46,46,46,46,46,18,0,0,0,0,0,0
0,0,0,0,11,11,11,25,11,25,12,25,11,25,11,46,11,25,12,25,12,25,15,25,11,12,11,5,0,0,0
0,0,0,0,16,46,18,0,0,0,0,0,6,0,16,46,18,0,0,0,0,0,23,0,16,46,18,0,0,0,0
0,0,0,0,11,25,14,0,0,0,0,0,0,0,12,25,12,0,0,0,0,0,0,0,11,25,11,0,0,0,0
0,0,0,0,0,0,0,0,0,0,0,0,0,0,0,0,0,0,0,0,0,0,0,0,23,0,0,0,0,0,0
0,0,0,0,0,0,0,0,0,0,0,0,0,0,0,0,0,0,0,0,0,0,0,0,0,0,0,0,0,0,0
0,0,0,0,0,0,0,0,0,0,0,0,0,0,0,0,0,0,0,0,0,0,0,0,0,0,0,0,0,0,0
0,0,0,0,0,0,0,0,0,0,0,0,0,0,0,0,0,0,0,0,0,0,0,0,0,0,0,0,0,0,0
0,0,0,0,0,0,0,0,0,0,0,0,0,0,0,0,0,0,0,0,0,0,0,0,0,0,0,0,0,0,0
0,0,0,0,0,0,0,58,11,12,24,0,0,0,0,0,0,0,0,0,9,11,12,58,0,0,0,0,0,0,0
0,0,0,0,0,0,0,58,12,11,12,9,0,0,0,0,0,0,0,0,11,12,11,58,0,0,0,0,0,0,0
0,0,0,0,0,0,0,58,11,11,6,0,0,0,0,0,0,0,0,0,0,11,11,58,0,0,0,0,0,0,0
0,0,0,0,0,0,0,0,0,0,0,0,0,0,0,0,0,0,0,0,0,0,0,0,0,0,0,0,0,0,0
0,0,0,0,0,0,0,0,0,0,0,0,0,0,0,0,0,0,0,0,0,0,0,0,0,0,0,0,0,0,0
0,0,0,0,0,0,0,0,0,0,0,0,0,0,0,0,0,0,0,0,0,0,0,0,0,0,0,0,0,0,0
0,0,0,0,0,0,0,0,0,0,0,0,0,0,0,0,0,0,0,0,0,0,0,0,0,0,0,0,0,0,0
0,0,0,0,0,0,0,0,0,0,0,0,0,0,0,0,0,0,0,0,0,0,0,0,0,0,0,0,0,0,0
0,0,0,0,11,21,11,0,0,0,0,0,0,0,12,21,12,0,0,0,0,0,0,0,21,21,21,0,0,0,0
0,0,0,0,16,46,18,0,0,9,9,36,0,0,16,46,18,0,0,0,0,0,0,0,16,46,18,0,0,0,0
0,0,0,0,11,11,12,21,11,21,11,21,12,21,12,46,14,21,11,21,12,21,11,21,12,11,11,0,0,0,0
0,0,0,0,0,0,16,46,46,46,46,46,46,46,46,46,46,46,46,46,46,46,46,46,18,0,0,0,0,0,0
0,0,0,0,0,9,12,46,46,46,46,46,46,46,46,46,46,46,46,46,46,46,46,46,15,0,0,0,0,0,0
0,0,0,0,0,6,16,46,46,46,46,46,46,46,2,2,2,46,46,2,2,2,46,46,18,0,0,0,0,0,0
0,0,0,0,0,23,12,46,46,46,46,46,46,2,2,2,2,2,2,2,2,2,46,46,11,0,0,0,0,0,0
0,0,0,0,0,0,16,46,46,46,46,46,46,46,46,2,2,2,2,2,2,46,46,46,18,0,0,0,0,0,0
0,0,0,0,0,0,11,46,46,46,46,46,46,46,46,46,46,2,2,2,46,46,46,46,11,0,0,0,0,0,0
0,0,0,0,0,0,16,46,46,46,46,46,46,46,46,46,46,46,46,46,46,46,46,46,18,0,0,0,0,0,0
0,0,0,0,11,12,15,25,12,25,11,25,11,25,12,46,12,25,12,25,11,25,12,25,11,11,12,0,0,0,0
0,0,0,0,16,46,18,0,0,0,0,0,9,0,16,46,18,0,0,0,0,0,0,0,16,46,18,0,0,0,0
0,0,0,0,14,25,12,0,0,0,0,0,0,0,12,25,11,0,0,0,0,0,0,0,11,25,15,0,0,0,0
0,0,0,0,0,0,0,0,0,0,0,0,0,0,23,0,0,0,0,0,0,0,0,0,0,0,0,0,0,0,0
0,0,0,0,0,0,0,0,0,0,0,0,0,0,0,0,0,0,0,0,0,0,0,0,0,0,0,0,0,0,0
0,0,0,0,0,0,0,0,0,0,0,0,0,0,0,0,0,0,0,0,0,0,0,0,0,0,0,0,0,0,0
0,0,0,0,0,0,0,0,0,0,0,0,0,0,0,0,0,0,0,0,0,0,0,0,0,0,0,0,0,0,0
endlayer

layer
0,0,0,0,0,0,0,0,0,0,0,0,0,0,0,0,0,0,0,0,0,0,0,0,0,0,0,0,0,0,0
0,0,0,0,0,0,0,0,0,0,0,0,0,0,0,0,0,0,0,0,0,0,0,0,0,0,0,0,0,0,0
0,0,0,0,0,0,0,0,0,0,0,0,0,0,0,0,0,0,0,0,0,0,0,0,0,0,0,0,0,0,0
0,0,0,0,0,0,0,0,0,0,0,0,0,0,0,0,0,0,0,0,0,0,0,0,0,0,0,0,0,0,0
0,0,0,0,20,0,20,0,0,0,0,0,0,0,20,0,20,0,0,0,0,0,0,0,20,0,20,0,0,0,0
0,0,0,0,0,48,0,0,0,0,0,0,0,0,0,0,0,0,0,0,0,0,0,0,0,47,0,0,0,0,0
0,0,0,0,20,0,20,20,20,20,20,20,20,20,20,20,20,9,20,20,20,20,20,20,20,0,20,0,0,0,0
0,0,0,0,0,9,20,6,0,0,47,47,47,0,6,47,0,6,13,47,9,13,47,0,20,0,0,0,0,0,0
0,0,0,0,0,0,20,6,6,6,9,13,6,9,0,9,0,0,0,9,59,0,59,6,20,0,0,0,0,0,0
0,0,0,0,0,0,20,9,6,0,6,9,9,47,47,0,0,13,6,48,59,59,0,9,20,0,0,0,0,0,0
0,0,0,0,0,0,6,9,13,9,59,6,6,0,9,6,0,0,9,0,47,59,59,0,20,0,0,0,0,0,0
0,0,0,0,0,0,20,13,9,59,59,6,6,9,0,0,9,6,24,0,59,59,0,0,20,0,0,0,0,0,0
0,0,0,0,0,0,20,48,0,9,6,6,0,9,0,0,0,6,6,0,59,0,0,0,20,0,0,0,0,0,0
0,0,0,0,0,0,20,0,47,47,9,6,5,0,0,6,0,6,0,0,0,0,0,0,0,0,0,0,0,0,0
0,0,0,0,20,0,20,20,20,20,20,20,6,20,20,20,20,20,20,20,20,20,20,20,0,0,20,0,0,0,0
0,0,0,0,0,47,0,0,0,0,0,0,0,0,0,47,0,0,0,0,0,0,0,0,0,0,0,0,0,0,0
0,0,0,0,20,0,20,0,0,0,0,0,0,0,20,0,20,0,0,0,0,0,0,0,20,0,20,0,0,0,0
0,0,0,0,0,0,0,0,0,0,0,0,0,0,0,0,0,0,0,0,0,0,0,0,0,0,0,0,0,0,0
0,0,0,0,0,0,0,0,0,0,0,0,0,0,0,0,0,0,0,0,0,0,0,0,0,0,0,0,0,0,0
0,0,0,0,0,0,0,0,0,0,0,0,0,0,0,0,0,0,0,0,0,0,0,0,0,0,0,0,0,0,0
0,0,0,0,0,0,0,0,0,0,0,0,0,0,0,0,0,0,0,0,0,0,0,0,0,0,0,0,0,0,0
0,0,0,0,0,0,0,0,24,0,0,0,0,0,0,0,0,0,0,0,0,0,0,0,0,0,0,0,0,0,0
0,0,0,0,0,0,0,58,11,12,0,0,0,0,0,0,0,0,0,0,0,8,11,58,0,0,0,0,0,0,0
0,0,0,0,0,0,0,58,11,12,6,0,0,0,0,0,0,0,0,13,0,11,14,58,0,0,0,0,0,0,0
0,0,0,0,0,0,0,58,14,12,29,0,0,0,0,0,0,0,0,0,0,11,14,58,0,0,0,0,0,0,0
0,0,0,0,0,0,0,0,0,0,0,0,0,0,0,0,0,0,0,0,0,0,0,0,0,0,0,0,0,0,0
0,0,0,0,0,0,0,0,0,0,0,0,0,0,0,0,0,0,0,0,0,0,0,0,0,0,0,0,0,0,0
0,0,0,0,0,0,0,0,0,0,0,0,0,0,0,0,0,0,0,0,0,0,0,0,0,0,0,0,0,0,0
0,0,0,0,0,0,0,0,0,0,0,0,0,0,0,0,0,0,0,0,0,0,0,0,0,0,0,0,0,0,0
0,0,0,0,0,0,0,0,0,0,0,0,0,0,0,0,0,0,0,0,0,0,0,0,0,0,0,0,0,0,0
0,0,0,0,20,0,20,0,0,0,0,0,0,0,20,0,20,0,0,0,0,0,0,0,20,0,20,0,0,0,0
0,0,0,0,0,47,0,0,0,0,0,0,0,0,0,0,0,0,0,0,0,0,0,0,0,47,0,0,0,0,0
0,0,0,0,20,0,20,20,20,20,9,20,20,20,20,20,20,20,20,20,20,20,20,20,20,0,20,0,0,0,0
0,0,0,0,0,9,20,0,0,48,6,47,47,0,0,47,0,0,0,0,0,9,0,0,20,0,0,0,0,0,0
0,0,0,0,0,0,20,9,0,0,23,9,9,0,0,9,0,9,47,47,0,48,6,6,20,0,0,0,0,0,0
0,0,0,0,0,0,20,0,9,0,9,9,0,6,46,46,46,9,9,46,46,46,0,0,20,0,0,0,0,0,0
0,0,0,0,0,0,20,9,24,6,0,6,6,46,46,46,46,46,46,46,46,46,47,0,20,0,0,0,0,0,0
0,0,0,0,0,0,20,0,6,47,0,9,0,6,6,46,46,46,46,46,46,0,0,0,20,0,0,0,0,0,0
0,0,0,0,0,0,20,9,9,6,9,0,0,0,47,47,6,46,46,46,6,13,9,6,20,0,0,0,0,0,0
0,0,0,0,0,0,20,6,48,0,47,9,0,6,0,0,0,0,47,6,0,9,0,47,20,0,0,0,0,0,0
0,0,0,0,20,6,6,20,20,20,20,20,6,20,20,20,20,20,20,20,20,20,20,20,20,0,20,0,0,0,0
0,0,0,0,0,9,5,0,0,0,0,0,0,0,0,47,0,0,0,0,0,0,0,0,0,47,0,0,0,0,0
0,0,0,0,20,0,20,0,0,0,0,0,0,0,20,0,20,0,0,0,0,0,0,0,20,0,20,0,0,0,0
0,0,0,0,0,0,0,0,0,0,0,0,0,0,0,0,0,0,0,0,0,0,0,0,0,0,0,0,0,0,0
0,0,0,0,0,0,0,0,0,0,0,0,0,0,0,0,0,0,0,0,0,0,0,0,0,0,0,0,0,0,0
0,0,0,0,0,0,0,0,0,0,0,0,0,0,0,0,0,0,0,0,0,0,0,0,0,0,0,0,0,0,0
0,0,0,0,0,0,0,0,0,0,0,0,0,0,0,0,0,0,0,0,0,0,0,0,0,0,0,0,0,0,0
endlayer

layer
0,0,0,0,0,0,0,0,0,0,0,0,0,0,0,0,0,0,0,0,0,0,0,0,0,0,0,0,0,0,0
0,0,0,0,0,0,0,0,0,0,0,0,0,0,0,0,0,0,0,0,0,0,0,0,0,0,0,0,0,0,0
0,0,0,0,0,0,0,0,0,0,0,0,0,0,0,0,0,0,0,0,0,0,0,0,0,0,0,0,0,0,0
0,0,0,0,0,0,0,0,0,0,0,0,0,0,0,0,0,0,0,0,0,0,0,0,0,0,0,0,0,0,0
0,0,0,0,0,0,0,0,0,0,0,0,0,0,0,0,0,0,0,0,0,0,0,0,0,0,0,0,0,0,0
0,0,0,0,0,54,0,0,0,0,0,0,0,0,0,0,0,0,0,0,0,0,0,0,0,0,0,0,0,0,0
0,0,0,0,0,0,0,0,0,0,0,0,0,0,0,0,0,0,0,0,0,0,0,24,0,0,0,0,0,0,0
0,0,0,0,0,0,9,0,0,0,0,0,0,0,0,0,0,0,13,0,0,13,0,6,5,0,0,0,0,0,0
0,0,0,0,0,0,9,6,0,0,0,0,0,0,0,0,0,9,0,0,0,24,0,0,0,0,0,0,0,0,0
0,0,0,0,0,0,23,0,0,0,0,0,6,0,0,0,0,0,0,0,0,0,0,0,0,0,0,0,0,0,0
0,0,0,0,0,0,0,6,0,6,6,0,0,0,0,0,0,0,0,0,0,59,5,0,0,0,0,0,0,0,0
0,0,0,0,0,0,0,0,0,9,59,6,0,0,0,0,0,9,0,0,59,59,0,0,0,0,0,0,0,0,0
0,0,0,0,0,0,0,54,0,0,9,0,0,6,0,0,0,0,0,0,0,0,0,0,0,0,0,0,0,0,0
0,0,0,0,0,0,0,0,0,0,0,0,0,0,0,0,0,0,54,0,0,0,0,0,0,0,0,0,0,0,0
0,0,0,0,0,0,0,0,0,0,0,0,0,0,0,0,0,0,0,0,0,0,0,0,0,0,0,0,0,0,0
0,0,0,0,0,0,0,0,0,0,0,0,0,0,0,0,0,0,0,0,0,0,0,0,0,0,0,0,0,0,0
0,0,0,0,0,0,0,0,0,0,0,0,0,0,0,0,0,0,0,0,0,0,0,0,0,0,0,0,0,0,0
0,0,0,0,0,0,0,0,0,0,0,0,0,0,0,0,0,0,0,0,0,0,0,0,0,0,0,0,0,0,0
0,0,0,0,0,0,0,0,0,0,0,0,0,0,0,0,0,0,0,0,0,0,0,0,0,0,0,0,0,0,0
0,0,0,0,0,0,0,0,0,0,0,0,0,0,0,0,0,0,0,0,0,0,0,0,0,0,0,0,0,0,0
0,0,0,0,0,0,0,0,0,0,0,0,0,0,0,0,0,0,0,0,0,0,0,0,0,0,0,0,0,0,0
0,0,0,0,0,0,0,0,24,0,0,0,0,0,0,0,0,0,0,0,0,0,0,0,0,0,0,0,0,0,0
0,0,0,0,0,0,0,58,12,12,0,0,0,0,0,0,0,0,0,0,0,12,11,58,0,0,0,0,0,0,0
0,0,0,0,0,0,0,58,12,11,0,0,0,0,0,0,0,0,0,13,0,11,12,58,0,0,0,0,0,0,0
0,0,0,0,0,0,0,58,11,11,5,0,0,0,0,0,0,0,0,0,0,11,11,58,0,0,0,0,0,0,0
0,0,0,0,0,0,0,0,0,0,0,0,0,0,0,0,0,0,0,0,0,0,0,23,0,0,0,0,0,0,0
0,0,0,0,0,0,0,0,0,0,0,0,0,0,0,0,0,0,0,0,0,0,0,0,0,0,0,0,0,0,0
0,0,0,0,0,0,0,0,0,0,0,0,0,0,0,0,0,0,0,0,0,0,0,0,0,0,0,0,0,0,0
0,0,0,0,0,0,0,0,0,0,0,0,0,0,0,0,0,0,0,0,0,0,0,0,0,0,0,0,0,0,0
0,0,0,0,0,0,0,0,0,0,0,0,0,0,0,0,0,0,0,0,0,0,0,0,0,0,0,0,0,0,0
0,0,0,0,0,0,0,0,0,0,0,0,0,0,0,0,0,0,0,0,0,0,0,0,0,0,0,0,0,0,0
0,0,0,0,0,0,0,0,0,0,0,0,0,0,0,0,0,0,0,0,0,0,0,0,0,0,0,0,0,0,0
0,0,0,0,0,0,0,0,0,0,0,0,0,0,0,0,0,0,0,0,0,0,0,0,0,0,0,0,0,0,0
0,0,0,0,0,0,0,0,0,54,0,0,0,0,0,0,0,0,0,0,0,0,0,0,0,0,0,0,0,0,0
0,0,0,0,0,0,0,0,0,0,0,0,0,0,0,24,9,0,0,0,0,54,9,5,0,0,0,0,0,0,0
0,0,0,0,0,0,0,0,0,0,0,0,0,0,0,6,6,0,0,9,47,47,0,0,0,0,0,0,0,0,0
0,0,0,0,0,0,0,0,0,0,0,0,0,47,6,6,47,48,9,6,9,47,0,0,0,0,0,0,0,0,0
0,0,0,0,0,0,0,0,0,0,6,0,0,9,0,47,6,6,6,6,47,0,0,0,0,0,0,0,0,0,0
0,0,0,0,0,0,0,0,0,0,0,0,0,0,0,0,0,6,47,47,0,0,0,0,0,0,0,0,0,0,0
0,0,0,0,0,0,0,0,54,0,0,0,0,0,0,0,0,0,0,0,0,0,0,0,0,0,0,0,0,0,0
0,0,0,0,0,0,6,0,0,0,0,0,0,0,0,0,0,0,0,0,0,0,0,0,0,0,0,0,0,0,0
0,0,0,0,0,0,0,0,0,0,0,0,0,0,0,0,0,0,0,0,0,0,0,0,0,0,0,0,0,0,0
0,0,0,0,0,0,0,0,0,0,0,0,0,0,0,0,0,0,0,0,0,0,0,0,0,0,0,0,0,0,0
0,0,0,0,0,0,0,0,0,0,0,0,0,0,0,0,0,0,0,0,0,0,0,0,0,0,0,0,0,0,0
0,0,0,0,0,0,0,0,0,0,0,0,0,0,0,0,0,0,0,0,0,0,0,0,0,0,0,0,0,0,0
0,0,0,0,0,0,0,0,0,0,0,0,0,0,0,0,0,0,0,0,0,0,0,0,0,0,0,0,0,0,0
0,0,0,0,0,0,0,0,0,0,0,0,0,0,0,0,0,0,0,0,0,0,0,0,0,0,0,0,0,0,0
endlayer

layer
0,0,0,0,0,0,0,0,0,0,0,0,0,0,0,0,0,0,0,0,0,0,0,0,0,0,0,0,0,0,0
0,0,0,0,0,0,0,0,0,0,0,0,0,0,0,0,0,0,0,0,0,0,0,0,0,0,0,0,0,0,0
0,0,0,0,0,0,0,0,0,0,0,0,0,0,0,0,0,0,0,0,0,0,0,0,0,0,0,0,0,0,0
0,0,0,0,0,0,0,0,0,0,0,0,0,0,0,0,0,0,0,0,0,0,0,0,0,0,0,0,0,0,0
0,0,0,0,0,0,0,0,0,0,0,0,0,0,0,0,0,0,0,0,0,0,0,0,0,0,0,0,0,0,0
0,0,0,0,0,0,0,0,0,0,0,0,0,0,0,0,0,0,0,0,0,0,0,0,0,0,0,0,0,0,0
0,0,0,0,0,0,0,0,0,0,0,0,0,0,0,0,0,0,0,0,0,0,0,0,0,0,0,0,0,0,0
0,0,0,0,0,0,0,0,0,0,0,0,0,0,0,0,0,0,13,0,0,13,6,9,5,0,0,0,0,0,0
0,0,0,0,0,0,0,0,0,0,0,0,0,0,0,0,0,9,6,0,0,24,0,9,0,0,0,0,0,0,0
0,0,0,0,0,0,0,0,0,0,0,0,0,0,0,0,0,0,6,0,0,6,0,0,0,0,0,0,0,0,0
0,0,0,0,0,0,0,0,0,0,0,0,0,0,0,0,0,0,9,0,0,59,6,0,0,0,0,0,0,0,0
0,0,0,0,0,0,0,0,0,0,9,6,0,0,0,0,0,0,0,0,0,0,0,9,0,0,0,0,0,0,0
0,0,0,0,0,0,0,0,0,0,0,0,0,0,0,0,0,0,0,0,0,0,0,0,0,0,0,0,0,0,0
0,0,0,0,0,0,0,0,0,0,0,0,0,0,0,0,0,0,0,0,0,9,0,0,5,0,0,0,0,0,0
0,0,0,0,0,0,0,0,0,0,0,0,0,0,0,0,0,0,0,0,0,0,0,0,0,0,0,0,0,0,0
0,0,0,0,0,0,0,0,0,0,0,0,0,0,0,0,0,0,0,0,0,0,0,0,0,0,0,0,0,0,0
0,0,0,0,0,0,0,0,0,0,0,0,0,0,0,0,0,0,0,0,0,0,0,0,0,0,0,0,0,0,0
0,0,0,0,0,0,0,0,0,0,0,0,0,0,0,0,0,0,0,0,0,0,0,0,0,0,0,0,0,0,0
0,0,0,0,0,0,0,0,0,0,0,0,0,0,0,0,0,0,0,0,0,0,0,0,0,0,0,0,0,0,0
0,0,0,0,0,0,0,0,0,0,0,0,0,0,0,0,0,0,0,0,0,0,0,0,0,0,0,0,0,0,0
0,0,0,0,0,0,0,0,0,0,0,0,0,0,0,0,0,0,0,0,0,0,0,0,0,0,0,0,0,0,0
0,0,0,0,0,0,0,0,24,0,0,0,0,0,0,0,0,0,0,0,0,0,0,0,0,0,0,0,0,0,0
0,0,0,0,0,0,0,58,12,11,0,0,0,0,0,0,0,0,0,0,24,11,14,58,0,0,0,0,0,0,0
0,0,0,0,0,0,0,58,11,11,11,0,0,0,0,0,0,0,0,13,11,11,11,58,0,0,0,0,0,0,0
0,0,0,0,0,0,0,58,11,12,0,0,0,0,0,0,0,0,0,0,0,12,14,58,0,0,0,0,0,0,0
0,0,0,0,0,0,0,0,0,0,0,0,0,0,0,0,0,0,0,0,0,0,0,23,0,0,0,0,0,0,0
0,0,0,0,0,0,0,0,0,0,0,0,0,0,0,0,0,0,0,0,0,0,0,0,0,0,0,0,0,0,0
0,0,0,0,0,0,0,0,0,0,0,0,0,0,0,0,0,0,0,0,0,0,0,0,0,0,0,0,0,0,0
0,0,0,0,0,0,0,0,0,0,0,0,0,0,0,0,0,0,0,0,0,0,0,0,0,0,0,0,0,0,0
0,0,0,0,0,0,0,0,0,0,0,0,0,0,0,0,0,0,0,0,0,0,0,0,0,0,0,0,0,0,0
0,0,0,0,0,0,0,0,0,0,0,0,0,0,0,0,0,0,0,0,0,0,0,0,0,0,0,0,0,0,0
0,0,0,0,0,0,0,0,0,0,0,0,0,0,0,0,0,0,0,0,0,0,0,0,0,0,0,0,0,0,0
0,0,0,0,0,0,0,0,0,0,0,0,0,0,0,0,0,0,0,0,0,0,0,0,0,0,0,0,0,0,0
0,0,0,0,0,0,0,0,0,0,0,0,0,0,0,0,0,0,0,0,0,0,0,0,0,0,0,0,0,0,0
0,0,0,0,0,0,0,0,0,0,0,0,0,0,0,0,0,0,0,0,0,0,0,0,0,0,0,0,0,0,0
0,0,0,0,0,0,0,0,0,0,0,0,0,0,0,0,0,0,0,0,0,0,0,0,0,0,0,0,0,0,0
0,0,0,0,0,0,0,0,0,0,0,0,0,0,9,0,0,0,0,0,0,0,0,0,0,0,0,0,0,0,0
0,0,0,0,0,0,0,0,0,0,0,0,0,0,0,0,0,0,0,0,0,0,0,0,0,0,0,0,0,0,0
0,0,0,0,0,0,0,0,0,0,0,0,0,0,0,0,0,0,0,0,0,0,0,0,0,0,0,0,0,0,0
0,0,0,0,0,0,0,0,0,0,0,0,0,0,0,0,0,0,0,0,0,0,0,0,0,0,0,0,0,0,0
0,0,0,0,0,0,0,0,0,0,0,0,0,0,0,0,0,0,0,0,0,0,0,0,0,0,0,0,0,0,0
0,0,0,0,0,0,0,0,0,0,0,0,0,0,0,0,0,0,0,0,0,0,0,0,0,0,0,0,0,0,0
0,0,0,0,0,0,0,0,0,0,0,0,0,0,0,0,0,0,0,0,0,0,0,0,0,0,0,0,0,0,0
0,0,0,0,0,0,0,0,0,0,0,0,0,0,0,0,0,0,0,0,0,0,0,0,0,0,0,0,0,0,0
0,0,0,0,0,0,0,0,0,0,0,0,0,0,0,0,0,0,0,0,0,0,0,0,0,0,0,0,0,0,0
0,0,0,0,0,0,0,0,0,0,0,0,0,0,0,0,0,0,0,0,0,0,0,0,0,0,0,0,0,0,0
0,0,0,0,0,0,0,0,0,0,0,0,0,0,0,0,0,0,0,0,0,0,0,0,0,0,0,0,0,0,0
endlayer

layer
0,0,0,0,0,0,0,0,0,0,0,0,0,0,0,0,0,0,0,0,0,0,0,0,0,0,0,0,0,0,0
0,0,0,0,0,0,0,0,0,0,0,0,0,0,0,0,0,0,0,0,0,0,0,0,0,0,0,0,0,0,0
0,0,0,0,0,0,0,0,0,0,0,0,0,0,0,0,0,0,0,0,0,0,0,0,0,0,0,0,0,0,0
0,0,0,0,0,0,0,0,0,0,0,0,0,0,0,0,0,0,0,0,0,0,0,0,0,0,0,0,0,0,0
0,0,0,0,0,0,0,0,0,0,0,0,0,0,0,0,0,0,0,0,0,0,0,0,0,0,0,0,0,0,0
0,0,0,0,0,0,0,0,0,0,0,0,0,0,0,0,0,0,0,0,0,0,0,0,0,0,0,0,0,0,0
0,0,0,0,0,0,0,0,0,0,0,0,0,0,0,0,0,0,0,0,0,0,0,0,0,0,0,0,0,0,0
0,0,0,0,0,0,0,0,0,0,0,0,0,0,0,0,0,0,13,9,0,9,6,0,0,0,0,0,0,0,0
0,0,0,0,0,0,0,0,0,0,0,0,0,0,0,0,0,0,6,6,6,6,6,9,0,0,0,0,0,0,0
0,0,0,0,0,0,0,0,0,0,0,0,0,0,0,0,0,9,0,9,9,59,9,9,0,0,0,0,0,0,0
0,0,0,0,0,0,0,0,0,0,0,0,0,0,0,0,0,9,6,6,6,59,59,6,0,0,0,0,0,0,0
0,0,0,0,0,0,0,0,0,0,0,0,0,0,0,0,0,0,6,9,0,6,9,9,9,0,0,0,0,0,0
0,0,0,0,0,0,0,0,0,0,0,0,0,0,0,0,0,0,0,6,9,6,0,6,6,0,0,0,0,0,0
0,0,0,0,0,0,0,0,0,0,0,0,0,0,0,0,0,0,0,0,9,9,6,9,5,0,0,0,0,0,0
0,0,0,0,0,0,0,0,0,0,0,0,0,0,0,0,0,0,0,0,0,0,0,0,0,0,0,0,0,0,0
0,0,0,0,0,0,0,0,0,0,0,0,0,0,0,0,0,0,0,0,0,0,0,0,0,0,0,0,0,0,0
0,0,0,0,0,0,0,0,0,0,0,0,0,0,0,0,0,0,0,0,0,0,0,0,0,0,0,0,0,0,0
0,0,0,0,0,0,0,0,0,0,0,0,0,0,0,0,0,0,0,0,0,0,0,0,0,0,0,0,0,0,0
0,0,0,0,0,0,0,0,0,0,0,0,0,0,0,0,0,0,0,0,0,0,0,0,0,0,0,0,0,0,0
0,0,0,0,0,0,0,0,0,0,0,0,0,0,0,0,0,0,0,0,0,0,0,0,0,0,0,0,0,0,0
0,0,0,0,0,0,0,0,0,0,0,0,0,0,0,0,0,0,0,0,0,0,0,0,0,0,0,0,0,0,0
0,0,0,0,0,0,0,0,0,0,0,0,0,0,0,0,0,0,0,0,0,0,0,0,0,0,0,0,0,0,0
0,0,0,0,0,0,0,0,58,11,12,0,0,0,0,0,0,0,0,0,11,11,58,0,0,0,0,0,0,0,0
0,0,0,0,0,0,0,58,11,14,12,0,0,0,0,0,0,0,0,0,11,12,11,58,0,0,0,0,0,0,0
0,0,0,0,0,0,0,0,58,12,11,0,0,0,0,0,0,23,0,0,11,25,58,11,0,0,0,0,0,0,0
0,0,0,0,0,0,0,0,0,0,0,0,0,0,0,0,0,0,0,0,0,0,0,0,0,0,0,0,0,0,0
0,0,0,0,0,0,0,0,0,0,0,0,0,0,0,0,0,0,0,0,0,0,0,0,0,0,0,0,0,0,0
0,0,0,0,0,0,0,0,0,0,0,0,0,0,0,0,0,0,0,0,0,0,0,0,0,0,0,0,0,0,0
0,0,0,0,0,0,0,0,0,0,0,0,0,0,0,0,0,0,0,0,0,0,0,0,0,0,0,0,0,0,0
0,0,0,0,0,0,0,0,0,0,0,0,0,0,0,0,0,0,0,0,0,0,0,0,0,0,0,0,0,0,0
0,0,0,0,0,0,0,0,0,0,0,0,0,0,0,0,0,0,0,0,0,0,0,0,0,0,0,0,0,0,0
0,0,0,0,0,0,0,0,0,0,0,0,0,0,0,0,0,0,0,0,0,0,0,0,0,0,0,0,0,0,0
0,0,0,0,0,0,0,0,0,0,0,0,0,0,0,0,0,0,0,0,0,0,0,0,0,0,0,0,0,0,0
0,0,0,0,0,0,0,0,0,0,0,0,0,0,0,0,0,0,0,0,0,0,0,0,0,0,0,0,0,0,0
0,0,0,0,0,0,0,0,0,0,0,0,0,0,0,0,0,0,0,0,0,0,0,0,0,0,0,0,0,0,0
0,0,0,0,0,0,0,0,0,0,0,0,0,0,0,0,0,0,0,0,0,0,0,0,0,0,0,0,0,0,0
0,0,0,0,0,0,0,0,0,0,0,0,0,0,0,0,0,0,0,0,0,0,0,0,0,0,0,0,0,0,0
0,0,0,0,0,0,0,0,0,0,0,0,0,0,0,0,0,0,0,0,0,0,0,0,0,0,0,0,0,0,0
0,0,0,0,0,0,0,0,0,0,0,0,0,0,0,0,0,0,0,0,0,0,0,0,0,0,0,0,0,0,0
0,0,0,0,0,0,0,0,0,0,0,0,0,0,0,0,0,0,0,0,0,0,0,0,0,0,0,0,0,0,0
0,0,0,0,0,0,0,0,0,0,0,0,0,0,0,0,0,0,0,0,0,0,0,0,0,0,0,0,0,0,0
0,0,0,0,0,0,0,0,0,0,0,0,0,0,0,0,0,0,0,0,0,0,0,0,0,0,0,0,0,0,0
0,0,0,0,0,0,0,0,0,0,0,0,0,0,0,0,0,0,0,0,0,0,0,0,0,0,0,0,0,0,0
0,0,0,0,0,0,0,0,0,0,0,0,0,0,0,0,0,0,0,0,0,0,0,0,0,0,0,0,0,0,0
0,0,0,0,0,0,0,0,0,0,0,0,0,0,0,0,0,0,0,0,0,0,0,0,0,0,0,0,0,0,0
0,0,0,0,0,0,0,0,0,0,0,0,0,0,0,0,0,0,0,0,0,0,0,0,0,0,0,0,0,0,0
0,0,0,0,0,0,0,0,0,0,0,0,0,0,0,0,0,0,0,0,0,0,0,0,0,0,0,0,0,0,0
endlayer

layer
0,0,0,0,0,0,0,0,0,0,0,0,0,0,0,0,0,0,0,0,0,0,0,0,0,0,0,0,0,0,0
0,0,0,0,0,0,0,0,0,0,0,0,0,0,0,0,0,0,0,0,0,0,0,0,0,0,0,0,0,0,0
0,0,0,0,0,0,0,0,0,0,0,0,0,0,0,0,0,0,0,0,0,0,0,0,0,0,0,0,0,0,0
0,0,0,0,0,0,0,0,0,0,0,0,0,0,0,0,0,0,0,0,0,0,0,0,0,0,0,0,0,0,0
0,0,0,0,0,0,0,0,0,0,0,0,0,0,0,0,0,0,0,0,0,0,0,0,0,0,0,0,0,0,0
0,0,0,0,0,0,0,0,0,0,0,0,0,0,0,0,0,0,0,0,0,0,0,0,0,0,0,0,0,0,0
0,0,0,0,0,0,0,0,0,0,0,0,0,0,0,0,0,0,24,0,0,0,0,0,0,0,0,0,0,0,0
0,0,0,0,0,0,0,0,0,0,0,0,0,0,0,0,0,0,6,6,6,6,9,0,0,0,0,0,0,0,0
0,0,0,0,0,0,0,0,0,0,0,0,0,0,0,0,0,0,6,0,59,24,6,6,0,0,0,0,0,0,0
0,0,0,0,0,0,0,0,0,0,0,0,0,0,0,0,0,24,6,9,59,9,9,9,0,0,0,0,0,0,0
0,0,0,0,0,0,0,0,0,0,0,0,0,0,0,0,0,9,6,9,9,9,59,6,6,0,0,0,0,0,0
0,0,0,0,0,0,0,0,0,0,0,0,0,0,0,0,0,0,6,23,0,6,59,9,9,0,0,0,0,0,0
0,0,0,0,0,0,0,0,0,0,0,0,0,0,0,0,0,6,9,59,59,6,9,6,0,0,0,0,0,0,0
0,0,0,0,0,0,0,0,0,0,0,0,0,0,0,0,0,0,0,6,6,9,9,0,0,0,0,0,0,0,0
0,0,0,0,0,0,0,0,0,0,0,0,0,0,0,0,0,0,0,0,0,0,0,0,0,0,0,0,0,0,0
0,0,0,0,0,0,0,0,0,0,0,0,0,0,0,0,0,0,0,0,0,0,0,0,0,0,0,0,0,0,0
0,0,0,0,0,0,0,0,0,0,0,0,0,0,0,0,0,0,0,0,0,0,0,0,0,0,0,0,0,0,0
0,0,0,0,0,0,0,0,0,0,0,0,0,0,0,0,0,0,0,0,0,0,0,0,0,0,0,0,0,0,0
0,0,0,0,0,0,0,0,0,0,0,0,0,0,0,0,0,0,0,0,0,0,0,0,0,0,0,0,0,0,0
0,0,0,0,0,0,0,0,0,0,0,0,0,0,0,0,0,0,0,0,0,0,0,0,0,0,0,0,0,0,0
0,0,0,0,0,0,0,0,0,0,0,0,0,0,0,0,0,0,0,0,0,0,0,0,0,0,0,0,0,0,0
