
# Created by Ruins mod version 17.2 Ingame Parser
# authoring Player: BARTLLOW

# TEMPLATE PARAMETER SETTINGS:
#
# criterion expression specifying mod ids required to load template
# may include plus (AND), minus (AND NOT), comma (OR), and parentheses
# all required mods listed must be present; no prohibited mods can be
requiredMods=
#
# likelihood this template will be chosen relative to all others
# e.g., a weight=6 template is chosen 3X as often as one with weight=2
weight=1
#
# list of dimensions in which this template may spawn, even if generic
# one or more dimension names, separated by commas (blank = all)
dimensionsToSpawnIn=
#
# list of other biomes in which this template may spawn
# biome corresponding to directory is always assumed, listed or not
# generic templates should leave this list empty
biomesToSpawnIn=
#
# criterion expression specifying types of biome where template spawns
# this is in addition to those explicitly listed as biomesToSpawnIn
# generic templates should leave this list empty
biomeTypesToSpawnIn=
#
# list of biomes in which this template may not spawn
# takes precedence over biomeTypesToSpawnIn, but NOT biomesToSpawnIn
# should be empty if biomeTypesToSpawnIn is empty
biomesToNotSpawnIn=
#
# depth template is pushed down into the surface when built
# offset is min/max range of random additional bury depth
embed_into_distance=0
random_height_offset=0,0
#
# whitelist/blacklist of block types on which template may be built
# specify one, not both; leave the other empty (both empty = allow all)
acceptable_target_blocks=
unacceptable_target_blocks=flowing_water,water,flowing_lava,lava
#
# size of template (#layers, #rows per layer, #blocks per row)
dimensions=34,27,13
#
# max number of missing blocks allowed in surface beneath template
allowable_overhang=0
#
# depth/height limit affected by terrain leveling
# also maximum bumpiness tolerated in surface beneath template
max_leveling=2
#
# padding applied to all sides of template horizontal footprint
# expands area affected by terrain leveling (-1 = no leveling)
leveling_buffer=0
#
# do not rotate template randomly when built (1 = no rotation)
preventRotation=0
#
# treat water/lava blocks as air and protect them from rule0 (1 = yes)
preserve_water=0
preserve_lava=0
#
# minimum distance this template must have from instances of itself
uniqueMinDistance=0
#
# min/max distances this template can be from world spawn (0 = no limit)
# only applies to overworld--i.e., dimension 0
spawnMinDistance=0
spawnMaxDistance=0
#
# other template built nearby whenever this one is
# syntax: <name>;<relativeX>;<maxYdifference>;<relativeZ>[;<chance>]
# may be used more than once to specify multiple neighbors
adjoining_template=

rule1=0,100,minecraft:grass-0
rule2=0,100,minecraft:dirt-0
rule3=0,100,minecraft:planks-5
rule4=0,100,minecraft:double_stone_slab-8
rule5=0,100,minecraft:stone-6
rule6=0,100,minecraft:tallgrass-1
rule7=0,100,minecraft:leaves-12
rule8=0,100,minecraft:leaves-4
rule9=0,100,minecraft:vine-8
rule10=0,100,minecraft:red_flower-8
rule11=0,100,minecraft:oak_stairs-1
rule12=0,100,minecraft:oak_stairs-5
rule13=0,100,minecraft:oak_stairs-4
rule14=0,100,minecraft:dark_oak_door-5
rule15=0,100,minecraft:dark_oak_door-2
rule16=0,100,minecraft:red_flower-0
rule17=0,100,minecraft:stonebrick-0
rule18=0,100,minecraft:vine-1
rule19=0,100,minecraft:dark_oak_door-1
rule20=0,100,minecraft:log-1
rule21=0,100,minecraft:stone_brick_stairs-0
rule22=0,100,IInventory;minecraft:chest;minecraft:written_book#{pages:["\"When do clouds become shields?\\n\\nNow the desire is dead\\nWe sought the luscious glaciers before we revealed euphoria.\\nWhere is the aching horse, the acheronian dawn \"","\"now?\\n\\nin or in, how beauty soars on.\\nIs beauty really gentle like yearning?\\nWhat is the full end to devotedly reveal the night?\\nWhy did the kiss hie it, to usurp \"","\"the fear?\\n\\nThe gentle kiss ne\\u0027er finds a eye.\\nshimmer barely like a sandy home between terror.\\nfondness, sand, and ever need.\\nWe fought the luscious glaciers \"","\"before we heard serendipity.\\nbeauty like 20 cheeks\\nblood like 90 texts\\n\\nreveal the luscious glaciers within you, Jakob!\\nThe blood of 10 \"","\"peasants\\n9 hearts\\n\""],author:"Sigurdur",title:"We remembered to reveal."}#0#23-4
rule23=0,100,minecraft:yellow_flower-0
rule24=0,100,minecraft:light_weighted_pressure_plate-0
rule25=1,100,minecraft:redstone_torch-5
rule26=0,100,minecraft:dark_oak_door-8
rule27=0,100,IInventory;minecraft:chest;minecraft:paper#41#0#15+minecraft:paper#34#0#20+minecraft:book#1#0#26-4
rule28=0,100,minecraft:stone_slab-13
rule29=0,100,minecraft:stonebrick-3
rule30=2,100,minecraft:torch-3
rule31=0,100,minecraft:stone_brick_stairs-3
rule32=0,100,minecraft:stonebrick-1
rule33=2,100,minecraft:torch-4
rule34=0,100,minecraft:wooden_slab-8
rule35=0,100,minecraft:oak_stairs-6
rule36=0,100,minecraft:double_wooden_slab-0
rule37=0,100,minecraft:oak_stairs-7
rule38=0,100,minecraft:planks-0
rule39=0,100,minecraft:stonebrick-2
rule40=0,100,minecraft:vine-9
rule41=0,100,minecraft:fence-0
rule42=0,100,minecraft:enchanting_table-0
rule43=0,100,ChestGenHook:chests/simple_dungeon:5-4
rule44=0,100,minecraft:stained_glass_pane-3
rule45=0,100,minecraft:stained_glass_pane-4
rule46=0,100,minecraft:stone_brick_stairs-7
rule47=0,100,minecraft:stone_brick_stairs-6
rule48=2,100,minecraft:torch-2
rule49=0,100,minecraft:stone_brick_stairs-4
rule50=0,100,minecraft:stone_brick_stairs-5
rule51=0,100,minecraft:stained_glass_pane-13
rule52=0,100,minecraft:stained_glass_pane-14
rule53=0,100,minecraft:stone_brick_stairs-2
rule54=0,100,minecraft:stone_brick_stairs-1
rule55=2,100,minecraft:torch-1
rule56=0,100,minecraft:stone_slab-0
rule57=0,100,minecraft:stone_slab-8
rule58=0,100,minecraft:oak_stairs-2
rule59=0,100,minecraft:oak_stairs-3
rule60=0,100,minecraft:cobblestone_wall-0
rule61=0,100,minecraft:nether_brick_fence-0
rule62=0,100,minecraft:wooden_slab-0
rule63=0,100,minecraft:iron_bars-0
rule64=0,100,minecraft:stained_glass-3
rule65=0,100,minecraft:stone_slab-5

layer
1,1,1,1,1,1,1,1,1,1,1,1,1
2,2,2,2,2,2,2,2,2,2,2,2,2
1,2,3,3,3,3,3,3,3,3,3,2,1
1,2,3,3,3,3,3,3,3,3,3,2,1
1,2,3,3,3,3,3,3,3,3,3,2,1
2,2,3,3,3,3,3,3,3,3,3,2,2
1,2,3,3,3,3,3,3,3,3,3,2,1
1,2,3,3,3,3,3,3,3,3,3,2,1
1,2,3,3,3,3,3,3,3,3,3,2,1
2,2,3,3,3,3,3,3,3,3,3,2,2
1,2,3,3,3,3,3,3,3,3,3,2,1
1,2,3,3,3,3,3,3,3,3,3,2,1
1,2,3,3,3,3,3,3,3,3,3,2,1
2,2,3,3,3,3,3,3,3,3,3,2,2
1,2,3,3,3,3,3,3,3,3,3,2,1
1,2,3,3,3,3,3,3,3,3,3,2,1
1,2,3,3,3,3,3,3,3,3,3,2,1
2,2,3,3,3,3,3,3,3,3,3,2,2
1,1,3,3,3,3,3,3,3,3,3,1,1
1,1,1,2,2,3,3,3,2,1,1,1,1
1,1,1,1,2,3,3,3,2,4,4,4,4
1,1,1,1,2,3,3,3,3,5,5,5,5
1,1,1,1,2,3,3,3,2,4,4,4,4
1,1,1,1,2,3,3,3,2,1,1,1,1
1,1,2,2,1,2,2,2,1,2,2,1,1
1,1,1,1,2,1,1,1,2,1,1,1,1
1,1,1,1,2,1,1,1,2,1,1,1,1
endlayer

layer
6,6,6,0,0,6,6,6,9,7,8,7,6
4,4,4,4,4,4,4,4,4,4,4,4,4
10,4,0,0,0,0,0,0,0,0,0,4,8
6,4,0,11,11,11,0,11,11,11,0,4,8
6,4,0,0,0,0,0,0,0,0,0,4,8
4,4,0,11,11,11,0,11,11,11,0,4,4
0,4,0,0,0,0,0,0,0,0,0,4,8
6,4,0,11,11,11,0,11,11,11,0,4,8
6,4,0,0,0,0,0,0,0,0,0,4,8
4,4,0,11,11,11,0,11,11,11,0,4,4
6,4,0,0,0,0,0,0,0,0,0,4,8
6,4,0,11,11,11,0,11,11,11,0,4,8
6,4,0,0,0,0,0,0,0,0,0,4,8
4,4,0,11,11,11,0,11,11,11,0,4,4
6,4,0,0,0,0,0,0,0,0,0,4,8
6,4,0,0,0,0,0,0,0,0,0,4,8
6,4,12,0,0,0,0,0,0,0,12,4,7
4,4,13,0,0,0,0,0,0,0,13,4,4
6,0,4,4,0,15,0,14,0,4,4,6,6
0,0,6,0,17,0,17,0,17,8,16,6,10
0,6,0,0,17,0,17,0,17,18,0,0,0
0,0,6,6,17,21,20,0,19,0,0,0,0
0,10,6,6,17,0,17,22,17,0,0,0,0
0,0,6,0,17,17,17,0,17,8,0,0,6
0,6,4,4,6,17,17,17,16,4,4,16,6
0,0,6,0,4,6,6,0,4,0,6,6,6
0,0,0,6,4,6,6,6,4,6,6,23,6
endlayer

layer
0,0,0,0,0,0,0,0,9,9,9,7,0
4,17,17,17,17,17,17,17,17,17,17,17,4
0,17,0,0,0,0,0,0,0,0,0,17,18
0,17,0,0,0,0,0,0,0,0,0,17,18
0,17,0,0,0,0,0,0,0,0,0,17,8
4,17,0,0,0,0,0,0,0,0,0,17,4
0,17,0,0,0,0,0,0,0,0,0,17,18
0,17,0,0,0,0,0,0,0,0,0,17,18
0,17,0,0,0,0,0,0,0,0,0,17,18
4,17,0,0,0,0,0,0,0,0,0,17,4
0,17,0,0,0,0,0,0,0,0,0,17,18
0,17,0,0,0,0,0,0,0,0,0,17,8
0,17,0,0,0,0,0,0,0,0,0,17,0
4,17,0,0,0,0,0,0,0,0,0,17,4
0,17,0,0,0,0,0,0,0,0,0,17,8
0,17,0,0,0,0,0,0,0,0,0,17,18
0,17,0,0,0,0,0,0,0,0,24,17,18
4,17,25,0,0,0,0,0,0,0,25,17,4
0,0,4,4,0,26,0,26,0,4,4,0,0
0,0,0,0,17,0,17,0,17,7,0,0,0
0,0,0,0,17,0,17,0,17,18,0,0,0
0,0,0,0,17,0,20,0,26,0,0,0,0
0,0,0,0,17,21,17,27,17,0,0,0,0
0,0,0,0,17,17,17,0,17,8,0,0,0
0,0,4,4,0,17,17,17,0,4,4,0,0
0,0,0,0,4,0,0,0,4,0,0,0,0
0,0,0,0,4,0,0,0,4,0,0,0,0
endlayer

layer
0,0,0,0,0,0,0,0,9,9,9,7,0
4,17,17,17,17,17,17,17,17,17,17,17,4
0,17,0,0,0,0,0,0,0,0,0,17,0
0,17,0,0,0,0,0,0,0,0,0,17,0
0,17,0,0,0,0,0,0,0,0,0,17,18
4,17,0,0,0,0,0,0,0,0,0,17,4
0,17,0,0,0,0,0,0,0,0,0,17,18
0,17,0,0,0,0,0,0,0,0,0,17,18
0,17,0,0,0,0,0,0,0,0,0,17,18
4,17,0,0,0,0,0,0,0,0,0,17,4
0,17,0,0,0,0,0,0,0,0,0,17,18
0,17,0,0,0,0,0,0,0,0,0,17,0
0,17,0,0,0,0,0,0,0,0,0,17,0
4,17,0,0,0,0,0,0,0,0,0,17,4
0,17,0,0,0,0,0,0,0,0,0,17,8
0,17,0,0,0,0,0,0,0,0,0,17,18
0,17,0,0,0,0,0,0,0,0,0,17,18
4,17,0,0,0,0,0,0,0,0,0,17,4
0,0,4,4,0,0,0,0,0,4,4,0,0
0,0,0,0,17,17,17,17,17,18,0,0,0
0,0,0,0,17,0,17,28,17,18,0,0,0
0,0,0,0,17,30,20,28,29,0,0,0,0
0,0,0,0,17,0,31,28,17,0,0,0,0
0,0,0,0,17,17,17,17,17,7,0,0,0
0,0,4,4,0,17,17,17,0,4,4,0,0
0,0,0,0,4,0,0,0,4,0,0,0,0
0,0,0,0,4,0,0,0,4,0,0,0,0
endlayer

layer
0,0,0,0,0,0,0,0,0,9,9,9,0
4,17,17,17,17,17,17,17,17,17,17,17,4
0,17,0,0,0,0,0,0,0,0,0,17,0
0,17,33,0,0,0,0,0,0,0,30,32,0
0,17,0,0,0,0,0,0,0,0,0,17,18
4,17,0,0,0,0,0,0,0,0,0,17,4
0,17,0,0,0,0,0,0,0,0,0,17,18
0,17,33,0,0,0,0,0,0,0,30,17,18
0,17,0,0,0,0,0,0,0,0,0,17,18
4,17,0,0,0,0,0,0,0,0,0,17,4
0,17,0,0,0,0,0,0,0,0,0,17,18
0,17,33,0,0,0,0,0,0,0,30,17,0
0,17,0,0,0,0,0,0,0,0,0,17,0
4,17,0,0,0,0,0,0,0,0,0,17,4
0,17,0,0,0,0,0,0,0,0,0,17,18
0,17,33,0,0,0,0,0,0,0,30,17,0
0,17,0,0,0,0,0,0,0,0,0,17,18
4,17,0,0,0,34,34,34,0,0,0,17,4
0,0,4,4,37,36,36,36,35,4,4,0,0
0,0,0,0,17,17,17,17,32,0,0,0,0
0,0,0,0,17,12,38,38,17,18,0,0,0
0,0,0,0,17,0,20,38,17,0,0,0,0
0,0,0,0,17,0,0,31,17,0,0,0,0
0,0,0,0,17,38,38,38,39,0,0,0,0
0,0,4,4,0,17,17,17,0,4,4,0,0
0,0,0,0,4,0,0,0,4,0,0,0,0
0,0,0,0,4,0,0,0,4,0,0,0,0
endlayer

layer
0,0,0,0,0,0,0,0,0,9,9,9,0
4,17,17,17,17,17,17,17,17,17,17,17,4
0,17,0,0,0,0,0,0,0,0,0,17,0
0,17,0,0,0,0,0,0,0,0,0,17,0
0,17,0,0,0,0,0,0,0,0,0,17,0
4,17,0,0,0,0,0,0,0,0,0,17,4
0,17,0,0,0,0,0,0,0,0,0,17,18
0,17,0,0,0,0,0,0,0,0,0,17,18
0,17,0,0,0,0,0,0,0,0,0,17,18
4,17,0,0,0,0,0,0,0,0,0,17,4
0,17,0,0,0,0,0,0,0,0,0,17,18
0,17,0,0,0,0,0,0,0,0,0,32,0
0,17,0,0,0,0,0,0,0,0,0,17,0
4,17,0,0,0,0,0,0,0,0,0,17,4
0,17,0,0,0,0,0,0,0,0,0,17,0
0,17,0,0,0,0,0,0,0,0,0,17,0
0,17,0,0,0,0,0,0,0,0,0,17,40
4,17,0,0,0,41,42,41,0,0,0,17,4
0,0,4,4,41,41,0,41,41,4,4,0,0
0,0,0,0,17,0,0,0,17,0,0,0,0
0,0,0,0,17,0,0,0,39,0,0,0,0
0,0,0,0,17,21,20,0,17,0,0,0,0
0,0,0,0,17,0,0,0,17,0,0,0,0
0,0,0,0,17,43,43,0,17,0,0,0,0
0,0,4,4,0,17,17,17,0,4,4,0,0
0,0,0,0,4,0,0,0,4,0,0,0,0
0,0,0,0,4,0,0,0,4,0,0,0,0
endlayer

layer
0,0,0,0,0,0,0,0,0,9,9,0,0
4,17,17,17,17,17,17,17,17,17,17,17,4
0,17,0,0,0,0,0,0,0,0,0,17,0
0,44,0,0,0,0,0,0,0,0,0,44,0
0,17,0,0,0,0,0,0,0,0,0,17,0
4,17,0,0,0,0,0,0,0,0,0,17,4
0,17,0,0,0,0,0,0,0,0,0,17,18
0,44,0,0,0,0,0,0,0,0,0,44,0
0,17,0,0,0,0,0,0,0,0,0,39,0
4,17,0,0,0,0,0,0,0,0,0,17,4
0,17,0,0,0,0,0,0,0,0,0,17,0
0,44,0,0,0,0,0,0,0,0,0,44,0
0,17,0,0,0,0,0,0,0,0,0,17,0
4,17,0,0,0,0,0,0,0,0,0,17,4
0,17,0,0,0,0,0,0,0,0,0,39,0
0,44,0,0,0,0,0,0,0,0,0,44,0
0,17,0,0,0,0,0,0,0,0,0,17,0
4,17,0,0,0,0,0,0,0,0,0,17,4
0,0,4,4,41,0,0,0,41,4,4,0,0
0,0,0,0,17,0,0,0,17,0,0,0,0
0,0,0,0,17,0,0,0,17,0,0,0,0
0,0,0,0,17,0,20,0,17,0,0,0,0
0,0,0,0,17,21,0,0,17,0,0,0,0
0,0,0,0,17,43,43,0,17,0,0,0,0
0,0,4,4,0,17,17,17,0,4,4,0,0
0,0,0,0,4,0,0,0,4,0,0,0,0
0,0,0,0,4,0,0,0,4,0,0,0,0
endlayer

layer
0,0,0,0,0,0,0,0,0,9,9,0,0
4,17,17,17,17,44,45,44,17,17,17,17,4
0,17,0,0,0,0,0,0,0,0,0,17,0
0,44,0,0,0,0,0,0,0,0,0,44,0
0,17,0,0,0,0,0,0,0,0,0,17,0
4,17,0,0,0,0,0,0,0,0,0,17,4
0,17,0,0,0,0,0,0,0,0,0,17,18
0,44,0,0,0,0,0,0,0,0,0,44,0
0,17,0,0,0,0,0,0,0,0,0,17,0
4,17,0,0,0,0,0,0,0,0,0,17,4
0,17,0,0,0,0,0,0,0,0,0,17,0
0,44,0,0,0,0,0,0,0,0,0,44,0
0,17,0,0,0,0,0,0,0,0,0,17,0
4,17,0,0,0,0,0,0,0,0,0,17,4
0,17,0,0,0,0,0,0,0,0,0,17,0
0,44,0,0,0,0,0,0,0,0,0,44,0
0,17,0,0,0,0,0,0,0,0,0,17,0
4,17,47,0,0,0,0,0,0,0,46,17,4
0,0,4,4,41,0,0,0,41,4,4,0,0
0,0,0,0,17,0,0,0,17,0,0,0,0
0,0,0,0,17,0,48,0,17,0,0,0,0
0,0,0,0,17,0,20,0,17,0,0,0,0
0,0,0,0,17,0,31,0,39,0,0,0,0
0,0,0,0,17,50,50,49,17,0,0,0,0
0,0,4,4,0,17,17,17,0,4,4,0,0
0,0,0,0,4,0,0,0,4,0,0,0,0
0,0,0,0,4,0,0,0,4,0,0,0,0
endlayer

layer
0,0,0,0,0,0,0,0,0,0,0,0,0
4,17,17,17,17,51,52,51,17,17,17,17,4
0,17,0,0,0,0,0,0,0,0,0,17,0
0,44,0,0,0,0,0,0,0,0,0,44,0
0,17,0,0,0,0,0,0,0,0,0,39,0
4,17,0,0,0,0,0,0,0,0,0,17,4
0,17,0,0,0,0,0,0,0,0,0,39,0
0,44,0,0,0,0,0,0,0,0,0,44,0
0,17,0,0,0,0,0,0,0,0,0,17,0
4,17,0,0,0,0,0,0,0,0,0,17,4
0,17,0,0,0,0,0,0,0,0,0,17,0
0,44,0,0,0,0,0,0,0,0,0,44,0
0,17,0,0,0,0,0,0,0,0,0,17,0
4,17,0,0,0,0,0,0,0,0,0,17,4
0,17,0,0,0,0,0,0,0,0,0,17,0
0,44,0,0,0,0,0,0,0,0,0,44,0
0,17,0,0,0,0,0,0,0,0,0,17,0
4,17,17,0,0,0,0,0,0,0,17,17,4
0,0,31,4,13,13,13,13,13,4,53,0,0
0,0,0,0,17,17,17,17,17,0,0,0,0
0,0,0,0,17,0,0,0,17,0,0,0,0
0,0,0,0,17,0,20,0,17,0,0,0,0
0,0,0,0,17,0,0,31,39,0,0,0,0
0,0,0,0,17,17,17,17,17,0,0,0,0
0,0,31,4,0,17,17,17,0,4,53,0,0
0,0,0,0,4,0,0,0,4,0,0,0,0
0,0,0,0,54,0,0,0,54,0,0,0,0
endlayer

layer
0,0,0,0,0,0,0,0,0,0,0,0,0
4,17,17,17,17,44,45,44,17,17,17,17,4
0,17,0,0,0,0,0,0,0,0,0,17,0
0,17,0,0,0,0,0,0,0,0,0,17,0
0,17,0,0,0,0,48,0,0,0,0,17,0
4,17,0,0,0,30,5,33,0,0,0,17,4
0,17,0,0,0,0,55,0,0,0,0,17,0
0,17,0,0,0,0,0,0,0,0,0,17,0
0,17,0,0,0,0,48,0,0,0,0,17,0
4,17,0,0,0,30,5,33,0,0,0,17,4
0,17,0,0,0,0,55,0,0,0,0,17,0
0,17,0,0,0,0,0,0,0,0,0,17,0
0,17,0,0,0,0,48,0,0,0,0,17,0
4,17,0,0,0,30,5,33,0,0,0,17,4
0,17,0,0,0,0,55,0,0,0,0,17,0
0,17,0,0,0,0,0,0,0,0,0,17,0
0,17,0,0,0,0,0,0,0,0,0,32,0
4,17,17,0,0,0,0,0,0,0,17,17,4
0,0,0,4,0,0,0,0,0,4,0,0,0
0,0,0,0,17,17,17,17,17,0,0,0,0
0,0,0,0,17,38,38,38,17,0,0,0,0
0,0,0,0,17,12,20,54,17,0,0,0,0
0,0,0,0,17,0,0,0,17,0,0,0,0
0,0,0,0,17,17,17,17,17,0,0,0,0
0,0,0,4,0,17,17,17,0,4,0,0,0
0,0,0,0,4,0,0,0,4,0,0,0,0
0,0,0,0,0,0,0,0,0,0,0,0,0
endlayer

layer
0,4,0,0,0,0,0,0,0,0,0,4,0
4,4,17,17,17,51,52,51,17,17,17,4,4
56,4,0,0,0,0,0,0,0,0,0,4,56
56,4,0,0,0,0,0,0,0,0,0,4,56
56,4,0,0,0,0,0,0,0,0,0,4,56
4,4,47,0,0,0,41,0,0,0,46,4,4
56,4,0,0,0,0,0,0,0,0,0,4,56
56,4,0,0,0,0,0,0,0,0,0,4,56
56,4,0,0,0,0,0,0,0,0,0,4,56
4,4,47,0,0,0,41,0,0,0,46,4,4
56,4,0,0,0,0,0,0,0,0,0,4,56
56,4,0,0,0,0,0,0,0,0,0,4,56
56,4,0,0,0,0,0,0,0,0,0,4,56
4,4,47,0,0,0,41,0,0,0,46,4,4
56,4,0,0,0,0,0,0,0,0,0,4,56
56,4,0,0,0,0,0,0,0,0,0,4,56
56,4,0,0,0,0,0,0,0,0,0,4,56
4,4,17,0,0,0,0,0,0,0,17,4,4
0,4,57,4,0,0,0,0,0,4,57,4,0
0,0,0,0,17,17,17,17,17,0,0,0,0
0,0,0,0,17,17,17,54,17,0,0,0,0
0,0,0,0,17,17,20,0,17,0,0,0,0
0,0,0,0,17,0,0,0,17,0,0,0,0
0,0,0,0,17,17,17,17,17,8,0,0,0
0,0,0,4,0,17,17,17,0,4,0,0,0
0,0,0,0,4,0,0,0,4,0,0,0,0
0,0,0,0,0,0,0,0,0,0,0,0,0
endlayer

layer
0,56,4,0,0,0,0,0,0,0,4,56,0
4,17,17,17,17,44,45,44,17,17,17,17,4
0,59,35,0,0,0,0,0,0,0,37,58,0
0,59,35,0,0,0,0,0,0,0,37,58,0
0,59,35,0,0,0,0,0,0,0,37,58,0
31,17,17,47,0,0,41,0,0,46,17,17,53
0,59,35,0,0,0,0,0,0,0,37,58,0
0,59,35,0,0,0,0,0,0,0,37,58,0
0,59,35,0,0,0,0,0,0,0,37,58,0
31,17,17,47,0,0,41,0,0,46,17,17,53
0,59,35,0,0,0,0,0,0,0,37,58,0
0,59,35,0,0,0,0,0,0,0,37,58,0
0,59,35,0,0,0,0,0,0,0,37,58,0
31,17,17,47,0,0,41,0,0,46,17,17,53
0,59,35,0,0,0,0,0,0,0,37,58,0
0,59,35,0,0,0,0,0,0,0,37,58,0
0,59,35,0,0,0,0,0,0,0,37,58,0
31,17,17,47,0,0,0,0,0,46,17,17,53
0,56,4,4,0,48,0,48,0,4,4,56,0
0,0,0,0,17,17,17,17,17,0,0,0,0
0,0,0,0,17,17,53,0,17,0,0,0,0
0,0,0,0,17,17,20,0,32,0,0,0,0
0,0,0,0,17,0,55,0,17,0,0,0,0
0,0,0,0,17,17,17,17,17,8,0,0,0
0,0,0,4,0,17,17,17,0,4,0,0,0
0,0,0,0,4,0,0,0,4,0,0,0,0
0,0,0,0,0,0,0,0,0,0,0,0,0
endlayer

layer
0,0,56,4,0,0,0,0,0,4,56,0,0
4,31,17,17,17,17,52,17,17,17,17,53,4
0,0,59,35,0,0,0,0,0,37,58,0,0
0,0,59,35,0,0,0,0,0,37,58,0,0
0,0,59,35,0,0,0,0,0,37,58,0,0
0,31,17,17,47,0,41,0,46,17,17,53,0
0,0,59,35,0,0,0,0,0,37,58,0,0
0,0,59,35,0,0,0,0,0,37,58,0,0
0,0,59,35,0,0,0,0,0,37,58,0,0
0,31,17,17,47,0,41,0,46,17,17,53,0
0,0,59,35,0,0,0,0,0,37,58,0,0
0,0,59,35,0,0,0,0,0,37,58,0,0
0,0,59,35,0,0,0,0,0,37,58,0,0
0,31,17,17,47,0,41,0,46,17,17,53,0
0,0,59,35,0,0,0,0,0,37,58,0,0
0,0,59,35,0,0,0,0,0,37,58,0,0
0,0,59,35,0,0,0,0,0,37,58,0,0
0,31,17,17,47,0,0,0,46,17,17,53,0
0,0,56,4,0,48,0,48,0,4,56,0,0
0,0,0,0,17,17,17,17,17,0,0,0,0
0,0,0,0,17,53,0,0,17,0,0,0,0
0,0,0,0,17,17,20,0,17,0,0,0,0
0,0,0,0,17,0,0,0,32,0,0,0,0
0,0,0,0,17,17,17,17,17,8,0,0,0
0,0,0,4,0,17,17,17,0,4,0,0,0
0,0,0,0,4,0,0,0,4,0,0,0,0
0,0,0,0,0,0,0,0,0,0,0,0,0
endlayer

layer
0,0,0,56,4,0,0,0,4,56,0,0,0
60,0,31,17,17,17,17,17,17,17,53,0,60
0,0,0,59,35,0,0,0,37,58,0,0,0
0,0,0,59,35,0,0,0,37,58,0,0,0
0,0,0,59,35,0,0,0,37,58,0,0,0
0,0,31,17,17,47,41,46,17,17,53,0,0
0,0,0,59,35,0,0,0,37,58,0,0,0
0,0,0,59,35,0,0,0,37,58,0,0,0
0,0,0,59,35,0,0,0,37,58,0,0,0
0,0,31,17,17,47,41,46,17,17,53,0,0
0,0,0,59,35,0,0,0,37,58,0,0,0
0,0,0,59,35,0,0,0,37,58,0,0,0
0,0,0,59,35,0,0,0,37,58,0,0,0
0,0,31,17,17,47,41,46,17,17,53,0,0
0,0,0,59,35,0,0,0,37,58,0,0,0
0,0,0,59,35,0,0,0,37,58,0,0,0
0,0,0,59,35,0,0,0,37,58,0,0,0
0,0,31,17,17,47,0,46,17,17,53,0,0
0,0,0,4,0,0,0,0,0,4,0,0,0
0,0,0,0,17,17,17,17,39,0,0,0,0
0,0,0,0,17,0,0,0,17,0,0,0,0
0,0,0,0,17,21,20,0,17,0,0,0,0
0,0,0,0,17,47,0,0,17,8,0,0,0
0,0,0,0,17,17,17,17,17,8,0,0,0
0,0,0,4,0,17,17,17,0,4,0,0,0
0,0,0,0,4,0,0,0,4,0,0,0,0
0,0,0,0,0,0,0,0,0,0,0,0,0
endlayer

layer
0,0,0,0,56,4,0,4,56,0,0,0,0
60,0,0,31,17,17,17,17,17,53,0,0,60
0,0,0,0,59,35,0,37,58,0,0,0,0
0,0,0,0,59,35,0,37,58,0,0,0,0
0,0,0,0,59,35,0,37,58,0,0,0,0
0,0,0,31,17,17,17,17,17,53,0,0,0
0,0,0,0,59,35,0,37,58,0,0,0,0
0,0,0,0,59,35,0,37,58,0,0,0,0
0,0,0,0,59,35,0,37,58,0,0,0,0
0,0,0,31,17,17,17,17,17,53,0,0,0
0,0,0,0,59,35,0,37,58,0,0,0,0
0,0,0,0,59,35,0,37,58,0,0,0,0
0,0,0,0,59,35,0,37,58,0,0,0,0
0,0,0,31,17,17,17,17,17,53,0,0,0
0,0,0,0,59,35,0,37,58,0,0,0,0
0,0,0,0,59,35,0,37,58,0,0,0,0
0,0,0,0,59,35,0,37,58,0,0,0,0
0,0,0,31,17,17,17,17,17,53,0,0,0
0,0,0,31,4,0,0,0,4,53,0,0,0
0,0,0,0,17,17,17,17,17,0,0,0,0
0,0,0,0,17,0,0,0,17,0,0,0,0
0,0,0,0,17,0,20,0,17,0,0,0,0
0,0,0,0,17,21,47,0,17,0,0,0,0
0,0,0,0,17,17,17,17,8,0,0,0,0
0,0,0,31,4,54,54,54,4,53,0,0,0
0,0,0,0,54,0,0,0,54,0,0,0,0
0,0,0,0,0,0,0,0,0,0,0,0,0
endlayer

layer
0,0,0,0,0,56,4,56,0,0,0,0,0
61,0,0,0,31,17,17,17,53,0,0,0,61
0,0,0,0,0,59,38,58,0,0,0,0,0
0,0,0,0,0,59,38,58,0,0,0,0,0
0,0,0,0,0,59,38,58,0,0,0,0,0
0,0,0,0,31,17,17,17,53,0,0,0,0
0,0,0,0,0,59,38,58,0,0,0,0,0
0,0,0,0,0,59,38,58,0,0,0,0,0
0,0,0,0,0,59,38,58,0,0,0,0,0
0,0,0,0,31,17,17,17,53,0,0,0,0
0,0,0,0,0,59,38,58,0,0,0,0,0
0,0,0,0,0,59,38,58,0,0,0,0,0
0,0,0,0,0,59,38,58,0,0,0,0,0
0,0,0,0,31,17,17,17,53,0,0,0,0
0,0,0,0,0,59,38,58,0,0,0,0,0
0,0,0,0,0,59,38,58,0,0,0,0,0
0,0,0,0,0,59,38,58,0,0,0,0,0
0,0,0,0,31,17,17,17,53,0,0,0,0
0,0,0,0,4,59,0,58,4,0,0,0,0
0,0,0,0,17,17,17,17,17,0,0,0,0
0,0,0,46,17,0,48,0,17,47,0,0,0
0,0,0,46,17,0,20,0,17,47,0,0,0
0,0,0,46,17,0,31,47,17,47,0,0,0
0,0,0,0,17,17,17,17,17,0,0,0,0
0,0,0,0,4,0,0,0,4,0,0,0,0
0,0,0,0,0,0,0,0,0,0,0,0,0
0,0,0,0,0,0,0,0,0,0,0,0,0
endlayer

layer
0,0,0,0,0,0,56,0,0,0,0,0,0
61,0,0,0,0,31,4,53,0,0,0,0,61
0,0,0,0,0,0,62,0,0,0,0,0,0
0,0,0,0,0,0,62,0,0,0,0,0,0
0,0,0,0,0,0,62,0,0,0,0,0,0
0,0,0,0,0,31,17,53,0,0,0,0,0
0,0,0,0,0,0,62,0,0,0,0,0,0
0,0,0,0,0,0,62,0,0,0,0,0,0
0,0,0,0,0,0,62,0,0,0,0,0,0
0,0,0,0,0,31,17,53,0,0,0,0,0
0,0,0,0,0,0,62,0,0,0,0,0,0
0,0,0,0,0,0,62,0,0,0,0,0,0
0,0,0,0,0,0,62,0,0,0,0,0,0
0,0,0,0,0,31,17,53,0,0,0,0,0
0,0,0,0,0,0,62,0,0,0,0,0,0
0,0,0,0,0,0,62,0,0,0,0,0,0
0,0,0,0,0,0,62,0,0,0,0,0,0
0,0,0,0,0,31,17,53,0,0,0,0,0
0,0,0,0,4,0,62,0,4,0,0,0,0
0,0,0,0,17,17,17,17,17,0,0,0,0
0,0,0,63,64,0,0,0,64,63,0,0,0
0,0,0,0,64,0,20,49,64,0,0,0,0
0,0,0,63,64,0,0,31,64,63,0,0,0
0,0,0,0,17,17,17,17,17,0,0,0,0
0,0,0,0,4,0,0,0,4,0,0,0,0
0,0,0,0,0,0,0,0,0,0,0,0,0
0,0,0,0,0,0,0,0,0,0,0,0,0
endlayer

layer
0,0,0,0,0,0,0,0,0,0,0,0,0
0,0,0,0,0,0,4,0,0,0,0,0,0
0,0,0,0,0,0,0,0,0,0,0,0,0
0,0,0,0,0,0,0,0,0,0,0,0,0
0,0,0,0,0,0,0,0,0,0,0,0,0
0,0,0,0,0,0,65,0,0,0,0,0,0
0,0,0,0,0,0,0,0,0,0,0,0,0
0,0,0,0,0,0,0,0,0,0,0,0,0
0,0,0,0,0,0,0,0,0,0,0,0,0
0,0,0,0,0,0,65,0,0,0,0,0,0
0,0,0,0,0,0,0,0,0,0,0,0,0
0,0,0,0,0,0,0,0,0,0,0,0,0
0,0,0,0,0,0,0,0,0,0,0,0,0
0,0,0,0,0,0,65,0,0,0,0,0,0
0,0,0,0,0,0,0,0,0,0,0,0,0
0,0,0,0,0,0,0,0,0,0,0,0,0
0,0,0,0,0,0,0,0,0,0,0,0,0
0,0,0,0,0,0,65,0,0,0,0,0,0
0,0,0,0,4,0,0,0,4,0,0,0,0
0,0,0,0,17,17,17,17,17,0,0,0,0
0,0,0,63,64,0,0,49,64,63,0,0,0
0,0,0,0,64,0,20,54,64,0,0,0,0
0,0,0,63,64,0,0,0,64,63,0,0,0
0,0,0,0,17,17,17,17,17,0,0,0,0
0,0,0,0,4,0,0,0,4,0,0,0,0
0,0,0,0,0,0,0,0,0,0,0,0,0
0,0,0,0,0,0,0,0,0,0,0,0,0
endlayer

layer
0,0,0,0,0,0,0,0,0,0,0,0,0
0,0,0,0,0,0,60,0,0,0,0,0,0
0,0,0,0,0,0,0,0,0,0,0,0,0
0,0,0,0,0,0,0,0,0,0,0,0,0
0,0,0,0,0,0,0,0,0,0,0,0,0
0,0,0,0,0,0,0,0,0,0,0,0,0
0,0,0,0,0,0,0,0,0,0,0,0,0
0,0,0,0,0,0,0,0,0,0,0,0,0
0,0,0,0,0,0,0,0,0,0,0,0,0
0,0,0,0,0,0,0,0,0,0,0,0,0
0,0,0,0,0,0,0,0,0,0,0,0,0
0,0,0,0,0,0,0,0,0,0,0,0,0
0,0,0,0,0,0,0,0,0,0,0,0,0
0,0,0,0,0,0,0,0,0,0,0,0,0
0,0,0,0,0,0,0,0,0,0,0,0,0
0,0,0,0,0,0,0,0,0,0,0,0,0
0,0,0,0,0,0,0,0,0,0,0,0,0
0,0,0,0,0,0,0,0,0,0,0,0,0
0,0,0,0,4,0,0,0,4,0,0,0,0
0,0,0,0,17,17,17,17,39,0,0,0,0
0,0,0,63,64,0,46,54,64,63,0,0,0
0,0,0,0,64,0,20,0,64,0,0,0,0
0,0,0,63,64,0,0,0,64,63,0,0,0
0,0,0,0,17,17,17,17,17,0,0,0,0
0,0,0,0,4,0,0,0,4,0,0,0,0
0,0,0,0,0,0,0,0,0,0,0,0,0
0,0,0,0,0,0,0,0,0,0,0,0,0
endlayer

layer
0,0,0,0,0,0,0,0,0,0,0,0,0
0,0,0,0,0,0,60,0,0,0,0,0,0
0,0,0,0,0,0,0,0,0,0,0,0,0
0,0,0,0,0,0,0,0,0,0,0,0,0
0,0,0,0,0,0,0,0,0,0,0,0,0
0,0,0,0,0,0,0,0,0,0,0,0,0
0,0,0,0,0,0,0,0,0,0,0,0,0
0,0,0,0,0,0,0,0,0,0,0,0,0
0,0,0,0,0,0,0,0,0,0,0,0,0
0,0,0,0,0,0,0,0,0,0,0,0,0
0,0,0,0,0,0,0,0,0,0,0,0,0
0,0,0,0,0,0,0,0,0,0,0,0,0
0,0,0,0,0,0,0,0,0,0,0,0,0
0,0,0,0,0,0,0,0,0,0,0,0,0
0,0,0,0,0,0,0,0,0,0,0,0,0
0,0,0,0,0,0,0,0,0,0,0,0,0
0,0,0,0,0,0,0,0,0,0,0,0,0
0,0,0,0,0,0,0,0,0,0,0,0,0
0,0,0,0,4,0,0,0,4,0,0,0,0
0,0,0,0,17,17,17,17,17,0,0,0,0
0,0,0,31,17,46,53,0,17,53,0,0,0
0,0,0,0,64,0,20,0,64,0,0,0,0
0,0,0,31,17,0,55,0,17,53,0,0,0
0,0,0,0,17,17,17,17,17,0,0,0,0
0,0,0,0,4,0,0,0,4,0,0,0,0
0,0,0,0,0,0,0,0,0,0,0,0,0
0,0,0,0,0,0,0,0,0,0,0,0,0
endlayer

layer
0,0,0,0,0,0,0,0,0,0,0,0,0
0,0,0,0,0,0,61,0,0,0,0,0,0
0,0,0,0,0,0,0,0,0,0,0,0,0
0,0,0,0,0,0,0,0,0,0,0,0,0
0,0,0,0,0,0,0,0,0,0,0,0,0
0,0,0,0,0,0,0,0,0,0,0,0,0
0,0,0,0,0,0,0,0,0,0,0,0,0
0,0,0,0,0,0,0,0,0,0,0,0,0
0,0,0,0,0,0,0,0,0,0,0,0,0
0,0,0,0,0,0,0,0,0,0,0,0,0
0,0,0,0,0,0,0,0,0,0,0,0,0
0,0,0,0,0,0,0,0,0,0,0,0,0
0,0,0,0,0,0,0,0,0,0,0,0,0
0,0,0,0,0,0,0,0,0,0,0,0,0
0,0,0,0,0,0,0,0,0,0,0,0,0
0,0,0,0,0,0,0,0,0,0,0,0,0
0,0,0,0,0,0,0,0,0,0,0,0,0
0,0,0,0,0,0,0,0,0,0,0,0,0
0,0,0,0,4,0,0,0,4,0,0,0,0
0,0,0,0,17,17,17,17,17,0,0,0,0
0,0,0,0,17,53,0,0,17,0,0,0,0
0,0,0,31,17,50,20,0,17,53,0,0,0
0,0,0,0,17,0,0,0,17,0,0,0,0
0,0,0,0,17,17,17,17,17,0,0,0,0
0,0,0,0,4,0,0,0,4,0,0,0,0
0,0,0,0,0,0,0,0,0,0,0,0,0
0,0,0,0,0,0,0,0,0,0,0,0,0
endlayer

layer
0,0,0,0,0,0,0,0,0,0,0,0,0
0,0,0,0,0,0,61,0,0,0,0,0,0
0,0,0,0,0,0,0,0,0,0,0,0,0
0,0,0,0,0,0,0,0,0,0,0,0,0
0,0,0,0,0,0,0,0,0,0,0,0,0
0,0,0,0,0,0,0,0,0,0,0,0,0
0,0,0,0,0,0,0,0,0,0,0,0,0
0,0,0,0,0,0,0,0,0,0,0,0,0
0,0,0,0,0,0,0,0,0,0,0,0,0
0,0,0,0,0,0,0,0,0,0,0,0,0
0,0,0,0,0,0,0,0,0,0,0,0,0
0,0,0,0,0,0,0,0,0,0,0,0,0
0,0,0,0,0,0,0,0,0,0,0,0,0
0,0,0,0,0,0,0,0,0,0,0,0,0
0,0,0,0,0,0,0,0,0,0,0,0,0
0,0,0,0,0,0,0,0,0,0,0,0,0
0,0,0,0,0,0,0,0,0,0,0,0,0
0,0,0,0,0,0,0,0,0,0,0,0,0
0,0,0,0,21,0,0,0,21,0,0,0,0
0,0,0,0,4,17,17,17,4,0,0,0,0
0,0,0,0,17,0,0,0,17,0,0,0,0
0,0,0,0,17,21,20,0,17,0,0,0,0
0,0,0,0,17,50,0,0,17,0,0,0,0
0,0,0,0,4,17,17,17,4,0,0,0,0
0,0,0,0,54,0,0,0,54,0,0,0,0
0,0,0,0,0,0,0,0,0,0,0,0,0
0,0,0,0,0,0,0,0,0,0,0,0,0
endlayer

layer
0,0,0,0,0,0,0,0,0,0,0,0,0
0,0,0,0,0,0,0,0,0,0,0,0,0
0,0,0,0,0,0,0,0,0,0,0,0,0
0,0,0,0,0,0,0,0,0,0,0,0,0
0,0,0,0,0,0,0,0,0,0,0,0,0
0,0,0,0,0,0,0,0,0,0,0,0,0
0,0,0,0,0,0,0,0,0,0,0,0,0
0,0,0,0,0,0,0,0,0,0,0,0,0
0,0,0,0,0,0,0,0,0,0,0,0,0
0,0,0,0,0,0,0,0,0,0,0,0,0
0,0,0,0,0,0,0,0,0,0,0,0,0
0,0,0,0,0,0,0,0,0,0,0,0,0
0,0,0,0,0,0,0,0,0,0,0,0,0
0,0,0,0,0,0,0,0,0,0,0,0,0
0,0,0,0,0,0,0,0,0,0,0,0,0
0,0,0,0,0,0,0,0,0,0,0,0,0
0,0,0,0,0,0,0,0,0,0,0,0,0
0,0,0,0,0,0,0,0,0,0,0,0,0
0,0,0,0,0,0,0,0,0,0,0,0,0
0,0,0,0,4,17,17,17,4,0,0,0,0
0,0,0,0,17,0,48,0,17,0,0,0,0
0,0,0,0,17,0,20,0,17,0,0,0,0
0,0,0,0,17,21,47,0,17,0,0,0,0
0,0,0,0,4,17,17,17,4,0,0,0,0
0,0,0,0,0,0,0,0,0,0,0,0,0
0,0,0,0,0,0,0,0,0,0,0,0,0
0,0,0,0,0,0,0,0,0,0,0,0,0
endlayer

layer
0,0,0,0,0,0,0,0,0,0,0,0,0
0,0,0,0,0,0,0,0,0,0,0,0,0
0,0,0,0,0,0,0,0,0,0,0,0,0
0,0,0,0,0,0,0,0,0,0,0,0,0
0,0,0,0,0,0,0,0,0,0,0,0,0
0,0,0,0,0,0,0,0,0,0,0,0,0
0,0,0,0,0,0,0,0,0,0,0,0,0
0,0,0,0,0,0,0,0,0,0,0,0,0
0,0,0,0,0,0,0,0,0,0,0,0,0
0,0,0,0,0,0,0,0,0,0,0,0,0
0,0,0,0,0,0,0,0,0,0,0,0,0
0,0,0,0,0,0,0,0,0,0,0,0,0
0,0,0,0,0,0,0,0,0,0,0,0,0
0,0,0,0,0,0,0,0,0,0,0,0,0
0,0,0,0,0,0,0,0,0,0,0,0,0
0,0,0,0,0,0,0,0,0,0,0,0,0
0,0,0,0,0,0,0,0,0,0,0,0,0
0,0,0,0,0,0,0,0,0,0,0,0,0
0,0,0,0,0,0,0,0,0,0,0,0,0
0,0,0,0,4,17,17,17,4,0,0,0,0
0,0,0,0,17,0,0,0,17,0,0,0,0
0,0,0,0,17,0,20,0,17,0,0,0,0
0,0,0,0,17,0,31,47,17,0,0,0,0
0,0,0,0,4,17,17,17,4,0,0,0,0
0,0,0,0,0,0,0,0,0,0,0,0,0
0,0,0,0,0,0,0,0,0,0,0,0,0
0,0,0,0,0,0,0,0,0,0,0,0,0
endlayer

layer
0,0,0,0,0,0,0,0,0,0,0,0,0
0,0,0,0,0,0,0,0,0,0,0,0,0
0,0,0,0,0,0,0,0,0,0,0,0,0
0,0,0,0,0,0,0,0,0,0,0,0,0
0,0,0,0,0,0,0,0,0,0,0,0,0
0,0,0,0,0,0,0,0,0,0,0,0,0
0,0,0,0,0,0,0,0,0,0,0,0,0
0,0,0,0,0,0,0,0,0,0,0,0,0
0,0,0,0,0,0,0,0,0,0,0,0,0
0,0,0,0,0,0,0,0,0,0,0,0,0
0,0,0,0,0,0,0,0,0,0,0,0,0
0,0,0,0,0,0,0,0,0,0,0,0,0
0,0,0,0,0,0,0,0,0,0,0,0,0
0,0,0,0,0,0,0,0,0,0,0,0,0
0,0,0,0,0,0,0,0,0,0,0,0,0
0,0,0,0,0,0,0,0,0,0,0,0,0
0,0,0,0,0,0,0,0,0,0,0,0,0
0,0,0,0,0,0,0,0,0,0,0,0,0
0,0,0,0,0,0,0,0,0,0,0,0,0
0,0,0,0,4,17,17,17,4,0,0,0,0
0,0,0,0,17,0,0,0,17,0,0,0,0
0,0,0,0,17,0,20,49,17,0,0,0,0
0,0,0,0,17,0,0,31,39,0,0,0,0
0,0,0,0,4,17,17,17,4,0,0,0,0
0,0,0,0,0,0,0,0,0,0,0,0,0
0,0,0,0,0,0,0,0,0,0,0,0,0
0,0,0,0,0,0,0,0,0,0,0,0,0
endlayer

layer
0,0,0,0,0,0,0,0,0,0,0,0,0
0,0,0,0,0,0,0,0,0,0,0,0,0
0,0,0,0,0,0,0,0,0,0,0,0,0
0,0,0,0,0,0,0,0,0,0,0,0,0
0,0,0,0,0,0,0,0,0,0,0,0,0
0,0,0,0,0,0,0,0,0,0,0,0,0
0,0,0,0,0,0,0,0,0,0,0,0,0
0,0,0,0,0,0,0,0,0,0,0,0,0
0,0,0,0,0,0,0,0,0,0,0,0,0
0,0,0,0,0,0,0,0,0,0,0,0,0
0,0,0,0,0,0,0,0,0,0,0,0,0
0,0,0,0,0,0,0,0,0,0,0,0,0
0,0,0,0,0,0,0,0,0,0,0,0,0
0,0,0,0,0,0,0,0,0,0,0,0,0
0,0,0,0,0,0,0,0,0,0,0,0,0
0,0,0,0,0,0,0,0,0,0,0,0,0
0,0,0,0,0,0,0,0,0,0,0,0,0
0,0,0,0,0,0,0,0,0,0,0,0,0
0,0,0,0,0,0,0,0,0,0,0,0,0
0,0,0,0,4,17,17,17,4,0,0,0,0
0,0,0,0,17,0,0,49,17,0,0,0,0
0,0,0,0,17,0,20,54,17,0,0,0,0
0,0,0,0,17,0,0,0,17,0,0,0,0
0,0,0,0,4,17,17,17,4,0,0,0,0
0,0,0,0,0,0,0,0,0,0,0,0,0
0,0,0,0,0,0,0,0,0,0,0,0,0
0,0,0,0,0,0,0,0,0,0,0,0,0
endlayer

layer
0,0,0,0,0,0,0,0,0,0,0,0,0
0,0,0,0,0,0,0,0,0,0,0,0,0
0,0,0,0,0,0,0,0,0,0,0,0,0
0,0,0,0,0,0,0,0,0,0,0,0,0
0,0,0,0,0,0,0,0,0,0,0,0,0
0,0,0,0,0,0,0,0,0,0,0,0,0
0,0,0,0,0,0,0,0,0,0,0,0,0
0,0,0,0,0,0,0,0,0,0,0,0,0
0,0,0,0,0,0,0,0,0,0,0,0,0
0,0,0,0,0,0,0,0,0,0,0,0,0
0,0,0,0,0,0,0,0,0,0,0,0,0
0,0,0,0,0,0,0,0,0,0,0,0,0
0,0,0,0,0,0,0,0,0,0,0,0,0
0,0,0,0,0,0,0,0,0,0,0,0,0
0,0,0,0,0,0,0,0,0,0,0,0,0
0,0,0,0,0,0,0,0,0,0,0,0,0
0,0,0,0,0,0,0,0,0,0,0,0,0
0,0,0,0,0,0,0,0,0,0,0,0,0
0,0,0,0,0,0,0,0,0,0,0,0,0
0,0,0,0,4,17,17,17,4,0,0,0,0
0,0,0,0,17,28,46,54,17,0,0,0,0
0,0,0,0,17,28,20,0,17,0,0,0,0
0,0,0,0,17,28,55,0,17,0,0,0,0
0,0,0,0,4,17,17,17,4,0,0,0,0
0,0,0,0,0,0,0,0,0,0,0,0,0
0,0,0,0,0,0,0,0,0,0,0,0,0
0,0,0,0,0,0,0,0,0,0,0,0,0
endlayer

layer
0,0,0,0,0,0,0,0,0,0,0,0,0
0,0,0,0,0,0,0,0,0,0,0,0,0
0,0,0,0,0,0,0,0,0,0,0,0,0
0,0,0,0,0,0,0,0,0,0,0,0,0
0,0,0,0,0,0,0,0,0,0,0,0,0
0,0,0,0,0,0,0,0,0,0,0,0,0
0,0,0,0,0,0,0,0,0,0,0,0,0
0,0,0,0,0,0,0,0,0,0,0,0,0
0,0,0,0,0,0,0,0,0,0,0,0,0
0,0,0,0,0,0,0,0,0,0,0,0,0
0,0,0,0,0,0,0,0,0,0,0,0,0
0,0,0,0,0,0,0,0,0,0,0,0,0
0,0,0,0,0,0,0,0,0,0,0,0,0
0,0,0,0,0,0,0,0,0,0,0,0,0
0,0,0,0,0,0,0,0,0,0,0,0,0
0,0,0,0,0,0,0,0,0,0,0,0,0
0,0,0,0,0,0,0,0,0,0,0,0,0
0,0,0,0,0,0,0,0,0,0,0,0,0
0,0,0,0,0,0,0,0,0,0,0,0,0
0,0,0,0,4,4,4,4,4,0,0,0,0
0,0,0,0,4,38,53,0,4,0,0,0,0
0,0,0,0,4,38,38,0,4,0,0,0,0
0,0,0,0,4,38,35,0,4,0,0,0,0
0,0,0,0,4,4,4,4,4,0,0,0,0
0,0,0,0,0,0,0,0,0,0,0,0,0
0,0,0,0,0,0,0,0,0,0,0,0,0
0,0,0,0,0,0,0,0,0,0,0,0,0
endlayer

layer
0,0,0,0,0,0,0,0,0,0,0,0,0
0,0,0,0,0,0,0,0,0,0,0,0,0
0,0,0,0,0,0,0,0,0,0,0,0,0
0,0,0,0,0,0,0,0,0,0,0,0,0
0,0,0,0,0,0,0,0,0,0,0,0,0
0,0,0,0,0,0,0,0,0,0,0,0,0
0,0,0,0,0,0,0,0,0,0,0,0,0
0,0,0,0,0,0,0,0,0,0,0,0,0
0,0,0,0,0,0,0,0,0,0,0,0,0
0,0,0,0,0,0,0,0,0,0,0,0,0
0,0,0,0,0,0,0,0,0,0,0,0,0
0,0,0,0,0,0,0,0,0,0,0,0,0
0,0,0,0,0,0,0,0,0,0,0,0,0
0,0,0,0,0,0,0,0,0,0,0,0,0
0,0,0,0,0,0,0,0,0,0,0,0,0
0,0,0,0,0,0,0,0,0,0,0,0,0
0,0,0,0,0,0,0,0,0,0,0,0,0
0,0,0,0,0,0,0,0,0,0,0,0,0
0,0,0,0,0,0,0,0,0,0,0,0,0
0,0,0,0,4,21,4,21,4,0,0,0,0
0,0,0,0,31,0,0,0,53,0,0,0,0
0,0,0,0,4,0,0,0,4,0,0,0,0
0,0,0,0,31,0,0,0,53,0,0,0,0
0,0,0,0,4,54,4,54,4,0,0,0,0
0,0,0,0,0,0,0,0,0,0,0,0,0
0,0,0,0,0,0,0,0,0,0,0,0,0
0,0,0,0,0,0,0,0,0,0,0,0,0
endlayer

layer
0,0,0,0,0,0,0,0,0,0,0,0,0
0,0,0,0,0,0,0,0,0,0,0,0,0
0,0,0,0,0,0,0,0,0,0,0,0,0
0,0,0,0,0,0,0,0,0,0,0,0,0
0,0,0,0,0,0,0,0,0,0,0,0,0
0,0,0,0,0,0,0,0,0,0,0,0,0
0,0,0,0,0,0,0,0,0,0,0,0,0
0,0,0,0,0,0,0,0,0,0,0,0,0
0,0,0,0,0,0,0,0,0,0,0,0,0
0,0,0,0,0,0,0,0,0,0,0,0,0
0,0,0,0,0,0,0,0,0,0,0,0,0
0,0,0,0,0,0,0,0,0,0,0,0,0
0,0,0,0,0,0,0,0,0,0,0,0,0
0,0,0,0,0,0,0,0,0,0,0,0,0
0,0,0,0,0,0,0,0,0,0,0,0,0
0,0,0,0,0,0,0,0,0,0,0,0,0
0,0,0,0,0,0,0,0,0,0,0,0,0
0,0,0,0,0,0,0,0,0,0,0,0,0
0,0,0,0,0,0,0,0,0,0,0,0,0
0,0,0,0,4,0,0,0,4,0,0,0,0
0,0,0,0,0,0,0,0,0,0,0,0,0
0,0,0,0,0,0,0,0,0,0,0,0,0
0,0,0,0,0,0,0,0,0,0,0,0,0
0,0,0,0,4,0,0,0,4,0,0,0,0
0,0,0,0,0,0,0,0,0,0,0,0,0
0,0,0,0,0,0,0,0,0,0,0,0,0
0,0,0,0,0,0,0,0,0,0,0,0,0
endlayer

layer
0,0,0,0,0,0,0,0,0,0,0,0,0
0,0,0,0,0,0,0,0,0,0,0,0,0
0,0,0,0,0,0,0,0,0,0,0,0,0
0,0,0,0,0,0,0,0,0,0,0,0,0
0,0,0,0,0,0,0,0,0,0,0,0,0
0,0,0,0,0,0,0,0,0,0,0,0,0
0,0,0,0,0,0,0,0,0,0,0,0,0
0,0,0,0,0,0,0,0,0,0,0,0,0
0,0,0,0,0,0,0,0,0,0,0,0,0
0,0,0,0,0,0,0,0,0,0,0,0,0
0,0,0,0,0,0,0,0,0,0,0,0,0
0,0,0,0,0,0,0,0,0,0,0,0,0
0,0,0,0,0,0,0,0,0,0,0,0,0
0,0,0,0,0,0,0,0,0,0,0,0,0
0,0,0,0,0,0,0,0,0,0,0,0,0
0,0,0,0,0,0,0,0,0,0,0,0,0
0,0,0,0,0,0,0,0,0,0,0,0,0
0,0,0,0,0,0,0,0,0,0,0,0,0
0,0,0,0,0,0,0,0,0,0,0,0,0
0,0,0,0,60,0,0,0,60,0,0,0,0
0,0,0,0,0,0,0,0,0,0,0,0,0
0,0,0,0,0,0,0,0,0,0,0,0,0
0,0,0,0,0,0,0,0,0,0,0,0,0
0,0,0,0,60,0,0,0,60,0,0,0,0
0,0,0,0,0,0,0,0,0,0,0,0,0
0,0,0,0,0,0,0,0,0,0,0,0,0
0,0,0,0,0,0,0,0,0,0,0,0,0
endlayer

layer
0,0,0,0,0,0,0,0,0,0,0,0,0
0,0,0,0,0,0,0,0,0,0,0,0,0
0,0,0,0,0,0,0,0,0,0,0,0,0
0,0,0,0,0,0,0,0,0,0,0,0,0
0,0,0,0,0,0,0,0,0,0,0,0,0
0,0,0,0,0,0,0,0,0,0,0,0,0
0,0,0,0,0,0,0,0,0,0,0,0,0
0,0,0,0,0,0,0,0,0,0,0,0,0
0,0,0,0,0,0,0,0,0,0,0,0,0
0,0,0,0,0,0,0,0,0,0,0,0,0
0,0,0,0,0,0,0,0,0,0,0,0,0
0,0,0,0,0,0,0,0,0,0,0,0,0
0,0,0,0,0,0,0,0,0,0,0,0,0
0,0,0,0,0,0,0,0,0,0,0,0,0
0,0,0,0,0,0,0,0,0,0,0,0,0
0,0,0,0,0,0,0,0,0,0,0,0,0
0,0,0,0,0,0,0,0,0,0,0,0,0
0,0,0,0,0,0,0,0,0,0,0,0,0
0,0,0,0,0,0,0,0,0,0,0,0,0
0,0,0,0,60,0,0,0,60,0,0,0,0
0,0,0,0,0,0,0,0,0,0,0,0,0
0,0,0,0,0,0,0,0,0,0,0,0,0
0,0,0,0,0,0,0,0,0,0,0,0,0
0,0,0,0,60,0,0,0,60,0,0,0,0
0,0,0,0,0,0,0,0,0,0,0,0,0
0,0,0,0,0,0,0,0,0,0,0,0,0
0,0,0,0,0,0,0,0,0,0,0,0,0
endlayer

layer
0,0,0,0,0,0,0,0,0,0,0,0,0
0,0,0,0,0,0,0,0,0,0,0,0,0
0,0,0,0,0,0,0,0,0,0,0,0,0
0,0,0,0,0,0,0,0,0,0,0,0,0
0,0,0,0,0,0,0,0,0,0,0,0,0
0,0,0,0,0,0,0,0,0,0,0,0,0
0,0,0,0,0,0,0,0,0,0,0,0,0
0,0,0,0,0,0,0,0,0,0,0,0,0
0,0,0,0,0,0,0,0,0,0,0,0,0
0,0,0,0,0,0,0,0,0,0,0,0,0
0,0,0,0,0,0,0,0,0,0,0,0,0
0,0,0,0,0,0,0,0,0,0,0,0,0
0,0,0,0,0,0,0,0,0,0,0,0,0
0,0,0,0,0,0,0,0,0,0,0,0,0
0,0,0,0,0,0,0,0,0,0,0,0,0
0,0,0,0,0,0,0,0,0,0,0,0,0
0,0,0,0,0,0,0,0,0,0,0,0,0
0,0,0,0,0,0,0,0,0,0,0,0,0
0,0,0,0,0,0,0,0,0,0,0,0,0
0,0,0,0,61,0,0,0,61,0,0,0,0
0,0,0,0,0,0,0,0,0,0,0,0,0
0,0,0,0,0,0,0,0,0,0,0,0,0
0,0,0,0,0,0,0,0,0,0,0,0,0
0,0,0,0,61,0,0,0,61,0,0,0,0
0,0,0,0,0,0,0,0,0,0,0,0,0
0,0,0,0,0,0,0,0,0,0,0,0,0
0,0,0,0,0,0,0,0,0,0,0,0,0
endlayer

layer
0,0,0,0,0,0,0,0,0,0,0,0,0
0,0,0,0,0,0,0,0,0,0,0,0,0
0,0,0,0,0,0,0,0,0,0,0,0,0
0,0,0,0,0,0,0,0,0,0,0,0,0
0,0,0,0,0,0,0,0,0,0,0,0,0
0,0,0,0,0,0,0,0,0,0,0,0,0
0,0,0,0,0,0,0,0,0,0,0,0,0
0,0,0,0,0,0,0,0,0,0,0,0,0
0,0,0,0,0,0,0,0,0,0,0,0,0
0,0,0,0,0,0,0,0,0,0,0,0,0
0,0,0,0,0,0,0,0,0,0,0,0,0
0,0,0,0,0,0,0,0,0,0,0,0,0
0,0,0,0,0,0,0,0,0,0,0,0,0
0,0,0,0,0,0,0,0,0,0,0,0,0
0,0,0,0,0,0,0,0,0,0,0,0,0
0,0,0,0,0,0,0,0,0,0,0,0,0
0,0,0,0,0,0,0,0,0,0,0,0,0
0,0,0,0,0,0,0,0,0,0,0,0,0
0,0,0,0,0,0,0,0,0,0,0,0,0
0,0,0,0,61,0,0,0,61,0,0,0,0
0,0,0,0,0,0,0,0,0,0,0,0,0
0,0,0,0,0,0,0,0,0,0,0,0,0
0,0,0,0,0,0,0,0,0,0,0,0,0
0,0,0,0,61,0,0,0,61,0,0,0,0
0,0,0,0,0,0,0,0,0,0,0,0,0
0,0,0,0,0,0,0,0,0,0,0,0,0
0,0,0,0,0,0,0,0,0,0,0,0,0
endlayer

