
# Created by Ruins mod version 17.2 Ingame Parser
# authoring Player: BARTLLOW

# TEMPLATE PARAMETER SETTINGS:
#
# criterion expression specifying mod ids required to load template
# may include plus (AND), minus (AND NOT), comma (OR), and parentheses
# all required mods listed must be present; no prohibited mods can be
requiredMods=
#
# likelihood this template will be chosen relative to all others
# e.g., a weight=6 template is chosen 3X as often as one with weight=2
weight=1
#
# list of dimensions in which this template may spawn, even if generic
# one or more dimension names, separated by commas (blank = all)
dimensionsToSpawnIn=
#
# list of other biomes in which this template may spawn
# biome corresponding to directory is always assumed, listed or not
# generic templates should leave this list empty
biomesToSpawnIn=
#
# criterion expression specifying types of biome where template spawns
# this is in addition to those explicitly listed as biomesToSpawnIn
# generic templates should leave this list empty
biomeTypesToSpawnIn=
#
# list of biomes in which this template may not spawn
# takes precedence over biomeTypesToSpawnIn, but NOT biomesToSpawnIn
# should be empty if biomeTypesToSpawnIn is empty
biomesToNotSpawnIn=
#
# depth template is pushed down into the surface when built
# offset is min/max range of random additional bury depth
embed_into_distance=9
random_height_offset=0,0
#
# whitelist/blacklist of block types on which template may be built
# specify one, not both; leave the other empty (both empty = allow all)
acceptable_target_blocks=
unacceptable_target_blocks=flowing_water,water,flowing_lava,lava,Natura:Cloud,red_mushroom_block,brown_mushroom_block,planks,cobblestone,end_stone,obsidian,purpur_block,iron_bars,purpur_slab,purpur_pillar,netherrack,soul_sand,quartz_ore
#
# size of template (#layers, #rows per layer, #blocks per row)
dimensions=14,16,26
#
# max number of missing blocks allowed in surface beneath template
allowable_overhang=0
#
# depth/height limit affected by terrain leveling
# also maximum bumpiness tolerated in surface beneath template
max_leveling=0
#
# padding applied to all sides of template horizontal footprint
# expands area affected by terrain leveling (-1 = no leveling)
leveling_buffer=0
#
# do not rotate template randomly when built (1 = no rotation)
preventRotation=0
#
# treat water/lava blocks as air and protect them from rule0 (1 = yes)
preserve_water=0
preserve_lava=0
#
# minimum distance this template must have from instances of itself
uniqueMinDistance=0
#
# min/max distances this template can be from world spawn (0 = no limit)
# only applies to overworld--i.e., dimension 0
spawnMinDistance=0
spawnMaxDistance=0
#
# other template built nearby whenever this one is
# syntax: <name>;<relativeX>;<maxYdifference>;<relativeZ>[;<chance>]
# may be used more than once to specify multiple neighbors
adjoining_template=

rule1=0,100,preserveBlock
rule2=0,100,minecraft:stone-0
rule3=0,100,minecraft:iron_ore-0
rule4=0,100,minecraft:coal_ore-0
rule5=0,100,immersiveengineering:wooden_decoration-0
rule6=0,100,minecraft:vine-2
rule7=0,100,immersiveengineering:wooden_device0-0
rule8=0,100,industrialrenewal:buffer_stop_rail-2
rule9=0,100,industrialrenewal:normal_rail-0
rule10=0,100,industrialrenewal:normal_rail-5
rule11=0,100,minecraft:vine-8
rule12=0,100,minecraft:gravel-0
rule13=0,100,rustic:iron_lantern-3
rule14=0,100,immersiveengineering:ore-2
rule15=0,100,rustic:iron_lantern-0
rule16=0,100,minecraft:vine-4
rule17=0,100,industrialrenewal:buffer_stop_rail-1
rule18=0,100,industrialrenewal:normal_rail-1
rule19=0,100,minecraft:vine-1
rule20=0,100,industrialrenewal:normal_rail-7
rule21=0,100,minecraft:lever-5
rule22=0,100,immersiveengineering:ore-0
rule23=0,100,minecraft:dirt-0
rule24=0,100,rustic:iron_lantern-5
rule25=0,100,minecraft:grass-0
rule26=0,100,minecraft:vine-6
rule27=0,100,minecraft:coal_block-0
rule28=0,100,industrialrenewal:normal_rail-9
rule29=0,100,minecraft:lever-6
rule30=0,100,industrialrenewal:buffer_stop_rail-3
rule31=0,100,minecraft:vine-12
rule32=0,100,rustic:iron_lantern-1
rule33=0,100,immersiveengineering:treated_wood-2
rule34=0,100,minecraft:vine-10

layer
1,1,1,1,1,1,1,1,1,1,1,1,1,1,1,1,1,1,1,1,1,1,1,1,1,1
1,1,1,1,1,1,1,1,1,1,1,1,1,1,1,1,1,1,1,1,1,1,1,1,1,1
1,1,1,1,1,1,1,1,1,1,1,1,1,1,1,1,1,1,1,1,1,1,1,1,1,1
1,1,1,1,1,1,1,1,1,1,1,1,1,1,1,1,1,1,1,1,1,1,1,1,1,1
1,1,1,1,1,1,1,1,1,1,1,1,1,1,1,1,1,1,1,1,1,1,1,1,1,1
1,1,1,1,1,1,1,1,1,1,1,1,1,1,1,1,1,1,1,1,1,1,1,1,1,1
1,1,1,1,1,1,1,1,1,1,1,1,1,1,1,1,1,1,1,1,1,2,2,1,1,1
1,1,1,1,1,1,1,1,1,1,1,1,0,0,0,2,2,2,2,2,2,2,2,2,2,2
1,1,1,1,1,1,1,1,1,1,1,1,2,2,2,2,2,2,2,2,2,2,2,2,2,2
1,1,1,1,1,1,1,1,1,1,1,1,2,2,2,2,2,2,2,2,2,2,2,2,2,1
1,1,1,1,1,1,1,1,1,1,1,1,2,2,2,2,2,2,2,2,2,3,3,2,2,2
1,1,1,1,1,1,1,1,1,1,1,1,0,2,2,2,2,2,2,2,2,2,2,2,2,1
1,1,1,1,1,1,1,1,1,1,1,1,0,2,2,2,1,1,1,1,1,1,1,1,1,1
1,1,1,1,1,1,1,1,1,1,1,1,1,1,1,1,1,1,1,1,1,1,1,1,1,1
1,1,1,1,1,1,1,1,1,1,1,1,1,1,1,1,1,1,1,1,1,1,1,1,1,1
1,1,1,1,1,1,1,1,1,1,1,1,1,1,1,1,1,1,1,1,1,1,1,1,1,1
endlayer

layer
1,1,1,1,1,1,1,1,1,1,1,1,1,1,1,1,1,1,1,1,1,1,1,1,1,1
1,1,1,1,1,1,1,1,1,1,1,1,1,1,1,1,1,1,1,1,1,1,1,1,1,1
1,1,1,1,1,1,1,1,1,1,1,1,1,1,1,1,1,1,1,1,1,1,1,1,1,1
1,1,1,1,1,1,1,1,1,1,1,1,1,1,1,1,1,1,1,1,1,1,1,1,1,1
1,1,1,1,1,1,1,1,1,1,1,1,1,1,1,1,1,1,1,1,1,1,1,1,1,1
1,1,1,1,1,1,1,1,1,1,1,1,1,1,1,1,1,1,1,1,1,1,1,1,1,1
1,1,1,1,1,1,1,1,1,1,1,1,1,1,1,1,4,4,2,2,1,2,2,2,2,2
1,1,1,1,1,1,1,1,1,1,1,2,2,2,4,4,4,4,4,2,2,2,2,2,2,2
1,1,1,1,1,1,1,1,1,1,1,2,2,2,2,2,2,4,6,5,0,6,6,0,5,2
1,1,1,1,1,1,1,1,1,1,1,2,2,2,2,2,2,2,10,9,9,9,9,8,7,4
1,1,1,1,1,1,1,1,1,1,1,2,2,2,2,2,2,2,0,5,0,0,11,11,5,4
1,1,1,1,1,1,1,1,1,1,1,1,2,2,2,2,2,2,2,2,2,3,2,2,2,2
1,1,1,1,1,1,1,1,1,1,1,1,0,2,2,2,2,1,2,2,2,0,2,2,2,1
1,1,1,1,1,1,1,1,1,1,1,1,1,1,1,1,1,1,1,1,1,1,1,1,1,1
1,1,1,1,1,1,1,1,1,1,1,1,1,1,1,1,1,1,1,1,1,1,1,1,1,1
1,1,1,1,1,1,1,1,1,1,1,1,1,1,1,1,1,1,1,1,1,1,1,1,1,1
endlayer

layer
1,1,1,1,1,1,1,1,1,1,1,1,2,2,1,1,1,1,1,1,1,1,1,1,1,1
1,1,1,1,1,1,1,1,1,1,1,2,2,4,4,2,1,1,1,1,1,1,1,1,1,1
1,1,1,1,1,1,1,1,1,1,1,1,4,4,4,2,1,1,1,1,1,1,1,1,1,1
1,1,1,1,1,1,1,1,1,1,1,1,4,2,2,2,1,1,1,1,1,1,1,1,1,1
1,1,1,1,1,1,1,1,1,1,1,1,2,2,2,2,1,1,1,1,1,1,1,1,1,1
1,1,1,1,1,1,1,1,1,1,1,1,2,2,2,2,1,1,1,1,1,1,1,1,1,1
1,1,1,1,1,1,1,1,1,1,1,2,2,2,4,4,4,4,2,2,2,2,2,2,12,12
1,1,1,1,1,1,1,1,1,1,1,2,2,2,4,4,4,4,4,2,2,2,2,2,12,12
1,1,1,1,1,1,1,1,1,1,1,2,2,2,2,2,2,0,6,5,0,6,6,0,5,12
1,1,1,1,1,1,1,1,1,1,1,2,2,2,2,2,2,10,0,0,0,0,0,0,13,12
1,1,1,1,1,1,1,1,1,1,1,2,2,2,2,2,2,11,0,5,0,0,11,11,5,2
1,1,1,1,1,1,1,1,1,1,1,2,2,2,2,2,2,2,2,2,2,2,2,2,2,2
1,1,1,1,1,1,1,1,1,1,1,1,0,2,2,2,2,2,2,2,2,2,2,2,2,2
1,1,1,1,1,1,1,1,1,1,1,1,1,1,1,1,1,1,1,1,1,1,1,1,1,1
1,1,1,1,1,1,1,1,1,1,1,1,1,1,1,1,1,1,1,1,1,1,1,1,1,1
1,1,1,1,1,1,1,1,1,1,1,1,1,1,1,1,1,1,1,1,1,1,1,1,1,1
endlayer

layer
1,1,1,1,1,1,1,1,1,1,1,2,2,2,4,4,1,1,1,1,1,1,1,1,1,1
1,1,1,1,1,1,1,1,1,1,1,2,4,4,4,4,1,1,1,1,1,1,1,1,1,1
1,1,1,1,1,1,1,1,1,1,1,2,4,4,4,4,1,1,1,1,1,1,1,1,1,1
1,1,1,1,1,1,1,1,1,1,1,2,4,4,2,2,1,1,1,1,1,1,1,1,1,1
1,1,1,1,1,1,1,1,1,1,1,2,2,2,2,2,1,1,1,1,1,1,1,1,1,1
1,1,1,1,1,1,1,1,1,1,1,2,2,2,2,14,1,1,1,1,1,1,1,1,1,1
1,1,1,1,1,1,1,1,1,1,1,2,2,2,2,2,2,2,2,2,2,2,2,12,12,12
1,1,1,1,1,1,1,1,1,1,1,2,2,2,2,2,2,2,2,2,2,2,12,12,12,12
1,1,1,1,1,1,1,1,1,1,1,2,2,2,2,2,0,0,6,5,15,6,0,0,5,12
1,1,1,1,1,1,1,1,1,1,1,2,2,2,2,2,10,16,0,0,0,0,0,0,0,12
1,1,1,1,1,1,1,1,1,1,1,2,2,2,2,2,0,11,0,5,15,0,11,0,5,2
1,1,1,1,1,1,1,1,1,1,2,2,2,2,2,2,2,2,2,2,2,2,2,2,2,2
1,1,1,1,1,1,1,1,1,1,2,2,2,2,2,2,2,2,2,2,2,2,2,2,2,1
1,1,1,1,1,1,1,1,1,1,2,1,1,1,1,1,1,1,1,1,1,1,1,1,1,1
1,1,1,1,1,1,1,1,1,1,2,1,1,1,1,1,1,1,1,1,1,1,1,1,1,1
1,1,1,1,1,1,1,1,1,1,1,1,1,1,1,1,1,1,1,1,1,1,1,1,1,1
endlayer

layer
1,1,1,1,1,1,1,1,1,1,2,2,2,2,2,4,1,1,1,1,1,1,1,1,1,1
1,1,1,1,1,1,1,1,1,1,2,2,7,7,6,4,1,1,1,1,1,1,1,1,1,1
1,1,1,1,1,1,1,1,1,1,2,2,5,17,5,2,1,1,1,1,1,1,1,1,1,1
1,1,1,1,1,1,1,1,1,1,2,2,0,18,0,2,1,1,1,1,1,1,1,1,1,1
1,1,1,1,1,1,1,2,2,2,2,2,19,18,16,14,1,1,1,1,1,1,1,1,1,1
1,1,1,1,1,1,1,3,2,2,2,2,19,18,0,14,1,1,1,1,1,1,1,1,1,1
1,1,1,1,1,1,1,2,2,2,2,2,0,18,0,2,2,2,2,2,2,2,1,12,12,2
1,1,1,1,1,1,1,2,2,2,2,2,5,18,5,2,2,2,2,2,2,2,12,12,12,1
1,1,1,1,1,1,1,2,2,2,2,5,0,18,0,5,0,0,6,2,2,2,2,2,2,2
1,1,1,1,1,1,1,2,2,2,2,10,9,20,9,9,0,16,0,2,2,2,2,2,2,2
1,1,1,1,1,1,1,2,2,2,2,5,7,21,11,5,0,11,0,2,2,2,2,2,2,1
1,1,1,1,1,1,1,2,2,2,2,2,2,22,22,2,2,2,2,2,2,2,2,2,2,1
1,1,1,1,1,1,1,2,2,2,2,2,2,2,2,2,2,2,2,1,1,2,2,1,1,1
1,1,1,1,1,1,1,2,2,2,2,1,1,1,1,1,1,1,1,1,1,1,1,1,1,1
1,1,1,1,1,1,1,2,2,2,2,1,1,1,1,1,1,1,1,1,1,1,1,1,1,1
1,1,1,1,1,1,1,1,2,1,1,1,1,1,1,1,1,1,1,1,1,1,1,1,1,1
endlayer

layer
1,1,1,1,1,1,1,1,1,1,25,25,2,2,2,25,1,1,1,1,1,1,1,1,1,1
1,1,1,1,1,1,1,1,1,1,25,2,7,24,6,2,1,1,1,1,1,1,1,1,1,1
1,1,1,1,1,1,1,1,1,1,25,2,5,0,5,2,1,1,1,1,1,1,1,1,1,1
1,1,1,1,1,1,1,1,1,1,25,2,0,0,0,2,1,1,1,1,1,1,1,1,1,1
1,1,1,1,1,1,1,25,25,25,25,2,19,0,16,2,1,1,1,1,1,1,1,1,1,1
1,1,1,1,1,1,1,25,25,25,25,2,19,0,0,2,1,1,1,1,1,1,1,1,1,1
1,1,1,1,1,1,1,25,25,25,25,2,0,0,0,2,25,25,25,1,25,1,1,1,1,1
1,1,1,1,1,1,2,25,25,2,2,2,5,0,5,2,2,2,25,25,25,25,1,1,2,1
1,1,1,1,1,1,1,25,25,2,0,5,0,0,0,5,0,0,2,25,25,1,1,1,1,1
1,1,1,1,1,1,1,25,25,2,10,0,0,0,0,0,0,16,2,25,25,25,1,2,1,2
1,1,1,1,1,1,1,25,25,2,11,5,0,11,11,5,0,11,2,25,25,1,1,1,1,1
1,1,1,1,1,1,2,25,25,25,2,2,2,2,3,2,2,2,25,25,25,25,1,1,2,1
1,1,1,1,1,1,1,25,25,25,25,25,25,25,25,25,25,25,1,1,1,2,1,1,1,1
1,1,1,1,1,1,1,25,25,25,25,1,1,1,1,1,1,1,1,1,1,2,1,1,1,1
1,1,1,1,1,1,1,25,25,25,25,1,1,1,1,1,1,1,1,1,1,1,1,1,1,1
1,1,1,1,1,1,1,2,25,1,1,1,1,1,1,1,1,1,1,1,1,1,1,1,1,1
endlayer

layer
1,1,1,1,1,1,1,1,1,1,25,25,2,2,2,2,1,1,1,1,1,1,1,1,1,1
1,1,1,1,1,1,1,1,1,1,25,2,0,6,6,2,1,1,1,1,1,1,1,1,1,1
1,1,1,1,1,1,1,1,1,1,25,2,5,0,5,2,1,1,1,1,1,1,1,1,1,1
1,1,1,1,1,1,1,1,1,1,25,2,0,0,0,2,1,1,1,1,1,1,1,1,1,1
1,1,1,1,1,1,1,25,25,25,25,2,19,0,16,2,1,1,1,1,1,1,1,1,1,1
1,1,1,1,1,1,2,25,25,25,25,2,19,0,0,2,1,1,1,1,1,1,1,1,1,1
1,1,1,1,1,1,2,25,25,25,25,2,15,0,15,2,25,25,2,1,1,1,1,1,1,1
1,1,1,1,1,1,2,25,25,2,2,2,5,0,5,2,2,25,1,1,1,1,1,1,1,1
1,1,1,1,1,1,2,25,2,6,0,5,0,0,0,5,15,2,1,2,1,1,1,1,1,1
1,1,1,1,1,1,1,25,2,10,0,0,0,0,0,0,0,2,1,1,1,1,1,1,1,1
1,1,1,1,1,1,1,25,2,11,11,5,0,11,11,5,15,2,1,1,1,1,1,1,1,1
1,1,1,1,1,1,2,25,25,2,2,2,2,2,2,2,2,25,2,1,2,1,1,1,1,1
1,1,1,1,2,1,1,25,25,25,25,25,25,2,25,25,25,25,1,1,1,1,1,1,1,1
1,1,1,1,1,2,2,25,25,25,25,1,1,1,1,1,1,1,1,1,1,1,1,1,1,1
1,1,1,1,1,1,2,25,25,25,25,1,1,1,1,1,1,1,1,1,1,1,1,1,1,1
1,1,1,1,1,1,1,25,25,25,1,1,1,1,1,1,1,1,1,1,1,1,1,1,1,1
endlayer

layer
1,1,1,1,1,1,1,1,1,1,1,25,25,25,25,1,1,1,1,1,1,1,1,1,1,1
1,1,1,1,1,1,1,1,1,1,25,25,2,2,2,1,1,1,1,1,1,1,1,1,1,1
1,1,1,1,1,1,1,1,1,1,25,25,2,2,2,25,1,1,1,1,1,1,1,1,1,1
1,1,1,1,1,1,1,1,1,1,25,25,2,22,2,25,1,1,1,1,1,1,1,1,1,1
1,1,1,1,25,25,25,25,25,25,25,25,2,22,2,25,1,1,1,1,1,1,1,1,1,1
1,1,1,1,25,25,25,25,25,25,25,25,2,2,2,25,1,1,1,1,1,1,1,1,1,1
1,1,1,1,25,25,25,25,25,25,25,25,2,2,2,25,25,1,1,1,1,1,1,1,1,1
1,1,1,1,25,25,25,25,2,2,2,2,2,2,2,25,25,1,1,1,1,1,1,1,1,1
1,1,1,1,25,25,25,2,5,6,0,5,2,2,2,2,2,1,1,25,1,1,1,1,1,1
1,1,1,1,25,25,25,2,10,0,0,0,2,2,2,2,2,1,1,1,1,25,1,1,1,1
1,1,1,1,25,25,25,2,5,11,0,5,2,2,2,2,2,1,1,1,1,1,1,1,1,1
1,1,1,1,25,25,25,25,2,2,2,2,25,25,25,25,25,1,25,1,1,1,1,1,1,1
1,1,1,1,25,25,25,25,25,25,25,25,25,0,0,0,25,1,1,1,1,1,1,1,1,1
1,1,1,1,25,25,25,25,25,25,25,1,1,1,1,1,1,1,1,1,1,1,1,1,1,1
1,1,1,1,25,25,25,25,25,25,1,1,1,1,1,1,1,1,1,1,1,1,1,1,1,1
1,1,1,1,25,25,25,25,25,1,1,1,1,1,1,1,1,1,1,1,1,1,1,1,1,1
endlayer

layer
1,1,1,1,1,1,1,1,1,1,1,1,1,1,1,1,1,1,1,1,1,1,1,1,1,1
1,1,1,1,1,1,1,1,1,1,1,25,1,1,1,1,1,1,1,1,1,1,1,1,1,1
1,1,1,1,1,1,1,1,1,1,25,25,25,1,1,1,1,1,1,1,1,1,1,1,1,1
1,1,1,1,1,1,1,1,1,1,25,25,25,25,1,1,1,1,1,1,1,1,1,1,1,1
1,1,25,25,25,25,25,25,25,25,25,25,25,25,1,1,1,1,1,1,1,1,1,1,1,1
1,25,25,25,25,25,25,25,25,25,25,25,25,1,1,1,1,1,1,1,1,1,1,1,1,1
1,25,25,25,25,25,25,25,25,25,25,25,25,25,1,1,1,1,1,1,1,1,1,1,1,1
25,25,25,25,25,25,25,2,2,2,2,25,25,1,1,1,1,1,1,1,1,1,1,1,1,1
25,25,25,25,25,25,25,6,5,6,15,2,25,25,1,1,1,1,1,1,1,1,1,1,1,1
1,25,25,25,25,25,25,10,0,0,0,2,25,25,1,1,1,1,1,1,1,1,1,1,1,1
1,25,25,25,25,25,25,11,5,11,15,2,25,1,1,25,1,1,1,1,1,1,1,1,1,1
25,25,25,25,25,25,25,2,2,2,2,25,1,1,1,1,25,1,1,1,1,1,1,1,1,1
25,25,25,25,25,25,25,25,25,25,25,1,1,1,1,1,1,1,1,1,1,1,1,1,1,1
1,25,25,25,25,25,25,25,25,25,25,1,1,1,1,1,1,1,1,1,1,1,1,1,1,1
1,25,25,25,25,25,25,25,25,25,1,1,1,1,1,1,1,1,1,1,1,1,1,1,1,1
1,1,25,25,25,25,25,25,25,1,1,1,1,1,1,1,1,1,1,1,1,1,1,1,1,1
endlayer

layer
1,1,1,1,1,1,1,1,1,1,1,1,1,1,1,1,1,1,1,1,1,1,1,1,1,1
1,1,1,1,1,1,1,1,1,1,1,1,1,1,1,1,1,1,1,1,1,1,1,1,1,1
1,1,0,0,25,25,25,1,1,1,1,1,1,1,1,1,1,1,1,1,1,1,1,1,1,1
1,0,0,25,25,25,25,25,25,1,1,1,1,1,1,1,1,1,1,1,1,1,1,1,1,1
1,0,0,25,2,2,2,2,25,1,25,1,1,1,1,1,1,1,1,1,1,1,1,1,1,1
0,0,17,26,2,2,2,2,25,25,25,25,1,1,1,1,1,1,1,1,1,1,1,1,1,1
0,0,18,16,2,2,2,2,2,2,25,25,25,1,1,1,1,1,1,1,1,1,1,1,1,1
0,0,18,27,5,2,2,2,2,2,2,25,25,1,1,1,1,1,1,1,1,1,1,1,1,1
0,0,18,0,27,0,6,6,5,6,2,25,25,25,1,1,1,1,1,1,1,1,1,1,1,1
0,29,28,9,9,9,9,0,0,0,2,25,25,25,1,1,1,1,1,1,1,1,1,1,1,1
0,0,18,0,0,11,11,11,5,16,2,2,25,25,1,1,1,1,1,1,1,1,1,1,1,1
0,0,18,0,5,2,2,2,2,2,2,2,25,1,1,1,1,1,1,1,1,1,1,1,1,1
0,0,18,16,2,2,2,2,2,2,2,25,25,1,1,1,1,1,1,1,1,1,1,1,1,1
1,0,30,2,2,2,2,2,2,2,25,25,1,1,1,1,1,1,1,1,1,1,1,1,1,1
1,1,0,1,2,2,2,2,2,25,25,1,1,1,1,1,1,1,1,1,1,1,1,1,1,1
1,1,1,1,1,2,2,25,25,25,1,1,1,1,1,1,1,1,1,1,1,1,1,1,1,1
endlayer

layer
1,1,1,1,1,1,1,1,1,1,1,1,1,1,1,1,1,1,1,1,1,1,1,1,1,1
1,1,1,0,1,1,1,1,1,1,1,1,1,1,1,1,1,1,1,1,1,1,1,1,1,1
1,0,0,0,0,25,25,1,1,1,1,1,1,1,1,1,1,1,1,1,1,1,1,1,1,1
0,0,0,0,25,25,1,25,1,1,1,1,1,1,1,1,1,1,1,1,1,1,1,1,1,1
0,0,0,25,25,25,2,25,25,1,1,1,1,1,1,1,1,1,1,1,1,1,1,1,1,1
0,0,0,26,25,2,2,2,25,1,25,25,1,1,1,1,1,1,1,1,1,1,1,1,1,1
0,0,0,0,2,2,2,2,2,25,25,25,1,1,1,1,1,1,1,1,1,1,1,1,1,1
0,0,0,27,5,2,2,2,2,2,25,25,1,1,1,1,1,1,1,1,1,1,1,1,1,1
0,0,0,0,0,0,6,0,5,2,2,25,25,1,1,1,1,1,1,1,1,1,1,1,1,1
0,0,0,0,0,0,0,0,0,2,2,25,25,1,1,1,1,1,1,1,1,1,1,1,1,1
0,0,0,0,0,11,11,0,5,2,2,25,25,1,1,1,1,1,1,1,1,1,1,1,1,1
0,0,0,0,5,2,2,2,2,2,25,25,1,1,1,1,1,1,1,1,1,1,1,1,1,1
0,0,0,0,31,2,2,2,2,25,25,25,25,1,1,1,1,1,1,1,1,1,1,1,1,1
0,0,0,32,2,2,2,2,2,25,25,25,1,1,1,1,1,1,1,1,1,1,1,1,1,1
1,0,0,0,25,2,2,25,25,25,25,1,1,1,1,1,1,1,1,1,1,1,1,1,1,1
1,1,1,1,1,1,25,25,25,25,1,1,1,1,1,1,1,1,1,1,1,1,1,1,1,1
endlayer

layer
1,1,1,1,1,1,1,1,1,1,1,1,1,1,1,1,1,1,1,1,1,1,1,1,1,1
1,0,0,0,0,1,1,1,1,1,1,1,1,1,1,1,1,1,1,1,1,1,1,1,1,1
0,0,0,0,0,1,1,1,1,1,1,1,1,1,1,1,1,1,1,1,1,1,1,1,1,1
0,0,0,0,0,1,1,1,1,1,1,1,1,1,1,1,1,1,1,1,1,1,1,1,1,1
0,0,0,0,0,25,25,25,1,1,1,1,1,1,1,1,1,1,1,1,1,1,1,1,1,1
0,0,0,0,25,25,2,25,25,1,1,1,1,1,1,1,1,1,1,1,1,1,1,1,1,1
0,0,0,13,25,2,2,2,25,1,1,1,1,1,1,1,1,1,1,1,1,1,1,1,1,1
0,0,0,0,5,2,2,2,25,25,25,25,1,1,1,1,1,1,1,1,1,1,1,1,1,1
0,0,0,0,0,0,6,15,2,2,25,25,25,1,1,1,1,1,1,1,1,1,1,1,1,1
0,0,0,0,0,0,0,0,2,2,25,25,1,1,1,1,1,1,1,1,1,1,1,1,1,1
0,0,0,0,0,11,11,15,2,2,2,25,1,1,1,1,1,1,1,1,1,1,1,1,1,1
0,0,0,0,5,2,2,2,2,25,25,25,1,1,1,1,1,1,1,1,1,1,1,1,1,1
0,0,0,0,11,2,2,2,25,25,25,1,1,1,1,1,1,1,1,1,1,1,1,1,1,1
0,0,0,0,25,2,2,25,25,25,1,1,1,1,1,1,1,1,1,1,1,1,1,1,1,1
0,0,0,0,25,25,25,25,25,1,1,1,1,1,1,1,1,1,1,1,1,1,1,1,1,1
1,1,0,1,1,1,25,1,1,1,1,1,1,1,1,1,1,1,1,1,1,1,1,1,1,1
endlayer

layer
1,1,0,0,1,1,1,1,1,1,1,1,1,1,1,1,1,1,1,1,1,1,1,1,1,1
0,0,0,0,0,1,1,1,1,1,1,1,1,1,1,1,1,1,1,1,1,1,1,1,1,1
0,0,0,0,0,0,1,1,1,1,1,1,1,1,1,1,1,1,1,1,1,1,1,1,1,1
0,0,0,0,0,0,1,1,1,1,1,1,1,1,1,1,1,1,1,1,1,1,1,1,1,1
0,0,0,0,0,0,25,25,1,1,1,1,1,1,1,1,1,1,1,1,1,1,1,1,1,1
0,0,0,0,0,25,25,25,25,1,1,1,1,1,1,1,1,1,1,1,1,1,1,1,1,1
0,0,0,0,25,25,25,25,25,1,1,1,1,1,1,1,1,1,1,1,1,1,1,1,1,1
0,0,0,0,33,2,2,25,25,25,1,1,1,1,1,1,1,1,1,1,1,1,1,1,1,1
0,0,0,0,33,2,2,2,25,25,25,1,1,1,1,1,1,1,1,1,1,1,1,1,1,1
0,0,0,0,33,2,2,2,2,25,25,1,1,1,1,1,1,1,1,1,1,1,1,1,1,1
0,0,0,0,33,2,2,2,25,25,25,1,1,1,1,1,1,1,1,1,1,1,1,1,1,1
0,0,0,0,33,2,2,25,25,25,1,1,1,1,1,1,1,1,1,1,1,1,1,1,1,1
0,0,0,0,34,25,25,25,25,1,1,1,1,1,1,1,1,1,1,1,1,1,1,1,1,1
0,0,0,0,25,25,25,25,1,1,1,1,1,1,1,1,1,1,1,1,1,1,1,1,1,1
0,0,0,0,0,25,25,1,1,1,1,1,1,1,1,1,1,1,1,1,1,1,1,1,1,1
0,0,0,0,1,1,1,1,1,1,1,1,1,1,1,1,1,1,1,1,1,1,1,1,1,1
endlayer

layer
0,0,0,0,0,1,1,1,1,1,1,1,1,1,1,1,1,1,1,1,1,1,1,1,1,1
0,0,0,0,0,0,1,1,1,1,1,1,1,1,1,1,1,1,1,1,1,1,1,1,1,1
0,0,0,0,0,0,0,1,1,1,1,1,1,1,1,1,1,1,1,1,1,1,1,1,1,1
0,0,0,0,0,0,0,1,1,1,1,1,1,1,1,1,1,1,1,1,1,1,1,1,1,1
0,0,0,0,0,0,1,1,1,1,1,1,1,1,1,1,1,1,1,1,1,1,1,1,1,1
0,0,0,0,0,0,1,1,1,1,1,1,1,1,1,1,1,1,1,1,1,1,1,1,1,1
0,0,0,0,0,25,25,25,1,1,1,1,1,1,1,1,1,1,1,1,1,1,1,1,1,1
0,0,0,0,25,25,25,25,25,1,1,1,1,1,1,1,1,1,1,1,1,1,1,1,1,1
0,0,0,0,25,25,25,25,25,1,1,1,1,1,1,1,1,1,1,1,1,1,1,1,1,1
0,0,0,0,0,25,25,25,25,25,1,1,1,1,1,1,1,1,1,1,1,1,1,1,1,1
0,0,0,0,0,25,25,25,25,25,1,1,1,1,1,1,1,1,1,1,1,1,1,1,1,1
0,0,0,0,25,25,25,25,25,1,1,1,1,1,1,1,1,1,1,1,1,1,1,1,1,1
0,0,0,0,0,25,25,1,1,1,1,1,1,1,1,1,1,1,1,1,1,1,1,1,1,1
0,0,0,0,0,25,1,1,1,1,1,1,1,1,1,1,1,1,1,1,1,1,1,1,1,1
0,0,0,0,0,1,1,1,1,1,1,1,1,1,1,1,1,1,1,1,1,1,1,1,1,1
0,0,0,0,0,0,1,1,1,1,1,1,1,1,1,1,1,1,1,1,1,1,1,1,1,1
endlayer

