
# Created by Ruins mod version 17.2 Ingame Parser
# authoring Player: BARTLLOW

# TEMPLATE PARAMETER SETTINGS:
#
# criterion expression specifying mod ids required to load template
# may include plus (AND), minus (AND NOT), comma (OR), and parentheses
# all required mods listed must be present; no prohibited mods can be
requiredMods=
#
# likelihood this template will be chosen relative to all others
# e.g., a weight=6 template is chosen 3X as often as one with weight=2
weight=1
#
# list of dimensions in which this template may spawn, even if generic
# one or more dimension names, separated by commas (blank = all)
dimensionsToSpawnIn=
#
# list of other biomes in which this template may spawn
# biome corresponding to directory is always assumed, listed or not
# generic templates should leave this list empty
biomesToSpawnIn=
#
# criterion expression specifying types of biome where template spawns
# this is in addition to those explicitly listed as biomesToSpawnIn
# generic templates should leave this list empty
biomeTypesToSpawnIn=
#
# list of biomes in which this template may not spawn
# takes precedence over biomeTypesToSpawnIn, but NOT biomesToSpawnIn
# should be empty if biomeTypesToSpawnIn is empty
biomesToNotSpawnIn=
#
# depth template is pushed down into the surface when built
# offset is min/max range of random additional bury depth
embed_into_distance=0
random_height_offset=0,0
#
# whitelist/blacklist of block types on which template may be built
# specify one, not both; leave the other empty (both empty = allow all)
acceptable_target_blocks=
unacceptable_target_blocks=flowing_water,water,flowing_lava,lava
#
# size of template (#layers, #rows per layer, #blocks per row)
dimensions=6,21,29
#
# max number of missing blocks allowed in surface beneath template
allowable_overhang=0
#
# depth/height limit affected by terrain leveling
# also maximum bumpiness tolerated in surface beneath template
max_leveling=2
#
# padding applied to all sides of template horizontal footprint
# expands area affected by terrain leveling (-1 = no leveling)
leveling_buffer=0
#
# do not rotate template randomly when built (1 = no rotation)
preventRotation=0
#
# treat water/lava blocks as air and protect them from rule0 (1 = yes)
preserve_water=0
preserve_lava=0
#
# minimum distance this template must have from instances of itself
uniqueMinDistance=0
#
# min/max distances this template can be from world spawn (0 = no limit)
# only applies to overworld--i.e., dimension 0
spawnMinDistance=0
spawnMaxDistance=0
#
# other template built nearby whenever this one is
# syntax: <name>;<relativeX>;<maxYdifference>;<relativeZ>[;<chance>]
# may be used more than once to specify multiple neighbors
adjoining_template=

rule1=0,100,minecraft:dirt-0
rule2=0,100,minecraft:grass-0
rule3=0,100,minecraft:stone-0
rule4=0,100,minecraft:gravel-0
rule5=0,100,minecraft:netherrack-0
rule6=0,100,minecraft:log-1
rule7=0,100,minecraft:fence-0
rule8=0,100,minecraft:planks-1
rule9=0,100,IInventory;minecraft:chest;minecraft:web#1#0#13+minecraft:web#1#0#17+minecraft:written_book#{pages:["\"Although it\\u0027s now more treacherous and less halcyon.\\nNow the end is hot\\nAll the skies give sunny, so love the lovers.\\n\\nThe drear moon gamely pulls a hand.\\n\"","\"Only the hand loves as a stormy lips.\\nWhere locks whisper\\nWe lead to lead.\\nVeera!\\nIs hostility really empty like transformation?\\n\\nVeera\\n\"","\"Why do the kisses make pain so needlessly?\\nlovers fought the heart about the sunny lies, ne\\u0027er but wailfully.\\nlo! death, the clear betrayal.\\n\\nCount the skies, give the enigma.\\n\"","\"Only the bed likes as a clear hand.\\nNo moon is vigorous, no hair is blue.\\nhorror, desire, and ever affection.\\nheart and sky, god, well! hearts like the essence.\\nabout lovers of \"","\"life and locks of transformation\\n\""],author:"Sven Kristinesson",title:"O!"}#0#24-5
rule10=0,100,IInventory;minecraft:chest;minecraft:web#1#0#0+minecraft:web#1#0#2+minecraft:web#1#0#4+minecraft:web#1#0#12+minecraft:web#1#0#13+minecraft:bone#1#0#14+minecraft:web#1#0#15+minecraft:web#1#0#16+minecraft:web#1#0#18+minecraft:web#1#0#19+minecraft:web#1#0#20+minecraft:web#1#0#24-5
rule11=0,100,minecraft:crafting_table-0
rule12=0,100,minecraft:iron_bars-0
rule13=0,100,minecraft:stone_slab-0
rule14=0,100,minecraft:cauldron-1
rule15=0,100,minecraft:fire-15
rule16=0,100,minecraft:double_stone_slab-0
rule17=0,100,minecraft:planks-0
rule18=0,100,minecraft:mob_spawner-0
rule19=0,100,minecraft:furnace-2
rule20=0,100,minecraft:furnace-4
rule21=0,100,IInventory;minecraft:chest;minecraft:web#1#0#13+minecraft:web#1#0#17+minecraft:written_book#{pages:["\"Rise dissemblingly like a aching kiss above hatred.\\ncravenly, hearts grieve\\nhostility like 70 locks\\nWe saw to hear.\\n50 hearts triumph mindlessly\\nWhy did the moon lead it, to love \"","\"the passion?\\n10000 lips\\n40 skies rise cravenly\\n\\nCould you drive it so wailfully?\\ngod embraces...\\nAnd bleed barely, \\nWhat is hostility after all...\\n\""],author:"Sven Kristinesson",title:"Lo!"}#0#24-4
rule22=0,100,IInventory;minecraft:chest;minecraft:web#1#0#0+minecraft:web#1#0#2+minecraft:web#1#0#4+minecraft:web#1#0#12+minecraft:web#1#0#13+minecraft:bone#1#0#14+minecraft:web#1#0#15+minecraft:web#1#0#16+minecraft:web#1#0#18+minecraft:web#1#0#19+minecraft:web#1#0#20+minecraft:web#1#0#24-4
rule23=1,100,minecraft:torch-5
rule24=0,100,minecraft:cauldron-0
rule25=2,100,minecraft:torch-2
rule26=0,100,minecraft:wool-8
rule27=0,100,minecraft:oak_stairs-7
rule28=0,100,minecraft:wooden_slab-0
rule29=0,100,minecraft:oak_stairs-4
rule30=0,100,minecraft:wooden_slab-1

layer
1,2,2,2,1,2,2,2,2,2,2,2,2,2,2,2,2,2,2,2,2,2,2,2,1,2,2,2,1
2,2,2,2,2,2,2,2,2,2,2,2,2,2,2,2,2,2,2,2,2,2,2,2,2,2,2,2,2
2,2,2,2,2,2,2,2,2,2,2,2,2,2,2,2,2,2,2,2,2,2,2,2,2,2,2,2,2
2,2,2,1,2,2,2,2,2,2,2,2,2,2,1,2,2,2,2,2,2,2,2,2,1,1,2,2,2
1,2,2,2,3,4,3,3,4,4,3,4,3,4,3,3,3,3,3,4,4,4,4,3,3,1,2,2,1
2,2,2,1,4,3,4,4,4,3,3,4,4,4,3,4,4,3,4,4,4,4,2,3,3,2,2,2,2
2,2,2,1,4,4,3,3,4,4,3,4,4,4,4,3,4,3,3,3,3,3,4,4,4,2,2,2,2
2,2,2,1,4,3,4,3,4,4,3,4,4,5,5,5,4,4,4,4,3,4,3,3,3,2,2,2,2
1,2,2,1,4,4,4,3,4,4,4,4,4,5,4,5,4,3,4,3,4,4,4,4,4,2,2,2,1
2,2,2,1,4,4,3,4,4,3,4,4,4,5,5,5,4,4,4,4,4,4,6,3,3,2,2,2,2
2,2,2,1,4,3,4,3,3,3,3,4,3,4,3,3,3,4,3,3,3,3,4,3,4,2,2,2,2
2,2,2,1,3,4,4,3,3,4,3,3,4,4,4,4,3,4,4,3,3,3,4,4,3,2,2,2,2
1,2,2,1,3,4,4,3,3,4,3,3,4,3,3,3,3,4,3,4,3,3,4,4,3,2,2,2,1
2,2,2,1,3,4,4,3,4,3,3,3,3,4,3,3,4,4,4,4,3,4,4,3,3,1,2,2,2
2,2,2,1,4,4,3,4,4,3,4,4,3,4,3,4,4,6,4,3,4,4,6,3,3,1,2,2,2
2,2,2,1,3,3,3,3,4,4,3,4,4,4,3,4,4,4,3,4,3,4,4,3,3,1,2,2,2
1,2,2,1,4,4,3,4,4,4,4,3,4,4,4,3,4,4,3,4,3,4,3,3,4,1,2,2,1
2,2,2,6,1,1,1,1,1,1,1,1,6,4,4,4,6,1,1,1,1,1,1,1,1,1,2,2,2
2,2,2,2,2,2,2,2,2,2,2,2,2,3,3,3,2,2,2,2,2,2,2,2,2,2,2,2,2
2,2,2,2,2,2,2,2,2,2,2,2,2,4,4,4,2,2,2,2,2,2,2,2,2,2,2,2,2
1,2,2,2,1,2,2,2,1,2,2,2,6,4,4,3,6,2,2,2,1,2,2,2,1,2,2,2,1
endlayer

layer
6,7,7,7,6,0,0,0,0,0,0,0,0,0,0,0,0,0,0,0,0,0,0,0,6,0,7,7,6
7,0,0,0,0,0,0,0,0,0,0,0,0,0,0,0,0,0,0,0,0,0,0,0,0,0,0,0,7
7,0,0,0,0,0,0,0,0,0,0,0,0,0,0,0,0,0,0,0,0,0,0,0,0,0,0,0,7
7,0,0,6,0,0,0,0,0,0,0,0,0,0,8,0,0,0,0,0,0,0,0,0,8,6,0,0,7
6,0,0,0,7,10,9,0,0,0,0,0,0,0,0,0,0,0,0,0,0,0,0,0,0,8,0,0,6
7,0,0,8,11,0,0,0,0,0,0,0,0,0,0,0,0,0,0,0,0,0,0,0,0,0,0,0,7
7,0,0,8,14,0,0,0,0,0,0,0,0,13,13,13,0,0,0,0,0,0,12,0,0,0,0,0,7
7,0,0,8,0,0,0,0,0,0,0,0,13,15,15,15,13,0,0,0,0,0,12,0,0,0,0,0,0
6,0,0,8,0,0,0,0,0,0,0,0,13,15,16,15,13,0,0,0,0,0,12,0,0,0,0,0,6
7,0,0,8,7,0,0,0,7,0,0,0,13,15,15,15,13,0,0,0,0,0,6,17,17,0,0,0,7
7,0,0,8,0,0,0,0,0,0,0,0,0,13,13,13,0,0,0,0,0,0,12,0,0,0,0,0,7
7,0,0,8,18,0,0,0,0,0,0,0,0,0,0,0,0,0,0,0,0,0,12,0,0,0,0,0,7
6,0,0,8,0,0,0,0,0,0,0,0,0,0,0,0,0,0,0,0,0,0,12,0,0,0,0,0,6
7,0,0,8,7,0,0,0,7,0,0,0,0,0,0,0,0,0,0,0,0,0,12,0,0,0,0,0,7
7,0,0,8,11,0,0,0,0,0,0,0,0,0,0,0,0,6,12,0,12,12,6,17,18,0,0,0,7
7,0,0,8,19,0,0,0,0,0,0,0,0,0,0,0,0,12,0,0,0,0,17,17,17,8,0,0,7
6,0,0,8,7,22,21,20,7,0,0,0,0,0,0,0,0,12,0,0,0,0,17,17,17,8,0,0,6
7,0,0,6,8,8,8,8,8,8,8,8,6,0,0,0,6,8,8,8,8,8,8,8,8,6,0,0,7
7,0,0,0,0,0,0,0,0,0,0,0,0,0,0,0,0,0,0,0,0,0,0,0,0,0,0,0,7
7,0,0,0,0,0,0,0,0,0,0,0,0,0,0,0,0,0,0,0,0,0,0,0,0,0,0,0,7
6,7,7,7,6,7,7,7,6,7,7,7,6,12,0,12,6,7,7,7,6,7,7,7,6,7,7,7,6
endlayer

layer
6,7,7,0,6,0,0,0,0,0,0,0,0,0,0,0,0,0,0,0,0,0,0,0,0,0,0,7,6
7,0,0,0,0,0,0,0,0,0,0,0,0,0,0,0,0,0,0,0,0,0,0,0,0,0,0,0,7
0,0,0,0,0,0,0,0,0,0,0,0,0,0,0,0,0,0,0,0,0,0,0,0,0,0,0,0,7
7,0,0,6,0,0,0,0,0,0,0,0,0,0,0,0,0,0,0,0,0,0,0,0,0,0,0,0,7
6,0,0,0,23,0,0,0,0,0,0,0,0,0,0,0,0,0,0,0,0,0,0,0,0,8,0,0,6
7,0,0,0,0,0,0,0,0,0,0,0,0,0,0,0,0,0,0,0,0,0,0,0,0,0,0,0,7
7,0,0,8,0,0,0,0,0,0,0,0,0,0,0,0,0,0,0,0,0,0,12,0,0,0,0,0,7
7,0,0,8,0,0,0,0,0,0,0,0,0,0,0,0,0,0,0,0,0,0,12,0,0,0,0,0,7
6,0,0,8,0,0,0,0,0,0,0,0,0,0,24,0,0,0,0,0,0,0,12,0,0,0,0,0,6
7,0,0,8,7,0,0,0,7,0,0,0,0,0,0,0,0,0,0,0,0,0,0,0,0,0,0,0,7
7,0,0,8,0,0,0,0,0,0,0,0,0,0,0,0,0,0,0,0,0,0,12,0,0,0,0,0,7
7,0,0,8,0,0,0,0,0,0,0,0,0,0,0,0,0,0,0,0,0,0,12,0,0,0,0,0,7
6,0,0,8,0,0,0,0,0,0,0,0,0,0,0,0,0,0,0,0,0,0,12,0,0,0,0,0,6
7,0,0,8,7,0,0,0,7,0,0,0,0,0,0,0,0,25,0,0,0,0,12,0,0,0,0,0,7
7,0,0,8,0,0,0,0,0,0,0,0,0,0,0,0,0,6,12,0,12,12,6,17,0,0,0,0,7
7,0,0,8,0,0,0,0,0,0,0,0,0,0,0,0,0,12,0,0,0,0,17,17,17,0,0,0,7
6,0,0,8,23,0,0,0,7,0,0,0,0,0,0,0,0,12,0,0,0,0,17,17,17,8,0,0,6
7,0,0,6,8,8,8,8,8,8,8,8,6,0,0,0,6,8,8,8,8,8,8,8,8,6,0,0,7
7,0,0,0,0,0,0,0,0,0,0,0,0,0,0,0,0,0,0,0,0,0,0,0,0,0,0,0,7
7,0,0,0,0,0,0,0,0,0,0,0,0,0,0,0,0,0,0,0,0,0,0,0,0,0,0,0,7
6,7,7,7,6,7,7,7,6,7,7,7,6,12,0,12,6,7,7,7,6,7,7,7,6,7,7,7,6
endlayer

layer
6,0,0,0,0,0,0,0,0,0,0,0,0,0,0,0,0,0,0,0,0,0,0,0,6,0,0,0,6
0,0,0,0,0,0,0,0,0,0,0,0,0,0,0,0,0,0,0,0,0,0,0,0,0,0,0,0,0
0,0,0,0,0,0,0,0,0,0,0,0,0,0,0,0,0,0,0,0,0,0,0,0,0,0,0,0,0
0,0,0,0,0,0,0,0,0,0,0,0,0,0,0,0,0,0,0,0,0,0,0,0,0,0,0,0,0
6,0,0,0,0,0,0,0,0,0,0,0,0,0,0,0,0,0,0,0,0,0,0,0,0,0,0,0,6
0,0,0,0,0,0,0,0,0,0,0,0,0,0,0,0,0,0,0,0,0,0,0,0,0,0,0,0,0
0,0,0,0,0,0,0,0,0,0,0,0,0,0,0,0,0,0,0,0,0,0,0,0,0,0,0,0,0
0,0,0,8,26,0,0,0,0,0,0,0,0,0,0,0,0,0,0,0,0,0,0,0,0,0,0,0,0
6,0,0,8,26,0,0,0,0,0,0,0,0,0,0,0,0,0,0,0,0,0,0,0,0,0,0,0,6
0,0,0,8,26,0,0,0,0,0,0,0,0,0,0,0,0,0,0,0,0,0,0,0,0,0,0,0,0
0,0,0,8,0,0,0,0,0,0,0,0,0,0,0,0,0,0,0,0,0,0,0,0,0,0,0,0,0
0,0,0,8,0,0,0,0,0,0,0,0,0,0,0,0,0,0,0,0,0,0,0,0,0,0,0,0,0
6,0,0,8,0,0,0,0,0,0,0,0,0,0,0,0,0,0,0,0,0,0,27,0,0,0,0,0,6
0,0,0,8,26,0,0,0,0,0,0,0,0,0,0,0,0,0,0,0,0,0,0,0,0,0,0,0,0
0,0,0,8,0,0,0,0,26,0,0,0,0,0,0,0,0,6,29,29,29,29,6,0,28,0,0,0,0
0,0,0,8,0,0,0,0,26,0,0,0,0,0,0,0,0,27,28,28,28,28,28,28,28,8,0,0,0
6,0,0,8,0,0,0,26,26,0,0,0,0,0,0,0,0,27,28,28,28,28,28,28,28,8,0,0,6
0,0,0,6,8,8,8,8,8,8,8,8,6,0,0,0,6,8,8,8,8,8,8,8,8,6,0,0,0
0,0,0,0,0,0,0,0,0,0,0,0,0,0,0,0,0,0,0,0,0,0,0,0,0,0,0,0,0
0,0,0,0,0,0,0,0,0,0,0,0,0,0,0,0,0,0,0,0,0,0,0,0,0,0,0,0,0
6,0,0,0,6,0,0,0,6,0,0,0,6,12,12,12,6,0,0,0,6,0,0,0,6,0,0,0,6
endlayer

layer
0,0,0,0,0,0,0,0,0,0,0,0,0,0,0,0,0,0,0,0,0,0,0,0,0,0,0,0,0
0,0,0,0,0,0,0,0,0,0,0,0,0,0,0,0,0,0,0,0,0,0,0,0,0,0,0,0,0
0,0,0,0,0,0,0,0,0,0,0,0,0,0,0,0,0,0,0,0,0,0,0,0,0,0,0,0,0
0,0,0,0,0,0,0,0,0,0,0,0,0,0,0,0,0,0,0,0,0,0,0,0,0,0,0,0,0
0,0,0,0,0,0,0,0,0,0,0,0,0,0,0,0,0,0,0,0,0,0,0,0,0,0,0,0,0
0,0,0,0,0,0,0,0,0,0,0,0,0,0,0,0,0,0,0,0,0,0,0,0,0,0,0,0,0
0,0,0,0,0,0,0,0,0,0,0,0,0,0,0,0,0,0,0,0,0,0,0,0,0,0,0,0,0
0,0,0,30,0,0,0,0,0,0,0,0,0,0,0,0,0,0,0,0,0,0,0,0,0,0,0,0,0
0,0,0,23,0,0,0,0,0,0,0,0,0,0,0,0,0,0,0,0,0,0,0,0,0,0,0,0,0
0,0,0,30,0,0,0,0,0,0,0,0,0,0,0,0,0,0,0,0,0,0,0,0,0,0,0,0,0
0,0,0,0,0,0,0,0,0,0,0,0,0,0,0,0,0,0,0,0,0,0,0,0,0,0,0,0,0
0,0,0,30,0,0,0,0,0,0,0,0,0,0,0,0,0,0,0,0,0,0,0,0,0,0,0,0,0
0,0,0,23,0,0,0,0,0,0,0,0,0,0,0,0,0,0,0,0,0,0,0,0,0,0,0,0,0
0,0,0,30,0,0,0,0,0,0,0,0,0,0,0,0,0,0,0,0,0,0,0,0,0,0,0,0,0
0,0,0,0,0,0,0,26,0,0,0,0,0,0,0,0,0,0,0,0,0,0,23,0,0,0,0,0,0
0,0,0,30,0,26,0,26,0,0,0,0,0,0,0,0,0,0,0,0,0,0,0,0,0,0,0,0,0
0,0,0,0,0,0,0,0,0,0,0,0,0,0,0,0,0,0,0,0,0,0,0,0,0,0,0,0,0
0,0,0,6,0,30,0,30,0,30,0,30,6,0,0,0,6,30,0,30,0,30,0,30,0,6,0,0,0
0,0,0,0,0,0,0,0,0,0,0,0,0,0,0,0,0,0,0,0,0,0,0,0,0,0,0,0,0
0,0,0,0,0,0,0,0,0,0,0,0,0,0,0,0,0,0,0,0,0,0,0,0,0,0,0,0,0
0,0,0,0,0,0,0,0,0,0,0,0,0,0,0,0,0,0,0,0,0,0,0,0,0,0,0,0,0
endlayer

layer
0,0,0,0,0,0,0,0,0,0,0,0,0,0,0,0,0,0,0,0,0,0,0,0,0,0,0,0,0
0,0,0,0,0,0,0,0,0,0,0,0,0,0,0,0,0,0,0,0,0,0,0,0,0,0,0,0,0
0,0,0,0,0,0,0,0,0,0,0,0,0,0,0,0,0,0,0,0,0,0,0,0,0,0,0,0,0
0,0,0,0,0,0,0,0,0,0,0,0,0,0,0,0,0,0,0,0,0,0,0,0,0,0,0,0,0
0,0,0,0,0,0,0,0,0,0,0,0,0,0,0,0,0,0,0,0,0,0,0,0,0,0,0,0,0
0,0,0,0,0,0,0,0,0,0,0,0,0,0,0,0,0,0,0,0,0,0,0,0,0,0,0,0,0
0,0,0,0,0,0,0,0,0,0,0,0,0,0,0,0,0,0,0,0,0,0,0,0,0,0,0,0,0
0,0,0,0,0,0,0,0,0,0,0,0,0,0,0,0,0,0,0,0,0,0,0,0,0,0,0,0,0
0,0,0,0,0,0,0,0,0,0,0,0,0,0,0,0,0,0,0,0,0,0,0,0,0,0,0,0,0
0,0,0,0,0,0,0,0,0,0,0,0,0,0,0,0,0,0,0,0,0,0,0,0,0,0,0,0,0
0,0,0,0,0,0,0,0,0,0,0,0,0,0,0,0,0,0,0,0,0,0,0,0,0,0,0,0,0
0,0,0,0,0,0,0,0,0,0,0,0,0,0,0,0,0,0,0,0,0,0,0,0,0,0,0,0,0
0,0,0,0,0,0,0,0,0,0,0,0,0,0,0,0,0,0,0,0,0,0,0,0,0,0,0,0,0
0,0,0,0,0,0,0,0,0,0,0,0,0,0,0,0,0,0,0,0,0,0,0,0,0,0,0,0,0
0,0,0,0,0,0,0,0,0,0,0,0,0,0,0,0,0,0,0,0,0,0,0,0,0,0,0,0,0
0,0,0,0,0,0,0,0,0,0,0,0,0,0,0,0,0,0,0,0,0,0,0,0,0,0,0,0,0
0,0,0,0,0,0,0,0,0,0,0,0,0,0,0,0,0,0,0,0,0,0,0,0,0,0,0,0,0
0,0,0,23,0,0,0,0,0,0,0,0,23,0,0,0,23,0,0,0,0,0,0,0,0,23,0,0,0
0,0,0,0,0,0,0,0,0,0,0,0,0,0,0,0,0,0,0,0,0,0,0,0,0,0,0,0,0
0,0,0,0,0,0,0,0,0,0,0,0,0,0,0,0,0,0,0,0,0,0,0,0,0,0,0,0,0
0,0,0,0,0,0,0,0,0,0,0,0,0,0,0,0,0,0,0,0,0,0,0,0,0,0,0,0,0
endlayer

