
# Created by Ruins mod version 17.2 Ingame Parser
# authoring Player: BARTLLOW

# TEMPLATE PARAMETER SETTINGS:
#
# criterion expression specifying mod ids required to load template
# may include plus (AND), minus (AND NOT), comma (OR), and parentheses
# all required mods listed must be present; no prohibited mods can be
requiredMods=
#
# likelihood this template will be chosen relative to all others
# e.g., a weight=6 template is chosen 3X as often as one with weight=2
weight=1
#
# list of dimensions in which this template may spawn, even if generic
# one or more dimension names, separated by commas (blank = all)
dimensionsToSpawnIn=
#
# list of other biomes in which this template may spawn
# biome corresponding to directory is always assumed, listed or not
# generic templates should leave this list empty
biomesToSpawnIn=
#
# criterion expression specifying types of biome where template spawns
# this is in addition to those explicitly listed as biomesToSpawnIn
# generic templates should leave this list empty
biomeTypesToSpawnIn=
#
# list of biomes in which this template may not spawn
# takes precedence over biomeTypesToSpawnIn, but NOT biomesToSpawnIn
# should be empty if biomeTypesToSpawnIn is empty
biomesToNotSpawnIn=
#
# depth template is pushed down into the surface when built
# offset is min/max range of random additional bury depth
embed_into_distance=0
random_height_offset=0,0
#
# whitelist/blacklist of block types on which template may be built
# specify one, not both; leave the other empty (both empty = allow all)
acceptable_target_blocks=
unacceptable_target_blocks=flowing_water,water,flowing_lava,lava
#
# size of template (#layers, #rows per layer, #blocks per row)
dimensions=18,31,29
#
# max number of missing blocks allowed in surface beneath template
allowable_overhang=0
#
# depth/height limit affected by terrain leveling
# also maximum bumpiness tolerated in surface beneath template
max_leveling=2
#
# padding applied to all sides of template horizontal footprint
# expands area affected by terrain leveling (-1 = no leveling)
leveling_buffer=0
#
# do not rotate template randomly when built (1 = no rotation)
preventRotation=0
#
# treat water/lava blocks as air and protect them from rule0 (1 = yes)
preserve_water=0
preserve_lava=0
#
# minimum distance this template must have from instances of itself
uniqueMinDistance=0
#
# min/max distances this template can be from world spawn (0 = no limit)
# only applies to overworld--i.e., dimension 0
spawnMinDistance=0
spawnMaxDistance=0
#
# other template built nearby whenever this one is
# syntax: <name>;<relativeX>;<maxYdifference>;<relativeZ>[;<chance>]
# may be used more than once to specify multiple neighbors
adjoining_template=

rule1=0,100,minecraft:grass-0
rule2=0,100,minecraft:dirt-0
rule3=0,100,minecraft:vine-1
rule4=0,100,minecraft:cobblestone-0
rule5=0,100,minecraft:vine-8
rule6=0,100,minecraft:vine-4
rule7=0,100,minecraft:planks-0
rule8=0,100,minecraft:web-0
rule9=0,100,minecraft:mossy_cobblestone-0
rule10=0,100,minecraft:stone_stairs-2
rule11=0,100,minecraft:wool-14
rule12=0,100,minecraft:wool-12
rule13=0,100,minecraft:stone_stairs-5
rule14=0,100,minecraft:stone_stairs-7
rule15=0,100,minecraft:stone_stairs-6
rule16=0,100,minecraft:stone_stairs-0
rule17=0,100,minecraft:vine-2
rule18=0,100,minecraft:stonebrick-1
rule19=0,100,minecraft:stonebrick-2
rule20=0,100,minecraft:stonebrick-0
rule21=0,100,minecraft:stone_stairs-1
rule22=0,100,minecraft:stone_stairs-4
rule23=0,100,minecraft:stone_stairs-3
rule24=0,100,minecraft:fence-0
rule25=0,100,minecraft:furnace-5
rule26=0,100,minecraft:vine-9
rule27=0,100,minecraft:iron_bars-0
rule28=0,100,minecraft:ladder-3
rule29=0,100,IInventory;minecraft:chest;minecraft:iron_pickaxe#1#0#3+minecraft:diamond#2#0#5+minecraft:golden_horse_armor#1#0#8+minecraft:iron_helmet#1#0#13+minecraft:sapling#3#0#16+minecraft:iron_boots#1#0#17+minecraft:bread#2#0#19+minecraft:apple#2#0#23-3
rule30=0,100,minecraft:bookshelf-0
rule31=0,100,minecraft:furnace-4
rule32=0,100,minecraft:stone_brick_stairs-6
rule33=0,100,minecraft:stone_brick_stairs-3
rule34=0,100,minecraft:stone_brick_stairs-4
rule35=0,100,minecraft:stone_brick_stairs-7
rule36=0,100,minecraft:crafting_table-0
rule37=0,100,minecraft:furnace-2
rule38=0,100,minecraft:bed-0
rule39=0,100,minecraft:bed-8
rule40=0,100,IInventory;minecraft:furnace;minecraft:coal#11#0#1-2
rule41=0,100,IInventory;minecraft:chest;minecraft:web#1#0#4+minecraft:web#1#0#10+minecraft:web#1#0#11+minecraft:web#1#0#15+minecraft:rotten_flesh#2#0#16+minecraft:web#1#0#18+minecraft:written_book#{pages:["\"We rived the monumental seas before we hurt flesh.\\nBut when the shields die\\nBut when the captains die\\n\\nrun heavily like a calm rapscallion amidst rapture.\\n\"","\"shields, peasants, peasants - Those are our true rapture.\\nThey stalk to terrify.\\n\\nBut when the peasants run\\nRonja!\\nWhat is agony after all...\\n\"","\"\\nbehold, how the monumental seas hastily preens\\nWhen vulture lost, \\nThey never rive the peasants nor the peasants, with flesh.\\nEver to stalk a weapon, it rived a \"","\"shield.\\n\\nWhere was the calm rapture then?\\nWhy did the vulture rive it, to terrify the agony?\\nshields die and amidst them rapture runs!\\n\""],author:"Joonas Helgasson",title:"20 captains"}#0#25-2
rule42=0,100,minecraft:double_stone_slab-4
rule43=0,100,minecraft:double_stone_slab-3
rule44=0,100,minecraft:vine-12
rule45=0,100,IInventory;minecraft:furnace;minecraft:coal#11#0#1-4
rule46=0,100,minecraft:double_stone_slab-0
rule47=0,100,minecraft:stone_brick_stairs-5
rule48=0,100,minecraft:oak_stairs-2
rule49=0,100,minecraft:vine-5
rule50=0,100,minecraft:vine-3
rule51=0,100,minecraft:vine-6
rule52=0,100,minecraft:vine-10
rule53=0,100,minecraft:vine-13
rule54=0,100,minecraft:stone_brick_stairs-2
rule55=2,100,minecraft:torch-3
rule56=0,100,minecraft:oak_stairs-4
rule57=0,100,minecraft:oak_stairs-1
rule58=1,100,minecraft:torch-5
rule59=0,100,minecraft:wooden_pressure_plate-0
rule60=2,100,minecraft:torch-4
rule61=0,100,IInventory;minecraft:chest;minecraft:web#1#0#1+minecraft:web#1#0#5+minecraft:web#1#0#6+minecraft:web#1#0#12+minecraft:red_mushroom#1#0#17+minecraft:web#1#0#18+minecraft:web#1#0#20+minecraft:web#1#0#21+minecraft:bone#1#0#22+minecraft:web#1#0#26-5
rule62=0,100,IInventory;minecraft:chest;minecraft:bone#1#0#13+minecraft:web#1#0#19-5
rule63=0,100,IInventory;minecraft:chest;minecraft:web#1#0#11+minecraft:web#1#0#12+minecraft:rotten_flesh#3#0#13+minecraft:web#1#0#21-2
rule64=0,100,minecraft:double_stone_slab-5
rule65=2,100,minecraft:torch-1

layer
1,1,1,1,2,1,2,1,1,1,1,1,1,1,1,1,1,1,1,1,1,1,2,1,2,1,1,1,1
1,1,1,1,2,2,2,1,1,1,1,1,2,2,2,1,2,1,1,1,1,1,2,2,1,1,1,1,1
1,1,1,2,2,2,2,2,1,1,1,2,2,2,2,2,2,2,1,1,1,2,2,2,2,2,1,1,1
1,1,2,2,2,2,2,2,2,1,2,2,2,2,2,2,2,2,2,1,2,2,2,1,2,2,2,1,1
2,2,2,2,2,1,1,2,2,2,2,2,2,2,2,2,2,2,2,2,2,2,2,2,1,1,1,2,1
1,1,2,2,2,2,1,2,2,2,2,2,2,2,2,2,2,2,2,2,2,2,1,1,1,2,2,2,1
1,2,2,2,2,2,2,2,2,2,2,2,2,2,2,2,2,2,2,2,1,2,2,2,2,1,2,1,2
1,1,2,1,2,2,2,1,2,2,2,2,2,1,2,2,2,2,2,2,1,2,2,2,2,2,2,1,1
1,1,1,2,2,1,2,1,2,2,2,1,2,2,2,1,2,2,2,2,2,1,2,2,2,2,1,1,1
1,1,1,1,2,2,2,2,2,2,1,2,2,1,1,2,2,1,2,1,2,2,1,2,2,1,1,1,1
1,1,1,1,1,1,1,2,2,2,2,2,1,2,1,2,2,2,2,2,2,1,2,2,2,1,1,1,1
1,1,1,1,1,2,1,2,1,2,1,2,2,2,2,2,1,2,2,2,2,2,1,2,2,1,1,1,1
1,1,1,1,2,2,2,1,2,2,1,2,2,1,2,2,2,1,2,2,2,2,2,1,2,1,1,1,1
1,1,1,1,2,2,2,2,2,1,2,1,1,2,2,2,2,2,2,2,2,2,2,2,2,1,1,1,1
1,1,2,2,2,2,2,2,2,2,2,1,2,1,2,1,2,2,2,2,1,2,2,2,2,1,1,1,1
1,1,2,1,2,2,2,2,2,2,2,2,2,2,2,1,1,1,2,2,2,2,2,1,2,1,1,1,1
1,1,2,2,1,1,2,2,2,2,2,1,1,1,2,2,2,2,2,1,2,1,1,2,2,1,1,1,1
1,1,2,2,2,2,2,2,2,2,2,2,2,2,2,2,2,1,2,2,2,2,2,2,2,1,1,1,1
1,1,1,2,2,2,1,2,1,2,2,2,2,2,2,2,2,2,2,2,2,2,2,2,2,1,1,1,1
1,1,1,1,2,1,1,2,2,2,2,2,2,1,2,2,2,2,2,2,2,2,2,2,1,1,1,1,1
1,1,1,1,2,2,2,2,1,2,1,2,2,2,1,2,2,2,2,2,2,2,2,2,2,1,1,1,1
1,1,1,1,2,2,2,2,2,2,2,2,1,2,2,2,2,1,1,2,1,2,2,2,2,1,1,1,1
1,1,1,2,2,2,2,1,2,2,2,2,2,1,2,2,2,1,2,2,2,2,1,1,2,1,1,1,1
1,1,1,2,2,2,2,2,1,2,2,2,2,2,1,2,2,2,1,2,2,2,2,2,1,1,1,1,1
1,1,2,2,2,2,2,2,2,2,2,2,2,2,2,2,2,2,2,2,2,2,1,1,1,1,1,1,1
1,2,2,2,2,2,1,1,2,2,2,2,2,2,2,2,2,2,2,2,1,1,1,1,1,1,1,1,1
2,2,2,2,1,1,2,2,2,2,2,2,2,2,2,2,2,2,2,2,1,1,1,1,1,1,1,1,1
1,1,2,2,2,2,2,1,2,1,2,2,2,2,2,2,2,1,1,1,1,1,1,1,1,1,1,1,1
1,1,1,2,1,2,1,2,1,1,1,2,2,2,2,2,2,1,1,1,1,1,1,1,1,1,1,1,1
1,1,1,1,2,2,1,1,1,1,1,1,2,2,1,1,1,1,1,1,1,1,1,1,1,1,1,1,1
1,1,1,1,2,1,2,1,1,1,1,1,1,1,1,1,1,1,2,2,1,1,1,1,1,1,1,1,1
endlayer

layer
0,0,0,0,4,6,4,0,0,0,0,0,0,0,0,0,5,0,0,0,0,0,4,0,4,3,0,0,0
0,0,0,5,4,9,4,8,0,0,0,0,1,7,7,7,1,5,0,0,0,6,4,4,4,3,0,0,0
0,0,0,4,4,4,4,4,0,0,8,1,1,2,7,2,1,1,0,0,0,4,4,4,4,4,0,0,0
5,8,4,4,4,4,4,9,4,3,1,1,1,2,1,2,1,1,1,5,4,4,4,4,4,4,4,5,5
4,4,4,11,11,11,11,11,4,4,4,1,1,10,9,9,1,1,4,9,4,4,4,9,4,4,4,4,4
6,14,4,11,11,11,11,11,4,9,1,1,2,9,13,4,1,1,1,4,4,4,12,12,12,4,4,4,8
4,4,4,11,11,11,11,11,4,9,4,4,4,9,4,9,4,4,4,4,4,4,12,12,12,4,4,4,4
17,0,4,11,11,11,11,11,4,9,4,4,4,4,16,15,4,9,4,4,9,4,4,4,4,4,4,0,0
0,0,0,4,4,4,9,4,4,4,4,4,4,9,4,4,4,4,4,4,4,4,4,4,4,4,0,0,0
0,0,0,6,4,4,4,4,4,18,4,9,9,4,9,4,4,4,4,4,9,4,4,4,4,0,0,0,0
0,0,0,0,4,4,4,4,4,4,4,4,4,4,4,9,4,4,4,9,4,4,4,10,4,3,0,0,0
0,0,0,0,4,4,4,4,4,20,4,4,9,4,4,4,16,4,4,4,4,4,19,4,9,0,0,0,0
0,0,6,4,4,4,4,10,4,20,4,4,4,13,4,4,9,4,4,20,4,4,4,4,4,3,0,0,0
0,0,4,10,4,4,4,4,4,21,4,4,4,4,4,4,4,9,4,18,4,20,9,4,4,0,0,0,0
0,0,4,4,9,9,4,4,18,4,9,19,4,20,20,4,20,4,20,18,18,4,4,4,9,0,0,0,0
0,0,4,21,4,19,20,4,9,4,4,9,4,4,4,4,4,13,4,4,4,19,4,4,18,0,0,0,0
0,0,4,9,20,4,20,4,4,4,4,15,4,9,4,4,4,4,4,9,4,21,18,4,4,0,0,0,0
0,0,4,4,15,20,4,4,4,9,4,4,4,4,4,9,4,9,4,9,9,4,4,4,4,3,0,0,0
0,0,0,4,4,4,20,4,10,4,9,4,4,4,11,4,4,4,4,9,4,4,4,4,4,0,0,0,0
0,0,0,0,4,4,20,4,9,4,4,4,20,11,11,11,11,9,4,4,4,4,4,4,13,0,0,0,0
0,0,0,0,4,4,4,4,4,9,4,22,20,11,11,11,11,4,9,4,4,4,4,4,4,0,0,0,0
0,0,0,5,9,4,4,4,9,4,4,4,20,4,4,4,11,4,4,4,4,4,9,16,4,5,0,0,0
0,0,0,4,23,4,4,4,15,4,11,2,2,4,4,4,11,11,11,4,4,4,4,4,4,4,0,0,0
5,0,4,4,4,4,4,11,11,11,20,4,4,4,4,4,4,4,11,11,4,4,4,4,4,0,0,0,0
15,4,4,9,4,11,11,11,4,9,4,1,2,4,4,9,2,1,4,4,9,4,4,0,0,0,0,0,0
8,9,4,4,4,11,11,11,4,4,4,1,1,4,4,4,2,1,1,9,4,0,0,0,0,0,0,0,0
4,4,4,4,4,4,9,9,9,4,4,1,1,9,4,9,1,1,2,2,0,0,0,0,0,0,0,0,0
0,0,4,4,4,4,9,4,4,3,1,1,1,2,2,2,1,1,0,0,0,0,0,0,0,0,0,0,0
0,0,0,4,4,4,4,4,8,0,0,1,1,2,7,2,1,0,0,0,0,0,0,0,0,0,0,0,0
0,0,0,6,9,4,4,0,0,0,0,8,1,7,7,3,0,0,0,0,0,0,0,0,0,0,0,0,0
0,0,0,0,4,0,4,3,0,0,0,0,0,0,0,0,0,0,0,0,0,0,0,0,0,0,0,0,0
endlayer

layer
0,0,0,0,4,6,4,3,0,0,0,0,0,0,0,0,0,0,0,0,0,6,4,0,4,3,0,0,0
0,0,0,0,4,4,9,3,0,0,0,0,0,0,0,0,0,0,0,0,0,6,4,4,4,3,0,0,0
0,0,0,4,25,25,25,4,0,0,0,0,0,7,0,7,0,0,0,0,5,4,25,25,25,4,24,0,0
0,5,4,27,27,27,27,27,4,5,5,0,0,7,7,7,0,0,0,5,4,3,0,24,0,24,4,26,0
9,4,4,0,0,0,0,0,0,4,4,0,0,0,0,0,0,0,4,4,3,0,0,0,0,7,28,4,4
6,9,7,8,0,0,0,0,0,4,8,5,7,4,4,4,5,0,5,4,0,0,0,0,0,7,6,4,0
4,4,7,7,8,0,0,0,6,4,4,4,4,8,5,0,4,4,4,4,0,0,0,0,0,7,29,4,4
0,0,16,7,7,5,0,0,0,20,20,20,19,9,9,4,20,0,0,20,3,0,0,0,8,7,4,0,0
0,0,24,9,7,7,31,5,20,4,4,4,4,20,20,20,4,4,4,4,20,30,0,0,30,9,24,0,0
0,0,0,6,4,18,0,32,0,17,0,0,8,20,20,20,0,0,0,0,6,19,20,19,4,0,0,0,0
0,0,0,0,4,3,4,0,0,0,0,0,0,20,20,20,0,0,0,0,0,0,0,20,9,3,0,0,0
0,0,0,0,4,0,4,0,0,0,0,0,0,20,20,20,0,0,0,0,0,0,6,19,4,0,0,0,0
0,0,0,6,4,0,4,24,0,0,0,0,0,20,20,20,0,0,0,0,0,0,0,18,9,3,0,0,0
0,0,0,0,4,0,4,24,0,0,0,0,0,21,21,21,0,0,0,0,0,0,0,20,4,0,0,0,0
0,0,0,0,0,0,17,0,0,0,0,0,0,0,0,0,0,0,0,0,0,0,0,19,33,0,0,0,0
0,0,0,0,0,0,0,0,0,0,0,0,0,0,0,0,0,0,0,0,0,0,0,20,20,0,0,0,0
0,0,0,0,0,0,0,0,0,5,5,5,0,0,5,0,5,0,0,0,0,0,0,20,34,0,0,0,0
0,0,0,0,4,0,0,24,0,20,20,18,20,18,20,20,19,19,20,20,0,0,0,19,9,3,0,0,0
0,0,0,6,9,0,0,24,6,35,18,20,19,20,20,20,20,20,20,18,0,0,0,20,9,0,0,0,0
0,0,0,0,4,0,0,24,0,19,19,20,11,19,19,20,18,18,19,19,0,0,0,20,4,0,0,0,0
0,0,0,6,4,3,0,0,6,19,3,20,11,20,20,20,20,19,0,20,0,0,0,19,4,3,0,0,0
0,0,0,5,4,18,0,20,0,20,20,20,11,16,16,16,20,19,20,20,6,20,20,18,4,5,0,0,0
0,0,24,4,36,36,4,0,20,20,6,11,11,18,18,20,19,19,20,19,18,0,0,0,17,4,0,0,0
5,0,4,17,5,7,8,0,20,19,11,4,21,9,4,13,4,4,20,20,0,0,0,0,0,0,0,0,0
23,9,39,38,7,0,0,0,17,4,4,0,7,4,4,4,7,6,4,4,37,0,0,0,0,0,0,0,0
6,4,41,7,17,0,0,0,6,4,3,0,0,4,4,4,7,0,0,4,40,0,0,0,0,0,0,0,0
9,4,39,0,0,0,0,0,0,4,4,0,0,0,21,21,7,8,4,4,0,0,0,0,0,0,0,0,0
17,6,4,5,0,0,0,5,4,3,0,0,0,7,7,7,0,0,0,0,0,0,0,0,0,0,0,0,0
0,0,0,22,0,0,0,4,17,0,0,0,0,7,3,7,0,0,0,0,0,0,0,0,0,0,0,0,0
0,0,0,6,4,4,4,0,0,0,0,0,0,17,0,0,0,0,0,0,0,0,0,0,0,0,0,0,0
0,0,0,6,4,8,4,3,0,0,0,0,0,0,0,0,0,0,0,0,0,0,0,0,0,0,0,0,0
endlayer

layer
0,0,0,0,4,6,4,3,0,0,0,0,0,0,0,0,0,0,0,0,0,6,4,0,4,3,0,0,0
0,0,0,0,20,20,20,3,0,0,0,0,0,0,0,0,0,0,0,0,0,6,20,20,20,3,0,0,0
0,0,0,20,43,17,43,20,0,0,0,0,0,0,0,0,0,0,0,0,5,20,42,0,42,19,24,0,0
0,44,20,0,0,0,17,17,20,5,5,0,0,0,0,0,0,0,0,5,20,0,0,0,17,7,20,0,0
4,18,0,0,0,0,0,0,17,20,4,0,0,0,0,0,0,0,4,20,17,0,0,0,6,7,28,20,4
6,18,0,0,0,0,0,0,6,4,0,5,0,0,0,0,0,0,44,20,0,0,0,0,0,0,0,20,0
4,20,4,0,0,0,0,0,6,4,4,4,4,0,0,0,4,4,4,20,0,0,0,0,0,0,0,18,4
0,0,19,0,0,0,0,0,0,20,19,20,20,20,0,5,5,0,0,8,0,0,0,0,0,0,18,17,0
0,0,24,20,9,45,0,5,20,4,4,4,4,20,20,20,4,4,4,4,20,5,0,0,30,20,24,0,0
0,0,0,6,4,20,0,20,0,0,0,0,17,20,20,20,0,0,0,17,6,20,20,20,20,0,0,0,0
0,0,0,0,20,3,0,0,0,0,0,0,0,20,20,20,0,0,0,0,0,0,0,0,19,3,0,0,0
0,0,0,6,18,0,0,0,0,0,0,0,0,0,0,0,0,0,0,0,0,0,0,0,19,0,0,0,0
0,0,0,6,19,3,0,0,0,0,0,0,0,0,0,0,0,0,0,0,0,0,0,0,20,3,0,0,0
0,0,0,0,18,0,0,0,0,0,0,0,0,0,0,0,0,0,0,0,0,0,0,0,19,0,0,0,0
0,0,0,0,17,0,0,0,0,0,0,0,0,0,0,0,0,0,0,0,0,0,0,0,19,0,0,0,0
0,0,0,0,0,0,0,0,0,0,0,0,0,0,0,0,0,0,0,0,0,0,0,0,4,0,0,0,0
0,0,0,0,0,0,0,0,0,5,0,0,0,0,5,0,5,5,0,0,0,0,0,0,20,0,0,0,0
0,0,0,0,19,0,0,24,0,20,19,20,20,20,46,20,18,20,20,20,3,0,0,0,20,3,0,0,0
0,0,0,6,20,0,0,0,6,20,17,0,0,8,0,0,0,0,6,20,0,0,0,0,20,0,0,0,0
0,0,0,0,20,0,0,0,0,20,0,0,0,4,0,0,0,0,0,20,3,0,0,0,20,0,0,0,0
0,0,0,6,19,3,0,0,0,20,3,23,0,4,0,0,0,0,6,20,0,0,0,0,20,3,0,0,0
0,0,0,6,20,20,0,19,5,20,0,4,0,18,20,20,0,0,6,20,6,20,20,20,4,0,0,0,0
0,0,24,18,3,7,4,0,20,20,0,0,9,20,20,20,0,0,0,20,20,0,17,0,17,0,0,0,0
5,0,19,17,0,0,17,0,4,20,20,20,20,4,4,4,20,20,19,20,0,0,0,0,0,0,0,0,0
9,20,3,0,7,0,0,0,0,20,4,0,8,4,4,4,0,6,4,4,0,0,0,0,0,0,0,0,0
6,19,0,7,0,0,0,0,6,20,5,0,0,0,0,0,0,0,0,4,0,0,0,0,0,0,0,0,0
9,20,7,0,0,0,0,0,5,20,4,0,0,0,0,0,0,6,4,0,0,0,0,0,0,0,0,0,0
0,6,20,5,0,0,0,5,20,17,17,0,0,0,0,0,0,0,0,0,0,0,0,0,0,0,0,0,0
0,0,0,20,5,0,5,20,17,0,0,0,0,0,0,0,0,0,0,0,0,0,0,0,0,0,0,0,0
0,0,0,0,20,20,20,0,0,0,0,0,0,0,0,0,0,0,0,0,0,0,0,0,0,0,0,0,0
0,0,0,6,4,8,4,3,0,0,0,0,0,0,0,0,0,0,0,0,0,0,0,0,0,0,0,0,0
endlayer

layer
0,0,0,0,4,44,4,3,0,0,0,0,0,0,0,0,0,0,0,0,0,6,4,5,9,3,0,0,0
0,0,0,5,20,20,20,0,0,0,0,0,0,0,0,0,0,0,0,0,0,6,20,20,20,0,0,0,0
0,0,0,20,0,17,8,20,0,0,0,0,0,0,0,0,0,0,0,0,0,20,0,0,7,19,0,0,0
0,6,20,0,0,0,0,0,20,0,5,0,0,0,0,0,0,0,0,6,20,0,0,0,0,7,47,0,0
4,19,0,0,0,0,0,0,17,20,4,0,0,0,0,0,0,0,4,20,17,0,0,0,6,7,28,20,4
5,20,0,0,0,0,0,0,6,20,0,0,0,0,0,0,0,0,44,20,0,0,0,0,0,0,0,20,0
4,18,4,0,0,0,0,0,0,20,4,4,4,0,0,0,4,4,4,20,0,0,0,0,0,0,0,19,4
0,0,19,0,0,0,0,0,0,4,13,4,20,0,0,0,0,0,0,0,0,0,0,0,0,0,20,3,0
0,0,0,20,9,8,0,5,20,4,4,4,4,20,20,20,4,4,4,4,20,5,0,0,0,20,24,0,0
0,0,0,0,19,19,18,19,0,0,0,0,0,0,0,0,0,0,0,0,6,20,20,20,20,0,0,0,0
0,0,0,0,19,0,0,0,0,0,0,0,0,0,0,0,0,0,0,0,0,0,0,0,20,3,0,0,0
0,0,0,6,19,0,0,0,0,0,0,0,0,0,0,0,0,0,0,0,0,0,0,0,20,0,0,0,0
0,0,0,0,20,3,0,0,0,0,0,0,0,0,0,0,0,0,0,0,0,0,0,0,20,3,0,0,0
0,0,0,0,19,0,0,0,0,0,0,0,0,0,0,0,0,0,0,0,0,0,0,0,20,0,0,0,0
0,0,0,0,17,0,0,0,0,0,0,0,0,0,0,0,0,0,0,0,0,0,0,0,4,0,0,0,0
0,0,0,0,0,0,0,0,0,0,0,0,0,0,0,0,0,0,0,0,0,0,0,0,17,0,0,0,0
0,0,0,0,0,0,0,48,0,0,0,5,0,0,5,0,5,5,0,0,0,0,0,0,4,0,0,0,0
0,0,0,0,20,0,0,48,0,19,46,46,46,20,46,20,46,46,46,20,3,0,0,0,20,0,0,0,0
0,0,0,6,20,0,0,48,6,19,17,17,0,0,0,0,0,0,0,20,0,0,0,0,20,0,0,0,0
0,0,0,0,20,0,0,0,0,20,0,0,0,0,0,0,0,0,6,20,3,0,0,0,20,0,0,0,0
0,0,0,6,20,3,0,0,0,20,0,0,0,0,0,0,0,0,6,20,3,0,0,0,20,3,0,0,0
0,0,0,6,19,20,19,20,0,20,0,0,0,0,0,0,0,0,6,20,49,20,20,20,20,3,0,0,0
0,0,24,20,0,0,17,0,20,20,0,0,0,0,0,5,0,0,0,20,20,0,17,0,0,0,0,0,0
5,0,19,50,0,0,0,0,6,20,20,20,20,20,19,18,20,20,20,20,3,0,0,0,0,0,0,0,0
4,20,3,0,0,0,0,0,6,20,4,0,0,0,0,0,0,51,4,20,0,0,0,0,0,0,0,0,0
0,19,0,0,0,0,0,0,6,20,5,0,0,0,0,0,0,0,8,20,0,0,0,0,0,0,0,0,0
4,19,3,0,0,0,0,0,5,20,4,0,0,0,0,0,0,6,4,0,0,0,0,0,0,0,0,0,0
0,0,20,5,0,0,0,0,20,17,17,0,0,0,0,0,0,0,0,0,0,0,0,0,0,0,0,0,0
0,0,0,20,5,0,5,20,3,0,0,0,0,0,0,0,0,0,0,0,0,0,0,0,0,0,0,0,0
0,0,0,0,20,20,20,17,0,0,0,0,0,0,0,0,0,0,0,0,0,0,0,0,0,0,0,0,0
0,0,0,6,4,6,4,0,0,0,0,0,0,0,0,0,0,0,0,0,0,0,0,0,0,0,0,0,0
endlayer

layer
0,0,0,0,4,44,4,3,0,0,0,0,0,0,0,0,0,0,0,0,0,6,4,0,4,3,0,0,0
0,0,0,0,20,18,20,5,0,0,0,0,0,0,0,0,0,0,0,0,0,6,20,20,20,0,0,0,0
0,0,0,20,0,17,6,20,0,0,0,0,0,0,0,0,0,0,0,0,5,20,0,0,4,32,0,0,0
0,6,19,3,0,0,0,0,20,5,5,0,0,0,0,0,0,0,0,6,20,17,0,0,0,7,20,5,0
4,20,3,0,0,0,0,0,17,20,4,0,0,0,0,0,0,0,4,20,17,0,0,0,0,17,28,20,4
5,0,0,0,0,0,0,0,6,20,0,0,0,0,0,0,0,0,44,0,0,0,0,0,0,0,0,24,0
4,20,5,0,0,0,0,0,0,20,4,0,0,0,0,0,0,0,4,20,0,0,0,0,0,0,0,19,4
0,0,20,3,0,0,0,0,0,4,0,0,0,0,0,0,0,0,0,0,0,0,0,0,0,0,20,3,17
0,0,0,20,3,0,5,5,20,0,0,0,0,0,0,0,0,0,0,0,20,5,0,5,0,20,24,0,0
0,0,0,0,20,19,20,20,0,0,0,0,0,0,0,0,0,0,0,0,6,20,20,20,20,3,0,0,0
0,0,0,0,32,0,0,0,0,0,0,0,0,0,0,0,0,0,0,0,0,0,0,0,20,0,0,0,0
0,0,0,0,20,0,0,0,0,0,0,0,0,0,0,0,0,0,0,0,0,0,0,0,20,0,0,0,0
0,0,0,0,18,3,0,0,0,0,0,0,0,0,0,0,0,0,0,0,0,0,0,0,20,0,0,0,0
0,0,0,6,19,0,0,0,0,0,0,0,0,0,0,0,0,0,0,0,0,0,0,0,20,0,0,0,0
0,0,0,0,20,0,48,0,0,0,0,0,0,0,0,0,0,0,0,0,0,0,0,0,0,0,0,0,0
0,0,0,6,0,0,48,0,0,0,0,0,0,0,0,0,0,0,0,0,0,0,0,0,0,0,0,0,0
0,0,0,0,20,0,48,0,0,0,0,0,0,0,0,0,0,0,0,0,0,0,0,0,0,0,0,0,0
0,0,0,0,19,0,48,0,0,4,20,20,20,4,0,20,20,34,19,20,3,0,0,0,20,0,0,0,0
0,0,0,6,20,0,48,0,0,4,50,17,0,0,0,17,0,0,0,20,3,0,0,0,20,0,0,0,0
0,0,0,6,20,0,48,0,0,20,0,0,0,0,0,0,0,0,6,20,3,0,0,0,20,0,0,0,0
0,0,0,6,18,0,0,0,6,20,3,0,0,0,0,0,0,0,6,20,0,0,0,0,20,3,0,0,0
0,0,0,6,19,20,20,20,5,20,0,0,0,0,0,0,0,0,0,20,3,20,20,20,20,3,0,0,0
0,0,0,18,3,17,17,0,20,20,0,0,0,0,0,5,0,0,6,20,20,0,0,0,0,0,0,0,0
0,0,20,0,0,0,0,0,6,20,0,20,20,19,4,19,20,20,4,4,3,0,0,0,0,0,0,0,0
9,20,0,0,0,0,0,0,0,20,4,17,0,0,0,0,0,0,4,20,3,0,0,0,0,0,0,0,0
0,0,0,0,0,0,0,0,0,19,52,0,0,0,0,0,0,0,5,18,0,0,0,0,0,0,0,0,0
15,19,0,0,0,0,0,0,5,20,4,0,0,0,0,0,0,0,4,0,0,0,0,0,0,0,0,0,0
0,0,19,5,0,0,0,5,20,17,17,0,0,0,0,0,0,0,0,0,0,0,0,0,0,0,0,0,0
0,0,0,20,5,0,0,20,0,0,0,0,0,0,0,0,0,0,0,0,0,0,0,0,0,0,0,0,0
0,0,0,0,20,18,20,17,0,0,0,0,0,0,0,0,0,0,0,0,0,0,0,0,0,0,0,0,0
0,0,0,0,4,51,4,0,0,0,0,0,0,0,0,0,0,0,0,0,0,0,0,0,0,0,0,0,0
endlayer

layer
0,0,0,0,4,53,4,0,0,0,0,0,0,0,0,0,0,0,0,0,0,6,4,0,4,0,0,0,0
0,0,0,0,20,4,20,0,0,0,0,0,0,0,0,0,0,0,0,0,0,44,20,4,19,0,0,0,0
0,0,6,20,0,0,0,20,0,0,0,0,0,0,0,0,0,0,0,0,44,20,0,0,4,54,0,0,0
0,6,20,3,0,0,0,0,20,26,0,0,0,0,0,0,0,0,0,6,20,0,0,0,0,0,19,5,0
4,20,3,0,0,0,0,0,0,20,0,0,0,0,0,0,0,0,4,20,0,0,0,0,0,0,28,20,14
5,20,0,0,0,0,0,0,6,4,0,0,0,0,0,0,0,0,0,0,0,0,0,0,0,0,55,20,3
4,20,5,0,0,0,0,0,0,20,0,0,0,0,0,0,0,0,0,0,0,0,0,0,0,0,8,18,14
0,0,20,3,0,0,0,0,6,20,0,0,0,0,0,0,0,0,0,0,0,0,0,0,0,0,18,3,0
0,0,0,19,26,5,0,5,20,0,0,0,0,0,0,0,0,0,0,0,0,5,0,5,0,19,24,0,0
0,0,0,0,18,18,20,20,0,0,0,0,0,0,0,0,0,0,0,0,0,20,0,20,20,3,0,0,0
0,0,0,0,20,0,0,0,0,0,0,0,0,0,0,0,0,0,0,0,0,0,0,0,20,0,0,0,0
0,0,0,0,20,0,0,0,0,0,0,0,0,0,0,0,0,0,0,0,0,0,0,0,20,0,0,0,0
0,0,0,0,20,0,0,0,0,0,0,0,0,0,0,0,0,0,0,0,0,0,0,0,20,0,0,0,0
0,0,0,6,20,48,0,0,0,0,0,0,0,0,0,0,0,0,0,0,0,0,0,0,20,0,0,0,0
0,0,0,0,19,48,0,0,0,0,0,0,0,0,0,0,0,0,0,0,0,0,0,0,0,0,0,0,0
0,0,0,6,19,48,3,0,0,0,0,0,0,0,0,0,0,0,0,0,0,0,0,0,0,0,0,0,0
0,0,0,0,20,48,0,0,0,0,0,0,0,0,0,5,0,0,0,5,0,0,0,0,0,0,0,0,0
0,0,0,0,18,48,0,0,0,46,20,0,20,46,6,46,20,3,20,46,3,0,0,0,20,0,0,0,0
0,0,0,0,19,48,0,0,0,20,17,0,0,0,0,17,0,0,0,20,3,0,0,0,20,0,0,0,0
0,0,0,6,18,48,3,0,0,20,0,0,0,0,0,0,0,0,6,20,3,0,0,0,20,0,0,0,0
0,0,0,6,20,48,0,0,6,20,3,0,0,0,0,0,0,0,6,20,0,0,0,0,20,0,0,0,0
0,0,0,6,19,18,20,20,0,20,0,0,0,0,0,0,0,0,0,20,3,20,20,20,20,0,0,0,0
0,0,24,19,3,17,0,0,20,20,3,0,0,0,0,5,0,0,0,20,20,0,0,0,0,0,0,0,0
0,0,20,0,0,0,0,0,0,0,0,20,20,4,3,4,20,20,0,4,0,0,0,0,0,0,0,0,0
4,20,8,0,0,0,0,0,0,20,4,0,0,0,0,0,0,0,4,20,0,0,0,0,0,0,0,0,0
0,20,0,0,0,0,0,0,0,4,0,0,0,0,0,0,0,0,5,0,0,0,0,0,0,0,0,0,0
4,20,0,0,0,0,0,0,5,20,4,0,0,0,0,0,0,0,4,0,0,0,0,0,0,0,0,0,0
0,0,20,5,0,0,0,5,20,17,17,0,0,0,0,0,0,0,0,0,0,0,0,0,0,0,0,0,0
0,0,17,20,0,0,0,20,0,0,0,0,0,0,0,0,0,0,0,0,0,0,0,0,0,0,0,0,0
0,0,0,0,20,4,20,17,0,0,0,0,0,0,0,0,0,0,0,0,0,0,0,0,0,0,0,0,0
0,0,0,0,4,0,4,0,0,0,0,0,0,0,0,0,0,0,0,0,0,0,0,0,0,0,0,0,0
endlayer

layer
0,0,0,0,0,0,0,0,0,0,0,0,0,0,0,0,0,0,0,0,0,0,0,0,16,0,0,0,0
0,0,0,0,4,0,4,0,0,0,0,0,0,0,0,0,0,0,0,0,0,0,4,0,4,0,0,0,0
0,0,6,4,17,0,0,4,5,0,0,0,0,0,0,0,0,0,0,0,0,0,0,0,17,9,0,0,0
0,0,4,3,0,0,0,0,4,0,0,0,0,0,0,0,0,0,0,0,0,0,0,0,0,0,4,5,0
23,9,3,0,0,0,0,0,6,4,0,0,0,0,0,0,0,0,0,0,0,0,0,0,0,0,0,4,10
0,4,0,0,0,0,0,0,0,4,0,0,0,0,0,0,0,0,0,0,0,0,0,0,0,0,7,4,0
23,4,5,0,0,0,0,0,0,4,0,0,0,0,0,0,0,0,0,0,0,0,0,0,0,0,7,22,10
0,0,4,0,0,0,0,0,0,0,0,0,0,0,0,0,0,0,0,0,0,0,0,0,0,0,20,3,0
0,0,0,4,5,5,0,0,20,0,0,0,0,0,0,0,0,0,0,0,0,0,0,5,5,20,24,0,0
0,0,0,6,4,20,20,20,0,0,0,0,0,0,0,0,0,0,0,0,0,0,0,20,4,3,0,0,0
0,0,0,0,4,19,0,0,0,0,0,0,0,0,0,0,0,0,0,0,0,0,0,0,4,0,0,0,0
0,0,0,0,13,20,0,0,0,0,0,0,0,0,0,0,0,0,0,0,0,0,0,0,4,3,0,0,0
0,0,0,0,4,19,0,0,0,0,0,0,0,0,0,0,0,0,0,0,0,0,0,0,4,0,0,0,0
0,0,0,6,4,19,0,0,0,0,0,0,0,0,0,0,0,0,0,0,0,0,0,0,4,0,0,0,0
0,0,0,0,9,20,0,0,0,0,0,0,0,0,0,0,0,0,0,0,0,0,0,0,0,0,0,0,0
0,0,0,6,4,20,3,0,0,0,0,0,0,0,0,0,0,0,0,0,0,0,0,0,0,0,0,0,0
0,0,0,0,4,18,3,0,0,0,0,0,0,0,0,0,0,0,0,5,0,0,0,0,0,0,0,0,0
0,0,0,0,4,19,0,0,0,4,0,0,0,46,6,46,0,0,0,20,3,0,0,0,4,3,0,0,0
0,0,0,0,4,20,0,0,0,4,0,0,0,0,0,0,0,0,0,20,3,0,0,0,4,0,0,0,0
0,0,0,0,14,20,3,0,0,20,0,0,0,0,0,0,0,0,0,20,0,0,0,0,4,0,0,0,0
0,0,0,0,4,20,0,0,6,20,3,0,0,0,0,0,0,0,6,20,0,0,0,0,4,0,0,0,0
0,0,0,0,4,20,18,20,0,20,0,0,0,0,0,0,0,0,0,20,3,20,20,20,4,0,0,0,0
0,0,24,20,7,0,0,0,20,20,3,5,0,0,0,5,0,0,0,20,20,3,0,0,0,0,0,0,0
0,6,19,7,7,0,0,0,0,0,0,20,20,4,0,4,20,4,0,20,0,0,0,0,0,0,0,0,0
23,4,7,7,0,0,0,0,0,4,0,0,0,17,0,0,0,17,0,4,0,0,0,0,0,0,0,0,0
0,4,7,0,0,0,0,0,0,0,0,0,0,0,0,0,0,0,0,0,0,0,0,0,0,0,0,0,0
23,4,0,0,0,0,0,0,0,4,0,0,0,0,0,0,0,0,0,0,0,0,0,0,0,0,0,0,0
0,0,4,5,0,0,0,5,4,17,0,0,0,0,0,0,0,0,0,0,0,0,0,0,0,0,0,0,0
0,0,17,4,0,0,0,4,17,0,0,0,0,0,0,0,0,0,0,0,0,0,0,0,0,0,0,0,0
0,0,0,0,4,0,4,17,0,0,0,0,0,0,0,0,0,0,0,0,0,0,0,0,0,0,0,0,0
0,0,0,0,0,0,0,0,0,0,0,0,0,0,0,0,0,0,0,0,0,0,0,0,0,0,0,0,0
endlayer

layer
0,0,0,0,0,0,0,0,0,0,0,0,0,0,0,0,0,0,0,0,0,0,0,0,5,0,0,0,0
0,0,0,0,0,0,0,0,0,0,0,0,0,0,0,0,0,0,0,0,0,0,0,0,20,0,0,0,0
0,0,6,20,0,0,0,20,0,0,0,0,0,0,0,0,0,0,0,0,0,0,0,0,17,20,0,0,0
0,0,20,0,0,0,0,0,20,0,0,0,0,0,0,0,0,0,0,0,0,0,0,0,0,0,20,0,0
6,20,3,0,0,0,0,0,0,20,0,0,0,0,0,0,0,0,0,0,0,0,0,0,0,0,0,20,0
0,18,3,0,0,0,0,0,0,0,0,0,0,0,0,0,0,0,0,0,0,0,0,0,0,0,7,4,0
6,20,5,0,0,0,0,0,6,4,0,0,0,0,0,0,0,0,0,0,0,0,0,0,0,0,56,4,0
0,0,20,0,0,0,0,0,5,0,0,0,0,0,0,0,0,0,0,0,0,0,0,0,0,6,18,0,0
0,0,0,19,5,5,0,0,20,0,0,0,0,0,0,0,0,0,0,0,0,0,0,0,44,20,24,0,0
0,0,0,0,4,20,4,20,0,0,0,0,0,0,0,0,0,0,0,0,0,0,0,0,20,0,0,0,0
0,0,0,0,20,21,3,0,0,0,0,0,0,0,0,0,0,0,0,0,0,0,0,0,0,0,0,0,0
0,0,0,0,20,23,0,0,0,0,0,0,0,0,0,0,0,0,0,0,0,0,0,0,0,0,0,0,0
0,0,0,0,20,16,0,0,0,0,0,0,0,0,0,0,0,0,0,0,0,0,0,0,0,0,0,0,0
0,0,0,6,4,0,0,0,0,0,0,0,0,0,0,0,0,0,0,0,0,0,0,0,4,0,0,0,0
0,0,0,0,21,24,0,0,0,0,0,0,0,0,0,0,0,0,0,0,0,0,0,0,0,0,0,0,0
0,0,0,0,23,24,0,0,0,0,0,0,0,0,0,0,0,0,0,0,0,0,0,0,0,0,0,0,0
0,0,0,0,16,24,0,0,0,0,0,0,0,0,0,0,0,0,0,5,0,0,0,0,0,0,0,0,0
0,0,0,0,9,24,0,0,0,20,0,0,0,20,6,20,0,0,0,20,0,0,0,0,4,3,0,0,0
0,0,0,0,24,21,0,0,0,20,0,0,0,0,0,0,0,0,0,20,3,0,0,0,0,0,0,0,0
0,0,0,0,24,23,3,0,0,20,0,0,0,0,0,0,0,0,0,20,0,0,0,0,0,0,0,0,0
0,0,0,0,24,16,0,0,0,20,0,0,0,0,0,0,0,0,6,20,3,0,0,0,0,0,0,0,0
0,0,0,5,18,18,20,20,0,20,0,0,0,0,0,0,0,0,0,20,26,20,20,20,0,0,0,0,0
0,0,24,18,36,0,0,0,20,0,0,0,0,0,0,0,0,0,0,20,20,3,0,0,0,0,0,0,0
0,6,20,36,36,0,0,0,0,0,0,0,0,0,0,0,0,0,0,4,17,0,0,0,0,0,0,0,0
6,4,57,57,0,0,0,0,0,0,0,0,0,0,0,0,0,0,0,4,0,0,0,0,0,0,0,0,0
0,4,24,0,0,0,0,0,0,0,0,0,0,0,0,0,0,0,0,0,0,0,0,0,0,0,0,0,0
6,20,0,0,0,0,0,0,0,0,0,0,0,0,0,0,0,0,0,0,0,0,0,0,0,0,0,0,0
0,0,20,3,0,0,0,0,0,0,0,0,0,0,0,0,0,0,0,0,0,0,0,0,0,0,0,0,0
0,0,17,20,0,0,0,0,0,0,0,0,0,0,0,0,0,0,0,0,0,0,0,0,0,0,0,0,0
0,0,0,0,0,0,0,0,0,0,0,0,0,0,0,0,0,0,0,0,0,0,0,0,0,0,0,0,0
0,0,0,0,0,0,0,0,0,0,0,0,0,0,0,0,0,0,0,0,0,0,0,0,0,0,0,0,0
endlayer

layer
0,0,0,0,0,0,0,0,0,0,0,0,0,0,0,0,0,0,0,0,0,0,0,0,5,0,0,0,0
0,0,0,0,0,0,0,0,0,0,0,0,0,0,0,0,0,0,0,0,0,0,0,0,20,0,0,0,0
0,0,0,20,0,0,0,0,0,0,0,0,0,0,0,0,0,0,0,0,0,0,0,0,17,4,0,0,0
0,0,20,17,0,0,0,0,0,0,0,0,0,0,0,0,0,0,0,0,0,0,0,0,0,6,9,0,0
6,20,3,0,0,0,0,0,0,0,0,0,0,0,0,0,0,0,0,0,0,0,0,0,0,0,0,4,0
0,4,0,0,0,0,0,0,0,0,0,0,0,0,0,0,0,0,0,0,0,0,0,0,0,0,0,24,0
0,20,5,0,0,0,0,0,6,20,0,0,0,0,0,0,0,0,0,0,0,0,0,0,0,0,0,4,0
0,6,20,3,0,0,0,0,5,0,0,0,0,0,0,0,0,0,0,0,0,0,0,0,0,6,20,17,0
0,0,0,20,5,0,0,5,20,0,0,0,0,0,0,0,0,0,0,0,0,0,0,0,0,20,0,0,0
0,0,0,0,20,4,20,20,0,0,0,0,0,0,0,0,0,0,0,0,0,0,0,0,0,0,0,0,0
0,0,0,0,9,21,3,0,0,0,0,0,0,0,0,0,0,0,0,0,0,0,0,0,0,0,0,0,0
0,0,0,0,4,23,0,0,0,0,0,0,0,0,0,0,0,0,0,0,0,0,0,0,0,0,0,0,0
0,0,0,0,4,16,3,0,0,0,0,0,0,0,0,0,0,0,0,0,0,0,0,0,0,0,0,0,0
0,0,0,6,4,0,0,0,0,0,0,0,0,0,0,0,0,0,0,0,0,0,0,0,0,0,0,0,0
0,0,0,0,21,24,0,0,0,0,0,0,0,0,0,0,0,0,0,0,0,0,0,0,0,0,0,0,0
0,0,0,0,23,24,0,0,0,0,0,0,0,0,0,0,0,0,0,0,0,0,0,0,0,0,0,0,0
0,0,0,0,16,24,0,0,0,0,0,0,0,0,0,0,0,0,0,5,0,0,0,0,0,0,0,0,0
0,0,0,0,18,24,0,0,0,20,0,0,0,0,0,0,0,0,0,20,0,0,0,0,4,0,0,0,0
0,0,0,0,58,21,0,0,0,20,0,0,0,0,0,0,0,0,0,20,3,0,0,0,0,0,0,0,0
0,0,0,0,0,23,0,0,0,20,0,0,0,0,0,0,0,0,0,20,0,0,0,0,0,0,0,0,0
0,0,0,0,58,16,3,0,0,20,0,0,0,0,0,0,0,0,6,20,3,0,0,0,0,0,0,0,0
0,0,0,5,4,18,20,20,0,0,0,0,0,0,0,0,0,0,0,20,26,20,20,20,0,0,0,0,0
0,0,24,20,17,0,0,0,0,0,0,0,0,0,0,0,0,0,0,20,20,50,0,0,0,0,0,0,0
0,6,19,0,0,0,0,0,0,0,0,0,0,0,0,0,0,0,0,4,0,0,0,0,0,0,0,0,0
6,4,0,0,0,0,0,0,0,0,0,0,0,0,0,0,0,0,0,20,0,0,0,0,0,0,0,0,0
0,24,59,0,0,0,0,0,0,0,0,0,0,0,0,0,0,0,0,0,0,0,0,0,0,0,0,0,0
6,4,0,0,0,0,0,0,0,0,0,0,0,0,0,0,0,0,0,0,0,0,0,0,0,0,0,0,0
0,0,4,3,0,0,0,0,0,0,0,0,0,0,0,0,0,0,0,0,0,0,0,0,0,0,0,0,0
0,0,17,0,0,0,0,0,0,0,0,0,0,0,0,0,0,0,0,0,0,0,0,0,0,0,0,0,0
0,0,0,0,0,0,0,0,0,0,0,0,0,0,0,0,0,0,0,0,0,0,0,0,0,0,0,0,0
0,0,0,0,0,0,0,0,0,0,0,0,0,0,0,0,0,0,0,0,0,0,0,0,0,0,0,0,0
endlayer

layer
0,0,0,0,0,0,0,0,0,0,0,0,0,0,0,0,0,0,0,0,0,0,0,0,5,0,0,0,0
0,0,0,0,0,0,0,0,0,0,0,0,0,0,0,0,0,0,0,0,0,0,0,0,20,0,0,0,0
0,0,0,4,0,0,0,0,0,0,0,0,0,0,0,0,0,0,0,0,0,0,0,0,17,19,0,0,0
0,0,4,17,0,0,0,0,0,0,0,0,0,0,0,0,0,0,0,0,0,0,0,0,0,6,20,5,0
6,4,17,0,0,0,0,0,0,0,0,0,0,0,0,0,0,0,0,0,0,0,0,0,0,0,0,20,0
0,20,0,0,0,0,0,0,0,0,0,0,0,0,0,0,0,0,0,0,0,0,0,0,0,0,6,4,0
0,4,0,0,0,0,0,0,0,0,0,0,0,0,0,0,0,0,0,0,0,0,0,0,0,0,0,9,0
0,6,4,3,0,0,0,0,0,0,0,0,0,0,0,0,0,0,0,0,0,0,0,0,0,6,19,17,0
0,0,0,4,5,0,5,0,0,0,0,0,0,0,0,0,0,0,0,0,0,0,0,0,0,20,0,0,0
0,0,0,0,4,20,20,20,0,0,0,0,0,0,0,0,0,0,0,0,0,0,0,0,0,0,0,0,0
0,0,0,0,51,4,17,0,0,0,0,0,0,0,0,0,0,0,0,0,0,0,0,0,0,0,0,0,0
0,0,0,0,0,23,0,0,0,0,0,0,0,0,0,0,0,0,0,0,0,0,0,0,0,0,0,0,0
0,0,0,0,5,16,0,0,0,0,0,0,0,0,0,0,0,0,0,0,0,0,0,0,0,0,0,0,0
0,0,0,6,13,0,0,0,0,0,0,0,0,0,0,0,0,0,0,0,0,0,0,0,0,0,0,0,0
0,0,0,0,21,24,0,0,0,0,0,0,0,0,0,0,0,0,0,0,0,0,0,0,0,0,0,0,0
0,0,0,0,23,24,0,0,0,0,0,0,0,0,0,0,0,0,0,0,0,0,0,0,0,0,0,0,0
0,0,0,0,16,24,0,0,0,0,0,0,0,0,0,0,0,0,0,0,0,0,0,0,0,0,0,0,0
0,0,0,0,20,24,0,0,0,0,0,0,0,0,0,0,0,0,0,0,0,0,0,0,4,0,0,0,0
0,0,0,0,0,21,0,0,0,0,0,0,0,0,0,0,0,0,0,0,0,0,0,0,0,0,0,0,0
0,0,0,0,0,23,0,0,0,0,0,0,0,0,0,0,0,0,0,0,0,0,0,0,0,0,0,0,0
0,0,0,0,0,16,3,0,0,0,0,0,0,0,0,0,0,0,0,0,0,0,0,0,0,0,0,0,0
0,0,0,5,4,19,20,20,0,0,0,0,0,0,0,0,0,0,0,0,26,20,0,0,0,0,0,0,0
0,0,24,18,17,0,0,0,0,0,0,0,0,0,0,0,0,0,0,0,20,50,0,0,0,0,0,0,0
0,6,20,0,0,0,0,0,0,0,0,0,0,0,0,0,0,0,0,0,0,0,0,0,0,0,0,0,0
6,4,0,0,0,0,0,0,0,0,0,0,0,0,0,0,0,0,0,4,0,0,0,0,0,0,0,0,0
0,4,60,0,0,0,0,0,0,0,0,0,0,0,0,0,0,0,0,0,0,0,0,0,0,0,0,0,0
6,19,5,0,0,0,0,0,0,0,0,0,0,0,0,0,0,0,0,0,0,0,0,0,0,0,0,0,0
0,0,20,0,0,0,0,0,0,0,0,0,0,0,0,0,0,0,0,0,0,0,0,0,0,0,0,0,0
0,0,17,0,0,0,0,0,0,0,0,0,0,0,0,0,0,0,0,0,0,0,0,0,0,0,0,0,0
0,0,0,0,0,0,0,0,0,0,0,0,0,0,0,0,0,0,0,0,0,0,0,0,0,0,0,0,0
0,0,0,0,0,0,0,0,0,0,0,0,0,0,0,0,0,0,0,0,0,0,0,0,0,0,0,0,0
endlayer

layer
0,0,0,0,0,0,0,0,0,0,0,0,0,0,0,0,0,0,0,0,0,0,0,0,5,0,0,0,0
0,0,0,0,0,0,0,0,0,0,0,0,0,0,0,0,0,0,0,0,0,0,0,0,4,0,0,0,0
0,0,0,20,0,0,0,0,0,0,0,0,0,0,0,0,0,0,0,0,0,0,0,0,0,20,0,0,0
0,0,20,17,0,0,0,0,0,0,0,0,0,0,0,0,0,0,0,0,0,0,0,0,0,6,20,0,0
0,20,17,0,0,0,0,0,0,0,0,0,0,0,0,0,0,0,0,0,0,0,0,0,0,0,28,20,0
0,20,0,0,0,0,0,0,0,0,0,0,0,0,0,0,0,0,0,0,0,0,0,0,0,6,6,18,0
0,20,3,0,0,0,0,0,0,0,0,0,0,0,0,0,0,0,0,0,0,0,0,0,0,0,0,20,0
0,6,20,0,0,0,0,0,0,0,0,0,0,0,0,0,0,0,0,0,0,0,0,0,0,6,20,0,0
0,0,0,20,0,0,5,0,0,0,0,0,0,0,0,0,0,0,0,0,0,0,0,0,0,20,0,0,0
0,0,0,0,4,20,20,20,0,0,0,0,0,0,0,0,0,0,0,0,0,0,0,0,0,0,0,0,0
0,0,0,0,17,0,17,0,0,0,0,0,0,0,0,0,0,0,0,0,0,0,0,0,0,0,0,0,0
0,0,0,0,0,4,0,0,0,0,0,0,0,0,0,0,0,0,0,0,0,0,0,0,0,0,0,0,0
0,0,0,0,5,16,0,0,0,0,0,0,0,0,0,0,0,0,0,0,0,0,0,0,0,0,0,0,0
0,0,0,6,4,0,0,0,0,0,0,0,0,0,0,0,0,0,0,0,0,0,0,0,0,0,0,0,0
0,0,0,0,21,0,0,0,0,0,0,0,0,0,0,0,0,0,0,0,0,0,0,0,0,0,0,0,0
0,0,0,0,23,24,0,0,0,0,0,0,0,0,0,0,0,0,0,0,0,0,0,0,0,0,0,0,0
0,0,0,0,16,24,0,0,0,0,0,0,0,0,0,0,0,0,0,0,0,0,0,0,0,0,0,0,0
0,0,0,0,4,24,0,3,0,0,0,0,0,0,0,0,0,0,0,0,0,0,0,0,4,0,0,0,0
0,0,0,0,0,21,0,0,0,0,0,0,0,0,0,0,0,0,0,0,0,0,0,0,0,0,0,0,0
0,0,0,0,0,23,0,0,0,0,0,0,0,0,0,0,0,0,0,0,0,0,0,0,0,0,0,0,0
0,0,0,0,0,16,3,0,0,0,0,0,0,0,0,0,0,0,0,0,0,0,0,0,0,0,0,0,0
0,0,0,0,4,20,20,20,0,0,0,0,0,0,0,0,0,0,0,0,0,20,0,0,0,0,0,0,0
0,0,24,20,7,7,17,0,0,0,0,0,0,0,0,0,0,0,0,0,20,0,0,0,0,0,0,0,0
0,0,18,7,7,0,0,0,0,0,0,0,0,0,0,0,0,0,0,0,0,0,0,0,0,0,0,0,0
6,18,7,7,0,0,0,0,0,0,0,0,0,0,0,0,0,0,0,0,0,0,0,0,0,0,0,0,0
0,20,7,0,0,0,0,0,0,0,0,0,0,0,0,0,0,0,0,0,0,0,0,0,0,0,0,0,0
0,19,5,0,0,0,0,0,0,0,0,0,0,0,0,0,0,0,0,0,0,0,0,0,0,0,0,0,0
0,51,20,0,0,0,0,0,0,0,0,0,0,0,0,0,0,0,0,0,0,0,0,0,0,0,0,0,0
0,0,17,0,0,0,0,0,0,0,0,0,0,0,0,0,0,0,0,0,0,0,0,0,0,0,0,0,0
0,0,0,0,0,0,0,0,0,0,0,0,0,0,0,0,0,0,0,0,0,0,0,0,0,0,0,0,0
0,0,0,0,0,0,0,0,0,0,0,0,0,0,0,0,0,0,0,0,0,0,0,0,0,0,0,0,0
endlayer

layer
0,0,0,0,0,0,0,0,0,0,0,0,0,0,0,0,0,0,0,0,0,0,0,0,5,0,0,0,0
0,0,0,0,0,0,0,0,0,0,0,0,0,0,0,0,0,0,0,0,0,0,0,0,4,0,0,0,0
0,0,0,0,0,0,0,0,0,0,0,0,0,0,0,0,0,0,0,0,0,0,0,0,0,20,0,0,0
0,0,20,0,0,0,0,0,0,0,0,0,0,0,0,0,0,0,0,0,0,0,0,0,0,6,20,0,0
0,20,0,0,0,0,0,0,0,0,0,0,0,0,0,0,0,0,0,0,0,0,0,0,0,6,0,20,0
0,20,3,0,0,0,0,0,0,0,0,0,0,0,0,0,0,0,0,0,0,0,0,0,0,6,6,20,0
6,20,26,0,0,0,0,0,0,0,0,0,0,0,0,0,0,0,0,0,0,0,0,0,0,0,0,20,0
0,6,20,0,0,0,0,0,0,0,0,0,0,0,0,0,0,0,0,0,0,0,0,0,0,0,20,0,0
0,0,0,20,3,0,0,0,0,0,0,0,0,0,0,0,0,0,0,0,0,0,0,0,0,20,0,0,0
0,0,0,0,20,20,20,20,0,0,0,0,0,0,0,0,0,0,0,0,0,0,0,0,0,0,0,0,0
0,0,0,0,17,0,17,0,0,0,0,0,0,0,0,0,0,0,0,0,0,0,0,0,0,0,0,0,0
0,0,0,0,0,0,0,0,0,0,0,0,0,0,0,0,0,0,0,0,0,0,0,0,0,0,0,0,0
0,0,0,0,5,4,0,0,0,0,0,0,0,0,0,0,0,0,0,0,0,0,0,0,0,0,0,0,0
0,0,0,0,4,0,0,0,0,0,0,0,0,0,0,0,0,0,0,0,0,0,0,0,0,0,0,0,0
0,0,0,0,21,0,0,0,0,0,0,0,0,0,0,0,0,0,0,0,0,0,0,0,0,0,0,0,0
0,0,0,0,23,24,0,0,0,0,0,0,0,0,0,0,0,0,0,0,0,0,0,0,0,0,0,0,0
0,0,0,0,16,24,0,0,0,0,0,0,0,0,0,0,0,0,0,0,0,0,0,0,0,0,0,0,0
0,0,0,0,4,24,0,3,0,0,0,0,0,0,0,0,0,0,0,0,0,0,0,0,0,0,0,0,0
0,0,0,0,0,21,0,0,0,0,0,0,0,0,0,0,0,0,0,0,0,0,0,0,0,0,0,0,0
0,0,0,0,0,23,0,0,0,0,0,0,0,0,0,0,0,0,0,0,0,0,0,0,0,0,0,0,0
0,0,0,0,0,16,0,0,0,0,0,0,0,0,0,0,0,0,0,0,0,0,0,0,0,0,0,0,0
0,0,0,6,4,20,19,20,0,0,0,0,0,0,0,0,0,0,0,0,0,0,0,0,0,0,0,0,0
0,0,24,20,62,61,17,0,0,0,0,0,0,0,0,0,0,0,0,0,0,0,0,0,0,0,0,0,0
0,0,20,30,0,0,0,0,0,0,0,0,0,0,0,0,0,0,0,0,0,0,0,0,0,0,0,0,0
0,18,39,38,0,0,0,0,0,0,0,0,0,0,0,0,0,0,0,0,0,0,0,0,0,0,0,0,0
0,20,63,0,0,0,0,0,0,0,0,0,0,0,0,0,0,0,0,0,0,0,0,0,0,0,0,0,0
0,20,5,0,0,0,0,0,0,0,0,0,0,0,0,0,0,0,0,0,0,0,0,0,0,0,0,0,0
0,6,20,0,0,0,0,0,0,0,0,0,0,0,0,0,0,0,0,0,0,0,0,0,0,0,0,0,0
0,0,17,0,0,0,0,0,0,0,0,0,0,0,0,0,0,0,0,0,0,0,0,0,0,0,0,0,0
0,0,0,0,0,0,0,0,0,0,0,0,0,0,0,0,0,0,0,0,0,0,0,0,0,0,0,0,0
0,0,0,0,0,0,0,0,0,0,0,0,0,0,0,0,0,0,0,0,0,0,0,0,0,0,0,0,0
endlayer

layer
0,0,0,0,0,0,0,0,0,0,0,0,0,0,0,0,0,0,0,0,0,0,0,0,0,0,0,0,0
0,0,0,0,0,0,0,0,0,0,0,0,0,0,0,0,0,0,0,0,0,0,0,0,0,5,0,0,0
0,0,0,0,0,0,0,0,0,0,0,0,0,0,0,0,0,0,0,0,0,0,0,0,0,20,0,0,0
0,6,20,0,0,0,0,0,0,0,0,0,0,0,0,0,0,0,0,0,0,0,0,0,0,0,20,0,0
0,20,17,0,0,0,0,0,0,0,0,0,0,0,0,0,0,0,0,0,0,0,0,0,0,6,55,20,3
0,64,3,0,0,0,0,0,0,0,0,0,0,0,0,0,0,0,0,0,0,0,0,0,0,6,0,24,0
6,20,26,0,0,0,0,0,0,0,0,0,0,0,0,0,0,0,0,0,0,0,0,0,0,0,55,18,0
0,6,20,0,0,0,0,0,0,0,0,0,0,0,0,0,0,0,0,0,0,0,0,0,0,0,20,0,0
0,0,0,20,26,0,0,0,0,0,0,0,0,0,0,0,0,0,0,0,0,0,0,0,0,20,0,0,0
0,0,0,0,20,20,20,20,0,0,0,0,0,0,0,0,0,0,0,0,0,0,0,0,0,0,0,0,0
0,0,0,0,17,0,0,0,0,0,0,0,0,0,0,0,0,0,0,0,0,0,0,0,0,0,0,0,0
0,0,0,0,0,0,0,0,0,0,0,0,0,0,0,0,0,0,0,0,0,0,0,0,0,0,0,0,0
0,0,0,0,5,0,0,0,0,0,0,0,0,0,0,0,0,0,0,0,0,0,0,0,0,0,0,0,0
0,0,0,0,4,0,0,0,0,0,0,0,0,0,0,0,0,0,0,0,0,0,0,0,0,0,0,0,0
0,0,0,0,21,24,0,0,0,0,0,0,0,0,0,0,0,0,0,0,0,0,0,0,0,0,0,0,0
0,0,0,0,23,24,0,0,0,0,0,0,0,0,0,0,0,0,0,0,0,0,0,0,0,0,0,0,0
0,0,0,0,16,24,0,0,0,0,0,0,0,0,0,0,0,0,0,0,0,0,0,0,0,0,0,0,0
0,0,0,0,4,24,0,3,0,0,0,0,0,0,0,0,0,0,0,0,0,0,0,0,0,0,0,0,0
0,0,0,6,0,21,0,0,0,0,0,0,0,0,0,0,0,0,0,0,0,0,0,0,0,0,0,0,0
0,0,0,6,0,23,0,3,0,0,0,0,0,0,0,0,0,0,0,0,0,0,0,0,0,0,0,0,0
0,0,0,0,0,16,0,0,0,0,0,0,0,0,0,0,0,0,0,0,0,0,0,0,0,0,0,0,0
0,0,0,6,4,18,20,20,0,0,0,0,0,0,0,0,0,0,0,0,0,0,0,0,0,0,0,0,0
0,0,24,20,65,65,0,0,0,0,0,0,0,0,0,0,0,0,0,0,0,0,0,0,0,0,0,0,0
0,6,20,0,0,0,0,0,0,0,0,0,0,0,0,0,0,0,0,0,0,0,0,0,0,0,0,0,0
0,20,60,0,0,0,0,0,0,0,0,0,0,0,0,0,0,0,0,0,0,0,0,0,0,0,0,0,0
0,24,0,0,0,0,0,0,0,0,0,0,0,0,0,0,0,0,0,0,0,0,0,0,0,0,0,0,0
6,18,0,3,0,0,0,0,0,0,0,0,0,0,0,0,0,0,0,0,0,0,0,0,0,0,0,0,0
0,6,20,0,0,0,0,0,0,0,0,0,0,0,0,0,0,0,0,0,0,0,0,0,0,0,0,0,0
0,0,0,0,0,0,0,0,0,0,0,0,0,0,0,0,0,0,0,0,0,0,0,0,0,0,0,0,0
0,0,0,0,0,0,0,0,0,0,0,0,0,0,0,0,0,0,0,0,0,0,0,0,0,0,0,0,0
0,0,0,0,0,0,0,0,0,0,0,0,0,0,0,0,0,0,0,0,0,0,0,0,0,0,0,0,0
endlayer

layer
0,0,0,0,0,0,0,0,0,0,0,0,0,0,0,0,0,0,0,0,0,0,0,0,0,0,0,0,0
0,0,0,0,0,0,0,0,0,0,0,0,0,0,0,0,0,0,0,0,0,0,0,0,0,0,0,0,0
0,0,0,0,0,0,0,0,0,0,0,0,0,0,0,0,0,0,0,0,0,0,0,0,0,20,24,0,0
0,6,20,0,0,0,0,0,0,0,0,0,0,0,0,0,0,0,0,0,0,0,0,0,0,17,20,0,0
0,20,17,0,0,0,0,0,0,0,0,0,0,0,0,0,0,0,0,0,0,0,0,0,0,6,7,20,3
0,0,0,0,0,0,0,0,0,0,0,0,0,0,0,0,0,0,0,0,0,0,0,0,0,6,7,20,0
6,20,0,0,0,0,0,0,0,0,0,0,0,0,0,0,0,0,0,0,0,0,0,0,0,0,7,34,0
0,17,20,0,0,0,0,0,0,0,0,0,0,0,0,0,0,0,0,0,0,0,0,0,0,0,18,17,0
0,0,0,20,26,5,0,0,0,0,0,0,0,0,0,0,0,0,0,0,0,0,0,0,0,64,0,0,0
0,0,0,0,20,20,0,4,0,0,0,0,0,0,0,0,0,0,0,0,0,0,0,0,0,0,0,0,0
0,0,0,0,0,0,0,0,0,0,0,0,0,0,0,0,0,0,0,0,0,0,0,0,0,0,0,0,0
0,0,0,0,0,0,0,0,0,0,0,0,0,0,0,0,0,0,0,0,0,0,0,0,0,0,0,0,0
0,0,0,0,0,0,0,0,0,0,0,0,0,0,0,0,0,0,0,0,0,0,0,0,0,0,0,0,0
0,0,0,6,4,13,0,0,0,0,0,0,0,0,0,0,0,0,0,0,0,0,0,0,0,0,0,0,0
0,0,0,0,21,4,9,3,0,0,0,0,0,0,0,0,0,0,0,0,0,0,0,0,0,0,0,0,0
0,0,0,0,23,9,4,0,0,0,0,0,0,0,0,0,0,0,0,0,0,0,0,0,0,0,0,0,0
0,0,0,0,16,4,4,0,0,0,0,0,0,0,0,0,0,0,0,0,0,0,0,0,0,0,0,0,0
0,0,0,0,9,9,4,3,0,0,0,0,0,0,0,0,0,0,0,0,0,0,0,0,0,0,0,0,0
0,0,0,6,9,4,4,0,0,0,0,0,0,0,0,0,0,0,0,0,0,0,0,0,0,0,0,0,0
0,0,0,6,4,4,9,3,0,0,0,0,0,0,0,0,0,0,0,0,0,0,0,0,0,0,0,0,0
0,0,0,0,20,4,9,0,0,0,0,0,0,0,0,0,0,0,0,0,0,0,0,0,0,0,0,0,0
0,0,0,6,18,20,20,4,0,0,0,0,0,0,0,0,0,0,0,0,0,0,0,0,0,0,0,0,0
0,0,24,20,7,7,0,0,0,0,0,0,0,0,0,0,0,0,0,0,0,0,0,0,0,0,0,0,0
0,0,18,7,7,0,0,0,0,0,0,0,0,0,0,0,0,0,0,0,0,0,0,0,0,0,0,0,0
0,20,7,7,7,0,0,0,0,0,0,0,0,0,0,0,0,0,0,0,0,0,0,0,0,0,0,0,0
0,18,7,7,0,0,0,0,0,0,0,0,0,0,0,0,0,0,0,0,0,0,0,0,0,0,0,0,0
6,19,7,3,0,0,0,0,0,0,0,0,0,0,0,0,0,0,0,0,0,0,0,0,0,0,0,0,0
0,6,20,0,0,0,0,0,0,0,0,0,0,0,0,0,0,0,0,0,0,0,0,0,0,0,0,0,0
0,0,0,0,0,0,0,0,0,0,0,0,0,0,0,0,0,0,0,0,0,0,0,0,0,0,0,0,0
0,0,0,0,0,0,0,0,0,0,0,0,0,0,0,0,0,0,0,0,0,0,0,0,0,0,0,0,0
0,0,0,0,0,0,0,0,0,0,0,0,0,0,0,0,0,0,0,0,0,0,0,0,0,0,0,0,0
endlayer

layer
0,0,0,0,0,0,0,0,0,0,0,0,0,0,0,0,0,0,0,0,0,0,0,0,0,0,0,0,0
0,0,0,0,0,0,0,0,0,0,0,0,0,0,0,0,0,0,0,0,0,0,0,0,0,0,0,0,0
0,0,0,0,0,0,0,0,0,0,0,0,0,0,0,0,0,0,0,0,0,0,0,0,0,64,24,0,0
0,0,0,0,0,0,0,0,0,0,0,0,0,0,0,0,0,0,0,0,0,0,0,0,0,17,64,0,0
0,4,0,0,0,0,0,0,0,0,0,0,0,0,0,0,0,0,0,0,0,0,0,0,0,6,4,4,0
0,0,0,0,0,0,0,0,0,0,0,0,0,0,0,0,0,0,0,0,0,0,0,0,0,0,8,64,0
6,4,0,0,0,0,0,0,0,0,0,0,0,0,0,0,0,0,0,0,0,0,0,0,0,0,4,4,0
0,17,0,0,0,0,0,0,0,0,0,0,0,0,0,0,0,0,0,0,0,0,0,0,0,0,64,17,0
0,0,0,64,0,0,0,0,0,0,0,0,0,0,0,0,0,0,0,0,0,0,0,0,0,0,0,0,0
0,0,0,0,4,0,0,0,0,0,0,0,0,0,0,0,0,0,0,0,0,0,0,0,0,0,0,0,0
0,0,0,0,17,0,0,0,0,0,0,0,0,0,0,0,0,0,0,0,0,0,0,0,0,0,0,0,0
0,0,0,0,0,0,0,0,0,0,0,0,0,0,0,0,0,0,0,0,0,0,0,0,0,0,0,0,0
0,0,0,0,0,0,0,0,0,0,0,0,0,0,0,0,0,0,0,0,0,0,0,0,0,0,0,0,0
0,0,0,6,4,0,0,0,0,0,0,0,0,0,0,0,0,0,0,0,0,0,0,0,0,0,0,0,0
0,0,0,0,4,0,24,0,0,0,0,0,0,0,0,0,0,0,0,0,0,0,0,0,0,0,0,0,0
0,0,0,0,4,0,24,0,0,0,0,0,0,0,0,0,0,0,0,0,0,0,0,0,0,0,0,0,0
0,0,0,0,4,0,24,0,0,0,0,0,0,0,0,0,0,0,0,0,0,0,0,0,0,0,0,0,0
0,0,0,0,13,0,24,0,0,0,0,0,0,0,0,0,0,0,0,0,0,0,0,0,0,0,0,0,0
0,0,0,0,4,0,24,0,0,0,0,0,0,0,0,0,0,0,0,0,0,0,0,0,0,0,0,0,0
0,0,0,0,4,0,24,0,0,0,0,0,0,0,0,0,0,0,0,0,0,0,0,0,0,0,0,0,0
0,0,0,0,4,0,24,0,0,0,0,0,0,0,0,0,0,0,0,0,0,0,0,0,0,0,0,0,0
0,0,0,6,9,8,9,0,0,0,0,0,0,0,0,0,0,0,0,0,0,0,0,0,0,0,0,0,0
0,0,24,64,4,0,0,0,0,0,0,0,0,0,0,0,0,0,0,0,0,0,0,0,0,0,0,0,0
0,0,64,24,0,0,0,0,0,0,0,0,0,0,0,0,0,0,0,0,0,0,0,0,0,0,0,0,0
0,4,4,0,0,0,0,0,0,0,0,0,0,0,0,0,0,0,0,0,0,0,0,0,0,0,0,0,0
0,64,17,0,0,0,0,0,0,0,0,0,0,0,0,0,0,0,0,0,0,0,0,0,0,0,0,0,0
0,4,9,3,0,0,0,0,0,0,0,0,0,0,0,0,0,0,0,0,0,0,0,0,0,0,0,0,0
0,0,64,0,0,0,0,0,0,0,0,0,0,0,0,0,0,0,0,0,0,0,0,0,0,0,0,0,0
0,0,0,0,0,0,0,0,0,0,0,0,0,0,0,0,0,0,0,0,0,0,0,0,0,0,0,0,0
0,0,0,0,0,0,0,0,0,0,0,0,0,0,0,0,0,0,0,0,0,0,0,0,0,0,0,0,0
0,0,0,0,0,0,0,0,0,0,0,0,0,0,0,0,0,0,0,0,0,0,0,0,0,0,0,0,0
endlayer

layer
0,0,0,0,0,0,0,0,0,0,0,0,0,0,0,0,0,0,0,0,0,0,0,0,0,0,0,0,0
0,0,0,0,0,0,0,0,0,0,0,0,0,0,0,0,0,0,0,0,0,0,0,0,0,0,0,0,0
0,0,0,0,0,0,0,0,0,0,0,0,0,0,0,0,0,0,0,0,0,0,0,0,0,0,24,0,0
0,0,0,0,0,0,0,0,0,0,0,0,0,0,0,0,0,0,0,0,0,0,0,0,0,0,24,0,0
0,4,0,0,0,0,0,0,0,0,0,0,0,0,0,0,0,0,0,0,0,0,0,0,0,0,16,4,0
0,0,0,0,0,0,0,0,0,0,0,0,0,0,0,0,0,0,0,0,0,0,0,0,0,0,5,0,0
0,4,0,0,0,0,0,0,0,0,0,0,0,0,0,0,0,0,0,0,0,0,0,0,0,0,4,4,0
0,17,0,0,0,0,0,0,0,0,0,0,0,0,0,0,0,0,0,0,0,0,0,0,0,0,24,17,0
0,0,0,0,0,0,0,0,0,0,0,0,0,0,0,0,0,0,0,0,0,0,0,0,0,0,0,0,0
0,0,0,0,4,0,0,0,0,0,0,0,0,0,0,0,0,0,0,0,0,0,0,0,0,0,0,0,0
0,0,0,0,17,0,0,0,0,0,0,0,0,0,0,0,0,0,0,0,0,0,0,0,0,0,0,0,0
0,0,0,0,0,0,0,0,0,0,0,0,0,0,0,0,0,0,0,0,0,0,0,0,0,0,0,0,0
0,0,0,0,24,0,0,0,0,0,0,0,0,0,0,0,0,0,0,0,0,0,0,0,0,0,0,0,0
0,0,0,0,24,0,0,0,0,0,0,0,0,0,0,0,0,0,0,0,0,0,0,0,0,0,0,0,0
0,0,0,0,24,0,0,0,0,0,0,0,0,0,0,0,0,0,0,0,0,0,0,0,0,0,0,0,0
0,0,0,0,24,0,0,0,0,0,0,0,0,0,0,0,0,0,0,0,0,0,0,0,0,0,0,0,0
0,0,0,0,24,0,0,0,0,0,0,0,0,0,0,0,0,0,0,0,0,0,0,0,0,0,0,0,0
0,0,0,0,24,0,0,0,0,0,0,0,0,0,0,0,0,0,0,0,0,0,0,0,0,0,0,0,0
0,0,0,0,24,0,0,0,0,0,0,0,0,0,0,0,0,0,0,0,0,0,0,0,0,0,0,0,0
0,0,0,0,24,0,0,0,0,0,0,0,0,0,0,0,0,0,0,0,0,0,0,0,0,0,0,0,0
0,0,0,0,24,0,58,0,0,0,0,0,0,0,0,0,0,0,0,0,0,0,0,0,0,0,0,0,0
0,0,0,0,4,49,4,0,0,0,0,0,0,0,0,0,0,0,0,0,0,0,0,0,0,0,0,0,0
0,0,24,24,4,0,0,0,0,0,0,0,0,0,0,0,0,0,0,0,0,0,0,0,0,0,0,0,0
0,0,24,24,0,0,0,0,0,0,0,0,0,0,0,0,0,0,0,0,0,0,0,0,0,0,0,0,0
0,4,4,0,0,0,0,0,0,0,0,0,0,0,0,0,0,0,0,0,0,0,0,0,0,0,0,0,0
0,0,0,0,0,0,0,0,0,0,0,0,0,0,0,0,0,0,0,0,0,0,0,0,0,0,0,0,0
0,4,4,0,0,0,0,0,0,0,0,0,0,0,0,0,0,0,0,0,0,0,0,0,0,0,0,0,0
0,0,0,0,0,0,0,0,0,0,0,0,0,0,0,0,0,0,0,0,0,0,0,0,0,0,0,0,0
0,0,0,0,0,0,0,0,0,0,0,0,0,0,0,0,0,0,0,0,0,0,0,0,0,0,0,0,0
0,0,0,0,0,0,0,0,0,0,0,0,0,0,0,0,0,0,0,0,0,0,0,0,0,0,0,0,0
0,0,0,0,0,0,0,0,0,0,0,0,0,0,0,0,0,0,0,0,0,0,0,0,0,0,0,0,0
endlayer

layer
0,0,0,0,0,0,0,0,0,0,0,0,0,0,0,0,0,0,0,0,0,0,0,0,0,0,0,0,0
0,0,0,0,0,0,0,0,0,0,0,0,0,0,0,0,0,0,0,0,0,0,0,0,0,0,0,0,0
0,0,0,0,0,0,0,0,0,0,0,0,0,0,0,0,0,0,0,0,0,0,0,0,0,0,0,0,0
0,0,0,0,0,0,0,0,0,0,0,0,0,0,0,0,0,0,0,0,0,0,0,0,0,0,0,0,0
0,0,0,0,0,0,0,0,0,0,0,0,0,0,0,0,0,0,0,0,0,0,0,0,0,0,23,10,0
0,0,0,0,0,0,0,0,0,0,0,0,0,0,0,0,0,0,0,0,0,0,0,0,0,0,0,0,0
0,0,0,0,0,0,0,0,0,0,0,0,0,0,0,0,0,0,0,0,0,0,0,0,0,0,23,10,0
0,0,0,0,0,0,0,0,0,0,0,0,0,0,0,0,0,0,0,0,0,0,0,0,0,0,0,0,0
0,0,0,0,0,0,0,0,0,0,0,0,0,0,0,0,0,0,0,0,0,0,0,0,0,0,0,0,0
0,0,0,0,0,0,0,0,0,0,0,0,0,0,0,0,0,0,0,0,0,0,0,0,0,0,0,0,0
0,0,0,0,0,0,0,0,0,0,0,0,0,0,0,0,0,0,0,0,0,0,0,0,0,0,0,0,0
0,0,0,0,0,0,0,0,0,0,0,0,0,0,0,0,0,0,0,0,0,0,0,0,0,0,0,0,0
0,0,0,0,0,0,0,0,0,0,0,0,0,0,0,0,0,0,0,0,0,0,0,0,0,0,0,0,0
0,0,0,0,0,0,0,0,0,0,0,0,0,0,0,0,0,0,0,0,0,0,0,0,0,0,0,0,0
0,0,0,0,0,0,0,0,0,0,0,0,0,0,0,0,0,0,0,0,0,0,0,0,0,0,0,0,0
0,0,0,0,0,0,0,0,0,0,0,0,0,0,0,0,0,0,0,0,0,0,0,0,0,0,0,0,0
0,0,0,0,0,0,0,0,0,0,0,0,0,0,0,0,0,0,0,0,0,0,0,0,0,0,0,0,0
0,0,0,0,0,0,0,0,0,0,0,0,0,0,0,0,0,0,0,0,0,0,0,0,0,0,0,0,0
0,0,0,0,0,0,0,0,0,0,0,0,0,0,0,0,0,0,0,0,0,0,0,0,0,0,0,0,0
0,0,0,0,0,0,0,0,0,0,0,0,0,0,0,0,0,0,0,0,0,0,0,0,0,0,0,0,0
0,0,0,0,58,0,0,0,0,0,0,0,0,0,0,0,0,0,0,0,0,0,0,0,0,0,0,0,0
0,0,0,0,16,0,16,0,0,0,0,0,0,0,0,0,0,0,0,0,0,0,0,0,0,0,0,0,0
0,0,0,0,21,0,0,0,0,0,0,0,0,0,0,0,0,0,0,0,0,0,0,0,0,0,0,0,0
0,0,0,58,0,0,0,0,0,0,0,0,0,0,0,0,0,0,0,0,0,0,0,0,0,0,0,0,0
0,23,10,0,0,0,0,0,0,0,0,0,0,0,0,0,0,0,0,0,0,0,0,0,0,0,0,0,0
0,0,0,0,0,0,0,0,0,0,0,0,0,0,0,0,0,0,0,0,0,0,0,0,0,0,0,0,0
0,23,10,0,0,0,0,0,0,0,0,0,0,0,0,0,0,0,0,0,0,0,0,0,0,0,0,0,0
0,0,0,0,0,0,0,0,0,0,0,0,0,0,0,0,0,0,0,0,0,0,0,0,0,0,0,0,0
0,0,0,0,0,0,0,0,0,0,0,0,0,0,0,0,0,0,0,0,0,0,0,0,0,0,0,0,0
0,0,0,0,0,0,0,0,0,0,0,0,0,0,0,0,0,0,0,0,0,0,0,0,0,0,0,0,0
0,0,0,0,0,0,0,0,0,0,0,0,0,0,0,0,0,0,0,0,0,0,0,0,0,0,0,0,0
endlayer

