
# Created by Ruins mod version 17.2 Ingame Parser
# authoring Player: BARTLLOW

# TEMPLATE PARAMETER SETTINGS:
#
# criterion expression specifying mod ids required to load template
# may include plus (AND), minus (AND NOT), comma (OR), and parentheses
# all required mods listed must be present; no prohibited mods can be
requiredMods=
#
# likelihood this template will be chosen relative to all others
# e.g., a weight=6 template is chosen 3X as often as one with weight=2
weight=1
#
# list of dimensions in which this template may spawn, even if generic
# one or more dimension names, separated by commas (blank = all)
dimensionsToSpawnIn=
#
# list of other biomes in which this template may spawn
# biome corresponding to directory is always assumed, listed or not
# generic templates should leave this list empty
biomesToSpawnIn=
#
# criterion expression specifying types of biome where template spawns
# this is in addition to those explicitly listed as biomesToSpawnIn
# generic templates should leave this list empty
biomeTypesToSpawnIn=
#
# list of biomes in which this template may not spawn
# takes precedence over biomeTypesToSpawnIn, but NOT biomesToSpawnIn
# should be empty if biomeTypesToSpawnIn is empty
biomesToNotSpawnIn=
#
# depth template is pushed down into the surface when built
# offset is min/max range of random additional bury depth
embed_into_distance=0
random_height_offset=0,0
#
# whitelist/blacklist of block types on which template may be built
# specify one, not both; leave the other empty (both empty = allow all)
acceptable_target_blocks=
unacceptable_target_blocks=flowing_water,water,flowing_lava,lava
#
# size of template (#layers, #rows per layer, #blocks per row)
dimensions=17,31,29
#
# max number of missing blocks allowed in surface beneath template
allowable_overhang=0
#
# depth/height limit affected by terrain leveling
# also maximum bumpiness tolerated in surface beneath template
max_leveling=2
#
# padding applied to all sides of template horizontal footprint
# expands area affected by terrain leveling (-1 = no leveling)
leveling_buffer=0
#
# do not rotate template randomly when built (1 = no rotation)
preventRotation=0
#
# treat water/lava blocks as air and protect them from rule0 (1 = yes)
preserve_water=0
preserve_lava=0
#
# minimum distance this template must have from instances of itself
uniqueMinDistance=0
#
# min/max distances this template can be from world spawn (0 = no limit)
# only applies to overworld--i.e., dimension 0
spawnMinDistance=0
spawnMaxDistance=0
#
# other template built nearby whenever this one is
# syntax: <name>;<relativeX>;<maxYdifference>;<relativeZ>[;<chance>]
# may be used more than once to specify multiple neighbors
adjoining_template=

rule1=0,100,minecraft:grass-0
rule2=0,100,minecraft:dirt-0
rule3=0,100,minecraft:cobblestone-0
rule4=0,100,minecraft:vine-1
rule5=0,100,minecraft:planks-0
rule6=0,100,minecraft:oak_stairs-3
rule7=0,100,minecraft:vine-8
rule8=0,100,minecraft:web-0
rule9=0,100,minecraft:double_stone_slab-0
rule10=0,100,minecraft:vine-4
rule11=0,100,minecraft:mossy_cobblestone-0
rule12=0,100,minecraft:stone_stairs-6
rule13=0,100,minecraft:stone_stairs-0
rule14=0,100,minecraft:vine-2
rule15=0,100,minecraft:stone_stairs-3
rule16=0,100,minecraft:wool-14
rule17=0,100,minecraft:stone_stairs-2
rule18=0,100,minecraft:stone_stairs-7
rule19=0,100,minecraft:stonebrick-0
rule20=0,100,minecraft:stone_stairs-4
rule21=0,100,minecraft:stonebrick-2
rule22=0,100,minecraft:stonebrick-1
rule23=0,100,minecraft:stone_stairs-1
rule24=0,100,minecraft:stone_stairs-5
rule25=0,100,minecraft:wool-12
rule26=0,100,minecraft:fence-0
rule27=0,100,minecraft:bed-9
rule28=0,100,IInventory;minecraft:chest;minecraft:web#1#0#3+minecraft:web#1#0#15+minecraft:web#1#0#18+minecraft:web#1#0#23-5
rule29=0,100,minecraft:bed-1
rule30=0,100,minecraft:furnace-2
rule31=0,100,minecraft:bed-0
rule32=0,100,minecraft:bed-8
rule33=0,100,minecraft:crafting_table-0
rule34=0,100,minecraft:stone_brick_stairs-4
rule35=0,100,minecraft:bookshelf-0
rule36=0,100,minecraft:lit_furnace-5
rule37=0,100,minecraft:stone_brick_stairs-1
rule38=0,100,IInventory;minecraft:furnace;minecraft:coal#1#0#1-5
rule39=0,100,minecraft:iron_bars-0
rule40=0,100,minecraft:furnace-4
rule41=0,100,minecraft:vine-12
rule42=0,100,minecraft:oak_stairs-5
rule43=0,100,minecraft:vine-10
rule44=0,100,minecraft:stone_brick_stairs-0
rule45=0,100,minecraft:vine-6
rule46=0,100,minecraft:furnace-5
rule47=0,100,minecraft:vine-9
rule48=0,100,minecraft:double_stone_slab-4
rule49=0,100,minecraft:stone_slab-4
rule50=0,100,minecraft:double_stone_slab-3
rule51=0,100,minecraft:stone_slab-3
rule52=0,100,minecraft:stone_brick_stairs-2
rule53=0,100,minecraft:stone_brick_stairs-6
rule54=0,100,minecraft:vine-3
rule55=0,100,minecraft:stone_brick_stairs-3
rule56=0,100,minecraft:vine-5
rule57=0,100,minecraft:stone_brick_stairs-5
rule58=0,100,minecraft:oak_stairs-2
rule59=0,100,minecraft:double_stone_slab-5

layer
1,1,1,1,2,1,2,1,1,1,1,1,1,1,1,1,1,1,1,1,1,1,2,1,2,1,1,1,1
1,1,1,1,1,2,2,1,1,1,1,1,1,1,2,2,1,1,1,1,1,1,2,2,2,1,1,1,1
1,1,1,1,2,2,1,2,1,1,1,1,2,2,2,2,2,1,1,1,1,2,1,1,1,2,1,1,1
1,1,1,1,1,1,2,1,1,1,1,2,2,2,2,2,2,2,1,1,2,2,1,1,1,2,2,1,1
1,2,1,2,1,2,2,2,2,2,2,2,2,2,1,2,2,2,2,1,2,2,1,1,2,2,2,2,1
1,2,2,2,1,2,2,1,2,2,2,2,2,2,1,2,2,2,2,2,2,2,1,2,1,2,1,1,1
1,1,2,1,1,1,1,2,2,1,2,2,2,2,1,2,2,2,2,2,1,1,2,2,2,2,1,2,1
1,1,2,2,2,2,2,2,1,2,2,2,2,2,2,1,2,2,2,2,2,2,2,2,2,2,1,1,1
1,1,1,1,1,1,2,2,2,2,2,2,2,2,1,2,2,2,1,2,1,1,2,2,2,1,1,1,1
1,1,1,1,2,2,2,2,1,1,2,1,2,1,2,1,2,1,2,2,1,1,2,1,1,1,1,1,1
1,1,1,1,2,1,2,1,1,1,2,2,1,2,2,1,2,2,1,2,1,2,1,2,2,1,1,1,1
1,1,1,1,1,2,1,1,1,1,2,2,2,2,1,1,1,2,2,2,1,1,1,2,2,1,1,1,1
1,1,1,2,2,1,2,1,2,2,2,2,2,2,1,1,1,1,2,2,1,1,1,1,2,1,1,1,1
1,1,1,2,1,1,2,2,2,2,1,1,1,2,1,1,2,1,2,2,1,2,1,2,1,1,1,1,1
1,1,2,2,1,2,2,2,2,1,2,2,2,2,1,2,2,1,2,1,2,1,2,2,1,1,1,1,1
1,1,1,1,2,2,2,2,2,2,1,2,2,1,2,2,2,2,2,1,1,2,2,2,1,1,1,1,1
1,1,1,1,2,2,1,1,2,1,1,2,2,1,1,2,1,1,2,1,2,2,2,1,1,1,1,1,1
1,1,2,2,2,2,2,1,2,1,1,1,1,1,2,1,2,1,1,2,1,2,1,2,2,1,1,1,1
1,1,1,2,2,2,2,1,1,2,2,2,1,2,2,2,2,1,1,2,2,2,2,2,1,1,1,1,1
1,1,1,1,2,1,1,1,1,1,2,1,1,2,1,1,2,1,1,1,2,1,2,2,1,1,1,1,1
1,1,1,1,1,2,2,2,1,1,1,1,1,2,2,1,2,1,1,2,2,2,2,2,1,1,1,1,1
1,1,1,1,2,2,2,1,1,1,2,2,1,1,2,1,2,2,2,2,2,1,2,1,2,1,1,1,1
1,1,1,1,1,1,1,2,2,1,1,2,2,2,2,1,2,1,2,2,1,1,1,1,2,1,1,1,1
1,1,1,1,2,1,2,2,2,1,2,2,2,2,2,2,1,1,2,2,2,1,2,1,2,2,2,1,1
1,2,2,1,2,2,2,2,1,1,1,2,2,1,1,2,2,2,1,1,2,2,1,2,2,2,1,2,2
1,2,2,2,2,1,1,2,1,1,2,2,2,2,1,2,2,2,2,2,2,1,1,2,2,2,1,2,1
1,2,2,1,1,2,1,2,1,2,2,2,2,2,2,2,2,2,2,2,1,2,1,2,2,1,2,2,1
1,1,1,2,2,1,2,1,1,1,2,2,2,2,2,2,2,2,1,1,2,1,1,1,1,2,2,1,1
1,1,1,2,2,2,1,2,1,1,1,1,2,2,1,2,2,1,1,1,1,2,1,2,2,2,1,1,1
1,1,1,1,2,2,2,1,1,1,1,1,1,2,2,2,2,1,1,1,1,1,2,2,2,1,1,1,1
1,1,1,1,1,1,2,1,1,1,1,1,1,1,1,1,1,1,1,1,1,1,2,1,2,1,1,1,1
endlayer

layer
0,0,0,0,3,0,3,4,0,0,0,0,0,0,0,0,0,0,0,0,0,0,3,0,3,0,0,0,0
0,0,0,8,3,3,3,0,0,0,0,0,7,6,5,5,0,0,0,0,0,0,3,3,3,4,0,0,0
0,0,0,3,11,3,3,3,0,0,0,10,1,5,5,5,1,4,0,0,0,3,3,9,3,3,0,0,0
0,10,11,3,3,12,3,3,3,4,0,1,1,5,5,5,1,1,8,8,11,3,11,9,3,3,3,7,7
3,3,3,3,3,11,3,3,3,3,3,1,2,3,3,13,2,1,3,3,3,3,3,9,3,3,3,11,3
0,3,3,3,3,16,16,16,11,3,3,1,2,3,11,11,1,1,1,3,3,3,3,3,15,11,3,3,14
3,3,3,3,3,16,16,16,3,3,3,1,2,3,3,17,1,1,3,3,3,3,3,3,3,3,3,3,3
0,0,3,3,3,3,3,16,16,16,16,3,3,3,3,3,3,3,16,16,3,3,3,11,3,3,3,4,14
0,0,8,3,3,3,11,3,3,3,16,16,16,3,3,11,16,16,16,3,3,3,3,3,3,3,0,0,0
0,0,0,14,3,3,11,18,3,3,11,11,16,3,3,11,16,3,3,3,3,3,3,3,17,0,0,0,0
0,0,0,10,3,3,11,15,3,3,11,11,16,16,16,16,16,11,3,3,3,3,3,11,3,0,0,0,0
0,0,0,10,3,3,19,3,11,3,11,3,16,16,16,16,16,3,3,3,13,3,3,3,11,4,0,0,0
0,0,0,3,3,3,19,3,3,3,3,3,3,11,16,11,3,20,3,3,3,3,3,15,3,0,0,0,0
0,0,3,3,3,19,3,3,3,3,3,3,11,3,3,3,3,3,3,3,3,3,11,3,3,0,0,0,0
0,10,3,3,19,3,22,3,3,11,3,3,3,11,15,3,3,15,3,3,3,3,21,3,3,0,0,0,0
0,0,3,17,3,21,21,3,3,3,3,11,3,11,3,3,11,3,3,3,20,19,3,11,22,4,0,0,0
0,0,3,11,3,11,3,17,21,3,23,21,3,21,19,3,19,3,22,21,21,3,3,3,3,4,0,0,0
0,0,3,11,3,3,3,3,11,3,11,3,3,13,11,3,11,11,3,19,3,19,3,3,3,0,0,0,0
0,0,10,11,3,3,11,3,3,22,3,3,3,3,3,3,3,3,3,22,3,3,11,11,3,0,0,0,0
0,0,0,0,3,3,3,3,3,19,3,3,3,11,3,3,3,3,3,11,3,3,19,3,3,4,0,0,0
0,0,0,0,24,11,11,11,3,3,3,11,3,11,11,3,3,3,3,11,3,3,3,3,3,4,0,0,0
0,0,0,10,3,3,3,11,3,19,3,3,3,3,3,3,3,11,3,3,3,3,11,3,3,0,0,0,0
0,0,0,3,3,3,3,3,3,3,3,3,3,11,3,3,3,11,3,3,3,3,3,3,3,3,8,0,0
0,0,15,16,16,16,16,16,3,3,11,3,3,3,3,3,3,3,3,3,3,3,3,3,3,3,3,7,0
3,3,3,16,16,16,16,16,3,3,3,11,3,3,18,3,3,20,11,11,11,3,25,25,25,3,3,3,3
8,3,3,16,16,16,16,16,3,11,1,1,1,3,11,3,2,1,1,3,11,3,25,25,25,3,3,3,0
3,3,3,16,16,16,16,16,11,3,15,1,1,23,3,3,2,1,11,3,3,3,3,3,3,3,3,3,3
0,0,3,3,3,11,11,3,3,0,1,1,1,1,2,2,1,1,14,0,3,3,24,3,3,3,3,0,0
0,0,0,3,3,3,3,3,0,0,0,1,1,2,5,2,1,1,0,0,0,3,3,3,3,3,4,0,0
0,0,0,14,3,3,3,4,0,0,0,0,0,5,5,5,1,8,0,0,0,0,3,3,3,8,0,0,0
0,0,0,0,3,4,3,0,0,0,0,0,0,0,0,0,0,0,0,0,0,0,11,0,3,0,0,0,0
endlayer

layer
0,0,0,0,3,0,3,0,0,0,0,0,0,0,0,0,0,0,0,0,0,0,20,8,3,0,0,0,0
0,0,0,7,12,3,3,0,0,0,0,0,0,0,0,0,0,0,0,0,0,0,11,3,3,0,0,0,0
0,0,26,3,27,28,27,12,26,0,0,0,0,0,0,0,0,0,0,0,0,3,0,14,0,17,0,0,0
0,10,3,26,29,5,29,5,3,4,0,0,0,0,0,0,0,0,7,0,11,4,0,0,0,14,3,0,0
11,3,32,31,5,5,5,5,0,3,11,4,5,13,13,13,5,0,11,3,30,0,0,0,0,0,12,3,3
8,3,0,0,5,5,5,5,8,3,8,0,5,12,11,11,5,0,8,11,30,0,0,0,0,0,0,3,14
3,3,4,0,0,0,0,0,0,3,3,8,5,20,3,3,5,7,3,3,30,0,0,0,0,10,3,3,3
0,0,3,0,0,0,0,7,19,4,10,11,11,3,3,3,3,3,7,0,5,0,0,0,0,5,3,4,14
0,0,0,3,33,33,10,19,21,21,22,21,19,19,21,21,21,22,19,19,21,22,19,7,5,11,0,0,0
0,0,0,14,3,19,0,19,14,19,19,19,22,23,23,23,21,21,19,19,3,22,0,19,3,14,0,0,0
0,0,0,10,3,4,3,14,10,22,0,19,19,21,19,19,19,21,0,19,14,0,11,19,3,0,0,0,0
0,0,0,10,3,0,11,0,0,19,22,19,22,19,19,22,19,19,21,21,4,0,3,21,11,4,0,0,0
0,0,0,10,3,0,3,0,10,19,19,21,19,34,22,22,19,19,21,19,4,0,3,19,11,0,0,0,0
0,0,0,10,11,4,3,0,0,21,19,21,22,19,0,22,22,19,19,19,4,0,3,21,11,4,0,0,0
0,0,0,0,22,0,3,0,0,0,0,0,0,14,14,14,14,0,0,14,0,0,11,21,19,0,0,0,0
0,0,0,0,19,4,3,0,0,0,0,0,0,0,0,0,0,0,0,0,0,0,3,19,19,4,0,0,0
0,0,0,10,8,19,3,4,0,0,0,0,0,0,0,0,0,0,0,0,0,0,3,19,21,4,0,0,0
0,0,0,0,3,21,3,0,0,0,0,0,0,13,13,13,0,0,0,0,0,0,11,21,3,0,0,0,0
0,0,0,0,3,19,3,0,0,0,0,0,0,19,21,19,0,0,0,0,0,0,11,19,3,0,0,0,0
0,0,0,0,11,21,3,0,0,0,0,0,0,19,21,22,0,0,0,0,0,0,3,19,3,0,0,0,0
0,0,0,10,3,19,3,7,0,0,0,7,0,19,19,19,0,0,0,0,7,0,3,21,3,4,0,0,0
0,0,0,0,3,19,19,21,11,3,3,3,3,19,19,19,3,18,3,3,3,19,0,19,11,0,0,0,0
0,0,0,3,3,38,5,5,19,3,3,3,23,21,19,21,11,3,3,3,37,35,36,36,35,3,0,0,0
0,7,3,8,0,0,5,5,22,8,14,14,8,11,3,7,8,7,8,14,21,14,14,0,14,10,3,7,0
3,3,3,0,0,0,5,5,3,3,3,3,3,35,35,35,3,3,3,3,3,0,0,0,0,10,3,3,3
8,3,0,0,0,0,7,5,5,3,4,8,5,3,3,3,5,8,8,3,0,0,0,0,0,0,0,3,8
3,3,3,0,0,0,5,5,3,3,3,0,5,23,23,23,5,0,3,3,3,0,0,0,0,0,3,3,3
0,0,3,39,39,39,39,39,3,14,0,0,0,5,5,5,0,0,0,0,3,0,0,0,0,7,3,0,14
0,0,0,3,40,40,40,11,0,0,0,0,10,5,8,5,0,0,0,0,0,3,40,40,40,3,0,0,0
0,0,0,0,11,11,11,4,0,0,0,0,0,0,0,0,0,0,0,0,0,0,11,3,3,0,0,0,0
0,0,0,0,3,14,3,0,0,0,0,0,0,0,0,0,0,0,0,0,0,0,3,8,11,0,0,0,0
endlayer

layer
0,0,0,10,11,0,3,0,0,0,0,0,0,0,0,0,0,0,0,0,0,0,3,10,11,0,0,0,0
0,0,0,41,19,21,19,0,0,0,0,0,0,0,0,0,0,0,0,0,0,0,19,19,19,0,0,0,0
0,0,0,19,42,5,5,21,0,0,0,0,0,0,0,0,0,0,0,0,0,19,0,14,0,19,0,0,0
0,10,19,5,5,14,5,0,19,0,0,0,0,0,0,0,0,0,7,0,21,4,0,0,0,14,22,4,0
3,21,5,0,14,0,0,0,0,19,11,4,0,0,0,0,0,10,3,21,11,0,0,0,0,0,10,22,3
10,22,0,0,0,0,0,0,0,19,0,0,0,13,13,13,0,0,0,3,5,0,0,0,0,0,0,19,14
11,19,4,0,0,0,0,0,0,22,3,0,0,3,3,3,0,0,3,3,5,0,0,0,0,0,10,22,3
0,0,19,7,0,0,0,0,21,43,10,19,19,3,3,11,21,19,7,0,19,0,0,0,0,8,21,0,14
0,0,0,21,4,0,0,0,19,19,15,8,0,23,23,23,3,11,3,19,21,4,0,7,3,19,0,0,0
0,0,0,14,22,19,0,21,45,22,0,0,0,21,19,44,3,3,3,19,4,19,0,21,3,14,0,0,0
0,0,0,10,22,0,0,14,0,22,0,0,0,0,0,3,3,3,0,21,0,0,0,3,19,0,0,0,0
0,0,0,0,21,0,0,0,0,19,0,0,0,0,0,10,3,8,0,21,0,0,10,3,19,0,0,0,0
0,0,0,10,21,0,0,0,0,21,4,7,0,0,7,0,0,0,10,44,4,0,0,3,19,0,0,0,0
0,0,0,10,19,4,0,0,0,22,19,19,19,21,0,19,4,19,4,21,4,0,0,3,21,4,0,0,0
0,0,0,0,22,0,0,0,0,0,0,0,14,0,14,0,0,0,0,14,0,0,0,3,0,0,0,0,0
0,0,0,0,11,0,0,0,0,0,0,0,0,0,0,0,0,0,0,0,0,0,0,11,3,0,0,0,0
0,0,0,10,7,3,0,0,0,0,0,0,0,0,0,0,0,0,0,0,0,0,0,11,19,4,0,0,0
0,0,0,0,19,3,0,0,0,0,0,0,0,0,0,0,0,0,0,0,0,0,0,3,19,4,0,0,0
0,0,0,0,19,3,0,0,0,0,0,0,0,0,0,0,0,0,0,0,0,0,0,3,19,0,0,0,0
0,0,0,10,19,11,0,0,0,0,0,0,0,13,13,13,0,0,0,0,0,0,0,23,21,0,0,0,0
0,0,0,10,19,3,7,7,0,0,0,0,0,21,21,19,0,0,0,0,0,0,0,3,21,4,0,0,0
0,0,0,0,3,19,19,19,4,0,0,0,0,19,19,21,0,0,0,0,0,22,0,21,19,0,0,0,0
0,0,0,19,0,0,46,21,21,11,3,3,3,21,21,19,3,23,3,3,19,35,3,8,35,19,0,0,0
0,7,22,0,0,0,0,0,5,0,14,14,0,19,19,43,0,0,7,43,0,14,14,0,14,10,19,7,7
11,19,4,0,0,0,0,0,3,3,11,3,3,35,35,35,3,11,3,19,3,0,0,0,0,0,3,21,3
0,21,0,0,0,0,0,0,10,3,47,14,0,23,23,23,0,14,7,19,0,0,0,0,0,0,7,21,7
3,19,0,0,0,0,0,7,11,21,3,0,0,0,0,0,0,0,3,21,3,0,0,0,0,0,3,21,18
0,14,19,4,0,5,5,5,22,14,0,0,0,0,0,0,0,0,14,0,21,7,7,0,0,7,22,0,0
0,0,0,21,50,51,50,19,0,0,0,0,0,0,0,0,0,0,0,0,0,19,48,49,48,21,0,0,0
0,0,0,10,19,22,19,4,0,0,0,0,0,0,0,0,0,0,0,0,0,0,21,19,19,0,0,0,0
0,0,0,0,3,14,3,0,0,0,0,0,0,0,0,0,0,0,0,0,0,0,3,0,3,0,0,0,0
endlayer

layer
0,0,0,10,20,0,3,0,0,0,0,0,0,0,0,0,0,0,0,0,0,0,11,7,3,0,0,0,0
0,0,0,41,21,19,19,0,0,0,0,0,0,0,0,0,0,0,0,0,0,0,21,19,19,7,0,0,0
0,0,0,19,0,0,0,19,0,0,0,0,0,0,0,0,0,0,0,0,0,19,0,0,0,19,4,0,0
0,10,19,4,0,0,0,0,19,0,0,0,0,0,0,0,0,0,0,0,19,4,0,0,0,10,22,4,0
3,19,3,0,0,0,0,0,0,19,3,0,0,0,0,0,0,10,3,21,0,0,0,0,0,0,10,21,3
45,19,0,0,0,0,0,0,0,19,0,0,0,0,0,0,0,0,8,19,4,0,0,0,0,0,10,19,14
3,19,0,0,0,0,0,0,0,19,3,4,0,0,7,0,7,0,3,19,3,0,0,0,0,0,10,22,3
0,0,19,7,0,0,0,0,19,22,19,19,21,22,21,19,19,19,21,19,4,0,0,0,0,10,21,0,14
0,0,0,22,4,7,7,0,19,19,14,0,0,22,19,19,4,0,0,21,52,0,0,7,8,19,0,0,0
0,0,0,14,19,22,21,21,0,19,0,0,0,0,8,3,4,0,0,19,4,21,19,19,21,0,0,0,0
0,0,0,10,21,0,14,14,0,22,0,0,0,0,0,14,0,0,0,19,0,0,0,0,19,0,0,0,0
0,0,0,10,19,0,0,0,0,21,0,0,0,0,0,0,0,0,0,21,0,0,0,10,21,0,0,0,0
0,0,0,10,19,0,0,0,0,19,7,7,0,0,7,0,0,7,10,19,4,0,0,10,19,0,0,0,0
0,0,0,10,22,4,0,0,0,21,9,9,9,21,19,19,0,9,4,22,4,0,0,10,52,0,0,0,0
0,0,0,10,3,0,0,0,0,0,0,14,14,0,14,0,0,0,0,14,0,0,0,0,0,0,0,0,0
0,0,0,0,14,0,0,0,0,0,0,0,0,0,0,0,0,0,0,0,0,0,0,10,3,0,0,0,0
0,0,0,10,0,0,0,0,0,0,0,0,0,0,0,0,0,0,0,0,0,0,0,0,11,0,0,0,0
0,0,0,0,21,0,0,0,0,0,0,0,0,0,0,0,0,0,0,0,0,0,0,10,19,4,0,0,0
0,0,0,0,22,4,0,0,0,0,0,0,0,0,0,0,0,0,0,0,0,0,0,0,21,0,0,0,0
0,0,0,10,21,0,0,0,0,0,0,0,0,0,0,0,0,0,0,0,0,0,0,0,37,4,0,0,0
0,0,0,10,19,7,7,7,0,0,0,0,0,0,0,0,0,0,0,0,0,0,0,10,22,0,0,0,0
0,0,0,0,19,19,19,19,0,0,0,0,0,13,13,13,0,0,0,0,0,21,19,19,22,0,0,0,0
0,0,0,19,0,0,3,0,19,11,3,11,3,19,19,19,3,11,3,3,19,21,3,0,3,21,0,0,0
0,7,19,0,0,0,0,0,7,8,14,14,8,19,3,3,0,8,7,43,14,0,14,0,14,0,19,7,7
3,19,4,0,0,0,0,0,5,21,3,3,3,0,0,23,11,3,3,19,0,0,0,0,0,0,0,53,3
7,19,0,0,0,0,0,0,10,19,47,14,0,0,0,0,0,0,14,19,0,0,0,0,0,0,10,19,47
12,21,0,0,0,0,0,0,5,19,3,0,0,0,0,0,0,0,3,19,7,0,0,0,0,0,10,19,3
0,14,19,0,0,0,0,8,21,14,0,0,0,0,0,0,0,0,14,0,19,7,7,0,0,7,21,0,0
0,0,0,44,5,5,5,22,0,0,0,0,0,0,0,0,0,0,0,0,0,21,3,4,3,21,0,0,0
0,0,0,0,19,19,19,4,0,0,0,0,0,0,0,0,0,0,0,0,0,14,21,19,21,0,0,0,0
0,0,0,0,3,14,3,0,0,0,0,0,0,0,0,0,0,0,0,0,0,0,3,0,3,4,0,0,0
endlayer

layer
0,0,0,10,3,0,3,0,0,0,0,0,0,0,0,0,0,0,0,0,0,0,3,7,3,0,0,0,0
0,0,0,0,37,0,22,7,0,0,0,0,0,0,0,0,0,0,0,0,0,0,19,19,19,7,0,0,0
0,0,0,21,0,0,0,22,0,0,0,0,0,0,0,0,0,0,0,0,0,21,0,0,14,19,47,0,0
0,10,19,54,0,0,0,0,22,4,0,0,0,0,0,0,0,0,0,10,19,0,0,0,0,10,19,4,0
3,21,0,0,0,0,0,0,0,21,3,0,0,0,0,0,0,10,11,19,4,0,0,0,0,0,0,19,3
45,19,4,0,0,0,0,0,10,19,8,0,0,0,0,0,0,0,10,0,4,0,0,0,0,0,0,19,14
3,19,7,0,0,0,0,0,0,19,3,4,7,7,7,0,0,0,3,19,0,0,0,0,0,0,41,21,3
0,0,21,7,0,0,0,0,21,19,19,22,22,19,3,19,19,19,21,21,4,0,0,0,0,10,22,0,14
0,0,0,19,0,7,7,0,19,19,0,14,14,8,3,0,0,0,14,19,55,0,0,7,0,19,0,0,0
0,0,0,14,19,19,19,19,14,19,0,0,0,0,0,0,0,0,0,21,56,21,19,19,19,4,0,0,0
0,0,0,10,19,0,14,14,0,19,0,0,0,0,0,0,0,0,0,19,4,0,0,0,22,0,0,0,0
0,0,0,10,19,0,0,0,0,19,0,0,0,0,0,0,0,0,0,21,0,0,0,0,19,0,0,0,0
0,0,0,10,19,0,0,0,0,3,7,7,0,7,0,0,0,7,10,19,0,0,0,0,19,0,0,0,0
0,0,0,10,19,0,0,0,0,3,21,19,21,3,9,19,0,19,4,21,4,0,0,10,19,0,0,0,0
0,0,0,0,0,0,0,0,0,14,0,14,14,0,14,0,0,0,0,0,0,0,0,0,0,0,0,0,0
0,0,0,0,7,0,0,0,0,0,0,0,0,0,0,0,0,0,0,0,0,0,0,0,0,0,0,0,0
0,0,0,10,21,0,0,0,0,0,0,0,0,0,0,0,0,0,0,0,0,0,0,0,3,0,0,0,0
0,0,0,0,19,0,0,0,0,0,0,0,0,0,0,0,0,0,0,0,0,0,0,10,19,4,0,0,0
0,0,0,10,19,4,0,0,0,0,0,0,0,0,0,0,0,0,0,0,0,0,0,0,19,0,0,0,0
0,0,0,10,19,0,0,0,0,0,0,0,0,0,0,0,0,0,0,0,0,0,0,0,19,4,0,0,0
0,0,0,10,19,7,7,7,0,0,0,0,0,0,0,0,0,0,0,0,0,0,0,0,19,0,0,0,0
0,0,0,0,19,19,3,19,0,0,0,0,0,3,3,3,0,0,0,0,0,19,21,19,19,0,0,0,0
0,0,26,19,0,0,0,0,19,3,3,3,3,3,3,11,3,3,3,3,21,0,0,10,3,19,0,0,0
0,7,19,0,0,0,0,0,0,21,19,19,19,3,17,19,19,19,19,19,4,0,0,0,0,0,19,7,7
3,19,54,0,0,0,0,0,0,22,11,0,0,0,0,0,0,14,3,22,0,0,0,0,0,0,0,19,3
7,26,4,0,0,0,0,0,10,0,0,0,0,0,0,0,0,0,14,19,0,0,0,0,0,0,10,19,4
3,19,7,0,0,0,0,0,0,19,3,0,0,0,0,0,0,10,3,19,7,0,0,0,0,0,10,21,3
0,14,19,0,0,0,0,0,22,14,0,0,0,0,0,0,0,0,0,10,19,47,7,0,0,0,21,0,14
0,0,0,19,3,0,0,21,0,0,0,0,0,0,0,0,0,0,0,0,0,19,3,47,0,57,0,0,0
0,0,0,14,22,19,19,4,0,0,0,0,0,0,0,0,0,0,0,0,0,14,19,19,19,4,0,0,0
0,0,0,0,3,14,11,0,0,0,0,0,0,0,0,0,0,0,0,0,0,0,3,4,3,4,0,0,0
endlayer

layer
0,0,0,10,3,0,3,0,0,0,0,0,0,0,0,0,0,0,0,0,0,0,3,0,3,0,0,0,0
0,0,0,7,19,52,19,7,0,0,0,0,0,0,0,0,0,0,0,0,0,7,19,3,19,4,0,0,0
0,0,0,21,0,0,0,21,0,0,0,0,0,0,0,0,0,0,0,0,7,19,0,0,14,19,7,0,0
0,10,22,14,14,0,0,10,19,4,0,0,0,0,0,0,0,0,0,10,19,0,0,0,0,10,19,4,0
3,19,0,0,0,0,0,0,0,19,3,0,0,0,0,0,0,10,3,22,4,0,0,0,0,0,0,19,3
45,3,4,0,0,0,0,0,10,3,0,0,0,0,0,0,0,0,10,19,4,0,0,0,0,0,10,3,14
3,19,7,0,0,0,0,0,0,19,3,4,7,7,7,0,0,0,3,19,0,0,0,0,0,0,10,19,3
0,0,19,7,0,0,0,0,19,19,19,19,19,3,12,3,22,22,19,44,7,0,0,0,0,0,19,0,14
0,0,26,19,4,7,7,0,19,19,0,14,14,0,0,0,0,0,0,19,19,0,7,0,0,19,0,0,0
0,0,0,0,19,19,19,19,14,19,0,0,0,0,0,0,0,0,0,19,56,19,19,19,19,4,0,0,0
0,0,0,0,19,58,14,14,0,19,0,0,0,0,0,0,0,0,0,19,4,0,0,0,19,0,0,0,0
0,0,0,10,19,58,0,0,0,19,4,0,0,0,0,0,0,0,0,21,0,0,0,0,19,4,0,0,0
0,0,0,10,19,58,0,0,0,19,0,0,0,7,0,0,7,0,7,21,0,0,0,0,19,0,0,0,0
0,0,0,0,19,58,0,0,0,9,19,4,19,9,9,9,21,8,19,9,0,0,0,10,21,0,0,0,0
0,0,0,0,0,58,0,0,0,14,0,0,14,0,0,0,0,0,14,0,0,0,0,0,19,4,0,0,0
0,0,0,0,0,58,0,0,0,0,0,0,0,0,0,0,0,0,0,0,0,0,0,0,0,0,0,0,0
0,0,0,10,21,0,0,0,0,0,0,0,0,0,0,0,0,0,0,0,0,0,0,0,0,0,0,0,0
0,0,0,10,19,0,0,0,0,0,0,0,0,0,0,0,0,0,0,0,0,0,0,0,19,4,0,0,0
0,0,0,0,19,0,0,0,0,0,0,0,0,0,0,0,0,0,0,0,0,0,0,0,19,0,0,0,0
0,0,0,10,19,0,0,0,0,0,0,0,0,0,0,0,0,0,0,0,0,0,0,0,19,0,0,0,0
0,0,0,10,19,7,7,0,0,0,0,0,0,0,0,0,0,0,0,0,0,0,0,0,19,0,0,0,0
0,0,0,0,19,19,19,21,0,0,0,0,0,0,0,0,0,0,0,0,0,19,19,19,19,4,0,0,0
0,0,10,19,0,0,0,0,19,7,0,0,0,7,7,7,0,7,0,7,19,0,0,0,10,19,0,0,0
0,41,19,0,0,0,0,0,0,19,19,19,22,3,19,21,19,19,19,19,4,0,0,0,0,10,19,4,7
3,19,0,0,0,0,0,0,0,19,11,14,0,0,0,0,0,14,3,19,0,0,0,0,0,0,14,19,3
7,19,4,0,0,0,0,0,10,21,4,0,0,0,0,0,0,0,0,3,0,0,0,0,0,0,10,3,4
3,19,7,0,0,0,0,0,0,19,11,0,0,0,0,0,0,10,3,19,0,0,0,0,0,0,7,19,3
14,14,19,0,0,0,0,0,19,14,0,0,0,0,0,0,0,0,0,10,19,47,0,0,0,0,19,0,14
0,0,0,19,0,0,0,19,0,0,0,0,0,0,0,0,0,0,0,0,14,19,0,47,0,19,0,0,0
0,0,0,14,19,3,19,4,0,0,0,0,0,0,0,0,0,0,0,0,0,14,19,3,19,4,0,0,0
0,0,0,0,3,14,3,0,0,0,0,0,0,0,0,0,0,0,0,0,0,0,3,4,3,0,0,0,0
endlayer

layer
0,0,0,0,13,0,13,0,0,0,0,0,0,0,0,0,0,0,0,0,0,0,7,0,7,0,0,0,0
0,0,0,0,3,3,3,7,0,0,0,0,0,0,0,0,0,0,0,0,0,7,3,19,3,4,0,0,0
0,0,0,3,0,0,0,3,0,0,0,0,0,0,0,0,0,0,0,0,7,3,0,0,0,19,7,0,0
0,10,3,14,14,0,0,10,3,4,0,0,0,0,0,0,0,0,0,10,3,0,0,0,0,10,3,4,0
0,3,0,0,0,0,0,0,10,3,0,0,0,0,0,0,0,0,0,3,4,0,0,0,0,0,0,3,4
0,3,4,0,0,0,0,0,10,19,0,0,0,0,0,0,0,0,10,3,0,0,0,0,0,0,10,19,0
10,3,7,0,0,0,0,0,0,3,0,0,0,0,7,7,0,0,10,3,0,0,0,0,0,0,10,3,0
0,14,19,0,0,0,0,0,19,19,19,19,19,3,19,3,19,3,3,3,7,0,0,0,0,0,3,0,0
0,0,0,19,47,0,7,10,19,19,0,0,0,0,14,0,0,0,10,19,19,4,7,0,0,19,0,0,0
0,0,0,0,3,19,19,19,0,19,4,0,0,0,0,0,0,0,0,19,10,19,19,19,3,4,0,0,0
0,0,0,0,3,19,0,0,0,19,0,0,0,0,0,0,0,0,0,19,4,0,14,0,3,0,0,0,0
0,0,0,10,3,19,0,0,10,19,4,0,0,0,0,0,0,0,0,19,4,0,0,0,3,4,0,0,0
0,0,0,10,3,19,0,0,0,3,0,0,0,7,0,0,7,0,7,19,0,0,0,0,3,4,0,0,0
0,0,0,0,3,19,0,0,10,3,0,0,0,9,10,9,9,0,9,19,0,0,0,10,3,4,0,0,0
0,0,0,0,0,19,0,0,0,0,0,0,0,0,0,0,0,0,14,0,0,0,0,0,3,4,0,0,0
0,0,0,0,0,19,0,0,0,0,0,0,0,0,0,0,0,0,0,0,0,0,0,0,0,0,0,0,0
0,0,0,10,3,0,0,0,0,0,0,0,0,0,0,0,0,0,0,0,0,0,0,0,0,0,0,0,0
0,0,0,10,3,0,0,0,0,0,0,0,0,0,0,0,0,0,0,0,0,0,0,0,3,4,0,0,0
0,0,0,0,3,0,0,0,0,0,0,0,0,0,0,0,0,0,0,0,0,0,0,0,3,0,0,0,0
0,0,0,0,3,0,0,0,0,0,0,0,0,0,0,0,0,0,0,0,0,0,0,0,3,0,0,0,0
0,0,0,10,3,0,7,0,0,0,0,0,0,0,0,0,0,0,0,0,0,0,0,0,3,0,0,0,0
0,0,0,10,3,19,19,19,0,0,0,0,0,0,0,0,0,0,0,0,0,19,19,19,3,4,0,0,0
0,0,10,3,0,0,0,0,19,7,7,0,0,0,0,7,0,7,0,10,19,0,0,0,10,19,0,0,0
0,7,3,0,0,0,0,0,0,3,3,3,19,21,21,3,19,19,19,19,4,0,0,0,0,0,19,4,0
0,3,4,0,0,0,0,0,0,3,0,0,0,0,0,0,0,0,10,3,0,0,0,0,0,0,14,3,0
10,3,0,0,0,0,0,0,0,3,4,0,0,0,0,0,0,0,0,19,0,0,0,0,0,0,10,3,0
0,3,0,0,0,0,0,0,0,3,4,0,0,0,0,0,0,0,0,3,0,0,0,0,0,0,7,3,0
0,14,3,0,0,0,0,0,19,54,0,0,0,0,0,0,0,0,0,10,3,47,0,0,0,0,3,4,0
0,0,0,3,7,0,0,3,0,0,0,0,0,0,0,0,0,0,0,0,14,3,0,0,0,19,0,0,0
0,0,0,14,3,19,3,4,0,0,0,0,0,0,0,0,0,0,0,0,0,14,3,19,3,4,0,0,0
0,0,0,0,0,0,14,0,0,0,0,0,0,0,0,0,0,0,0,0,0,0,14,14,14,0,0,0,0
endlayer

layer
0,0,0,0,0,0,0,0,0,0,0,0,0,0,0,0,0,0,0,0,0,0,7,0,7,0,0,0,0
0,0,0,0,17,13,15,0,0,0,0,0,0,0,0,0,0,0,0,0,0,7,19,0,19,4,0,0,0
0,0,0,19,46,46,46,19,0,0,0,0,0,0,0,0,0,0,0,0,7,19,0,0,0,3,0,0,0
0,10,19,14,14,14,0,10,19,4,0,0,0,0,0,0,0,0,0,41,19,0,0,0,0,10,19,4,0
10,19,4,0,0,0,0,0,0,19,0,0,0,0,0,0,0,0,10,19,54,0,0,0,0,0,0,19,4
0,3,4,0,0,0,0,0,0,19,0,0,0,0,0,0,0,0,10,3,4,0,0,0,0,0,10,3,0
10,3,7,0,0,0,0,0,0,19,0,0,0,0,0,7,0,0,10,3,0,0,0,0,0,0,10,19,0
0,14,19,0,0,0,0,0,3,19,19,3,19,3,21,19,19,19,19,3,7,0,0,0,0,0,19,0,0
0,0,0,19,47,0,7,10,19,19,0,0,0,0,0,0,0,0,0,19,19,0,7,7,10,3,0,0,0
0,0,0,14,19,19,19,19,8,19,4,0,0,0,0,0,0,0,10,19,10,19,19,19,3,0,0,0,0
0,0,0,0,19,3,14,0,0,19,4,0,0,0,0,0,0,0,0,19,4,0,0,0,3,0,0,0,0
0,0,0,0,3,3,0,0,0,19,0,0,0,0,0,0,0,0,0,19,0,0,0,0,3,4,0,0,0
0,0,0,0,11,3,0,0,0,19,0,0,0,0,0,0,7,0,0,19,0,0,0,0,3,4,0,0,0
0,0,0,0,3,3,0,0,0,19,0,0,0,19,10,19,19,0,19,19,0,0,0,10,3,4,0,0,0
0,0,0,0,0,11,0,0,0,0,0,0,0,0,0,0,0,0,14,0,0,0,0,0,3,4,0,0,0
0,0,0,0,0,3,0,0,0,0,0,0,0,0,0,0,0,0,0,0,0,0,0,0,0,0,0,0,0
0,0,0,0,0,0,0,0,0,0,0,0,0,0,0,0,0,0,0,0,0,0,0,0,0,0,0,0,0
0,0,0,10,3,0,0,0,0,0,0,0,0,0,0,0,0,0,0,0,0,0,0,0,3,0,0,0,0
0,0,0,0,19,0,0,0,0,0,0,0,0,0,0,0,0,0,0,0,0,0,0,0,3,0,0,0,0
0,0,0,0,19,0,0,0,0,0,0,0,0,0,0,0,0,0,0,0,0,0,0,0,3,0,0,0,0
0,0,0,0,22,0,0,7,0,0,0,0,0,0,0,0,0,0,0,0,0,0,0,0,19,0,0,0,0
0,0,0,0,3,19,19,19,0,0,0,0,0,0,0,0,0,0,0,0,0,19,19,21,19,4,0,0,0
0,0,0,19,0,0,0,0,19,7,7,0,7,0,0,7,0,0,7,10,19,0,0,0,10,19,0,0,0
0,7,19,0,0,0,0,0,0,3,19,19,19,19,0,3,19,3,19,19,14,0,0,0,0,10,19,0,0
0,19,0,0,0,0,0,0,0,3,0,14,0,0,0,14,0,0,10,19,0,0,0,0,0,0,14,3,0
0,19,0,0,0,0,0,0,0,3,0,0,0,0,0,0,0,0,0,19,0,0,0,0,0,0,10,3,0
0,19,0,0,0,0,0,0,0,19,4,0,0,0,0,0,0,0,0,19,0,0,0,0,0,0,0,19,0
0,45,19,0,0,0,0,0,3,4,0,0,0,0,0,0,0,0,0,10,19,47,0,0,0,0,19,4,0
0,0,0,19,7,0,0,19,0,0,0,0,0,0,0,0,0,0,0,0,14,19,0,0,0,3,0,0,0
0,0,0,14,19,19,19,4,0,0,0,0,0,0,0,0,0,0,0,0,0,0,19,19,19,4,0,0,0
0,0,0,0,0,0,14,0,0,0,0,0,0,0,0,0,0,0,0,0,0,0,14,14,14,0,0,0,0
endlayer

layer
0,0,0,0,0,0,0,0,0,0,0,0,0,0,0,0,0,0,0,0,0,0,0,0,0,0,0,0,0
0,0,0,0,19,19,19,0,0,0,0,0,0,0,0,0,0,0,0,0,0,7,19,0,0,0,0,0,0
0,0,10,3,3,4,11,3,0,0,0,0,0,0,0,0,0,0,0,0,7,19,0,0,0,19,0,0,0
0,0,3,0,14,0,0,45,19,0,0,0,0,0,0,0,0,0,0,0,19,14,0,0,0,10,19,4,0
10,3,0,0,0,0,0,0,0,3,0,0,0,0,0,0,0,0,0,19,4,0,0,0,0,0,0,19,0
0,21,0,0,0,0,0,0,10,22,4,0,0,0,0,0,0,0,10,3,4,0,0,0,0,0,0,22,0
10,3,0,0,0,0,0,0,0,3,0,0,0,7,0,7,0,0,10,19,4,0,0,0,0,0,10,19,4
0,14,19,0,0,0,0,0,19,19,19,0,0,3,0,19,19,19,19,19,7,0,0,0,0,0,19,0,0
0,0,0,19,47,0,7,7,19,19,0,0,0,0,0,0,0,0,0,19,19,0,7,7,10,19,0,0,0
0,0,0,14,3,19,19,19,0,19,0,0,0,0,0,0,0,0,10,19,10,19,19,19,19,14,0,0,0
0,0,0,0,0,0,14,0,0,19,4,0,0,0,0,0,0,0,0,19,4,0,0,0,3,0,0,0,0
0,0,0,0,0,0,0,0,0,19,0,0,0,0,0,0,0,0,0,19,0,0,0,0,11,0,0,0,0
0,0,0,0,0,0,0,0,0,19,0,0,0,0,0,0,0,0,0,19,0,0,0,0,3,0,0,0,0
0,0,0,0,19,4,0,0,0,19,0,0,0,0,0,0,19,0,19,19,0,0,0,10,3,4,0,0,0
0,0,0,0,0,0,0,0,0,14,0,0,0,0,0,0,0,0,0,0,0,0,0,0,0,0,0,0,0
0,0,0,0,0,0,0,0,0,0,0,0,0,0,0,0,0,0,0,0,0,0,0,0,0,0,0,0,0
0,0,0,0,0,0,0,0,0,0,0,0,0,0,0,0,0,0,0,0,0,0,0,0,0,0,0,0,0
0,0,0,10,3,0,0,0,0,0,0,0,0,0,0,0,0,0,0,0,0,0,0,10,19,0,0,0,0
0,0,0,0,0,0,0,0,0,0,0,0,0,0,0,0,0,0,0,0,0,0,0,0,3,0,0,0,0
0,0,0,0,0,0,0,0,0,0,0,0,0,0,0,0,0,0,0,0,0,0,0,0,3,0,0,0,0
0,0,0,0,0,0,0,0,0,0,0,0,0,0,0,0,0,0,0,0,0,0,0,0,11,0,0,0,0
0,0,0,0,19,3,19,19,0,0,0,0,0,0,0,0,0,0,0,0,0,19,3,21,3,0,0,0,0
0,0,0,19,0,0,0,0,19,7,0,0,7,0,0,0,0,0,7,10,19,0,0,0,10,19,0,0,0
0,7,19,0,0,0,0,0,0,19,19,19,19,19,0,3,19,19,19,19,14,0,0,0,0,10,19,0,0
0,19,4,0,0,0,0,0,0,19,0,14,14,0,0,0,0,0,10,3,0,0,0,0,0,0,14,3,0
0,3,0,0,0,0,0,0,0,3,0,0,0,0,0,0,0,0,0,21,0,0,0,0,0,0,0,21,4
0,19,0,0,0,0,0,0,0,19,4,0,0,0,0,0,0,0,0,3,0,0,0,0,0,0,0,3,0
0,45,19,7,0,0,0,0,19,4,0,0,0,0,0,0,0,0,0,10,3,0,0,0,0,10,3,4,0
0,0,0,19,7,0,0,19,0,0,0,0,0,0,0,0,0,0,0,0,14,3,0,0,0,19,0,0,0
0,0,0,14,19,0,19,4,0,0,0,0,0,0,0,0,0,0,0,0,0,0,19,59,19,14,0,0,0
0,0,0,0,0,0,14,0,0,0,0,0,0,0,0,0,0,0,0,0,0,0,0,14,0,0,0,0,0
endlayer

layer
0,0,0,0,0,0,0,0,0,0,0,0,0,0,0,0,0,0,0,0,0,0,0,0,0,0,0,0,0
0,0,0,0,19,19,19,7,0,0,0,0,0,0,0,0,0,0,0,0,0,7,0,0,0,0,0,0,0
0,0,10,19,14,0,10,19,7,0,0,0,0,0,0,0,0,0,0,0,7,3,0,0,0,0,0,0,0
0,0,19,0,0,0,0,0,3,0,0,0,0,0,0,0,0,0,0,0,3,14,0,0,0,10,3,4,0
10,19,0,0,0,0,0,0,10,19,0,0,0,0,0,0,0,0,0,3,4,0,0,0,0,0,10,3,0
0,19,4,0,0,0,0,0,10,19,4,0,0,0,0,0,0,0,10,3,4,0,0,0,0,0,0,19,0
10,3,0,0,0,0,0,0,0,19,0,0,0,0,0,7,0,0,10,3,4,0,0,0,0,0,0,3,0
0,14,19,0,0,0,0,0,3,19,0,0,0,0,0,19,0,0,0,3,7,0,0,0,0,10,3,0,0
0,0,0,19,47,0,7,7,19,3,0,0,0,0,0,0,0,0,10,3,19,0,0,0,10,19,0,0,0
0,0,0,45,3,19,19,19,0,11,0,0,0,0,0,0,0,0,10,3,10,19,19,19,3,54,0,0,0
0,0,0,0,0,0,14,0,0,0,0,0,0,0,0,0,0,0,0,0,0,0,0,0,14,0,0,0,0
0,0,0,0,0,0,0,0,0,0,0,0,0,0,0,0,0,0,0,0,0,0,0,0,0,0,0,0,0
0,0,0,0,0,0,0,0,0,0,0,0,0,0,0,0,0,0,0,0,0,0,0,0,0,0,0,0,0
0,0,0,0,19,0,0,0,0,0,0,0,0,0,0,0,0,0,0,0,0,0,0,10,3,0,0,0,0
0,0,0,0,0,0,0,0,0,0,0,0,0,0,0,0,0,0,0,0,0,0,0,0,0,0,0,0,0
0,0,0,0,0,0,0,0,0,0,0,0,0,0,0,0,0,0,0,0,0,0,0,0,0,0,0,0,0
0,0,0,0,0,0,0,0,0,0,0,0,0,0,0,0,0,0,0,0,0,0,0,0,0,0,0,0,0
0,0,0,0,3,0,0,0,0,0,0,0,0,0,0,0,0,0,0,0,0,0,0,10,19,0,0,0,0
0,0,0,0,14,0,0,0,0,0,0,0,0,0,0,0,0,0,0,0,0,0,0,0,14,0,0,0,0
0,0,0,0,0,0,0,0,0,0,0,0,0,0,0,0,0,0,0,0,0,0,0,0,0,0,0,0,0
0,0,0,0,0,0,0,0,0,0,0,0,0,0,0,0,0,0,0,0,0,0,0,0,7,0,0,0,0
0,0,0,0,3,19,19,19,0,0,0,0,0,0,0,0,0,0,0,0,0,19,19,19,3,0,0,0,0
0,0,0,3,0,0,0,10,19,4,0,0,0,0,0,0,0,0,0,10,19,0,0,0,10,19,0,0,0
0,41,3,0,0,0,0,0,0,3,0,0,0,0,0,3,0,0,0,19,14,0,0,0,0,10,19,7,0
0,3,4,0,0,0,0,0,10,3,4,0,0,0,0,0,0,0,0,19,0,0,0,0,0,0,45,3,0
10,19,0,0,0,0,0,0,0,3,0,0,0,0,0,0,0,0,0,19,0,0,0,0,0,0,0,19,4
0,3,0,0,0,0,0,0,0,3,4,0,0,0,0,0,0,0,0,19,0,0,0,0,0,0,0,19,0
0,45,3,7,0,0,0,0,19,0,0,0,0,0,0,0,0,0,0,10,19,0,0,0,0,10,19,4,0
0,0,0,3,47,0,0,3,0,0,0,0,0,0,0,0,0,0,0,0,14,19,0,0,0,19,0,0,0
0,0,0,45,19,0,19,0,0,0,0,0,0,0,0,0,0,0,0,0,0,14,19,0,19,14,0,0,0
0,0,0,0,0,0,14,0,0,0,0,0,0,0,0,0,0,0,0,0,0,0,0,0,0,0,0,0,0
endlayer

layer
0,0,0,0,0,0,0,0,0,0,0,0,0,0,0,0,0,0,0,0,0,0,0,0,0,0,0,0,0
0,0,0,10,19,59,19,47,0,0,0,0,0,0,0,0,0,0,0,0,0,0,0,0,0,0,0,0,0
0,0,10,19,14,0,14,19,7,0,0,0,0,0,0,0,0,0,0,0,7,19,0,0,0,0,0,0,0
0,7,19,14,0,0,0,0,19,4,0,0,0,0,0,0,0,0,0,7,19,14,0,0,0,10,19,0,0
10,19,0,0,0,0,0,0,10,19,0,0,0,0,0,0,0,0,10,19,4,0,0,0,0,0,45,19,0
0,19,4,0,0,0,0,0,10,19,0,0,0,0,0,0,0,0,10,19,4,0,0,0,0,0,10,19,4
10,19,0,0,0,0,0,0,0,19,4,0,0,0,0,0,0,0,10,3,4,0,0,0,0,0,0,19,0
0,0,19,0,0,0,0,0,0,19,0,0,0,0,0,0,0,0,0,3,7,0,0,0,0,10,19,0,0
0,0,0,19,4,0,7,7,0,14,0,0,0,0,0,0,0,0,0,8,19,0,0,0,10,19,0,0,0
0,0,0,45,3,19,19,19,0,0,0,0,0,0,0,0,0,0,0,0,10,19,19,19,3,4,0,0,0
0,0,0,0,0,0,14,14,0,0,0,0,0,0,0,0,0,0,0,0,0,0,14,0,14,0,0,0,0
0,0,0,0,0,0,0,0,0,0,0,0,0,0,0,0,0,0,0,0,0,0,0,0,0,0,0,0,0
0,0,0,0,0,0,0,0,0,0,0,0,0,0,0,0,0,0,0,0,0,0,0,0,0,0,0,0,0
0,0,0,0,3,0,0,0,0,0,0,0,0,0,0,0,0,0,0,0,0,0,0,10,3,0,0,0,0
0,0,0,0,0,0,0,0,0,0,0,0,0,0,0,0,0,0,0,0,0,0,0,0,0,0,0,0,0
0,0,0,0,0,0,0,0,0,0,0,0,0,0,0,0,0,0,0,0,0,0,0,0,0,0,0,0,0
0,0,0,0,0,0,0,0,0,0,0,0,0,0,0,0,0,0,0,0,0,0,0,0,0,0,0,0,0
0,0,0,10,3,0,0,0,0,0,0,0,0,0,0,0,0,0,0,0,0,0,0,0,3,4,0,0,0
0,0,0,0,14,0,0,0,0,0,0,0,0,0,0,0,0,0,0,0,0,0,0,0,14,0,0,0,0
0,0,0,0,0,0,0,0,0,0,0,0,0,0,0,0,0,0,0,0,0,0,0,0,0,0,0,0,0
0,0,0,0,7,0,0,0,0,0,0,0,0,0,0,0,0,0,0,0,0,0,0,0,7,0,0,0,0
0,0,0,0,3,19,19,19,0,0,0,0,0,0,0,0,0,0,0,0,0,19,19,19,3,0,0,0,0
0,0,0,19,0,0,0,10,19,4,0,0,0,0,0,0,0,0,0,41,19,0,0,0,0,19,0,0,0
0,0,19,4,0,0,0,0,0,3,0,0,0,0,0,19,0,0,0,19,14,0,0,0,0,14,19,7,0
10,19,4,0,0,0,0,0,10,3,4,0,0,0,0,0,0,0,0,19,0,0,0,0,0,0,45,19,0
0,19,0,0,0,0,0,0,0,19,0,0,0,0,0,0,0,0,0,19,0,0,0,0,0,0,0,19,4
0,19,0,0,0,0,0,0,0,19,0,0,0,0,0,0,0,0,0,19,0,0,0,0,0,0,0,19,4
0,45,19,7,0,0,0,0,19,4,0,0,0,0,0,0,0,0,0,45,19,7,0,0,0,10,19,4,0
0,0,0,19,47,0,0,19,0,0,0,0,0,0,0,0,0,0,0,0,10,19,0,0,0,19,14,0,0
0,0,0,0,3,0,0,0,0,0,0,0,0,0,0,0,0,0,0,0,0,14,3,0,3,14,0,0,0
0,0,0,0,0,0,0,0,0,0,0,0,0,0,0,0,0,0,0,0,0,0,0,0,0,0,0,0,0
endlayer

layer
0,0,0,0,0,0,0,0,0,0,0,0,0,0,0,0,0,0,0,0,0,0,0,0,0,0,0,0,0
0,0,0,7,3,0,3,7,0,0,0,0,0,0,0,0,0,0,0,0,0,0,0,0,0,0,0,0,0
0,0,0,19,0,0,14,19,0,0,0,0,0,0,0,0,0,0,0,0,10,19,0,0,0,0,0,0,0
0,7,19,0,0,0,0,0,19,0,0,0,0,0,0,0,0,0,0,7,19,14,0,0,0,0,19,0,0
0,19,14,0,0,0,0,0,10,19,0,0,0,0,0,0,0,0,10,19,4,0,0,0,0,0,0,19,0
0,59,4,0,0,0,0,0,0,0,0,0,0,0,0,0,0,0,10,19,4,0,0,0,0,0,10,19,4
10,19,7,0,0,0,0,0,10,19,0,0,0,0,0,0,0,0,0,19,4,0,0,0,0,0,10,19,0
0,0,19,0,0,0,0,0,0,19,0,0,0,0,0,0,0,0,0,19,7,0,0,0,0,0,19,0,0
0,0,0,19,4,0,7,0,0,14,0,0,0,0,0,0,0,0,0,0,19,4,0,0,0,19,14,0,0
0,0,0,0,3,19,19,19,0,0,0,0,0,0,0,0,0,0,0,0,0,19,19,19,19,4,0,0,0
0,0,0,0,0,0,14,14,0,0,0,0,0,0,0,0,0,0,0,0,0,0,14,0,14,0,0,0,0
0,0,0,0,0,0,0,0,0,0,0,0,0,0,0,0,0,0,0,0,0,0,0,0,0,0,0,0,0
0,0,0,0,7,0,0,0,0,0,0,0,0,0,0,0,0,0,0,0,0,0,0,0,0,0,0,0,0
0,0,0,0,3,0,0,0,0,0,0,0,0,0,0,0,0,0,0,0,0,0,0,0,3,0,0,0,0
0,0,0,0,0,0,0,0,0,0,0,0,0,0,0,0,0,0,0,0,0,0,0,0,0,0,0,0,0
0,0,0,0,0,0,0,0,0,0,0,0,0,0,0,0,0,0,0,0,0,0,0,0,0,0,0,0,0
0,0,0,0,0,0,0,0,0,0,0,0,0,0,0,0,0,0,0,0,0,0,0,0,0,0,0,0,0
0,0,0,0,3,4,0,0,0,0,0,0,0,0,0,0,0,0,0,0,0,0,0,0,3,4,0,0,0
0,0,0,0,14,0,0,0,0,0,0,0,0,0,0,0,0,0,0,0,0,0,0,0,14,0,0,0,0
0,0,0,0,0,0,0,0,0,0,0,0,0,0,0,0,0,0,0,0,0,0,0,0,0,0,0,0,0
0,0,0,0,7,0,0,0,0,0,0,0,0,0,0,0,0,0,0,0,0,0,0,0,7,0,0,0,0
0,0,0,0,19,19,19,19,4,0,0,0,0,0,0,0,0,0,0,0,0,19,19,19,3,0,0,0,0
0,0,0,19,0,0,0,10,19,0,0,0,0,0,0,0,0,0,0,0,19,0,0,0,0,59,0,0,0
0,10,19,4,0,0,0,0,0,19,0,0,0,0,0,0,0,0,0,19,14,0,0,0,0,14,19,7,0
10,19,4,0,0,0,0,0,10,19,4,0,0,0,0,0,0,0,0,19,0,0,0,0,0,0,14,19,0
0,19,0,0,0,0,0,0,0,19,0,0,0,0,0,0,0,0,0,59,0,0,0,0,0,0,0,59,0
0,19,0,0,0,0,0,0,0,19,4,0,0,0,0,0,0,0,0,19,4,0,0,0,0,0,7,19,4
0,10,19,7,0,0,0,0,19,4,0,0,0,0,0,0,0,0,0,45,19,7,0,0,0,10,19,4,0
0,0,0,19,0,0,0,19,0,0,0,0,0,0,0,0,0,0,0,0,10,19,0,0,0,19,54,0,0
0,0,0,0,0,0,0,0,0,0,0,0,0,0,0,0,0,0,0,0,0,14,0,0,0,14,0,0,0
0,0,0,0,0,0,0,0,0,0,0,0,0,0,0,0,0,0,0,0,0,0,0,0,0,0,0,0,0
endlayer

layer
0,0,0,0,0,0,0,0,0,0,0,0,0,0,0,0,0,0,0,0,0,0,0,0,0,0,0,0,0
0,0,0,7,0,0,0,7,0,0,0,0,0,0,0,0,0,0,0,0,0,0,0,0,0,0,0,0,0
0,0,0,19,0,0,0,19,4,0,0,0,0,0,0,0,0,0,0,0,10,19,0,0,0,0,0,0,0
0,0,19,4,0,0,0,0,0,0,0,0,0,0,0,0,0,0,0,0,19,14,0,0,0,0,19,0,0
0,19,54,0,0,0,0,0,0,19,0,0,0,0,0,0,0,0,10,19,4,0,0,0,0,0,0,19,0
0,0,0,0,0,0,0,0,0,0,0,0,0,0,0,0,0,0,0,59,4,0,0,0,0,0,10,59,0
0,19,47,0,0,0,0,0,0,19,0,0,0,0,0,0,0,0,0,19,4,0,0,0,0,0,10,19,0
0,0,19,0,0,0,0,0,0,19,0,0,0,0,0,0,0,0,0,19,0,0,0,0,0,0,19,0,0
0,0,0,19,0,0,7,0,0,14,0,0,0,0,0,0,0,0,0,0,19,4,0,0,0,59,0,0,0
0,0,0,0,3,19,19,19,0,0,0,0,0,0,0,0,0,0,0,0,14,19,19,19,19,0,0,0,0
0,0,0,0,0,0,0,0,0,0,0,0,0,0,0,0,0,0,0,0,0,0,14,0,14,0,0,0,0
0,0,0,0,0,0,0,0,0,0,0,0,0,0,0,0,0,0,0,0,0,0,0,0,0,0,0,0,0
0,0,0,0,7,0,0,0,0,0,0,0,0,0,0,0,0,0,0,0,0,0,0,0,7,0,0,0,0
0,0,0,10,3,0,0,0,0,0,0,0,0,0,0,0,0,0,0,0,0,0,0,0,3,0,0,0,0
0,0,0,0,0,0,0,0,0,0,0,0,0,0,0,0,0,0,0,0,0,0,0,0,0,0,0,0,0
0,0,0,0,0,0,0,0,0,0,0,0,0,0,0,0,0,0,0,0,0,0,0,0,0,0,0,0,0
0,0,0,0,0,0,0,0,0,0,0,0,0,0,0,0,0,0,0,0,0,0,0,0,0,0,0,0,0
0,0,0,0,3,0,0,0,0,0,0,0,0,0,0,0,0,0,0,0,0,0,0,0,3,4,0,0,0
0,0,0,0,14,0,0,0,0,0,0,0,0,0,0,0,0,0,0,0,0,0,0,0,0,0,0,0,0
0,0,0,0,0,0,0,0,0,0,0,0,0,0,0,0,0,0,0,0,0,0,0,0,0,0,0,0,0
0,0,0,0,7,0,0,0,0,0,0,0,0,0,0,0,0,0,0,0,0,7,0,0,0,0,0,0,0
0,0,0,0,19,19,3,19,4,0,0,0,0,0,0,0,0,0,0,0,0,19,19,0,3,0,0,0,0
0,0,7,19,0,0,0,10,3,0,0,0,0,0,0,0,0,0,0,0,19,0,0,0,0,0,7,0,0
0,10,19,0,0,0,0,0,0,19,0,0,0,0,0,0,0,0,0,19,54,0,0,0,0,10,19,47,0
0,19,0,0,0,0,0,0,10,19,0,0,0,0,0,0,0,0,10,19,0,0,0,0,0,0,14,19,0
0,59,0,0,0,0,0,0,0,59,0,0,0,0,0,0,0,0,0,8,0,0,0,0,0,0,0,7,0
0,19,0,0,0,0,0,0,10,19,4,0,0,0,0,0,0,0,0,19,7,0,0,0,0,0,7,19,4
0,10,19,0,0,0,0,0,0,14,0,0,0,0,0,0,0,0,0,45,19,7,0,0,0,0,19,54,0
0,0,14,19,0,0,0,19,0,0,0,0,0,0,0,0,0,0,0,0,10,19,0,0,0,59,0,0,0
0,0,0,0,0,0,0,0,0,0,0,0,0,0,0,0,0,0,0,0,0,0,0,0,0,0,0,0,0
0,0,0,0,0,0,0,0,0,0,0,0,0,0,0,0,0,0,0,0,0,0,0,0,0,0,0,0,0
endlayer

layer
0,0,0,0,0,0,0,0,0,0,0,0,0,0,0,0,0,0,0,0,0,0,0,0,0,0,0,0,0
0,0,0,7,0,0,0,0,0,0,0,0,0,0,0,0,0,0,0,0,0,0,0,0,0,0,0,0,0
0,0,0,19,0,0,10,19,4,0,0,0,0,0,0,0,0,0,0,0,41,19,0,0,0,0,0,0,0
0,0,19,0,0,0,0,0,0,0,0,0,0,0,0,0,0,0,0,0,19,14,0,0,0,0,0,0,0
0,19,0,0,0,0,0,0,0,19,0,0,0,0,0,0,0,0,10,19,4,0,0,0,0,0,0,19,0
0,0,0,0,0,0,0,0,0,0,0,0,0,0,0,0,0,0,0,0,0,0,0,0,0,0,0,0,0
0,19,0,0,0,0,0,0,0,19,0,0,0,0,0,0,0,0,0,19,0,0,0,0,0,0,0,19,4
0,0,19,0,0,0,0,0,0,19,0,0,0,0,0,0,0,0,0,19,0,0,0,0,0,0,19,14,0
0,0,0,19,0,0,0,0,0,0,0,0,0,0,0,0,0,0,0,0,3,0,0,0,0,0,0,0,0
0,0,0,0,19,19,19,3,0,0,0,0,0,0,0,0,0,0,0,0,0,3,19,19,19,4,0,0,0
0,0,0,0,0,0,0,0,0,0,0,0,0,0,0,0,0,0,0,0,0,0,0,0,0,0,0,0,0
0,0,0,0,0,0,0,0,0,0,0,0,0,0,0,0,0,0,0,0,0,0,0,0,0,0,0,0,0
0,0,0,0,0,0,0,0,0,0,0,0,0,0,0,0,0,0,0,0,0,0,0,0,0,0,0,0,0
0,0,0,0,3,0,0,0,0,0,0,0,0,0,0,0,0,0,0,0,0,0,0,0,3,0,0,0,0
0,0,0,0,0,0,0,0,0,0,0,0,0,0,0,0,0,0,0,0,0,0,0,0,0,0,0,0,0
0,0,0,0,0,0,0,0,0,0,0,0,0,0,0,0,0,0,0,0,0,0,0,0,0,0,0,0,0
0,0,0,0,0,0,0,0,0,0,0,0,0,0,0,0,0,0,0,0,0,0,0,0,0,0,0,0,0
0,0,0,0,3,0,0,0,0,0,0,0,0,0,0,0,0,0,0,0,0,0,0,0,3,4,0,0,0
0,0,0,0,0,0,0,0,0,0,0,0,0,0,0,0,0,0,0,0,0,0,0,0,0,0,0,0,0
0,0,0,0,0,0,0,0,0,0,0,0,0,0,0,0,0,0,0,0,0,0,0,0,0,0,0,0,0
0,0,0,0,0,0,0,0,0,0,0,0,0,0,0,0,0,0,0,0,0,0,0,0,7,0,0,0,0
0,0,0,0,19,19,0,3,0,0,0,0,0,0,0,0,0,0,0,0,0,3,19,0,19,0,0,0,0
0,0,0,19,0,0,0,0,0,0,0,0,0,0,0,0,0,0,0,0,3,0,0,0,0,0,0,0,0
0,10,19,0,0,0,0,0,0,19,0,0,0,0,0,0,0,0,0,19,0,0,0,0,0,10,19,0,0
0,19,0,0,0,0,0,0,0,19,0,0,0,0,0,0,0,0,10,19,0,0,0,0,0,0,14,19,0
0,0,0,0,0,0,0,0,0,7,0,0,0,0,0,0,0,0,0,0,0,0,0,0,0,0,0,0,0
0,19,0,0,0,0,0,0,10,19,4,0,0,0,0,0,0,0,0,19,7,0,0,0,0,0,7,19,0
0,10,19,0,0,0,0,0,0,0,0,0,0,0,0,0,0,0,0,0,19,47,0,0,0,0,19,54,0
0,0,45,19,0,0,0,19,0,0,0,0,0,0,0,0,0,0,0,0,0,19,0,0,0,0,0,0,0
0,0,0,0,0,0,0,0,0,0,0,0,0,0,0,0,0,0,0,0,0,0,0,0,0,0,0,0,0
0,0,0,0,0,0,0,0,0,0,0,0,0,0,0,0,0,0,0,0,0,0,0,0,0,0,0,0,0
endlayer

layer
0,0,0,0,0,0,0,0,0,0,0,0,0,0,0,0,0,0,0,0,0,0,0,0,0,0,0,0,0
0,0,0,7,0,0,0,0,0,0,0,0,0,0,0,0,0,0,0,0,0,0,0,0,0,0,0,0,0
0,0,0,59,0,0,0,59,4,0,0,0,0,0,0,0,0,0,0,0,0,59,0,0,0,0,0,0,0
0,0,59,0,0,0,0,0,0,0,0,0,0,0,0,0,0,0,0,0,59,14,0,0,0,0,0,0,0
0,3,0,0,0,0,0,0,0,0,0,0,0,0,0,0,0,0,0,3,0,0,0,0,0,0,0,3,0
0,0,0,0,0,0,0,0,0,0,0,0,0,0,0,0,0,0,0,0,0,0,0,0,0,0,0,0,0
0,3,3,0,0,0,0,0,0,0,0,0,0,0,0,0,0,0,0,3,0,0,0,0,0,0,0,3,4
0,0,0,0,0,0,0,0,0,0,0,0,0,0,0,0,0,0,0,14,0,0,0,0,0,0,0,0,0
0,0,0,0,0,0,0,0,0,0,0,0,0,0,0,0,0,0,0,0,0,0,0,0,0,0,0,0,0
0,0,0,0,0,0,0,0,0,0,0,0,0,0,0,0,0,0,0,0,0,0,3,0,3,0,0,0,0
0,0,0,0,0,0,0,0,0,0,0,0,0,0,0,0,0,0,0,0,0,0,0,0,0,0,0,0,0
0,0,0,0,0,0,0,0,0,0,0,0,0,0,0,0,0,0,0,0,0,0,0,0,0,0,0,0,0
0,0,0,0,0,0,0,0,0,0,0,0,0,0,0,0,0,0,0,0,0,0,0,0,0,0,0,0,0
0,0,0,0,0,0,0,0,0,0,0,0,0,0,0,0,0,0,0,0,0,0,0,0,3,0,0,0,0
0,0,0,0,0,0,0,0,0,0,0,0,0,0,0,0,0,0,0,0,0,0,0,0,0,0,0,0,0
0,0,0,0,0,0,0,0,0,0,0,0,0,0,0,0,0,0,0,0,0,0,0,0,0,0,0,0,0
0,0,0,0,0,0,0,0,0,0,0,0,0,0,0,0,0,0,0,0,0,0,0,0,0,0,0,0,0
0,0,0,0,0,0,0,0,0,0,0,0,0,0,0,0,0,0,0,0,0,0,0,0,3,0,0,0,0
0,0,0,0,0,0,0,0,0,0,0,0,0,0,0,0,0,0,0,0,0,0,0,0,0,0,0,0,0
0,0,0,0,0,0,0,0,0,0,0,0,0,0,0,0,0,0,0,0,0,0,0,0,0,0,0,0,0
0,0,0,0,0,0,0,0,0,0,0,0,0,0,0,0,0,0,0,0,0,0,0,0,7,0,0,0,0
0,0,0,0,0,0,0,0,0,0,0,0,0,0,0,0,0,0,0,0,0,0,3,0,3,0,0,0,0
0,0,0,59,0,0,0,0,0,0,0,0,0,0,0,0,0,0,0,0,0,0,0,0,0,0,0,0,0
0,0,0,0,0,0,0,0,0,7,0,0,0,0,0,0,0,0,0,0,0,0,0,0,0,10,59,0,0
0,3,0,0,0,0,0,0,0,3,0,0,0,0,0,0,0,0,10,3,0,0,0,0,0,0,0,3,0
0,0,0,0,0,0,0,0,0,7,0,0,0,0,0,0,0,0,0,0,0,0,0,0,0,0,0,0,0
0,3,0,0,0,0,0,0,0,3,0,0,0,0,0,0,0,0,0,3,0,0,0,0,0,0,0,3,0
0,0,59,0,0,0,0,0,0,0,0,0,0,0,0,0,0,0,0,10,59,47,0,0,0,0,59,54,0
0,0,0,59,0,0,0,0,0,0,0,0,0,0,0,0,0,0,0,0,0,59,0,0,0,0,0,0,0
0,0,0,0,0,0,0,0,0,0,0,0,0,0,0,0,0,0,0,0,0,0,0,0,0,0,0,0,0
0,0,0,0,0,0,0,0,0,0,0,0,0,0,0,0,0,0,0,0,0,0,0,0,0,0,0,0,0
endlayer

layer
0,0,0,0,0,0,0,0,0,0,0,0,0,0,0,0,0,0,0,0,0,0,0,0,0,0,0,0,0
0,0,0,0,0,0,0,0,0,0,0,0,0,0,0,0,0,0,0,0,0,0,0,0,0,0,0,0,0
0,0,0,0,0,0,0,0,0,0,0,0,0,0,0,0,0,0,0,0,0,0,0,0,0,0,0,0,0
0,0,0,0,0,0,0,0,0,0,0,0,0,0,0,0,0,0,0,0,0,0,0,0,0,0,0,0,0
0,0,0,0,0,0,0,0,0,0,0,0,0,0,0,0,0,0,0,0,0,0,0,0,0,0,0,0,0
0,0,0,0,0,0,0,0,0,0,0,0,0,0,0,0,0,0,0,0,0,0,0,0,0,0,0,0,0
0,0,0,0,0,0,0,0,0,0,0,0,0,0,0,0,0,0,0,0,0,0,0,0,0,0,0,0,0
0,0,0,0,0,0,0,0,0,0,0,0,0,0,0,0,0,0,0,0,0,0,0,0,0,0,0,0,0
0,0,0,0,0,0,0,0,0,0,0,0,0,0,0,0,0,0,0,0,0,0,0,0,0,0,0,0,0
0,0,0,0,0,0,0,0,0,0,0,0,0,0,0,0,0,0,0,0,0,0,0,0,0,0,0,0,0
0,0,0,0,0,0,0,0,0,0,0,0,0,0,0,0,0,0,0,0,0,0,0,0,0,0,0,0,0
0,0,0,0,0,0,0,0,0,0,0,0,0,0,0,0,0,0,0,0,0,0,0,0,0,0,0,0,0
0,0,0,0,0,0,0,0,0,0,0,0,0,0,0,0,0,0,0,0,0,0,0,0,0,0,0,0,0
0,0,0,0,0,0,0,0,0,0,0,0,0,0,0,0,0,0,0,0,0,0,0,0,0,0,0,0,0
0,0,0,0,0,0,0,0,0,0,0,0,0,0,0,0,0,0,0,0,0,0,0,0,0,0,0,0,0
0,0,0,0,0,0,0,0,0,0,0,0,0,0,0,0,0,0,0,0,0,0,0,0,0,0,0,0,0
0,0,0,0,0,0,0,0,0,0,0,0,0,0,0,0,0,0,0,0,0,0,0,0,0,0,0,0,0
0,0,0,0,0,0,0,0,0,0,0,0,0,0,0,0,0,0,0,0,0,0,0,0,0,0,0,0,0
0,0,0,0,0,0,0,0,0,0,0,0,0,0,0,0,0,0,0,0,0,0,0,0,0,0,0,0,0
0,0,0,0,0,0,0,0,0,0,0,0,0,0,0,0,0,0,0,0,0,0,0,0,0,0,0,0,0
0,0,0,0,0,0,0,0,0,0,0,0,0,0,0,0,0,0,0,0,0,0,0,0,7,0,0,0,0
0,0,0,0,0,0,0,0,0,0,0,0,0,0,0,0,0,0,0,0,0,0,3,0,3,0,0,0,0
0,0,0,0,0,0,0,0,0,0,0,0,0,0,0,0,0,0,0,0,0,0,0,0,0,0,0,0,0
0,0,0,0,0,0,0,0,0,7,0,0,0,0,0,0,0,0,0,0,0,0,0,0,0,0,0,7,0
0,0,0,0,0,0,0,0,0,3,0,0,0,0,0,0,0,0,10,3,0,0,0,0,0,0,0,3,0
0,0,0,0,0,0,0,0,0,7,0,0,0,0,0,0,0,0,0,0,0,0,0,0,0,0,0,0,0
0,0,0,0,0,0,0,0,0,3,0,0,0,0,0,0,0,0,0,3,0,0,0,0,0,0,0,0,0
0,0,0,0,0,0,0,0,0,0,0,0,0,0,0,0,0,0,0,0,0,0,0,0,0,0,0,0,0
0,0,0,0,0,0,0,0,0,0,0,0,0,0,0,0,0,0,0,0,0,0,0,0,0,0,0,0,0
0,0,0,0,0,0,0,0,0,0,0,0,0,0,0,0,0,0,0,0,0,0,0,0,0,0,0,0,0
0,0,0,0,0,0,0,0,0,0,0,0,0,0,0,0,0,0,0,0,0,0,0,0,0,0,0,0,0
endlayer

