
# Created by Ruins mod version 17.2 Ingame Parser
# authoring Player: BARTLLOW

# TEMPLATE PARAMETER SETTINGS:
#
# criterion expression specifying mod ids required to load template
# may include plus (AND), minus (AND NOT), comma (OR), and parentheses
# all required mods listed must be present; no prohibited mods can be
requiredMods=
#
# likelihood this template will be chosen relative to all others
# e.g., a weight=6 template is chosen 3X as often as one with weight=2
weight=1
#
# list of dimensions in which this template may spawn, even if generic
# one or more dimension names, separated by commas (blank = all)
dimensionsToSpawnIn=
#
# list of other biomes in which this template may spawn
# biome corresponding to directory is always assumed, listed or not
# generic templates should leave this list empty
biomesToSpawnIn=
#
# criterion expression specifying types of biome where template spawns
# this is in addition to those explicitly listed as biomesToSpawnIn
# generic templates should leave this list empty
biomeTypesToSpawnIn=
#
# list of biomes in which this template may not spawn
# takes precedence over biomeTypesToSpawnIn, but NOT biomesToSpawnIn
# should be empty if biomeTypesToSpawnIn is empty
biomesToNotSpawnIn=
#
# depth template is pushed down into the surface when built
# offset is min/max range of random additional bury depth
embed_into_distance=0
random_height_offset=0,0
#
# whitelist/blacklist of block types on which template may be built
# specify one, not both; leave the other empty (both empty = allow all)
acceptable_target_blocks=
unacceptable_target_blocks=flowing_water,water,flowing_lava,lava
#
# size of template (#layers, #rows per layer, #blocks per row)
dimensions=6,13,21
#
# max number of missing blocks allowed in surface beneath template
allowable_overhang=0
#
# depth/height limit affected by terrain leveling
# also maximum bumpiness tolerated in surface beneath template
max_leveling=2
#
# padding applied to all sides of template horizontal footprint
# expands area affected by terrain leveling (-1 = no leveling)
leveling_buffer=0
#
# do not rotate template randomly when built (1 = no rotation)
preventRotation=0
#
# treat water/lava blocks as air and protect them from rule0 (1 = yes)
preserve_water=0
preserve_lava=0
#
# minimum distance this template must have from instances of itself
uniqueMinDistance=0
#
# min/max distances this template can be from world spawn (0 = no limit)
# only applies to overworld--i.e., dimension 0
spawnMinDistance=0
spawnMaxDistance=0
#
# other template built nearby whenever this one is
# syntax: <name>;<relativeX>;<maxYdifference>;<relativeZ>[;<chance>]
# may be used more than once to specify multiple neighbors
adjoining_template=

rule1=0,100,minecraft:dirt-0
rule2=0,100,minecraft:grass-0
rule3=0,100,minecraft:stonebrick-0
rule4=0,100,minecraft:stonebrick-2
rule5=0,100,minecraft:stonebrick-1
rule6=0,100,IInventory;minecraft:chest;minecraft:web#1#0#7+minecraft:written_book#{pages:["\"Behold! We radiated the night and the prey, why not bleed?\\nweapons, corpses, kings - Those are our true noise.\\nThe terror of 2 corpses\\n\""],author:"Teemu Hanssson",title:"Vir"}#0#12+minecraft:bone#1#0#20+minecraft:bone#1#0#22-5
rule7=0,100,minecraft:stone_brick_stairs-1
rule8=0,100,minecraft:stone_slab-5
rule9=0,100,minecraft:iron_bars-0
rule10=2,100,minecraft:redstone_torch-1
rule11=0,100,minecraft:stone_brick_stairs-0
rule12=0,100,minecraft:lever-0
rule13=0,100,minecraft:stone_brick_stairs-2
rule14=0,100,minecraft:stone_brick_stairs-7
rule15=0,100,minecraft:stone_brick_stairs-6
rule16=0,100,minecraft:stone_brick_stairs-3
rule17=0,100,minecraft:redstone_wire-0

layer
1,1,1,1,1,1,1,1,1,1,1,1,1,2,2,1,1,1,2,1,1
2,2,2,2,2,2,2,2,2,2,2,2,2,2,2,2,2,2,2,2,2
1,2,2,2,2,2,2,2,2,2,2,2,2,2,2,2,1,2,1,2,1
1,2,2,2,2,2,2,2,2,2,2,2,2,2,2,2,1,2,2,2,1
1,2,2,2,2,2,2,2,2,2,2,2,2,2,2,2,1,2,1,2,1
1,2,2,2,2,2,2,2,2,2,2,2,2,2,2,2,2,2,2,2,1
1,2,2,2,2,2,2,2,2,2,2,2,2,2,2,2,2,2,2,2,1
2,2,2,2,2,2,2,2,2,2,2,2,2,2,2,2,2,2,2,2,2
1,2,2,2,2,2,2,2,2,2,2,2,2,2,2,2,2,2,2,2,1
1,2,2,2,2,2,2,2,2,2,2,2,2,2,2,2,2,2,2,2,2
2,2,2,2,2,2,2,2,2,2,2,2,1,2,2,2,1,2,1,2,1
2,2,2,2,2,2,2,2,2,2,2,2,2,2,2,2,2,2,2,2,1
2,1,1,1,2,1,2,1,1,2,2,2,1,1,1,1,2,1,1,1,1
endlayer

layer
3,4,5,3,4,3,4,5,5,3,5,3,3,5,3,3,3,3,3,4,3
5,0,0,0,0,0,0,0,0,0,0,0,0,0,0,0,3,6,5,0,5
3,0,7,0,7,0,7,0,7,0,7,0,7,0,7,0,4,0,3,0,3
5,0,0,0,0,0,0,0,0,0,0,0,0,0,0,0,3,0,3,0,4
3,0,0,0,0,0,0,0,0,0,0,0,0,0,0,0,3,0,5,0,3
4,0,0,0,0,0,0,0,0,0,0,0,0,0,0,0,0,0,0,0,5
5,0,0,0,0,0,0,0,0,0,0,0,0,0,0,0,0,0,0,0,3
3,0,0,0,0,0,0,0,0,0,0,0,0,0,0,0,0,0,0,0,4
3,0,0,0,0,0,0,0,0,0,0,0,0,0,0,0,0,0,0,0,5
4,0,0,0,0,0,0,0,0,0,0,0,0,0,0,0,0,0,0,0,5
3,0,8,0,8,0,8,0,8,0,0,0,5,0,5,0,4,0,3,0,4
5,0,0,0,0,0,0,0,0,0,0,0,0,0,0,0,0,0,0,0,3
3,4,3,4,5,3,3,5,4,0,0,0,4,5,3,5,4,3,5,4,3
endlayer

layer
3,9,4,9,3,9,4,9,3,9,3,9,5,9,3,9,5,3,5,9,4
9,0,0,0,0,0,0,0,0,0,0,0,0,0,0,0,4,10,5,0,9
5,0,0,0,0,0,0,0,0,0,0,0,0,0,0,0,5,0,5,0,3
9,0,0,0,0,0,0,0,0,0,0,0,0,0,0,0,3,0,3,0,9
3,0,0,0,0,0,0,0,0,0,0,0,0,0,0,0,4,0,4,0,5
9,0,0,0,0,0,0,0,0,0,0,0,0,0,0,0,0,0,0,0,9
4,0,0,0,0,0,0,0,0,0,0,0,0,0,0,0,0,0,0,0,4
9,0,0,0,0,0,0,0,0,0,0,0,0,0,0,0,0,0,0,0,9
5,0,0,0,0,0,0,0,0,0,0,0,0,0,0,0,0,0,0,0,3
9,0,0,0,0,0,0,0,0,0,0,0,0,0,0,0,0,0,0,0,9
3,0,0,0,0,0,0,0,0,0,0,0,0,0,0,0,0,0,0,0,4
9,0,0,0,0,0,0,0,0,0,0,0,0,0,0,0,0,0,0,0,9
5,9,3,9,3,9,5,9,5,0,0,0,5,9,3,9,5,9,5,9,3
endlayer

layer
8,0,8,0,8,0,8,0,8,0,8,0,8,0,8,0,8,11,8,0,8
0,0,0,0,0,0,0,0,0,0,0,0,0,0,0,0,5,3,3,0,0
8,0,0,0,0,0,0,0,0,0,0,0,0,0,0,0,3,5,4,0,8
0,0,0,0,0,0,0,0,0,0,0,0,0,0,0,0,4,12,3,0,0
8,0,0,0,0,0,0,0,0,0,0,0,0,0,0,0,3,5,3,0,8
0,0,0,0,0,0,0,0,0,0,0,0,0,0,0,0,0,0,0,0,0
8,0,0,0,0,0,0,0,0,0,0,0,0,0,0,0,0,0,0,0,8
0,0,0,0,0,0,0,0,0,0,0,0,0,0,0,0,0,0,0,0,0
8,0,0,0,0,0,0,0,0,0,0,0,0,0,0,0,0,0,0,0,8
0,0,0,0,0,0,0,0,0,0,0,0,0,0,0,0,0,0,0,0,0
8,0,0,0,0,0,0,0,0,0,0,0,0,0,0,0,0,0,0,0,8
0,0,0,0,0,0,0,0,0,0,0,0,0,0,0,0,0,0,0,0,0
8,0,8,0,8,0,8,0,16,15,0,14,13,0,8,0,8,0,8,0,8
endlayer

layer
0,0,0,0,0,0,0,0,0,0,0,0,0,0,0,0,0,0,0,0,0
0,0,0,0,0,0,0,0,0,0,0,0,0,0,0,0,0,0,0,0,0
0,0,0,0,0,0,0,0,0,0,0,0,0,0,0,0,0,4,0,0,0
0,0,0,0,0,0,0,0,0,0,0,0,0,0,0,0,0,5,0,0,0
0,0,0,0,0,0,0,0,0,0,0,0,0,0,0,0,0,17,0,0,0
0,0,0,0,0,0,0,0,0,0,0,0,0,0,0,0,0,0,0,0,0
0,0,0,0,0,0,0,0,0,0,0,0,0,0,0,0,0,0,0,0,0
0,0,0,0,0,0,0,0,0,0,0,0,0,0,0,0,0,0,0,0,0
0,0,0,0,0,0,0,0,0,0,0,0,0,0,0,0,0,0,0,0,0
0,0,0,0,0,0,0,0,0,0,0,0,0,0,0,0,0,0,0,0,0
0,0,0,0,0,0,0,0,0,0,0,0,0,0,0,0,0,0,0,0,0
0,0,0,0,0,0,0,0,0,0,0,0,0,0,0,0,0,0,0,0,0
0,0,0,0,0,0,0,0,0,16,3,13,0,0,0,0,0,0,0,0,0
endlayer

layer
0,0,0,0,0,0,0,0,0,0,0,0,0,0,0,0,0,0,0,0,0
0,0,0,0,0,0,0,0,0,0,0,0,0,0,0,0,0,0,0,0,0
0,0,0,0,0,0,0,0,0,0,0,0,0,0,0,0,0,0,0,0,0
0,0,0,0,0,0,0,0,0,0,0,0,0,0,0,0,0,0,0,0,0
0,0,0,0,0,0,0,0,0,0,0,0,0,0,0,0,0,0,0,0,0
0,0,0,0,0,0,0,0,0,0,0,0,0,0,0,0,0,0,0,0,0
0,0,0,0,0,0,0,0,0,0,0,0,0,0,0,0,0,0,0,0,0
0,0,0,0,0,0,0,0,0,0,0,0,0,0,0,0,0,0,0,0,0
0,0,0,0,0,0,0,0,0,0,0,0,0,0,0,0,0,0,0,0,0
0,0,0,0,0,0,0,0,0,0,0,0,0,0,0,0,0,0,0,0,0
0,0,0,0,0,0,0,0,0,0,0,0,0,0,0,0,0,0,0,0,0
0,0,0,0,0,0,0,0,0,0,0,0,0,0,0,0,0,0,0,0,0
0,0,0,0,0,0,0,0,0,0,8,0,0,0,0,0,0,0,0,0,0
endlayer

