
# Created by Ruins mod version 17.2 Ingame Parser
# authoring Player: BARTLLOW

# TEMPLATE PARAMETER SETTINGS:
#
# criterion expression specifying mod ids required to load template
# may include plus (AND), minus (AND NOT), comma (OR), and parentheses
# all required mods listed must be present; no prohibited mods can be
requiredMods=
#
# likelihood this template will be chosen relative to all others
# e.g., a weight=6 template is chosen 3X as often as one with weight=2
weight=1
#
# list of dimensions in which this template may spawn, even if generic
# one or more dimension names, separated by commas (blank = all)
dimensionsToSpawnIn=
#
# list of other biomes in which this template may spawn
# biome corresponding to directory is always assumed, listed or not
# generic templates should leave this list empty
biomesToSpawnIn=
#
# criterion expression specifying types of biome where template spawns
# this is in addition to those explicitly listed as biomesToSpawnIn
# generic templates should leave this list empty
biomeTypesToSpawnIn=
#
# list of biomes in which this template may not spawn
# takes precedence over biomeTypesToSpawnIn, but NOT biomesToSpawnIn
# should be empty if biomeTypesToSpawnIn is empty
biomesToNotSpawnIn=
#
# depth template is pushed down into the surface when built
# offset is min/max range of random additional bury depth
embed_into_distance=0
random_height_offset=0,0
#
# whitelist/blacklist of block types on which template may be built
# specify one, not both; leave the other empty (both empty = allow all)
acceptable_target_blocks=
unacceptable_target_blocks=flowing_water,water,flowing_lava,lava
#
# size of template (#layers, #rows per layer, #blocks per row)
dimensions=6,29,21
#
# max number of missing blocks allowed in surface beneath template
allowable_overhang=0
#
# depth/height limit affected by terrain leveling
# also maximum bumpiness tolerated in surface beneath template
max_leveling=2
#
# padding applied to all sides of template horizontal footprint
# expands area affected by terrain leveling (-1 = no leveling)
leveling_buffer=0
#
# do not rotate template randomly when built (1 = no rotation)
preventRotation=0
#
# treat water/lava blocks as air and protect them from rule0 (1 = yes)
preserve_water=0
preserve_lava=0
#
# minimum distance this template must have from instances of itself
uniqueMinDistance=0
#
# min/max distances this template can be from world spawn (0 = no limit)
# only applies to overworld--i.e., dimension 0
spawnMinDistance=0
spawnMaxDistance=0
#
# other template built nearby whenever this one is
# syntax: <name>;<relativeX>;<maxYdifference>;<relativeZ>[;<chance>]
# may be used more than once to specify multiple neighbors
adjoining_template=

rule1=0,100,minecraft:dirt-0
rule2=0,100,minecraft:grass-0
rule3=0,100,minecraft:stone-0
rule4=0,100,minecraft:log-1
rule5=0,100,minecraft:netherrack-0
rule6=0,100,minecraft:fence-0
rule7=0,100,minecraft:planks-1
rule8=0,100,minecraft:planks-0
rule9=0,100,minecraft:iron_ore-0
rule10=0,100,minecraft:gold_ore-0
rule11=0,100,minecraft:gold_block-0
rule12=0,100,minecraft:iron_bars-0
rule13=0,100,minecraft:bed-10
rule14=0,100,minecraft:bed-2
rule15=0,100,minecraft:oak_stairs-1
rule16=0,100,minecraft:hay_block-0
rule17=0,100,minecraft:wooden_door-3
rule18=0,100,minecraft:stone_slab-0
rule19=0,100,minecraft:fire-15
rule20=0,100,minecraft:double_stone_slab-0
rule21=0,100,minecraft:furnace-3
rule22=0,100,minecraft:clay-0
rule23=0,100,minecraft:furnace-4
rule24=0,100,minecraft:crafting_table-0
rule25=0,100,IInventory;minecraft:chest;minecraft:golden_horse_armor#1#0#0+minecraft:saddle#1#0#2+minecraft:bread#3#0#23+minecraft:apple#2#0#24-4
rule26=0,100,IInventory;minecraft:chest;minecraft:baked_potato#10#0#0+minecraft:sapling#5#0#1+minecraft:carrot#5#0#5+minecraft:apple#9#0#7+minecraft:baked_potato#4#0#15+minecraft:potato#2#0#19+minecraft:cooked_beef#4#0#21+minecraft:iron_sword#1#0#24+minecraft:cooked_chicken#2#0#26-4
rule27=0,100,minecraft:cauldron-0
rule28=2,100,minecraft:torch-1
rule29=0,100,minecraft:wooden_door-9
rule30=2,100,minecraft:torch-3
rule31=2,100,minecraft:torch-4
rule32=1,100,minecraft:torch-5
rule33=0,100,minecraft:wooden_slab-0
rule34=0,100,minecraft:oak_stairs-5
rule35=0,100,minecraft:oak_stairs-7
rule36=0,100,minecraft:wooden_slab-1

layer
1,2,2,2,1,2,2,2,1,2,2,2,1,2,2,2,1,2,2,2,1
2,2,2,2,2,2,2,2,2,2,2,2,2,2,2,2,2,2,2,2,2
2,2,2,2,2,2,2,2,2,2,2,2,2,2,2,2,2,2,2,2,2
2,2,2,1,1,1,1,1,1,1,1,1,1,1,1,1,1,1,2,2,2
1,2,2,1,3,3,3,3,3,3,3,3,3,3,3,3,3,1,2,2,1
2,2,2,1,3,3,3,3,3,3,3,3,3,3,3,3,3,1,2,2,2
2,2,2,1,3,4,3,3,3,4,3,3,3,3,4,3,3,1,2,2,2
2,2,2,1,3,3,3,3,3,3,3,3,3,3,3,3,3,1,2,2,2
1,2,2,1,3,3,3,3,3,3,3,3,3,3,3,3,3,1,2,2,1
2,2,2,1,3,3,3,3,3,3,3,3,3,3,3,3,3,1,2,2,2
2,2,2,1,3,3,3,3,3,3,3,3,3,3,3,3,3,1,2,2,2
2,2,2,1,3,3,3,3,3,3,3,3,3,3,4,3,3,1,2,2,2
1,2,2,1,3,3,3,3,3,3,3,3,3,3,3,3,3,4,2,2,4
2,2,2,1,3,3,3,5,5,5,3,3,3,3,3,3,3,3,3,3,3
2,2,2,1,3,3,3,5,3,5,3,3,3,3,3,3,3,3,3,3,3
2,2,2,1,3,3,3,5,5,5,3,3,3,3,3,3,3,3,3,3,3
1,2,2,1,3,3,3,3,3,3,3,3,3,3,3,3,3,4,2,2,4
2,2,2,1,3,3,3,3,3,3,3,3,3,3,3,3,3,1,2,2,2
2,2,2,1,3,3,3,3,3,3,3,3,3,3,3,3,3,1,2,2,2
2,2,2,1,3,3,3,3,3,3,3,3,3,3,3,3,3,1,2,2,2
1,2,2,1,3,3,3,3,3,3,3,3,3,3,3,3,3,1,2,2,1
2,2,2,1,3,3,3,3,3,3,3,3,3,3,3,3,3,1,2,2,2
2,2,2,1,3,3,3,3,3,3,3,3,3,3,3,3,3,1,2,2,2
2,2,2,1,3,3,3,3,3,3,3,3,3,3,3,3,3,1,2,2,2
1,2,2,1,3,3,3,3,3,3,3,3,3,3,3,3,3,1,2,2,1
2,2,2,1,1,1,1,1,1,1,1,1,1,1,1,1,1,4,2,2,2
2,2,2,2,2,2,2,2,2,2,2,2,2,2,2,2,2,2,2,2,2
2,2,2,2,2,2,2,2,2,2,2,2,2,2,2,2,2,2,2,2,2
1,2,2,2,1,2,2,2,1,2,2,2,1,2,2,2,1,2,2,2,1
endlayer

layer
4,6,6,6,4,6,6,6,4,6,6,6,4,6,6,6,4,6,6,6,4
6,0,0,0,0,0,0,0,0,0,0,0,0,0,0,0,0,0,0,0,6
6,0,0,0,0,0,0,0,0,0,0,0,0,0,0,0,0,0,0,0,6
6,0,0,4,7,7,7,7,7,7,7,7,7,7,7,7,7,4,0,0,6
4,0,0,7,8,8,0,11,0,8,10,10,9,9,8,8,8,7,0,0,4
6,0,0,7,8,8,0,0,0,8,0,0,0,9,8,8,8,7,0,0,6
6,0,0,7,8,4,12,12,12,4,12,12,0,12,4,8,8,7,0,0,6
6,0,0,7,15,0,0,0,0,0,0,0,0,0,8,14,13,7,0,0,6
4,0,0,7,0,0,0,0,0,0,0,0,2,0,8,14,13,7,0,0,4
6,0,0,7,0,0,0,0,0,0,0,0,0,0,17,0,16,7,0,0,6
6,0,0,7,0,0,0,0,0,0,0,0,0,0,8,0,16,7,0,0,6
6,0,0,7,0,0,0,0,0,0,0,0,0,0,4,8,8,7,0,0,6
4,0,0,7,0,0,0,18,18,18,0,0,0,0,0,0,0,4,0,0,4
6,0,0,7,0,0,18,19,19,19,18,0,0,0,0,0,0,0,0,0,12
6,0,0,7,0,0,18,19,20,19,18,0,0,0,0,0,0,0,0,0,0
6,0,0,7,0,0,18,19,19,19,18,0,0,0,0,0,0,0,0,0,12
4,0,0,7,0,0,0,18,18,18,0,0,0,0,0,0,0,4,0,0,4
6,0,0,7,0,0,0,0,0,0,0,0,0,0,0,0,0,7,0,0,6
6,0,0,7,0,0,0,0,0,0,0,0,0,0,0,0,0,7,0,0,6
6,0,0,7,0,0,0,0,0,0,0,0,0,0,0,0,0,7,0,0,6
4,0,0,7,6,0,0,0,0,6,0,0,0,6,0,0,6,7,0,0,4
6,0,0,7,0,0,0,0,0,0,0,0,0,0,0,0,21,7,0,0,6
6,0,0,7,22,0,2,0,0,0,0,0,0,0,0,0,8,7,0,0,6
6,0,0,7,22,0,0,0,0,0,0,0,0,0,0,0,8,7,0,0,6
4,0,0,7,6,24,27,26,25,6,0,0,0,6,24,23,6,7,0,0,4
6,0,0,4,7,7,7,7,7,7,7,7,7,7,7,7,7,4,0,0,6
6,0,0,0,0,0,0,0,0,0,0,0,0,0,0,0,0,0,0,0,6
6,0,0,0,0,0,0,0,0,0,0,0,0,0,0,0,0,0,0,0,6
4,6,6,6,4,6,6,6,4,6,6,6,4,6,6,6,4,6,6,6,4
endlayer

layer
4,6,6,6,4,6,6,6,4,6,6,6,4,6,6,6,4,6,6,6,4
6,0,0,0,0,0,0,0,0,0,0,0,0,0,0,0,0,0,0,0,6
6,0,0,0,0,0,0,0,0,0,0,0,0,0,0,0,0,0,0,0,6
6,0,0,4,7,7,7,7,7,7,7,7,7,7,7,7,7,4,0,0,6
4,0,0,7,8,8,0,0,0,8,10,0,9,9,8,8,8,7,0,0,4
6,0,0,7,8,8,0,0,0,8,0,0,0,0,8,8,8,7,0,0,6
6,0,0,7,15,4,12,12,12,4,12,12,0,12,4,8,8,7,0,0,6
6,0,0,7,0,0,0,0,0,28,0,0,0,0,8,0,0,7,0,0,6
4,0,0,7,0,0,0,0,0,0,0,0,0,0,8,0,0,7,0,0,4
6,0,0,7,0,0,0,0,0,0,0,0,0,0,29,0,16,7,0,0,6
6,0,0,7,0,0,0,0,0,0,0,0,0,0,8,0,16,7,0,0,6
6,0,0,7,0,0,0,0,0,0,0,0,0,30,4,8,8,7,0,0,6
4,0,0,7,0,0,0,0,0,0,0,0,0,0,0,0,0,4,0,0,4
6,0,0,7,0,0,0,0,0,0,0,0,0,0,0,0,0,0,0,0,12
6,0,0,7,31,0,0,0,27,0,0,0,0,0,0,0,0,0,0,0,0
6,0,0,7,0,0,0,0,0,0,0,0,0,0,0,0,0,0,0,0,12
4,0,0,7,0,0,0,0,0,0,0,0,0,0,0,0,0,4,0,0,4
6,0,0,7,0,0,0,0,0,0,0,0,0,0,0,0,0,7,0,0,6
6,0,0,7,0,0,0,0,0,0,0,0,0,0,0,0,0,7,0,0,6
6,0,0,7,0,0,0,0,0,0,0,0,0,0,0,0,0,7,0,0,6
4,0,0,7,6,0,0,0,0,6,0,0,0,6,0,0,6,7,0,0,4
6,0,0,7,0,0,0,0,0,0,0,0,0,0,0,0,0,7,0,0,6
6,0,0,7,0,0,0,0,0,0,0,0,0,0,0,0,0,7,0,0,6
6,0,0,7,0,0,0,0,0,0,0,0,0,0,0,0,0,7,0,0,6
4,0,0,7,32,0,0,0,0,6,0,0,0,6,0,0,32,7,0,0,4
6,0,0,4,7,7,7,7,7,7,7,7,7,7,7,7,7,4,0,0,6
6,0,0,0,0,0,0,0,0,0,0,0,0,0,0,0,0,0,0,0,6
6,0,0,0,0,0,0,0,0,0,0,0,0,0,0,0,0,0,0,0,6
4,6,6,6,4,6,6,6,4,6,6,6,4,6,6,6,4,6,6,6,4
endlayer

layer
4,0,0,0,4,0,0,0,4,0,0,0,4,0,0,0,4,0,0,0,4
0,0,0,0,0,0,0,0,0,0,0,0,0,0,0,0,0,0,0,0,0
0,0,0,0,0,0,0,0,0,0,0,0,0,0,0,0,0,0,0,0,0
0,0,0,4,7,7,7,7,7,7,7,7,7,7,7,7,7,4,0,0,0
4,0,0,7,33,33,33,33,33,33,33,33,33,33,33,33,33,7,0,0,4
0,0,0,7,33,33,33,33,33,33,33,33,33,33,33,33,33,7,0,0,0
0,0,0,7,0,4,34,34,34,34,34,34,34,34,4,33,33,7,0,0,0
0,0,0,7,0,0,0,0,0,0,0,0,0,0,35,33,33,7,0,0,0
4,0,0,7,0,0,0,0,0,0,0,0,0,0,35,33,33,7,0,0,4
0,0,0,7,0,0,0,0,0,0,0,0,0,0,8,33,33,7,0,0,0
0,0,0,7,0,0,0,0,0,0,0,0,0,0,35,33,33,7,0,0,0
0,0,0,7,0,0,0,0,0,0,0,0,0,0,4,34,34,7,0,0,0
4,0,0,7,0,0,0,0,0,0,0,0,0,0,0,0,0,4,0,0,4
0,0,0,7,0,0,0,0,0,0,0,0,0,0,0,0,0,0,0,0,12
0,0,0,7,0,0,0,0,0,0,0,0,0,0,0,0,0,0,0,0,12
0,0,0,7,0,0,0,0,0,0,0,0,0,0,0,0,0,0,0,0,12
4,0,0,7,0,0,0,0,0,0,0,0,0,0,0,0,0,4,0,0,4
0,0,0,7,0,0,0,0,0,0,0,0,0,0,0,0,0,7,0,0,0
0,0,0,7,0,0,0,0,0,0,0,0,0,0,0,0,0,7,0,0,0
0,0,0,7,0,0,0,0,0,0,0,0,0,0,0,0,0,7,0,0,0
4,0,0,7,0,0,0,0,0,0,0,0,0,0,0,0,0,7,0,0,4
0,0,0,7,0,0,0,0,0,0,0,0,0,0,0,0,0,7,0,0,0
0,0,0,7,0,0,0,0,0,0,0,0,0,0,0,0,0,7,0,0,0
0,0,0,7,0,0,0,0,0,0,0,0,0,0,0,0,0,7,0,0,0
4,0,0,7,0,0,0,0,0,0,0,0,0,0,0,0,0,7,0,0,4
0,0,0,4,7,7,7,7,7,7,7,7,7,7,7,7,7,4,0,0,0
0,0,0,0,0,0,0,0,0,0,0,0,0,0,0,0,0,0,0,0,0
0,0,0,0,0,0,0,0,0,0,0,0,0,0,0,0,0,0,0,0,0
4,0,0,0,4,0,0,0,4,0,0,0,4,0,0,0,4,0,0,0,4
endlayer

layer
0,0,0,0,0,0,0,0,0,0,0,0,0,0,0,0,0,0,0,0,0
0,0,0,0,0,0,0,0,0,0,0,0,0,0,0,0,0,0,0,0,0
0,0,0,0,0,0,0,0,0,0,0,0,0,0,0,0,0,0,0,0,0
0,0,0,4,0,36,0,36,32,36,0,36,32,36,0,36,0,4,0,0,0
0,0,0,0,0,0,0,0,0,0,0,0,0,0,0,0,0,0,0,0,0
0,0,0,36,0,0,0,0,0,0,0,0,0,0,0,0,0,36,0,0,0
0,0,0,0,0,32,0,0,0,0,0,0,0,0,32,0,0,0,0,0,0
0,0,0,36,0,0,0,0,0,0,0,0,0,0,0,0,0,36,0,0,0
0,0,0,0,0,0,0,0,0,0,0,0,0,0,0,0,0,0,0,0,0
0,0,0,36,0,0,0,0,0,0,0,0,0,0,0,0,0,36,0,0,0
0,0,0,32,0,0,0,0,0,0,0,0,0,0,0,0,0,0,0,0,0
0,0,0,36,0,0,0,0,0,0,0,0,0,0,0,0,0,36,0,0,0
0,0,0,0,0,0,0,0,0,0,0,0,0,0,0,0,0,4,0,0,0
0,0,0,36,0,0,0,0,0,0,0,0,0,0,0,0,0,0,0,0,0
0,0,0,0,0,0,0,0,0,0,0,0,0,0,0,0,0,0,0,0,0
0,0,0,36,0,0,0,0,0,0,0,0,0,0,0,0,0,0,0,0,0
0,0,0,0,0,0,0,0,0,0,0,0,0,0,0,0,0,4,0,0,0
0,0,0,36,0,0,0,0,0,0,0,0,0,0,0,0,0,36,0,0,0
0,0,0,32,0,0,0,0,0,0,0,0,0,0,0,0,0,0,0,0,0
0,0,0,36,0,0,0,0,0,0,0,0,0,0,0,0,0,36,0,0,0
0,0,0,0,0,0,0,0,0,0,0,0,0,0,0,0,0,0,0,0,0
0,0,0,36,0,0,0,0,0,0,0,0,0,0,0,0,0,36,0,0,0
0,0,0,0,0,0,0,0,0,0,0,0,0,0,0,0,0,0,0,0,0
0,0,0,36,0,0,0,0,0,0,0,0,0,0,0,0,0,36,0,0,0
0,0,0,0,0,0,0,0,0,0,0,0,0,0,0,0,0,0,0,0,0
0,0,0,4,0,36,0,36,32,36,0,36,32,36,0,36,0,4,0,0,0
0,0,0,0,0,0,0,0,0,0,0,0,0,0,0,0,0,0,0,0,0
0,0,0,0,0,0,0,0,0,0,0,0,0,0,0,0,0,0,0,0,0
0,0,0,0,0,0,0,0,0,0,0,0,0,0,0,0,0,0,0,0,0
endlayer

layer
0,0,0,0,0,0,0,0,0,0,0,0,0,0,0,0,0,0,0,0,0
0,0,0,0,0,0,0,0,0,0,0,0,0,0,0,0,0,0,0,0,0
0,0,0,0,0,0,0,0,0,0,0,0,0,0,0,0,0,0,0,0,0
0,0,0,32,0,0,0,0,0,0,0,0,0,0,0,0,0,32,0,0,0
0,0,0,0,0,0,0,0,0,0,0,0,0,0,0,0,0,0,0,0,0
0,0,0,0,0,0,0,0,0,0,0,0,0,0,0,0,0,0,0,0,0
0,0,0,0,0,0,0,0,0,0,0,0,0,0,0,0,0,0,0,0,0
0,0,0,0,0,0,0,0,0,0,0,0,0,0,0,0,0,0,0,0,0
0,0,0,0,0,0,0,0,0,0,0,0,0,0,0,0,0,0,0,0,0
0,0,0,0,0,0,0,0,0,0,0,0,0,0,0,0,0,0,0,0,0
0,0,0,0,0,0,0,0,0,0,0,0,0,0,0,0,0,0,0,0,0
0,0,0,0,0,0,0,0,0,0,0,0,0,0,0,0,0,0,0,0,0
0,0,0,0,0,0,0,0,0,0,0,0,0,0,0,0,0,32,0,0,0
0,0,0,0,0,0,0,0,0,0,0,0,0,0,0,0,0,0,0,0,0
0,0,0,0,0,0,0,0,0,0,0,0,0,0,0,0,0,0,0,0,0
0,0,0,0,0,0,0,0,0,0,0,0,0,0,0,0,0,0,0,0,0
0,0,0,0,0,0,0,0,0,0,0,0,0,0,0,0,0,32,0,0,0
0,0,0,0,0,0,0,0,0,0,0,0,0,0,0,0,0,0,0,0,0
0,0,0,0,0,0,0,0,0,0,0,0,0,0,0,0,0,0,0,0,0
0,0,0,0,0,0,0,0,0,0,0,0,0,0,0,0,0,0,0,0,0
0,0,0,0,0,0,0,0,0,0,0,0,0,0,0,0,0,0,0,0,0
0,0,0,0,0,0,0,0,0,0,0,0,0,0,0,0,0,0,0,0,0
0,0,0,0,0,0,0,0,0,0,0,0,0,0,0,0,0,0,0,0,0
0,0,0,0,0,0,0,0,0,0,0,0,0,0,0,0,0,0,0,0,0
0,0,0,0,0,0,0,0,0,0,0,0,0,0,0,0,0,0,0,0,0
0,0,0,32,0,0,0,0,0,0,0,0,0,0,0,0,0,32,0,0,0
0,0,0,0,0,0,0,0,0,0,0,0,0,0,0,0,0,0,0,0,0
0,0,0,0,0,0,0,0,0,0,0,0,0,0,0,0,0,0,0,0,0
0,0,0,0,0,0,0,0,0,0,0,0,0,0,0,0,0,0,0,0,0
endlayer

