
# Created by Ruins mod version 17.2 Ingame Parser
# authoring Player: BARTLLOW

# TEMPLATE PARAMETER SETTINGS:
#
# criterion expression specifying mod ids required to load template
# may include plus (AND), minus (AND NOT), comma (OR), and parentheses
# all required mods listed must be present; no prohibited mods can be
requiredMods=
#
# likelihood this template will be chosen relative to all others
# e.g., a weight=6 template is chosen 3X as often as one with weight=2
weight=1
#
# list of dimensions in which this template may spawn, even if generic
# one or more dimension names, separated by commas (blank = all)
dimensionsToSpawnIn=
#
# list of other biomes in which this template may spawn
# biome corresponding to directory is always assumed, listed or not
# generic templates should leave this list empty
biomesToSpawnIn=
#
# criterion expression specifying types of biome where template spawns
# this is in addition to those explicitly listed as biomesToSpawnIn
# generic templates should leave this list empty
biomeTypesToSpawnIn=
#
# list of biomes in which this template may not spawn
# takes precedence over biomeTypesToSpawnIn, but NOT biomesToSpawnIn
# should be empty if biomeTypesToSpawnIn is empty
biomesToNotSpawnIn=
#
# depth template is pushed down into the surface when built
# offset is min/max range of random additional bury depth
embed_into_distance=0
random_height_offset=0,0
#
# whitelist/blacklist of block types on which template may be built
# specify one, not both; leave the other empty (both empty = allow all)
acceptable_target_blocks=
unacceptable_target_blocks=flowing_water,water,flowing_lava,lava
#
# size of template (#layers, #rows per layer, #blocks per row)
dimensions=32,9,9
#
# max number of missing blocks allowed in surface beneath template
allowable_overhang=0
#
# depth/height limit affected by terrain leveling
# also maximum bumpiness tolerated in surface beneath template
max_leveling=2
#
# padding applied to all sides of template horizontal footprint
# expands area affected by terrain leveling (-1 = no leveling)
leveling_buffer=0
#
# do not rotate template randomly when built (1 = no rotation)
preventRotation=0
#
# treat water/lava blocks as air and protect them from rule0 (1 = yes)
preserve_water=0
preserve_lava=0
#
# minimum distance this template must have from instances of itself
uniqueMinDistance=0
#
# min/max distances this template can be from world spawn (0 = no limit)
# only applies to overworld--i.e., dimension 0
spawnMinDistance=0
spawnMaxDistance=0
#
# other template built nearby whenever this one is
# syntax: <name>;<relativeX>;<maxYdifference>;<relativeZ>[;<chance>]
# may be used more than once to specify multiple neighbors
adjoining_template=

rule1=0,100,minecraft:stone-0
rule2=0,100,minecraft:tnt-0
rule3=0,100,minecraft:stonebrick-0
rule4=0,100,minecraft:nether_brick-0
rule5=0,100,minecraft:stone_brick_stairs-1
rule6=0,100,minecraft:stone_slab-5
rule7=0,100,IInventory;minecraft:chest;minecraft:web#1#0#7+minecraft:web#1#0#13+minecraft:bone#1#0#16+minecraft:bone#1#0#20+minecraft:web#1#0#21+minecraft:web#1#0#25-5
rule8=0,100,minecraft:stone_brick_stairs-3
rule9=0,100,minecraft:stone_pressure_plate-0
rule10=0,100,minecraft:stone_brick_stairs-2
rule11=0,100,ChestGenHook:chests/simple_dungeon:5-3
rule12=0,100,ChestGenHook:chests/simple_dungeon:5-2
rule13=0,100,IInventory;minecraft:chest;minecraft:web#1#0#7+minecraft:web#1#0#8+minecraft:web#1#0#16+minecraft:web#1#0#19+minecraft:web#1#0#21+minecraft:web#1#0#25-4
rule14=0,100,minecraft:stone_brick_stairs-0
rule15=0,100,minecraft:stone_brick_stairs-5
rule16=0,100,minecraft:stone_slab-13
rule17=0,100,minecraft:stone_brick_stairs-7
rule18=0,100,minecraft:stone_brick_stairs-6
rule19=0,100,minecraft:stone_brick_stairs-4
rule20=0,100,minecraft:grass-0
rule21=0,100,minecraft:dirt-0
rule22=0,100,minecraft:glowstone-0
rule23=0,100,minecraft:nether_brick_fence-0
rule24=0,100,minecraft:nether_brick_stairs-4
rule25=0,100,minecraft:nether_brick_stairs-6
rule26=0,100,minecraft:nether_brick_stairs-7
rule27=0,100,minecraft:nether_brick_stairs-5
rule28=0,100,minecraft:obsidian-0
rule29=0,100,minecraft:nether_brick_stairs-0
rule30=0,100,minecraft:nether_brick_stairs-1
rule31=0,100,minecraft:nether_brick_stairs-2
rule32=0,100,minecraft:nether_brick_stairs-3

layer
0,0,0,0,0,0,0,0,0
0,0,0,0,0,0,0,0,0
0,0,0,0,0,0,0,0,0
0,0,0,0,1,0,0,0,0
0,0,0,1,1,1,0,0,0
0,0,0,0,1,0,0,0,0
0,0,0,0,0,0,0,0,0
0,0,0,0,0,0,0,0,0
0,0,0,0,0,0,0,0,0
endlayer

layer
0,0,0,0,0,0,0,0,0
0,0,0,0,0,0,0,0,0
0,0,0,0,1,0,0,0,0
0,0,0,1,2,1,0,0,0
0,0,1,2,2,2,1,0,0
0,0,0,1,2,1,0,0,0
0,0,0,0,1,0,0,0,0
0,0,0,0,0,0,0,0,0
0,0,0,0,0,0,0,0,0
endlayer

layer
0,0,0,0,0,0,0,0,0
0,0,0,0,0,0,0,0,0
0,0,0,3,3,3,0,0,0
0,0,3,3,3,3,3,0,0
0,0,3,3,3,3,3,0,0
0,0,3,3,3,3,3,0,0
0,0,0,3,3,3,0,0,0
0,0,0,0,0,0,0,0,0
0,0,0,0,0,0,0,0,0
endlayer

layer
0,0,0,0,0,0,0,0,0
0,0,4,5,5,5,4,0,0
0,4,6,0,7,0,6,4,0
0,10,0,9,0,9,0,8,0
0,10,12,0,9,0,11,8,0
0,10,0,9,0,9,0,8,0
0,4,6,0,13,0,6,4,0
0,0,4,14,14,14,4,0,0
0,0,0,0,0,0,0,0,0
endlayer

layer
0,0,0,0,0,0,0,0,0
0,0,4,15,15,15,4,0,0
0,4,16,0,0,0,16,4,0
0,18,0,0,0,0,0,17,0
0,18,0,0,0,0,0,17,0
0,18,0,0,0,0,0,17,0
0,4,16,0,0,0,16,4,0
0,0,4,19,19,19,4,0,0
0,0,0,0,0,0,0,0,0
endlayer

layer
0,0,0,0,0,0,0,0,0
0,0,0,0,0,0,0,0,0
0,0,3,4,3,3,0,0,0
0,0,3,0,0,0,4,0,0
0,0,3,0,0,0,3,0,0
0,0,4,0,0,0,3,0,0
0,0,0,3,3,4,0,0,0
0,0,0,0,0,0,0,0,0
0,0,0,0,0,0,0,0,0
endlayer

layer
0,0,0,0,0,0,0,0,0
0,0,0,0,0,0,0,0,0
0,0,3,3,4,3,0,0,0
0,0,3,0,0,0,3,0,0
0,0,4,0,0,0,4,0,0
0,0,3,0,0,0,3,0,0
0,0,0,3,4,3,0,0,0
0,0,0,0,0,0,0,0,0
0,0,0,0,0,0,0,0,0
endlayer

layer
0,0,0,0,0,0,0,0,0
0,0,0,0,0,0,0,0,0
0,0,0,3,3,4,0,0,0
0,0,4,0,0,0,3,0,0
0,0,3,0,0,0,3,0,0
0,0,3,0,0,0,4,0,0
0,0,0,4,3,3,0,0,0
0,0,0,0,0,0,0,0,0
0,0,0,0,0,0,0,0,0
endlayer

layer
0,0,0,0,0,0,0,0,0
0,0,0,0,0,0,0,0,0
0,0,0,4,3,3,0,0,0
0,0,3,0,0,0,4,0,0
0,0,3,0,0,0,3,0,0
0,0,4,0,0,0,3,0,0
0,0,0,3,3,4,0,0,0
0,0,0,0,0,0,0,0,0
0,0,0,0,0,0,0,0,0
endlayer

layer
0,0,0,0,0,0,0,0,0
0,0,0,0,0,0,0,0,0
0,0,0,3,4,3,0,0,0
0,0,3,0,0,0,3,0,0
0,0,4,0,0,0,4,0,0
0,0,3,0,0,0,3,0,0
0,0,0,3,4,3,0,0,0
0,0,0,0,0,0,0,0,0
0,0,0,0,0,0,0,0,0
endlayer

layer
0,0,0,0,0,0,0,0,0
0,0,0,0,0,0,0,0,0
0,0,0,3,3,4,0,0,0
0,0,4,0,0,0,3,0,0
0,0,3,0,0,0,3,0,0
0,0,3,0,0,0,4,0,0
0,0,0,4,3,3,0,0,0
0,0,0,0,0,0,0,0,0
0,0,0,0,0,0,0,0,0
endlayer

layer
0,0,0,0,0,0,0,0,0
0,0,0,0,0,0,0,0,0
0,0,0,4,3,3,0,0,0
0,0,3,0,0,0,4,0,0
0,0,3,0,0,0,3,0,0
0,0,4,0,0,0,3,0,0
0,0,0,3,3,4,0,0,0
0,0,0,0,0,0,0,0,0
0,0,0,0,0,0,0,0,0
endlayer

layer
0,0,0,0,0,0,0,0,0
0,0,0,0,0,0,0,0,0
0,0,0,3,4,3,0,0,0
0,0,3,0,0,0,3,0,0
0,0,4,0,0,0,4,0,0
0,0,3,0,0,0,3,0,0
0,0,0,3,4,3,0,0,0
0,0,0,0,0,0,0,0,0
0,0,0,0,0,0,0,0,0
endlayer

layer
0,0,0,0,0,0,0,0,0
0,0,0,0,0,0,0,0,0
0,0,0,3,3,4,0,0,0
0,0,4,0,0,0,3,0,0
0,0,3,0,0,0,3,0,0
0,0,3,0,0,0,4,0,0
0,0,0,4,3,3,0,0,0
0,0,0,0,0,0,0,0,0
0,0,0,0,0,0,0,0,0
endlayer

layer
0,0,0,0,0,0,0,0,0
0,0,0,0,0,0,0,0,0
0,0,0,4,3,3,0,0,0
0,0,3,0,0,0,4,0,0
0,0,3,0,0,0,3,0,0
0,0,4,0,0,0,3,0,0
0,0,0,3,3,4,0,0,0
0,0,0,0,0,0,0,0,0
0,0,0,0,0,0,0,0,0
endlayer

layer
0,0,0,0,0,0,0,0,0
0,0,0,0,0,0,0,0,0
0,0,0,3,4,3,0,0,0
0,0,3,0,0,0,3,0,0
0,0,4,0,0,0,4,0,0
0,0,3,0,0,0,3,0,0
0,0,0,3,4,3,0,0,0
0,0,0,0,0,0,0,0,0
0,0,0,0,0,0,0,0,0
endlayer

layer
0,0,0,0,0,0,0,0,0
0,0,0,0,0,0,0,0,0
0,0,0,3,3,4,0,0,0
0,0,4,0,0,0,3,0,0
0,0,3,0,0,0,3,0,0
0,0,3,0,0,0,4,0,0
0,0,0,4,3,3,0,0,0
0,0,0,0,0,0,0,0,0
0,0,0,0,0,0,0,0,0
endlayer

layer
0,0,0,0,20,0,0,0,0
0,0,20,20,20,20,20,0,0
0,20,3,3,3,3,3,20,0
0,21,3,4,3,4,3,21,0
20,20,3,3,4,3,3,20,20
0,20,3,4,3,4,3,20,0
0,20,3,3,3,3,3,20,0
0,0,20,20,20,20,20,0,0
0,0,0,0,20,0,0,0,0
endlayer

layer
0,0,0,0,0,0,0,0,0
0,0,0,3,0,3,0,0,0
0,0,0,0,0,0,0,0,0
0,3,0,0,0,0,0,3,0
0,0,0,0,0,0,0,0,0
0,3,0,0,0,0,0,3,0
0,0,0,0,0,0,0,0,0
0,0,0,3,0,3,0,0,0
0,0,0,0,0,0,0,0,0
endlayer

layer
0,0,0,0,0,0,0,0,0
0,0,0,3,0,3,0,0,0
0,0,0,0,0,0,0,0,0
0,3,0,0,0,0,0,3,0
0,0,0,0,0,0,0,0,0
0,3,0,0,0,0,0,3,0
0,0,0,0,0,0,0,0,0
0,0,0,3,0,3,0,0,0
0,0,0,0,0,0,0,0,0
endlayer

layer
0,0,0,19,0,0,0,0,0
0,0,0,5,0,14,0,0,0
0,0,0,0,0,15,0,0,0
0,8,18,0,0,0,0,8,18
0,0,0,0,0,0,0,0,0
17,10,0,0,0,0,17,10,0
0,0,0,19,0,0,0,0,0
0,0,0,5,0,14,0,0,0
0,0,0,0,0,15,0,0,0
endlayer

layer
0,0,0,22,0,0,0,0,0
0,0,0,0,0,0,0,0,0
0,0,0,0,0,14,0,0,0
0,0,8,3,19,3,0,0,22
0,0,0,17,0,18,0,0,0
22,0,0,3,15,3,10,0,0
0,0,0,5,0,0,0,0,0
0,0,0,0,0,0,0,0,0
0,0,0,0,0,22,0,0,0
endlayer

layer
0,0,0,0,0,0,0,0,0
0,0,0,0,0,0,0,0,0
0,0,0,0,0,0,0,0,0
0,0,0,8,0,14,0,0,0
0,0,0,0,0,0,0,0,0
0,0,0,5,0,10,0,0,0
0,0,0,0,0,0,0,0,0
0,0,0,0,0,0,0,0,0
0,0,0,0,0,0,0,0,0
endlayer

layer
0,0,0,0,0,0,0,0,0
0,0,0,0,0,0,0,0,0
0,0,0,0,0,0,0,0,0
0,0,0,0,0,0,0,0,0
0,0,0,0,23,0,0,0,0
0,0,0,0,0,0,0,0,0
0,0,0,0,0,0,0,0,0
0,0,0,0,0,0,0,0,0
0,0,0,0,0,0,0,0,0
endlayer

layer
0,0,0,0,0,0,0,0,0
0,0,0,0,0,0,0,0,0
0,0,0,0,0,0,0,0,0
0,0,0,0,0,0,0,0,0
0,0,0,0,4,0,0,0,0
0,0,0,0,0,0,0,0,0
0,0,0,0,0,0,0,0,0
0,0,0,0,0,0,0,0,0
0,0,0,0,0,0,0,0,0
endlayer

layer
0,0,0,0,22,0,0,0,0
0,0,0,0,0,0,0,0,0
0,0,0,0,0,0,0,0,0
0,0,0,0,24,0,0,0,0
22,0,0,26,4,25,0,0,22
0,0,0,0,27,0,0,0,0
0,0,0,0,0,0,0,0,0
0,0,0,0,0,0,0,0,0
0,0,0,0,22,0,0,0,0
endlayer

layer
0,0,0,0,23,0,0,0,0
0,0,0,0,0,0,0,0,0
0,0,0,0,0,0,0,0,0
0,0,0,0,23,0,0,0,0
23,0,0,23,28,23,0,0,23
0,0,0,0,23,0,0,0,0
0,0,0,0,0,0,0,0,0
0,0,0,0,0,0,0,0,0
0,0,0,0,23,0,0,0,0
endlayer

layer
0,0,0,0,27,0,0,0,0
0,0,0,0,0,0,0,0,0
0,0,0,0,0,0,0,0,0
0,0,0,0,24,0,0,0,0
25,0,0,26,4,25,0,0,26
0,0,0,0,27,0,0,0,0
0,0,0,0,0,0,0,0,0
0,0,0,0,0,0,0,0,0
0,0,0,0,24,0,0,0,0
endlayer

layer
0,0,0,0,29,0,0,0,0
0,0,0,0,27,0,0,0,0
0,0,0,0,24,0,0,0,0
0,0,0,0,30,0,0,0,0
32,25,26,31,4,32,25,26,31
0,0,0,0,29,0,0,0,0
0,0,0,0,27,0,0,0,0
0,0,0,0,24,0,0,0,0
0,0,0,0,30,0,0,0,0
endlayer

layer
0,0,0,0,0,0,0,0,0
0,0,0,0,0,0,0,0,0
0,0,0,0,23,0,0,0,0
0,0,0,0,23,0,0,0,0
0,0,23,23,4,23,23,0,0
0,0,0,0,23,0,0,0,0
0,0,0,0,23,0,0,0,0
0,0,0,0,0,0,0,0,0
0,0,0,0,0,0,0,0,0
endlayer

layer
0,0,0,0,0,0,0,0,0
0,0,0,0,0,0,0,0,0
0,0,0,0,0,0,0,0,0
0,0,0,0,0,0,0,0,0
0,0,0,0,4,0,0,0,0
0,0,0,0,0,0,0,0,0
0,0,0,0,0,0,0,0,0
0,0,0,0,0,0,0,0,0
0,0,0,0,0,0,0,0,0
endlayer

layer
0,0,0,0,0,0,0,0,0
0,0,0,0,0,0,0,0,0
0,0,0,0,0,0,0,0,0
0,0,0,0,0,0,0,0,0
0,0,0,0,23,0,0,0,0
0,0,0,0,0,0,0,0,0
0,0,0,0,0,0,0,0,0
0,0,0,0,0,0,0,0,0
0,0,0,0,0,0,0,0,0
endlayer

