
# Created by Ruins mod version 17.2 Ingame Parser
# authoring Player: BARTLLOW

# TEMPLATE PARAMETER SETTINGS:
#
# criterion expression specifying mod ids required to load template
# may include plus (AND), minus (AND NOT), comma (OR), and parentheses
# all required mods listed must be present; no prohibited mods can be
requiredMods=
#
# likelihood this template will be chosen relative to all others
# e.g., a weight=6 template is chosen 3X as often as one with weight=2
weight=1
#
# list of dimensions in which this template may spawn, even if generic
# one or more dimension names, separated by commas (blank = all)
dimensionsToSpawnIn=
#
# list of other biomes in which this template may spawn
# biome corresponding to directory is always assumed, listed or not
# generic templates should leave this list empty
biomesToSpawnIn=
#
# criterion expression specifying types of biome where template spawns
# this is in addition to those explicitly listed as biomesToSpawnIn
# generic templates should leave this list empty
biomeTypesToSpawnIn=
#
# list of biomes in which this template may not spawn
# takes precedence over biomeTypesToSpawnIn, but NOT biomesToSpawnIn
# should be empty if biomeTypesToSpawnIn is empty
biomesToNotSpawnIn=
#
# depth template is pushed down into the surface when built
# offset is min/max range of random additional bury depth
embed_into_distance=0
random_height_offset=0,0
#
# whitelist/blacklist of block types on which template may be built
# specify one, not both; leave the other empty (both empty = allow all)
acceptable_target_blocks=
unacceptable_target_blocks=flowing_water,water,flowing_lava,lava
#
# size of template (#layers, #rows per layer, #blocks per row)
dimensions=12,11,11
#
# max number of missing blocks allowed in surface beneath template
allowable_overhang=0
#
# depth/height limit affected by terrain leveling
# also maximum bumpiness tolerated in surface beneath template
max_leveling=2
#
# padding applied to all sides of template horizontal footprint
# expands area affected by terrain leveling (-1 = no leveling)
leveling_buffer=0
#
# do not rotate template randomly when built (1 = no rotation)
preventRotation=0
#
# treat water/lava blocks as air and protect them from rule0 (1 = yes)
preserve_water=0
preserve_lava=0
#
# minimum distance this template must have from instances of itself
uniqueMinDistance=0
#
# min/max distances this template can be from world spawn (0 = no limit)
# only applies to overworld--i.e., dimension 0
spawnMinDistance=0
spawnMaxDistance=0
#
# other template built nearby whenever this one is
# syntax: <name>;<relativeX>;<maxYdifference>;<relativeZ>[;<chance>]
# may be used more than once to specify multiple neighbors
adjoining_template=

rule1=0,100,minecraft:dirt-0
rule2=0,100,minecraft:grass-0
rule3=0,100,minecraft:sponge-0
rule4=0,100,minecraft:stonebrick-0
rule5=0,100,minecraft:stonebrick-2
rule6=0,100,minecraft:stonebrick-1
rule7=0,100,minecraft:double_plant-2
rule8=0,100,minecraft:tallgrass-1
rule9=0,100,minecraft:log-3
rule10=0,100,minecraft:stone_brick_stairs-0
rule11=0,100,minecraft:log-7
rule12=0,100,minecraft:stone-0
rule13=0,100,minecraft:stonebrick-3
rule14=0,100,minecraft:stone_brick_stairs-3
rule15=0,100,minecraft:red_flower-0
rule16=0,100,minecraft:stone_brick_stairs-7
rule17=0,100,minecraft:stone_brick_stairs-1
rule18=0,100,minecraft:log-11
rule19=0,100,minecraft:vine-1
rule20=0,100,minecraft:vine-2
rule21=0,100,minecraft:double_plant-10
rule22=0,100,minecraft:vine-4
rule23=1,100,minecraft:redstone_torch-5
rule24=0,100,IInventory;minecraft:chest;minecraft:leather_helmet#1#0#8+minecraft:spider_eye#4#0#11+minecraft:bone#3#0#19+minecraft:arrow#16#0#26-3
rule25=0,100,minecraft:vine-8
rule26=0,100,minecraft:leaves-15
rule27=0,100,minecraft:leaves-7
rule28=0,100,minecraft:stone_slab-13
rule29=0,100,minecraft:stone_brick_stairs-4
rule30=0,100,minecraft:stone_brick_stairs-6
rule31=0,100,minecraft:stone_brick_stairs-5

layer
1,1,1,1,1,1,1,1,1,1,1
1,1,1,1,1,1,1,1,1,1,1
1,2,2,1,1,2,1,2,2,1,1
1,2,2,2,1,2,1,2,2,1,1
1,2,1,2,2,2,1,2,2,1,1
1,2,2,1,2,2,2,1,1,1,1
1,2,2,2,1,2,2,1,1,1,1
1,2,1,2,2,2,1,2,2,1,1
1,2,2,2,2,1,2,2,1,1,1
1,1,1,1,1,1,1,1,1,1,1
1,1,1,1,1,1,1,1,1,1,1
endlayer

layer
2,2,2,1,1,2,2,2,2,2,2
1,2,2,1,2,1,2,2,2,2,1
2,1,1,2,2,1,2,2,1,2,2
2,2,1,2,2,1,2,2,1,2,1
2,2,2,2,2,2,2,1,1,2,2
2,2,2,2,2,2,1,1,1,1,2
1,2,2,2,2,2,2,1,1,2,2
1,2,1,2,2,2,1,2,1,2,1
1,1,1,2,2,2,2,1,1,2,2
2,1,2,2,1,2,1,2,1,2,2
2,2,2,2,2,2,2,2,2,2,2
endlayer

layer
3,3,3,3,3,3,3,3,3,3,3
3,4,4,6,5,6,5,4,4,4,3
3,5,4,8,0,9,8,7,0,4,3
3,8,12,8,8,11,10,10,10,4,3
3,8,8,7,15,7,14,2,13,5,3
0,8,8,8,7,8,16,2,2,4,3
3,8,8,8,7,0,14,2,13,4,3
3,8,12,8,8,8,17,17,17,5,3
3,6,6,19,7,8,8,18,9,6,3
3,6,5,4,5,4,5,5,4,4,3
3,3,3,3,3,3,20,20,20,3,3
endlayer

layer
0,0,0,0,0,0,0,0,0,0,0
0,5,5,5,4,5,5,5,6,4,0
0,5,4,0,0,9,0,21,0,5,19
0,0,12,0,0,0,0,0,22,4,0
0,22,0,21,0,21,0,7,23,6,0
0,0,0,0,21,0,0,7,24,5,0
0,0,0,19,21,0,0,7,23,5,0
0,22,12,0,0,0,0,0,11,6,0
0,6,4,19,21,0,0,0,9,4,0
0,6,5,5,6,4,5,6,4,4,0
0,0,0,0,0,0,20,20,20,0,0
endlayer

layer
0,0,0,0,25,0,0,25,0,0,0
0,6,6,6,6,6,6,5,4,4,0
0,5,6,0,26,9,26,0,22,4,19
0,5,12,0,26,0,0,0,22,4,19
0,22,12,0,0,0,0,21,22,5,0
16,6,5,0,0,0,0,21,0,5,0
0,0,12,19,0,0,0,21,0,6,0
0,6,12,0,0,0,0,0,0,4,0
0,5,5,0,25,0,25,0,9,6,19
0,4,4,5,4,6,4,4,6,5,0
0,0,0,0,0,0,0,20,20,0,0
endlayer

layer
0,0,0,0,25,0,0,25,0,27,0
0,5,6,5,5,6,4,4,5,5,0
0,6,6,19,26,9,26,26,26,4,19
0,6,4,19,26,26,0,0,22,5,19
0,5,5,0,0,0,0,0,22,4,0
4,4,6,0,0,0,0,0,0,5,0
0,6,5,19,0,0,0,0,0,4,0
0,6,5,0,0,0,0,0,0,6,0
0,5,4,0,25,25,25,0,9,4,19
0,6,4,5,5,5,6,6,6,4,0
0,0,0,0,0,0,0,0,20,0,0
endlayer

layer
0,26,0,0,25,0,0,0,0,27,0
0,4,5,5,6,5,4,6,6,4,0
0,0,12,19,26,9,26,0,22,4,19
0,0,13,19,0,26,26,0,22,4,19
0,5,4,0,0,0,0,0,22,4,0
4,5,5,0,0,0,0,0,0,4,0
0,4,4,19,0,0,0,0,0,5,0
0,0,13,0,0,0,0,0,0,6,0
0,0,12,0,25,25,0,0,27,4,19
0,4,6,5,5,4,6,4,4,4,0
0,0,0,0,0,0,0,0,20,0,0
endlayer

layer
0,26,27,0,25,0,0,0,27,27,0
0,5,6,4,6,6,4,6,4,6,0
0,0,12,19,0,9,0,0,22,6,19
0,0,12,19,0,0,0,0,22,5,0
0,6,4,0,0,0,0,0,0,6,0
0,6,5,0,0,0,0,0,0,4,0
0,6,6,19,0,0,0,0,0,5,0
0,0,12,0,0,0,0,0,26,6,0
0,0,12,0,25,25,26,26,26,5,19
0,4,6,5,4,6,4,5,5,5,0
0,0,0,0,0,0,0,0,20,0,0
endlayer

layer
0,26,27,0,0,0,0,0,27,27,0
0,4,6,6,5,5,5,4,4,5,0
0,4,5,4,5,5,5,5,4,4,0
0,5,5,6,28,28,28,28,6,6,0
0,6,6,5,28,28,28,28,6,4,0
0,6,6,5,28,28,28,28,5,6,0
0,5,4,5,28,28,28,28,6,4,0
0,4,5,4,28,28,28,26,5,6,0
27,6,4,5,5,6,6,6,5,5,19
0,4,4,4,4,6,4,5,4,4,0
0,0,0,0,0,0,0,0,20,0,0
endlayer

layer
0,26,29,0,29,0,29,0,29,27,0
16,5,5,6,5,5,5,6,4,5,30
0,6,2,2,2,2,2,2,2,6,0
16,6,2,2,2,2,2,2,2,4,30
0,6,2,2,2,2,2,2,2,6,0
16,4,2,2,2,2,2,2,2,4,30
0,5,2,2,2,2,2,2,2,6,0
16,4,2,2,2,2,2,2,2,6,30
26,4,2,2,2,2,2,2,2,4,19
16,5,5,6,5,6,4,4,5,5,30
0,26,31,0,31,0,31,0,31,0,0
endlayer

layer
0,26,4,0,4,0,5,0,6,27,0
4,26,27,0,0,0,0,0,27,26,4
0,27,27,0,8,0,8,8,26,26,0
6,0,0,8,8,8,8,8,26,0,6
0,0,0,7,8,8,8,0,0,0,25
6,0,8,0,0,8,8,8,8,0,5
0,0,0,8,0,8,8,8,0,0,0
4,26,0,8,8,8,8,8,8,0,4
0,26,27,8,8,8,8,8,8,0,25
4,26,26,0,0,0,0,0,0,22,5
20,22,4,0,5,0,4,0,4,0,20
endlayer

layer
0,0,5,0,6,19,5,0,5,19,0
6,0,0,0,0,0,0,0,0,0,4
0,0,27,0,0,0,0,0,0,0,0
4,0,0,0,0,0,0,0,0,0,6
0,0,0,21,0,0,0,0,0,0,25
4,0,0,0,0,0,0,0,0,0,5
0,0,0,0,0,0,0,0,0,0,0
4,0,0,0,0,0,0,0,0,0,6
0,0,0,0,0,0,0,0,0,0,25
4,0,0,0,0,0,0,0,0,0,4
0,22,6,0,6,0,5,0,4,0,0
endlayer

